Workbook

Sheet Start
A1: REVIEW DECK ▸ YOUR DAILY 10 MINUTES
A2: Every move from the course on a flashcard. A little every day beats cramming.
A4: TODAY
A5: Cards due today | B5: {=COUNTIF(Deck!$K$5:$K$178,"DUE")} -> 0
A6: New cards | B6: {=COUNTIF(Deck!$K$5:$K$178,"NEW")} -> 174
A7: Mastered (Box 5) | B7: {=COUNTIF(Deck!$H$5:$H$178,5)} -> 0
A8: Mastery | B8: {=TEXT(B7/174,"0%")} -> 0%
A10: CARDS PER BOX
A11: Box | B11: Cards
A12: New | B12: {=COUNTIF(Deck!$K$5:$K$178,"NEW")} -> 174
A13: Box 1 | B13: {=COUNTIF(Deck!$H$5:$H$178,1)} -> 0
A14: Box 2 | B14: {=COUNTIF(Deck!$H$5:$H$178,2)} -> 0
A15: Box 3 | B15: {=COUNTIF(Deck!$H$5:$H$178,3)} -> 0
A16: Box 4 | B16: {=COUNTIF(Deck!$H$5:$H$178,4)} -> 0
A17: Box 5 | B17: {=COUNTIF(Deck!$H$5:$H$178,5)} -> 0
A20: HOW IT WORKS
A21: Every card lives in a box from 1 to 5. Box 1 cards come back tomorrow; Box 5 cards wait a month.
A22: Intervals: Box 1 → 1 day · Box 2 → 3 days · Box 3 → 7 days · Box 4 → 14 days · Box 5 → 30 days.
A23: Right answer: the card moves up a box. Missed it: back to Box 1. NEW cards haven't been reviewed yet.
A24: Start with the cards from worlds you have played; leave the rest as NEW until you get there.
A26: DAILY ROUTINE
A27: 1 · Open the Deck sheet, select the Status header (K4), press Alt+↓ and keep only DUE (plus any NEW cards).
A28: 2 · Type each answer in the yellow Your answer cell and check the Result.
A29: 3 · Set Box to the Suggested box (select the Box cell, press Alt+↓, pick the number).
A30: 4 · Select Last reviewed and press Ctrl+; to stamp today's date.
A31: 5 · Clear your answers (select them, press Delete), then clear the filter (Alt+↓ → Select All).
A32: 6 · Come back tomorrow: a little every day is how it sticks.

Sheet Deck
A1: REVIEW DECK ▸ ALL CARDS
A2: Answer the DUE cards, move each to its Suggested box, and stamp the date with Ctrl+;.
A4: Card | B4: World | C4: Stage | D4: Prompt | E4: Your answer | F4: Result | G4: Suggested box | H4: Box | I4: Last reviewed | J4: Next due | K4: Status
A5: 1 | B5: S1 | C5: S1-1 Warp Zones | D5: Which keys jump to the edge of the current data block (any direction)? | F5: {=IFERROR(_xlfn.LET(_xlpm.a,Deck!$E$5,IF(TRIM(_xlpm.a&"")="","",IF(OR(SUBSTITUTE(SUBSTITUTE(SUBSTITUTE(SUBSTITUTE(SUBSTITUTE(SUBSTITUTE(SUBSTITUTE(SUBSTITUTE(SUBSTITUTE(SUBSTITUTE(SUBSTITUTE(SUBSTITUTE(SUBSTITUTE(SUBSTITUTE(SUBSTITUTE(SUBSTITUTE(SUBSTITUTE(SUBSTITUTE(SUBSTITUTE(SUBSTITUTE(SUBSTITUTE(SUBSTITUTE(SUBSTITUTE(SUBSTITUTE(SUBSTITUTE(SUBSTITUTE(SUBSTITUTE(UPPER(_xlpm.a)," ",""),"CONTROL","CTRL"),"CTL","CTRL"),"ESCAPE","ESC"),"RETURN","ENTER"),"PAGEDOWN","PGDN"),"PGDOWN","PGDN"),"PAGEUP","PGUP"),"ARROWKEYS","ARROW"),"ARROWKEY","ARROW"),"ARROWS","ARROW"),"DOWNARROW","DOWN"),"UPARROW","UP"),"LEFTARROW","LEFT"),"RIGHTARROW","RIGHT"),"ARROWDOWN","DOWN"),"ARROWUP","UP"),"ARROWLEFT","LEFT"),"ARROWRIGHT","RIGHT"),"↓","DOWN"),"↑","UP"),"←","LEFT"),"→","RIGHT"),"SPACEBAR","SPACE"),"−","-"),"MINUS","-"),"PLUS","+")=Key!$E$2:$I$2),"✔ CLEAR","✘ TRY AGAIN"))),"✘ TRY AGAIN")} | G5: {=IF(F5="","",IF(LEFT(F5,1)="✔",MIN(IF(H5="",1,H5)+1,5),1))} | J5: {=IF(OR(H5="",I5=""),"",IFERROR(I5+CHOOSE(H5,1,3,7,14,30),""))} | K5: {=IF(H5="","NEW",IF(J5="","DUE",IF(J5<=TODAY(),"DUE","in "&(J5-TODAY())&IF(J5-TODAY()=1," day"," days"))))} -> NEW
A6: 2 | B6: S1 | C6: S1-1 Warp Zones | D6: Which keys take you to the very first cell of the sheet (A1)? | F6: {=IFERROR(_xlfn.LET(_xlpm.a,Deck!$E$6,IF(TRIM(_xlpm.a&"")="","",IF(OR(SUBSTITUTE(SUBSTITUTE(SUBSTITUTE(SUBSTITUTE(SUBSTITUTE(SUBSTITUTE(SUBSTITUTE(SUBSTITUTE(SUBSTITUTE(SUBSTITUTE(SUBSTITUTE(SUBSTITUTE(SUBSTITUTE(SUBSTITUTE(SUBSTITUTE(SUBSTITUTE(SUBSTITUTE(SUBSTITUTE(SUBSTITUTE(SUBSTITUTE(SUBSTITUTE(SUBSTITUTE(SUBSTITUTE(SUBSTITUTE(SUBSTITUTE(SUBSTITUTE(SUBSTITUTE(UPPER(_xlpm.a)," ",""),"CONTROL","CTRL"),"CTL","CTRL"),"ESCAPE","ESC"),"RETURN","ENTER"),"PAGEDOWN","PGDN"),"PGDOWN","PGDN"),"PAGEUP","PGUP"),"ARROWKEYS","ARROW"),"ARROWKEY","ARROW"),"ARROWS","ARROW"),"DOWNARROW","DOWN"),"UPARROW","UP"),"LEFTARROW","LEFT"),"RIGHTARROW","RIGHT"),"ARROWDOWN","DOWN"),"ARROWUP","UP"),"ARROWLEFT","LEFT"),"ARROWRIGHT","RIGHT"),"↓","DOWN"),"↑","UP"),"←","LEFT"),"→","RIGHT"),"SPACEBAR","SPACE"),"−","-"),"MINUS","-"),"PLUS","+")=Key!$E$3:$E$3),"✔ CLEAR","✘ TRY AGAIN"))),"✘ TRY AGAIN")} | G6: {=IF(F6="","",IF(LEFT(F6,1)="✔",MIN(IF(H6="",1,H6)+1,5),1))} | J6: {=IF(OR(H6="",I6=""),"",IFERROR(I6+CHOOSE(H6,1,3,7,14,30),""))} | K6: {=IF(H6="","NEW",IF(J6="","DUE",IF(J6<=TODAY(),"DUE","in "&(J6-TODAY())&IF(J6-TODAY()=1," day"," days"))))} -> NEW
A7: 3 | B7: S1 | C7: S1-1 Warp Zones | D7: Which keys jump to the last used cell on the sheet? | F7: {=IFERROR(_xlfn.LET(_xlpm.a,Deck!$E$7,IF(TRIM(_xlpm.a&"")="","",IF(OR(SUBSTITUTE(SUBSTITUTE(SUBSTITUTE(SUBSTITUTE(SUBSTITUTE(SUBSTITUTE(SUBSTITUTE(SUBSTITUTE(SUBSTITUTE(SUBSTITUTE(SUBSTITUTE(SUBSTITUTE(SUBSTITUTE(SUBSTITUTE(SUBSTITUTE(SUBSTITUTE(SUBSTITUTE(SUBSTITUTE(SUBSTITUTE(SUBSTITUTE(SUBSTITUTE(SUBSTITUTE(SUBSTITUTE(SUBSTITUTE(SUBSTITUTE(SUBSTITUTE(SUBSTITUTE(UPPER(_xlpm.a)," ",""),"CONTROL","CTRL"),"CTL","CTRL"),"ESCAPE","ESC"),"RETURN","ENTER"),"PAGEDOWN","PGDN"),"PGDOWN","PGDN"),"PAGEUP","PGUP"),"ARROWKEYS","ARROW"),"ARROWKEY","ARROW"),"ARROWS","ARROW"),"DOWNARROW","DOWN"),"UPARROW","UP"),"LEFTARROW","LEFT"),"RIGHTARROW","RIGHT"),"ARROWDOWN","DOWN"),"ARROWUP","UP"),"ARROWLEFT","LEFT"),"ARROWRIGHT","RIGHT"),"↓","DOWN"),"↑","UP"),"←","LEFT"),"→","RIGHT"),"SPACEBAR","SPACE"),"−","-"),"MINUS","-"),"PLUS","+")=Key!$E$4:$E$4),"✔ CLEAR","✘ TRY AGAIN"))),"✘ TRY AGAIN")} | G7: {=IF(F7="","",IF(LEFT(F7,1)="✔",MIN(IF(H7="",1,H7)+1,5),1))} | J7: {=IF(OR(H7="",I7=""),"",IFERROR(I7+CHOOSE(H7,1,3,7,14,30),""))} | K7: {=IF(H7="","NEW",IF(J7="","DUE",IF(J7<=TODAY(),"DUE","in "&(J7-TODAY())&IF(J7-TODAY()=1," day"," days"))))} -> NEW
A8: 4 | B8: S1 | C8: S1-1 Warp Zones | D8: Which single key moves to column A of the current row? | F8: {=IFERROR(_xlfn.LET(_xlpm.a,Deck!$E$8,IF(TRIM(_xlpm.a&"")="","",IF(OR(SUBSTITUTE(SUBSTITUTE(SUBSTITUTE(SUBSTITUTE(SUBSTITUTE(SUBSTITUTE(SUBSTITUTE(SUBSTITUTE(SUBSTITUTE(SUBSTITUTE(SUBSTITUTE(SUBSTITUTE(SUBSTITUTE(SUBSTITUTE(SUBSTITUTE(SUBSTITUTE(SUBSTITUTE(SUBSTITUTE(SUBSTITUTE(SUBSTITUTE(SUBSTITUTE(SUBSTITUTE(SUBSTITUTE(SUBSTITUTE(SUBSTITUTE(SUBSTITUTE(SUBSTITUTE(UPPER(_xlpm.a)," ",""),"CONTROL","CTRL"),"CTL","CTRL"),"ESCAPE","ESC"),"RETURN","ENTER"),"PAGEDOWN","PGDN"),"PGDOWN","PGDN"),"PAGEUP","PGUP"),"ARROWKEYS","ARROW"),"ARROWKEY","ARROW"),"ARROWS","ARROW"),"DOWNARROW","DOWN"),"UPARROW","UP"),"LEFTARROW","LEFT"),"RIGHTARROW","RIGHT"),"ARROWDOWN","DOWN"),"ARROWUP","UP"),"ARROWLEFT","LEFT"),"ARROWRIGHT","RIGHT"),"↓","DOWN"),"↑","UP"),"←","LEFT"),"→","RIGHT"),"SPACEBAR","SPACE"),"−","-"),"MINUS","-"),"PLUS","+")=Key!$E$5:$E$5),"✔ CLEAR","✘ TRY AGAIN"))),"✘ TRY AGAIN")} | G8: {=IF(F8="","",IF(LEFT(F8,1)="✔",MIN(IF(H8="",1,H8)+1,5),1))} | J8: {=IF(OR(H8="",I8=""),"",IFERROR(I8+CHOOSE(H8,1,3,7,14,30),""))} | K8: {=IF(H8="","NEW",IF(J8="","DUE",IF(J8<=TODAY(),"DUE","in "&(J8-TODAY())&IF(J8-TODAY()=1," day"," days"))))} -> NEW
A9: 5 | B9: S1 | C9: S1-2 Teleport | D9: Which key opens the Go To box? | F9: {=IFERROR(_xlfn.LET(_xlpm.a,Deck!$E$9,IF(TRIM(_xlpm.a&"")="","",IF(OR(SUBSTITUTE(SUBSTITUTE(SUBSTITUTE(SUBSTITUTE(SUBSTITUTE(SUBSTITUTE(SUBSTITUTE(SUBSTITUTE(SUBSTITUTE(SUBSTITUTE(SUBSTITUTE(SUBSTITUTE(SUBSTITUTE(SUBSTITUTE(SUBSTITUTE(SUBSTITUTE(SUBSTITUTE(SUBSTITUTE(SUBSTITUTE(SUBSTITUTE(SUBSTITUTE(SUBSTITUTE(SUBSTITUTE(SUBSTITUTE(SUBSTITUTE(SUBSTITUTE(SUBSTITUTE(UPPER(_xlpm.a)," ",""),"CONTROL","CTRL"),"CTL","CTRL"),"ESCAPE","ESC"),"RETURN","ENTER"),"PAGEDOWN","PGDN"),"PGDOWN","PGDN"),"PAGEUP","PGUP"),"ARROWKEYS","ARROW"),"ARROWKEY","ARROW"),"ARROWS","ARROW"),"DOWNARROW","DOWN"),"UPARROW","UP"),"LEFTARROW","LEFT"),"RIGHTARROW","RIGHT"),"ARROWDOWN","DOWN"),"ARROWUP","UP"),"ARROWLEFT","LEFT"),"ARROWRIGHT","RIGHT"),"↓","DOWN"),"↑","UP"),"←","LEFT"),"→","RIGHT"),"SPACEBAR","SPACE"),"−","-"),"MINUS","-"),"PLUS","+")=Key!$E$6:$F$6),"✔ CLEAR","✘ TRY AGAIN"))),"✘ TRY AGAIN")} | G9: {=IF(F9="","",IF(LEFT(F9,1)="✔",MIN(IF(H9="",1,H9)+1,5),1))} | J9: {=IF(OR(H9="",I9=""),"",IFERROR(I9+CHOOSE(H9,1,3,7,14,30),""))} | K9: {=IF(H9="","NEW",IF(J9="","DUE",IF(J9<=TODAY(),"DUE","in "&(J9-TODAY())&IF(J9-TODAY()=1," day"," days"))))} -> NEW
A10: 6 | B10: S1 | C10: S1-2 Teleport | D10: Which keys move to the next sheet? | F10: {=IFERROR(_xlfn.LET(_xlpm.a,Deck!$E$10,IF(TRIM(_xlpm.a&"")="","",IF(OR(SUBSTITUTE(SUBSTITUTE(SUBSTITUTE(SUBSTITUTE(SUBSTITUTE(SUBSTITUTE(SUBSTITUTE(SUBSTITUTE(SUBSTITUTE(SUBSTITUTE(SUBSTITUTE(SUBSTITUTE(SUBSTITUTE(SUBSTITUTE(SUBSTITUTE(SUBSTITUTE(SUBSTITUTE(SUBSTITUTE(SUBSTITUTE(SUBSTITUTE(SUBSTITUTE(SUBSTITUTE(SUBSTITUTE(SUBSTITUTE(SUBSTITUTE(SUBSTITUTE(SUBSTITUTE(UPPER(_xlpm.a)," ",""),"CONTROL","CTRL"),"CTL","CTRL"),"ESCAPE","ESC"),"RETURN","ENTER"),"PAGEDOWN","PGDN"),"PGDOWN","PGDN"),"PAGEUP","PGUP"),"ARROWKEYS","ARROW"),"ARROWKEY","ARROW"),"ARROWS","ARROW"),"DOWNARROW","DOWN"),"UPARROW","UP"),"LEFTARROW","LEFT"),"RIGHTARROW","RIGHT"),"ARROWDOWN","DOWN"),"ARROWUP","UP"),"ARROWLEFT","LEFT"),"ARROWRIGHT","RIGHT"),"↓","DOWN"),"↑","UP"),"←","LEFT"),"→","RIGHT"),"SPACEBAR","SPACE"),"−","-"),"MINUS","-"),"PLUS","+")=Key!$E$7:$E$7),"✔ CLEAR","✘ TRY AGAIN"))),"✘ TRY AGAIN")} | G10: {=IF(F10="","",IF(LEFT(F10,1)="✔",MIN(IF(H10="",1,H10)+1,5),1))} | J10: {=IF(OR(H10="",I10=""),"",IFERROR(I10+CHOOSE(H10,1,3,7,14,30),""))} | K10: {=IF(H10="","NEW",IF(J10="","DUE",IF(J10<=TODAY(),"DUE","in "&(J10-TODAY())&IF(J10-TODAY()=1," day"," days"))))} -> NEW
A11: 7 | B11: S1 | C11: S1-2 Teleport | D11: Which keys move to the previous sheet? | F11: {=IFERROR(_xlfn.LET(_xlpm.a,Deck!$E$11,IF(TRIM(_xlpm.a&"")="","",IF(OR(SUBSTITUTE(SUBSTITUTE(SUBSTITUTE(SUBSTITUTE(SUBSTITUTE(SUBSTITUTE(SUBSTITUTE(SUBSTITUTE(SUBSTITUTE(SUBSTITUTE(SUBSTITUTE(SUBSTITUTE(SUBSTITUTE(SUBSTITUTE(SUBSTITUTE(SUBSTITUTE(SUBSTITUTE(SUBSTITUTE(SUBSTITUTE(SUBSTITUTE(SUBSTITUTE(SUBSTITUTE(SUBSTITUTE(SUBSTITUTE(SUBSTITUTE(SUBSTITUTE(SUBSTITUTE(UPPER(_xlpm.a)," ",""),"CONTROL","CTRL"),"CTL","CTRL"),"ESCAPE","ESC"),"RETURN","ENTER"),"PAGEDOWN","PGDN"),"PGDOWN","PGDN"),"PAGEUP","PGUP"),"ARROWKEYS","ARROW"),"ARROWKEY","ARROW"),"ARROWS","ARROW"),"DOWNARROW","DOWN"),"UPARROW","UP"),"LEFTARROW","LEFT"),"RIGHTARROW","RIGHT"),"ARROWDOWN","DOWN"),"ARROWUP","UP"),"ARROWLEFT","LEFT"),"ARROWRIGHT","RIGHT"),"↓","DOWN"),"↑","UP"),"←","LEFT"),"→","RIGHT"),"SPACEBAR","SPACE"),"−","-"),"MINUS","-"),"PLUS","+")=Key!$E$8:$E$8),"✔ CLEAR","✘ TRY AGAIN"))),"✘ TRY AGAIN")} | G11: {=IF(F11="","",IF(LEFT(F11,1)="✔",MIN(IF(H11="",1,H11)+1,5),1))} | J11: {=IF(OR(H11="",I11=""),"",IFERROR(I11+CHOOSE(H11,1,3,7,14,30),""))} | K11: {=IF(H11="","NEW",IF(J11="","DUE",IF(J11<=TODAY(),"DUE","in "&(J11-TODAY())&IF(J11-TODAY()=1," day"," days"))))} -> NEW
A12: 8 | B12: S1 | C12: S1-2 Teleport | D12: Which key scrolls one screen down? | F12: {=IFERROR(_xlfn.LET(_xlpm.a,Deck!$E$12,IF(TRIM(_xlpm.a&"")="","",IF(OR(SUBSTITUTE(SUBSTITUTE(SUBSTITUTE(SUBSTITUTE(SUBSTITUTE(SUBSTITUTE(SUBSTITUTE(SUBSTITUTE(SUBSTITUTE(SUBSTITUTE(SUBSTITUTE(SUBSTITUTE(SUBSTITUTE(SUBSTITUTE(SUBSTITUTE(SUBSTITUTE(SUBSTITUTE(SUBSTITUTE(SUBSTITUTE(SUBSTITUTE(SUBSTITUTE(SUBSTITUTE(SUBSTITUTE(SUBSTITUTE(SUBSTITUTE(SUBSTITUTE(SUBSTITUTE(UPPER(_xlpm.a)," ",""),"CONTROL","CTRL"),"CTL","CTRL"),"ESCAPE","ESC"),"RETURN","ENTER"),"PAGEDOWN","PGDN"),"PGDOWN","PGDN"),"PAGEUP","PGUP"),"ARROWKEYS","ARROW"),"ARROWKEY","ARROW"),"ARROWS","ARROW"),"DOWNARROW","DOWN"),"UPARROW","UP"),"LEFTARROW","LEFT"),"RIGHTARROW","RIGHT"),"ARROWDOWN","DOWN"),"ARROWUP","UP"),"ARROWLEFT","LEFT"),"ARROWRIGHT","RIGHT"),"↓","DOWN"),"↑","UP"),"←","LEFT"),"→","RIGHT"),"SPACEBAR","SPACE"),"−","-"),"MINUS","-"),"PLUS","+")=Key!$E$9:$E$9),"✔ CLEAR","✘ TRY AGAIN"))),"✘ TRY AGAIN")} | G12: {=IF(F12="","",IF(LEFT(F12,1)="✔",MIN(IF(H12="",1,H12)+1,5),1))} | J12: {=IF(OR(H12="",I12=""),"",IFERROR(I12+CHOOSE(H12,1,3,7,14,30),""))} | K12: {=IF(H12="","NEW",IF(J12="","DUE",IF(J12<=TODAY(),"DUE","in "&(J12-TODAY())&IF(J12-TODAY()=1," day"," days"))))} -> NEW
A13: 9 | B13: S1 | C13: S1-2 Teleport | D13: Which keys scroll one screen to the right? | F13: {=IFERROR(_xlfn.LET(_xlpm.a,Deck!$E$13,IF(TRIM(_xlpm.a&"")="","",IF(OR(SUBSTITUTE(SUBSTITUTE(SUBSTITUTE(SUBSTITUTE(SUBSTITUTE(SUBSTITUTE(SUBSTITUTE(SUBSTITUTE(SUBSTITUTE(SUBSTITUTE(SUBSTITUTE(SUBSTITUTE(SUBSTITUTE(SUBSTITUTE(SUBSTITUTE(SUBSTITUTE(SUBSTITUTE(SUBSTITUTE(SUBSTITUTE(SUBSTITUTE(SUBSTITUTE(SUBSTITUTE(SUBSTITUTE(SUBSTITUTE(SUBSTITUTE(SUBSTITUTE(SUBSTITUTE(UPPER(_xlpm.a)," ",""),"CONTROL","CTRL"),"CTL","CTRL"),"ESCAPE","ESC"),"RETURN","ENTER"),"PAGEDOWN","PGDN"),"PGDOWN","PGDN"),"PAGEUP","PGUP"),"ARROWKEYS","ARROW"),"ARROWKEY","ARROW"),"ARROWS","ARROW"),"DOWNARROW","DOWN"),"UPARROW","UP"),"LEFTARROW","LEFT"),"RIGHTARROW","RIGHT"),"ARROWDOWN","DOWN"),"ARROWUP","UP"),"ARROWLEFT","LEFT"),"ARROWRIGHT","RIGHT"),"↓","DOWN"),"↑","UP"),"←","LEFT"),"→","RIGHT"),"SPACEBAR","SPACE"),"−","-"),"MINUS","-"),"PLUS","+")=Key!$E$10:$E$10),"✔ CLEAR","✘ TRY AGAIN"))),"✘ TRY AGAIN")} | G13: {=IF(F13="","",IF(LEFT(F13,1)="✔",MIN(IF(H13="",1,H13)+1,5),1))} | J13: {=IF(OR(H13="",I13=""),"",IFERROR(I13+CHOOSE(H13,1,3,7,14,30),""))} | K13: {=IF(H13="","NEW",IF(J13="","DUE",IF(J13<=TODAY(),"DUE","in "&(J13-TODAY())&IF(J13-TODAY()=1," day"," days"))))} -> NEW
A14: 10 | B14: S1 | C14: S1-3 Lasso | D14: Which keys grow the selection by one cell? | F14: {=IFERROR(_xlfn.LET(_xlpm.a,Deck!$E$14,IF(TRIM(_xlpm.a&"")="","",IF(OR(SUBSTITUTE(SUBSTITUTE(SUBSTITUTE(SUBSTITUTE(SUBSTITUTE(SUBSTITUTE(SUBSTITUTE(SUBSTITUTE(SUBSTITUTE(SUBSTITUTE(SUBSTITUTE(SUBSTITUTE(SUBSTITUTE(SUBSTITUTE(SUBSTITUTE(SUBSTITUTE(SUBSTITUTE(SUBSTITUTE(SUBSTITUTE(SUBSTITUTE(SUBSTITUTE(SUBSTITUTE(SUBSTITUTE(SUBSTITUTE(SUBSTITUTE(SUBSTITUTE(SUBSTITUTE(UPPER(_xlpm.a)," ",""),"CONTROL","CTRL"),"CTL","CTRL"),"ESCAPE","ESC"),"RETURN","ENTER"),"PAGEDOWN","PGDN"),"PGDOWN","PGDN"),"PAGEUP","PGUP"),"ARROWKEYS","ARROW"),"ARROWKEY","ARROW"),"ARROWS","ARROW"),"DOWNARROW","DOWN"),"UPARROW","UP"),"LEFTARROW","LEFT"),"RIGHTARROW","RIGHT"),"ARROWDOWN","DOWN"),"ARROWUP","UP"),"ARROWLEFT","LEFT"),"ARROWRIGHT","RIGHT"),"↓","DOWN"),"↑","UP"),"←","LEFT"),"→","RIGHT"),"SPACEBAR","SPACE"),"−","-"),"MINUS","-"),"PLUS","+")=Key!$E$11:$I$11),"✔ CLEAR","✘ TRY AGAIN"))),"✘ TRY AGAIN")} | G14: {=IF(F14="","",IF(LEFT(F14,1)="✔",MIN(IF(H14="",1,H14)+1,5),1))} | J14: {=IF(OR(H14="",I14=""),"",IFERROR(I14+CHOOSE(H14,1,3,7,14,30),""))} | K14: {=IF(H14="","NEW",IF(J14="","DUE",IF(J14<=TODAY(),"DUE","in "&(J14-TODAY())&IF(J14-TODAY()=1," day"," days"))))} -> NEW
A15: 11 | B15: S1 | C15: S1-3 Lasso | D15: Which keys extend the selection all the way to the edge of the data? | F15: {=IFERROR(_xlfn.LET(_xlpm.a,Deck!$E$15,IF(TRIM(_xlpm.a&"")="","",IF(OR(SUBSTITUTE(SUBSTITUTE(SUBSTITUTE(SUBSTITUTE(SUBSTITUTE(SUBSTITUTE(SUBSTITUTE(SUBSTITUTE(SUBSTITUTE(SUBSTITUTE(SUBSTITUTE(SUBSTITUTE(SUBSTITUTE(SUBSTITUTE(SUBSTITUTE(SUBSTITUTE(SUBSTITUTE(SUBSTITUTE(SUBSTITUTE(SUBSTITUTE(SUBSTITUTE(SUBSTITUTE(SUBSTITUTE(SUBSTITUTE(SUBSTITUTE(SUBSTITUTE(SUBSTITUTE(UPPER(_xlpm.a)," ",""),"CONTROL","CTRL"),"CTL","CTRL"),"ESCAPE","ESC"),"RETURN","ENTER"),"PAGEDOWN","PGDN"),"PGDOWN","PGDN"),"PAGEUP","PGUP"),"ARROWKEYS","ARROW"),"ARROWKEY","ARROW"),"ARROWS","ARROW"),"DOWNARROW","DOWN"),"UPARROW","UP"),"LEFTARROW","LEFT"),"RIGHTARROW","RIGHT"),"ARROWDOWN","DOWN"),"ARROWUP","UP"),"ARROWLEFT","LEFT"),"ARROWRIGHT","RIGHT"),"↓","DOWN"),"↑","UP"),"←","LEFT"),"→","RIGHT"),"SPACEBAR","SPACE"),"−","-"),"MINUS","-"),"PLUS","+")=Key!$E$12:$N$12),"✔ CLEAR","✘ TRY AGAIN"))),"✘ TRY AGAIN")} | G15: {=IF(F15="","",IF(LEFT(F15,1)="✔",MIN(IF(H15="",1,H15)+1,5),1))} | J15: {=IF(OR(H15="",I15=""),"",IFERROR(I15+CHOOSE(H15,1,3,7,14,30),""))} | K15: {=IF(H15="","NEW",IF(J15="","DUE",IF(J15<=TODAY(),"DUE","in "&(J15-TODAY())&IF(J15-TODAY()=1," day"," days"))))} -> NEW
A16: 12 | B16: S1 | C16: S1-3 Lasso | D16: Which keys extend the selection to the last used cell? | F16: {=IFERROR(_xlfn.LET(_xlpm.a,Deck!$E$16,IF(TRIM(_xlpm.a&"")="","",IF(OR(SUBSTITUTE(SUBSTITUTE(SUBSTITUTE(SUBSTITUTE(SUBSTITUTE(SUBSTITUTE(SUBSTITUTE(SUBSTITUTE(SUBSTITUTE(SUBSTITUTE(SUBSTITUTE(SUBSTITUTE(SUBSTITUTE(SUBSTITUTE(SUBSTITUTE(SUBSTITUTE(SUBSTITUTE(SUBSTITUTE(SUBSTITUTE(SUBSTITUTE(SUBSTITUTE(SUBSTITUTE(SUBSTITUTE(SUBSTITUTE(SUBSTITUTE(SUBSTITUTE(SUBSTITUTE(UPPER(_xlpm.a)," ",""),"CONTROL","CTRL"),"CTL","CTRL"),"ESCAPE","ESC"),"RETURN","ENTER"),"PAGEDOWN","PGDN"),"PGDOWN","PGDN"),"PAGEUP","PGUP"),"ARROWKEYS","ARROW"),"ARROWKEY","ARROW"),"ARROWS","ARROW"),"DOWNARROW","DOWN"),"UPARROW","UP"),"LEFTARROW","LEFT"),"RIGHTARROW","RIGHT"),"ARROWDOWN","DOWN"),"ARROWUP","UP"),"ARROWLEFT","LEFT"),"ARROWRIGHT","RIGHT"),"↓","DOWN"),"↑","UP"),"←","LEFT"),"→","RIGHT"),"SPACEBAR","SPACE"),"−","-"),"MINUS","-"),"PLUS","+")=Key!$E$13:$F$13),"✔ CLEAR","✘ TRY AGAIN"))),"✘ TRY AGAIN")} | G16: {=IF(F16="","",IF(LEFT(F16,1)="✔",MIN(IF(H16="",1,H16)+1,5),1))} | J16: {=IF(OR(H16="",I16=""),"",IFERROR(I16+CHOOSE(H16,1,3,7,14,30),""))} | K16: {=IF(H16="","NEW",IF(J16="","DUE",IF(J16<=TODAY(),"DUE","in "&(J16-TODAY())&IF(J16-TODAY()=1," day"," days"))))} -> NEW
A17: 13 | B17: S1 | C17: S1-3 Lasso | D17: Which keys extend the selection back to cell A1? | F17: {=IFERROR(_xlfn.LET(_xlpm.a,Deck!$E$17,IF(TRIM(_xlpm.a&"")="","",IF(OR(SUBSTITUTE(SUBSTITUTE(SUBSTITUTE(SUBSTITUTE(SUBSTITUTE(SUBSTITUTE(SUBSTITUTE(SUBSTITUTE(SUBSTITUTE(SUBSTITUTE(SUBSTITUTE(SUBSTITUTE(SUBSTITUTE(SUBSTITUTE(SUBSTITUTE(SUBSTITUTE(SUBSTITUTE(SUBSTITUTE(SUBSTITUTE(SUBSTITUTE(SUBSTITUTE(SUBSTITUTE(SUBSTITUTE(SUBSTITUTE(SUBSTITUTE(SUBSTITUTE(SUBSTITUTE(UPPER(_xlpm.a)," ",""),"CONTROL","CTRL"),"CTL","CTRL"),"ESCAPE","ESC"),"RETURN","ENTER"),"PAGEDOWN","PGDN"),"PGDOWN","PGDN"),"PAGEUP","PGUP"),"ARROWKEYS","ARROW"),"ARROWKEY","ARROW"),"ARROWS","ARROW"),"DOWNARROW","DOWN"),"UPARROW","UP"),"LEFTARROW","LEFT"),"RIGHTARROW","RIGHT"),"ARROWDOWN","DOWN"),"ARROWUP","UP"),"ARROWLEFT","LEFT"),"ARROWRIGHT","RIGHT"),"↓","DOWN"),"↑","UP"),"←","LEFT"),"→","RIGHT"),"SPACEBAR","SPACE"),"−","-"),"MINUS","-"),"PLUS","+")=Key!$E$14:$F$14),"✔ CLEAR","✘ TRY AGAIN"))),"✘ TRY AGAIN")} | G17: {=IF(F17="","",IF(LEFT(F17,1)="✔",MIN(IF(H17="",1,H17)+1,5),1))} | J17: {=IF(OR(H17="",I17=""),"",IFERROR(I17+CHOOSE(H17,1,3,7,14,30),""))} | K17: {=IF(H17="","NEW",IF(J17="","DUE",IF(J17<=TODAY(),"DUE","in "&(J17-TODAY())&IF(J17-TODAY()=1," day"," days"))))} -> NEW
A18: 14 | B18: S1 | C18: S1-4 Grab | D18: Which keys select the entire row? | F18: {=IFERROR(_xlfn.LET(_xlpm.a,Deck!$E$18,IF(TRIM(_xlpm.a&"")="","",IF(OR(SUBSTITUTE(SUBSTITUTE(SUBSTITUTE(SUBSTITUTE(SUBSTITUTE(SUBSTITUTE(SUBSTITUTE(SUBSTITUTE(SUBSTITUTE(SUBSTITUTE(SUBSTITUTE(SUBSTITUTE(SUBSTITUTE(SUBSTITUTE(SUBSTITUTE(SUBSTITUTE(SUBSTITUTE(SUBSTITUTE(SUBSTITUTE(SUBSTITUTE(SUBSTITUTE(SUBSTITUTE(SUBSTITUTE(SUBSTITUTE(SUBSTITUTE(SUBSTITUTE(SUBSTITUTE(UPPER(_xlpm.a)," ",""),"CONTROL","CTRL"),"CTL","CTRL"),"ESCAPE","ESC"),"RETURN","ENTER"),"PAGEDOWN","PGDN"),"PGDOWN","PGDN"),"PAGEUP","PGUP"),"ARROWKEYS","ARROW"),"ARROWKEY","ARROW"),"ARROWS","ARROW"),"DOWNARROW","DOWN"),"UPARROW","UP"),"LEFTARROW","LEFT"),"RIGHTARROW","RIGHT"),"ARROWDOWN","DOWN"),"ARROWUP","UP"),"ARROWLEFT","LEFT"),"ARROWRIGHT","RIGHT"),"↓","DOWN"),"↑","UP"),"←","LEFT"),"→","RIGHT"),"SPACEBAR","SPACE"),"−","-"),"MINUS","-"),"PLUS","+")=Key!$E$15:$E$15),"✔ CLEAR","✘ TRY AGAIN"))),"✘ TRY AGAIN")} | G18: {=IF(F18="","",IF(LEFT(F18,1)="✔",MIN(IF(H18="",1,H18)+1,5),1))} | J18: {=IF(OR(H18="",I18=""),"",IFERROR(I18+CHOOSE(H18,1,3,7,14,30),""))} | K18: {=IF(H18="","NEW",IF(J18="","DUE",IF(J18<=TODAY(),"DUE","in "&(J18-TODAY())&IF(J18-TODAY()=1," day"," days"))))} -> NEW
A19: 15 | B19: S1 | C19: S1-4 Grab | D19: Which keys select the entire column? | F19: {=IFERROR(_xlfn.LET(_xlpm.a,Deck!$E$19,IF(TRIM(_xlpm.a&"")="","",IF(OR(SUBSTITUTE(SUBSTITUTE(SUBSTITUTE(SUBSTITUTE(SUBSTITUTE(SUBSTITUTE(SUBSTITUTE(SUBSTITUTE(SUBSTITUTE(SUBSTITUTE(SUBSTITUTE(SUBSTITUTE(SUBSTITUTE(SUBSTITUTE(SUBSTITUTE(SUBSTITUTE(SUBSTITUTE(SUBSTITUTE(SUBSTITUTE(SUBSTITUTE(SUBSTITUTE(SUBSTITUTE(SUBSTITUTE(SUBSTITUTE(SUBSTITUTE(SUBSTITUTE(SUBSTITUTE(UPPER(_xlpm.a)," ",""),"CONTROL","CTRL"),"CTL","CTRL"),"ESCAPE","ESC"),"RETURN","ENTER"),"PAGEDOWN","PGDN"),"PGDOWN","PGDN"),"PAGEUP","PGUP"),"ARROWKEYS","ARROW"),"ARROWKEY","ARROW"),"ARROWS","ARROW"),"DOWNARROW","DOWN"),"UPARROW","UP"),"LEFTARROW","LEFT"),"RIGHTARROW","RIGHT"),"ARROWDOWN","DOWN"),"ARROWUP","UP"),"ARROWLEFT","LEFT"),"ARROWRIGHT","RIGHT"),"↓","DOWN"),"↑","UP"),"←","LEFT"),"→","RIGHT"),"SPACEBAR","SPACE"),"−","-"),"MINUS","-"),"PLUS","+")=Key!$E$16:$E$16),"✔ CLEAR","✘ TRY AGAIN"))),"✘ TRY AGAIN")} | G19: {=IF(F19="","",IF(LEFT(F19,1)="✔",MIN(IF(H19="",1,H19)+1,5),1))} | J19: {=IF(OR(H19="",I19=""),"",IFERROR(I19+CHOOSE(H19,1,3,7,14,30),""))} | K19: {=IF(H19="","NEW",IF(J19="","DUE",IF(J19<=TODAY(),"DUE","in "&(J19-TODAY())&IF(J19-TODAY()=1," day"," days"))))} -> NEW
A20: 16 | B20: S1 | C20: S1-4 Grab | D20: Which keys select the current data block (and the whole sheet if you keep pressing)? | F20: {=IFERROR(_xlfn.LET(_xlpm.a,Deck!$E$20,IF(TRIM(_xlpm.a&"")="","",IF(OR(SUBSTITUTE(SUBSTITUTE(SUBSTITUTE(SUBSTITUTE(SUBSTITUTE(SUBSTITUTE(SUBSTITUTE(SUBSTITUTE(SUBSTITUTE(SUBSTITUTE(SUBSTITUTE(SUBSTITUTE(SUBSTITUTE(SUBSTITUTE(SUBSTITUTE(SUBSTITUTE(SUBSTITUTE(SUBSTITUTE(SUBSTITUTE(SUBSTITUTE(SUBSTITUTE(SUBSTITUTE(SUBSTITUTE(SUBSTITUTE(SUBSTITUTE(SUBSTITUTE(SUBSTITUTE(UPPER(_xlpm.a)," ",""),"CONTROL","CTRL"),"CTL","CTRL"),"ESCAPE","ESC"),"RETURN","ENTER"),"PAGEDOWN","PGDN"),"PGDOWN","PGDN"),"PAGEUP","PGUP"),"ARROWKEYS","ARROW"),"ARROWKEY","ARROW"),"ARROWS","ARROW"),"DOWNARROW","DOWN"),"UPARROW","UP"),"LEFTARROW","LEFT"),"RIGHTARROW","RIGHT"),"ARROWDOWN","DOWN"),"ARROWUP","UP"),"ARROWLEFT","LEFT"),"ARROWRIGHT","RIGHT"),"↓","DOWN"),"↑","UP"),"←","LEFT"),"→","RIGHT"),"SPACEBAR","SPACE"),"−","-"),"MINUS","-"),"PLUS","+")=Key!$E$17:$G$17),"✔ CLEAR","✘ TRY AGAIN"))),"✘ TRY AGAIN")} | G20: {=IF(F20="","",IF(LEFT(F20,1)="✔",MIN(IF(H20="",1,H20)+1,5),1))} | J20: {=IF(OR(H20="",I20=""),"",IFERROR(I20+CHOOSE(H20,1,3,7,14,30),""))} | K20: {=IF(H20="","NEW",IF(J20="","DUE",IF(J20<=TODAY(),"DUE","in "&(J20-TODAY())&IF(J20-TODAY()=1," day"," days"))))} -> NEW
A21: 17 | B21: F1 | C21: F1-1 Power Up | D21: Which character must every formula start with? | F21: {=IFERROR(_xlfn.LET(_xlpm.a,Deck!$E$21,IF(TRIM(_xlpm.a&"")="","",IF(OR(SUBSTITUTE(SUBSTITUTE(SUBSTITUTE(SUBSTITUTE(SUBSTITUTE(SUBSTITUTE(SUBSTITUTE(SUBSTITUTE(SUBSTITUTE(SUBSTITUTE(SUBSTITUTE(SUBSTITUTE(SUBSTITUTE(SUBSTITUTE(SUBSTITUTE(SUBSTITUTE(SUBSTITUTE(SUBSTITUTE(SUBSTITUTE(SUBSTITUTE(SUBSTITUTE(SUBSTITUTE(SUBSTITUTE(SUBSTITUTE(SUBSTITUTE(SUBSTITUTE(SUBSTITUTE(UPPER(_xlpm.a)," ",""),"CONTROL","CTRL"),"CTL","CTRL"),"ESCAPE","ESC"),"RETURN","ENTER"),"PAGEDOWN","PGDN"),"PGDOWN","PGDN"),"PAGEUP","PGUP"),"ARROWKEYS","ARROW"),"ARROWKEY","ARROW"),"ARROWS","ARROW"),"DOWNARROW","DOWN"),"UPARROW","UP"),"LEFTARROW","LEFT"),"RIGHTARROW","RIGHT"),"ARROWDOWN","DOWN"),"ARROWUP","UP"),"ARROWLEFT","LEFT"),"ARROWRIGHT","RIGHT"),"↓","DOWN"),"↑","UP"),"←","LEFT"),"→","RIGHT"),"SPACEBAR","SPACE"),"−","-"),"MINUS","-"),"PLUS","+")=Key!$E$18:$H$18),"✔ CLEAR","✘ TRY AGAIN"))),"✘ TRY AGAIN")} | G21: {=IF(F21="","",IF(LEFT(F21,1)="✔",MIN(IF(H21="",1,H21)+1,5),1))} | J21: {=IF(OR(H21="",I21=""),"",IFERROR(I21+CHOOSE(H21,1,3,7,14,30),""))} | K21: {=IF(H21="","NEW",IF(J21="","DUE",IF(J21<=TODAY(),"DUE","in "&(J21-TODAY())&IF(J21-TODAY()=1," day"," days"))))} -> NEW
A22: 18 | B22: F1 | C22: F1-1 Power Up | D22: Which operator raises a number to a power? | F22: {=IFERROR(_xlfn.LET(_xlpm.a,Deck!$E$22,IF(TRIM(_xlpm.a&"")="","",IF(OR(SUBSTITUTE(SUBSTITUTE(SUBSTITUTE(SUBSTITUTE(SUBSTITUTE(SUBSTITUTE(SUBSTITUTE(SUBSTITUTE(SUBSTITUTE(SUBSTITUTE(SUBSTITUTE(SUBSTITUTE(SUBSTITUTE(SUBSTITUTE(SUBSTITUTE(SUBSTITUTE(SUBSTITUTE(SUBSTITUTE(SUBSTITUTE(SUBSTITUTE(SUBSTITUTE(SUBSTITUTE(SUBSTITUTE(SUBSTITUTE(SUBSTITUTE(SUBSTITUTE(SUBSTITUTE(UPPER(_xlpm.a)," ",""),"CONTROL","CTRL"),"CTL","CTRL"),"ESCAPE","ESC"),"RETURN","ENTER"),"PAGEDOWN","PGDN"),"PGDOWN","PGDN"),"PAGEUP","PGUP"),"ARROWKEYS","ARROW"),"ARROWKEY","ARROW"),"ARROWS","ARROW"),"DOWNARROW","DOWN"),"UPARROW","UP"),"LEFTARROW","LEFT"),"RIGHTARROW","RIGHT"),"ARROWDOWN","DOWN"),"ARROWUP","UP"),"ARROWLEFT","LEFT"),"ARROWRIGHT","RIGHT"),"↓","DOWN"),"↑","UP"),"←","LEFT"),"→","RIGHT"),"SPACEBAR","SPACE"),"−","-"),"MINUS","-"),"PLUS","+")=Key!$E$19:$F$19),"✔ CLEAR","✘ TRY AGAIN"))),"✘ TRY AGAIN")} | G22: {=IF(F22="","",IF(LEFT(F22,1)="✔",MIN(IF(H22="",1,H22)+1,5),1))} | J22: {=IF(OR(H22="",I22=""),"",IFERROR(I22+CHOOSE(H22,1,3,7,14,30),""))} | K22: {=IF(H22="","NEW",IF(J22="","DUE",IF(J22<=TODAY(),"DUE","in "&(J22-TODAY())&IF(J22-TODAY()=1," day"," days"))))} -> NEW
A23: 19 | B23: F1 | C23: F1-1 Power Up | D23: What does =2+3*4 return? | F23: {=IFERROR(_xlfn.LET(_xlpm.a,Deck!$E$23,IF(TRIM(_xlpm.a&"")="","",IF(OR(SUBSTITUTE(SUBSTITUTE(SUBSTITUTE(SUBSTITUTE(SUBSTITUTE(SUBSTITUTE(SUBSTITUTE(SUBSTITUTE(SUBSTITUTE(SUBSTITUTE(SUBSTITUTE(SUBSTITUTE(SUBSTITUTE(SUBSTITUTE(SUBSTITUTE(SUBSTITUTE(SUBSTITUTE(SUBSTITUTE(SUBSTITUTE(SUBSTITUTE(SUBSTITUTE(SUBSTITUTE(SUBSTITUTE(SUBSTITUTE(SUBSTITUTE(SUBSTITUTE(SUBSTITUTE(UPPER(_xlpm.a)," ",""),"CONTROL","CTRL"),"CTL","CTRL"),"ESCAPE","ESC"),"RETURN","ENTER"),"PAGEDOWN","PGDN"),"PGDOWN","PGDN"),"PAGEUP","PGUP"),"ARROWKEYS","ARROW"),"ARROWKEY","ARROW"),"ARROWS","ARROW"),"DOWNARROW","DOWN"),"UPARROW","UP"),"LEFTARROW","LEFT"),"RIGHTARROW","RIGHT"),"ARROWDOWN","DOWN"),"ARROWUP","UP"),"ARROWLEFT","LEFT"),"ARROWRIGHT","RIGHT"),"↓","DOWN"),"↑","UP"),"←","LEFT"),"→","RIGHT"),"SPACEBAR","SPACE"),"−","-"),"MINUS","-"),"PLUS","+")=Key!$E$20:$E$20),"✔ CLEAR","✘ TRY AGAIN"))),"✘ TRY AGAIN")} | G23: {=IF(F23="","",IF(LEFT(F23,1)="✔",MIN(IF(H23="",1,H23)+1,5),1))} | J23: {=IF(OR(H23="",I23=""),"",IFERROR(I23+CHOOSE(H23,1,3,7,14,30),""))} | K23: {=IF(H23="","NEW",IF(J23="","DUE",IF(J23<=TODAY(),"DUE","in "&(J23-TODAY())&IF(J23-TODAY()=1," day"," days"))))} -> NEW
A24: 20 | B24: F1 | C24: F1-1 Power Up | D24: Type the formula that multiplies cell B2 by cell C2. | F24: {=IFERROR(_xlfn.LET(_xlpm.a,Deck!$E$24,IF(TRIM(_xlpm.a&"")="","",IF(OR(SUBSTITUTE(SUBSTITUTE(SUBSTITUTE(SUBSTITUTE(SUBSTITUTE(SUBSTITUTE(SUBSTITUTE(SUBSTITUTE(SUBSTITUTE(SUBSTITUTE(SUBSTITUTE(SUBSTITUTE(SUBSTITUTE(SUBSTITUTE(SUBSTITUTE(SUBSTITUTE(SUBSTITUTE(SUBSTITUTE(SUBSTITUTE(SUBSTITUTE(SUBSTITUTE(SUBSTITUTE(SUBSTITUTE(SUBSTITUTE(SUBSTITUTE(SUBSTITUTE(SUBSTITUTE(UPPER(_xlpm.a)," ",""),"CONTROL","CTRL"),"CTL","CTRL"),"ESCAPE","ESC"),"RETURN","ENTER"),"PAGEDOWN","PGDN"),"PGDOWN","PGDN"),"PAGEUP","PGUP"),"ARROWKEYS","ARROW"),"ARROWKEY","ARROW"),"ARROWS","ARROW"),"DOWNARROW","DOWN"),"UPARROW","UP"),"LEFTARROW","LEFT"),"RIGHTARROW","RIGHT"),"ARROWDOWN","DOWN"),"ARROWUP","UP"),"ARROWLEFT","LEFT"),"ARROWRIGHT","RIGHT"),"↓","DOWN"),"↑","UP"),"←","LEFT"),"→","RIGHT"),"SPACEBAR","SPACE"),"−","-"),"MINUS","-"),"PLUS","+")=Key!$E$21:$H$21),"✔ CLEAR","✘ TRY AGAIN"))),"✘ TRY AGAIN")} | G24: {=IF(F24="","",IF(LEFT(F24,1)="✔",MIN(IF(H24="",1,H24)+1,5),1))} | J24: {=IF(OR(H24="",I24=""),"",IFERROR(I24+CHOOSE(H24,1,3,7,14,30),""))} | K24: {=IF(H24="","NEW",IF(J24="","DUE",IF(J24<=TODAY(),"DUE","in "&(J24-TODAY())&IF(J24-TODAY()=1," day"," days"))))} -> NEW
A25: 21 | B25: F1 | C25: F1-2 Big Six | D25: Which function adds up a range of numbers? | F25: {=IFERROR(_xlfn.LET(_xlpm.a,Deck!$E$25,IF(TRIM(_xlpm.a&"")="","",IF(OR(SUBSTITUTE(SUBSTITUTE(SUBSTITUTE(SUBSTITUTE(SUBSTITUTE(SUBSTITUTE(SUBSTITUTE(SUBSTITUTE(SUBSTITUTE(SUBSTITUTE(SUBSTITUTE(SUBSTITUTE(SUBSTITUTE(SUBSTITUTE(SUBSTITUTE(SUBSTITUTE(SUBSTITUTE(SUBSTITUTE(SUBSTITUTE(SUBSTITUTE(SUBSTITUTE(SUBSTITUTE(SUBSTITUTE(SUBSTITUTE(SUBSTITUTE(SUBSTITUTE(SUBSTITUTE(UPPER(_xlpm.a)," ",""),"CONTROL","CTRL"),"CTL","CTRL"),"ESCAPE","ESC"),"RETURN","ENTER"),"PAGEDOWN","PGDN"),"PGDOWN","PGDN"),"PAGEUP","PGUP"),"ARROWKEYS","ARROW"),"ARROWKEY","ARROW"),"ARROWS","ARROW"),"DOWNARROW","DOWN"),"UPARROW","UP"),"LEFTARROW","LEFT"),"RIGHTARROW","RIGHT"),"ARROWDOWN","DOWN"),"ARROWUP","UP"),"ARROWLEFT","LEFT"),"ARROWRIGHT","RIGHT"),"↓","DOWN"),"↑","UP"),"←","LEFT"),"→","RIGHT"),"SPACEBAR","SPACE"),"−","-"),"MINUS","-"),"PLUS","+")=Key!$E$22:$J$22),"✔ CLEAR","✘ TRY AGAIN"))),"✘ TRY AGAIN")} | G25: {=IF(F25="","",IF(LEFT(F25,1)="✔",MIN(IF(H25="",1,H25)+1,5),1))} | J25: {=IF(OR(H25="",I25=""),"",IFERROR(I25+CHOOSE(H25,1,3,7,14,30),""))} | K25: {=IF(H25="","NEW",IF(J25="","DUE",IF(J25<=TODAY(),"DUE","in "&(J25-TODAY())&IF(J25-TODAY()=1," day"," days"))))} -> NEW
A26: 22 | B26: F1 | C26: F1-2 Big Six | D26: Which function returns the mean of a range? | F26: {=IFERROR(_xlfn.LET(_xlpm.a,Deck!$E$26,IF(TRIM(_xlpm.a&"")="","",IF(OR(SUBSTITUTE(SUBSTITUTE(SUBSTITUTE(SUBSTITUTE(SUBSTITUTE(SUBSTITUTE(SUBSTITUTE(SUBSTITUTE(SUBSTITUTE(SUBSTITUTE(SUBSTITUTE(SUBSTITUTE(SUBSTITUTE(SUBSTITUTE(SUBSTITUTE(SUBSTITUTE(SUBSTITUTE(SUBSTITUTE(SUBSTITUTE(SUBSTITUTE(SUBSTITUTE(SUBSTITUTE(SUBSTITUTE(SUBSTITUTE(SUBSTITUTE(SUBSTITUTE(SUBSTITUTE(UPPER(_xlpm.a)," ",""),"CONTROL","CTRL"),"CTL","CTRL"),"ESCAPE","ESC"),"RETURN","ENTER"),"PAGEDOWN","PGDN"),"PGDOWN","PGDN"),"PAGEUP","PGUP"),"ARROWKEYS","ARROW"),"ARROWKEY","ARROW"),"ARROWS","ARROW"),"DOWNARROW","DOWN"),"UPARROW","UP"),"LEFTARROW","LEFT"),"RIGHTARROW","RIGHT"),"ARROWDOWN","DOWN"),"ARROWUP","UP"),"ARROWLEFT","LEFT"),"ARROWRIGHT","RIGHT"),"↓","DOWN"),"↑","UP"),"←","LEFT"),"→","RIGHT"),"SPACEBAR","SPACE"),"−","-"),"MINUS","-"),"PLUS","+")=Key!$E$23:$J$23),"✔ CLEAR","✘ TRY AGAIN"))),"✘ TRY AGAIN")} | G26: {=IF(F26="","",IF(LEFT(F26,1)="✔",MIN(IF(H26="",1,H26)+1,5),1))} | J26: {=IF(OR(H26="",I26=""),"",IFERROR(I26+CHOOSE(H26,1,3,7,14,30),""))} | K26: {=IF(H26="","NEW",IF(J26="","DUE",IF(J26<=TODAY(),"DUE","in "&(J26-TODAY())&IF(J26-TODAY()=1," day"," days"))))} -> NEW
A27: 23 | B27: F1 | C27: F1-2 Big Six | D27: Which function returns the largest number in a range? | F27: {=IFERROR(_xlfn.LET(_xlpm.a,Deck!$E$27,IF(TRIM(_xlpm.a&"")="","",IF(OR(SUBSTITUTE(SUBSTITUTE(SUBSTITUTE(SUBSTITUTE(SUBSTITUTE(SUBSTITUTE(SUBSTITUTE(SUBSTITUTE(SUBSTITUTE(SUBSTITUTE(SUBSTITUTE(SUBSTITUTE(SUBSTITUTE(SUBSTITUTE(SUBSTITUTE(SUBSTITUTE(SUBSTITUTE(SUBSTITUTE(SUBSTITUTE(SUBSTITUTE(SUBSTITUTE(SUBSTITUTE(SUBSTITUTE(SUBSTITUTE(SUBSTITUTE(SUBSTITUTE(SUBSTITUTE(UPPER(_xlpm.a)," ",""),"CONTROL","CTRL"),"CTL","CTRL"),"ESCAPE","ESC"),"RETURN","ENTER"),"PAGEDOWN","PGDN"),"PGDOWN","PGDN"),"PAGEUP","PGUP"),"ARROWKEYS","ARROW"),"ARROWKEY","ARROW"),"ARROWS","ARROW"),"DOWNARROW","DOWN"),"UPARROW","UP"),"LEFTARROW","LEFT"),"RIGHTARROW","RIGHT"),"ARROWDOWN","DOWN"),"ARROWUP","UP"),"ARROWLEFT","LEFT"),"ARROWRIGHT","RIGHT"),"↓","DOWN"),"↑","UP"),"←","LEFT"),"→","RIGHT"),"SPACEBAR","SPACE"),"−","-"),"MINUS","-"),"PLUS","+")=Key!$E$24:$J$24),"✔ CLEAR","✘ TRY AGAIN"))),"✘ TRY AGAIN")} | G27: {=IF(F27="","",IF(LEFT(F27,1)="✔",MIN(IF(H27="",1,H27)+1,5),1))} | J27: {=IF(OR(H27="",I27=""),"",IFERROR(I27+CHOOSE(H27,1,3,7,14,30),""))} | K27: {=IF(H27="","NEW",IF(J27="","DUE",IF(J27<=TODAY(),"DUE","in "&(J27-TODAY())&IF(J27-TODAY()=1," day"," days"))))} -> NEW
A28: 24 | B28: F1 | C28: F1-2 Big Six | D28: Which function returns the smallest number in a range? | F28: {=IFERROR(_xlfn.LET(_xlpm.a,Deck!$E$28,IF(TRIM(_xlpm.a&"")="","",IF(OR(SUBSTITUTE(SUBSTITUTE(SUBSTITUTE(SUBSTITUTE(SUBSTITUTE(SUBSTITUTE(SUBSTITUTE(SUBSTITUTE(SUBSTITUTE(SUBSTITUTE(SUBSTITUTE(SUBSTITUTE(SUBSTITUTE(SUBSTITUTE(SUBSTITUTE(SUBSTITUTE(SUBSTITUTE(SUBSTITUTE(SUBSTITUTE(SUBSTITUTE(SUBSTITUTE(SUBSTITUTE(SUBSTITUTE(SUBSTITUTE(SUBSTITUTE(SUBSTITUTE(SUBSTITUTE(UPPER(_xlpm.a)," ",""),"CONTROL","CTRL"),"CTL","CTRL"),"ESCAPE","ESC"),"RETURN","ENTER"),"PAGEDOWN","PGDN"),"PGDOWN","PGDN"),"PAGEUP","PGUP"),"ARROWKEYS","ARROW"),"ARROWKEY","ARROW"),"ARROWS","ARROW"),"DOWNARROW","DOWN"),"UPARROW","UP"),"LEFTARROW","LEFT"),"RIGHTARROW","RIGHT"),"ARROWDOWN","DOWN"),"ARROWUP","UP"),"ARROWLEFT","LEFT"),"ARROWRIGHT","RIGHT"),"↓","DOWN"),"↑","UP"),"←","LEFT"),"→","RIGHT"),"SPACEBAR","SPACE"),"−","-"),"MINUS","-"),"PLUS","+")=Key!$E$25:$J$25),"✔ CLEAR","✘ TRY AGAIN"))),"✘ TRY AGAIN")} | G28: {=IF(F28="","",IF(LEFT(F28,1)="✔",MIN(IF(H28="",1,H28)+1,5),1))} | J28: {=IF(OR(H28="",I28=""),"",IFERROR(I28+CHOOSE(H28,1,3,7,14,30),""))} | K28: {=IF(H28="","NEW",IF(J28="","DUE",IF(J28<=TODAY(),"DUE","in "&(J28-TODAY())&IF(J28-TODAY()=1," day"," days"))))} -> NEW
A29: 25 | B29: F1 | C29: F1-2 Big Six | D29: Which function counts only the cells that hold numbers? | F29: {=IFERROR(_xlfn.LET(_xlpm.a,Deck!$E$29,IF(TRIM(_xlpm.a&"")="","",IF(OR(SUBSTITUTE(SUBSTITUTE(SUBSTITUTE(SUBSTITUTE(SUBSTITUTE(SUBSTITUTE(SUBSTITUTE(SUBSTITUTE(SUBSTITUTE(SUBSTITUTE(SUBSTITUTE(SUBSTITUTE(SUBSTITUTE(SUBSTITUTE(SUBSTITUTE(SUBSTITUTE(SUBSTITUTE(SUBSTITUTE(SUBSTITUTE(SUBSTITUTE(SUBSTITUTE(SUBSTITUTE(SUBSTITUTE(SUBSTITUTE(SUBSTITUTE(SUBSTITUTE(SUBSTITUTE(UPPER(_xlpm.a)," ",""),"CONTROL","CTRL"),"CTL","CTRL"),"ESCAPE","ESC"),"RETURN","ENTER"),"PAGEDOWN","PGDN"),"PGDOWN","PGDN"),"PAGEUP","PGUP"),"ARROWKEYS","ARROW"),"ARROWKEY","ARROW"),"ARROWS","ARROW"),"DOWNARROW","DOWN"),"UPARROW","UP"),"LEFTARROW","LEFT"),"RIGHTARROW","RIGHT"),"ARROWDOWN","DOWN"),"ARROWUP","UP"),"ARROWLEFT","LEFT"),"ARROWRIGHT","RIGHT"),"↓","DOWN"),"↑","UP"),"←","LEFT"),"→","RIGHT"),"SPACEBAR","SPACE"),"−","-"),"MINUS","-"),"PLUS","+")=Key!$E$26:$J$26),"✔ CLEAR","✘ TRY AGAIN"))),"✘ TRY AGAIN")} | G29: {=IF(F29="","",IF(LEFT(F29,1)="✔",MIN(IF(H29="",1,H29)+1,5),1))} | J29: {=IF(OR(H29="",I29=""),"",IFERROR(I29+CHOOSE(H29,1,3,7,14,30),""))} | K29: {=IF(H29="","NEW",IF(J29="","DUE",IF(J29<=TODAY(),"DUE","in "&(J29-TODAY())&IF(J29-TODAY()=1," day"," days"))))} -> NEW
A30: 26 | B30: F1 | C30: F1-2 Big Six | D30: Which function counts every non-empty cell? | F30: {=IFERROR(_xlfn.LET(_xlpm.a,Deck!$E$30,IF(TRIM(_xlpm.a&"")="","",IF(OR(SUBSTITUTE(SUBSTITUTE(SUBSTITUTE(SUBSTITUTE(SUBSTITUTE(SUBSTITUTE(SUBSTITUTE(SUBSTITUTE(SUBSTITUTE(SUBSTITUTE(SUBSTITUTE(SUBSTITUTE(SUBSTITUTE(SUBSTITUTE(SUBSTITUTE(SUBSTITUTE(SUBSTITUTE(SUBSTITUTE(SUBSTITUTE(SUBSTITUTE(SUBSTITUTE(SUBSTITUTE(SUBSTITUTE(SUBSTITUTE(SUBSTITUTE(SUBSTITUTE(SUBSTITUTE(UPPER(_xlpm.a)," ",""),"CONTROL","CTRL"),"CTL","CTRL"),"ESCAPE","ESC"),"RETURN","ENTER"),"PAGEDOWN","PGDN"),"PGDOWN","PGDN"),"PAGEUP","PGUP"),"ARROWKEYS","ARROW"),"ARROWKEY","ARROW"),"ARROWS","ARROW"),"DOWNARROW","DOWN"),"UPARROW","UP"),"LEFTARROW","LEFT"),"RIGHTARROW","RIGHT"),"ARROWDOWN","DOWN"),"ARROWUP","UP"),"ARROWLEFT","LEFT"),"ARROWRIGHT","RIGHT"),"↓","DOWN"),"↑","UP"),"←","LEFT"),"→","RIGHT"),"SPACEBAR","SPACE"),"−","-"),"MINUS","-"),"PLUS","+")=Key!$E$27:$J$27),"✔ CLEAR","✘ TRY AGAIN"))),"✘ TRY AGAIN")} | G30: {=IF(F30="","",IF(LEFT(F30,1)="✔",MIN(IF(H30="",1,H30)+1,5),1))} | J30: {=IF(OR(H30="",I30=""),"",IFERROR(I30+CHOOSE(H30,1,3,7,14,30),""))} | K30: {=IF(H30="","NEW",IF(J30="","DUE",IF(J30<=TODAY(),"DUE","in "&(J30-TODAY())&IF(J30-TODAY()=1," day"," days"))))} -> NEW
A31: 27 | B31: F1 | C31: F1-2 Big Six | D31: Which keys insert an AutoSum formula? | F31: {=IFERROR(_xlfn.LET(_xlpm.a,Deck!$E$31,IF(TRIM(_xlpm.a&"")="","",IF(OR(SUBSTITUTE(SUBSTITUTE(SUBSTITUTE(SUBSTITUTE(SUBSTITUTE(SUBSTITUTE(SUBSTITUTE(SUBSTITUTE(SUBSTITUTE(SUBSTITUTE(SUBSTITUTE(SUBSTITUTE(SUBSTITUTE(SUBSTITUTE(SUBSTITUTE(SUBSTITUTE(SUBSTITUTE(SUBSTITUTE(SUBSTITUTE(SUBSTITUTE(SUBSTITUTE(SUBSTITUTE(SUBSTITUTE(SUBSTITUTE(SUBSTITUTE(SUBSTITUTE(SUBSTITUTE(UPPER(_xlpm.a)," ",""),"CONTROL","CTRL"),"CTL","CTRL"),"ESCAPE","ESC"),"RETURN","ENTER"),"PAGEDOWN","PGDN"),"PGDOWN","PGDN"),"PAGEUP","PGUP"),"ARROWKEYS","ARROW"),"ARROWKEY","ARROW"),"ARROWS","ARROW"),"DOWNARROW","DOWN"),"UPARROW","UP"),"LEFTARROW","LEFT"),"RIGHTARROW","RIGHT"),"ARROWDOWN","DOWN"),"ARROWUP","UP"),"ARROWLEFT","LEFT"),"ARROWRIGHT","RIGHT"),"↓","DOWN"),"↑","UP"),"←","LEFT"),"→","RIGHT"),"SPACEBAR","SPACE"),"−","-"),"MINUS","-"),"PLUS","+")=Key!$E$28:$E$28),"✔ CLEAR","✘ TRY AGAIN"))),"✘ TRY AGAIN")} | G31: {=IF(F31="","",IF(LEFT(F31,1)="✔",MIN(IF(H31="",1,H31)+1,5),1))} | J31: {=IF(OR(H31="",I31=""),"",IFERROR(I31+CHOOSE(H31,1,3,7,14,30),""))} | K31: {=IF(H31="","NEW",IF(J31="","DUE",IF(J31<=TODAY(),"DUE","in "&(J31-TODAY())&IF(J31-TODAY()=1," day"," days"))))} -> NEW
A32: 28 | B32: F1 | C32: F1-3 Anchors | D32: Type the absolute version of the reference E6. | F32: {=IFERROR(_xlfn.LET(_xlpm.a,Deck!$E$32,IF(TRIM(_xlpm.a&"")="","",IF(OR(SUBSTITUTE(SUBSTITUTE(SUBSTITUTE(SUBSTITUTE(SUBSTITUTE(SUBSTITUTE(SUBSTITUTE(SUBSTITUTE(SUBSTITUTE(SUBSTITUTE(SUBSTITUTE(SUBSTITUTE(SUBSTITUTE(SUBSTITUTE(SUBSTITUTE(SUBSTITUTE(SUBSTITUTE(SUBSTITUTE(SUBSTITUTE(SUBSTITUTE(SUBSTITUTE(SUBSTITUTE(SUBSTITUTE(SUBSTITUTE(SUBSTITUTE(SUBSTITUTE(SUBSTITUTE(UPPER(_xlpm.a)," ",""),"CONTROL","CTRL"),"CTL","CTRL"),"ESCAPE","ESC"),"RETURN","ENTER"),"PAGEDOWN","PGDN"),"PGDOWN","PGDN"),"PAGEUP","PGUP"),"ARROWKEYS","ARROW"),"ARROWKEY","ARROW"),"ARROWS","ARROW"),"DOWNARROW","DOWN"),"UPARROW","UP"),"LEFTARROW","LEFT"),"RIGHTARROW","RIGHT"),"ARROWDOWN","DOWN"),"ARROWUP","UP"),"ARROWLEFT","LEFT"),"ARROWRIGHT","RIGHT"),"↓","DOWN"),"↑","UP"),"←","LEFT"),"→","RIGHT"),"SPACEBAR","SPACE"),"−","-"),"MINUS","-"),"PLUS","+")=Key!$E$29:$E$29),"✔ CLEAR","✘ TRY AGAIN"))),"✘ TRY AGAIN")} | G32: {=IF(F32="","",IF(LEFT(F32,1)="✔",MIN(IF(H32="",1,H32)+1,5),1))} | J32: {=IF(OR(H32="",I32=""),"",IFERROR(I32+CHOOSE(H32,1,3,7,14,30),""))} | K32: {=IF(H32="","NEW",IF(J32="","DUE",IF(J32<=TODAY(),"DUE","in "&(J32-TODAY())&IF(J32-TODAY()=1," day"," days"))))} -> NEW
A33: 29 | B33: F1 | C33: F1-3 Anchors | D33: Type a reference to C16 that locks only the row. | F33: {=IFERROR(_xlfn.LET(_xlpm.a,Deck!$E$33,IF(TRIM(_xlpm.a&"")="","",IF(OR(SUBSTITUTE(SUBSTITUTE(SUBSTITUTE(SUBSTITUTE(SUBSTITUTE(SUBSTITUTE(SUBSTITUTE(SUBSTITUTE(SUBSTITUTE(SUBSTITUTE(SUBSTITUTE(SUBSTITUTE(SUBSTITUTE(SUBSTITUTE(SUBSTITUTE(SUBSTITUTE(SUBSTITUTE(SUBSTITUTE(SUBSTITUTE(SUBSTITUTE(SUBSTITUTE(SUBSTITUTE(SUBSTITUTE(SUBSTITUTE(SUBSTITUTE(SUBSTITUTE(SUBSTITUTE(UPPER(_xlpm.a)," ",""),"CONTROL","CTRL"),"CTL","CTRL"),"ESCAPE","ESC"),"RETURN","ENTER"),"PAGEDOWN","PGDN"),"PGDOWN","PGDN"),"PAGEUP","PGUP"),"ARROWKEYS","ARROW"),"ARROWKEY","ARROW"),"ARROWS","ARROW"),"DOWNARROW","DOWN"),"UPARROW","UP"),"LEFTARROW","LEFT"),"RIGHTARROW","RIGHT"),"ARROWDOWN","DOWN"),"ARROWUP","UP"),"ARROWLEFT","LEFT"),"ARROWRIGHT","RIGHT"),"↓","DOWN"),"↑","UP"),"←","LEFT"),"→","RIGHT"),"SPACEBAR","SPACE"),"−","-"),"MINUS","-"),"PLUS","+")=Key!$E$30:$E$30),"✔ CLEAR","✘ TRY AGAIN"))),"✘ TRY AGAIN")} | G33: {=IF(F33="","",IF(LEFT(F33,1)="✔",MIN(IF(H33="",1,H33)+1,5),1))} | J33: {=IF(OR(H33="",I33=""),"",IFERROR(I33+CHOOSE(H33,1,3,7,14,30),""))} | K33: {=IF(H33="","NEW",IF(J33="","DUE",IF(J33<=TODAY(),"DUE","in "&(J33-TODAY())&IF(J33-TODAY()=1," day"," days"))))} -> NEW
A34: 30 | B34: F1 | C34: F1-3 Anchors | D34: Which key adds or cycles the $ signs on a reference you are editing? | F34: {=IFERROR(_xlfn.LET(_xlpm.a,Deck!$E$34,IF(TRIM(_xlpm.a&"")="","",IF(OR(SUBSTITUTE(SUBSTITUTE(SUBSTITUTE(SUBSTITUTE(SUBSTITUTE(SUBSTITUTE(SUBSTITUTE(SUBSTITUTE(SUBSTITUTE(SUBSTITUTE(SUBSTITUTE(SUBSTITUTE(SUBSTITUTE(SUBSTITUTE(SUBSTITUTE(SUBSTITUTE(SUBSTITUTE(SUBSTITUTE(SUBSTITUTE(SUBSTITUTE(SUBSTITUTE(SUBSTITUTE(SUBSTITUTE(SUBSTITUTE(SUBSTITUTE(SUBSTITUTE(SUBSTITUTE(UPPER(_xlpm.a)," ",""),"CONTROL","CTRL"),"CTL","CTRL"),"ESCAPE","ESC"),"RETURN","ENTER"),"PAGEDOWN","PGDN"),"PGDOWN","PGDN"),"PAGEUP","PGUP"),"ARROWKEYS","ARROW"),"ARROWKEY","ARROW"),"ARROWS","ARROW"),"DOWNARROW","DOWN"),"UPARROW","UP"),"LEFTARROW","LEFT"),"RIGHTARROW","RIGHT"),"ARROWDOWN","DOWN"),"ARROWUP","UP"),"ARROWLEFT","LEFT"),"ARROWRIGHT","RIGHT"),"↓","DOWN"),"↑","UP"),"←","LEFT"),"→","RIGHT"),"SPACEBAR","SPACE"),"−","-"),"MINUS","-"),"PLUS","+")=Key!$E$31:$E$31),"✔ CLEAR","✘ TRY AGAIN"))),"✘ TRY AGAIN")} | G34: {=IF(F34="","",IF(LEFT(F34,1)="✔",MIN(IF(H34="",1,H34)+1,5),1))} | J34: {=IF(OR(H34="",I34=""),"",IFERROR(I34+CHOOSE(H34,1,3,7,14,30),""))} | K34: {=IF(H34="","NEW",IF(J34="","DUE",IF(J34<=TODAY(),"DUE","in "&(J34-TODAY())&IF(J34-TODAY()=1," day"," days"))))} -> NEW
A35: 31 | B35: F1 | C35: F1-3 Anchors | D35: Which keys copy the top cell down into the selected cells? | F35: {=IFERROR(_xlfn.LET(_xlpm.a,Deck!$E$35,IF(TRIM(_xlpm.a&"")="","",IF(OR(SUBSTITUTE(SUBSTITUTE(SUBSTITUTE(SUBSTITUTE(SUBSTITUTE(SUBSTITUTE(SUBSTITUTE(SUBSTITUTE(SUBSTITUTE(SUBSTITUTE(SUBSTITUTE(SUBSTITUTE(SUBSTITUTE(SUBSTITUTE(SUBSTITUTE(SUBSTITUTE(SUBSTITUTE(SUBSTITUTE(SUBSTITUTE(SUBSTITUTE(SUBSTITUTE(SUBSTITUTE(SUBSTITUTE(SUBSTITUTE(SUBSTITUTE(SUBSTITUTE(SUBSTITUTE(UPPER(_xlpm.a)," ",""),"CONTROL","CTRL"),"CTL","CTRL"),"ESCAPE","ESC"),"RETURN","ENTER"),"PAGEDOWN","PGDN"),"PGDOWN","PGDN"),"PAGEUP","PGUP"),"ARROWKEYS","ARROW"),"ARROWKEY","ARROW"),"ARROWS","ARROW"),"DOWNARROW","DOWN"),"UPARROW","UP"),"LEFTARROW","LEFT"),"RIGHTARROW","RIGHT"),"ARROWDOWN","DOWN"),"ARROWUP","UP"),"ARROWLEFT","LEFT"),"ARROWRIGHT","RIGHT"),"↓","DOWN"),"↑","UP"),"←","LEFT"),"→","RIGHT"),"SPACEBAR","SPACE"),"−","-"),"MINUS","-"),"PLUS","+")=Key!$E$32:$E$32),"✔ CLEAR","✘ TRY AGAIN"))),"✘ TRY AGAIN")} | G35: {=IF(F35="","",IF(LEFT(F35,1)="✔",MIN(IF(H35="",1,H35)+1,5),1))} | J35: {=IF(OR(H35="",I35=""),"",IFERROR(I35+CHOOSE(H35,1,3,7,14,30),""))} | K35: {=IF(H35="","NEW",IF(J35="","DUE",IF(J35<=TODAY(),"DUE","in "&(J35-TODAY())&IF(J35-TODAY()=1," day"," days"))))} -> NEW
A36: 32 | B36: F1 | C36: F1-4 Precision | D36: Which function rounds a number to a chosen number of digits? | F36: {=IFERROR(_xlfn.LET(_xlpm.a,Deck!$E$36,IF(TRIM(_xlpm.a&"")="","",IF(OR(SUBSTITUTE(SUBSTITUTE(SUBSTITUTE(SUBSTITUTE(SUBSTITUTE(SUBSTITUTE(SUBSTITUTE(SUBSTITUTE(SUBSTITUTE(SUBSTITUTE(SUBSTITUTE(SUBSTITUTE(SUBSTITUTE(SUBSTITUTE(SUBSTITUTE(SUBSTITUTE(SUBSTITUTE(SUBSTITUTE(SUBSTITUTE(SUBSTITUTE(SUBSTITUTE(SUBSTITUTE(SUBSTITUTE(SUBSTITUTE(SUBSTITUTE(SUBSTITUTE(SUBSTITUTE(UPPER(_xlpm.a)," ",""),"CONTROL","CTRL"),"CTL","CTRL"),"ESCAPE","ESC"),"RETURN","ENTER"),"PAGEDOWN","PGDN"),"PGDOWN","PGDN"),"PAGEUP","PGUP"),"ARROWKEYS","ARROW"),"ARROWKEY","ARROW"),"ARROWS","ARROW"),"DOWNARROW","DOWN"),"UPARROW","UP"),"LEFTARROW","LEFT"),"RIGHTARROW","RIGHT"),"ARROWDOWN","DOWN"),"ARROWUP","UP"),"ARROWLEFT","LEFT"),"ARROWRIGHT","RIGHT"),"↓","DOWN"),"↑","UP"),"←","LEFT"),"→","RIGHT"),"SPACEBAR","SPACE"),"−","-"),"MINUS","-"),"PLUS","+")=Key!$E$33:$J$33),"✔ CLEAR","✘ TRY AGAIN"))),"✘ TRY AGAIN")} | G36: {=IF(F36="","",IF(LEFT(F36,1)="✔",MIN(IF(H36="",1,H36)+1,5),1))} | J36: {=IF(OR(H36="",I36=""),"",IFERROR(I36+CHOOSE(H36,1,3,7,14,30),""))} | K36: {=IF(H36="","NEW",IF(J36="","DUE",IF(J36<=TODAY(),"DUE","in "&(J36-TODAY())&IF(J36-TODAY()=1," day"," days"))))} -> NEW
A37: 33 | B37: F1 | C37: F1-4 Precision | D37: Which function always rounds up, away from zero? | F37: {=IFERROR(_xlfn.LET(_xlpm.a,Deck!$E$37,IF(TRIM(_xlpm.a&"")="","",IF(OR(SUBSTITUTE(SUBSTITUTE(SUBSTITUTE(SUBSTITUTE(SUBSTITUTE(SUBSTITUTE(SUBSTITUTE(SUBSTITUTE(SUBSTITUTE(SUBSTITUTE(SUBSTITUTE(SUBSTITUTE(SUBSTITUTE(SUBSTITUTE(SUBSTITUTE(SUBSTITUTE(SUBSTITUTE(SUBSTITUTE(SUBSTITUTE(SUBSTITUTE(SUBSTITUTE(SUBSTITUTE(SUBSTITUTE(SUBSTITUTE(SUBSTITUTE(SUBSTITUTE(SUBSTITUTE(UPPER(_xlpm.a)," ",""),"CONTROL","CTRL"),"CTL","CTRL"),"ESCAPE","ESC"),"RETURN","ENTER"),"PAGEDOWN","PGDN"),"PGDOWN","PGDN"),"PAGEUP","PGUP"),"ARROWKEYS","ARROW"),"ARROWKEY","ARROW"),"ARROWS","ARROW"),"DOWNARROW","DOWN"),"UPARROW","UP"),"LEFTARROW","LEFT"),"RIGHTARROW","RIGHT"),"ARROWDOWN","DOWN"),"ARROWUP","UP"),"ARROWLEFT","LEFT"),"ARROWRIGHT","RIGHT"),"↓","DOWN"),"↑","UP"),"←","LEFT"),"→","RIGHT"),"SPACEBAR","SPACE"),"−","-"),"MINUS","-"),"PLUS","+")=Key!$E$34:$J$34),"✔ CLEAR","✘ TRY AGAIN"))),"✘ TRY AGAIN")} | G37: {=IF(F37="","",IF(LEFT(F37,1)="✔",MIN(IF(H37="",1,H37)+1,5),1))} | J37: {=IF(OR(H37="",I37=""),"",IFERROR(I37+CHOOSE(H37,1,3,7,14,30),""))} | K37: {=IF(H37="","NEW",IF(J37="","DUE",IF(J37<=TODAY(),"DUE","in "&(J37-TODAY())&IF(J37-TODAY()=1," day"," days"))))} -> NEW
A38: 34 | B38: F1 | C38: F1-4 Precision | D38: Which function always rounds down, toward zero? | F38: {=IFERROR(_xlfn.LET(_xlpm.a,Deck!$E$38,IF(TRIM(_xlpm.a&"")="","",IF(OR(SUBSTITUTE(SUBSTITUTE(SUBSTITUTE(SUBSTITUTE(SUBSTITUTE(SUBSTITUTE(SUBSTITUTE(SUBSTITUTE(SUBSTITUTE(SUBSTITUTE(SUBSTITUTE(SUBSTITUTE(SUBSTITUTE(SUBSTITUTE(SUBSTITUTE(SUBSTITUTE(SUBSTITUTE(SUBSTITUTE(SUBSTITUTE(SUBSTITUTE(SUBSTITUTE(SUBSTITUTE(SUBSTITUTE(SUBSTITUTE(SUBSTITUTE(SUBSTITUTE(SUBSTITUTE(UPPER(_xlpm.a)," ",""),"CONTROL","CTRL"),"CTL","CTRL"),"ESCAPE","ESC"),"RETURN","ENTER"),"PAGEDOWN","PGDN"),"PGDOWN","PGDN"),"PAGEUP","PGUP"),"ARROWKEYS","ARROW"),"ARROWKEY","ARROW"),"ARROWS","ARROW"),"DOWNARROW","DOWN"),"UPARROW","UP"),"LEFTARROW","LEFT"),"RIGHTARROW","RIGHT"),"ARROWDOWN","DOWN"),"ARROWUP","UP"),"ARROWLEFT","LEFT"),"ARROWRIGHT","RIGHT"),"↓","DOWN"),"↑","UP"),"←","LEFT"),"→","RIGHT"),"SPACEBAR","SPACE"),"−","-"),"MINUS","-"),"PLUS","+")=Key!$E$35:$J$35),"✔ CLEAR","✘ TRY AGAIN"))),"✘ TRY AGAIN")} | G38: {=IF(F38="","",IF(LEFT(F38,1)="✔",MIN(IF(H38="",1,H38)+1,5),1))} | J38: {=IF(OR(H38="",I38=""),"",IFERROR(I38+CHOOSE(H38,1,3,7,14,30),""))} | K38: {=IF(H38="","NEW",IF(J38="","DUE",IF(J38<=TODAY(),"DUE","in "&(J38-TODAY())&IF(J38-TODAY()=1," day"," days"))))} -> NEW
A39: 35 | B39: F1 | C39: F1-5 X-Ray | D39: Which keys switch between showing results and showing formulas? | F39: {=IFERROR(_xlfn.LET(_xlpm.a,Deck!$E$39,IF(TRIM(_xlpm.a&"")="","",IF(OR(SUBSTITUTE(SUBSTITUTE(SUBSTITUTE(SUBSTITUTE(SUBSTITUTE(SUBSTITUTE(SUBSTITUTE(SUBSTITUTE(SUBSTITUTE(SUBSTITUTE(SUBSTITUTE(SUBSTITUTE(SUBSTITUTE(SUBSTITUTE(SUBSTITUTE(SUBSTITUTE(SUBSTITUTE(SUBSTITUTE(SUBSTITUTE(SUBSTITUTE(SUBSTITUTE(SUBSTITUTE(SUBSTITUTE(SUBSTITUTE(SUBSTITUTE(SUBSTITUTE(SUBSTITUTE(UPPER(_xlpm.a)," ",""),"CONTROL","CTRL"),"CTL","CTRL"),"ESCAPE","ESC"),"RETURN","ENTER"),"PAGEDOWN","PGDN"),"PGDOWN","PGDN"),"PAGEUP","PGUP"),"ARROWKEYS","ARROW"),"ARROWKEY","ARROW"),"ARROWS","ARROW"),"DOWNARROW","DOWN"),"UPARROW","UP"),"LEFTARROW","LEFT"),"RIGHTARROW","RIGHT"),"ARROWDOWN","DOWN"),"ARROWUP","UP"),"ARROWLEFT","LEFT"),"ARROWRIGHT","RIGHT"),"↓","DOWN"),"↑","UP"),"←","LEFT"),"→","RIGHT"),"SPACEBAR","SPACE"),"−","-"),"MINUS","-"),"PLUS","+")=Key!$E$36:$H$36),"✔ CLEAR","✘ TRY AGAIN"))),"✘ TRY AGAIN")} | G39: {=IF(F39="","",IF(LEFT(F39,1)="✔",MIN(IF(H39="",1,H39)+1,5),1))} | J39: {=IF(OR(H39="",I39=""),"",IFERROR(I39+CHOOSE(H39,1,3,7,14,30),""))} | K39: {=IF(H39="","NEW",IF(J39="","DUE",IF(J39<=TODAY(),"DUE","in "&(J39-TODAY())&IF(J39-TODAY()=1," day"," days"))))} -> NEW
A40: 36 | B40: F1 | C40: F1-5 X-Ray | D40: Which key edits the active cell and color-codes its references? | F40: {=IFERROR(_xlfn.LET(_xlpm.a,Deck!$E$40,IF(TRIM(_xlpm.a&"")="","",IF(OR(SUBSTITUTE(SUBSTITUTE(SUBSTITUTE(SUBSTITUTE(SUBSTITUTE(SUBSTITUTE(SUBSTITUTE(SUBSTITUTE(SUBSTITUTE(SUBSTITUTE(SUBSTITUTE(SUBSTITUTE(SUBSTITUTE(SUBSTITUTE(SUBSTITUTE(SUBSTITUTE(SUBSTITUTE(SUBSTITUTE(SUBSTITUTE(SUBSTITUTE(SUBSTITUTE(SUBSTITUTE(SUBSTITUTE(SUBSTITUTE(SUBSTITUTE(SUBSTITUTE(SUBSTITUTE(UPPER(_xlpm.a)," ",""),"CONTROL","CTRL"),"CTL","CTRL"),"ESCAPE","ESC"),"RETURN","ENTER"),"PAGEDOWN","PGDN"),"PGDOWN","PGDN"),"PAGEUP","PGUP"),"ARROWKEYS","ARROW"),"ARROWKEY","ARROW"),"ARROWS","ARROW"),"DOWNARROW","DOWN"),"UPARROW","UP"),"LEFTARROW","LEFT"),"RIGHTARROW","RIGHT"),"ARROWDOWN","DOWN"),"ARROWUP","UP"),"ARROWLEFT","LEFT"),"ARROWRIGHT","RIGHT"),"↓","DOWN"),"↑","UP"),"←","LEFT"),"→","RIGHT"),"SPACEBAR","SPACE"),"−","-"),"MINUS","-"),"PLUS","+")=Key!$E$37:$E$37),"✔ CLEAR","✘ TRY AGAIN"))),"✘ TRY AGAIN")} | G40: {=IF(F40="","",IF(LEFT(F40,1)="✔",MIN(IF(H40="",1,H40)+1,5),1))} | J40: {=IF(OR(H40="",I40=""),"",IFERROR(I40+CHOOSE(H40,1,3,7,14,30),""))} | K40: {=IF(H40="","NEW",IF(J40="","DUE",IF(J40<=TODAY(),"DUE","in "&(J40-TODAY())&IF(J40-TODAY()=1," day"," days"))))} -> NEW
A41: 37 | B41: F1 | C41: F1-5 X-Ray | D41: While typing a function name, which key inserts the highlighted AutoComplete suggestion? | F41: {=IFERROR(_xlfn.LET(_xlpm.a,Deck!$E$41,IF(TRIM(_xlpm.a&"")="","",IF(OR(SUBSTITUTE(SUBSTITUTE(SUBSTITUTE(SUBSTITUTE(SUBSTITUTE(SUBSTITUTE(SUBSTITUTE(SUBSTITUTE(SUBSTITUTE(SUBSTITUTE(SUBSTITUTE(SUBSTITUTE(SUBSTITUTE(SUBSTITUTE(SUBSTITUTE(SUBSTITUTE(SUBSTITUTE(SUBSTITUTE(SUBSTITUTE(SUBSTITUTE(SUBSTITUTE(SUBSTITUTE(SUBSTITUTE(SUBSTITUTE(SUBSTITUTE(SUBSTITUTE(SUBSTITUTE(UPPER(_xlpm.a)," ",""),"CONTROL","CTRL"),"CTL","CTRL"),"ESCAPE","ESC"),"RETURN","ENTER"),"PAGEDOWN","PGDN"),"PGDOWN","PGDN"),"PAGEUP","PGUP"),"ARROWKEYS","ARROW"),"ARROWKEY","ARROW"),"ARROWS","ARROW"),"DOWNARROW","DOWN"),"UPARROW","UP"),"LEFTARROW","LEFT"),"RIGHTARROW","RIGHT"),"ARROWDOWN","DOWN"),"ARROWUP","UP"),"ARROWLEFT","LEFT"),"ARROWRIGHT","RIGHT"),"↓","DOWN"),"↑","UP"),"←","LEFT"),"→","RIGHT"),"SPACEBAR","SPACE"),"−","-"),"MINUS","-"),"PLUS","+")=Key!$E$38:$E$38),"✔ CLEAR","✘ TRY AGAIN"))),"✘ TRY AGAIN")} | G41: {=IF(F41="","",IF(LEFT(F41,1)="✔",MIN(IF(H41="",1,H41)+1,5),1))} | J41: {=IF(OR(H41="",I41=""),"",IFERROR(I41+CHOOSE(H41,1,3,7,14,30),""))} | K41: {=IF(H41="","NEW",IF(J41="","DUE",IF(J41<=TODAY(),"DUE","in "&(J41-TODAY())&IF(J41-TODAY()=1," day"," days"))))} -> NEW
...

Sheet Key
A1: Challenge | B1: Hint | C1: Expected | E1: Lists / per-cell expectations →
A2: Deck 1 | B2: Hold Ctrl and tap an arrow key. | E2: CTRL+ARROW | F2: CTRL+DOWN | G2: CTRL+LEFT | H2: CTRL+RIGHT | I2: CTRL+UP
A3: Deck 2 | B3: Ctrl plus the key that means 'start'. | E3: CTRL+HOME
A4: Deck 3 | B4: Ctrl plus the opposite of Home. | E4: CTRL+END
A5: Deck 4 | B5: One key, no Ctrl. | E5: HOME
A6: Deck 5 | B6: A function key, or Ctrl plus G. | E6: CTRL+G | F6: F5
A7: Deck 6 | B7: Ctrl plus Page Down. | E7: CTRL+PGDN
A8: Deck 7 | B8: Ctrl plus Page Up. | E8: CTRL+PGUP
A9: Deck 8 | B9: Page Down. | E9: PGDN
A10: Deck 9 | B10: Alt plus Page Down. | E10: ALT+PGDN
A11: Deck 10 | B11: Hold Shift and tap an arrow. | E11: SHIFT+ARROW | F11: SHIFT+DOWN | G11: SHIFT+LEFT | H11: SHIFT+RIGHT | I11: SHIFT+UP
A12: Deck 11 | B12: The warp-zone keys plus Shift. | E12: CTRL+SHIFT+ARROW | F12: CTRL+SHIFT+DOWN | G12: CTRL+SHIFT+LEFT | H12: CTRL+SHIFT+RIGHT | I12: CTRL+SHIFT+UP | J12: SHIFT+CTRL+ARROW | K12: SHIFT+CTRL+DOWN | L12: SHIFT+CTRL+LEFT | M12: SHIFT+CTRL+RIGHT | N12: SHIFT+CTRL+UP
A13: Deck 12 | B13: Ctrl+End plus Shift. | E13: CTRL+SHIFT+END | F13: SHIFT+CTRL+END
A14: Deck 13 | B14: Ctrl+Home plus Shift. | E14: CTRL+SHIFT+HOME | F14: SHIFT+CTRL+HOME
A15: Deck 14 | B15: The long key plus Shift. | E15: SHIFT+SPACE
A16: Deck 15 | B16: The long key plus Ctrl. | E16: CTRL+SPACE
A17: Deck 16 | B17: Think 'A' for All. | E17: CTRL+A | F17: CTRL+SHIFT+SPACE | G17: SHIFT+CTRL+SPACE
A18: Deck 17 | B18: The key left of Backspace. | E18: = | F18: EQUALS | G18: EQUALSIGN | H18: EQUALSSIGN
A19: Deck 18 | B19: Shift+6 on a US keyboard. | E19: CARET | F19: ^
A20: Deck 19 | B20: Multiply before you add. | E20: 14
A21: Deck 20 | B21: Start with = then the two cell addresses. | E21: =B2*C2 | F21: =C2*B2 | G21: B2*C2 | H21: C2*B2
A22: Deck 21 | B22: Three letters. | E22: =SUM | F22: =SUM( | G22: =SUM() | H22: SUM | I22: SUM( | J22: SUM()
A23: Deck 22 | B23: Starts with AVER. | E23: =AVERAGE | F23: =AVERAGE( | G23: =AVERAGE() | H23: AVERAGE | I23: AVERAGE( | J23: AVERAGE()
A24: Deck 23 | B24: Short for maximum. | E24: =MAX | F24: =MAX( | G24: =MAX() | H24: MAX | I24: MAX( | J24: MAX()
A25: Deck 24 | B25: Short for minimum. | E25: =MIN | F25: =MIN( | G25: =MIN() | H25: MIN | I25: MIN( | J25: MIN()
A26: Deck 25 | B26: The plain counting function. | E26: =COUNT | F26: =COUNT( | G26: =COUNT() | H26: COUNT | I26: COUNT( | J26: COUNT()
A27: Deck 26 | B27: COUNT plus one letter. | E27: =COUNTA | F27: =COUNTA( | G27: =COUNTA() | H27: COUNTA | I27: COUNTA( | J27: COUNTA()
A28: Deck 27 | B28: Alt plus the equals key. | E28: ALT+=
A29: Deck 28 | B29: Put $ before the column and the row. | E29: $E$6
A30: Deck 29 | B30: The $ goes right before 16. | E30: C$16
A31: Deck 30 | B31: A function key between F3 and F5. | E31: F4
A32: Deck 31 | B32: D for Down. | E32: CTRL+D
A33: Deck 32 | B33: The plain rounding function. | E33: =ROUND | F33: =ROUND( | G33: =ROUND() | H33: ROUND | I33: ROUND( | J33: ROUND()
A34: Deck 33 | B34: ROUND plus a direction. | E34: =ROUNDUP | F34: =ROUNDUP( | G34: =ROUNDUP() | H34: ROUNDUP | I34: ROUNDUP( | J34: ROUNDUP()
A35: Deck 34 | B35: ROUND plus the other direction. | E35: =ROUNDDOWN | F35: =ROUNDDOWN( | G35: =ROUNDDOWN() | H35: ROUNDDOWN | I35: ROUNDDOWN( | J35: ROUNDDOWN()
A36: Deck 35 | B36: Ctrl plus the key left of 1. | E36: CTRL+BACKTICK | F36: CTRL+GRAVE | G36: CTRL+GRAVEACCENT | H36: CTRL+`
A37: Deck 36 | B37: The function key after F1. | E37: F2
A38: Deck 37 | B38: The key above Caps Lock. | E38: TAB
A39: Deck 38 | B39: Ctrl+Shift plus A for arguments. | E39: CTRL+SHIFT+A | F39: SHIFT+CTRL+A
A40: Deck 39 | B40: Shift plus F3. | E40: SHIFT+F3
...
