Workbook

Sheet Start
A1: SHORTCUTS 2 ▸ ENTER & EDIT
A2: Type, fill, copy and stamp data at speed.
A4: HOW TO PLAY
A5: 1 · Each stage: read the BRIEFING, then answer WARM-UP, TRAINING and CHALLENGES.
A6: 2 · Yellow cells are yours: type, pick from a list (Alt+↓), or follow a ▶ ARENA link and do the move there.
A7: 3 · ✔ CLEAR = right · ✘ = try again · · not yet = drill not done. Stuck? Pick 'Show hint' (5 XP instead of 10).
A8: 4 · Formatting or hiding drills: press F9 to refresh the check. Tab jumps between yellow cells.
A9: Needs Windows with Microsoft Excel 365 or 2021+ (English). In Protected View, click Enable Editing.
A11: STAGE SELECT
A12: Stage | B12: Name | C12: Score | D12: Stars | E12: Status | F12: Go
A13: S2-1 | B13: Quick Entry | C13: {=SUM('S2-1 Quick Entry'!$G$15:$G$45)&" / 240"} -> 0 / 240 | D13: {=IF(SUM('S2-1 Quick Entry'!$G$15:$G$45)>=240,"★★★",IF(SUM('S2-1 Quick Entry'!$G$15:$G$45)>=240*0.8,"★★☆",IF(SUM('S2-1 Quick Entry'!$G$15:$G$45)>=240*0.5,"★☆☆","☆☆☆")))} -> ☆☆☆ | E13: {=IF(SUM('S2-1 Quick Entry'!$G$15:$G$45)>=240,"PERFECT",IF(SUM('S2-1 Quick Entry'!$G$15:$G$45)>=240*0.5,"CLEARED",IF(SUM('S2-1 Quick Entry'!$G$15:$G$45)>0,"IN PROGRESS","NEW")))} -> NEW | F13: Go to S2-1 Quick Entry
A14: S2-2 | B14: Clone Machine | C14: {=SUM('S2-2 Clone Machine'!$G$17:$G$50)&" / 270"} -> 0 / 270 | D14: {=IF(SUM('S2-2 Clone Machine'!$G$17:$G$50)>=270,"★★★",IF(SUM('S2-2 Clone Machine'!$G$17:$G$50)>=270*0.8,"★★☆",IF(SUM('S2-2 Clone Machine'!$G$17:$G$50)>=270*0.5,"★☆☆","☆☆☆")))} -> ☆☆☆ | E14: {=IF(SUM('S2-2 Clone Machine'!$G$17:$G$50)>=270,"PERFECT",IF(SUM('S2-2 Clone Machine'!$G$17:$G$50)>=270*0.5,"CLEARED",IF(SUM('S2-2 Clone Machine'!$G$17:$G$50)>0,"IN PROGRESS","NEW")))} -> NEW | F14: Go to S2-2 Clone Machine
A15: S2-3 | B15: Stamps & Smart Fill | C15: {=SUM('S2-3 Stamps & Smart Fill'!$G$14:$G$42)&" / 220"} -> 0 / 220 | D15: {=IF(SUM('S2-3 Stamps & Smart Fill'!$G$14:$G$42)>=220,"★★★",IF(SUM('S2-3 Stamps & Smart Fill'!$G$14:$G$42)>=220*0.8,"★★☆",IF(SUM('S2-3 Stamps & Smart Fill'!$G$14:$G$42)>=220*0.5,"★☆☆","☆☆☆")))} -> ☆☆☆ | E15: {=IF(SUM('S2-3 Stamps & Smart Fill'!$G$14:$G$42)>=220,"PERFECT",IF(SUM('S2-3 Stamps & Smart Fill'!$G$14:$G$42)>=220*0.5,"CLEARED",IF(SUM('S2-3 Stamps & Smart Fill'!$G$14:$G$42)>0,"IN PROGRESS","NEW")))} -> NEW | F15: Go to S2-3 Stamps & Smart Fill
A16: BOSS | B16: Boss | C16: {=SUM(Boss!$G$14:$G$33)&" / 160"} -> 0 / 160 | D16: {=IF(SUM(Boss!$G$14:$G$33)>=160,"★★★",IF(SUM(Boss!$G$14:$G$33)>=160*0.8,"★★☆",IF(SUM(Boss!$G$14:$G$33)>=160*0.5,"★☆☆","☆☆☆")))} -> ☆☆☆ | E16: {=IF(Boss!$C$10="OPEN",IF(SUM(Boss!$G$14:$G$33)>=160*0.5,"DEFEATED","OPEN"),"LOCKED")} -> LOCKED | F16: Go to the Boss
A18: TOTAL SCORE | B18: {=(SUM('S2-1 Quick Entry'!$G$15:$G$45)+SUM('S2-2 Clone Machine'!$G$17:$G$50)+SUM('S2-3 Stamps & Smart Fill'!$G$14:$G$42)+SUM(Boss!$G$14:$G$33))&" / 890"} -> 0 / 890
A19: RANK | B19: {=_xlfn.LET(_xlpm.p,(SUM('S2-1 Quick Entry'!$G$15:$G$45)+SUM('S2-2 Clone Machine'!$G$17:$G$50)+SUM('S2-3 Stamps & Smart Fill'!$G$14:$G$42)+SUM(Boss!$G$14:$G$33))/890,IF(AND(_xlpm.p>=1,ISNUMBER(Boss!$C$8),Boss!$C$8<=10),"S",IF(_xlpm.p>=0.9,"A",IF(_xlpm.p>=0.75,"B",IF(_xlpm.p>=0.5,"C","D")))))} -> D | C19: S = 100% and under par · A ≥ 90% · B ≥ 75% · C ≥ 50%
A20: BEST TIME | B20: {=IF(ISNUMBER(Boss!$C$8),Boss!$C$8&" min (par 10)","—")} -> —
A21: NEXT UP | B21: {=IFERROR(INDEX($A$13:$A$15,MATCH("☆☆☆",$D$13:$D$15,0))&" "&INDEX($B$13:$B$15,MATCH("☆☆☆",$D$13:$D$15,0)),IF(Boss!$C$10="OPEN","the Boss","All clear! Aim for rank S"))} -> S2-1 Quick Entry
A23: Replay a stage: select its yellow answer cells and press Delete. Undo an arena drill with Ctrl+Z.

Sheet S2-1 Quick Entry
A1: STAGE S2-1 ▸ QUICK ENTRY
A2: Goal: type and move without reaching for the mouse
A3: {="SCORE "&TEXT(SUM($G$15:$G$45),"0000")&" / 0240"} -> SCORE 0000 / 0240 | C3: {=IF(SUM($G$15:$G$45)>=240,"★★★",IF(SUM($G$15:$G$45)>=240*0.8,"★★☆",IF(SUM($G$15:$G$45)>=240*0.5,"★☆☆","☆☆☆")))} -> ☆☆☆ | D3: {=REPT("█",ROUND(10*SUM($G$15:$G$45)/240,0))&REPT("░",10-ROUND(10*SUM($G$15:$G$45)/240,0))&" "&TEXT(SUM($G$15:$G$45)/240,"0%")} -> ░░░░░░░░░░ 0% | F3: {=IF(SUM($G$15:$G$45)>=240*0.5,"STAGE CLEAR! ▶ Next: S2-2 Clone Machine","")}
A5: BRIEFING · new moves in this stage
A6: # | B6: What it does · Pro tip | C6: Keys / Syntax
A7: 1 | B7: Confirm the entry and move UP one cell. Tip: Enter alone moves down. | C7: Shift+Enter
A8: 2 | B8: Confirm the entry and move right (Shift+Tab moves left). Tip: On a protected sheet, Tab hops between input cells. | C8: Tab / Shift+Tab
A9: 3 | B9: Fill every selected cell with what you just typed. Tip: Select a range, type once, press Ctrl+Enter: done. | C9: Ctrl+Enter
A10: 4 | B10: Start a new line inside the same cell. Tip: Great for addresses and notes. | C10: Alt+Enter
A11: 5 | B11: Cancel what you are typing; the cell stays unchanged. Tip: Esc also closes menus and dialogs. | C11: Esc
A13: WARM-UP · flashback to earlier stages
A14: # | B14: Mission | C14: Your answer | D14: Result | E14: Hint? | F14: Hint | G14: XP
A15: W1 | B15: Which function returns the smallest number in a range? (from F1-2 Big Six) | D15: {=IFERROR(_xlfn.LET(_xlpm.a,'S2-1 Quick Entry'!$C$15,IF(TRIM(_xlpm.a&"")="","",IF(OR(SUBSTITUTE(SUBSTITUTE(SUBSTITUTE(SUBSTITUTE(SUBSTITUTE(SUBSTITUTE(SUBSTITUTE(SUBSTITUTE(SUBSTITUTE(SUBSTITUTE(SUBSTITUTE(SUBSTITUTE(SUBSTITUTE(SUBSTITUTE(SUBSTITUTE(SUBSTITUTE(SUBSTITUTE(SUBSTITUTE(SUBSTITUTE(SUBSTITUTE(SUBSTITUTE(SUBSTITUTE(SUBSTITUTE(SUBSTITUTE(SUBSTITUTE(SUBSTITUTE(SUBSTITUTE(UPPER(_xlpm.a)," ",""),"CONTROL","CTRL"),"CTL","CTRL"),"ESCAPE","ESC"),"RETURN","ENTER"),"PAGEDOWN","PGDN"),"PGDOWN","PGDN"),"PAGEUP","PGUP"),"ARROWKEYS","ARROW"),"ARROWKEY","ARROW"),"ARROWS","ARROW"),"DOWNARROW","DOWN"),"UPARROW","UP"),"LEFTARROW","LEFT"),"RIGHTARROW","RIGHT"),"ARROWDOWN","DOWN"),"ARROWUP","UP"),"ARROWLEFT","LEFT"),"ARROWRIGHT","RIGHT"),"↓","DOWN"),"↑","UP"),"←","LEFT"),"→","RIGHT"),"SPACEBAR","SPACE"),"−","-"),"MINUS","-"),"PLUS","+")=Key!$E$2:$J$2),"✔ CLEAR","✘ TRY AGAIN"))),"✘ TRY AGAIN")} | F15: {=IF(E15="Show hint",Key!$B$2,"")} | G15: {=IF(LEFT(D15,1)="✔",IF(E15="Show hint",5,10),0)} -> 0
A16: W2 | B16: Which function counts only the cells that hold numbers? (from F1-2 Big Six) | D16: {=IFERROR(_xlfn.LET(_xlpm.a,'S2-1 Quick Entry'!$C$16,IF(TRIM(_xlpm.a&"")="","",IF(OR(SUBSTITUTE(SUBSTITUTE(SUBSTITUTE(SUBSTITUTE(SUBSTITUTE(SUBSTITUTE(SUBSTITUTE(SUBSTITUTE(SUBSTITUTE(SUBSTITUTE(SUBSTITUTE(SUBSTITUTE(SUBSTITUTE(SUBSTITUTE(SUBSTITUTE(SUBSTITUTE(SUBSTITUTE(SUBSTITUTE(SUBSTITUTE(SUBSTITUTE(SUBSTITUTE(SUBSTITUTE(SUBSTITUTE(SUBSTITUTE(SUBSTITUTE(SUBSTITUTE(SUBSTITUTE(UPPER(_xlpm.a)," ",""),"CONTROL","CTRL"),"CTL","CTRL"),"ESCAPE","ESC"),"RETURN","ENTER"),"PAGEDOWN","PGDN"),"PGDOWN","PGDN"),"PAGEUP","PGUP"),"ARROWKEYS","ARROW"),"ARROWKEY","ARROW"),"ARROWS","ARROW"),"DOWNARROW","DOWN"),"UPARROW","UP"),"LEFTARROW","LEFT"),"RIGHTARROW","RIGHT"),"ARROWDOWN","DOWN"),"ARROWUP","UP"),"ARROWLEFT","LEFT"),"ARROWRIGHT","RIGHT"),"↓","DOWN"),"↑","UP"),"←","LEFT"),"→","RIGHT"),"SPACEBAR","SPACE"),"−","-"),"MINUS","-"),"PLUS","+")=Key!$E$3:$J$3),"✔ CLEAR","✘ TRY AGAIN"))),"✘ TRY AGAIN")} | F16: {=IF(E16="Show hint",Key!$B$3,"")} | G16: {=IF(LEFT(D16,1)="✔",IF(E16="Show hint",5,10),0)} -> 0
A17: W3 | B17: Which function counts every non-empty cell? (from F1-2 Big Six) | D17: {=IFERROR(_xlfn.LET(_xlpm.a,'S2-1 Quick Entry'!$C$17,IF(TRIM(_xlpm.a&"")="","",IF(OR(SUBSTITUTE(SUBSTITUTE(SUBSTITUTE(SUBSTITUTE(SUBSTITUTE(SUBSTITUTE(SUBSTITUTE(SUBSTITUTE(SUBSTITUTE(SUBSTITUTE(SUBSTITUTE(SUBSTITUTE(SUBSTITUTE(SUBSTITUTE(SUBSTITUTE(SUBSTITUTE(SUBSTITUTE(SUBSTITUTE(SUBSTITUTE(SUBSTITUTE(SUBSTITUTE(SUBSTITUTE(SUBSTITUTE(SUBSTITUTE(SUBSTITUTE(SUBSTITUTE(SUBSTITUTE(UPPER(_xlpm.a)," ",""),"CONTROL","CTRL"),"CTL","CTRL"),"ESCAPE","ESC"),"RETURN","ENTER"),"PAGEDOWN","PGDN"),"PGDOWN","PGDN"),"PAGEUP","PGUP"),"ARROWKEYS","ARROW"),"ARROWKEY","ARROW"),"ARROWS","ARROW"),"DOWNARROW","DOWN"),"UPARROW","UP"),"LEFTARROW","LEFT"),"RIGHTARROW","RIGHT"),"ARROWDOWN","DOWN"),"ARROWUP","UP"),"ARROWLEFT","LEFT"),"ARROWRIGHT","RIGHT"),"↓","DOWN"),"↑","UP"),"←","LEFT"),"→","RIGHT"),"SPACEBAR","SPACE"),"−","-"),"MINUS","-"),"PLUS","+")=Key!$E$4:$J$4),"✔ CLEAR","✘ TRY AGAIN"))),"✘ TRY AGAIN")} | F17: {=IF(E17="Show hint",Key!$B$4,"")} | G17: {=IF(LEFT(D17,1)="✔",IF(E17="Show hint",5,10),0)} -> 0
A18: W4 | B18: Which keys insert an AutoSum formula? (from F1-2 Big Six) | D18: {=IFERROR(_xlfn.LET(_xlpm.a,'S2-1 Quick Entry'!$C$18,IF(TRIM(_xlpm.a&"")="","",IF(OR(SUBSTITUTE(SUBSTITUTE(SUBSTITUTE(SUBSTITUTE(SUBSTITUTE(SUBSTITUTE(SUBSTITUTE(SUBSTITUTE(SUBSTITUTE(SUBSTITUTE(SUBSTITUTE(SUBSTITUTE(SUBSTITUTE(SUBSTITUTE(SUBSTITUTE(SUBSTITUTE(SUBSTITUTE(SUBSTITUTE(SUBSTITUTE(SUBSTITUTE(SUBSTITUTE(SUBSTITUTE(SUBSTITUTE(SUBSTITUTE(SUBSTITUTE(SUBSTITUTE(SUBSTITUTE(UPPER(_xlpm.a)," ",""),"CONTROL","CTRL"),"CTL","CTRL"),"ESCAPE","ESC"),"RETURN","ENTER"),"PAGEDOWN","PGDN"),"PGDOWN","PGDN"),"PAGEUP","PGUP"),"ARROWKEYS","ARROW"),"ARROWKEY","ARROW"),"ARROWS","ARROW"),"DOWNARROW","DOWN"),"UPARROW","UP"),"LEFTARROW","LEFT"),"RIGHTARROW","RIGHT"),"ARROWDOWN","DOWN"),"ARROWUP","UP"),"ARROWLEFT","LEFT"),"ARROWRIGHT","RIGHT"),"↓","DOWN"),"↑","UP"),"←","LEFT"),"→","RIGHT"),"SPACEBAR","SPACE"),"−","-"),"MINUS","-"),"PLUS","+")=Key!$E$5:$E$5),"✔ CLEAR","✘ TRY AGAIN"))),"✘ TRY AGAIN")} | F18: {=IF(E18="Show hint",Key!$B$5,"")} | G18: {=IF(LEFT(D18,1)="✔",IF(E18="Show hint",5,10),0)} -> 0
A19: W5 | B19: Type the absolute version of the reference E6. (from F1-3 Anchors) | D19: {=IFERROR(_xlfn.LET(_xlpm.a,'S2-1 Quick Entry'!$C$19,IF(TRIM(_xlpm.a&"")="","",IF(OR(SUBSTITUTE(SUBSTITUTE(SUBSTITUTE(SUBSTITUTE(SUBSTITUTE(SUBSTITUTE(SUBSTITUTE(SUBSTITUTE(SUBSTITUTE(SUBSTITUTE(SUBSTITUTE(SUBSTITUTE(SUBSTITUTE(SUBSTITUTE(SUBSTITUTE(SUBSTITUTE(SUBSTITUTE(SUBSTITUTE(SUBSTITUTE(SUBSTITUTE(SUBSTITUTE(SUBSTITUTE(SUBSTITUTE(SUBSTITUTE(SUBSTITUTE(SUBSTITUTE(SUBSTITUTE(UPPER(_xlpm.a)," ",""),"CONTROL","CTRL"),"CTL","CTRL"),"ESCAPE","ESC"),"RETURN","ENTER"),"PAGEDOWN","PGDN"),"PGDOWN","PGDN"),"PAGEUP","PGUP"),"ARROWKEYS","ARROW"),"ARROWKEY","ARROW"),"ARROWS","ARROW"),"DOWNARROW","DOWN"),"UPARROW","UP"),"LEFTARROW","LEFT"),"RIGHTARROW","RIGHT"),"ARROWDOWN","DOWN"),"ARROWUP","UP"),"ARROWLEFT","LEFT"),"ARROWRIGHT","RIGHT"),"↓","DOWN"),"↑","UP"),"←","LEFT"),"→","RIGHT"),"SPACEBAR","SPACE"),"−","-"),"MINUS","-"),"PLUS","+")=Key!$E$6:$E$6),"✔ CLEAR","✘ TRY AGAIN"))),"✘ TRY AGAIN")} | F19: {=IF(E19="Show hint",Key!$B$6,"")} | G19: {=IF(LEFT(D19,1)="✔",IF(E19="Show hint",5,10),0)} -> 0
A20: W6 | B20: Type a reference to C16 that locks only the row. (from F1-3 Anchors) | D20: {=IFERROR(_xlfn.LET(_xlpm.a,'S2-1 Quick Entry'!$C$20,IF(TRIM(_xlpm.a&"")="","",IF(OR(SUBSTITUTE(SUBSTITUTE(SUBSTITUTE(SUBSTITUTE(SUBSTITUTE(SUBSTITUTE(SUBSTITUTE(SUBSTITUTE(SUBSTITUTE(SUBSTITUTE(SUBSTITUTE(SUBSTITUTE(SUBSTITUTE(SUBSTITUTE(SUBSTITUTE(SUBSTITUTE(SUBSTITUTE(SUBSTITUTE(SUBSTITUTE(SUBSTITUTE(SUBSTITUTE(SUBSTITUTE(SUBSTITUTE(SUBSTITUTE(SUBSTITUTE(SUBSTITUTE(SUBSTITUTE(UPPER(_xlpm.a)," ",""),"CONTROL","CTRL"),"CTL","CTRL"),"ESCAPE","ESC"),"RETURN","ENTER"),"PAGEDOWN","PGDN"),"PGDOWN","PGDN"),"PAGEUP","PGUP"),"ARROWKEYS","ARROW"),"ARROWKEY","ARROW"),"ARROWS","ARROW"),"DOWNARROW","DOWN"),"UPARROW","UP"),"LEFTARROW","LEFT"),"RIGHTARROW","RIGHT"),"ARROWDOWN","DOWN"),"ARROWUP","UP"),"ARROWLEFT","LEFT"),"ARROWRIGHT","RIGHT"),"↓","DOWN"),"↑","UP"),"←","LEFT"),"→","RIGHT"),"SPACEBAR","SPACE"),"−","-"),"MINUS","-"),"PLUS","+")=Key!$E$7:$E$7),"✔ CLEAR","✘ TRY AGAIN"))),"✘ TRY AGAIN")} | F20: {=IF(E20="Show hint",Key!$B$7,"")} | G20: {=IF(LEFT(D20,1)="✔",IF(E20="Show hint",5,10),0)} -> 0
A21: W7 | B21: Which key adds or cycles the $ signs on a reference you are editing? (from F1-3 Anchors) | D21: {=IFERROR(_xlfn.LET(_xlpm.a,'S2-1 Quick Entry'!$C$21,IF(TRIM(_xlpm.a&"")="","",IF(OR(SUBSTITUTE(SUBSTITUTE(SUBSTITUTE(SUBSTITUTE(SUBSTITUTE(SUBSTITUTE(SUBSTITUTE(SUBSTITUTE(SUBSTITUTE(SUBSTITUTE(SUBSTITUTE(SUBSTITUTE(SUBSTITUTE(SUBSTITUTE(SUBSTITUTE(SUBSTITUTE(SUBSTITUTE(SUBSTITUTE(SUBSTITUTE(SUBSTITUTE(SUBSTITUTE(SUBSTITUTE(SUBSTITUTE(SUBSTITUTE(SUBSTITUTE(SUBSTITUTE(SUBSTITUTE(UPPER(_xlpm.a)," ",""),"CONTROL","CTRL"),"CTL","CTRL"),"ESCAPE","ESC"),"RETURN","ENTER"),"PAGEDOWN","PGDN"),"PGDOWN","PGDN"),"PAGEUP","PGUP"),"ARROWKEYS","ARROW"),"ARROWKEY","ARROW"),"ARROWS","ARROW"),"DOWNARROW","DOWN"),"UPARROW","UP"),"LEFTARROW","LEFT"),"RIGHTARROW","RIGHT"),"ARROWDOWN","DOWN"),"ARROWUP","UP"),"ARROWLEFT","LEFT"),"ARROWRIGHT","RIGHT"),"↓","DOWN"),"↑","UP"),"←","LEFT"),"→","RIGHT"),"SPACEBAR","SPACE"),"−","-"),"MINUS","-"),"PLUS","+")=Key!$E$8:$E$8),"✔ CLEAR","✘ TRY AGAIN"))),"✘ TRY AGAIN")} | F21: {=IF(E21="Show hint",Key!$B$8,"")} | G21: {=IF(LEFT(D21,1)="✔",IF(E21="Show hint",5,10),0)} -> 0
A22: W8 | B22: Which keys copy the top cell down into the selected cells? (from F1-3 Anchors) | D22: {=IFERROR(_xlfn.LET(_xlpm.a,'S2-1 Quick Entry'!$C$22,IF(TRIM(_xlpm.a&"")="","",IF(OR(SUBSTITUTE(SUBSTITUTE(SUBSTITUTE(SUBSTITUTE(SUBSTITUTE(SUBSTITUTE(SUBSTITUTE(SUBSTITUTE(SUBSTITUTE(SUBSTITUTE(SUBSTITUTE(SUBSTITUTE(SUBSTITUTE(SUBSTITUTE(SUBSTITUTE(SUBSTITUTE(SUBSTITUTE(SUBSTITUTE(SUBSTITUTE(SUBSTITUTE(SUBSTITUTE(SUBSTITUTE(SUBSTITUTE(SUBSTITUTE(SUBSTITUTE(SUBSTITUTE(SUBSTITUTE(UPPER(_xlpm.a)," ",""),"CONTROL","CTRL"),"CTL","CTRL"),"ESCAPE","ESC"),"RETURN","ENTER"),"PAGEDOWN","PGDN"),"PGDOWN","PGDN"),"PAGEUP","PGUP"),"ARROWKEYS","ARROW"),"ARROWKEY","ARROW"),"ARROWS","ARROW"),"DOWNARROW","DOWN"),"UPARROW","UP"),"LEFTARROW","LEFT"),"RIGHTARROW","RIGHT"),"ARROWDOWN","DOWN"),"ARROWUP","UP"),"ARROWLEFT","LEFT"),"ARROWRIGHT","RIGHT"),"↓","DOWN"),"↑","UP"),"←","LEFT"),"→","RIGHT"),"SPACEBAR","SPACE"),"−","-"),"MINUS","-"),"PLUS","+")=Key!$E$9:$E$9),"✔ CLEAR","✘ TRY AGAIN"))),"✘ TRY AGAIN")} | F22: {=IF(E22="Show hint",Key!$B$9,"")} | G22: {=IF(LEFT(D22,1)="✔",IF(E22="Show hint",5,10),0)} -> 0
A23: W9 | B23: Which keys jump to the edge of the current data block (any direction)? (from S1-1 Warp Zones) | D23: {=IFERROR(_xlfn.LET(_xlpm.a,'S2-1 Quick Entry'!$C$23,IF(TRIM(_xlpm.a&"")="","",IF(OR(SUBSTITUTE(SUBSTITUTE(SUBSTITUTE(SUBSTITUTE(SUBSTITUTE(SUBSTITUTE(SUBSTITUTE(SUBSTITUTE(SUBSTITUTE(SUBSTITUTE(SUBSTITUTE(SUBSTITUTE(SUBSTITUTE(SUBSTITUTE(SUBSTITUTE(SUBSTITUTE(SUBSTITUTE(SUBSTITUTE(SUBSTITUTE(SUBSTITUTE(SUBSTITUTE(SUBSTITUTE(SUBSTITUTE(SUBSTITUTE(SUBSTITUTE(SUBSTITUTE(SUBSTITUTE(UPPER(_xlpm.a)," ",""),"CONTROL","CTRL"),"CTL","CTRL"),"ESCAPE","ESC"),"RETURN","ENTER"),"PAGEDOWN","PGDN"),"PGDOWN","PGDN"),"PAGEUP","PGUP"),"ARROWKEYS","ARROW"),"ARROWKEY","ARROW"),"ARROWS","ARROW"),"DOWNARROW","DOWN"),"UPARROW","UP"),"LEFTARROW","LEFT"),"RIGHTARROW","RIGHT"),"ARROWDOWN","DOWN"),"ARROWUP","UP"),"ARROWLEFT","LEFT"),"ARROWRIGHT","RIGHT"),"↓","DOWN"),"↑","UP"),"←","LEFT"),"→","RIGHT"),"SPACEBAR","SPACE"),"−","-"),"MINUS","-"),"PLUS","+")=Key!$E$10:$I$10),"✔ CLEAR","✘ TRY AGAIN"))),"✘ TRY AGAIN")} | F23: {=IF(E23="Show hint",Key!$B$10,"")} | G23: {=IF(LEFT(D23,1)="✔",IF(E23="Show hint",5,10),0)} -> 0
A24: W10 | B24: Which keys take you to the very first cell of the sheet (A1)? (from S1-1 Warp Zones) | D24: {=IFERROR(_xlfn.LET(_xlpm.a,'S2-1 Quick Entry'!$C$24,IF(TRIM(_xlpm.a&"")="","",IF(OR(SUBSTITUTE(SUBSTITUTE(SUBSTITUTE(SUBSTITUTE(SUBSTITUTE(SUBSTITUTE(SUBSTITUTE(SUBSTITUTE(SUBSTITUTE(SUBSTITUTE(SUBSTITUTE(SUBSTITUTE(SUBSTITUTE(SUBSTITUTE(SUBSTITUTE(SUBSTITUTE(SUBSTITUTE(SUBSTITUTE(SUBSTITUTE(SUBSTITUTE(SUBSTITUTE(SUBSTITUTE(SUBSTITUTE(SUBSTITUTE(SUBSTITUTE(SUBSTITUTE(SUBSTITUTE(UPPER(_xlpm.a)," ",""),"CONTROL","CTRL"),"CTL","CTRL"),"ESCAPE","ESC"),"RETURN","ENTER"),"PAGEDOWN","PGDN"),"PGDOWN","PGDN"),"PAGEUP","PGUP"),"ARROWKEYS","ARROW"),"ARROWKEY","ARROW"),"ARROWS","ARROW"),"DOWNARROW","DOWN"),"UPARROW","UP"),"LEFTARROW","LEFT"),"RIGHTARROW","RIGHT"),"ARROWDOWN","DOWN"),"ARROWUP","UP"),"ARROWLEFT","LEFT"),"ARROWRIGHT","RIGHT"),"↓","DOWN"),"↑","UP"),"←","LEFT"),"→","RIGHT"),"SPACEBAR","SPACE"),"−","-"),"MINUS","-"),"PLUS","+")=Key!$E$11:$E$11),"✔ CLEAR","✘ TRY AGAIN"))),"✘ TRY AGAIN")} | F24: {=IF(E24="Show hint",Key!$B$11,"")} | G24: {=IF(LEFT(D24,1)="✔",IF(E24="Show hint",5,10),0)} -> 0
A26: TRAINING · recognize the move (pick from the list)
A27: # | B27: Mission | C27: Your answer | D27: Result | E27: Hint? | F27: Hint | G27: XP
A28: T1 | B28: Which keys confirm an entry and move up one cell? | D28: {=IFERROR(IF('S2-1 Quick Entry'!$C$28&""="","",IF('S2-1 Quick Entry'!$C$28&""=Key!$C$12&"","✔ CLEAR","✘ TRY AGAIN")),"✘ TRY AGAIN")} | F28: {=IF(E28="Show hint",Key!$B$12,"")} | G28: {=IF(LEFT(D28,1)="✔",IF(E28="Show hint",5,10),0)} -> 0
A29: T2 | B29: Which key confirms an entry and moves one cell to the right? | D29: {=IFERROR(IF('S2-1 Quick Entry'!$C$29&""="","",IF('S2-1 Quick Entry'!$C$29&""=Key!$C$13&"","✔ CLEAR","✘ TRY AGAIN")),"✘ TRY AGAIN")} | F29: {=IF(E29="Show hint",Key!$B$13,"")} | G29: {=IF(LEFT(D29,1)="✔",IF(E29="Show hint",5,10),0)} -> 0
A30: T3 | B30: Which keys fill every selected cell with what you typed? | D30: {=IFERROR(IF('S2-1 Quick Entry'!$C$30&""="","",IF('S2-1 Quick Entry'!$C$30&""=Key!$C$14&"","✔ CLEAR","✘ TRY AGAIN")),"✘ TRY AGAIN")} | F30: {=IF(E30="Show hint",Key!$B$14,"")} | G30: {=IF(LEFT(D30,1)="✔",IF(E30="Show hint",5,10),0)} -> 0
A31: T4 | B31: Which keys start a new line inside the same cell? | D31: {=IFERROR(IF('S2-1 Quick Entry'!$C$31&""="","",IF('S2-1 Quick Entry'!$C$31&""=Key!$C$15&"","✔ CLEAR","✘ TRY AGAIN")),"✘ TRY AGAIN")} | F31: {=IF(E31="Show hint",Key!$B$15,"")} | G31: {=IF(LEFT(D31,1)="✔",IF(E31="Show hint",5,10),0)} -> 0
A32: T5 | B32: Which key cancels an entry and leaves the cell unchanged? | D32: {=IFERROR(IF('S2-1 Quick Entry'!$C$32&""="","",IF('S2-1 Quick Entry'!$C$32&""=Key!$C$16&"","✔ CLEAR","✘ TRY AGAIN")),"✘ TRY AGAIN")} | F32: {=IF(E32="Show hint",Key!$B$16,"")} | G32: {=IF(LEFT(D32,1)="✔",IF(E32="Show hint",5,10),0)} -> 0
A34: CHALLENGES · recall it, then do it
B35: ▶ Open S2-1 Arena (or press Ctrl+PgDn)
A36: # | B36: Mission | C36: Your answer | D36: Result | E36: Hint? | F36: Hint | G36: XP
A37: C1 | B37: Which keys confirm an entry and move up one cell? | D37: {=IFERROR(_xlfn.LET(_xlpm.a,'S2-1 Quick Entry'!$C$37,IF(TRIM(_xlpm.a&"")="","",IF(OR(SUBSTITUTE(SUBSTITUTE(SUBSTITUTE(SUBSTITUTE(SUBSTITUTE(SUBSTITUTE(SUBSTITUTE(SUBSTITUTE(SUBSTITUTE(SUBSTITUTE(SUBSTITUTE(SUBSTITUTE(SUBSTITUTE(SUBSTITUTE(SUBSTITUTE(SUBSTITUTE(SUBSTITUTE(SUBSTITUTE(SUBSTITUTE(SUBSTITUTE(SUBSTITUTE(SUBSTITUTE(SUBSTITUTE(SUBSTITUTE(SUBSTITUTE(SUBSTITUTE(SUBSTITUTE(UPPER(_xlpm.a)," ",""),"CONTROL","CTRL"),"CTL","CTRL"),"ESCAPE","ESC"),"RETURN","ENTER"),"PAGEDOWN","PGDN"),"PGDOWN","PGDN"),"PAGEUP","PGUP"),"ARROWKEYS","ARROW"),"ARROWKEY","ARROW"),"ARROWS","ARROW"),"DOWNARROW","DOWN"),"UPARROW","UP"),"LEFTARROW","LEFT"),"RIGHTARROW","RIGHT"),"ARROWDOWN","DOWN"),"ARROWUP","UP"),"ARROWLEFT","LEFT"),"ARROWRIGHT","RIGHT"),"↓","DOWN"),"↑","UP"),"←","LEFT"),"→","RIGHT"),"SPACEBAR","SPACE"),"−","-"),"MINUS","-"),"PLUS","+")=Key!$E$17:$E$17),"✔ CLEAR","✘ TRY AGAIN"))),"✘ TRY AGAIN")} | F37: {=IF(E37="Show hint",Key!$B$17,"")} | G37: {=IF(LEFT(D37,1)="✔",IF(E37="Show hint",5,10),0)} -> 0
A38: C2 | B38: Which key confirms an entry and moves one cell to the right? | D38: {=IFERROR(_xlfn.LET(_xlpm.a,'S2-1 Quick Entry'!$C$38,IF(TRIM(_xlpm.a&"")="","",IF(OR(SUBSTITUTE(SUBSTITUTE(SUBSTITUTE(SUBSTITUTE(SUBSTITUTE(SUBSTITUTE(SUBSTITUTE(SUBSTITUTE(SUBSTITUTE(SUBSTITUTE(SUBSTITUTE(SUBSTITUTE(SUBSTITUTE(SUBSTITUTE(SUBSTITUTE(SUBSTITUTE(SUBSTITUTE(SUBSTITUTE(SUBSTITUTE(SUBSTITUTE(SUBSTITUTE(SUBSTITUTE(SUBSTITUTE(SUBSTITUTE(SUBSTITUTE(SUBSTITUTE(SUBSTITUTE(UPPER(_xlpm.a)," ",""),"CONTROL","CTRL"),"CTL","CTRL"),"ESCAPE","ESC"),"RETURN","ENTER"),"PAGEDOWN","PGDN"),"PGDOWN","PGDN"),"PAGEUP","PGUP"),"ARROWKEYS","ARROW"),"ARROWKEY","ARROW"),"ARROWS","ARROW"),"DOWNARROW","DOWN"),"UPARROW","UP"),"LEFTARROW","LEFT"),"RIGHTARROW","RIGHT"),"ARROWDOWN","DOWN"),"ARROWUP","UP"),"ARROWLEFT","LEFT"),"ARROWRIGHT","RIGHT"),"↓","DOWN"),"↑","UP"),"←","LEFT"),"→","RIGHT"),"SPACEBAR","SPACE"),"−","-"),"MINUS","-"),"PLUS","+")=Key!$E$18:$E$18),"✔ CLEAR","✘ TRY AGAIN"))),"✘ TRY AGAIN")} | F38: {=IF(E38="Show hint",Key!$B$18,"")} | G38: {=IF(LEFT(D38,1)="✔",IF(E38="Show hint",5,10),0)} -> 0
A39: C3 | B39: Which keys fill every selected cell with what you typed? | D39: {=IFERROR(_xlfn.LET(_xlpm.a,'S2-1 Quick Entry'!$C$39,IF(TRIM(_xlpm.a&"")="","",IF(OR(SUBSTITUTE(SUBSTITUTE(SUBSTITUTE(SUBSTITUTE(SUBSTITUTE(SUBSTITUTE(SUBSTITUTE(SUBSTITUTE(SUBSTITUTE(SUBSTITUTE(SUBSTITUTE(SUBSTITUTE(SUBSTITUTE(SUBSTITUTE(SUBSTITUTE(SUBSTITUTE(SUBSTITUTE(SUBSTITUTE(SUBSTITUTE(SUBSTITUTE(SUBSTITUTE(SUBSTITUTE(SUBSTITUTE(SUBSTITUTE(SUBSTITUTE(SUBSTITUTE(SUBSTITUTE(UPPER(_xlpm.a)," ",""),"CONTROL","CTRL"),"CTL","CTRL"),"ESCAPE","ESC"),"RETURN","ENTER"),"PAGEDOWN","PGDN"),"PGDOWN","PGDN"),"PAGEUP","PGUP"),"ARROWKEYS","ARROW"),"ARROWKEY","ARROW"),"ARROWS","ARROW"),"DOWNARROW","DOWN"),"UPARROW","UP"),"LEFTARROW","LEFT"),"RIGHTARROW","RIGHT"),"ARROWDOWN","DOWN"),"ARROWUP","UP"),"ARROWLEFT","LEFT"),"ARROWRIGHT","RIGHT"),"↓","DOWN"),"↑","UP"),"←","LEFT"),"→","RIGHT"),"SPACEBAR","SPACE"),"−","-"),"MINUS","-"),"PLUS","+")=Key!$E$19:$E$19),"✔ CLEAR","✘ TRY AGAIN"))),"✘ TRY AGAIN")} | F39: {=IF(E39="Show hint",Key!$B$19,"")} | G39: {=IF(LEFT(D39,1)="✔",IF(E39="Show hint",5,10),0)} -> 0
A40: C4 | B40: Which keys start a new line inside the same cell? | D40: {=IFERROR(_xlfn.LET(_xlpm.a,'S2-1 Quick Entry'!$C$40,IF(TRIM(_xlpm.a&"")="","",IF(OR(SUBSTITUTE(SUBSTITUTE(SUBSTITUTE(SUBSTITUTE(SUBSTITUTE(SUBSTITUTE(SUBSTITUTE(SUBSTITUTE(SUBSTITUTE(SUBSTITUTE(SUBSTITUTE(SUBSTITUTE(SUBSTITUTE(SUBSTITUTE(SUBSTITUTE(SUBSTITUTE(SUBSTITUTE(SUBSTITUTE(SUBSTITUTE(SUBSTITUTE(SUBSTITUTE(SUBSTITUTE(SUBSTITUTE(SUBSTITUTE(SUBSTITUTE(SUBSTITUTE(SUBSTITUTE(UPPER(_xlpm.a)," ",""),"CONTROL","CTRL"),"CTL","CTRL"),"ESCAPE","ESC"),"RETURN","ENTER"),"PAGEDOWN","PGDN"),"PGDOWN","PGDN"),"PAGEUP","PGUP"),"ARROWKEYS","ARROW"),"ARROWKEY","ARROW"),"ARROWS","ARROW"),"DOWNARROW","DOWN"),"UPARROW","UP"),"LEFTARROW","LEFT"),"RIGHTARROW","RIGHT"),"ARROWDOWN","DOWN"),"ARROWUP","UP"),"ARROWLEFT","LEFT"),"ARROWRIGHT","RIGHT"),"↓","DOWN"),"↑","UP"),"←","LEFT"),"→","RIGHT"),"SPACEBAR","SPACE"),"−","-"),"MINUS","-"),"PLUS","+")=Key!$E$20:$E$20),"✔ CLEAR","✘ TRY AGAIN"))),"✘ TRY AGAIN")} | F40: {=IF(E40="Show hint",Key!$B$20,"")} | G40: {=IF(LEFT(D40,1)="✔",IF(E40="Show hint",5,10),0)} -> 0
A41: C5 | B41: Which key cancels an entry and leaves the cell unchanged? | D41: {=IFERROR(_xlfn.LET(_xlpm.a,'S2-1 Quick Entry'!$C$41,IF(TRIM(_xlpm.a&"")="","",IF(OR(SUBSTITUTE(SUBSTITUTE(SUBSTITUTE(SUBSTITUTE(SUBSTITUTE(SUBSTITUTE(SUBSTITUTE(SUBSTITUTE(SUBSTITUTE(SUBSTITUTE(SUBSTITUTE(SUBSTITUTE(SUBSTITUTE(SUBSTITUTE(SUBSTITUTE(SUBSTITUTE(SUBSTITUTE(SUBSTITUTE(SUBSTITUTE(SUBSTITUTE(SUBSTITUTE(SUBSTITUTE(SUBSTITUTE(SUBSTITUTE(SUBSTITUTE(SUBSTITUTE(SUBSTITUTE(UPPER(_xlpm.a)," ",""),"CONTROL","CTRL"),"CTL","CTRL"),"ESCAPE","ESC"),"RETURN","ENTER"),"PAGEDOWN","PGDN"),"PGDOWN","PGDN"),"PAGEUP","PGUP"),"ARROWKEYS","ARROW"),"ARROWKEY","ARROW"),"ARROWS","ARROW"),"DOWNARROW","DOWN"),"UPARROW","UP"),"LEFTARROW","LEFT"),"RIGHTARROW","RIGHT"),"ARROWDOWN","DOWN"),"ARROWUP","UP"),"ARROWLEFT","LEFT"),"ARROWRIGHT","RIGHT"),"↓","DOWN"),"↑","UP"),"←","LEFT"),"→","RIGHT"),"SPACEBAR","SPACE"),"−","-"),"MINUS","-"),"PLUS","+")=Key!$E$21:$E$21),"✔ CLEAR","✘ TRY AGAIN"))),"✘ TRY AGAIN")} | F41: {=IF(E41="Show hint",Key!$B$21,"")} | G41: {=IF(LEFT(D41,1)="✔",IF(E41="Show hint",5,10),0)} -> 0
A42: C6 | B42: In the arena, select B6:B15 (click B6, then Shift+click B15), type DONE and press Ctrl+Enter. Every selected cell gets DONE. | C42: ▶ ARENA C6 (cell B6) | D42: {=IF(IFERROR(AND('S2-1 Arena'!$B$6="DONE",'S2-1 Arena'!$B$7="DONE",'S2-1 Arena'!$B$8="DONE",'S2-1 Arena'!$B$9="DONE",'S2-1 Arena'!$B$10="DONE",'S2-1 Arena'!$B$11="DONE",'S2-1 Arena'!$B$12="DONE",'S2-1 Arena'!$B$13="DONE",'S2-1 Arena'!$B$14="DONE",'S2-1 Arena'!$B$15="DONE"),FALSE),"✔ CLEAR","· not yet")} -> · not yet | F42: {=IF(E42="Show hint",Key!$B$22,"")} | G42: {=IF(LEFT(D42,1)="✔",IF(E42="Show hint",5,10),0)} -> 0
A43: C7 | B43: In D6 type Line 1, press Alt+Enter, type Line 2, then press Enter. | C43: ▶ ARENA C7 (cell D6) | D43: {=IF(IFERROR(EXACT('S2-1 Arena'!$D$6,"Line 1"&CHAR(10)&"Line 2"),FALSE),"✔ CLEAR","· not yet")} -> · not yet | F43: {=IF(E43="Show hint",Key!$B$23,"")} | G43: {=IF(LEFT(D43,1)="✔",IF(E43="Show hint",5,10),0)} -> 0
A44: C8 | B44: In F6 type Name, press Tab, type Score, press Tab, type Level, then press Enter. | C44: ▶ ARENA C8 (cell F6) | D44: {=IF(IFERROR(AND('S2-1 Arena'!$F$6="Name",'S2-1 Arena'!$G$6="Score",'S2-1 Arena'!$H$6="Level"),FALSE),"✔ CLEAR","· not yet")} -> · not yet | F44: {=IF(E44="Show hint",Key!$B$24,"")} | G44: {=IF(LEFT(D44,1)="✔",IF(E44="Show hint",5,10),0)} -> 0
...

Sheet S2-1 Arena
A1: ARENA ▸ S2-1 QUICK ENTRY
A2: Practice area · everything here is editable. Missions and their checks are on the stage sheet.
A3: PASS CODE | B3: QUICKSTEP | D3: ◀ Back to S2-1 Quick Entry
B5: STATUS ▼ | D5: TWO LINES ▼ | F5: TAB ROW ▶
F10: UP AND DOWN ▼

Sheet S2-2 Clone Machine
A1: STAGE S2-2 ▸ CLONE MACHINE
A2: Goal: copy, move and fill without retyping
A3: {="SCORE "&TEXT(SUM($G$17:$G$50),"0000")&" / 0270"} -> SCORE 0000 / 0270 | C3: {=IF(SUM($G$17:$G$50)>=270,"★★★",IF(SUM($G$17:$G$50)>=270*0.8,"★★☆",IF(SUM($G$17:$G$50)>=270*0.5,"★☆☆","☆☆☆")))} -> ☆☆☆ | D3: {=REPT("█",ROUND(10*SUM($G$17:$G$50)/270,0))&REPT("░",10-ROUND(10*SUM($G$17:$G$50)/270,0))&" "&TEXT(SUM($G$17:$G$50)/270,"0%")} -> ░░░░░░░░░░ 0% | F3: {=IF(SUM($G$17:$G$50)>=270*0.5,"STAGE CLEAR! ▶ Next: S2-3 Stamps & Smart Fill","")}
A5: BRIEFING · new moves in this stage
A6: # | B6: What it does · Pro tip | C6: Keys / Syntax
A7: 1 | B7: Copy the selected cells. Tip: A moving border shows what's copied; Esc clears it. | C7: Ctrl+C
A8: 2 | B8: Cut the selected cells, ready to move them. Tip: Paste with Ctrl+V to finish the move. | C8: Ctrl+X
A9: 3 | B9: Paste what you copied or cut. Tip: Paste into the top-left destination cell. | C9: Ctrl+V
A10: 4 | B10: Open Paste Special: paste only values, formats and more. Tip: Ctrl+Alt+V, then V, then Enter pastes values only. | C10: Ctrl+Alt+V
A11: 5 | B11: Fill Right: copy the left cell into the selected cells to its right. Tip: The twin of Ctrl+D (Fill Down). | C11: Ctrl+R
A12: 6 | B12: Undo the last action. Tip: Press again to undo further back. | C12: Ctrl+Z
A13: 7 | B13: Redo, or repeat the last action. Tip: After an undo it redoes; otherwise it repeats your last action. | C13: Ctrl+Y
A15: WARM-UP · flashback to earlier stages
A16: # | B16: Mission | C16: Your answer | D16: Result | E16: Hint? | F16: Hint | G16: XP
A17: W1 | B17: Which keys confirm an entry and move up one cell? (from S2-1 Quick Entry) | D17: {=IFERROR(_xlfn.LET(_xlpm.a,'S2-2 Clone Machine'!$C$17,IF(TRIM(_xlpm.a&"")="","",IF(OR(SUBSTITUTE(SUBSTITUTE(SUBSTITUTE(SUBSTITUTE(SUBSTITUTE(SUBSTITUTE(SUBSTITUTE(SUBSTITUTE(SUBSTITUTE(SUBSTITUTE(SUBSTITUTE(SUBSTITUTE(SUBSTITUTE(SUBSTITUTE(SUBSTITUTE(SUBSTITUTE(SUBSTITUTE(SUBSTITUTE(SUBSTITUTE(SUBSTITUTE(SUBSTITUTE(SUBSTITUTE(SUBSTITUTE(SUBSTITUTE(SUBSTITUTE(SUBSTITUTE(SUBSTITUTE(UPPER(_xlpm.a)," ",""),"CONTROL","CTRL"),"CTL","CTRL"),"ESCAPE","ESC"),"RETURN","ENTER"),"PAGEDOWN","PGDN"),"PGDOWN","PGDN"),"PAGEUP","PGUP"),"ARROWKEYS","ARROW"),"ARROWKEY","ARROW"),"ARROWS","ARROW"),"DOWNARROW","DOWN"),"UPARROW","UP"),"LEFTARROW","LEFT"),"RIGHTARROW","RIGHT"),"ARROWDOWN","DOWN"),"ARROWUP","UP"),"ARROWLEFT","LEFT"),"ARROWRIGHT","RIGHT"),"↓","DOWN"),"↑","UP"),"←","LEFT"),"→","RIGHT"),"SPACEBAR","SPACE"),"−","-"),"MINUS","-"),"PLUS","+")=Key!$E$26:$E$26),"✔ CLEAR","✘ TRY AGAIN"))),"✘ TRY AGAIN")} | F17: {=IF(E17="Show hint",Key!$B$26,"")} | G17: {=IF(LEFT(D17,1)="✔",IF(E17="Show hint",5,10),0)} -> 0
A18: W2 | B18: Which key confirms an entry and moves one cell to the right? (from S2-1 Quick Entry) | D18: {=IFERROR(_xlfn.LET(_xlpm.a,'S2-2 Clone Machine'!$C$18,IF(TRIM(_xlpm.a&"")="","",IF(OR(SUBSTITUTE(SUBSTITUTE(SUBSTITUTE(SUBSTITUTE(SUBSTITUTE(SUBSTITUTE(SUBSTITUTE(SUBSTITUTE(SUBSTITUTE(SUBSTITUTE(SUBSTITUTE(SUBSTITUTE(SUBSTITUTE(SUBSTITUTE(SUBSTITUTE(SUBSTITUTE(SUBSTITUTE(SUBSTITUTE(SUBSTITUTE(SUBSTITUTE(SUBSTITUTE(SUBSTITUTE(SUBSTITUTE(SUBSTITUTE(SUBSTITUTE(SUBSTITUTE(SUBSTITUTE(UPPER(_xlpm.a)," ",""),"CONTROL","CTRL"),"CTL","CTRL"),"ESCAPE","ESC"),"RETURN","ENTER"),"PAGEDOWN","PGDN"),"PGDOWN","PGDN"),"PAGEUP","PGUP"),"ARROWKEYS","ARROW"),"ARROWKEY","ARROW"),"ARROWS","ARROW"),"DOWNARROW","DOWN"),"UPARROW","UP"),"LEFTARROW","LEFT"),"RIGHTARROW","RIGHT"),"ARROWDOWN","DOWN"),"ARROWUP","UP"),"ARROWLEFT","LEFT"),"ARROWRIGHT","RIGHT"),"↓","DOWN"),"↑","UP"),"←","LEFT"),"→","RIGHT"),"SPACEBAR","SPACE"),"−","-"),"MINUS","-"),"PLUS","+")=Key!$E$27:$E$27),"✔ CLEAR","✘ TRY AGAIN"))),"✘ TRY AGAIN")} | F18: {=IF(E18="Show hint",Key!$B$27,"")} | G18: {=IF(LEFT(D18,1)="✔",IF(E18="Show hint",5,10),0)} -> 0
A19: W3 | B19: Which keys fill every selected cell with what you typed? (from S2-1 Quick Entry) | D19: {=IFERROR(_xlfn.LET(_xlpm.a,'S2-2 Clone Machine'!$C$19,IF(TRIM(_xlpm.a&"")="","",IF(OR(SUBSTITUTE(SUBSTITUTE(SUBSTITUTE(SUBSTITUTE(SUBSTITUTE(SUBSTITUTE(SUBSTITUTE(SUBSTITUTE(SUBSTITUTE(SUBSTITUTE(SUBSTITUTE(SUBSTITUTE(SUBSTITUTE(SUBSTITUTE(SUBSTITUTE(SUBSTITUTE(SUBSTITUTE(SUBSTITUTE(SUBSTITUTE(SUBSTITUTE(SUBSTITUTE(SUBSTITUTE(SUBSTITUTE(SUBSTITUTE(SUBSTITUTE(SUBSTITUTE(SUBSTITUTE(UPPER(_xlpm.a)," ",""),"CONTROL","CTRL"),"CTL","CTRL"),"ESCAPE","ESC"),"RETURN","ENTER"),"PAGEDOWN","PGDN"),"PGDOWN","PGDN"),"PAGEUP","PGUP"),"ARROWKEYS","ARROW"),"ARROWKEY","ARROW"),"ARROWS","ARROW"),"DOWNARROW","DOWN"),"UPARROW","UP"),"LEFTARROW","LEFT"),"RIGHTARROW","RIGHT"),"ARROWDOWN","DOWN"),"ARROWUP","UP"),"ARROWLEFT","LEFT"),"ARROWRIGHT","RIGHT"),"↓","DOWN"),"↑","UP"),"←","LEFT"),"→","RIGHT"),"SPACEBAR","SPACE"),"−","-"),"MINUS","-"),"PLUS","+")=Key!$E$28:$E$28),"✔ CLEAR","✘ TRY AGAIN"))),"✘ TRY AGAIN")} | F19: {=IF(E19="Show hint",Key!$B$28,"")} | G19: {=IF(LEFT(D19,1)="✔",IF(E19="Show hint",5,10),0)} -> 0
A20: W4 | B20: Which keys start a new line inside the same cell? (from S2-1 Quick Entry) | D20: {=IFERROR(_xlfn.LET(_xlpm.a,'S2-2 Clone Machine'!$C$20,IF(TRIM(_xlpm.a&"")="","",IF(OR(SUBSTITUTE(SUBSTITUTE(SUBSTITUTE(SUBSTITUTE(SUBSTITUTE(SUBSTITUTE(SUBSTITUTE(SUBSTITUTE(SUBSTITUTE(SUBSTITUTE(SUBSTITUTE(SUBSTITUTE(SUBSTITUTE(SUBSTITUTE(SUBSTITUTE(SUBSTITUTE(SUBSTITUTE(SUBSTITUTE(SUBSTITUTE(SUBSTITUTE(SUBSTITUTE(SUBSTITUTE(SUBSTITUTE(SUBSTITUTE(SUBSTITUTE(SUBSTITUTE(SUBSTITUTE(UPPER(_xlpm.a)," ",""),"CONTROL","CTRL"),"CTL","CTRL"),"ESCAPE","ESC"),"RETURN","ENTER"),"PAGEDOWN","PGDN"),"PGDOWN","PGDN"),"PAGEUP","PGUP"),"ARROWKEYS","ARROW"),"ARROWKEY","ARROW"),"ARROWS","ARROW"),"DOWNARROW","DOWN"),"UPARROW","UP"),"LEFTARROW","LEFT"),"RIGHTARROW","RIGHT"),"ARROWDOWN","DOWN"),"ARROWUP","UP"),"ARROWLEFT","LEFT"),"ARROWRIGHT","RIGHT"),"↓","DOWN"),"↑","UP"),"←","LEFT"),"→","RIGHT"),"SPACEBAR","SPACE"),"−","-"),"MINUS","-"),"PLUS","+")=Key!$E$29:$E$29),"✔ CLEAR","✘ TRY AGAIN"))),"✘ TRY AGAIN")} | F20: {=IF(E20="Show hint",Key!$B$29,"")} | G20: {=IF(LEFT(D20,1)="✔",IF(E20="Show hint",5,10),0)} -> 0
A21: W5 | B21: Which key cancels an entry and leaves the cell unchanged? (from S2-1 Quick Entry) | D21: {=IFERROR(_xlfn.LET(_xlpm.a,'S2-2 Clone Machine'!$C$21,IF(TRIM(_xlpm.a&"")="","",IF(OR(SUBSTITUTE(SUBSTITUTE(SUBSTITUTE(SUBSTITUTE(SUBSTITUTE(SUBSTITUTE(SUBSTITUTE(SUBSTITUTE(SUBSTITUTE(SUBSTITUTE(SUBSTITUTE(SUBSTITUTE(SUBSTITUTE(SUBSTITUTE(SUBSTITUTE(SUBSTITUTE(SUBSTITUTE(SUBSTITUTE(SUBSTITUTE(SUBSTITUTE(SUBSTITUTE(SUBSTITUTE(SUBSTITUTE(SUBSTITUTE(SUBSTITUTE(SUBSTITUTE(SUBSTITUTE(UPPER(_xlpm.a)," ",""),"CONTROL","CTRL"),"CTL","CTRL"),"ESCAPE","ESC"),"RETURN","ENTER"),"PAGEDOWN","PGDN"),"PGDOWN","PGDN"),"PAGEUP","PGUP"),"ARROWKEYS","ARROW"),"ARROWKEY","ARROW"),"ARROWS","ARROW"),"DOWNARROW","DOWN"),"UPARROW","UP"),"LEFTARROW","LEFT"),"RIGHTARROW","RIGHT"),"ARROWDOWN","DOWN"),"ARROWUP","UP"),"ARROWLEFT","LEFT"),"ARROWRIGHT","RIGHT"),"↓","DOWN"),"↑","UP"),"←","LEFT"),"→","RIGHT"),"SPACEBAR","SPACE"),"−","-"),"MINUS","-"),"PLUS","+")=Key!$E$30:$E$30),"✔ CLEAR","✘ TRY AGAIN"))),"✘ TRY AGAIN")} | F21: {=IF(E21="Show hint",Key!$B$30,"")} | G21: {=IF(LEFT(D21,1)="✔",IF(E21="Show hint",5,10),0)} -> 0
A22: W6 | B22: Which function rounds a number to a chosen number of digits? (from F1-4 Precision) | D22: {=IFERROR(_xlfn.LET(_xlpm.a,'S2-2 Clone Machine'!$C$22,IF(TRIM(_xlpm.a&"")="","",IF(OR(SUBSTITUTE(SUBSTITUTE(SUBSTITUTE(SUBSTITUTE(SUBSTITUTE(SUBSTITUTE(SUBSTITUTE(SUBSTITUTE(SUBSTITUTE(SUBSTITUTE(SUBSTITUTE(SUBSTITUTE(SUBSTITUTE(SUBSTITUTE(SUBSTITUTE(SUBSTITUTE(SUBSTITUTE(SUBSTITUTE(SUBSTITUTE(SUBSTITUTE(SUBSTITUTE(SUBSTITUTE(SUBSTITUTE(SUBSTITUTE(SUBSTITUTE(SUBSTITUTE(SUBSTITUTE(UPPER(_xlpm.a)," ",""),"CONTROL","CTRL"),"CTL","CTRL"),"ESCAPE","ESC"),"RETURN","ENTER"),"PAGEDOWN","PGDN"),"PGDOWN","PGDN"),"PAGEUP","PGUP"),"ARROWKEYS","ARROW"),"ARROWKEY","ARROW"),"ARROWS","ARROW"),"DOWNARROW","DOWN"),"UPARROW","UP"),"LEFTARROW","LEFT"),"RIGHTARROW","RIGHT"),"ARROWDOWN","DOWN"),"ARROWUP","UP"),"ARROWLEFT","LEFT"),"ARROWRIGHT","RIGHT"),"↓","DOWN"),"↑","UP"),"←","LEFT"),"→","RIGHT"),"SPACEBAR","SPACE"),"−","-"),"MINUS","-"),"PLUS","+")=Key!$E$31:$J$31),"✔ CLEAR","✘ TRY AGAIN"))),"✘ TRY AGAIN")} | F22: {=IF(E22="Show hint",Key!$B$31,"")} | G22: {=IF(LEFT(D22,1)="✔",IF(E22="Show hint",5,10),0)} -> 0
A23: W7 | B23: Which function always rounds up, away from zero? (from F1-4 Precision) | D23: {=IFERROR(_xlfn.LET(_xlpm.a,'S2-2 Clone Machine'!$C$23,IF(TRIM(_xlpm.a&"")="","",IF(OR(SUBSTITUTE(SUBSTITUTE(SUBSTITUTE(SUBSTITUTE(SUBSTITUTE(SUBSTITUTE(SUBSTITUTE(SUBSTITUTE(SUBSTITUTE(SUBSTITUTE(SUBSTITUTE(SUBSTITUTE(SUBSTITUTE(SUBSTITUTE(SUBSTITUTE(SUBSTITUTE(SUBSTITUTE(SUBSTITUTE(SUBSTITUTE(SUBSTITUTE(SUBSTITUTE(SUBSTITUTE(SUBSTITUTE(SUBSTITUTE(SUBSTITUTE(SUBSTITUTE(SUBSTITUTE(UPPER(_xlpm.a)," ",""),"CONTROL","CTRL"),"CTL","CTRL"),"ESCAPE","ESC"),"RETURN","ENTER"),"PAGEDOWN","PGDN"),"PGDOWN","PGDN"),"PAGEUP","PGUP"),"ARROWKEYS","ARROW"),"ARROWKEY","ARROW"),"ARROWS","ARROW"),"DOWNARROW","DOWN"),"UPARROW","UP"),"LEFTARROW","LEFT"),"RIGHTARROW","RIGHT"),"ARROWDOWN","DOWN"),"ARROWUP","UP"),"ARROWLEFT","LEFT"),"ARROWRIGHT","RIGHT"),"↓","DOWN"),"↑","UP"),"←","LEFT"),"→","RIGHT"),"SPACEBAR","SPACE"),"−","-"),"MINUS","-"),"PLUS","+")=Key!$E$32:$J$32),"✔ CLEAR","✘ TRY AGAIN"))),"✘ TRY AGAIN")} | F23: {=IF(E23="Show hint",Key!$B$32,"")} | G23: {=IF(LEFT(D23,1)="✔",IF(E23="Show hint",5,10),0)} -> 0
A24: W8 | B24: Which function always rounds down, toward zero? (from F1-4 Precision) | D24: {=IFERROR(_xlfn.LET(_xlpm.a,'S2-2 Clone Machine'!$C$24,IF(TRIM(_xlpm.a&"")="","",IF(OR(SUBSTITUTE(SUBSTITUTE(SUBSTITUTE(SUBSTITUTE(SUBSTITUTE(SUBSTITUTE(SUBSTITUTE(SUBSTITUTE(SUBSTITUTE(SUBSTITUTE(SUBSTITUTE(SUBSTITUTE(SUBSTITUTE(SUBSTITUTE(SUBSTITUTE(SUBSTITUTE(SUBSTITUTE(SUBSTITUTE(SUBSTITUTE(SUBSTITUTE(SUBSTITUTE(SUBSTITUTE(SUBSTITUTE(SUBSTITUTE(SUBSTITUTE(SUBSTITUTE(SUBSTITUTE(UPPER(_xlpm.a)," ",""),"CONTROL","CTRL"),"CTL","CTRL"),"ESCAPE","ESC"),"RETURN","ENTER"),"PAGEDOWN","PGDN"),"PGDOWN","PGDN"),"PAGEUP","PGUP"),"ARROWKEYS","ARROW"),"ARROWKEY","ARROW"),"ARROWS","ARROW"),"DOWNARROW","DOWN"),"UPARROW","UP"),"LEFTARROW","LEFT"),"RIGHTARROW","RIGHT"),"ARROWDOWN","DOWN"),"ARROWUP","UP"),"ARROWLEFT","LEFT"),"ARROWRIGHT","RIGHT"),"↓","DOWN"),"↑","UP"),"←","LEFT"),"→","RIGHT"),"SPACEBAR","SPACE"),"−","-"),"MINUS","-"),"PLUS","+")=Key!$E$33:$J$33),"✔ CLEAR","✘ TRY AGAIN"))),"✘ TRY AGAIN")} | F24: {=IF(E24="Show hint",Key!$B$33,"")} | G24: {=IF(LEFT(D24,1)="✔",IF(E24="Show hint",5,10),0)} -> 0
A25: W9 | B25: Which keys jump to the last used cell on the sheet? (from S1-1 Warp Zones) | D25: {=IFERROR(_xlfn.LET(_xlpm.a,'S2-2 Clone Machine'!$C$25,IF(TRIM(_xlpm.a&"")="","",IF(OR(SUBSTITUTE(SUBSTITUTE(SUBSTITUTE(SUBSTITUTE(SUBSTITUTE(SUBSTITUTE(SUBSTITUTE(SUBSTITUTE(SUBSTITUTE(SUBSTITUTE(SUBSTITUTE(SUBSTITUTE(SUBSTITUTE(SUBSTITUTE(SUBSTITUTE(SUBSTITUTE(SUBSTITUTE(SUBSTITUTE(SUBSTITUTE(SUBSTITUTE(SUBSTITUTE(SUBSTITUTE(SUBSTITUTE(SUBSTITUTE(SUBSTITUTE(SUBSTITUTE(SUBSTITUTE(UPPER(_xlpm.a)," ",""),"CONTROL","CTRL"),"CTL","CTRL"),"ESCAPE","ESC"),"RETURN","ENTER"),"PAGEDOWN","PGDN"),"PGDOWN","PGDN"),"PAGEUP","PGUP"),"ARROWKEYS","ARROW"),"ARROWKEY","ARROW"),"ARROWS","ARROW"),"DOWNARROW","DOWN"),"UPARROW","UP"),"LEFTARROW","LEFT"),"RIGHTARROW","RIGHT"),"ARROWDOWN","DOWN"),"ARROWUP","UP"),"ARROWLEFT","LEFT"),"ARROWRIGHT","RIGHT"),"↓","DOWN"),"↑","UP"),"←","LEFT"),"→","RIGHT"),"SPACEBAR","SPACE"),"−","-"),"MINUS","-"),"PLUS","+")=Key!$E$34:$E$34),"✔ CLEAR","✘ TRY AGAIN"))),"✘ TRY AGAIN")} | F25: {=IF(E25="Show hint",Key!$B$34,"")} | G25: {=IF(LEFT(D25,1)="✔",IF(E25="Show hint",5,10),0)} -> 0
A26: W10 | B26: Which single key moves to column A of the current row? (from S1-1 Warp Zones) | D26: {=IFERROR(_xlfn.LET(_xlpm.a,'S2-2 Clone Machine'!$C$26,IF(TRIM(_xlpm.a&"")="","",IF(OR(SUBSTITUTE(SUBSTITUTE(SUBSTITUTE(SUBSTITUTE(SUBSTITUTE(SUBSTITUTE(SUBSTITUTE(SUBSTITUTE(SUBSTITUTE(SUBSTITUTE(SUBSTITUTE(SUBSTITUTE(SUBSTITUTE(SUBSTITUTE(SUBSTITUTE(SUBSTITUTE(SUBSTITUTE(SUBSTITUTE(SUBSTITUTE(SUBSTITUTE(SUBSTITUTE(SUBSTITUTE(SUBSTITUTE(SUBSTITUTE(SUBSTITUTE(SUBSTITUTE(SUBSTITUTE(UPPER(_xlpm.a)," ",""),"CONTROL","CTRL"),"CTL","CTRL"),"ESCAPE","ESC"),"RETURN","ENTER"),"PAGEDOWN","PGDN"),"PGDOWN","PGDN"),"PAGEUP","PGUP"),"ARROWKEYS","ARROW"),"ARROWKEY","ARROW"),"ARROWS","ARROW"),"DOWNARROW","DOWN"),"UPARROW","UP"),"LEFTARROW","LEFT"),"RIGHTARROW","RIGHT"),"ARROWDOWN","DOWN"),"ARROWUP","UP"),"ARROWLEFT","LEFT"),"ARROWRIGHT","RIGHT"),"↓","DOWN"),"↑","UP"),"←","LEFT"),"→","RIGHT"),"SPACEBAR","SPACE"),"−","-"),"MINUS","-"),"PLUS","+")=Key!$E$35:$E$35),"✔ CLEAR","✘ TRY AGAIN"))),"✘ TRY AGAIN")} | F26: {=IF(E26="Show hint",Key!$B$35,"")} | G26: {=IF(LEFT(D26,1)="✔",IF(E26="Show hint",5,10),0)} -> 0
A28: TRAINING · recognize the move (pick from the list)
A29: # | B29: Mission | C29: Your answer | D29: Result | E29: Hint? | F29: Hint | G29: XP
A30: T1 | B30: Which keys copy the selection? | D30: {=IFERROR(IF('S2-2 Clone Machine'!$C$30&""="","",IF('S2-2 Clone Machine'!$C$30&""=Key!$C$36&"","✔ CLEAR","✘ TRY AGAIN")),"✘ TRY AGAIN")} | F30: {=IF(E30="Show hint",Key!$B$36,"")} | G30: {=IF(LEFT(D30,1)="✔",IF(E30="Show hint",5,10),0)} -> 0
A31: T2 | B31: Which keys cut the selection? | D31: {=IFERROR(IF('S2-2 Clone Machine'!$C$31&""="","",IF('S2-2 Clone Machine'!$C$31&""=Key!$C$37&"","✔ CLEAR","✘ TRY AGAIN")),"✘ TRY AGAIN")} | F31: {=IF(E31="Show hint",Key!$B$37,"")} | G31: {=IF(LEFT(D31,1)="✔",IF(E31="Show hint",5,10),0)} -> 0
A32: T3 | B32: Which keys paste? | D32: {=IFERROR(IF('S2-2 Clone Machine'!$C$32&""="","",IF('S2-2 Clone Machine'!$C$32&""=Key!$C$38&"","✔ CLEAR","✘ TRY AGAIN")),"✘ TRY AGAIN")} | F32: {=IF(E32="Show hint",Key!$B$38,"")} | G32: {=IF(LEFT(D32,1)="✔",IF(E32="Show hint",5,10),0)} -> 0
A33: T4 | B33: Which keys open Paste Special? | D33: {=IFERROR(IF('S2-2 Clone Machine'!$C$33&""="","",IF('S2-2 Clone Machine'!$C$33&""=Key!$C$39&"","✔ CLEAR","✘ TRY AGAIN")),"✘ TRY AGAIN")} | F33: {=IF(E33="Show hint",Key!$B$39,"")} | G33: {=IF(LEFT(D33,1)="✔",IF(E33="Show hint",5,10),0)} -> 0
A34: T5 | B34: Which keys copy the left cell into the selected cells to its right? | D34: {=IFERROR(IF('S2-2 Clone Machine'!$C$34&""="","",IF('S2-2 Clone Machine'!$C$34&""=Key!$C$40&"","✔ CLEAR","✘ TRY AGAIN")),"✘ TRY AGAIN")} | F34: {=IF(E34="Show hint",Key!$B$40,"")} | G34: {=IF(LEFT(D34,1)="✔",IF(E34="Show hint",5,10),0)} -> 0
A35: T6 | B35: Which keys undo the last action? | D35: {=IFERROR(IF('S2-2 Clone Machine'!$C$35&""="","",IF('S2-2 Clone Machine'!$C$35&""=Key!$C$41&"","✔ CLEAR","✘ TRY AGAIN")),"✘ TRY AGAIN")} | F35: {=IF(E35="Show hint",Key!$B$41,"")} | G35: {=IF(LEFT(D35,1)="✔",IF(E35="Show hint",5,10),0)} -> 0
A36: T7 | B36: Which keys redo or repeat the last action? | D36: {=IFERROR(IF('S2-2 Clone Machine'!$C$36&""="","",IF('S2-2 Clone Machine'!$C$36&""=Key!$C$42&"","✔ CLEAR","✘ TRY AGAIN")),"✘ TRY AGAIN")} | F36: {=IF(E36="Show hint",Key!$B$42,"")} | G36: {=IF(LEFT(D36,1)="✔",IF(E36="Show hint",5,10),0)} -> 0
A38: CHALLENGES · recall it, then do it
B39: ▶ Open S2-2 Arena (or press Ctrl+PgDn)
A40: # | B40: Mission | C40: Your answer | D40: Result | E40: Hint? | F40: Hint | G40: XP
A41: C1 | B41: Which keys copy the selection? | D41: {=IFERROR(_xlfn.LET(_xlpm.a,'S2-2 Clone Machine'!$C$41,IF(TRIM(_xlpm.a&"")="","",IF(OR(SUBSTITUTE(SUBSTITUTE(SUBSTITUTE(SUBSTITUTE(SUBSTITUTE(SUBSTITUTE(SUBSTITUTE(SUBSTITUTE(SUBSTITUTE(SUBSTITUTE(SUBSTITUTE(SUBSTITUTE(SUBSTITUTE(SUBSTITUTE(SUBSTITUTE(SUBSTITUTE(SUBSTITUTE(SUBSTITUTE(SUBSTITUTE(SUBSTITUTE(SUBSTITUTE(SUBSTITUTE(SUBSTITUTE(SUBSTITUTE(SUBSTITUTE(SUBSTITUTE(SUBSTITUTE(UPPER(_xlpm.a)," ",""),"CONTROL","CTRL"),"CTL","CTRL"),"ESCAPE","ESC"),"RETURN","ENTER"),"PAGEDOWN","PGDN"),"PGDOWN","PGDN"),"PAGEUP","PGUP"),"ARROWKEYS","ARROW"),"ARROWKEY","ARROW"),"ARROWS","ARROW"),"DOWNARROW","DOWN"),"UPARROW","UP"),"LEFTARROW","LEFT"),"RIGHTARROW","RIGHT"),"ARROWDOWN","DOWN"),"ARROWUP","UP"),"ARROWLEFT","LEFT"),"ARROWRIGHT","RIGHT"),"↓","DOWN"),"↑","UP"),"←","LEFT"),"→","RIGHT"),"SPACEBAR","SPACE"),"−","-"),"MINUS","-"),"PLUS","+")=Key!$E$43:$E$43),"✔ CLEAR","✘ TRY AGAIN"))),"✘ TRY AGAIN")} | F41: {=IF(E41="Show hint",Key!$B$43,"")} | G41: {=IF(LEFT(D41,1)="✔",IF(E41="Show hint",5,10),0)} -> 0
A42: C2 | B42: Which keys cut the selection? | D42: {=IFERROR(_xlfn.LET(_xlpm.a,'S2-2 Clone Machine'!$C$42,IF(TRIM(_xlpm.a&"")="","",IF(OR(SUBSTITUTE(SUBSTITUTE(SUBSTITUTE(SUBSTITUTE(SUBSTITUTE(SUBSTITUTE(SUBSTITUTE(SUBSTITUTE(SUBSTITUTE(SUBSTITUTE(SUBSTITUTE(SUBSTITUTE(SUBSTITUTE(SUBSTITUTE(SUBSTITUTE(SUBSTITUTE(SUBSTITUTE(SUBSTITUTE(SUBSTITUTE(SUBSTITUTE(SUBSTITUTE(SUBSTITUTE(SUBSTITUTE(SUBSTITUTE(SUBSTITUTE(SUBSTITUTE(SUBSTITUTE(UPPER(_xlpm.a)," ",""),"CONTROL","CTRL"),"CTL","CTRL"),"ESCAPE","ESC"),"RETURN","ENTER"),"PAGEDOWN","PGDN"),"PGDOWN","PGDN"),"PAGEUP","PGUP"),"ARROWKEYS","ARROW"),"ARROWKEY","ARROW"),"ARROWS","ARROW"),"DOWNARROW","DOWN"),"UPARROW","UP"),"LEFTARROW","LEFT"),"RIGHTARROW","RIGHT"),"ARROWDOWN","DOWN"),"ARROWUP","UP"),"ARROWLEFT","LEFT"),"ARROWRIGHT","RIGHT"),"↓","DOWN"),"↑","UP"),"←","LEFT"),"→","RIGHT"),"SPACEBAR","SPACE"),"−","-"),"MINUS","-"),"PLUS","+")=Key!$E$44:$E$44),"✔ CLEAR","✘ TRY AGAIN"))),"✘ TRY AGAIN")} | F42: {=IF(E42="Show hint",Key!$B$44,"")} | G42: {=IF(LEFT(D42,1)="✔",IF(E42="Show hint",5,10),0)} -> 0
A43: C3 | B43: Which keys paste? | D43: {=IFERROR(_xlfn.LET(_xlpm.a,'S2-2 Clone Machine'!$C$43,IF(TRIM(_xlpm.a&"")="","",IF(OR(SUBSTITUTE(SUBSTITUTE(SUBSTITUTE(SUBSTITUTE(SUBSTITUTE(SUBSTITUTE(SUBSTITUTE(SUBSTITUTE(SUBSTITUTE(SUBSTITUTE(SUBSTITUTE(SUBSTITUTE(SUBSTITUTE(SUBSTITUTE(SUBSTITUTE(SUBSTITUTE(SUBSTITUTE(SUBSTITUTE(SUBSTITUTE(SUBSTITUTE(SUBSTITUTE(SUBSTITUTE(SUBSTITUTE(SUBSTITUTE(SUBSTITUTE(SUBSTITUTE(SUBSTITUTE(UPPER(_xlpm.a)," ",""),"CONTROL","CTRL"),"CTL","CTRL"),"ESCAPE","ESC"),"RETURN","ENTER"),"PAGEDOWN","PGDN"),"PGDOWN","PGDN"),"PAGEUP","PGUP"),"ARROWKEYS","ARROW"),"ARROWKEY","ARROW"),"ARROWS","ARROW"),"DOWNARROW","DOWN"),"UPARROW","UP"),"LEFTARROW","LEFT"),"RIGHTARROW","RIGHT"),"ARROWDOWN","DOWN"),"ARROWUP","UP"),"ARROWLEFT","LEFT"),"ARROWRIGHT","RIGHT"),"↓","DOWN"),"↑","UP"),"←","LEFT"),"→","RIGHT"),"SPACEBAR","SPACE"),"−","-"),"MINUS","-"),"PLUS","+")=Key!$E$45:$E$45),"✔ CLEAR","✘ TRY AGAIN"))),"✘ TRY AGAIN")} | F43: {=IF(E43="Show hint",Key!$B$45,"")} | G43: {=IF(LEFT(D43,1)="✔",IF(E43="Show hint",5,10),0)} -> 0
A44: C4 | B44: Which keys open Paste Special? | D44: {=IFERROR(_xlfn.LET(_xlpm.a,'S2-2 Clone Machine'!$C$44,IF(TRIM(_xlpm.a&"")="","",IF(OR(SUBSTITUTE(SUBSTITUTE(SUBSTITUTE(SUBSTITUTE(SUBSTITUTE(SUBSTITUTE(SUBSTITUTE(SUBSTITUTE(SUBSTITUTE(SUBSTITUTE(SUBSTITUTE(SUBSTITUTE(SUBSTITUTE(SUBSTITUTE(SUBSTITUTE(SUBSTITUTE(SUBSTITUTE(SUBSTITUTE(SUBSTITUTE(SUBSTITUTE(SUBSTITUTE(SUBSTITUTE(SUBSTITUTE(SUBSTITUTE(SUBSTITUTE(SUBSTITUTE(SUBSTITUTE(UPPER(_xlpm.a)," ",""),"CONTROL","CTRL"),"CTL","CTRL"),"ESCAPE","ESC"),"RETURN","ENTER"),"PAGEDOWN","PGDN"),"PGDOWN","PGDN"),"PAGEUP","PGUP"),"ARROWKEYS","ARROW"),"ARROWKEY","ARROW"),"ARROWS","ARROW"),"DOWNARROW","DOWN"),"UPARROW","UP"),"LEFTARROW","LEFT"),"RIGHTARROW","RIGHT"),"ARROWDOWN","DOWN"),"ARROWUP","UP"),"ARROWLEFT","LEFT"),"ARROWRIGHT","RIGHT"),"↓","DOWN"),"↑","UP"),"←","LEFT"),"→","RIGHT"),"SPACEBAR","SPACE"),"−","-"),"MINUS","-"),"PLUS","+")=Key!$E$46:$F$46),"✔ CLEAR","✘ TRY AGAIN"))),"✘ TRY AGAIN")} | F44: {=IF(E44="Show hint",Key!$B$46,"")} | G44: {=IF(LEFT(D44,1)="✔",IF(E44="Show hint",5,10),0)} -> 0
...

Sheet S2-2 Arena
A1: ARENA ▸ S2-2 CLONE MACHINE
A2: Practice area · everything here is editable. Missions and their checks are on the stage sheet.
A3: PASS CODE | B3: CLONE | D3: ◀ Back to S2-2 Clone Machine
B5: Budget | C5: Jan | D5: Feb | E5: Mar | F5: Apr | G5: May | H5: Jun
B6: TOTAL | C6: {=SUM(C7:C10)} -> 980
B7: Food | C7: 120 | D7: 130 | E7: 125 | F7: 140 | G7: 150 | H7: 135
B8: Rent | C8: 800 | D8: 800 | E8: 800 | F8: 820 | G8: 820 | H8: 820
B9: Fun | C9: 60 | D9: 90 | E9: 45 | F9: 70 | G9: 110 | H9: 80
B10: Travel | C10: 0 | D10: 0 | E10: 300 | F10: 0 | G10: 450 | H10: 0
B13: SNAPSHOT
B15: LIVE | C15: {=SUM(C7:C10)} -> 980 | D15: {=SUM(D7:D10)} -> 1020 | E15: {=SUM(E7:E10)} -> 1270 | F15: {=SUM(F7:F10)} -> 1030 | G15: {=SUM(G7:G10)} -> 1530 | H15: {=SUM(H7:H10)} -> 1035
B20: Player | C20: Score | D20: Rank
B22: Zelda | C22: 980 | D22: 1

Sheet S2-3 Stamps & Smart Fill
A1: STAGE S2-3 ▸ STAMPS & SMART FILL
A2: Goal: stamp dates and times, let Excel finish your pattern
A3: {="SCORE "&TEXT(SUM($G$14:$G$42),"0000")&" / 0220"} -> SCORE 0000 / 0220 | C3: {=IF(SUM($G$14:$G$42)>=220,"★★★",IF(SUM($G$14:$G$42)>=220*0.8,"★★☆",IF(SUM($G$14:$G$42)>=220*0.5,"★☆☆","☆☆☆")))} -> ☆☆☆ | D3: {=REPT("█",ROUND(10*SUM($G$14:$G$42)/220,0))&REPT("░",10-ROUND(10*SUM($G$14:$G$42)/220,0))&" "&TEXT(SUM($G$14:$G$42)/220,"0%")} -> ░░░░░░░░░░ 0% | F3: {=IF(SUM($G$14:$G$42)>=220*0.5,"STAGE CLEAR! ▶ Next: Boss","")}
A5: BRIEFING · new moves in this stage
A6: # | B6: What it does · Pro tip | C6: Keys / Syntax
A7: 1 | B7: Type today's date as a fixed value. Tip: Unlike =TODAY(), it never changes later. | C7: Ctrl+;
A8: 2 | B8: Type the current time as a fixed value. Tip: Stamp a START and a FINISH time to time yourself. | C8: Ctrl+Shift+:
A9: 3 | B9: Flash Fill: Excel spots your pattern and fills the column. Tip: Type one or two examples first, then press Ctrl+E. | C9: Ctrl+E
A10: 4 | B10: Open a cell's dropdown list. Tip: Then choose with the arrows and Enter. | C10: Alt+↓
A12: WARM-UP · flashback to earlier stages
A13: # | B13: Mission | C13: Your answer | D13: Result | E13: Hint? | F13: Hint | G13: XP
A14: W1 | B14: Which keys copy the selection? (from S2-2 Clone Machine) | D14: {=IFERROR(_xlfn.LET(_xlpm.a,'S2-3 Stamps & Smart Fill'!$C$14,IF(TRIM(_xlpm.a&"")="","",IF(OR(SUBSTITUTE(SUBSTITUTE(SUBSTITUTE(SUBSTITUTE(SUBSTITUTE(SUBSTITUTE(SUBSTITUTE(SUBSTITUTE(SUBSTITUTE(SUBSTITUTE(SUBSTITUTE(SUBSTITUTE(SUBSTITUTE(SUBSTITUTE(SUBSTITUTE(SUBSTITUTE(SUBSTITUTE(SUBSTITUTE(SUBSTITUTE(SUBSTITUTE(SUBSTITUTE(SUBSTITUTE(SUBSTITUTE(SUBSTITUTE(SUBSTITUTE(SUBSTITUTE(SUBSTITUTE(UPPER(_xlpm.a)," ",""),"CONTROL","CTRL"),"CTL","CTRL"),"ESCAPE","ESC"),"RETURN","ENTER"),"PAGEDOWN","PGDN"),"PGDOWN","PGDN"),"PAGEUP","PGUP"),"ARROWKEYS","ARROW"),"ARROWKEY","ARROW"),"ARROWS","ARROW"),"DOWNARROW","DOWN"),"UPARROW","UP"),"LEFTARROW","LEFT"),"RIGHTARROW","RIGHT"),"ARROWDOWN","DOWN"),"ARROWUP","UP"),"ARROWLEFT","LEFT"),"ARROWRIGHT","RIGHT"),"↓","DOWN"),"↑","UP"),"←","LEFT"),"→","RIGHT"),"SPACEBAR","SPACE"),"−","-"),"MINUS","-"),"PLUS","+")=Key!$E$53:$E$53),"✔ CLEAR","✘ TRY AGAIN"))),"✘ TRY AGAIN")} | F14: {=IF(E14="Show hint",Key!$B$53,"")} | G14: {=IF(LEFT(D14,1)="✔",IF(E14="Show hint",5,10),0)} -> 0
A15: W2 | B15: Which keys cut the selection? (from S2-2 Clone Machine) | D15: {=IFERROR(_xlfn.LET(_xlpm.a,'S2-3 Stamps & Smart Fill'!$C$15,IF(TRIM(_xlpm.a&"")="","",IF(OR(SUBSTITUTE(SUBSTITUTE(SUBSTITUTE(SUBSTITUTE(SUBSTITUTE(SUBSTITUTE(SUBSTITUTE(SUBSTITUTE(SUBSTITUTE(SUBSTITUTE(SUBSTITUTE(SUBSTITUTE(SUBSTITUTE(SUBSTITUTE(SUBSTITUTE(SUBSTITUTE(SUBSTITUTE(SUBSTITUTE(SUBSTITUTE(SUBSTITUTE(SUBSTITUTE(SUBSTITUTE(SUBSTITUTE(SUBSTITUTE(SUBSTITUTE(SUBSTITUTE(SUBSTITUTE(UPPER(_xlpm.a)," ",""),"CONTROL","CTRL"),"CTL","CTRL"),"ESCAPE","ESC"),"RETURN","ENTER"),"PAGEDOWN","PGDN"),"PGDOWN","PGDN"),"PAGEUP","PGUP"),"ARROWKEYS","ARROW"),"ARROWKEY","ARROW"),"ARROWS","ARROW"),"DOWNARROW","DOWN"),"UPARROW","UP"),"LEFTARROW","LEFT"),"RIGHTARROW","RIGHT"),"ARROWDOWN","DOWN"),"ARROWUP","UP"),"ARROWLEFT","LEFT"),"ARROWRIGHT","RIGHT"),"↓","DOWN"),"↑","UP"),"←","LEFT"),"→","RIGHT"),"SPACEBAR","SPACE"),"−","-"),"MINUS","-"),"PLUS","+")=Key!$E$54:$E$54),"✔ CLEAR","✘ TRY AGAIN"))),"✘ TRY AGAIN")} | F15: {=IF(E15="Show hint",Key!$B$54,"")} | G15: {=IF(LEFT(D15,1)="✔",IF(E15="Show hint",5,10),0)} -> 0
A16: W3 | B16: Which keys paste? (from S2-2 Clone Machine) | D16: {=IFERROR(_xlfn.LET(_xlpm.a,'S2-3 Stamps & Smart Fill'!$C$16,IF(TRIM(_xlpm.a&"")="","",IF(OR(SUBSTITUTE(SUBSTITUTE(SUBSTITUTE(SUBSTITUTE(SUBSTITUTE(SUBSTITUTE(SUBSTITUTE(SUBSTITUTE(SUBSTITUTE(SUBSTITUTE(SUBSTITUTE(SUBSTITUTE(SUBSTITUTE(SUBSTITUTE(SUBSTITUTE(SUBSTITUTE(SUBSTITUTE(SUBSTITUTE(SUBSTITUTE(SUBSTITUTE(SUBSTITUTE(SUBSTITUTE(SUBSTITUTE(SUBSTITUTE(SUBSTITUTE(SUBSTITUTE(SUBSTITUTE(UPPER(_xlpm.a)," ",""),"CONTROL","CTRL"),"CTL","CTRL"),"ESCAPE","ESC"),"RETURN","ENTER"),"PAGEDOWN","PGDN"),"PGDOWN","PGDN"),"PAGEUP","PGUP"),"ARROWKEYS","ARROW"),"ARROWKEY","ARROW"),"ARROWS","ARROW"),"DOWNARROW","DOWN"),"UPARROW","UP"),"LEFTARROW","LEFT"),"RIGHTARROW","RIGHT"),"ARROWDOWN","DOWN"),"ARROWUP","UP"),"ARROWLEFT","LEFT"),"ARROWRIGHT","RIGHT"),"↓","DOWN"),"↑","UP"),"←","LEFT"),"→","RIGHT"),"SPACEBAR","SPACE"),"−","-"),"MINUS","-"),"PLUS","+")=Key!$E$55:$E$55),"✔ CLEAR","✘ TRY AGAIN"))),"✘ TRY AGAIN")} | F16: {=IF(E16="Show hint",Key!$B$55,"")} | G16: {=IF(LEFT(D16,1)="✔",IF(E16="Show hint",5,10),0)} -> 0
A17: W4 | B17: Which keys open Paste Special? (from S2-2 Clone Machine) | D17: {=IFERROR(_xlfn.LET(_xlpm.a,'S2-3 Stamps & Smart Fill'!$C$17,IF(TRIM(_xlpm.a&"")="","",IF(OR(SUBSTITUTE(SUBSTITUTE(SUBSTITUTE(SUBSTITUTE(SUBSTITUTE(SUBSTITUTE(SUBSTITUTE(SUBSTITUTE(SUBSTITUTE(SUBSTITUTE(SUBSTITUTE(SUBSTITUTE(SUBSTITUTE(SUBSTITUTE(SUBSTITUTE(SUBSTITUTE(SUBSTITUTE(SUBSTITUTE(SUBSTITUTE(SUBSTITUTE(SUBSTITUTE(SUBSTITUTE(SUBSTITUTE(SUBSTITUTE(SUBSTITUTE(SUBSTITUTE(SUBSTITUTE(UPPER(_xlpm.a)," ",""),"CONTROL","CTRL"),"CTL","CTRL"),"ESCAPE","ESC"),"RETURN","ENTER"),"PAGEDOWN","PGDN"),"PGDOWN","PGDN"),"PAGEUP","PGUP"),"ARROWKEYS","ARROW"),"ARROWKEY","ARROW"),"ARROWS","ARROW"),"DOWNARROW","DOWN"),"UPARROW","UP"),"LEFTARROW","LEFT"),"RIGHTARROW","RIGHT"),"ARROWDOWN","DOWN"),"ARROWUP","UP"),"ARROWLEFT","LEFT"),"ARROWRIGHT","RIGHT"),"↓","DOWN"),"↑","UP"),"←","LEFT"),"→","RIGHT"),"SPACEBAR","SPACE"),"−","-"),"MINUS","-"),"PLUS","+")=Key!$E$56:$F$56),"✔ CLEAR","✘ TRY AGAIN"))),"✘ TRY AGAIN")} | F17: {=IF(E17="Show hint",Key!$B$56,"")} | G17: {=IF(LEFT(D17,1)="✔",IF(E17="Show hint",5,10),0)} -> 0
A18: W5 | B18: Which keys copy the left cell into the selected cells to its right? (from S2-2 Clone Machine) | D18: {=IFERROR(_xlfn.LET(_xlpm.a,'S2-3 Stamps & Smart Fill'!$C$18,IF(TRIM(_xlpm.a&"")="","",IF(OR(SUBSTITUTE(SUBSTITUTE(SUBSTITUTE(SUBSTITUTE(SUBSTITUTE(SUBSTITUTE(SUBSTITUTE(SUBSTITUTE(SUBSTITUTE(SUBSTITUTE(SUBSTITUTE(SUBSTITUTE(SUBSTITUTE(SUBSTITUTE(SUBSTITUTE(SUBSTITUTE(SUBSTITUTE(SUBSTITUTE(SUBSTITUTE(SUBSTITUTE(SUBSTITUTE(SUBSTITUTE(SUBSTITUTE(SUBSTITUTE(SUBSTITUTE(SUBSTITUTE(SUBSTITUTE(UPPER(_xlpm.a)," ",""),"CONTROL","CTRL"),"CTL","CTRL"),"ESCAPE","ESC"),"RETURN","ENTER"),"PAGEDOWN","PGDN"),"PGDOWN","PGDN"),"PAGEUP","PGUP"),"ARROWKEYS","ARROW"),"ARROWKEY","ARROW"),"ARROWS","ARROW"),"DOWNARROW","DOWN"),"UPARROW","UP"),"LEFTARROW","LEFT"),"RIGHTARROW","RIGHT"),"ARROWDOWN","DOWN"),"ARROWUP","UP"),"ARROWLEFT","LEFT"),"ARROWRIGHT","RIGHT"),"↓","DOWN"),"↑","UP"),"←","LEFT"),"→","RIGHT"),"SPACEBAR","SPACE"),"−","-"),"MINUS","-"),"PLUS","+")=Key!$E$57:$E$57),"✔ CLEAR","✘ TRY AGAIN"))),"✘ TRY AGAIN")} | F18: {=IF(E18="Show hint",Key!$B$57,"")} | G18: {=IF(LEFT(D18,1)="✔",IF(E18="Show hint",5,10),0)} -> 0
A19: W6 | B19: Which keys undo the last action? (from S2-2 Clone Machine) | D19: {=IFERROR(_xlfn.LET(_xlpm.a,'S2-3 Stamps & Smart Fill'!$C$19,IF(TRIM(_xlpm.a&"")="","",IF(OR(SUBSTITUTE(SUBSTITUTE(SUBSTITUTE(SUBSTITUTE(SUBSTITUTE(SUBSTITUTE(SUBSTITUTE(SUBSTITUTE(SUBSTITUTE(SUBSTITUTE(SUBSTITUTE(SUBSTITUTE(SUBSTITUTE(SUBSTITUTE(SUBSTITUTE(SUBSTITUTE(SUBSTITUTE(SUBSTITUTE(SUBSTITUTE(SUBSTITUTE(SUBSTITUTE(SUBSTITUTE(SUBSTITUTE(SUBSTITUTE(SUBSTITUTE(SUBSTITUTE(SUBSTITUTE(UPPER(_xlpm.a)," ",""),"CONTROL","CTRL"),"CTL","CTRL"),"ESCAPE","ESC"),"RETURN","ENTER"),"PAGEDOWN","PGDN"),"PGDOWN","PGDN"),"PAGEUP","PGUP"),"ARROWKEYS","ARROW"),"ARROWKEY","ARROW"),"ARROWS","ARROW"),"DOWNARROW","DOWN"),"UPARROW","UP"),"LEFTARROW","LEFT"),"RIGHTARROW","RIGHT"),"ARROWDOWN","DOWN"),"ARROWUP","UP"),"ARROWLEFT","LEFT"),"ARROWRIGHT","RIGHT"),"↓","DOWN"),"↑","UP"),"←","LEFT"),"→","RIGHT"),"SPACEBAR","SPACE"),"−","-"),"MINUS","-"),"PLUS","+")=Key!$E$58:$E$58),"✔ CLEAR","✘ TRY AGAIN"))),"✘ TRY AGAIN")} | F19: {=IF(E19="Show hint",Key!$B$58,"")} | G19: {=IF(LEFT(D19,1)="✔",IF(E19="Show hint",5,10),0)} -> 0
A20: W7 | B20: Which keys redo or repeat the last action? (from S2-2 Clone Machine) | D20: {=IFERROR(_xlfn.LET(_xlpm.a,'S2-3 Stamps & Smart Fill'!$C$20,IF(TRIM(_xlpm.a&"")="","",IF(OR(SUBSTITUTE(SUBSTITUTE(SUBSTITUTE(SUBSTITUTE(SUBSTITUTE(SUBSTITUTE(SUBSTITUTE(SUBSTITUTE(SUBSTITUTE(SUBSTITUTE(SUBSTITUTE(SUBSTITUTE(SUBSTITUTE(SUBSTITUTE(SUBSTITUTE(SUBSTITUTE(SUBSTITUTE(SUBSTITUTE(SUBSTITUTE(SUBSTITUTE(SUBSTITUTE(SUBSTITUTE(SUBSTITUTE(SUBSTITUTE(SUBSTITUTE(SUBSTITUTE(SUBSTITUTE(UPPER(_xlpm.a)," ",""),"CONTROL","CTRL"),"CTL","CTRL"),"ESCAPE","ESC"),"RETURN","ENTER"),"PAGEDOWN","PGDN"),"PGDOWN","PGDN"),"PAGEUP","PGUP"),"ARROWKEYS","ARROW"),"ARROWKEY","ARROW"),"ARROWS","ARROW"),"DOWNARROW","DOWN"),"UPARROW","UP"),"LEFTARROW","LEFT"),"RIGHTARROW","RIGHT"),"ARROWDOWN","DOWN"),"ARROWUP","UP"),"ARROWLEFT","LEFT"),"ARROWRIGHT","RIGHT"),"↓","DOWN"),"↑","UP"),"←","LEFT"),"→","RIGHT"),"SPACEBAR","SPACE"),"−","-"),"MINUS","-"),"PLUS","+")=Key!$E$59:$E$59),"✔ CLEAR","✘ TRY AGAIN"))),"✘ TRY AGAIN")} | F20: {=IF(E20="Show hint",Key!$B$59,"")} | G20: {=IF(LEFT(D20,1)="✔",IF(E20="Show hint",5,10),0)} -> 0
A21: W8 | B21: Which keys switch between showing results and showing formulas? (from F1-5 X-Ray) | D21: {=IFERROR(_xlfn.LET(_xlpm.a,'S2-3 Stamps & Smart Fill'!$C$21,IF(TRIM(_xlpm.a&"")="","",IF(OR(SUBSTITUTE(SUBSTITUTE(SUBSTITUTE(SUBSTITUTE(SUBSTITUTE(SUBSTITUTE(SUBSTITUTE(SUBSTITUTE(SUBSTITUTE(SUBSTITUTE(SUBSTITUTE(SUBSTITUTE(SUBSTITUTE(SUBSTITUTE(SUBSTITUTE(SUBSTITUTE(SUBSTITUTE(SUBSTITUTE(SUBSTITUTE(SUBSTITUTE(SUBSTITUTE(SUBSTITUTE(SUBSTITUTE(SUBSTITUTE(SUBSTITUTE(SUBSTITUTE(SUBSTITUTE(UPPER(_xlpm.a)," ",""),"CONTROL","CTRL"),"CTL","CTRL"),"ESCAPE","ESC"),"RETURN","ENTER"),"PAGEDOWN","PGDN"),"PGDOWN","PGDN"),"PAGEUP","PGUP"),"ARROWKEYS","ARROW"),"ARROWKEY","ARROW"),"ARROWS","ARROW"),"DOWNARROW","DOWN"),"UPARROW","UP"),"LEFTARROW","LEFT"),"RIGHTARROW","RIGHT"),"ARROWDOWN","DOWN"),"ARROWUP","UP"),"ARROWLEFT","LEFT"),"ARROWRIGHT","RIGHT"),"↓","DOWN"),"↑","UP"),"←","LEFT"),"→","RIGHT"),"SPACEBAR","SPACE"),"−","-"),"MINUS","-"),"PLUS","+")=Key!$E$60:$H$60),"✔ CLEAR","✘ TRY AGAIN"))),"✘ TRY AGAIN")} | F21: {=IF(E21="Show hint",Key!$B$60,"")} | G21: {=IF(LEFT(D21,1)="✔",IF(E21="Show hint",5,10),0)} -> 0
A22: W9 | B22: Which key edits the active cell and color-codes its references? (from F1-5 X-Ray) | D22: {=IFERROR(_xlfn.LET(_xlpm.a,'S2-3 Stamps & Smart Fill'!$C$22,IF(TRIM(_xlpm.a&"")="","",IF(OR(SUBSTITUTE(SUBSTITUTE(SUBSTITUTE(SUBSTITUTE(SUBSTITUTE(SUBSTITUTE(SUBSTITUTE(SUBSTITUTE(SUBSTITUTE(SUBSTITUTE(SUBSTITUTE(SUBSTITUTE(SUBSTITUTE(SUBSTITUTE(SUBSTITUTE(SUBSTITUTE(SUBSTITUTE(SUBSTITUTE(SUBSTITUTE(SUBSTITUTE(SUBSTITUTE(SUBSTITUTE(SUBSTITUTE(SUBSTITUTE(SUBSTITUTE(SUBSTITUTE(SUBSTITUTE(UPPER(_xlpm.a)," ",""),"CONTROL","CTRL"),"CTL","CTRL"),"ESCAPE","ESC"),"RETURN","ENTER"),"PAGEDOWN","PGDN"),"PGDOWN","PGDN"),"PAGEUP","PGUP"),"ARROWKEYS","ARROW"),"ARROWKEY","ARROW"),"ARROWS","ARROW"),"DOWNARROW","DOWN"),"UPARROW","UP"),"LEFTARROW","LEFT"),"RIGHTARROW","RIGHT"),"ARROWDOWN","DOWN"),"ARROWUP","UP"),"ARROWLEFT","LEFT"),"ARROWRIGHT","RIGHT"),"↓","DOWN"),"↑","UP"),"←","LEFT"),"→","RIGHT"),"SPACEBAR","SPACE"),"−","-"),"MINUS","-"),"PLUS","+")=Key!$E$61:$E$61),"✔ CLEAR","✘ TRY AGAIN"))),"✘ TRY AGAIN")} | F22: {=IF(E22="Show hint",Key!$B$61,"")} | G22: {=IF(LEFT(D22,1)="✔",IF(E22="Show hint",5,10),0)} -> 0
A23: W10 | B23: While typing a function name, which key inserts the highlighted AutoComplete suggestion? (from F1-5 X-Ray) | D23: {=IFERROR(_xlfn.LET(_xlpm.a,'S2-3 Stamps & Smart Fill'!$C$23,IF(TRIM(_xlpm.a&"")="","",IF(OR(SUBSTITUTE(SUBSTITUTE(SUBSTITUTE(SUBSTITUTE(SUBSTITUTE(SUBSTITUTE(SUBSTITUTE(SUBSTITUTE(SUBSTITUTE(SUBSTITUTE(SUBSTITUTE(SUBSTITUTE(SUBSTITUTE(SUBSTITUTE(SUBSTITUTE(SUBSTITUTE(SUBSTITUTE(SUBSTITUTE(SUBSTITUTE(SUBSTITUTE(SUBSTITUTE(SUBSTITUTE(SUBSTITUTE(SUBSTITUTE(SUBSTITUTE(SUBSTITUTE(SUBSTITUTE(UPPER(_xlpm.a)," ",""),"CONTROL","CTRL"),"CTL","CTRL"),"ESCAPE","ESC"),"RETURN","ENTER"),"PAGEDOWN","PGDN"),"PGDOWN","PGDN"),"PAGEUP","PGUP"),"ARROWKEYS","ARROW"),"ARROWKEY","ARROW"),"ARROWS","ARROW"),"DOWNARROW","DOWN"),"UPARROW","UP"),"LEFTARROW","LEFT"),"RIGHTARROW","RIGHT"),"ARROWDOWN","DOWN"),"ARROWUP","UP"),"ARROWLEFT","LEFT"),"ARROWRIGHT","RIGHT"),"↓","DOWN"),"↑","UP"),"←","LEFT"),"→","RIGHT"),"SPACEBAR","SPACE"),"−","-"),"MINUS","-"),"PLUS","+")=Key!$E$62:$E$62),"✔ CLEAR","✘ TRY AGAIN"))),"✘ TRY AGAIN")} | F23: {=IF(E23="Show hint",Key!$B$62,"")} | G23: {=IF(LEFT(D23,1)="✔",IF(E23="Show hint",5,10),0)} -> 0
A25: TRAINING · recognize the move (pick from the list)
A26: # | B26: Mission | C26: Your answer | D26: Result | E26: Hint? | F26: Hint | G26: XP
A27: T1 | B27: Which keys type today's date as a fixed value? | D27: {=IFERROR(IF('S2-3 Stamps & Smart Fill'!$C$27&""="","",IF('S2-3 Stamps & Smart Fill'!$C$27&""=Key!$C$63&"","✔ CLEAR","✘ TRY AGAIN")),"✘ TRY AGAIN")} | F27: {=IF(E27="Show hint",Key!$B$63,"")} | G27: {=IF(LEFT(D27,1)="✔",IF(E27="Show hint",5,10),0)} -> 0
A28: T2 | B28: Which keys type the current time as a fixed value? | D28: {=IFERROR(IF('S2-3 Stamps & Smart Fill'!$C$28&""="","",IF('S2-3 Stamps & Smart Fill'!$C$28&""=Key!$C$64&"","✔ CLEAR","✘ TRY AGAIN")),"✘ TRY AGAIN")} | F28: {=IF(E28="Show hint",Key!$B$64,"")} | G28: {=IF(LEFT(D28,1)="✔",IF(E28="Show hint",5,10),0)} -> 0
A29: T3 | B29: Which keys run Flash Fill? | D29: {=IFERROR(IF('S2-3 Stamps & Smart Fill'!$C$29&""="","",IF('S2-3 Stamps & Smart Fill'!$C$29&""=Key!$C$65&"","✔ CLEAR","✘ TRY AGAIN")),"✘ TRY AGAIN")} | F29: {=IF(E29="Show hint",Key!$B$65,"")} | G29: {=IF(LEFT(D29,1)="✔",IF(E29="Show hint",5,10),0)} -> 0
A30: T4 | B30: Which keys open the dropdown list of a cell? | D30: {=IFERROR(IF('S2-3 Stamps & Smart Fill'!$C$30&""="","",IF('S2-3 Stamps & Smart Fill'!$C$30&""=Key!$C$66&"","✔ CLEAR","✘ TRY AGAIN")),"✘ TRY AGAIN")} | F30: {=IF(E30="Show hint",Key!$B$66,"")} | G30: {=IF(LEFT(D30,1)="✔",IF(E30="Show hint",5,10),0)} -> 0
A32: CHALLENGES · recall it, then do it
B33: ▶ Open S2-3 Arena (or press Ctrl+PgDn)
A34: # | B34: Mission | C34: Your answer | D34: Result | E34: Hint? | F34: Hint | G34: XP
