Workbook

Sheet Start
A1: FORMULAS 2 ▸ LOGIC
A2: Make formulas decide: comparisons, IF, AND/OR/NOT, IFS and error shields.
A4: HOW TO PLAY
A5: 1 · Each stage: read the BRIEFING, then answer WARM-UP, TRAINING and CHALLENGES.
A6: 2 · Yellow cells are yours: type, pick from a list (Alt+↓), or follow a ▶ ARENA link and do the move there.
A7: 3 · ✔ CLEAR = right · ✘ = try again · · not yet = drill not done. Stuck? Pick 'Show hint' (5 XP instead of 10).
A8: 4 · Formatting or hiding drills: press F9 to refresh the check. Tab jumps between yellow cells.
A9: Needs Windows with Microsoft Excel 365 or 2021+ (English). In Protected View, click Enable Editing.
A11: STAGE SELECT
A12: Stage | B12: Name | C12: Score | D12: Stars | E12: Status | F12: Go
A13: F2-1 | B13: True or False | C13: {=SUM('F2-1 True or False'!$G$13:$G$38)&" / 190"} -> 0 / 190 | D13: {=IF(SUM('F2-1 True or False'!$G$13:$G$38)>=190,"★★★",IF(SUM('F2-1 True or False'!$G$13:$G$38)>=190*0.8,"★★☆",IF(SUM('F2-1 True or False'!$G$13:$G$38)>=190*0.5,"★☆☆","☆☆☆")))} -> ☆☆☆ | E13: {=IF(SUM('F2-1 True or False'!$G$13:$G$38)>=190,"PERFECT",IF(SUM('F2-1 True or False'!$G$13:$G$38)>=190*0.5,"CLEARED",IF(SUM('F2-1 True or False'!$G$13:$G$38)>0,"IN PROGRESS","NEW")))} -> NEW | F13: Go to F2-1 True or False
A14: F2-2 | B14: Fork in the Road | C14: {=SUM('F2-2 Fork in the Road'!$G$13:$G$38)&" / 190"} -> 0 / 190 | D14: {=IF(SUM('F2-2 Fork in the Road'!$G$13:$G$38)>=190,"★★★",IF(SUM('F2-2 Fork in the Road'!$G$13:$G$38)>=190*0.8,"★★☆",IF(SUM('F2-2 Fork in the Road'!$G$13:$G$38)>=190*0.5,"★☆☆","☆☆☆")))} -> ☆☆☆ | E14: {=IF(SUM('F2-2 Fork in the Road'!$G$13:$G$38)>=190,"PERFECT",IF(SUM('F2-2 Fork in the Road'!$G$13:$G$38)>=190*0.5,"CLEARED",IF(SUM('F2-2 Fork in the Road'!$G$13:$G$38)>0,"IN PROGRESS","NEW")))} -> NEW | F14: Go to F2-2 Fork in the Road
A15: F2-3 | B15: Combo Moves | C15: {=SUM('F2-3 Combo Moves'!$G$13:$G$38)&" / 190"} -> 0 / 190 | D15: {=IF(SUM('F2-3 Combo Moves'!$G$13:$G$38)>=190,"★★★",IF(SUM('F2-3 Combo Moves'!$G$13:$G$38)>=190*0.8,"★★☆",IF(SUM('F2-3 Combo Moves'!$G$13:$G$38)>=190*0.5,"★☆☆","☆☆☆")))} -> ☆☆☆ | E15: {=IF(SUM('F2-3 Combo Moves'!$G$13:$G$38)>=190,"PERFECT",IF(SUM('F2-3 Combo Moves'!$G$13:$G$38)>=190*0.5,"CLEARED",IF(SUM('F2-3 Combo Moves'!$G$13:$G$38)>0,"IN PROGRESS","NEW")))} -> NEW | F15: Go to F2-3 Combo Moves
A16: F2-4 | B16: Multi-Level | C16: {=SUM('F2-4 Multi-Level'!$G$13:$G$38)&" / 190"} -> 0 / 190 | D16: {=IF(SUM('F2-4 Multi-Level'!$G$13:$G$38)>=190,"★★★",IF(SUM('F2-4 Multi-Level'!$G$13:$G$38)>=190*0.8,"★★☆",IF(SUM('F2-4 Multi-Level'!$G$13:$G$38)>=190*0.5,"★☆☆","☆☆☆")))} -> ☆☆☆ | E16: {=IF(SUM('F2-4 Multi-Level'!$G$13:$G$38)>=190,"PERFECT",IF(SUM('F2-4 Multi-Level'!$G$13:$G$38)>=190*0.5,"CLEARED",IF(SUM('F2-4 Multi-Level'!$G$13:$G$38)>0,"IN PROGRESS","NEW")))} -> NEW | F16: Go to F2-4 Multi-Level
A17: F2-5 | B17: Error Shield | C17: {=SUM('F2-5 Error Shield'!$G$14:$G$42)&" / 220"} -> 0 / 220 | D17: {=IF(SUM('F2-5 Error Shield'!$G$14:$G$42)>=220,"★★★",IF(SUM('F2-5 Error Shield'!$G$14:$G$42)>=220*0.8,"★★☆",IF(SUM('F2-5 Error Shield'!$G$14:$G$42)>=220*0.5,"★☆☆","☆☆☆")))} -> ☆☆☆ | E17: {=IF(SUM('F2-5 Error Shield'!$G$14:$G$42)>=220,"PERFECT",IF(SUM('F2-5 Error Shield'!$G$14:$G$42)>=220*0.5,"CLEARED",IF(SUM('F2-5 Error Shield'!$G$14:$G$42)>0,"IN PROGRESS","NEW")))} -> NEW | F17: Go to F2-5 Error Shield
A18: BOSS | B18: Boss | C18: {=SUM(Boss!$G$14:$G$33)&" / 160"} -> 0 / 160 | D18: {=IF(SUM(Boss!$G$14:$G$33)>=160,"★★★",IF(SUM(Boss!$G$14:$G$33)>=160*0.8,"★★☆",IF(SUM(Boss!$G$14:$G$33)>=160*0.5,"★☆☆","☆☆☆")))} -> ☆☆☆ | E18: {=IF(Boss!$C$10="OPEN",IF(SUM(Boss!$G$14:$G$33)>=160*0.5,"DEFEATED","OPEN"),"LOCKED")} -> LOCKED | F18: Go to the Boss
A20: TOTAL SCORE | B20: {=(SUM('F2-1 True or False'!$G$13:$G$38)+SUM('F2-2 Fork in the Road'!$G$13:$G$38)+SUM('F2-3 Combo Moves'!$G$13:$G$38)+SUM('F2-4 Multi-Level'!$G$13:$G$38)+SUM('F2-5 Error Shield'!$G$14:$G$42)+SUM(Boss!$G$14:$G$33))&" / 1140"} -> 0 / 1140
A21: RANK | B21: {=_xlfn.LET(_xlpm.p,(SUM('F2-1 True or False'!$G$13:$G$38)+SUM('F2-2 Fork in the Road'!$G$13:$G$38)+SUM('F2-3 Combo Moves'!$G$13:$G$38)+SUM('F2-4 Multi-Level'!$G$13:$G$38)+SUM('F2-5 Error Shield'!$G$14:$G$42)+SUM(Boss!$G$14:$G$33))/1140,IF(AND(_xlpm.p>=1,ISNUMBER(Boss!$C$8),Boss!$C$8<=15),"S",IF(_xlpm.p>=0.9,"A",IF(_xlpm.p>=0.75,"B",IF(_xlpm.p>=0.5,"C","D")))))} -> D | C21: S = 100% and under par · A ≥ 90% · B ≥ 75% · C ≥ 50%
A22: BEST TIME | B22: {=IF(ISNUMBER(Boss!$C$8),Boss!$C$8&" min (par 15)","—")} -> —
A23: NEXT UP | B23: {=IFERROR(INDEX($A$13:$A$17,MATCH("☆☆☆",$D$13:$D$17,0))&" "&INDEX($B$13:$B$17,MATCH("☆☆☆",$D$13:$D$17,0)),IF(Boss!$C$10="OPEN","the Boss","All clear! Aim for rank S"))} -> F2-1 True or False
A25: Replay a stage: select its yellow answer cells and press Delete. Undo an arena drill with Ctrl+Z.

Sheet F2-1 True or False
A1: STAGE F2-1 ▸ TRUE OR FALSE
A2: Goal: ask Excel yes-or-no questions
A3: {="SCORE "&TEXT(SUM($G$13:$G$38),"0000")&" / 0190"} -> SCORE 0000 / 0190 | C3: {=IF(SUM($G$13:$G$38)>=190,"★★★",IF(SUM($G$13:$G$38)>=190*0.8,"★★☆",IF(SUM($G$13:$G$38)>=190*0.5,"★☆☆","☆☆☆")))} -> ☆☆☆ | D3: {=REPT("█",ROUND(10*SUM($G$13:$G$38)/190,0))&REPT("░",10-ROUND(10*SUM($G$13:$G$38)/190,0))&" "&TEXT(SUM($G$13:$G$38)/190,"0%")} -> ░░░░░░░░░░ 0% | F3: {=IF(SUM($G$13:$G$38)>=190*0.5,"STAGE CLEAR! ▶ Next: F2-2 Fork in the Road","")}
A5: BRIEFING · new moves in this stage
A6: # | B6: What it does · Pro tip | C6: Keys / Syntax
A7: 1 | B7: Compare two values: = < > <= >= give TRUE or FALSE. Tip: =B2>=50 is TRUE when B2 is 50 or more. | C7: >=
A8: 2 | B8: Not equal to. Tip: =A2<>"Closed" is TRUE for anything except Closed. | C8: <>
A9: 3 | B9: Text inside a formula goes in double quotes. Tip: Comparisons ignore case: ="YES"="yes" is TRUE. | C9: "text"
A11: WARM-UP · flashback to earlier stages
A12: # | B12: Mission | C12: Your answer | D12: Result | E12: Hint? | F12: Hint | G12: XP
A13: W1 | B13: Which keys confirm an entry and move up one cell? (from S2-1 Quick Entry) | D13: {=IFERROR(_xlfn.LET(_xlpm.a,'F2-1 True or False'!$C$13,IF(TRIM(_xlpm.a&"")="","",IF(OR(SUBSTITUTE(SUBSTITUTE(SUBSTITUTE(SUBSTITUTE(SUBSTITUTE(SUBSTITUTE(SUBSTITUTE(SUBSTITUTE(SUBSTITUTE(SUBSTITUTE(SUBSTITUTE(SUBSTITUTE(SUBSTITUTE(SUBSTITUTE(SUBSTITUTE(SUBSTITUTE(SUBSTITUTE(SUBSTITUTE(SUBSTITUTE(SUBSTITUTE(SUBSTITUTE(SUBSTITUTE(SUBSTITUTE(SUBSTITUTE(SUBSTITUTE(SUBSTITUTE(SUBSTITUTE(UPPER(_xlpm.a)," ",""),"CONTROL","CTRL"),"CTL","CTRL"),"ESCAPE","ESC"),"RETURN","ENTER"),"PAGEDOWN","PGDN"),"PGDOWN","PGDN"),"PAGEUP","PGUP"),"ARROWKEYS","ARROW"),"ARROWKEY","ARROW"),"ARROWS","ARROW"),"DOWNARROW","DOWN"),"UPARROW","UP"),"LEFTARROW","LEFT"),"RIGHTARROW","RIGHT"),"ARROWDOWN","DOWN"),"ARROWUP","UP"),"ARROWLEFT","LEFT"),"ARROWRIGHT","RIGHT"),"↓","DOWN"),"↑","UP"),"←","LEFT"),"→","RIGHT"),"SPACEBAR","SPACE"),"−","-"),"MINUS","-"),"PLUS","+")=Key!$E$2:$E$2),"✔ CLEAR","✘ TRY AGAIN"))),"✘ TRY AGAIN")} | F13: {=IF(E13="Show hint",Key!$B$2,"")} | G13: {=IF(LEFT(D13,1)="✔",IF(E13="Show hint",5,10),0)} -> 0
A14: W2 | B14: Which key confirms an entry and moves one cell to the right? (from S2-1 Quick Entry) | D14: {=IFERROR(_xlfn.LET(_xlpm.a,'F2-1 True or False'!$C$14,IF(TRIM(_xlpm.a&"")="","",IF(OR(SUBSTITUTE(SUBSTITUTE(SUBSTITUTE(SUBSTITUTE(SUBSTITUTE(SUBSTITUTE(SUBSTITUTE(SUBSTITUTE(SUBSTITUTE(SUBSTITUTE(SUBSTITUTE(SUBSTITUTE(SUBSTITUTE(SUBSTITUTE(SUBSTITUTE(SUBSTITUTE(SUBSTITUTE(SUBSTITUTE(SUBSTITUTE(SUBSTITUTE(SUBSTITUTE(SUBSTITUTE(SUBSTITUTE(SUBSTITUTE(SUBSTITUTE(SUBSTITUTE(SUBSTITUTE(UPPER(_xlpm.a)," ",""),"CONTROL","CTRL"),"CTL","CTRL"),"ESCAPE","ESC"),"RETURN","ENTER"),"PAGEDOWN","PGDN"),"PGDOWN","PGDN"),"PAGEUP","PGUP"),"ARROWKEYS","ARROW"),"ARROWKEY","ARROW"),"ARROWS","ARROW"),"DOWNARROW","DOWN"),"UPARROW","UP"),"LEFTARROW","LEFT"),"RIGHTARROW","RIGHT"),"ARROWDOWN","DOWN"),"ARROWUP","UP"),"ARROWLEFT","LEFT"),"ARROWRIGHT","RIGHT"),"↓","DOWN"),"↑","UP"),"←","LEFT"),"→","RIGHT"),"SPACEBAR","SPACE"),"−","-"),"MINUS","-"),"PLUS","+")=Key!$E$3:$E$3),"✔ CLEAR","✘ TRY AGAIN"))),"✘ TRY AGAIN")} | F14: {=IF(E14="Show hint",Key!$B$3,"")} | G14: {=IF(LEFT(D14,1)="✔",IF(E14="Show hint",5,10),0)} -> 0
A15: W3 | B15: Which keys fill every selected cell with what you typed? (from S2-1 Quick Entry) | D15: {=IFERROR(_xlfn.LET(_xlpm.a,'F2-1 True or False'!$C$15,IF(TRIM(_xlpm.a&"")="","",IF(OR(SUBSTITUTE(SUBSTITUTE(SUBSTITUTE(SUBSTITUTE(SUBSTITUTE(SUBSTITUTE(SUBSTITUTE(SUBSTITUTE(SUBSTITUTE(SUBSTITUTE(SUBSTITUTE(SUBSTITUTE(SUBSTITUTE(SUBSTITUTE(SUBSTITUTE(SUBSTITUTE(SUBSTITUTE(SUBSTITUTE(SUBSTITUTE(SUBSTITUTE(SUBSTITUTE(SUBSTITUTE(SUBSTITUTE(SUBSTITUTE(SUBSTITUTE(SUBSTITUTE(SUBSTITUTE(UPPER(_xlpm.a)," ",""),"CONTROL","CTRL"),"CTL","CTRL"),"ESCAPE","ESC"),"RETURN","ENTER"),"PAGEDOWN","PGDN"),"PGDOWN","PGDN"),"PAGEUP","PGUP"),"ARROWKEYS","ARROW"),"ARROWKEY","ARROW"),"ARROWS","ARROW"),"DOWNARROW","DOWN"),"UPARROW","UP"),"LEFTARROW","LEFT"),"RIGHTARROW","RIGHT"),"ARROWDOWN","DOWN"),"ARROWUP","UP"),"ARROWLEFT","LEFT"),"ARROWRIGHT","RIGHT"),"↓","DOWN"),"↑","UP"),"←","LEFT"),"→","RIGHT"),"SPACEBAR","SPACE"),"−","-"),"MINUS","-"),"PLUS","+")=Key!$E$4:$E$4),"✔ CLEAR","✘ TRY AGAIN"))),"✘ TRY AGAIN")} | F15: {=IF(E15="Show hint",Key!$B$4,"")} | G15: {=IF(LEFT(D15,1)="✔",IF(E15="Show hint",5,10),0)} -> 0
A16: W4 | B16: Which keys start a new line inside the same cell? (from S2-1 Quick Entry) | D16: {=IFERROR(_xlfn.LET(_xlpm.a,'F2-1 True or False'!$C$16,IF(TRIM(_xlpm.a&"")="","",IF(OR(SUBSTITUTE(SUBSTITUTE(SUBSTITUTE(SUBSTITUTE(SUBSTITUTE(SUBSTITUTE(SUBSTITUTE(SUBSTITUTE(SUBSTITUTE(SUBSTITUTE(SUBSTITUTE(SUBSTITUTE(SUBSTITUTE(SUBSTITUTE(SUBSTITUTE(SUBSTITUTE(SUBSTITUTE(SUBSTITUTE(SUBSTITUTE(SUBSTITUTE(SUBSTITUTE(SUBSTITUTE(SUBSTITUTE(SUBSTITUTE(SUBSTITUTE(SUBSTITUTE(SUBSTITUTE(UPPER(_xlpm.a)," ",""),"CONTROL","CTRL"),"CTL","CTRL"),"ESCAPE","ESC"),"RETURN","ENTER"),"PAGEDOWN","PGDN"),"PGDOWN","PGDN"),"PAGEUP","PGUP"),"ARROWKEYS","ARROW"),"ARROWKEY","ARROW"),"ARROWS","ARROW"),"DOWNARROW","DOWN"),"UPARROW","UP"),"LEFTARROW","LEFT"),"RIGHTARROW","RIGHT"),"ARROWDOWN","DOWN"),"ARROWUP","UP"),"ARROWLEFT","LEFT"),"ARROWRIGHT","RIGHT"),"↓","DOWN"),"↑","UP"),"←","LEFT"),"→","RIGHT"),"SPACEBAR","SPACE"),"−","-"),"MINUS","-"),"PLUS","+")=Key!$E$5:$E$5),"✔ CLEAR","✘ TRY AGAIN"))),"✘ TRY AGAIN")} | F16: {=IF(E16="Show hint",Key!$B$5,"")} | G16: {=IF(LEFT(D16,1)="✔",IF(E16="Show hint",5,10),0)} -> 0
A17: W5 | B17: Which key cancels an entry and leaves the cell unchanged? (from S2-1 Quick Entry) | D17: {=IFERROR(_xlfn.LET(_xlpm.a,'F2-1 True or False'!$C$17,IF(TRIM(_xlpm.a&"")="","",IF(OR(SUBSTITUTE(SUBSTITUTE(SUBSTITUTE(SUBSTITUTE(SUBSTITUTE(SUBSTITUTE(SUBSTITUTE(SUBSTITUTE(SUBSTITUTE(SUBSTITUTE(SUBSTITUTE(SUBSTITUTE(SUBSTITUTE(SUBSTITUTE(SUBSTITUTE(SUBSTITUTE(SUBSTITUTE(SUBSTITUTE(SUBSTITUTE(SUBSTITUTE(SUBSTITUTE(SUBSTITUTE(SUBSTITUTE(SUBSTITUTE(SUBSTITUTE(SUBSTITUTE(SUBSTITUTE(UPPER(_xlpm.a)," ",""),"CONTROL","CTRL"),"CTL","CTRL"),"ESCAPE","ESC"),"RETURN","ENTER"),"PAGEDOWN","PGDN"),"PGDOWN","PGDN"),"PAGEUP","PGUP"),"ARROWKEYS","ARROW"),"ARROWKEY","ARROW"),"ARROWS","ARROW"),"DOWNARROW","DOWN"),"UPARROW","UP"),"LEFTARROW","LEFT"),"RIGHTARROW","RIGHT"),"ARROWDOWN","DOWN"),"ARROWUP","UP"),"ARROWLEFT","LEFT"),"ARROWRIGHT","RIGHT"),"↓","DOWN"),"↑","UP"),"←","LEFT"),"→","RIGHT"),"SPACEBAR","SPACE"),"−","-"),"MINUS","-"),"PLUS","+")=Key!$E$6:$E$6),"✔ CLEAR","✘ TRY AGAIN"))),"✘ TRY AGAIN")} | F17: {=IF(E17="Show hint",Key!$B$6,"")} | G17: {=IF(LEFT(D17,1)="✔",IF(E17="Show hint",5,10),0)} -> 0
A18: W6 | B18: Which keys move to the previous sheet? (from S1-2 Teleport) | D18: {=IFERROR(_xlfn.LET(_xlpm.a,'F2-1 True or False'!$C$18,IF(TRIM(_xlpm.a&"")="","",IF(OR(SUBSTITUTE(SUBSTITUTE(SUBSTITUTE(SUBSTITUTE(SUBSTITUTE(SUBSTITUTE(SUBSTITUTE(SUBSTITUTE(SUBSTITUTE(SUBSTITUTE(SUBSTITUTE(SUBSTITUTE(SUBSTITUTE(SUBSTITUTE(SUBSTITUTE(SUBSTITUTE(SUBSTITUTE(SUBSTITUTE(SUBSTITUTE(SUBSTITUTE(SUBSTITUTE(SUBSTITUTE(SUBSTITUTE(SUBSTITUTE(SUBSTITUTE(SUBSTITUTE(SUBSTITUTE(UPPER(_xlpm.a)," ",""),"CONTROL","CTRL"),"CTL","CTRL"),"ESCAPE","ESC"),"RETURN","ENTER"),"PAGEDOWN","PGDN"),"PGDOWN","PGDN"),"PAGEUP","PGUP"),"ARROWKEYS","ARROW"),"ARROWKEY","ARROW"),"ARROWS","ARROW"),"DOWNARROW","DOWN"),"UPARROW","UP"),"LEFTARROW","LEFT"),"RIGHTARROW","RIGHT"),"ARROWDOWN","DOWN"),"ARROWUP","UP"),"ARROWLEFT","LEFT"),"ARROWRIGHT","RIGHT"),"↓","DOWN"),"↑","UP"),"←","LEFT"),"→","RIGHT"),"SPACEBAR","SPACE"),"−","-"),"MINUS","-"),"PLUS","+")=Key!$E$7:$E$7),"✔ CLEAR","✘ TRY AGAIN"))),"✘ TRY AGAIN")} | F18: {=IF(E18="Show hint",Key!$B$7,"")} | G18: {=IF(LEFT(D18,1)="✔",IF(E18="Show hint",5,10),0)} -> 0
A19: W7 | B19: Which key scrolls one screen down? (from S1-2 Teleport) | D19: {=IFERROR(_xlfn.LET(_xlpm.a,'F2-1 True or False'!$C$19,IF(TRIM(_xlpm.a&"")="","",IF(OR(SUBSTITUTE(SUBSTITUTE(SUBSTITUTE(SUBSTITUTE(SUBSTITUTE(SUBSTITUTE(SUBSTITUTE(SUBSTITUTE(SUBSTITUTE(SUBSTITUTE(SUBSTITUTE(SUBSTITUTE(SUBSTITUTE(SUBSTITUTE(SUBSTITUTE(SUBSTITUTE(SUBSTITUTE(SUBSTITUTE(SUBSTITUTE(SUBSTITUTE(SUBSTITUTE(SUBSTITUTE(SUBSTITUTE(SUBSTITUTE(SUBSTITUTE(SUBSTITUTE(SUBSTITUTE(UPPER(_xlpm.a)," ",""),"CONTROL","CTRL"),"CTL","CTRL"),"ESCAPE","ESC"),"RETURN","ENTER"),"PAGEDOWN","PGDN"),"PGDOWN","PGDN"),"PAGEUP","PGUP"),"ARROWKEYS","ARROW"),"ARROWKEY","ARROW"),"ARROWS","ARROW"),"DOWNARROW","DOWN"),"UPARROW","UP"),"LEFTARROW","LEFT"),"RIGHTARROW","RIGHT"),"ARROWDOWN","DOWN"),"ARROWUP","UP"),"ARROWLEFT","LEFT"),"ARROWRIGHT","RIGHT"),"↓","DOWN"),"↑","UP"),"←","LEFT"),"→","RIGHT"),"SPACEBAR","SPACE"),"−","-"),"MINUS","-"),"PLUS","+")=Key!$E$8:$E$8),"✔ CLEAR","✘ TRY AGAIN"))),"✘ TRY AGAIN")} | F19: {=IF(E19="Show hint",Key!$B$8,"")} | G19: {=IF(LEFT(D19,1)="✔",IF(E19="Show hint",5,10),0)} -> 0
A20: W8 | B20: Which keys scroll one screen to the right? (from S1-2 Teleport) | D20: {=IFERROR(_xlfn.LET(_xlpm.a,'F2-1 True or False'!$C$20,IF(TRIM(_xlpm.a&"")="","",IF(OR(SUBSTITUTE(SUBSTITUTE(SUBSTITUTE(SUBSTITUTE(SUBSTITUTE(SUBSTITUTE(SUBSTITUTE(SUBSTITUTE(SUBSTITUTE(SUBSTITUTE(SUBSTITUTE(SUBSTITUTE(SUBSTITUTE(SUBSTITUTE(SUBSTITUTE(SUBSTITUTE(SUBSTITUTE(SUBSTITUTE(SUBSTITUTE(SUBSTITUTE(SUBSTITUTE(SUBSTITUTE(SUBSTITUTE(SUBSTITUTE(SUBSTITUTE(SUBSTITUTE(SUBSTITUTE(UPPER(_xlpm.a)," ",""),"CONTROL","CTRL"),"CTL","CTRL"),"ESCAPE","ESC"),"RETURN","ENTER"),"PAGEDOWN","PGDN"),"PGDOWN","PGDN"),"PAGEUP","PGUP"),"ARROWKEYS","ARROW"),"ARROWKEY","ARROW"),"ARROWS","ARROW"),"DOWNARROW","DOWN"),"UPARROW","UP"),"LEFTARROW","LEFT"),"RIGHTARROW","RIGHT"),"ARROWDOWN","DOWN"),"ARROWUP","UP"),"ARROWLEFT","LEFT"),"ARROWRIGHT","RIGHT"),"↓","DOWN"),"↑","UP"),"←","LEFT"),"→","RIGHT"),"SPACEBAR","SPACE"),"−","-"),"MINUS","-"),"PLUS","+")=Key!$E$9:$E$9),"✔ CLEAR","✘ TRY AGAIN"))),"✘ TRY AGAIN")} | F20: {=IF(E20="Show hint",Key!$B$9,"")} | G20: {=IF(LEFT(D20,1)="✔",IF(E20="Show hint",5,10),0)} -> 0
A21: W9 | B21: Which keys grow the selection by one cell? (from S1-3 Lasso) | D21: {=IFERROR(_xlfn.LET(_xlpm.a,'F2-1 True or False'!$C$21,IF(TRIM(_xlpm.a&"")="","",IF(OR(SUBSTITUTE(SUBSTITUTE(SUBSTITUTE(SUBSTITUTE(SUBSTITUTE(SUBSTITUTE(SUBSTITUTE(SUBSTITUTE(SUBSTITUTE(SUBSTITUTE(SUBSTITUTE(SUBSTITUTE(SUBSTITUTE(SUBSTITUTE(SUBSTITUTE(SUBSTITUTE(SUBSTITUTE(SUBSTITUTE(SUBSTITUTE(SUBSTITUTE(SUBSTITUTE(SUBSTITUTE(SUBSTITUTE(SUBSTITUTE(SUBSTITUTE(SUBSTITUTE(SUBSTITUTE(UPPER(_xlpm.a)," ",""),"CONTROL","CTRL"),"CTL","CTRL"),"ESCAPE","ESC"),"RETURN","ENTER"),"PAGEDOWN","PGDN"),"PGDOWN","PGDN"),"PAGEUP","PGUP"),"ARROWKEYS","ARROW"),"ARROWKEY","ARROW"),"ARROWS","ARROW"),"DOWNARROW","DOWN"),"UPARROW","UP"),"LEFTARROW","LEFT"),"RIGHTARROW","RIGHT"),"ARROWDOWN","DOWN"),"ARROWUP","UP"),"ARROWLEFT","LEFT"),"ARROWRIGHT","RIGHT"),"↓","DOWN"),"↑","UP"),"←","LEFT"),"→","RIGHT"),"SPACEBAR","SPACE"),"−","-"),"MINUS","-"),"PLUS","+")=Key!$E$10:$I$10),"✔ CLEAR","✘ TRY AGAIN"))),"✘ TRY AGAIN")} | F21: {=IF(E21="Show hint",Key!$B$10,"")} | G21: {=IF(LEFT(D21,1)="✔",IF(E21="Show hint",5,10),0)} -> 0
A22: W10 | B22: Which keys extend the selection all the way to the edge of the data? (from S1-3 Lasso) | D22: {=IFERROR(_xlfn.LET(_xlpm.a,'F2-1 True or False'!$C$22,IF(TRIM(_xlpm.a&"")="","",IF(OR(SUBSTITUTE(SUBSTITUTE(SUBSTITUTE(SUBSTITUTE(SUBSTITUTE(SUBSTITUTE(SUBSTITUTE(SUBSTITUTE(SUBSTITUTE(SUBSTITUTE(SUBSTITUTE(SUBSTITUTE(SUBSTITUTE(SUBSTITUTE(SUBSTITUTE(SUBSTITUTE(SUBSTITUTE(SUBSTITUTE(SUBSTITUTE(SUBSTITUTE(SUBSTITUTE(SUBSTITUTE(SUBSTITUTE(SUBSTITUTE(SUBSTITUTE(SUBSTITUTE(SUBSTITUTE(UPPER(_xlpm.a)," ",""),"CONTROL","CTRL"),"CTL","CTRL"),"ESCAPE","ESC"),"RETURN","ENTER"),"PAGEDOWN","PGDN"),"PGDOWN","PGDN"),"PAGEUP","PGUP"),"ARROWKEYS","ARROW"),"ARROWKEY","ARROW"),"ARROWS","ARROW"),"DOWNARROW","DOWN"),"UPARROW","UP"),"LEFTARROW","LEFT"),"RIGHTARROW","RIGHT"),"ARROWDOWN","DOWN"),"ARROWUP","UP"),"ARROWLEFT","LEFT"),"ARROWRIGHT","RIGHT"),"↓","DOWN"),"↑","UP"),"←","LEFT"),"→","RIGHT"),"SPACEBAR","SPACE"),"−","-"),"MINUS","-"),"PLUS","+")=Key!$E$11:$N$11),"✔ CLEAR","✘ TRY AGAIN"))),"✘ TRY AGAIN")} | F22: {=IF(E22="Show hint",Key!$B$11,"")} | G22: {=IF(LEFT(D22,1)="✔",IF(E22="Show hint",5,10),0)} -> 0
A24: TRAINING · recognize the move (pick from the list)
A25: # | B25: Mission | C25: Your answer | D25: Result | E25: Hint? | F25: Hint | G25: XP
A26: T1 | B26: Which operator means 'greater than or equal to'? | D26: {=IFERROR(IF('F2-1 True or False'!$C$26&""="","",IF('F2-1 True or False'!$C$26&""=Key!$C$12&"","✔ CLEAR","✘ TRY AGAIN")),"✘ TRY AGAIN")} | F26: {=IF(E26="Show hint",Key!$B$12,"")} | G26: {=IF(LEFT(D26,1)="✔",IF(E26="Show hint",5,10),0)} -> 0
A27: T2 | B27: Which operator means 'not equal to'? | D27: {=IFERROR(IF('F2-1 True or False'!$C$27&""="","",IF('F2-1 True or False'!$C$27&""=Key!$C$13&"","✔ CLEAR","✘ TRY AGAIN")),"✘ TRY AGAIN")} | F27: {=IF(E27="Show hint",Key!$B$13,"")} | G27: {=IF(LEFT(D27,1)="✔",IF(E27="Show hint",5,10),0)} -> 0
A28: T3 | B28: What must surround text inside a formula? | D28: {=IFERROR(IF('F2-1 True or False'!$C$28&""="","",IF('F2-1 True or False'!$C$28&""=Key!$C$14&"","✔ CLEAR","✘ TRY AGAIN")),"✘ TRY AGAIN")} | F28: {=IF(E28="Show hint",Key!$B$14,"")} | G28: {=IF(LEFT(D28,1)="✔",IF(E28="Show hint",5,10),0)} -> 0
A30: CHALLENGES · recall it, then do it
B31: ▶ Open F2-1 Arena (or press Ctrl+PgDn)
A32: # | B32: Mission | C32: Your answer | D32: Result | E32: Hint? | F32: Hint | G32: XP
A33: C1 | B33: Which operator means 'greater than or equal to'? | D33: {=IFERROR(_xlfn.LET(_xlpm.a,'F2-1 True or False'!$C$33,IF(TRIM(_xlpm.a&"")="","",IF(OR(SUBSTITUTE(SUBSTITUTE(SUBSTITUTE(SUBSTITUTE(SUBSTITUTE(SUBSTITUTE(SUBSTITUTE(SUBSTITUTE(SUBSTITUTE(SUBSTITUTE(SUBSTITUTE(SUBSTITUTE(SUBSTITUTE(SUBSTITUTE(SUBSTITUTE(SUBSTITUTE(SUBSTITUTE(SUBSTITUTE(SUBSTITUTE(SUBSTITUTE(SUBSTITUTE(SUBSTITUTE(SUBSTITUTE(SUBSTITUTE(SUBSTITUTE(SUBSTITUTE(SUBSTITUTE(UPPER(_xlpm.a)," ",""),"CONTROL","CTRL"),"CTL","CTRL"),"ESCAPE","ESC"),"RETURN","ENTER"),"PAGEDOWN","PGDN"),"PGDOWN","PGDN"),"PAGEUP","PGUP"),"ARROWKEYS","ARROW"),"ARROWKEY","ARROW"),"ARROWS","ARROW"),"DOWNARROW","DOWN"),"UPARROW","UP"),"LEFTARROW","LEFT"),"RIGHTARROW","RIGHT"),"ARROWDOWN","DOWN"),"ARROWUP","UP"),"ARROWLEFT","LEFT"),"ARROWRIGHT","RIGHT"),"↓","DOWN"),"↑","UP"),"←","LEFT"),"→","RIGHT"),"SPACEBAR","SPACE"),"−","-"),"MINUS","-"),"PLUS","+")=Key!$E$15:$E$15),"✔ CLEAR","✘ TRY AGAIN"))),"✘ TRY AGAIN")} | F33: {=IF(E33="Show hint",Key!$B$15,"")} | G33: {=IF(LEFT(D33,1)="✔",IF(E33="Show hint",5,10),0)} -> 0
A34: C2 | B34: Which operator means 'not equal to'? | D34: {=IFERROR(_xlfn.LET(_xlpm.a,'F2-1 True or False'!$C$34,IF(TRIM(_xlpm.a&"")="","",IF(OR(SUBSTITUTE(SUBSTITUTE(SUBSTITUTE(SUBSTITUTE(SUBSTITUTE(SUBSTITUTE(SUBSTITUTE(SUBSTITUTE(SUBSTITUTE(SUBSTITUTE(SUBSTITUTE(SUBSTITUTE(SUBSTITUTE(SUBSTITUTE(SUBSTITUTE(SUBSTITUTE(SUBSTITUTE(SUBSTITUTE(SUBSTITUTE(SUBSTITUTE(SUBSTITUTE(SUBSTITUTE(SUBSTITUTE(SUBSTITUTE(SUBSTITUTE(SUBSTITUTE(SUBSTITUTE(UPPER(_xlpm.a)," ",""),"CONTROL","CTRL"),"CTL","CTRL"),"ESCAPE","ESC"),"RETURN","ENTER"),"PAGEDOWN","PGDN"),"PGDOWN","PGDN"),"PAGEUP","PGUP"),"ARROWKEYS","ARROW"),"ARROWKEY","ARROW"),"ARROWS","ARROW"),"DOWNARROW","DOWN"),"UPARROW","UP"),"LEFTARROW","LEFT"),"RIGHTARROW","RIGHT"),"ARROWDOWN","DOWN"),"ARROWUP","UP"),"ARROWLEFT","LEFT"),"ARROWRIGHT","RIGHT"),"↓","DOWN"),"↑","UP"),"←","LEFT"),"→","RIGHT"),"SPACEBAR","SPACE"),"−","-"),"MINUS","-"),"PLUS","+")=Key!$E$16:$E$16),"✔ CLEAR","✘ TRY AGAIN"))),"✘ TRY AGAIN")} | F34: {=IF(E34="Show hint",Key!$B$16,"")} | G34: {=IF(LEFT(D34,1)="✔",IF(E34="Show hint",5,10),0)} -> 0
A35: C3 | B35: What must surround text inside a formula? | D35: {=IFERROR(_xlfn.LET(_xlpm.a,'F2-1 True or False'!$C$35,IF(TRIM(_xlpm.a&"")="","",IF(OR(SUBSTITUTE(SUBSTITUTE(SUBSTITUTE(SUBSTITUTE(SUBSTITUTE(SUBSTITUTE(SUBSTITUTE(SUBSTITUTE(SUBSTITUTE(SUBSTITUTE(SUBSTITUTE(SUBSTITUTE(SUBSTITUTE(SUBSTITUTE(SUBSTITUTE(SUBSTITUTE(SUBSTITUTE(SUBSTITUTE(SUBSTITUTE(SUBSTITUTE(SUBSTITUTE(SUBSTITUTE(SUBSTITUTE(SUBSTITUTE(SUBSTITUTE(SUBSTITUTE(SUBSTITUTE(UPPER(_xlpm.a)," ",""),"CONTROL","CTRL"),"CTL","CTRL"),"ESCAPE","ESC"),"RETURN","ENTER"),"PAGEDOWN","PGDN"),"PGDOWN","PGDN"),"PAGEUP","PGUP"),"ARROWKEYS","ARROW"),"ARROWKEY","ARROW"),"ARROWS","ARROW"),"DOWNARROW","DOWN"),"UPARROW","UP"),"LEFTARROW","LEFT"),"RIGHTARROW","RIGHT"),"ARROWDOWN","DOWN"),"ARROWUP","UP"),"ARROWLEFT","LEFT"),"ARROWRIGHT","RIGHT"),"↓","DOWN"),"↑","UP"),"←","LEFT"),"→","RIGHT"),"SPACEBAR","SPACE"),"−","-"),"MINUS","-"),"PLUS","+")=Key!$E$17:$H$17),"✔ CLEAR","✘ TRY AGAIN"))),"✘ TRY AGAIN")} | F35: {=IF(E35="Show hint",Key!$B$17,"")} | G35: {=IF(LEFT(D35,1)="✔",IF(E35="Show hint",5,10),0)} -> 0
A36: C4 | B36: In G6 write a formula that tests whether Ava's Score (C6) is at least 50. The answer is TRUE or FALSE. | C36: ▶ ARENA C4 (cell G6) | D36: {=IF(ISBLANK('F2-1 Arena'!$G$6),"",IF(NOT(_xlfn.ISFORMULA('F2-1 Arena'!$G$6)),"✘ That's a typed value · enter a formula",IF(ISERROR('F2-1 Arena'!$G$6),"✘ Your formula returns "&IFERROR(CHOOSE(ERROR.TYPE('F2-1 Arena'!$G$6),"#NULL!","#DIV/0!","#VALUE!","#REF!","#NAME?","#NUM!","#N/A","#GETTING_DATA","#SPILL!","#CONNECT!","#BLOCKED!","#UNKNOWN!","#FIELD!","#CALC!"),"an error"),IF(NOT(AND(IFERROR(AND(ISLOGICAL('F2-1 Arena'!$G$6),'F2-1 Arena'!$G$6=(Key!$C$18="TRUE")),FALSE))),"✘ TRY AGAIN","✔ CLEAR"))))} | F36: {=IF(E36="Show hint",Key!$B$18,"")} | G36: {=IF(LEFT(D36,1)="✔",IF(E36="Show hint",5,10),0)} -> 0
A37: C5 | B37: In G7 test whether Ben's License (E7) is NOT equal to "No". Use <>. | C37: ▶ ARENA C5 (cell G7) | D37: {=IF(ISBLANK('F2-1 Arena'!$G$7),"",IF(NOT(_xlfn.ISFORMULA('F2-1 Arena'!$G$7)),"✘ That's a typed value · enter a formula",IF(ISERROR('F2-1 Arena'!$G$7),"✘ Your formula returns "&IFERROR(CHOOSE(ERROR.TYPE('F2-1 Arena'!$G$7),"#NULL!","#DIV/0!","#VALUE!","#REF!","#NAME?","#NUM!","#N/A","#GETTING_DATA","#SPILL!","#CONNECT!","#BLOCKED!","#UNKNOWN!","#FIELD!","#CALC!"),"an error"),IF(NOT(AND(IFERROR(AND(ISLOGICAL('F2-1 Arena'!$G$7),'F2-1 Arena'!$G$7=(Key!$C$19="TRUE")),FALSE))),"✘ TRY AGAIN",IF(ISNUMBER(FIND("<>",_xlfn.FORMULATEXT('F2-1 Arena'!$G$7))),"✔ CLEAR","✘ CLOSE · your formula needs <>")))))} | F37: {=IF(E37="Show hint",Key!$B$19,"")} | G37: {=IF(LEFT(D37,1)="✔",IF(E37="Show hint",5,10),0)} -> 0
A38: C6 | B38: In G8 test whether Cy's License (E8) equals "yes" (type yes in lowercase, inside quotes). Excel ignores case when it compares text. | C38: ▶ ARENA C6 (cell G8) | D38: {=IF(ISBLANK('F2-1 Arena'!$G$8),"",IF(NOT(_xlfn.ISFORMULA('F2-1 Arena'!$G$8)),"✘ That's a typed value · enter a formula",IF(ISERROR('F2-1 Arena'!$G$8),"✘ Your formula returns "&IFERROR(CHOOSE(ERROR.TYPE('F2-1 Arena'!$G$8),"#NULL!","#DIV/0!","#VALUE!","#REF!","#NAME?","#NUM!","#N/A","#GETTING_DATA","#SPILL!","#CONNECT!","#BLOCKED!","#UNKNOWN!","#FIELD!","#CALC!"),"an error"),IF(NOT(AND(IFERROR(AND(ISLOGICAL('F2-1 Arena'!$G$8),'F2-1 Arena'!$G$8=(Key!$C$20="TRUE")),FALSE))),"✘ TRY AGAIN","✔ CLEAR"))))} | F38: {=IF(E38="Show hint",Key!$B$20,"")} | G38: {=IF(LEFT(D38,1)="✔",IF(E38="Show hint",5,10),0)} -> 0

Sheet F2-1 Arena
A1: ARENA ▸ F2-1 TRUE OR FALSE
A2: Practice area · everything here is editable. Missions and their checks are on the stage sheet.
A3: PASS CODE | B3: VERDICT | D3: ◀ Back to F2-1 True or False
B5: Name | C5: Score | D5: Age | E5: License
B6: Ava | C6: 92 | D6: 17 | E6: No | F6: Ava ≥ 50?
B7: Ben | C7: 48 | D7: 22 | E7: Yes | F7: Ben not No?
B8: Cy | C8: 75 | D8: 19 | E8: Yes | F8: Cy = yes?
B9: Dee | C9: 60 | D9: 16 | E9: No
B10: Eli | C10: 88 | D10: 30 | E10: Yes
B11: Fay | C11: 50 | D11: 18 | E11: Yes
B12: Gus | C12: 39 | D12: 25 | E12: No
B13: Hal | C13: 81 | D13: 41 | E13: Yes
B14: Ivy | C14: 99 | D14: 15 | E14: No
B15: Jo | C15: 70 | D15: 20 | E15: No

Sheet F2-2 Fork in the Road
A1: STAGE F2-2 ▸ FORK IN THE ROAD
A2: Goal: return different results with IF
A3: {="SCORE "&TEXT(SUM($G$13:$G$38),"0000")&" / 0190"} -> SCORE 0000 / 0190 | C3: {=IF(SUM($G$13:$G$38)>=190,"★★★",IF(SUM($G$13:$G$38)>=190*0.8,"★★☆",IF(SUM($G$13:$G$38)>=190*0.5,"★☆☆","☆☆☆")))} -> ☆☆☆ | D3: {=REPT("█",ROUND(10*SUM($G$13:$G$38)/190,0))&REPT("░",10-ROUND(10*SUM($G$13:$G$38)/190,0))&" "&TEXT(SUM($G$13:$G$38)/190,"0%")} -> ░░░░░░░░░░ 0% | F3: {=IF(SUM($G$13:$G$38)>=190*0.5,"STAGE CLEAR! ▶ Next: F2-3 Combo Moves","")}
A5: BRIEFING · new moves in this stage
A6: # | B6: What it does · Pro tip | C6: Keys / Syntax
A7: 1 | B7: IF(test, value_if_true, value_if_false) picks one of two results. Tip: =IF(B2>=50,"Pass","Fail") | C7: IF
A8: 2 | B8: Each branch can be a calculation, not just text. Tip: =IF(B2>100,B2*0.9,B2) discounts only big orders. | C8: IF + math
A9: 3 | B9: Two quotes with nothing between = empty text, a blank-looking result. Tip: =IF(A2="","",A2*2) stays blank until A2 has a value. | C9: ""
A11: WARM-UP · flashback to earlier stages
A12: # | B12: Mission | C12: Your answer | D12: Result | E12: Hint? | F12: Hint | G12: XP
A13: W1 | B13: Which operator means 'greater than or equal to'? (from F2-1 True or False) | D13: {=IFERROR(_xlfn.LET(_xlpm.a,'F2-2 Fork in the Road'!$C$13,IF(TRIM(_xlpm.a&"")="","",IF(OR(SUBSTITUTE(SUBSTITUTE(SUBSTITUTE(SUBSTITUTE(SUBSTITUTE(SUBSTITUTE(SUBSTITUTE(SUBSTITUTE(SUBSTITUTE(SUBSTITUTE(SUBSTITUTE(SUBSTITUTE(SUBSTITUTE(SUBSTITUTE(SUBSTITUTE(SUBSTITUTE(SUBSTITUTE(SUBSTITUTE(SUBSTITUTE(SUBSTITUTE(SUBSTITUTE(SUBSTITUTE(SUBSTITUTE(SUBSTITUTE(SUBSTITUTE(SUBSTITUTE(SUBSTITUTE(UPPER(_xlpm.a)," ",""),"CONTROL","CTRL"),"CTL","CTRL"),"ESCAPE","ESC"),"RETURN","ENTER"),"PAGEDOWN","PGDN"),"PGDOWN","PGDN"),"PAGEUP","PGUP"),"ARROWKEYS","ARROW"),"ARROWKEY","ARROW"),"ARROWS","ARROW"),"DOWNARROW","DOWN"),"UPARROW","UP"),"LEFTARROW","LEFT"),"RIGHTARROW","RIGHT"),"ARROWDOWN","DOWN"),"ARROWUP","UP"),"ARROWLEFT","LEFT"),"ARROWRIGHT","RIGHT"),"↓","DOWN"),"↑","UP"),"←","LEFT"),"→","RIGHT"),"SPACEBAR","SPACE"),"−","-"),"MINUS","-"),"PLUS","+")=Key!$E$21:$E$21),"✔ CLEAR","✘ TRY AGAIN"))),"✘ TRY AGAIN")} | F13: {=IF(E13="Show hint",Key!$B$21,"")} | G13: {=IF(LEFT(D13,1)="✔",IF(E13="Show hint",5,10),0)} -> 0
A14: W2 | B14: Which operator means 'not equal to'? (from F2-1 True or False) | D14: {=IFERROR(_xlfn.LET(_xlpm.a,'F2-2 Fork in the Road'!$C$14,IF(TRIM(_xlpm.a&"")="","",IF(OR(SUBSTITUTE(SUBSTITUTE(SUBSTITUTE(SUBSTITUTE(SUBSTITUTE(SUBSTITUTE(SUBSTITUTE(SUBSTITUTE(SUBSTITUTE(SUBSTITUTE(SUBSTITUTE(SUBSTITUTE(SUBSTITUTE(SUBSTITUTE(SUBSTITUTE(SUBSTITUTE(SUBSTITUTE(SUBSTITUTE(SUBSTITUTE(SUBSTITUTE(SUBSTITUTE(SUBSTITUTE(SUBSTITUTE(SUBSTITUTE(SUBSTITUTE(SUBSTITUTE(SUBSTITUTE(UPPER(_xlpm.a)," ",""),"CONTROL","CTRL"),"CTL","CTRL"),"ESCAPE","ESC"),"RETURN","ENTER"),"PAGEDOWN","PGDN"),"PGDOWN","PGDN"),"PAGEUP","PGUP"),"ARROWKEYS","ARROW"),"ARROWKEY","ARROW"),"ARROWS","ARROW"),"DOWNARROW","DOWN"),"UPARROW","UP"),"LEFTARROW","LEFT"),"RIGHTARROW","RIGHT"),"ARROWDOWN","DOWN"),"ARROWUP","UP"),"ARROWLEFT","LEFT"),"ARROWRIGHT","RIGHT"),"↓","DOWN"),"↑","UP"),"←","LEFT"),"→","RIGHT"),"SPACEBAR","SPACE"),"−","-"),"MINUS","-"),"PLUS","+")=Key!$E$22:$E$22),"✔ CLEAR","✘ TRY AGAIN"))),"✘ TRY AGAIN")} | F14: {=IF(E14="Show hint",Key!$B$22,"")} | G14: {=IF(LEFT(D14,1)="✔",IF(E14="Show hint",5,10),0)} -> 0
A15: W3 | B15: What must surround text inside a formula? (from F2-1 True or False) | D15: {=IFERROR(_xlfn.LET(_xlpm.a,'F2-2 Fork in the Road'!$C$15,IF(TRIM(_xlpm.a&"")="","",IF(OR(SUBSTITUTE(SUBSTITUTE(SUBSTITUTE(SUBSTITUTE(SUBSTITUTE(SUBSTITUTE(SUBSTITUTE(SUBSTITUTE(SUBSTITUTE(SUBSTITUTE(SUBSTITUTE(SUBSTITUTE(SUBSTITUTE(SUBSTITUTE(SUBSTITUTE(SUBSTITUTE(SUBSTITUTE(SUBSTITUTE(SUBSTITUTE(SUBSTITUTE(SUBSTITUTE(SUBSTITUTE(SUBSTITUTE(SUBSTITUTE(SUBSTITUTE(SUBSTITUTE(SUBSTITUTE(UPPER(_xlpm.a)," ",""),"CONTROL","CTRL"),"CTL","CTRL"),"ESCAPE","ESC"),"RETURN","ENTER"),"PAGEDOWN","PGDN"),"PGDOWN","PGDN"),"PAGEUP","PGUP"),"ARROWKEYS","ARROW"),"ARROWKEY","ARROW"),"ARROWS","ARROW"),"DOWNARROW","DOWN"),"UPARROW","UP"),"LEFTARROW","LEFT"),"RIGHTARROW","RIGHT"),"ARROWDOWN","DOWN"),"ARROWUP","UP"),"ARROWLEFT","LEFT"),"ARROWRIGHT","RIGHT"),"↓","DOWN"),"↑","UP"),"←","LEFT"),"→","RIGHT"),"SPACEBAR","SPACE"),"−","-"),"MINUS","-"),"PLUS","+")=Key!$E$23:$H$23),"✔ CLEAR","✘ TRY AGAIN"))),"✘ TRY AGAIN")} | F15: {=IF(E15="Show hint",Key!$B$23,"")} | G15: {=IF(LEFT(D15,1)="✔",IF(E15="Show hint",5,10),0)} -> 0
A16: W4 | B16: Which keys copy the selection? (from S2-2 Clone Machine) | D16: {=IFERROR(_xlfn.LET(_xlpm.a,'F2-2 Fork in the Road'!$C$16,IF(TRIM(_xlpm.a&"")="","",IF(OR(SUBSTITUTE(SUBSTITUTE(SUBSTITUTE(SUBSTITUTE(SUBSTITUTE(SUBSTITUTE(SUBSTITUTE(SUBSTITUTE(SUBSTITUTE(SUBSTITUTE(SUBSTITUTE(SUBSTITUTE(SUBSTITUTE(SUBSTITUTE(SUBSTITUTE(SUBSTITUTE(SUBSTITUTE(SUBSTITUTE(SUBSTITUTE(SUBSTITUTE(SUBSTITUTE(SUBSTITUTE(SUBSTITUTE(SUBSTITUTE(SUBSTITUTE(SUBSTITUTE(SUBSTITUTE(UPPER(_xlpm.a)," ",""),"CONTROL","CTRL"),"CTL","CTRL"),"ESCAPE","ESC"),"RETURN","ENTER"),"PAGEDOWN","PGDN"),"PGDOWN","PGDN"),"PAGEUP","PGUP"),"ARROWKEYS","ARROW"),"ARROWKEY","ARROW"),"ARROWS","ARROW"),"DOWNARROW","DOWN"),"UPARROW","UP"),"LEFTARROW","LEFT"),"RIGHTARROW","RIGHT"),"ARROWDOWN","DOWN"),"ARROWUP","UP"),"ARROWLEFT","LEFT"),"ARROWRIGHT","RIGHT"),"↓","DOWN"),"↑","UP"),"←","LEFT"),"→","RIGHT"),"SPACEBAR","SPACE"),"−","-"),"MINUS","-"),"PLUS","+")=Key!$E$24:$E$24),"✔ CLEAR","✘ TRY AGAIN"))),"✘ TRY AGAIN")} | F16: {=IF(E16="Show hint",Key!$B$24,"")} | G16: {=IF(LEFT(D16,1)="✔",IF(E16="Show hint",5,10),0)} -> 0
A17: W5 | B17: Which keys cut the selection? (from S2-2 Clone Machine) | D17: {=IFERROR(_xlfn.LET(_xlpm.a,'F2-2 Fork in the Road'!$C$17,IF(TRIM(_xlpm.a&"")="","",IF(OR(SUBSTITUTE(SUBSTITUTE(SUBSTITUTE(SUBSTITUTE(SUBSTITUTE(SUBSTITUTE(SUBSTITUTE(SUBSTITUTE(SUBSTITUTE(SUBSTITUTE(SUBSTITUTE(SUBSTITUTE(SUBSTITUTE(SUBSTITUTE(SUBSTITUTE(SUBSTITUTE(SUBSTITUTE(SUBSTITUTE(SUBSTITUTE(SUBSTITUTE(SUBSTITUTE(SUBSTITUTE(SUBSTITUTE(SUBSTITUTE(SUBSTITUTE(SUBSTITUTE(SUBSTITUTE(UPPER(_xlpm.a)," ",""),"CONTROL","CTRL"),"CTL","CTRL"),"ESCAPE","ESC"),"RETURN","ENTER"),"PAGEDOWN","PGDN"),"PGDOWN","PGDN"),"PAGEUP","PGUP"),"ARROWKEYS","ARROW"),"ARROWKEY","ARROW"),"ARROWS","ARROW"),"DOWNARROW","DOWN"),"UPARROW","UP"),"LEFTARROW","LEFT"),"RIGHTARROW","RIGHT"),"ARROWDOWN","DOWN"),"ARROWUP","UP"),"ARROWLEFT","LEFT"),"ARROWRIGHT","RIGHT"),"↓","DOWN"),"↑","UP"),"←","LEFT"),"→","RIGHT"),"SPACEBAR","SPACE"),"−","-"),"MINUS","-"),"PLUS","+")=Key!$E$25:$E$25),"✔ CLEAR","✘ TRY AGAIN"))),"✘ TRY AGAIN")} | F17: {=IF(E17="Show hint",Key!$B$25,"")} | G17: {=IF(LEFT(D17,1)="✔",IF(E17="Show hint",5,10),0)} -> 0
A18: W6 | B18: Which keys paste? (from S2-2 Clone Machine) | D18: {=IFERROR(_xlfn.LET(_xlpm.a,'F2-2 Fork in the Road'!$C$18,IF(TRIM(_xlpm.a&"")="","",IF(OR(SUBSTITUTE(SUBSTITUTE(SUBSTITUTE(SUBSTITUTE(SUBSTITUTE(SUBSTITUTE(SUBSTITUTE(SUBSTITUTE(SUBSTITUTE(SUBSTITUTE(SUBSTITUTE(SUBSTITUTE(SUBSTITUTE(SUBSTITUTE(SUBSTITUTE(SUBSTITUTE(SUBSTITUTE(SUBSTITUTE(SUBSTITUTE(SUBSTITUTE(SUBSTITUTE(SUBSTITUTE(SUBSTITUTE(SUBSTITUTE(SUBSTITUTE(SUBSTITUTE(SUBSTITUTE(UPPER(_xlpm.a)," ",""),"CONTROL","CTRL"),"CTL","CTRL"),"ESCAPE","ESC"),"RETURN","ENTER"),"PAGEDOWN","PGDN"),"PGDOWN","PGDN"),"PAGEUP","PGUP"),"ARROWKEYS","ARROW"),"ARROWKEY","ARROW"),"ARROWS","ARROW"),"DOWNARROW","DOWN"),"UPARROW","UP"),"LEFTARROW","LEFT"),"RIGHTARROW","RIGHT"),"ARROWDOWN","DOWN"),"ARROWUP","UP"),"ARROWLEFT","LEFT"),"ARROWRIGHT","RIGHT"),"↓","DOWN"),"↑","UP"),"←","LEFT"),"→","RIGHT"),"SPACEBAR","SPACE"),"−","-"),"MINUS","-"),"PLUS","+")=Key!$E$26:$E$26),"✔ CLEAR","✘ TRY AGAIN"))),"✘ TRY AGAIN")} | F18: {=IF(E18="Show hint",Key!$B$26,"")} | G18: {=IF(LEFT(D18,1)="✔",IF(E18="Show hint",5,10),0)} -> 0
A19: W7 | B19: Which keys open Paste Special? (from S2-2 Clone Machine) | D19: {=IFERROR(_xlfn.LET(_xlpm.a,'F2-2 Fork in the Road'!$C$19,IF(TRIM(_xlpm.a&"")="","",IF(OR(SUBSTITUTE(SUBSTITUTE(SUBSTITUTE(SUBSTITUTE(SUBSTITUTE(SUBSTITUTE(SUBSTITUTE(SUBSTITUTE(SUBSTITUTE(SUBSTITUTE(SUBSTITUTE(SUBSTITUTE(SUBSTITUTE(SUBSTITUTE(SUBSTITUTE(SUBSTITUTE(SUBSTITUTE(SUBSTITUTE(SUBSTITUTE(SUBSTITUTE(SUBSTITUTE(SUBSTITUTE(SUBSTITUTE(SUBSTITUTE(SUBSTITUTE(SUBSTITUTE(SUBSTITUTE(UPPER(_xlpm.a)," ",""),"CONTROL","CTRL"),"CTL","CTRL"),"ESCAPE","ESC"),"RETURN","ENTER"),"PAGEDOWN","PGDN"),"PGDOWN","PGDN"),"PAGEUP","PGUP"),"ARROWKEYS","ARROW"),"ARROWKEY","ARROW"),"ARROWS","ARROW"),"DOWNARROW","DOWN"),"UPARROW","UP"),"LEFTARROW","LEFT"),"RIGHTARROW","RIGHT"),"ARROWDOWN","DOWN"),"ARROWUP","UP"),"ARROWLEFT","LEFT"),"ARROWRIGHT","RIGHT"),"↓","DOWN"),"↑","UP"),"←","LEFT"),"→","RIGHT"),"SPACEBAR","SPACE"),"−","-"),"MINUS","-"),"PLUS","+")=Key!$E$27:$F$27),"✔ CLEAR","✘ TRY AGAIN"))),"✘ TRY AGAIN")} | F19: {=IF(E19="Show hint",Key!$B$27,"")} | G19: {=IF(LEFT(D19,1)="✔",IF(E19="Show hint",5,10),0)} -> 0
A20: W8 | B20: Which keys copy the left cell into the selected cells to its right? (from S2-2 Clone Machine) | D20: {=IFERROR(_xlfn.LET(_xlpm.a,'F2-2 Fork in the Road'!$C$20,IF(TRIM(_xlpm.a&"")="","",IF(OR(SUBSTITUTE(SUBSTITUTE(SUBSTITUTE(SUBSTITUTE(SUBSTITUTE(SUBSTITUTE(SUBSTITUTE(SUBSTITUTE(SUBSTITUTE(SUBSTITUTE(SUBSTITUTE(SUBSTITUTE(SUBSTITUTE(SUBSTITUTE(SUBSTITUTE(SUBSTITUTE(SUBSTITUTE(SUBSTITUTE(SUBSTITUTE(SUBSTITUTE(SUBSTITUTE(SUBSTITUTE(SUBSTITUTE(SUBSTITUTE(SUBSTITUTE(SUBSTITUTE(SUBSTITUTE(UPPER(_xlpm.a)," ",""),"CONTROL","CTRL"),"CTL","CTRL"),"ESCAPE","ESC"),"RETURN","ENTER"),"PAGEDOWN","PGDN"),"PGDOWN","PGDN"),"PAGEUP","PGUP"),"ARROWKEYS","ARROW"),"ARROWKEY","ARROW"),"ARROWS","ARROW"),"DOWNARROW","DOWN"),"UPARROW","UP"),"LEFTARROW","LEFT"),"RIGHTARROW","RIGHT"),"ARROWDOWN","DOWN"),"ARROWUP","UP"),"ARROWLEFT","LEFT"),"ARROWRIGHT","RIGHT"),"↓","DOWN"),"↑","UP"),"←","LEFT"),"→","RIGHT"),"SPACEBAR","SPACE"),"−","-"),"MINUS","-"),"PLUS","+")=Key!$E$28:$E$28),"✔ CLEAR","✘ TRY AGAIN"))),"✘ TRY AGAIN")} | F20: {=IF(E20="Show hint",Key!$B$28,"")} | G20: {=IF(LEFT(D20,1)="✔",IF(E20="Show hint",5,10),0)} -> 0
A21: W9 | B21: Which keys undo the last action? (from S2-2 Clone Machine) | D21: {=IFERROR(_xlfn.LET(_xlpm.a,'F2-2 Fork in the Road'!$C$21,IF(TRIM(_xlpm.a&"")="","",IF(OR(SUBSTITUTE(SUBSTITUTE(SUBSTITUTE(SUBSTITUTE(SUBSTITUTE(SUBSTITUTE(SUBSTITUTE(SUBSTITUTE(SUBSTITUTE(SUBSTITUTE(SUBSTITUTE(SUBSTITUTE(SUBSTITUTE(SUBSTITUTE(SUBSTITUTE(SUBSTITUTE(SUBSTITUTE(SUBSTITUTE(SUBSTITUTE(SUBSTITUTE(SUBSTITUTE(SUBSTITUTE(SUBSTITUTE(SUBSTITUTE(SUBSTITUTE(SUBSTITUTE(SUBSTITUTE(UPPER(_xlpm.a)," ",""),"CONTROL","CTRL"),"CTL","CTRL"),"ESCAPE","ESC"),"RETURN","ENTER"),"PAGEDOWN","PGDN"),"PGDOWN","PGDN"),"PAGEUP","PGUP"),"ARROWKEYS","ARROW"),"ARROWKEY","ARROW"),"ARROWS","ARROW"),"DOWNARROW","DOWN"),"UPARROW","UP"),"LEFTARROW","LEFT"),"RIGHTARROW","RIGHT"),"ARROWDOWN","DOWN"),"ARROWUP","UP"),"ARROWLEFT","LEFT"),"ARROWRIGHT","RIGHT"),"↓","DOWN"),"↑","UP"),"←","LEFT"),"→","RIGHT"),"SPACEBAR","SPACE"),"−","-"),"MINUS","-"),"PLUS","+")=Key!$E$29:$E$29),"✔ CLEAR","✘ TRY AGAIN"))),"✘ TRY AGAIN")} | F21: {=IF(E21="Show hint",Key!$B$29,"")} | G21: {=IF(LEFT(D21,1)="✔",IF(E21="Show hint",5,10),0)} -> 0
A22: W10 | B22: Which keys redo or repeat the last action? (from S2-2 Clone Machine) | D22: {=IFERROR(_xlfn.LET(_xlpm.a,'F2-2 Fork in the Road'!$C$22,IF(TRIM(_xlpm.a&"")="","",IF(OR(SUBSTITUTE(SUBSTITUTE(SUBSTITUTE(SUBSTITUTE(SUBSTITUTE(SUBSTITUTE(SUBSTITUTE(SUBSTITUTE(SUBSTITUTE(SUBSTITUTE(SUBSTITUTE(SUBSTITUTE(SUBSTITUTE(SUBSTITUTE(SUBSTITUTE(SUBSTITUTE(SUBSTITUTE(SUBSTITUTE(SUBSTITUTE(SUBSTITUTE(SUBSTITUTE(SUBSTITUTE(SUBSTITUTE(SUBSTITUTE(SUBSTITUTE(SUBSTITUTE(SUBSTITUTE(UPPER(_xlpm.a)," ",""),"CONTROL","CTRL"),"CTL","CTRL"),"ESCAPE","ESC"),"RETURN","ENTER"),"PAGEDOWN","PGDN"),"PGDOWN","PGDN"),"PAGEUP","PGUP"),"ARROWKEYS","ARROW"),"ARROWKEY","ARROW"),"ARROWS","ARROW"),"DOWNARROW","DOWN"),"UPARROW","UP"),"LEFTARROW","LEFT"),"RIGHTARROW","RIGHT"),"ARROWDOWN","DOWN"),"ARROWUP","UP"),"ARROWLEFT","LEFT"),"ARROWRIGHT","RIGHT"),"↓","DOWN"),"↑","UP"),"←","LEFT"),"→","RIGHT"),"SPACEBAR","SPACE"),"−","-"),"MINUS","-"),"PLUS","+")=Key!$E$30:$E$30),"✔ CLEAR","✘ TRY AGAIN"))),"✘ TRY AGAIN")} | F22: {=IF(E22="Show hint",Key!$B$30,"")} | G22: {=IF(LEFT(D22,1)="✔",IF(E22="Show hint",5,10),0)} -> 0
A24: TRAINING · recognize the move (pick from the list)
A25: # | B25: Mission | C25: Your answer | D25: Result | E25: Hint? | F25: Hint | G25: XP
A26: T1 | B26: Which function returns one value when a test is TRUE and another when FALSE? | D26: {=IFERROR(IF('F2-2 Fork in the Road'!$C$26&""="","",IF('F2-2 Fork in the Road'!$C$26&""=Key!$C$31&"","✔ CLEAR","✘ TRY AGAIN")),"✘ TRY AGAIN")} | F26: {=IF(E26="Show hint",Key!$B$31,"")} | G26: {=IF(LEFT(D26,1)="✔",IF(E26="Show hint",5,10),0)} -> 0
A27: T2 | B27: In =IF(B2>100,B2*0.9,B2), what is returned when B2 is 50? | D27: {=IFERROR(IF('F2-2 Fork in the Road'!$C$27&""="","",IF('F2-2 Fork in the Road'!$C$27&""=Key!$C$32&"","✔ CLEAR","✘ TRY AGAIN")),"✘ TRY AGAIN")} | F27: {=IF(E27="Show hint",Key!$B$32,"")} | G27: {=IF(LEFT(D27,1)="✔",IF(E27="Show hint",5,10),0)} -> 0
A28: T3 | B28: What do you type in a formula for an empty, blank-looking result? | D28: {=IFERROR(IF('F2-2 Fork in the Road'!$C$28&""="","",IF('F2-2 Fork in the Road'!$C$28&""=Key!$C$33&"","✔ CLEAR","✘ TRY AGAIN")),"✘ TRY AGAIN")} | F28: {=IF(E28="Show hint",Key!$B$33,"")} | G28: {=IF(LEFT(D28,1)="✔",IF(E28="Show hint",5,10),0)} -> 0
A30: CHALLENGES · recall it, then do it
B31: ▶ Open F2-2 Arena (or press Ctrl+PgDn)
A32: # | B32: Mission | C32: Your answer | D32: Result | E32: Hint? | F32: Hint | G32: XP
A33: C1 | B33: Which function returns one value when a test is TRUE and another when FALSE? | D33: {=IFERROR(_xlfn.LET(_xlpm.a,'F2-2 Fork in the Road'!$C$33,IF(TRIM(_xlpm.a&"")="","",IF(OR(SUBSTITUTE(SUBSTITUTE(SUBSTITUTE(SUBSTITUTE(SUBSTITUTE(SUBSTITUTE(SUBSTITUTE(SUBSTITUTE(SUBSTITUTE(SUBSTITUTE(SUBSTITUTE(SUBSTITUTE(SUBSTITUTE(SUBSTITUTE(SUBSTITUTE(SUBSTITUTE(SUBSTITUTE(SUBSTITUTE(SUBSTITUTE(SUBSTITUTE(SUBSTITUTE(SUBSTITUTE(SUBSTITUTE(SUBSTITUTE(SUBSTITUTE(SUBSTITUTE(SUBSTITUTE(UPPER(_xlpm.a)," ",""),"CONTROL","CTRL"),"CTL","CTRL"),"ESCAPE","ESC"),"RETURN","ENTER"),"PAGEDOWN","PGDN"),"PGDOWN","PGDN"),"PAGEUP","PGUP"),"ARROWKEYS","ARROW"),"ARROWKEY","ARROW"),"ARROWS","ARROW"),"DOWNARROW","DOWN"),"UPARROW","UP"),"LEFTARROW","LEFT"),"RIGHTARROW","RIGHT"),"ARROWDOWN","DOWN"),"ARROWUP","UP"),"ARROWLEFT","LEFT"),"ARROWRIGHT","RIGHT"),"↓","DOWN"),"↑","UP"),"←","LEFT"),"→","RIGHT"),"SPACEBAR","SPACE"),"−","-"),"MINUS","-"),"PLUS","+")=Key!$E$34:$J$34),"✔ CLEAR","✘ TRY AGAIN"))),"✘ TRY AGAIN")} | F33: {=IF(E33="Show hint",Key!$B$34,"")} | G33: {=IF(LEFT(D33,1)="✔",IF(E33="Show hint",5,10),0)} -> 0
A34: C2 | B34: In =IF(B2>100,B2*0.9,B2), what is returned when B2 is 50? | D34: {=IFERROR(_xlfn.LET(_xlpm.a,'F2-2 Fork in the Road'!$C$34,IF(TRIM(_xlpm.a&"")="","",IF(OR(SUBSTITUTE(SUBSTITUTE(SUBSTITUTE(SUBSTITUTE(SUBSTITUTE(SUBSTITUTE(SUBSTITUTE(SUBSTITUTE(SUBSTITUTE(SUBSTITUTE(SUBSTITUTE(SUBSTITUTE(SUBSTITUTE(SUBSTITUTE(SUBSTITUTE(SUBSTITUTE(SUBSTITUTE(SUBSTITUTE(SUBSTITUTE(SUBSTITUTE(SUBSTITUTE(SUBSTITUTE(SUBSTITUTE(SUBSTITUTE(SUBSTITUTE(SUBSTITUTE(SUBSTITUTE(UPPER(_xlpm.a)," ",""),"CONTROL","CTRL"),"CTL","CTRL"),"ESCAPE","ESC"),"RETURN","ENTER"),"PAGEDOWN","PGDN"),"PGDOWN","PGDN"),"PAGEUP","PGUP"),"ARROWKEYS","ARROW"),"ARROWKEY","ARROW"),"ARROWS","ARROW"),"DOWNARROW","DOWN"),"UPARROW","UP"),"LEFTARROW","LEFT"),"RIGHTARROW","RIGHT"),"ARROWDOWN","DOWN"),"ARROWUP","UP"),"ARROWLEFT","LEFT"),"ARROWRIGHT","RIGHT"),"↓","DOWN"),"↑","UP"),"←","LEFT"),"→","RIGHT"),"SPACEBAR","SPACE"),"−","-"),"MINUS","-"),"PLUS","+")=Key!$E$35:$E$35),"✔ CLEAR","✘ TRY AGAIN"))),"✘ TRY AGAIN")} | F34: {=IF(E34="Show hint",Key!$B$35,"")} | G34: {=IF(LEFT(D34,1)="✔",IF(E34="Show hint",5,10),0)} -> 0
A35: C3 | B35: What do you type in a formula for an empty, blank-looking result? | D35: {=IFERROR(_xlfn.LET(_xlpm.a,'F2-2 Fork in the Road'!$C$35,IF(TRIM(_xlpm.a&"")="","",IF(OR(SUBSTITUTE(SUBSTITUTE(SUBSTITUTE(SUBSTITUTE(SUBSTITUTE(SUBSTITUTE(SUBSTITUTE(SUBSTITUTE(SUBSTITUTE(SUBSTITUTE(SUBSTITUTE(SUBSTITUTE(SUBSTITUTE(SUBSTITUTE(SUBSTITUTE(SUBSTITUTE(SUBSTITUTE(SUBSTITUTE(SUBSTITUTE(SUBSTITUTE(SUBSTITUTE(SUBSTITUTE(SUBSTITUTE(SUBSTITUTE(SUBSTITUTE(SUBSTITUTE(SUBSTITUTE(UPPER(_xlpm.a)," ",""),"CONTROL","CTRL"),"CTL","CTRL"),"ESCAPE","ESC"),"RETURN","ENTER"),"PAGEDOWN","PGDN"),"PGDOWN","PGDN"),"PAGEUP","PGUP"),"ARROWKEYS","ARROW"),"ARROWKEY","ARROW"),"ARROWS","ARROW"),"DOWNARROW","DOWN"),"UPARROW","UP"),"LEFTARROW","LEFT"),"RIGHTARROW","RIGHT"),"ARROWDOWN","DOWN"),"ARROWUP","UP"),"ARROWLEFT","LEFT"),"ARROWRIGHT","RIGHT"),"↓","DOWN"),"↑","UP"),"←","LEFT"),"→","RIGHT"),"SPACEBAR","SPACE"),"−","-"),"MINUS","-"),"PLUS","+")=Key!$E$36:$E$36),"✔ CLEAR","✘ TRY AGAIN"))),"✘ TRY AGAIN")} | F35: {=IF(E35="Show hint",Key!$B$36,"")} | G35: {=IF(LEFT(D35,1)="✔",IF(E35="Show hint",5,10),0)} -> 0
A36: C4 | B36: In F6 write =IF(C6>=50,"Pass","Fail"), then select F6:F15 and press Ctrl+D. | C36: ▶ ARENA C4 (cell F6) | D36: {=IF(COUNTA('F2-2 Arena'!$F$6,'F2-2 Arena'!$F$7,'F2-2 Arena'!$F$8,'F2-2 Arena'!$F$9,'F2-2 Arena'!$F$10,'F2-2 Arena'!$F$11,'F2-2 Arena'!$F$12,'F2-2 Arena'!$F$13,'F2-2 Arena'!$F$14,'F2-2 Arena'!$F$15)=0,"",IF(OR(NOT(_xlfn.ISFORMULA('F2-2 Arena'!$F$6)),NOT(_xlfn.ISFORMULA('F2-2 Arena'!$F$7)),NOT(_xlfn.ISFORMULA('F2-2 Arena'!$F$8)),NOT(_xlfn.ISFORMULA('F2-2 Arena'!$F$9)),NOT(_xlfn.ISFORMULA('F2-2 Arena'!$F$10)),NOT(_xlfn.ISFORMULA('F2-2 Arena'!$F$11)),NOT(_xlfn.ISFORMULA('F2-2 Arena'!$F$12)),NOT(_xlfn.ISFORMULA('F2-2 Arena'!$F$13)),NOT(_xlfn.ISFORMULA('F2-2 Arena'!$F$14)),NOT(_xlfn.ISFORMULA('F2-2 Arena'!$F$15))),"✘ Some cells aren't formulas yet",IF(OR(ISERROR('F2-2 Arena'!$F$6),ISERROR('F2-2 Arena'!$F$7),ISERROR('F2-2 Arena'!$F$8),ISERROR('F2-2 Arena'!$F$9),ISERROR('F2-2 Arena'!$F$10),ISERROR('F2-2 Arena'!$F$11),ISERROR('F2-2 Arena'!$F$12),ISERROR('F2-2 Arena'!$F$13),ISERROR('F2-2 Arena'!$F$14),ISERROR('F2-2 Arena'!$F$15)),"✘ Some cells show an error",IF(NOT(AND(IFERROR(AND(ISTEXT('F2-2 Arena'!$F$6),'F2-2 Arena'!$F$6=Key!$E$37),FALSE),IFERROR(AND(ISTEXT('F2-2 Arena'!$F$7),'F2-2 Arena'!$F$7=Key!$F$37),FALSE),IFERROR(AND(ISTEXT('F2-2 Arena'!$F$8),'F2-2 Arena'!$F$8=Key!$G$37),FALSE),IFERROR(AND(ISTEXT('F2-2 Arena'!$F$9),'F2-2 Arena'!$F$9=Key!$H$37),FALSE),IFERROR(AND(ISTEXT('F2-2 Arena'!$F$10),'F2-2 Arena'!$F$10=Key!$I$37),FALSE),IFERROR(AND(ISTEXT('F2-2 Arena'!$F$11),'F2-2 Arena'!$F$11=Key!$J$37),FALSE),IFERROR(AND(ISTEXT('F2-2 Arena'!$F$12),'F2-2 Arena'!$F$12=Key!$K$37),FALSE),IFERROR(AND(ISTEXT('F2-2 Arena'!$F$13),'F2-2 Arena'!$F$13=Key!$L$37),FALSE),IFERROR(AND(ISTEXT('F2-2 Arena'!$F$14),'F2-2 Arena'!$F$14=Key!$M$37),FALSE),IFERROR(AND(ISTEXT('F2-2 Arena'!$F$15),'F2-2 Arena'!$F$15=Key!$N$37),FALSE))),"✘ TRY AGAIN",IF(AND(OR(ISNUMBER(FIND({"=","(",",","+","-","*","/","&"," ","<",">",":","@","^"}&"IF"&"(",UPPER(_xlfn.FORMULATEXT('F2-2 Arena'!$F$6)))))),"✔ CLEAR","✘ CLOSE · right value, but use IF")))))} | F36: {=IF(E36="Show hint",Key!$B$37,"")} | G36: {=IF(LEFT(D36,1)="✔",IF(E36="Show hint",5,10),0)} -> 0
A37: C5 | B37: In G6: if the Score is 80 or more, the bonus is Score × 10, otherwise 0. Fill down to G15. | C37: ▶ ARENA C5 (cell G6) | D37: {=IF(COUNTA('F2-2 Arena'!$G$6,'F2-2 Arena'!$G$7,'F2-2 Arena'!$G$8,'F2-2 Arena'!$G$9,'F2-2 Arena'!$G$10,'F2-2 Arena'!$G$11,'F2-2 Arena'!$G$12,'F2-2 Arena'!$G$13,'F2-2 Arena'!$G$14,'F2-2 Arena'!$G$15)=0,"",IF(OR(NOT(_xlfn.ISFORMULA('F2-2 Arena'!$G$6)),NOT(_xlfn.ISFORMULA('F2-2 Arena'!$G$7)),NOT(_xlfn.ISFORMULA('F2-2 Arena'!$G$8)),NOT(_xlfn.ISFORMULA('F2-2 Arena'!$G$9)),NOT(_xlfn.ISFORMULA('F2-2 Arena'!$G$10)),NOT(_xlfn.ISFORMULA('F2-2 Arena'!$G$11)),NOT(_xlfn.ISFORMULA('F2-2 Arena'!$G$12)),NOT(_xlfn.ISFORMULA('F2-2 Arena'!$G$13)),NOT(_xlfn.ISFORMULA('F2-2 Arena'!$G$14)),NOT(_xlfn.ISFORMULA('F2-2 Arena'!$G$15))),"✘ Some cells aren't formulas yet",IF(OR(ISERROR('F2-2 Arena'!$G$6),ISERROR('F2-2 Arena'!$G$7),ISERROR('F2-2 Arena'!$G$8),ISERROR('F2-2 Arena'!$G$9),ISERROR('F2-2 Arena'!$G$10),ISERROR('F2-2 Arena'!$G$11),ISERROR('F2-2 Arena'!$G$12),ISERROR('F2-2 Arena'!$G$13),ISERROR('F2-2 Arena'!$G$14),ISERROR('F2-2 Arena'!$G$15)),"✘ Some cells show an error",IF(NOT(AND(IFERROR(AND(ISNUMBER('F2-2 Arena'!$G$6),ABS('F2-2 Arena'!$G$6-Key!$E$38)<=1E-9*MAX(1,ABS(Key!$E$38))),FALSE),IFERROR(AND(ISNUMBER('F2-2 Arena'!$G$7),ABS('F2-2 Arena'!$G$7-Key!$F$38)<=1E-9*MAX(1,ABS(Key!$F$38))),FALSE),IFERROR(AND(ISNUMBER('F2-2 Arena'!$G$8),ABS('F2-2 Arena'!$G$8-Key!$G$38)<=1E-9*MAX(1,ABS(Key!$G$38))),FALSE),IFERROR(AND(ISNUMBER('F2-2 Arena'!$G$9),ABS('F2-2 Arena'!$G$9-Key!$H$38)<=1E-9*MAX(1,ABS(Key!$H$38))),FALSE),IFERROR(AND(ISNUMBER('F2-2 Arena'!$G$10),ABS('F2-2 Arena'!$G$10-Key!$I$38)<=1E-9*MAX(1,ABS(Key!$I$38))),FALSE),IFERROR(AND(ISNUMBER('F2-2 Arena'!$G$11),ABS('F2-2 Arena'!$G$11-Key!$J$38)<=1E-9*MAX(1,ABS(Key!$J$38))),FALSE),IFERROR(AND(ISNUMBER('F2-2 Arena'!$G$12),ABS('F2-2 Arena'!$G$12-Key!$K$38)<=1E-9*MAX(1,ABS(Key!$K$38))),FALSE),IFERROR(AND(ISNUMBER('F2-2 Arena'!$G$13),ABS('F2-2 Arena'!$G$13-Key!$L$38)<=1E-9*MAX(1,ABS(Key!$L$38))),FALSE),IFERROR(AND(ISNUMBER('F2-2 Arena'!$G$14),ABS('F2-2 Arena'!$G$14-Key!$M$38)<=1E-9*MAX(1,ABS(Key!$M$38))),FALSE),IFERROR(AND(ISNUMBER('F2-2 Arena'!$G$15),ABS('F2-2 Arena'!$G$15-Key!$N$38)<=1E-9*MAX(1,ABS(Key!$N$38))),FALSE))),"✘ TRY AGAIN",IF(AND(OR(ISNUMBER(FIND({"=","(",",","+","-","*","/","&"," ","<",">",":","@","^"}&"IF"&"(",UPPER(_xlfn.FORMULATEXT('F2-2 Arena'!$G$6)))))),"✔ CLEAR","✘ CLOSE · right value, but use IF")))))} | F37: {=IF(E37="Show hint",Key!$B$38,"")} | G37: {=IF(LEFT(D37,1)="✔",IF(E37="Show hint",5,10),0)} -> 0
A38: C6 | B38: J6 is empty. In I6 write a formula that shows empty text ("") when J6 is empty, otherwise J6*2. | C38: ▶ ARENA C6 (cell I6) | D38: {=IF(ISBLANK('F2-2 Arena'!$I$6),"",IF(NOT(_xlfn.ISFORMULA('F2-2 Arena'!$I$6)),"✘ That's a typed value · enter a formula",IF(ISERROR('F2-2 Arena'!$I$6),"✘ Your formula returns "&IFERROR(CHOOSE(ERROR.TYPE('F2-2 Arena'!$I$6),"#NULL!","#DIV/0!","#VALUE!","#REF!","#NAME?","#NUM!","#N/A","#GETTING_DATA","#SPILL!","#CONNECT!","#BLOCKED!","#UNKNOWN!","#FIELD!","#CALC!"),"an error"),IF(NOT(AND(IFERROR(AND(ISTEXT('F2-2 Arena'!$I$6),'F2-2 Arena'!$I$6=Key!$C$39),FALSE))),"✘ TRY AGAIN",IF(AND(OR(ISNUMBER(FIND({"=","(",",","+","-","*","/","&"," ","<",">",":","@","^"}&"IF"&"(",UPPER(_xlfn.FORMULATEXT('F2-2 Arena'!$I$6)))))),"✔ CLEAR","✘ CLOSE · right value, but use IF")))))} | F38: {=IF(E38="Show hint",Key!$B$39,"")} | G38: {=IF(LEFT(D38,1)="✔",IF(E38="Show hint",5,10),0)} -> 0

Sheet F2-2 Arena
A1: ARENA ▸ F2-2 FORK IN THE ROAD
A2: Practice area · everything here is editable. Missions and their checks are on the stage sheet.
A3: PASS CODE | B3: CROSSROADS | D3: ◀ Back to F2-2 Fork in the Road
B5: Name | C5: Score | D5: Age | E5: License | F5: Result | G5: Bonus | I5: Blank-safe ×2 | J5: Empty cell ↓
B6: Ava | C6: 92 | D6: 17 | E6: No
B7: Ben | C7: 48 | D7: 22 | E7: Yes
B8: Cy | C8: 75 | D8: 19 | E8: Yes
B9: Dee | C9: 60 | D9: 16 | E9: No
B10: Eli | C10: 88 | D10: 30 | E10: Yes
B11: Fay | C11: 50 | D11: 18 | E11: Yes
B12: Gus | C12: 39 | D12: 25 | E12: No
B13: Hal | C13: 81 | D13: 41 | E13: Yes
B14: Ivy | C14: 99 | D14: 15 | E14: No
B15: Jo | C15: 70 | D15: 20 | E15: No

Sheet F2-3 Combo Moves
A1: STAGE F2-3 ▸ COMBO MOVES
A2: Goal: combine conditions with AND, OR and NOT
A3: {="SCORE "&TEXT(SUM($G$13:$G$38),"0000")&" / 0190"} -> SCORE 0000 / 0190 | C3: {=IF(SUM($G$13:$G$38)>=190,"★★★",IF(SUM($G$13:$G$38)>=190*0.8,"★★☆",IF(SUM($G$13:$G$38)>=190*0.5,"★☆☆","☆☆☆")))} -> ☆☆☆ | D3: {=REPT("█",ROUND(10*SUM($G$13:$G$38)/190,0))&REPT("░",10-ROUND(10*SUM($G$13:$G$38)/190,0))&" "&TEXT(SUM($G$13:$G$38)/190,"0%")} -> ░░░░░░░░░░ 0% | F3: {=IF(SUM($G$13:$G$38)>=190*0.5,"STAGE CLEAR! ▶ Next: F2-4 Multi-Level","")}
A5: BRIEFING · new moves in this stage
A6: # | B6: What it does · Pro tip | C6: Keys / Syntax
A7: 1 | B7: TRUE only when every condition is TRUE. Tip: =AND(B2>=18,C2="Yes") | C7: AND
A8: 2 | B8: TRUE when at least one condition is TRUE. Tip: =OR(B2>=90,C2<16) | C8: OR
A9: 3 | B9: Flip TRUE to FALSE and FALSE to TRUE. Tip: =NOT(B2="Yes") is TRUE for No. | C9: NOT
A11: WARM-UP · flashback to earlier stages
A12: # | B12: Mission | C12: Your answer | D12: Result | E12: Hint? | F12: Hint | G12: XP
A13: W1 | B13: Which function returns one value when a test is TRUE and another when FALSE? (from F2-2 Fork in the Road) | D13: {=IFERROR(_xlfn.LET(_xlpm.a,'F2-3 Combo Moves'!$C$13,IF(TRIM(_xlpm.a&"")="","",IF(OR(SUBSTITUTE(SUBSTITUTE(SUBSTITUTE(SUBSTITUTE(SUBSTITUTE(SUBSTITUTE(SUBSTITUTE(SUBSTITUTE(SUBSTITUTE(SUBSTITUTE(SUBSTITUTE(SUBSTITUTE(SUBSTITUTE(SUBSTITUTE(SUBSTITUTE(SUBSTITUTE(SUBSTITUTE(SUBSTITUTE(SUBSTITUTE(SUBSTITUTE(SUBSTITUTE(SUBSTITUTE(SUBSTITUTE(SUBSTITUTE(SUBSTITUTE(SUBSTITUTE(SUBSTITUTE(UPPER(_xlpm.a)," ",""),"CONTROL","CTRL"),"CTL","CTRL"),"ESCAPE","ESC"),"RETURN","ENTER"),"PAGEDOWN","PGDN"),"PGDOWN","PGDN"),"PAGEUP","PGUP"),"ARROWKEYS","ARROW"),"ARROWKEY","ARROW"),"ARROWS","ARROW"),"DOWNARROW","DOWN"),"UPARROW","UP"),"LEFTARROW","LEFT"),"RIGHTARROW","RIGHT"),"ARROWDOWN","DOWN"),"ARROWUP","UP"),"ARROWLEFT","LEFT"),"ARROWRIGHT","RIGHT"),"↓","DOWN"),"↑","UP"),"←","LEFT"),"→","RIGHT"),"SPACEBAR","SPACE"),"−","-"),"MINUS","-"),"PLUS","+")=Key!$E$40:$J$40),"✔ CLEAR","✘ TRY AGAIN"))),"✘ TRY AGAIN")} | F13: {=IF(E13="Show hint",Key!$B$40,"")} | G13: {=IF(LEFT(D13,1)="✔",IF(E13="Show hint",5,10),0)} -> 0
A14: W2 | B14: In =IF(B2>100,B2*0.9,B2), what is returned when B2 is 50? (from F2-2 Fork in the Road) | D14: {=IFERROR(_xlfn.LET(_xlpm.a,'F2-3 Combo Moves'!$C$14,IF(TRIM(_xlpm.a&"")="","",IF(OR(SUBSTITUTE(SUBSTITUTE(SUBSTITUTE(SUBSTITUTE(SUBSTITUTE(SUBSTITUTE(SUBSTITUTE(SUBSTITUTE(SUBSTITUTE(SUBSTITUTE(SUBSTITUTE(SUBSTITUTE(SUBSTITUTE(SUBSTITUTE(SUBSTITUTE(SUBSTITUTE(SUBSTITUTE(SUBSTITUTE(SUBSTITUTE(SUBSTITUTE(SUBSTITUTE(SUBSTITUTE(SUBSTITUTE(SUBSTITUTE(SUBSTITUTE(SUBSTITUTE(SUBSTITUTE(UPPER(_xlpm.a)," ",""),"CONTROL","CTRL"),"CTL","CTRL"),"ESCAPE","ESC"),"RETURN","ENTER"),"PAGEDOWN","PGDN"),"PGDOWN","PGDN"),"PAGEUP","PGUP"),"ARROWKEYS","ARROW"),"ARROWKEY","ARROW"),"ARROWS","ARROW"),"DOWNARROW","DOWN"),"UPARROW","UP"),"LEFTARROW","LEFT"),"RIGHTARROW","RIGHT"),"ARROWDOWN","DOWN"),"ARROWUP","UP"),"ARROWLEFT","LEFT"),"ARROWRIGHT","RIGHT"),"↓","DOWN"),"↑","UP"),"←","LEFT"),"→","RIGHT"),"SPACEBAR","SPACE"),"−","-"),"MINUS","-"),"PLUS","+")=Key!$E$41:$E$41),"✔ CLEAR","✘ TRY AGAIN"))),"✘ TRY AGAIN")} | F14: {=IF(E14="Show hint",Key!$B$41,"")} | G14: {=IF(LEFT(D14,1)="✔",IF(E14="Show hint",5,10),0)} -> 0
A15: W3 | B15: What do you type in a formula for an empty, blank-looking result? (from F2-2 Fork in the Road) | D15: {=IFERROR(_xlfn.LET(_xlpm.a,'F2-3 Combo Moves'!$C$15,IF(TRIM(_xlpm.a&"")="","",IF(OR(SUBSTITUTE(SUBSTITUTE(SUBSTITUTE(SUBSTITUTE(SUBSTITUTE(SUBSTITUTE(SUBSTITUTE(SUBSTITUTE(SUBSTITUTE(SUBSTITUTE(SUBSTITUTE(SUBSTITUTE(SUBSTITUTE(SUBSTITUTE(SUBSTITUTE(SUBSTITUTE(SUBSTITUTE(SUBSTITUTE(SUBSTITUTE(SUBSTITUTE(SUBSTITUTE(SUBSTITUTE(SUBSTITUTE(SUBSTITUTE(SUBSTITUTE(SUBSTITUTE(SUBSTITUTE(UPPER(_xlpm.a)," ",""),"CONTROL","CTRL"),"CTL","CTRL"),"ESCAPE","ESC"),"RETURN","ENTER"),"PAGEDOWN","PGDN"),"PGDOWN","PGDN"),"PAGEUP","PGUP"),"ARROWKEYS","ARROW"),"ARROWKEY","ARROW"),"ARROWS","ARROW"),"DOWNARROW","DOWN"),"UPARROW","UP"),"LEFTARROW","LEFT"),"RIGHTARROW","RIGHT"),"ARROWDOWN","DOWN"),"ARROWUP","UP"),"ARROWLEFT","LEFT"),"ARROWRIGHT","RIGHT"),"↓","DOWN"),"↑","UP"),"←","LEFT"),"→","RIGHT"),"SPACEBAR","SPACE"),"−","-"),"MINUS","-"),"PLUS","+")=Key!$E$42:$E$42),"✔ CLEAR","✘ TRY AGAIN"))),"✘ TRY AGAIN")} | F15: {=IF(E15="Show hint",Key!$B$42,"")} | G15: {=IF(LEFT(D15,1)="✔",IF(E15="Show hint",5,10),0)} -> 0
A16: W4 | B16: Which keys type today's date as a fixed value? (from S2-3 Stamps & Smart Fill) | D16: {=IFERROR(_xlfn.LET(_xlpm.a,'F2-3 Combo Moves'!$C$16,IF(TRIM(_xlpm.a&"")="","",IF(OR(SUBSTITUTE(SUBSTITUTE(SUBSTITUTE(SUBSTITUTE(SUBSTITUTE(SUBSTITUTE(SUBSTITUTE(SUBSTITUTE(SUBSTITUTE(SUBSTITUTE(SUBSTITUTE(SUBSTITUTE(SUBSTITUTE(SUBSTITUTE(SUBSTITUTE(SUBSTITUTE(SUBSTITUTE(SUBSTITUTE(SUBSTITUTE(SUBSTITUTE(SUBSTITUTE(SUBSTITUTE(SUBSTITUTE(SUBSTITUTE(SUBSTITUTE(SUBSTITUTE(SUBSTITUTE(UPPER(_xlpm.a)," ",""),"CONTROL","CTRL"),"CTL","CTRL"),"ESCAPE","ESC"),"RETURN","ENTER"),"PAGEDOWN","PGDN"),"PGDOWN","PGDN"),"PAGEUP","PGUP"),"ARROWKEYS","ARROW"),"ARROWKEY","ARROW"),"ARROWS","ARROW"),"DOWNARROW","DOWN"),"UPARROW","UP"),"LEFTARROW","LEFT"),"RIGHTARROW","RIGHT"),"ARROWDOWN","DOWN"),"ARROWUP","UP"),"ARROWLEFT","LEFT"),"ARROWRIGHT","RIGHT"),"↓","DOWN"),"↑","UP"),"←","LEFT"),"→","RIGHT"),"SPACEBAR","SPACE"),"−","-"),"MINUS","-"),"PLUS","+")=Key!$E$43:$F$43),"✔ CLEAR","✘ TRY AGAIN"))),"✘ TRY AGAIN")} | F16: {=IF(E16="Show hint",Key!$B$43,"")} | G16: {=IF(LEFT(D16,1)="✔",IF(E16="Show hint",5,10),0)} -> 0
A17: W5 | B17: Which keys type the current time as a fixed value? (from S2-3 Stamps & Smart Fill) | D17: {=IFERROR(_xlfn.LET(_xlpm.a,'F2-3 Combo Moves'!$C$17,IF(TRIM(_xlpm.a&"")="","",IF(OR(SUBSTITUTE(SUBSTITUTE(SUBSTITUTE(SUBSTITUTE(SUBSTITUTE(SUBSTITUTE(SUBSTITUTE(SUBSTITUTE(SUBSTITUTE(SUBSTITUTE(SUBSTITUTE(SUBSTITUTE(SUBSTITUTE(SUBSTITUTE(SUBSTITUTE(SUBSTITUTE(SUBSTITUTE(SUBSTITUTE(SUBSTITUTE(SUBSTITUTE(SUBSTITUTE(SUBSTITUTE(SUBSTITUTE(SUBSTITUTE(SUBSTITUTE(SUBSTITUTE(SUBSTITUTE(UPPER(_xlpm.a)," ",""),"CONTROL","CTRL"),"CTL","CTRL"),"ESCAPE","ESC"),"RETURN","ENTER"),"PAGEDOWN","PGDN"),"PGDOWN","PGDN"),"PAGEUP","PGUP"),"ARROWKEYS","ARROW"),"ARROWKEY","ARROW"),"ARROWS","ARROW"),"DOWNARROW","DOWN"),"UPARROW","UP"),"LEFTARROW","LEFT"),"RIGHTARROW","RIGHT"),"ARROWDOWN","DOWN"),"ARROWUP","UP"),"ARROWLEFT","LEFT"),"ARROWRIGHT","RIGHT"),"↓","DOWN"),"↑","UP"),"←","LEFT"),"→","RIGHT"),"SPACEBAR","SPACE"),"−","-"),"MINUS","-"),"PLUS","+")=Key!$E$44:$K$44),"✔ CLEAR","✘ TRY AGAIN"))),"✘ TRY AGAIN")} | F17: {=IF(E17="Show hint",Key!$B$44,"")} | G17: {=IF(LEFT(D17,1)="✔",IF(E17="Show hint",5,10),0)} -> 0
A18: W6 | B18: Which keys run Flash Fill? (from S2-3 Stamps & Smart Fill) | D18: {=IFERROR(_xlfn.LET(_xlpm.a,'F2-3 Combo Moves'!$C$18,IF(TRIM(_xlpm.a&"")="","",IF(OR(SUBSTITUTE(SUBSTITUTE(SUBSTITUTE(SUBSTITUTE(SUBSTITUTE(SUBSTITUTE(SUBSTITUTE(SUBSTITUTE(SUBSTITUTE(SUBSTITUTE(SUBSTITUTE(SUBSTITUTE(SUBSTITUTE(SUBSTITUTE(SUBSTITUTE(SUBSTITUTE(SUBSTITUTE(SUBSTITUTE(SUBSTITUTE(SUBSTITUTE(SUBSTITUTE(SUBSTITUTE(SUBSTITUTE(SUBSTITUTE(SUBSTITUTE(SUBSTITUTE(SUBSTITUTE(UPPER(_xlpm.a)," ",""),"CONTROL","CTRL"),"CTL","CTRL"),"ESCAPE","ESC"),"RETURN","ENTER"),"PAGEDOWN","PGDN"),"PGDOWN","PGDN"),"PAGEUP","PGUP"),"ARROWKEYS","ARROW"),"ARROWKEY","ARROW"),"ARROWS","ARROW"),"DOWNARROW","DOWN"),"UPARROW","UP"),"LEFTARROW","LEFT"),"RIGHTARROW","RIGHT"),"ARROWDOWN","DOWN"),"ARROWUP","UP"),"ARROWLEFT","LEFT"),"ARROWRIGHT","RIGHT"),"↓","DOWN"),"↑","UP"),"←","LEFT"),"→","RIGHT"),"SPACEBAR","SPACE"),"−","-"),"MINUS","-"),"PLUS","+")=Key!$E$45:$E$45),"✔ CLEAR","✘ TRY AGAIN"))),"✘ TRY AGAIN")} | F18: {=IF(E18="Show hint",Key!$B$45,"")} | G18: {=IF(LEFT(D18,1)="✔",IF(E18="Show hint",5,10),0)} -> 0
A19: W7 | B19: Which keys open the dropdown list of a cell? (from S2-3 Stamps & Smart Fill) | D19: {=IFERROR(_xlfn.LET(_xlpm.a,'F2-3 Combo Moves'!$C$19,IF(TRIM(_xlpm.a&"")="","",IF(OR(SUBSTITUTE(SUBSTITUTE(SUBSTITUTE(SUBSTITUTE(SUBSTITUTE(SUBSTITUTE(SUBSTITUTE(SUBSTITUTE(SUBSTITUTE(SUBSTITUTE(SUBSTITUTE(SUBSTITUTE(SUBSTITUTE(SUBSTITUTE(SUBSTITUTE(SUBSTITUTE(SUBSTITUTE(SUBSTITUTE(SUBSTITUTE(SUBSTITUTE(SUBSTITUTE(SUBSTITUTE(SUBSTITUTE(SUBSTITUTE(SUBSTITUTE(SUBSTITUTE(SUBSTITUTE(UPPER(_xlpm.a)," ",""),"CONTROL","CTRL"),"CTL","CTRL"),"ESCAPE","ESC"),"RETURN","ENTER"),"PAGEDOWN","PGDN"),"PGDOWN","PGDN"),"PAGEUP","PGUP"),"ARROWKEYS","ARROW"),"ARROWKEY","ARROW"),"ARROWS","ARROW"),"DOWNARROW","DOWN"),"UPARROW","UP"),"LEFTARROW","LEFT"),"RIGHTARROW","RIGHT"),"ARROWDOWN","DOWN"),"ARROWUP","UP"),"ARROWLEFT","LEFT"),"ARROWRIGHT","RIGHT"),"↓","DOWN"),"↑","UP"),"←","LEFT"),"→","RIGHT"),"SPACEBAR","SPACE"),"−","-"),"MINUS","-"),"PLUS","+")=Key!$E$46:$E$46),"✔ CLEAR","✘ TRY AGAIN"))),"✘ TRY AGAIN")} | F19: {=IF(E19="Show hint",Key!$B$46,"")} | G19: {=IF(LEFT(D19,1)="✔",IF(E19="Show hint",5,10),0)} -> 0
A20: W8 | B20: Which keys extend the selection to the last used cell? (from S1-3 Lasso) | D20: {=IFERROR(_xlfn.LET(_xlpm.a,'F2-3 Combo Moves'!$C$20,IF(TRIM(_xlpm.a&"")="","",IF(OR(SUBSTITUTE(SUBSTITUTE(SUBSTITUTE(SUBSTITUTE(SUBSTITUTE(SUBSTITUTE(SUBSTITUTE(SUBSTITUTE(SUBSTITUTE(SUBSTITUTE(SUBSTITUTE(SUBSTITUTE(SUBSTITUTE(SUBSTITUTE(SUBSTITUTE(SUBSTITUTE(SUBSTITUTE(SUBSTITUTE(SUBSTITUTE(SUBSTITUTE(SUBSTITUTE(SUBSTITUTE(SUBSTITUTE(SUBSTITUTE(SUBSTITUTE(SUBSTITUTE(SUBSTITUTE(UPPER(_xlpm.a)," ",""),"CONTROL","CTRL"),"CTL","CTRL"),"ESCAPE","ESC"),"RETURN","ENTER"),"PAGEDOWN","PGDN"),"PGDOWN","PGDN"),"PAGEUP","PGUP"),"ARROWKEYS","ARROW"),"ARROWKEY","ARROW"),"ARROWS","ARROW"),"DOWNARROW","DOWN"),"UPARROW","UP"),"LEFTARROW","LEFT"),"RIGHTARROW","RIGHT"),"ARROWDOWN","DOWN"),"ARROWUP","UP"),"ARROWLEFT","LEFT"),"ARROWRIGHT","RIGHT"),"↓","DOWN"),"↑","UP"),"←","LEFT"),"→","RIGHT"),"SPACEBAR","SPACE"),"−","-"),"MINUS","-"),"PLUS","+")=Key!$E$47:$F$47),"✔ CLEAR","✘ TRY AGAIN"))),"✘ TRY AGAIN")} | F20: {=IF(E20="Show hint",Key!$B$47,"")} | G20: {=IF(LEFT(D20,1)="✔",IF(E20="Show hint",5,10),0)} -> 0
A21: W9 | B21: Which keys extend the selection back to cell A1? (from S1-3 Lasso) | D21: {=IFERROR(_xlfn.LET(_xlpm.a,'F2-3 Combo Moves'!$C$21,IF(TRIM(_xlpm.a&"")="","",IF(OR(SUBSTITUTE(SUBSTITUTE(SUBSTITUTE(SUBSTITUTE(SUBSTITUTE(SUBSTITUTE(SUBSTITUTE(SUBSTITUTE(SUBSTITUTE(SUBSTITUTE(SUBSTITUTE(SUBSTITUTE(SUBSTITUTE(SUBSTITUTE(SUBSTITUTE(SUBSTITUTE(SUBSTITUTE(SUBSTITUTE(SUBSTITUTE(SUBSTITUTE(SUBSTITUTE(SUBSTITUTE(SUBSTITUTE(SUBSTITUTE(SUBSTITUTE(SUBSTITUTE(SUBSTITUTE(UPPER(_xlpm.a)," ",""),"CONTROL","CTRL"),"CTL","CTRL"),"ESCAPE","ESC"),"RETURN","ENTER"),"PAGEDOWN","PGDN"),"PGDOWN","PGDN"),"PAGEUP","PGUP"),"ARROWKEYS","ARROW"),"ARROWKEY","ARROW"),"ARROWS","ARROW"),"DOWNARROW","DOWN"),"UPARROW","UP"),"LEFTARROW","LEFT"),"RIGHTARROW","RIGHT"),"ARROWDOWN","DOWN"),"ARROWUP","UP"),"ARROWLEFT","LEFT"),"ARROWRIGHT","RIGHT"),"↓","DOWN"),"↑","UP"),"←","LEFT"),"→","RIGHT"),"SPACEBAR","SPACE"),"−","-"),"MINUS","-"),"PLUS","+")=Key!$E$48:$F$48),"✔ CLEAR","✘ TRY AGAIN"))),"✘ TRY AGAIN")} | F21: {=IF(E21="Show hint",Key!$B$48,"")} | G21: {=IF(LEFT(D21,1)="✔",IF(E21="Show hint",5,10),0)} -> 0
A22: W10 | B22: Which keys select the entire row? (from S1-4 Grab) | D22: {=IFERROR(_xlfn.LET(_xlpm.a,'F2-3 Combo Moves'!$C$22,IF(TRIM(_xlpm.a&"")="","",IF(OR(SUBSTITUTE(SUBSTITUTE(SUBSTITUTE(SUBSTITUTE(SUBSTITUTE(SUBSTITUTE(SUBSTITUTE(SUBSTITUTE(SUBSTITUTE(SUBSTITUTE(SUBSTITUTE(SUBSTITUTE(SUBSTITUTE(SUBSTITUTE(SUBSTITUTE(SUBSTITUTE(SUBSTITUTE(SUBSTITUTE(SUBSTITUTE(SUBSTITUTE(SUBSTITUTE(SUBSTITUTE(SUBSTITUTE(SUBSTITUTE(SUBSTITUTE(SUBSTITUTE(SUBSTITUTE(UPPER(_xlpm.a)," ",""),"CONTROL","CTRL"),"CTL","CTRL"),"ESCAPE","ESC"),"RETURN","ENTER"),"PAGEDOWN","PGDN"),"PGDOWN","PGDN"),"PAGEUP","PGUP"),"ARROWKEYS","ARROW"),"ARROWKEY","ARROW"),"ARROWS","ARROW"),"DOWNARROW","DOWN"),"UPARROW","UP"),"LEFTARROW","LEFT"),"RIGHTARROW","RIGHT"),"ARROWDOWN","DOWN"),"ARROWUP","UP"),"ARROWLEFT","LEFT"),"ARROWRIGHT","RIGHT"),"↓","DOWN"),"↑","UP"),"←","LEFT"),"→","RIGHT"),"SPACEBAR","SPACE"),"−","-"),"MINUS","-"),"PLUS","+")=Key!$E$49:$E$49),"✔ CLEAR","✘ TRY AGAIN"))),"✘ TRY AGAIN")} | F22: {=IF(E22="Show hint",Key!$B$49,"")} | G22: {=IF(LEFT(D22,1)="✔",IF(E22="Show hint",5,10),0)} -> 0
A24: TRAINING · recognize the move (pick from the list)
A25: # | B25: Mission | C25: Your answer | D25: Result | E25: Hint? | F25: Hint | G25: XP
