Workbook

Sheet Start
A1: FORMULAS 3 ▸ CONDITIONAL MATH
A2: Count, add and average only the rows that match.
A4: HOW TO PLAY
A5: 1 · Each stage: read the BRIEFING, then answer WARM-UP, TRAINING and CHALLENGES.
A6: 2 · Yellow cells are yours: type, pick from a list (Alt+↓), or follow a ▶ ARENA link and do the move there.
A7: 3 · ✔ CLEAR = right · ✘ = try again · · not yet = drill not done. Stuck? Pick 'Show hint' (5 XP instead of 10).
A8: 4 · Formatting or hiding drills: press F9 to refresh the check. Tab jumps between yellow cells.
A9: Needs Windows with Microsoft Excel 365 or 2021+ (English). In Protected View, click Enable Editing.
A11: STAGE SELECT
A12: Stage | B12: Name | C12: Score | D12: Stars | E12: Status | F12: Go
A13: F3-1 | B13: Counters | C13: {=SUM('F3-1 Counters'!$G$13:$G$39)&" / 200"} -> 0 / 200 | D13: {=IF(SUM('F3-1 Counters'!$G$13:$G$39)>=200,"★★★",IF(SUM('F3-1 Counters'!$G$13:$G$39)>=200*0.8,"★★☆",IF(SUM('F3-1 Counters'!$G$13:$G$39)>=200*0.5,"★☆☆","☆☆☆")))} -> ☆☆☆ | E13: {=IF(SUM('F3-1 Counters'!$G$13:$G$39)>=200,"PERFECT",IF(SUM('F3-1 Counters'!$G$13:$G$39)>=200*0.5,"CLEARED",IF(SUM('F3-1 Counters'!$G$13:$G$39)>0,"IN PROGRESS","NEW")))} -> NEW | F13: Go to F3-1 Counters
A14: F3-2 | B14: Money Bags | C14: {=SUM('F3-2 Money Bags'!$G$12:$G$35)&" / 170"} -> 0 / 170 | D14: {=IF(SUM('F3-2 Money Bags'!$G$12:$G$35)>=170,"★★★",IF(SUM('F3-2 Money Bags'!$G$12:$G$35)>=170*0.8,"★★☆",IF(SUM('F3-2 Money Bags'!$G$12:$G$35)>=170*0.5,"★☆☆","☆☆☆")))} -> ☆☆☆ | E14: {=IF(SUM('F3-2 Money Bags'!$G$12:$G$35)>=170,"PERFECT",IF(SUM('F3-2 Money Bags'!$G$12:$G$35)>=170*0.5,"CLEARED",IF(SUM('F3-2 Money Bags'!$G$12:$G$35)>0,"IN PROGRESS","NEW")))} -> NEW | F14: Go to F3-2 Money Bags
A15: F3-3 | B15: Multi-Filter | C15: {=SUM('F3-3 Multi-Filter'!$G$13:$G$38)&" / 190"} -> 0 / 190 | D15: {=IF(SUM('F3-3 Multi-Filter'!$G$13:$G$38)>=190,"★★★",IF(SUM('F3-3 Multi-Filter'!$G$13:$G$38)>=190*0.8,"★★☆",IF(SUM('F3-3 Multi-Filter'!$G$13:$G$38)>=190*0.5,"★☆☆","☆☆☆")))} -> ☆☆☆ | E15: {=IF(SUM('F3-3 Multi-Filter'!$G$13:$G$38)>=190,"PERFECT",IF(SUM('F3-3 Multi-Filter'!$G$13:$G$38)>=190*0.5,"CLEARED",IF(SUM('F3-3 Multi-Filter'!$G$13:$G$38)>0,"IN PROGRESS","NEW")))} -> NEW | F15: Go to F3-3 Multi-Filter
A16: F3-4 | B16: Extremes | C16: {=SUM('F3-4 Extremes'!$G$14:$G$42)&" / 220"} -> 0 / 220 | D16: {=IF(SUM('F3-4 Extremes'!$G$14:$G$42)>=220,"★★★",IF(SUM('F3-4 Extremes'!$G$14:$G$42)>=220*0.8,"★★☆",IF(SUM('F3-4 Extremes'!$G$14:$G$42)>=220*0.5,"★☆☆","☆☆☆")))} -> ☆☆☆ | E16: {=IF(SUM('F3-4 Extremes'!$G$14:$G$42)>=220,"PERFECT",IF(SUM('F3-4 Extremes'!$G$14:$G$42)>=220*0.5,"CLEARED",IF(SUM('F3-4 Extremes'!$G$14:$G$42)>0,"IN PROGRESS","NEW")))} -> NEW | F16: Go to F3-4 Extremes
A17: BOSS | B17: Boss | C17: {=SUM(Boss!$G$14:$G$33)&" / 160"} -> 0 / 160 | D17: {=IF(SUM(Boss!$G$14:$G$33)>=160,"★★★",IF(SUM(Boss!$G$14:$G$33)>=160*0.8,"★★☆",IF(SUM(Boss!$G$14:$G$33)>=160*0.5,"★☆☆","☆☆☆")))} -> ☆☆☆ | E17: {=IF(Boss!$C$10="OPEN",IF(SUM(Boss!$G$14:$G$33)>=160*0.5,"DEFEATED","OPEN"),"LOCKED")} -> LOCKED | F17: Go to the Boss
A19: TOTAL SCORE | B19: {=(SUM('F3-1 Counters'!$G$13:$G$39)+SUM('F3-2 Money Bags'!$G$12:$G$35)+SUM('F3-3 Multi-Filter'!$G$13:$G$38)+SUM('F3-4 Extremes'!$G$14:$G$42)+SUM(Boss!$G$14:$G$33))&" / 940"} -> 0 / 940
A20: RANK | B20: {=_xlfn.LET(_xlpm.p,(SUM('F3-1 Counters'!$G$13:$G$39)+SUM('F3-2 Money Bags'!$G$12:$G$35)+SUM('F3-3 Multi-Filter'!$G$13:$G$38)+SUM('F3-4 Extremes'!$G$14:$G$42)+SUM(Boss!$G$14:$G$33))/940,IF(AND(_xlpm.p>=1,ISNUMBER(Boss!$C$8),Boss!$C$8<=15),"S",IF(_xlpm.p>=0.9,"A",IF(_xlpm.p>=0.75,"B",IF(_xlpm.p>=0.5,"C","D")))))} -> D | C20: S = 100% and under par · A ≥ 90% · B ≥ 75% · C ≥ 50%
A21: BEST TIME | B21: {=IF(ISNUMBER(Boss!$C$8),Boss!$C$8&" min (par 15)","—")} -> —
A22: NEXT UP | B22: {=IFERROR(INDEX($A$13:$A$16,MATCH("☆☆☆",$D$13:$D$16,0))&" "&INDEX($B$13:$B$16,MATCH("☆☆☆",$D$13:$D$16,0)),IF(Boss!$C$10="OPEN","the Boss","All clear! Aim for rank S"))} -> F3-1 Counters
A24: Replay a stage: select its yellow answer cells and press Delete. Undo an arena drill with Ctrl+Z.

Sheet F3-1 Counters
A1: STAGE F3-1 ▸ COUNTERS
A2: Goal: count only the rows you care about
A3: {="SCORE "&TEXT(SUM($G$13:$G$39),"0000")&" / 0200"} -> SCORE 0000 / 0200 | C3: {=IF(SUM($G$13:$G$39)>=200,"★★★",IF(SUM($G$13:$G$39)>=200*0.8,"★★☆",IF(SUM($G$13:$G$39)>=200*0.5,"★☆☆","☆☆☆")))} -> ☆☆☆ | D3: {=REPT("█",ROUND(10*SUM($G$13:$G$39)/200,0))&REPT("░",10-ROUND(10*SUM($G$13:$G$39)/200,0))&" "&TEXT(SUM($G$13:$G$39)/200,"0%")} -> ░░░░░░░░░░ 0% | F3: {=IF(SUM($G$13:$G$39)>=200*0.5,"STAGE CLEAR! ▶ Next: F3-2 Money Bags","")}
A5: BRIEFING · new moves in this stage
A6: # | B6: What it does · Pro tip | C6: Keys / Syntax
A7: 1 | B7: Count the cells that meet one condition. Tip: =COUNTIF(D6:D25,"East") counts the East rows. | C7: COUNTIF
A8: 2 | B8: Put comparison criteria in quotes: ">50", "<>East". Tip: The operator goes inside the quotes with the value. | C8: ">50"
A9: 3 | B9: * matches any text, ? one character: "G*" = starts with G. Tip: Wildcards work in COUNTIF, SUMIF and their IFS cousins. | C9: * and ?
A11: WARM-UP · flashback to earlier stages
A12: # | B12: Mission | C12: Your answer | D12: Result | E12: Hint? | F12: Hint | G12: XP
A13: W1 | B13: Which keys apply the Currency format? (from S3-1 Number Skins) | D13: {=IFERROR(_xlfn.LET(_xlpm.a,'F3-1 Counters'!$C$13,IF(TRIM(_xlpm.a&"")="","",IF(OR(SUBSTITUTE(SUBSTITUTE(SUBSTITUTE(SUBSTITUTE(SUBSTITUTE(SUBSTITUTE(SUBSTITUTE(SUBSTITUTE(SUBSTITUTE(SUBSTITUTE(SUBSTITUTE(SUBSTITUTE(SUBSTITUTE(SUBSTITUTE(SUBSTITUTE(SUBSTITUTE(SUBSTITUTE(SUBSTITUTE(SUBSTITUTE(SUBSTITUTE(SUBSTITUTE(SUBSTITUTE(SUBSTITUTE(SUBSTITUTE(SUBSTITUTE(SUBSTITUTE(SUBSTITUTE(UPPER(_xlpm.a)," ",""),"CONTROL","CTRL"),"CTL","CTRL"),"ESCAPE","ESC"),"RETURN","ENTER"),"PAGEDOWN","PGDN"),"PGDOWN","PGDN"),"PAGEUP","PGUP"),"ARROWKEYS","ARROW"),"ARROWKEY","ARROW"),"ARROWS","ARROW"),"DOWNARROW","DOWN"),"UPARROW","UP"),"LEFTARROW","LEFT"),"RIGHTARROW","RIGHT"),"ARROWDOWN","DOWN"),"ARROWUP","UP"),"ARROWLEFT","LEFT"),"ARROWRIGHT","RIGHT"),"↓","DOWN"),"↑","UP"),"←","LEFT"),"→","RIGHT"),"SPACEBAR","SPACE"),"−","-"),"MINUS","-"),"PLUS","+")=Key!$E$2:$H$2),"✔ CLEAR","✘ TRY AGAIN"))),"✘ TRY AGAIN")} | F13: {=IF(E13="Show hint",Key!$B$2,"")} | G13: {=IF(LEFT(D13,1)="✔",IF(E13="Show hint",5,10),0)} -> 0
A14: W2 | B14: Which keys apply the Percent format? (from S3-1 Number Skins) | D14: {=IFERROR(_xlfn.LET(_xlpm.a,'F3-1 Counters'!$C$14,IF(TRIM(_xlpm.a&"")="","",IF(OR(SUBSTITUTE(SUBSTITUTE(SUBSTITUTE(SUBSTITUTE(SUBSTITUTE(SUBSTITUTE(SUBSTITUTE(SUBSTITUTE(SUBSTITUTE(SUBSTITUTE(SUBSTITUTE(SUBSTITUTE(SUBSTITUTE(SUBSTITUTE(SUBSTITUTE(SUBSTITUTE(SUBSTITUTE(SUBSTITUTE(SUBSTITUTE(SUBSTITUTE(SUBSTITUTE(SUBSTITUTE(SUBSTITUTE(SUBSTITUTE(SUBSTITUTE(SUBSTITUTE(SUBSTITUTE(UPPER(_xlpm.a)," ",""),"CONTROL","CTRL"),"CTL","CTRL"),"ESCAPE","ESC"),"RETURN","ENTER"),"PAGEDOWN","PGDN"),"PGDOWN","PGDN"),"PAGEUP","PGUP"),"ARROWKEYS","ARROW"),"ARROWKEY","ARROW"),"ARROWS","ARROW"),"DOWNARROW","DOWN"),"UPARROW","UP"),"LEFTARROW","LEFT"),"RIGHTARROW","RIGHT"),"ARROWDOWN","DOWN"),"ARROWUP","UP"),"ARROWLEFT","LEFT"),"ARROWRIGHT","RIGHT"),"↓","DOWN"),"↑","UP"),"←","LEFT"),"→","RIGHT"),"SPACEBAR","SPACE"),"−","-"),"MINUS","-"),"PLUS","+")=Key!$E$3:$H$3),"✔ CLEAR","✘ TRY AGAIN"))),"✘ TRY AGAIN")} | F14: {=IF(E14="Show hint",Key!$B$3,"")} | G14: {=IF(LEFT(D14,1)="✔",IF(E14="Show hint",5,10),0)} -> 0
A15: W3 | B15: Which keys apply the Number format with a thousands separator? (from S3-1 Number Skins) | D15: {=IFERROR(_xlfn.LET(_xlpm.a,'F3-1 Counters'!$C$15,IF(TRIM(_xlpm.a&"")="","",IF(OR(SUBSTITUTE(SUBSTITUTE(SUBSTITUTE(SUBSTITUTE(SUBSTITUTE(SUBSTITUTE(SUBSTITUTE(SUBSTITUTE(SUBSTITUTE(SUBSTITUTE(SUBSTITUTE(SUBSTITUTE(SUBSTITUTE(SUBSTITUTE(SUBSTITUTE(SUBSTITUTE(SUBSTITUTE(SUBSTITUTE(SUBSTITUTE(SUBSTITUTE(SUBSTITUTE(SUBSTITUTE(SUBSTITUTE(SUBSTITUTE(SUBSTITUTE(SUBSTITUTE(SUBSTITUTE(UPPER(_xlpm.a)," ",""),"CONTROL","CTRL"),"CTL","CTRL"),"ESCAPE","ESC"),"RETURN","ENTER"),"PAGEDOWN","PGDN"),"PGDOWN","PGDN"),"PAGEUP","PGUP"),"ARROWKEYS","ARROW"),"ARROWKEY","ARROW"),"ARROWS","ARROW"),"DOWNARROW","DOWN"),"UPARROW","UP"),"LEFTARROW","LEFT"),"RIGHTARROW","RIGHT"),"ARROWDOWN","DOWN"),"ARROWUP","UP"),"ARROWLEFT","LEFT"),"ARROWRIGHT","RIGHT"),"↓","DOWN"),"↑","UP"),"←","LEFT"),"→","RIGHT"),"SPACEBAR","SPACE"),"−","-"),"MINUS","-"),"PLUS","+")=Key!$E$4:$H$4),"✔ CLEAR","✘ TRY AGAIN"))),"✘ TRY AGAIN")} | F15: {=IF(E15="Show hint",Key!$B$4,"")} | G15: {=IF(LEFT(D15,1)="✔",IF(E15="Show hint",5,10),0)} -> 0
A16: W4 | B16: Which keys apply the Date format? (from S3-1 Number Skins) | D16: {=IFERROR(_xlfn.LET(_xlpm.a,'F3-1 Counters'!$C$16,IF(TRIM(_xlpm.a&"")="","",IF(OR(SUBSTITUTE(SUBSTITUTE(SUBSTITUTE(SUBSTITUTE(SUBSTITUTE(SUBSTITUTE(SUBSTITUTE(SUBSTITUTE(SUBSTITUTE(SUBSTITUTE(SUBSTITUTE(SUBSTITUTE(SUBSTITUTE(SUBSTITUTE(SUBSTITUTE(SUBSTITUTE(SUBSTITUTE(SUBSTITUTE(SUBSTITUTE(SUBSTITUTE(SUBSTITUTE(SUBSTITUTE(SUBSTITUTE(SUBSTITUTE(SUBSTITUTE(SUBSTITUTE(SUBSTITUTE(UPPER(_xlpm.a)," ",""),"CONTROL","CTRL"),"CTL","CTRL"),"ESCAPE","ESC"),"RETURN","ENTER"),"PAGEDOWN","PGDN"),"PGDOWN","PGDN"),"PAGEUP","PGUP"),"ARROWKEYS","ARROW"),"ARROWKEY","ARROW"),"ARROWS","ARROW"),"DOWNARROW","DOWN"),"UPARROW","UP"),"LEFTARROW","LEFT"),"RIGHTARROW","RIGHT"),"ARROWDOWN","DOWN"),"ARROWUP","UP"),"ARROWLEFT","LEFT"),"ARROWRIGHT","RIGHT"),"↓","DOWN"),"↑","UP"),"←","LEFT"),"→","RIGHT"),"SPACEBAR","SPACE"),"−","-"),"MINUS","-"),"PLUS","+")=Key!$E$5:$H$5),"✔ CLEAR","✘ TRY AGAIN"))),"✘ TRY AGAIN")} | F16: {=IF(E16="Show hint",Key!$B$5,"")} | G16: {=IF(LEFT(D16,1)="✔",IF(E16="Show hint",5,10),0)} -> 0
A17: W5 | B17: Which keys apply the Time format? (from S3-1 Number Skins) | D17: {=IFERROR(_xlfn.LET(_xlpm.a,'F3-1 Counters'!$C$17,IF(TRIM(_xlpm.a&"")="","",IF(OR(SUBSTITUTE(SUBSTITUTE(SUBSTITUTE(SUBSTITUTE(SUBSTITUTE(SUBSTITUTE(SUBSTITUTE(SUBSTITUTE(SUBSTITUTE(SUBSTITUTE(SUBSTITUTE(SUBSTITUTE(SUBSTITUTE(SUBSTITUTE(SUBSTITUTE(SUBSTITUTE(SUBSTITUTE(SUBSTITUTE(SUBSTITUTE(SUBSTITUTE(SUBSTITUTE(SUBSTITUTE(SUBSTITUTE(SUBSTITUTE(SUBSTITUTE(SUBSTITUTE(SUBSTITUTE(UPPER(_xlpm.a)," ",""),"CONTROL","CTRL"),"CTL","CTRL"),"ESCAPE","ESC"),"RETURN","ENTER"),"PAGEDOWN","PGDN"),"PGDOWN","PGDN"),"PAGEUP","PGUP"),"ARROWKEYS","ARROW"),"ARROWKEY","ARROW"),"ARROWS","ARROW"),"DOWNARROW","DOWN"),"UPARROW","UP"),"LEFTARROW","LEFT"),"RIGHTARROW","RIGHT"),"ARROWDOWN","DOWN"),"ARROWUP","UP"),"ARROWLEFT","LEFT"),"ARROWRIGHT","RIGHT"),"↓","DOWN"),"↑","UP"),"←","LEFT"),"→","RIGHT"),"SPACEBAR","SPACE"),"−","-"),"MINUS","-"),"PLUS","+")=Key!$E$6:$H$6),"✔ CLEAR","✘ TRY AGAIN"))),"✘ TRY AGAIN")} | F17: {=IF(E17="Show hint",Key!$B$6,"")} | G17: {=IF(LEFT(D17,1)="✔",IF(E17="Show hint",5,10),0)} -> 0
A18: W6 | B18: Which keys reset a cell to the General format? (from S3-1 Number Skins) | D18: {=IFERROR(_xlfn.LET(_xlpm.a,'F3-1 Counters'!$C$18,IF(TRIM(_xlpm.a&"")="","",IF(OR(SUBSTITUTE(SUBSTITUTE(SUBSTITUTE(SUBSTITUTE(SUBSTITUTE(SUBSTITUTE(SUBSTITUTE(SUBSTITUTE(SUBSTITUTE(SUBSTITUTE(SUBSTITUTE(SUBSTITUTE(SUBSTITUTE(SUBSTITUTE(SUBSTITUTE(SUBSTITUTE(SUBSTITUTE(SUBSTITUTE(SUBSTITUTE(SUBSTITUTE(SUBSTITUTE(SUBSTITUTE(SUBSTITUTE(SUBSTITUTE(SUBSTITUTE(SUBSTITUTE(SUBSTITUTE(UPPER(_xlpm.a)," ",""),"CONTROL","CTRL"),"CTL","CTRL"),"ESCAPE","ESC"),"RETURN","ENTER"),"PAGEDOWN","PGDN"),"PGDOWN","PGDN"),"PAGEUP","PGUP"),"ARROWKEYS","ARROW"),"ARROWKEY","ARROW"),"ARROWS","ARROW"),"DOWNARROW","DOWN"),"UPARROW","UP"),"LEFTARROW","LEFT"),"RIGHTARROW","RIGHT"),"ARROWDOWN","DOWN"),"ARROWUP","UP"),"ARROWLEFT","LEFT"),"ARROWRIGHT","RIGHT"),"↓","DOWN"),"↑","UP"),"←","LEFT"),"→","RIGHT"),"SPACEBAR","SPACE"),"−","-"),"MINUS","-"),"PLUS","+")=Key!$E$7:$H$7),"✔ CLEAR","✘ TRY AGAIN"))),"✘ TRY AGAIN")} | F18: {=IF(E18="Show hint",Key!$B$7,"")} | G18: {=IF(LEFT(D18,1)="✔",IF(E18="Show hint",5,10),0)} -> 0
A19: W7 | B19: Which keys insert a function's argument names after you type its name? (from F1-5 X-Ray) | D19: {=IFERROR(_xlfn.LET(_xlpm.a,'F3-1 Counters'!$C$19,IF(TRIM(_xlpm.a&"")="","",IF(OR(SUBSTITUTE(SUBSTITUTE(SUBSTITUTE(SUBSTITUTE(SUBSTITUTE(SUBSTITUTE(SUBSTITUTE(SUBSTITUTE(SUBSTITUTE(SUBSTITUTE(SUBSTITUTE(SUBSTITUTE(SUBSTITUTE(SUBSTITUTE(SUBSTITUTE(SUBSTITUTE(SUBSTITUTE(SUBSTITUTE(SUBSTITUTE(SUBSTITUTE(SUBSTITUTE(SUBSTITUTE(SUBSTITUTE(SUBSTITUTE(SUBSTITUTE(SUBSTITUTE(SUBSTITUTE(UPPER(_xlpm.a)," ",""),"CONTROL","CTRL"),"CTL","CTRL"),"ESCAPE","ESC"),"RETURN","ENTER"),"PAGEDOWN","PGDN"),"PGDOWN","PGDN"),"PAGEUP","PGUP"),"ARROWKEYS","ARROW"),"ARROWKEY","ARROW"),"ARROWS","ARROW"),"DOWNARROW","DOWN"),"UPARROW","UP"),"LEFTARROW","LEFT"),"RIGHTARROW","RIGHT"),"ARROWDOWN","DOWN"),"ARROWUP","UP"),"ARROWLEFT","LEFT"),"ARROWRIGHT","RIGHT"),"↓","DOWN"),"↑","UP"),"←","LEFT"),"→","RIGHT"),"SPACEBAR","SPACE"),"−","-"),"MINUS","-"),"PLUS","+")=Key!$E$8:$F$8),"✔ CLEAR","✘ TRY AGAIN"))),"✘ TRY AGAIN")} | F19: {=IF(E19="Show hint",Key!$B$8,"")} | G19: {=IF(LEFT(D19,1)="✔",IF(E19="Show hint",5,10),0)} -> 0
A20: W8 | B20: Which keys open the Insert Function dialog? (from F1-5 X-Ray) | D20: {=IFERROR(_xlfn.LET(_xlpm.a,'F3-1 Counters'!$C$20,IF(TRIM(_xlpm.a&"")="","",IF(OR(SUBSTITUTE(SUBSTITUTE(SUBSTITUTE(SUBSTITUTE(SUBSTITUTE(SUBSTITUTE(SUBSTITUTE(SUBSTITUTE(SUBSTITUTE(SUBSTITUTE(SUBSTITUTE(SUBSTITUTE(SUBSTITUTE(SUBSTITUTE(SUBSTITUTE(SUBSTITUTE(SUBSTITUTE(SUBSTITUTE(SUBSTITUTE(SUBSTITUTE(SUBSTITUTE(SUBSTITUTE(SUBSTITUTE(SUBSTITUTE(SUBSTITUTE(SUBSTITUTE(SUBSTITUTE(UPPER(_xlpm.a)," ",""),"CONTROL","CTRL"),"CTL","CTRL"),"ESCAPE","ESC"),"RETURN","ENTER"),"PAGEDOWN","PGDN"),"PGDOWN","PGDN"),"PAGEUP","PGUP"),"ARROWKEYS","ARROW"),"ARROWKEY","ARROW"),"ARROWS","ARROW"),"DOWNARROW","DOWN"),"UPARROW","UP"),"LEFTARROW","LEFT"),"RIGHTARROW","RIGHT"),"ARROWDOWN","DOWN"),"ARROWUP","UP"),"ARROWLEFT","LEFT"),"ARROWRIGHT","RIGHT"),"↓","DOWN"),"↑","UP"),"←","LEFT"),"→","RIGHT"),"SPACEBAR","SPACE"),"−","-"),"MINUS","-"),"PLUS","+")=Key!$E$9:$E$9),"✔ CLEAR","✘ TRY AGAIN"))),"✘ TRY AGAIN")} | F20: {=IF(E20="Show hint",Key!$B$9,"")} | G20: {=IF(LEFT(D20,1)="✔",IF(E20="Show hint",5,10),0)} -> 0
A21: W9 | B21: Which keys confirm an entry and move up one cell? (from S2-1 Quick Entry) | D21: {=IFERROR(_xlfn.LET(_xlpm.a,'F3-1 Counters'!$C$21,IF(TRIM(_xlpm.a&"")="","",IF(OR(SUBSTITUTE(SUBSTITUTE(SUBSTITUTE(SUBSTITUTE(SUBSTITUTE(SUBSTITUTE(SUBSTITUTE(SUBSTITUTE(SUBSTITUTE(SUBSTITUTE(SUBSTITUTE(SUBSTITUTE(SUBSTITUTE(SUBSTITUTE(SUBSTITUTE(SUBSTITUTE(SUBSTITUTE(SUBSTITUTE(SUBSTITUTE(SUBSTITUTE(SUBSTITUTE(SUBSTITUTE(SUBSTITUTE(SUBSTITUTE(SUBSTITUTE(SUBSTITUTE(SUBSTITUTE(UPPER(_xlpm.a)," ",""),"CONTROL","CTRL"),"CTL","CTRL"),"ESCAPE","ESC"),"RETURN","ENTER"),"PAGEDOWN","PGDN"),"PGDOWN","PGDN"),"PAGEUP","PGUP"),"ARROWKEYS","ARROW"),"ARROWKEY","ARROW"),"ARROWS","ARROW"),"DOWNARROW","DOWN"),"UPARROW","UP"),"LEFTARROW","LEFT"),"RIGHTARROW","RIGHT"),"ARROWDOWN","DOWN"),"ARROWUP","UP"),"ARROWLEFT","LEFT"),"ARROWRIGHT","RIGHT"),"↓","DOWN"),"↑","UP"),"←","LEFT"),"→","RIGHT"),"SPACEBAR","SPACE"),"−","-"),"MINUS","-"),"PLUS","+")=Key!$E$10:$E$10),"✔ CLEAR","✘ TRY AGAIN"))),"✘ TRY AGAIN")} | F21: {=IF(E21="Show hint",Key!$B$10,"")} | G21: {=IF(LEFT(D21,1)="✔",IF(E21="Show hint",5,10),0)} -> 0
A22: W10 | B22: Which key confirms an entry and moves one cell to the right? (from S2-1 Quick Entry) | D22: {=IFERROR(_xlfn.LET(_xlpm.a,'F3-1 Counters'!$C$22,IF(TRIM(_xlpm.a&"")="","",IF(OR(SUBSTITUTE(SUBSTITUTE(SUBSTITUTE(SUBSTITUTE(SUBSTITUTE(SUBSTITUTE(SUBSTITUTE(SUBSTITUTE(SUBSTITUTE(SUBSTITUTE(SUBSTITUTE(SUBSTITUTE(SUBSTITUTE(SUBSTITUTE(SUBSTITUTE(SUBSTITUTE(SUBSTITUTE(SUBSTITUTE(SUBSTITUTE(SUBSTITUTE(SUBSTITUTE(SUBSTITUTE(SUBSTITUTE(SUBSTITUTE(SUBSTITUTE(SUBSTITUTE(SUBSTITUTE(UPPER(_xlpm.a)," ",""),"CONTROL","CTRL"),"CTL","CTRL"),"ESCAPE","ESC"),"RETURN","ENTER"),"PAGEDOWN","PGDN"),"PGDOWN","PGDN"),"PAGEUP","PGUP"),"ARROWKEYS","ARROW"),"ARROWKEY","ARROW"),"ARROWS","ARROW"),"DOWNARROW","DOWN"),"UPARROW","UP"),"LEFTARROW","LEFT"),"RIGHTARROW","RIGHT"),"ARROWDOWN","DOWN"),"ARROWUP","UP"),"ARROWLEFT","LEFT"),"ARROWRIGHT","RIGHT"),"↓","DOWN"),"↑","UP"),"←","LEFT"),"→","RIGHT"),"SPACEBAR","SPACE"),"−","-"),"MINUS","-"),"PLUS","+")=Key!$E$11:$E$11),"✔ CLEAR","✘ TRY AGAIN"))),"✘ TRY AGAIN")} | F22: {=IF(E22="Show hint",Key!$B$11,"")} | G22: {=IF(LEFT(D22,1)="✔",IF(E22="Show hint",5,10),0)} -> 0
A24: TRAINING · recognize the move (pick from the list)
A25: # | B25: Mission | C25: Your answer | D25: Result | E25: Hint? | F25: Hint | G25: XP
A26: T1 | B26: Which function counts cells that meet one condition? | D26: {=IFERROR(IF('F3-1 Counters'!$C$26&""="","",IF('F3-1 Counters'!$C$26&""=Key!$C$12&"","✔ CLEAR","✘ TRY AGAIN")),"✘ TRY AGAIN")} | F26: {=IF(E26="Show hint",Key!$B$12,"")} | G26: {=IF(LEFT(D26,1)="✔",IF(E26="Show hint",5,10),0)} -> 0
A27: T2 | B27: Pick the COUNTIF criteria for "greater than 50", quotes included. | D27: {=IFERROR(IF('F3-1 Counters'!$C$27&""="","",IF('F3-1 Counters'!$C$27&""=Key!$C$13&"","✔ CLEAR","✘ TRY AGAIN")),"✘ TRY AGAIN")} | F27: {=IF(E27="Show hint",Key!$B$13,"")} | G27: {=IF(LEFT(D27,1)="✔",IF(E27="Show hint",5,10),0)} -> 0
A28: T3 | B28: Which move is this? * matches any text, ? one character: "G*" = starts with G. | D28: {=IFERROR(IF('F3-1 Counters'!$C$28&""="","",IF('F3-1 Counters'!$C$28&""=Key!$C$14&"","✔ CLEAR","✘ TRY AGAIN")),"✘ TRY AGAIN")} | F28: {=IF(E28="Show hint",Key!$B$14,"")} | G28: {=IF(LEFT(D28,1)="✔",IF(E28="Show hint",5,10),0)} -> 0
A30: CHALLENGES · recall it, then do it
B31: ▶ Open F3-1 Arena (or press Ctrl+PgDn)
A32: # | B32: Mission | C32: Your answer | D32: Result | E32: Hint? | F32: Hint | G32: XP
A33: C1 | B33: Which function counts cells that meet one condition? | D33: {=IFERROR(_xlfn.LET(_xlpm.a,'F3-1 Counters'!$C$33,IF(TRIM(_xlpm.a&"")="","",IF(OR(SUBSTITUTE(SUBSTITUTE(SUBSTITUTE(SUBSTITUTE(SUBSTITUTE(SUBSTITUTE(SUBSTITUTE(SUBSTITUTE(SUBSTITUTE(SUBSTITUTE(SUBSTITUTE(SUBSTITUTE(SUBSTITUTE(SUBSTITUTE(SUBSTITUTE(SUBSTITUTE(SUBSTITUTE(SUBSTITUTE(SUBSTITUTE(SUBSTITUTE(SUBSTITUTE(SUBSTITUTE(SUBSTITUTE(SUBSTITUTE(SUBSTITUTE(SUBSTITUTE(SUBSTITUTE(UPPER(_xlpm.a)," ",""),"CONTROL","CTRL"),"CTL","CTRL"),"ESCAPE","ESC"),"RETURN","ENTER"),"PAGEDOWN","PGDN"),"PGDOWN","PGDN"),"PAGEUP","PGUP"),"ARROWKEYS","ARROW"),"ARROWKEY","ARROW"),"ARROWS","ARROW"),"DOWNARROW","DOWN"),"UPARROW","UP"),"LEFTARROW","LEFT"),"RIGHTARROW","RIGHT"),"ARROWDOWN","DOWN"),"ARROWUP","UP"),"ARROWLEFT","LEFT"),"ARROWRIGHT","RIGHT"),"↓","DOWN"),"↑","UP"),"←","LEFT"),"→","RIGHT"),"SPACEBAR","SPACE"),"−","-"),"MINUS","-"),"PLUS","+")=Key!$E$15:$J$15),"✔ CLEAR","✘ TRY AGAIN"))),"✘ TRY AGAIN")} | F33: {=IF(E33="Show hint",Key!$B$15,"")} | G33: {=IF(LEFT(D33,1)="✔",IF(E33="Show hint",5,10),0)} -> 0
A34: C2 | B34: Type the COUNTIF criteria for "greater than 50", quotes included. | D34: {=IFERROR(_xlfn.LET(_xlpm.a,'F3-1 Counters'!$C$34,IF(TRIM(_xlpm.a&"")="","",IF(OR(SUBSTITUTE(SUBSTITUTE(SUBSTITUTE(SUBSTITUTE(SUBSTITUTE(SUBSTITUTE(SUBSTITUTE(SUBSTITUTE(SUBSTITUTE(SUBSTITUTE(SUBSTITUTE(SUBSTITUTE(SUBSTITUTE(SUBSTITUTE(SUBSTITUTE(SUBSTITUTE(SUBSTITUTE(SUBSTITUTE(SUBSTITUTE(SUBSTITUTE(SUBSTITUTE(SUBSTITUTE(SUBSTITUTE(SUBSTITUTE(SUBSTITUTE(SUBSTITUTE(SUBSTITUTE(UPPER(_xlpm.a)," ",""),"CONTROL","CTRL"),"CTL","CTRL"),"ESCAPE","ESC"),"RETURN","ENTER"),"PAGEDOWN","PGDN"),"PGDOWN","PGDN"),"PAGEUP","PGUP"),"ARROWKEYS","ARROW"),"ARROWKEY","ARROW"),"ARROWS","ARROW"),"DOWNARROW","DOWN"),"UPARROW","UP"),"LEFTARROW","LEFT"),"RIGHTARROW","RIGHT"),"ARROWDOWN","DOWN"),"ARROWUP","UP"),"ARROWLEFT","LEFT"),"ARROWRIGHT","RIGHT"),"↓","DOWN"),"↑","UP"),"←","LEFT"),"→","RIGHT"),"SPACEBAR","SPACE"),"−","-"),"MINUS","-"),"PLUS","+")=Key!$E$16:$E$16),"✔ CLEAR","✘ TRY AGAIN"))),"✘ TRY AGAIN")} | F34: {=IF(E34="Show hint",Key!$B$16,"")} | G34: {=IF(LEFT(D34,1)="✔",IF(E34="Show hint",5,10),0)} -> 0
A35: C3 | B35: Which wildcard matches any number of characters? | D35: {=IFERROR(_xlfn.LET(_xlpm.a,'F3-1 Counters'!$C$35,IF(TRIM(_xlpm.a&"")="","",IF(OR(SUBSTITUTE(SUBSTITUTE(SUBSTITUTE(SUBSTITUTE(SUBSTITUTE(SUBSTITUTE(SUBSTITUTE(SUBSTITUTE(SUBSTITUTE(SUBSTITUTE(SUBSTITUTE(SUBSTITUTE(SUBSTITUTE(SUBSTITUTE(SUBSTITUTE(SUBSTITUTE(SUBSTITUTE(SUBSTITUTE(SUBSTITUTE(SUBSTITUTE(SUBSTITUTE(SUBSTITUTE(SUBSTITUTE(SUBSTITUTE(SUBSTITUTE(SUBSTITUTE(SUBSTITUTE(UPPER(_xlpm.a)," ",""),"CONTROL","CTRL"),"CTL","CTRL"),"ESCAPE","ESC"),"RETURN","ENTER"),"PAGEDOWN","PGDN"),"PGDOWN","PGDN"),"PAGEUP","PGUP"),"ARROWKEYS","ARROW"),"ARROWKEY","ARROW"),"ARROWS","ARROW"),"DOWNARROW","DOWN"),"UPARROW","UP"),"LEFTARROW","LEFT"),"RIGHTARROW","RIGHT"),"ARROWDOWN","DOWN"),"ARROWUP","UP"),"ARROWLEFT","LEFT"),"ARROWRIGHT","RIGHT"),"↓","DOWN"),"↑","UP"),"←","LEFT"),"→","RIGHT"),"SPACEBAR","SPACE"),"−","-"),"MINUS","-"),"PLUS","+")=Key!$E$17:$F$17),"✔ CLEAR","✘ TRY AGAIN"))),"✘ TRY AGAIN")} | F35: {=IF(E35="Show hint",Key!$B$17,"")} | G35: {=IF(LEFT(D35,1)="✔",IF(E35="Show hint",5,10),0)} -> 0
A36: C4 | B36: In M6 count the East orders: =COUNTIF(D6:D25,"East"). | C36: ▶ ARENA C4 (cell M6) | D36: {=IF(ISBLANK('F3-1 Arena'!$M$6),"",IF(NOT(_xlfn.ISFORMULA('F3-1 Arena'!$M$6)),"✘ That's a typed value · enter a formula",IF(ISERROR('F3-1 Arena'!$M$6),"✘ Your formula returns "&IFERROR(CHOOSE(ERROR.TYPE('F3-1 Arena'!$M$6),"#NULL!","#DIV/0!","#VALUE!","#REF!","#NAME?","#NUM!","#N/A","#GETTING_DATA","#SPILL!","#CONNECT!","#BLOCKED!","#UNKNOWN!","#FIELD!","#CALC!"),"an error"),IF(NOT(AND(IFERROR(AND(ISNUMBER('F3-1 Arena'!$M$6),ABS('F3-1 Arena'!$M$6-Key!$C$18)<=1E-9*MAX(1,ABS(Key!$C$18))),FALSE))),"✘ TRY AGAIN",IF(AND(OR(ISNUMBER(FIND({"=","(",",","+","-","*","/","&"," ","<",">",":","@","^"}&"COUNTIF"&"(",UPPER(_xlfn.FORMULATEXT('F3-1 Arena'!$M$6)))))),"✔ CLEAR","✘ CLOSE · right value, but use COUNTIF")))))} | F36: {=IF(E36="Show hint",Key!$B$18,"")} | G36: {=IF(LEFT(D36,1)="✔",IF(E36="Show hint",5,10),0)} -> 0
A37: C5 | B37: In M7 count the orders with more than 50 units (G6:G25). | C37: ▶ ARENA C5 (cell M7) | D37: {=IF(ISBLANK('F3-1 Arena'!$M$7),"",IF(NOT(_xlfn.ISFORMULA('F3-1 Arena'!$M$7)),"✘ That's a typed value · enter a formula",IF(ISERROR('F3-1 Arena'!$M$7),"✘ Your formula returns "&IFERROR(CHOOSE(ERROR.TYPE('F3-1 Arena'!$M$7),"#NULL!","#DIV/0!","#VALUE!","#REF!","#NAME?","#NUM!","#N/A","#GETTING_DATA","#SPILL!","#CONNECT!","#BLOCKED!","#UNKNOWN!","#FIELD!","#CALC!"),"an error"),IF(NOT(AND(IFERROR(AND(ISNUMBER('F3-1 Arena'!$M$7),ABS('F3-1 Arena'!$M$7-Key!$C$19)<=1E-9*MAX(1,ABS(Key!$C$19))),FALSE))),"✘ TRY AGAIN",IF(AND(OR(ISNUMBER(FIND({"=","(",",","+","-","*","/","&"," ","<",">",":","@","^"}&"COUNTIF"&"(",UPPER(_xlfn.FORMULATEXT('F3-1 Arena'!$M$7)))))),"✔ CLEAR","✘ CLOSE · right value, but use COUNTIF")))))} | F37: {=IF(E37="Show hint",Key!$B$19,"")} | G37: {=IF(LEFT(D37,1)="✔",IF(E37="Show hint",5,10),0)} -> 0
A38: C6 | B38: In M8 count the products (F6:F25) whose name starts with G. | C38: ▶ ARENA C6 (cell M8) | D38: {=IF(ISBLANK('F3-1 Arena'!$M$8),"",IF(NOT(_xlfn.ISFORMULA('F3-1 Arena'!$M$8)),"✘ That's a typed value · enter a formula",IF(ISERROR('F3-1 Arena'!$M$8),"✘ Your formula returns "&IFERROR(CHOOSE(ERROR.TYPE('F3-1 Arena'!$M$8),"#NULL!","#DIV/0!","#VALUE!","#REF!","#NAME?","#NUM!","#N/A","#GETTING_DATA","#SPILL!","#CONNECT!","#BLOCKED!","#UNKNOWN!","#FIELD!","#CALC!"),"an error"),IF(NOT(AND(IFERROR(AND(ISNUMBER('F3-1 Arena'!$M$8),ABS('F3-1 Arena'!$M$8-Key!$C$20)<=1E-9*MAX(1,ABS(Key!$C$20))),FALSE))),"✘ TRY AGAIN",IF(AND(OR(ISNUMBER(FIND({"=","(",",","+","-","*","/","&"," ","<",">",":","@","^"}&"COUNTIF"&"(",UPPER(_xlfn.FORMULATEXT('F3-1 Arena'!$M$8)))))),IF(ISNUMBER(FIND("*",_xlfn.FORMULATEXT('F3-1 Arena'!$M$8))),"✔ CLEAR","✘ CLOSE · your formula needs *"),"✘ CLOSE · right value, but use COUNTIF")))))} | F38: {=IF(E38="Show hint",Key!$B$20,"")} | G38: {=IF(LEFT(D38,1)="✔",IF(E38="Show hint",5,10),0)} -> 0
A39: C7 | B39: In M9 count the orders NOT from East. | C39: ▶ ARENA C7 (cell M9) | D39: {=IF(ISBLANK('F3-1 Arena'!$M$9),"",IF(NOT(_xlfn.ISFORMULA('F3-1 Arena'!$M$9)),"✘ That's a typed value · enter a formula",IF(ISERROR('F3-1 Arena'!$M$9),"✘ Your formula returns "&IFERROR(CHOOSE(ERROR.TYPE('F3-1 Arena'!$M$9),"#NULL!","#DIV/0!","#VALUE!","#REF!","#NAME?","#NUM!","#N/A","#GETTING_DATA","#SPILL!","#CONNECT!","#BLOCKED!","#UNKNOWN!","#FIELD!","#CALC!"),"an error"),IF(NOT(AND(IFERROR(AND(ISNUMBER('F3-1 Arena'!$M$9),ABS('F3-1 Arena'!$M$9-Key!$C$21)<=1E-9*MAX(1,ABS(Key!$C$21))),FALSE))),"✘ TRY AGAIN",IF(AND(OR(ISNUMBER(FIND({"=","(",",","+","-","*","/","&"," ","<",">",":","@","^"}&"COUNTIF"&"(",UPPER(_xlfn.FORMULATEXT('F3-1 Arena'!$M$9)))))),IF(ISNUMBER(FIND("<>",_xlfn.FORMULATEXT('F3-1 Arena'!$M$9))),"✔ CLEAR","✘ CLOSE · your formula needs <>"),"✘ CLOSE · right value, but use COUNTIF")))))} | F39: {=IF(E39="Show hint",Key!$B$21,"")} | G39: {=IF(LEFT(D39,1)="✔",IF(E39="Show hint",5,10),0)} -> 0

Sheet F3-1 Arena
A1: ARENA ▸ F3-1 COUNTERS
A2: Practice area · everything here is editable. Missions and their checks are on the stage sheet.
A3: PASS CODE | B3: COUNTER | D3: ◀ Back to F3-1 Counters
B5: Order | C5: Date | D5: Region | E5: Rep | F5: Product | G5: Units | H5: Revenue | K5: Min units
B6: O-101 | C6: 46027 | D6: East | E6: Kim | F6: Widget | G6: 40 | H6: 1200 | K6: 40 | L6: East orders
B7: O-102 | C7: 46031 | D7: West | E7: Lee | F7: Gadget | G7: 15 | H7: 900 | L7: Orders over 50 units
B8: O-103 | C8: 46036 | D8: North | E8: Ava | F8: Widget | G8: 55 | H8: 1650 | K8: Start | L8: Products starting with G
B9: O-104 | C9: 46042 | D9: East | E9: Kim | F9: Gizmo | G9: 20 | H9: 1000 | K9: 46054 | L9: Orders not from East
B10: O-105 | C10: 46055 | D10: South | E10: Raj | F10: Gadget | G10: 60 | H10: 3600 | K10: End
B11: O-106 | C11: 46060 | D11: West | E11: Lee | F11: Widget | G11: 35 | H11: 1050 | K11: 46112
B12: O-107 | C12: 46064 | D12: East | E12: Ava | F12: Gadget | G12: 25 | H12: 1500
B13: O-108 | C13: 46072 | D13: North | E13: Raj | F13: Gizmo | G13: 45 | H13: 2250
B14: O-109 | C14: 46084 | D14: West | E14: Kim | F14: Gizmo | G14: 10 | H14: 500
B15: O-110 | C15: 46089 | D15: East | E15: Lee | F15: Widget | G15: 70 | H15: 2100
B16: O-111 | C16: 46096 | D16: South | E16: Ava | F16: Widget | G16: 30 | H16: 900
B17: O-112 | C17: 46103 | D17: North | E17: Kim | F17: Gadget | G17: 50 | H17: 3000
B18: O-113 | C18: 46113 | D18: East | E18: Raj | F18: Gizmo | G18: 65 | H18: 3250
B19: O-114 | C19: 46118 | D19: West | E19: Ava | F19: Gadget | G19: 20 | H19: 1200
B20: O-115 | C20: 46125 | D20: South | E20: Lee | F20: Gizmo | G20: 15 | H20: 750
B21: O-116 | C21: 46133 | D21: East | E21: Kim | F21: Widget | G21: 50 | H21: 1500
B22: O-117 | C22: 46146 | D22: North | E22: Lee | F22: Widget | G22: 25 | H22: 750
B23: O-118 | C23: 46154 | D23: West | E23: Raj | F23: Gadget | G23: 40 | H23: 2400
... B25: O-120 | C25: 46169 | D25: East | E25: Ava | F25: Gadget | G25: 55 | H25: 3300

Sheet F3-2 Money Bags
A1: STAGE F3-2 ▸ MONEY BAGS
A2: Goal: add and average with a condition
A3: {="SCORE "&TEXT(SUM($G$12:$G$35),"0000")&" / 0170"} -> SCORE 0000 / 0170 | C3: {=IF(SUM($G$12:$G$35)>=170,"★★★",IF(SUM($G$12:$G$35)>=170*0.8,"★★☆",IF(SUM($G$12:$G$35)>=170*0.5,"★☆☆","☆☆☆")))} -> ☆☆☆ | D3: {=REPT("█",ROUND(10*SUM($G$12:$G$35)/170,0))&REPT("░",10-ROUND(10*SUM($G$12:$G$35)/170,0))&" "&TEXT(SUM($G$12:$G$35)/170,"0%")} -> ░░░░░░░░░░ 0% | F3: {=IF(SUM($G$12:$G$35)>=170*0.5,"STAGE CLEAR! ▶ Next: F3-3 Multi-Filter","")}
A5: BRIEFING · new moves in this stage
A6: # | B6: What it does · Pro tip | C6: Keys / Syntax
A7: 1 | B7: Add the values whose row meets one condition. Tip: =SUMIF(D6:D25,"West",H6:H25): test range, criteria, then sum range. | C7: SUMIF
A8: 2 | B8: Average the values whose row meets one condition. Tip: Same argument order as SUMIF. | C8: AVERAGEIF
A10: WARM-UP · flashback to earlier stages
A11: # | B11: Mission | C11: Your answer | D11: Result | E11: Hint? | F11: Hint | G11: XP
A12: W1 | B12: Which function counts cells that meet one condition? (from F3-1 Counters) | D12: {=IFERROR(_xlfn.LET(_xlpm.a,'F3-2 Money Bags'!$C$12,IF(TRIM(_xlpm.a&"")="","",IF(OR(SUBSTITUTE(SUBSTITUTE(SUBSTITUTE(SUBSTITUTE(SUBSTITUTE(SUBSTITUTE(SUBSTITUTE(SUBSTITUTE(SUBSTITUTE(SUBSTITUTE(SUBSTITUTE(SUBSTITUTE(SUBSTITUTE(SUBSTITUTE(SUBSTITUTE(SUBSTITUTE(SUBSTITUTE(SUBSTITUTE(SUBSTITUTE(SUBSTITUTE(SUBSTITUTE(SUBSTITUTE(SUBSTITUTE(SUBSTITUTE(SUBSTITUTE(SUBSTITUTE(SUBSTITUTE(UPPER(_xlpm.a)," ",""),"CONTROL","CTRL"),"CTL","CTRL"),"ESCAPE","ESC"),"RETURN","ENTER"),"PAGEDOWN","PGDN"),"PGDOWN","PGDN"),"PAGEUP","PGUP"),"ARROWKEYS","ARROW"),"ARROWKEY","ARROW"),"ARROWS","ARROW"),"DOWNARROW","DOWN"),"UPARROW","UP"),"LEFTARROW","LEFT"),"RIGHTARROW","RIGHT"),"ARROWDOWN","DOWN"),"ARROWUP","UP"),"ARROWLEFT","LEFT"),"ARROWRIGHT","RIGHT"),"↓","DOWN"),"↑","UP"),"←","LEFT"),"→","RIGHT"),"SPACEBAR","SPACE"),"−","-"),"MINUS","-"),"PLUS","+")=Key!$E$22:$J$22),"✔ CLEAR","✘ TRY AGAIN"))),"✘ TRY AGAIN")} | F12: {=IF(E12="Show hint",Key!$B$22,"")} | G12: {=IF(LEFT(D12,1)="✔",IF(E12="Show hint",5,10),0)} -> 0
A13: W2 | B13: Type the COUNTIF criteria for "greater than 50", quotes included. (from F3-1 Counters) | D13: {=IFERROR(_xlfn.LET(_xlpm.a,'F3-2 Money Bags'!$C$13,IF(TRIM(_xlpm.a&"")="","",IF(OR(SUBSTITUTE(SUBSTITUTE(SUBSTITUTE(SUBSTITUTE(SUBSTITUTE(SUBSTITUTE(SUBSTITUTE(SUBSTITUTE(SUBSTITUTE(SUBSTITUTE(SUBSTITUTE(SUBSTITUTE(SUBSTITUTE(SUBSTITUTE(SUBSTITUTE(SUBSTITUTE(SUBSTITUTE(SUBSTITUTE(SUBSTITUTE(SUBSTITUTE(SUBSTITUTE(SUBSTITUTE(SUBSTITUTE(SUBSTITUTE(SUBSTITUTE(SUBSTITUTE(SUBSTITUTE(UPPER(_xlpm.a)," ",""),"CONTROL","CTRL"),"CTL","CTRL"),"ESCAPE","ESC"),"RETURN","ENTER"),"PAGEDOWN","PGDN"),"PGDOWN","PGDN"),"PAGEUP","PGUP"),"ARROWKEYS","ARROW"),"ARROWKEY","ARROW"),"ARROWS","ARROW"),"DOWNARROW","DOWN"),"UPARROW","UP"),"LEFTARROW","LEFT"),"RIGHTARROW","RIGHT"),"ARROWDOWN","DOWN"),"ARROWUP","UP"),"ARROWLEFT","LEFT"),"ARROWRIGHT","RIGHT"),"↓","DOWN"),"↑","UP"),"←","LEFT"),"→","RIGHT"),"SPACEBAR","SPACE"),"−","-"),"MINUS","-"),"PLUS","+")=Key!$E$23:$E$23),"✔ CLEAR","✘ TRY AGAIN"))),"✘ TRY AGAIN")} | F13: {=IF(E13="Show hint",Key!$B$23,"")} | G13: {=IF(LEFT(D13,1)="✔",IF(E13="Show hint",5,10),0)} -> 0
A14: W3 | B14: Which wildcard matches any number of characters? (from F3-1 Counters) | D14: {=IFERROR(_xlfn.LET(_xlpm.a,'F3-2 Money Bags'!$C$14,IF(TRIM(_xlpm.a&"")="","",IF(OR(SUBSTITUTE(SUBSTITUTE(SUBSTITUTE(SUBSTITUTE(SUBSTITUTE(SUBSTITUTE(SUBSTITUTE(SUBSTITUTE(SUBSTITUTE(SUBSTITUTE(SUBSTITUTE(SUBSTITUTE(SUBSTITUTE(SUBSTITUTE(SUBSTITUTE(SUBSTITUTE(SUBSTITUTE(SUBSTITUTE(SUBSTITUTE(SUBSTITUTE(SUBSTITUTE(SUBSTITUTE(SUBSTITUTE(SUBSTITUTE(SUBSTITUTE(SUBSTITUTE(SUBSTITUTE(UPPER(_xlpm.a)," ",""),"CONTROL","CTRL"),"CTL","CTRL"),"ESCAPE","ESC"),"RETURN","ENTER"),"PAGEDOWN","PGDN"),"PGDOWN","PGDN"),"PAGEUP","PGUP"),"ARROWKEYS","ARROW"),"ARROWKEY","ARROW"),"ARROWS","ARROW"),"DOWNARROW","DOWN"),"UPARROW","UP"),"LEFTARROW","LEFT"),"RIGHTARROW","RIGHT"),"ARROWDOWN","DOWN"),"ARROWUP","UP"),"ARROWLEFT","LEFT"),"ARROWRIGHT","RIGHT"),"↓","DOWN"),"↑","UP"),"←","LEFT"),"→","RIGHT"),"SPACEBAR","SPACE"),"−","-"),"MINUS","-"),"PLUS","+")=Key!$E$24:$F$24),"✔ CLEAR","✘ TRY AGAIN"))),"✘ TRY AGAIN")} | F14: {=IF(E14="Show hint",Key!$B$24,"")} | G14: {=IF(LEFT(D14,1)="✔",IF(E14="Show hint",5,10),0)} -> 0
A15: W4 | B15: Which keys toggle bold? (from S3-2 Text Style) | D15: {=IFERROR(_xlfn.LET(_xlpm.a,'F3-2 Money Bags'!$C$15,IF(TRIM(_xlpm.a&"")="","",IF(OR(SUBSTITUTE(SUBSTITUTE(SUBSTITUTE(SUBSTITUTE(SUBSTITUTE(SUBSTITUTE(SUBSTITUTE(SUBSTITUTE(SUBSTITUTE(SUBSTITUTE(SUBSTITUTE(SUBSTITUTE(SUBSTITUTE(SUBSTITUTE(SUBSTITUTE(SUBSTITUTE(SUBSTITUTE(SUBSTITUTE(SUBSTITUTE(SUBSTITUTE(SUBSTITUTE(SUBSTITUTE(SUBSTITUTE(SUBSTITUTE(SUBSTITUTE(SUBSTITUTE(SUBSTITUTE(UPPER(_xlpm.a)," ",""),"CONTROL","CTRL"),"CTL","CTRL"),"ESCAPE","ESC"),"RETURN","ENTER"),"PAGEDOWN","PGDN"),"PGDOWN","PGDN"),"PAGEUP","PGUP"),"ARROWKEYS","ARROW"),"ARROWKEY","ARROW"),"ARROWS","ARROW"),"DOWNARROW","DOWN"),"UPARROW","UP"),"LEFTARROW","LEFT"),"RIGHTARROW","RIGHT"),"ARROWDOWN","DOWN"),"ARROWUP","UP"),"ARROWLEFT","LEFT"),"ARROWRIGHT","RIGHT"),"↓","DOWN"),"↑","UP"),"←","LEFT"),"→","RIGHT"),"SPACEBAR","SPACE"),"−","-"),"MINUS","-"),"PLUS","+")=Key!$E$25:$F$25),"✔ CLEAR","✘ TRY AGAIN"))),"✘ TRY AGAIN")} | F15: {=IF(E15="Show hint",Key!$B$25,"")} | G15: {=IF(LEFT(D15,1)="✔",IF(E15="Show hint",5,10),0)} -> 0
A16: W5 | B16: Which keys toggle italic? (from S3-2 Text Style) | D16: {=IFERROR(_xlfn.LET(_xlpm.a,'F3-2 Money Bags'!$C$16,IF(TRIM(_xlpm.a&"")="","",IF(OR(SUBSTITUTE(SUBSTITUTE(SUBSTITUTE(SUBSTITUTE(SUBSTITUTE(SUBSTITUTE(SUBSTITUTE(SUBSTITUTE(SUBSTITUTE(SUBSTITUTE(SUBSTITUTE(SUBSTITUTE(SUBSTITUTE(SUBSTITUTE(SUBSTITUTE(SUBSTITUTE(SUBSTITUTE(SUBSTITUTE(SUBSTITUTE(SUBSTITUTE(SUBSTITUTE(SUBSTITUTE(SUBSTITUTE(SUBSTITUTE(SUBSTITUTE(SUBSTITUTE(SUBSTITUTE(UPPER(_xlpm.a)," ",""),"CONTROL","CTRL"),"CTL","CTRL"),"ESCAPE","ESC"),"RETURN","ENTER"),"PAGEDOWN","PGDN"),"PGDOWN","PGDN"),"PAGEUP","PGUP"),"ARROWKEYS","ARROW"),"ARROWKEY","ARROW"),"ARROWS","ARROW"),"DOWNARROW","DOWN"),"UPARROW","UP"),"LEFTARROW","LEFT"),"RIGHTARROW","RIGHT"),"ARROWDOWN","DOWN"),"ARROWUP","UP"),"ARROWLEFT","LEFT"),"ARROWRIGHT","RIGHT"),"↓","DOWN"),"↑","UP"),"←","LEFT"),"→","RIGHT"),"SPACEBAR","SPACE"),"−","-"),"MINUS","-"),"PLUS","+")=Key!$E$26:$F$26),"✔ CLEAR","✘ TRY AGAIN"))),"✘ TRY AGAIN")} | F16: {=IF(E16="Show hint",Key!$B$26,"")} | G16: {=IF(LEFT(D16,1)="✔",IF(E16="Show hint",5,10),0)} -> 0
A17: W6 | B17: Which keys toggle underline? (from S3-2 Text Style) | D17: {=IFERROR(_xlfn.LET(_xlpm.a,'F3-2 Money Bags'!$C$17,IF(TRIM(_xlpm.a&"")="","",IF(OR(SUBSTITUTE(SUBSTITUTE(SUBSTITUTE(SUBSTITUTE(SUBSTITUTE(SUBSTITUTE(SUBSTITUTE(SUBSTITUTE(SUBSTITUTE(SUBSTITUTE(SUBSTITUTE(SUBSTITUTE(SUBSTITUTE(SUBSTITUTE(SUBSTITUTE(SUBSTITUTE(SUBSTITUTE(SUBSTITUTE(SUBSTITUTE(SUBSTITUTE(SUBSTITUTE(SUBSTITUTE(SUBSTITUTE(SUBSTITUTE(SUBSTITUTE(SUBSTITUTE(SUBSTITUTE(UPPER(_xlpm.a)," ",""),"CONTROL","CTRL"),"CTL","CTRL"),"ESCAPE","ESC"),"RETURN","ENTER"),"PAGEDOWN","PGDN"),"PGDOWN","PGDN"),"PAGEUP","PGUP"),"ARROWKEYS","ARROW"),"ARROWKEY","ARROW"),"ARROWS","ARROW"),"DOWNARROW","DOWN"),"UPARROW","UP"),"LEFTARROW","LEFT"),"RIGHTARROW","RIGHT"),"ARROWDOWN","DOWN"),"ARROWUP","UP"),"ARROWLEFT","LEFT"),"ARROWRIGHT","RIGHT"),"↓","DOWN"),"↑","UP"),"←","LEFT"),"→","RIGHT"),"SPACEBAR","SPACE"),"−","-"),"MINUS","-"),"PLUS","+")=Key!$E$27:$F$27),"✔ CLEAR","✘ TRY AGAIN"))),"✘ TRY AGAIN")} | F17: {=IF(E17="Show hint",Key!$B$27,"")} | G17: {=IF(LEFT(D17,1)="✔",IF(E17="Show hint",5,10),0)} -> 0
A18: W7 | B18: Which keys toggle strikethrough? (from S3-2 Text Style) | D18: {=IFERROR(_xlfn.LET(_xlpm.a,'F3-2 Money Bags'!$C$18,IF(TRIM(_xlpm.a&"")="","",IF(OR(SUBSTITUTE(SUBSTITUTE(SUBSTITUTE(SUBSTITUTE(SUBSTITUTE(SUBSTITUTE(SUBSTITUTE(SUBSTITUTE(SUBSTITUTE(SUBSTITUTE(SUBSTITUTE(SUBSTITUTE(SUBSTITUTE(SUBSTITUTE(SUBSTITUTE(SUBSTITUTE(SUBSTITUTE(SUBSTITUTE(SUBSTITUTE(SUBSTITUTE(SUBSTITUTE(SUBSTITUTE(SUBSTITUTE(SUBSTITUTE(SUBSTITUTE(SUBSTITUTE(SUBSTITUTE(UPPER(_xlpm.a)," ",""),"CONTROL","CTRL"),"CTL","CTRL"),"ESCAPE","ESC"),"RETURN","ENTER"),"PAGEDOWN","PGDN"),"PGDOWN","PGDN"),"PAGEUP","PGUP"),"ARROWKEYS","ARROW"),"ARROWKEY","ARROW"),"ARROWS","ARROW"),"DOWNARROW","DOWN"),"UPARROW","UP"),"LEFTARROW","LEFT"),"RIGHTARROW","RIGHT"),"ARROWDOWN","DOWN"),"ARROWUP","UP"),"ARROWLEFT","LEFT"),"ARROWRIGHT","RIGHT"),"↓","DOWN"),"↑","UP"),"←","LEFT"),"→","RIGHT"),"SPACEBAR","SPACE"),"−","-"),"MINUS","-"),"PLUS","+")=Key!$E$28:$E$28),"✔ CLEAR","✘ TRY AGAIN"))),"✘ TRY AGAIN")} | F18: {=IF(E18="Show hint",Key!$B$28,"")} | G18: {=IF(LEFT(D18,1)="✔",IF(E18="Show hint",5,10),0)} -> 0
A19: W8 | B19: Which keys fill every selected cell with what you typed? (from S2-1 Quick Entry) | D19: {=IFERROR(_xlfn.LET(_xlpm.a,'F3-2 Money Bags'!$C$19,IF(TRIM(_xlpm.a&"")="","",IF(OR(SUBSTITUTE(SUBSTITUTE(SUBSTITUTE(SUBSTITUTE(SUBSTITUTE(SUBSTITUTE(SUBSTITUTE(SUBSTITUTE(SUBSTITUTE(SUBSTITUTE(SUBSTITUTE(SUBSTITUTE(SUBSTITUTE(SUBSTITUTE(SUBSTITUTE(SUBSTITUTE(SUBSTITUTE(SUBSTITUTE(SUBSTITUTE(SUBSTITUTE(SUBSTITUTE(SUBSTITUTE(SUBSTITUTE(SUBSTITUTE(SUBSTITUTE(SUBSTITUTE(SUBSTITUTE(UPPER(_xlpm.a)," ",""),"CONTROL","CTRL"),"CTL","CTRL"),"ESCAPE","ESC"),"RETURN","ENTER"),"PAGEDOWN","PGDN"),"PGDOWN","PGDN"),"PAGEUP","PGUP"),"ARROWKEYS","ARROW"),"ARROWKEY","ARROW"),"ARROWS","ARROW"),"DOWNARROW","DOWN"),"UPARROW","UP"),"LEFTARROW","LEFT"),"RIGHTARROW","RIGHT"),"ARROWDOWN","DOWN"),"ARROWUP","UP"),"ARROWLEFT","LEFT"),"ARROWRIGHT","RIGHT"),"↓","DOWN"),"↑","UP"),"←","LEFT"),"→","RIGHT"),"SPACEBAR","SPACE"),"−","-"),"MINUS","-"),"PLUS","+")=Key!$E$29:$E$29),"✔ CLEAR","✘ TRY AGAIN"))),"✘ TRY AGAIN")} | F19: {=IF(E19="Show hint",Key!$B$29,"")} | G19: {=IF(LEFT(D19,1)="✔",IF(E19="Show hint",5,10),0)} -> 0
A20: W9 | B20: Which keys start a new line inside the same cell? (from S2-1 Quick Entry) | D20: {=IFERROR(_xlfn.LET(_xlpm.a,'F3-2 Money Bags'!$C$20,IF(TRIM(_xlpm.a&"")="","",IF(OR(SUBSTITUTE(SUBSTITUTE(SUBSTITUTE(SUBSTITUTE(SUBSTITUTE(SUBSTITUTE(SUBSTITUTE(SUBSTITUTE(SUBSTITUTE(SUBSTITUTE(SUBSTITUTE(SUBSTITUTE(SUBSTITUTE(SUBSTITUTE(SUBSTITUTE(SUBSTITUTE(SUBSTITUTE(SUBSTITUTE(SUBSTITUTE(SUBSTITUTE(SUBSTITUTE(SUBSTITUTE(SUBSTITUTE(SUBSTITUTE(SUBSTITUTE(SUBSTITUTE(SUBSTITUTE(UPPER(_xlpm.a)," ",""),"CONTROL","CTRL"),"CTL","CTRL"),"ESCAPE","ESC"),"RETURN","ENTER"),"PAGEDOWN","PGDN"),"PGDOWN","PGDN"),"PAGEUP","PGUP"),"ARROWKEYS","ARROW"),"ARROWKEY","ARROW"),"ARROWS","ARROW"),"DOWNARROW","DOWN"),"UPARROW","UP"),"LEFTARROW","LEFT"),"RIGHTARROW","RIGHT"),"ARROWDOWN","DOWN"),"ARROWUP","UP"),"ARROWLEFT","LEFT"),"ARROWRIGHT","RIGHT"),"↓","DOWN"),"↑","UP"),"←","LEFT"),"→","RIGHT"),"SPACEBAR","SPACE"),"−","-"),"MINUS","-"),"PLUS","+")=Key!$E$30:$E$30),"✔ CLEAR","✘ TRY AGAIN"))),"✘ TRY AGAIN")} | F20: {=IF(E20="Show hint",Key!$B$30,"")} | G20: {=IF(LEFT(D20,1)="✔",IF(E20="Show hint",5,10),0)} -> 0
A21: W10 | B21: Which key cancels an entry and leaves the cell unchanged? (from S2-1 Quick Entry) | D21: {=IFERROR(_xlfn.LET(_xlpm.a,'F3-2 Money Bags'!$C$21,IF(TRIM(_xlpm.a&"")="","",IF(OR(SUBSTITUTE(SUBSTITUTE(SUBSTITUTE(SUBSTITUTE(SUBSTITUTE(SUBSTITUTE(SUBSTITUTE(SUBSTITUTE(SUBSTITUTE(SUBSTITUTE(SUBSTITUTE(SUBSTITUTE(SUBSTITUTE(SUBSTITUTE(SUBSTITUTE(SUBSTITUTE(SUBSTITUTE(SUBSTITUTE(SUBSTITUTE(SUBSTITUTE(SUBSTITUTE(SUBSTITUTE(SUBSTITUTE(SUBSTITUTE(SUBSTITUTE(SUBSTITUTE(SUBSTITUTE(UPPER(_xlpm.a)," ",""),"CONTROL","CTRL"),"CTL","CTRL"),"ESCAPE","ESC"),"RETURN","ENTER"),"PAGEDOWN","PGDN"),"PGDOWN","PGDN"),"PAGEUP","PGUP"),"ARROWKEYS","ARROW"),"ARROWKEY","ARROW"),"ARROWS","ARROW"),"DOWNARROW","DOWN"),"UPARROW","UP"),"LEFTARROW","LEFT"),"RIGHTARROW","RIGHT"),"ARROWDOWN","DOWN"),"ARROWUP","UP"),"ARROWLEFT","LEFT"),"ARROWRIGHT","RIGHT"),"↓","DOWN"),"↑","UP"),"←","LEFT"),"→","RIGHT"),"SPACEBAR","SPACE"),"−","-"),"MINUS","-"),"PLUS","+")=Key!$E$31:$E$31),"✔ CLEAR","✘ TRY AGAIN"))),"✘ TRY AGAIN")} | F21: {=IF(E21="Show hint",Key!$B$31,"")} | G21: {=IF(LEFT(D21,1)="✔",IF(E21="Show hint",5,10),0)} -> 0
A23: TRAINING · recognize the move (pick from the list)
A24: # | B24: Mission | C24: Your answer | D24: Result | E24: Hint? | F24: Hint | G24: XP
A25: T1 | B25: Which function adds values that meet one condition? | D25: {=IFERROR(IF('F3-2 Money Bags'!$C$25&""="","",IF('F3-2 Money Bags'!$C$25&""=Key!$C$32&"","✔ CLEAR","✘ TRY AGAIN")),"✘ TRY AGAIN")} | F25: {=IF(E25="Show hint",Key!$B$32,"")} | G25: {=IF(LEFT(D25,1)="✔",IF(E25="Show hint",5,10),0)} -> 0
A26: T2 | B26: Which function averages values that meet one condition? | D26: {=IFERROR(IF('F3-2 Money Bags'!$C$26&""="","",IF('F3-2 Money Bags'!$C$26&""=Key!$C$33&"","✔ CLEAR","✘ TRY AGAIN")),"✘ TRY AGAIN")} | F26: {=IF(E26="Show hint",Key!$B$33,"")} | G26: {=IF(LEFT(D26,1)="✔",IF(E26="Show hint",5,10),0)} -> 0
A28: CHALLENGES · recall it, then do it
B29: ▶ Open F3-2 Arena (or press Ctrl+PgDn)
A30: # | B30: Mission | C30: Your answer | D30: Result | E30: Hint? | F30: Hint | G30: XP
A31: C1 | B31: Which function adds values that meet one condition? | D31: {=IFERROR(_xlfn.LET(_xlpm.a,'F3-2 Money Bags'!$C$31,IF(TRIM(_xlpm.a&"")="","",IF(OR(SUBSTITUTE(SUBSTITUTE(SUBSTITUTE(SUBSTITUTE(SUBSTITUTE(SUBSTITUTE(SUBSTITUTE(SUBSTITUTE(SUBSTITUTE(SUBSTITUTE(SUBSTITUTE(SUBSTITUTE(SUBSTITUTE(SUBSTITUTE(SUBSTITUTE(SUBSTITUTE(SUBSTITUTE(SUBSTITUTE(SUBSTITUTE(SUBSTITUTE(SUBSTITUTE(SUBSTITUTE(SUBSTITUTE(SUBSTITUTE(SUBSTITUTE(SUBSTITUTE(SUBSTITUTE(UPPER(_xlpm.a)," ",""),"CONTROL","CTRL"),"CTL","CTRL"),"ESCAPE","ESC"),"RETURN","ENTER"),"PAGEDOWN","PGDN"),"PGDOWN","PGDN"),"PAGEUP","PGUP"),"ARROWKEYS","ARROW"),"ARROWKEY","ARROW"),"ARROWS","ARROW"),"DOWNARROW","DOWN"),"UPARROW","UP"),"LEFTARROW","LEFT"),"RIGHTARROW","RIGHT"),"ARROWDOWN","DOWN"),"ARROWUP","UP"),"ARROWLEFT","LEFT"),"ARROWRIGHT","RIGHT"),"↓","DOWN"),"↑","UP"),"←","LEFT"),"→","RIGHT"),"SPACEBAR","SPACE"),"−","-"),"MINUS","-"),"PLUS","+")=Key!$E$34:$J$34),"✔ CLEAR","✘ TRY AGAIN"))),"✘ TRY AGAIN")} | F31: {=IF(E31="Show hint",Key!$B$34,"")} | G31: {=IF(LEFT(D31,1)="✔",IF(E31="Show hint",5,10),0)} -> 0
A32: C2 | B32: Which function averages values that meet one condition? | D32: {=IFERROR(_xlfn.LET(_xlpm.a,'F3-2 Money Bags'!$C$32,IF(TRIM(_xlpm.a&"")="","",IF(OR(SUBSTITUTE(SUBSTITUTE(SUBSTITUTE(SUBSTITUTE(SUBSTITUTE(SUBSTITUTE(SUBSTITUTE(SUBSTITUTE(SUBSTITUTE(SUBSTITUTE(SUBSTITUTE(SUBSTITUTE(SUBSTITUTE(SUBSTITUTE(SUBSTITUTE(SUBSTITUTE(SUBSTITUTE(SUBSTITUTE(SUBSTITUTE(SUBSTITUTE(SUBSTITUTE(SUBSTITUTE(SUBSTITUTE(SUBSTITUTE(SUBSTITUTE(SUBSTITUTE(SUBSTITUTE(UPPER(_xlpm.a)," ",""),"CONTROL","CTRL"),"CTL","CTRL"),"ESCAPE","ESC"),"RETURN","ENTER"),"PAGEDOWN","PGDN"),"PGDOWN","PGDN"),"PAGEUP","PGUP"),"ARROWKEYS","ARROW"),"ARROWKEY","ARROW"),"ARROWS","ARROW"),"DOWNARROW","DOWN"),"UPARROW","UP"),"LEFTARROW","LEFT"),"RIGHTARROW","RIGHT"),"ARROWDOWN","DOWN"),"ARROWUP","UP"),"ARROWLEFT","LEFT"),"ARROWRIGHT","RIGHT"),"↓","DOWN"),"↑","UP"),"←","LEFT"),"→","RIGHT"),"SPACEBAR","SPACE"),"−","-"),"MINUS","-"),"PLUS","+")=Key!$E$35:$J$35),"✔ CLEAR","✘ TRY AGAIN"))),"✘ TRY AGAIN")} | F32: {=IF(E32="Show hint",Key!$B$35,"")} | G32: {=IF(LEFT(D32,1)="✔",IF(E32="Show hint",5,10),0)} -> 0
A33: C3 | B33: In M6 add up the Revenue (H) of the West orders: =SUMIF(D6:D25,"West",H6:H25). | C33: ▶ ARENA C3 (cell M6) | D33: {=IF(ISBLANK('F3-2 Arena'!$M$6),"",IF(NOT(_xlfn.ISFORMULA('F3-2 Arena'!$M$6)),"✘ That's a typed value · enter a formula",IF(ISERROR('F3-2 Arena'!$M$6),"✘ Your formula returns "&IFERROR(CHOOSE(ERROR.TYPE('F3-2 Arena'!$M$6),"#NULL!","#DIV/0!","#VALUE!","#REF!","#NAME?","#NUM!","#N/A","#GETTING_DATA","#SPILL!","#CONNECT!","#BLOCKED!","#UNKNOWN!","#FIELD!","#CALC!"),"an error"),IF(NOT(AND(IFERROR(AND(ISNUMBER('F3-2 Arena'!$M$6),ABS('F3-2 Arena'!$M$6-Key!$C$36)<=1E-9*MAX(1,ABS(Key!$C$36))),FALSE))),"✘ TRY AGAIN",IF(AND(OR(ISNUMBER(FIND({"=","(",",","+","-","*","/","&"," ","<",">",":","@","^"}&"SUMIF"&"(",UPPER(_xlfn.FORMULATEXT('F3-2 Arena'!$M$6)))))),"✔ CLEAR","✘ CLOSE · right value, but use SUMIF")))))} | F33: {=IF(E33="Show hint",Key!$B$36,"")} | G33: {=IF(LEFT(D33,1)="✔",IF(E33="Show hint",5,10),0)} -> 0
A34: C4 | B34: In M7 average the Units (G) of Kim's orders (Rep in column E). | C34: ▶ ARENA C4 (cell M7) | D34: {=IF(ISBLANK('F3-2 Arena'!$M$7),"",IF(NOT(_xlfn.ISFORMULA('F3-2 Arena'!$M$7)),"✘ That's a typed value · enter a formula",IF(ISERROR('F3-2 Arena'!$M$7),"✘ Your formula returns "&IFERROR(CHOOSE(ERROR.TYPE('F3-2 Arena'!$M$7),"#NULL!","#DIV/0!","#VALUE!","#REF!","#NAME?","#NUM!","#N/A","#GETTING_DATA","#SPILL!","#CONNECT!","#BLOCKED!","#UNKNOWN!","#FIELD!","#CALC!"),"an error"),IF(NOT(AND(IFERROR(AND(ISNUMBER('F3-2 Arena'!$M$7),ABS('F3-2 Arena'!$M$7-Key!$C$37)<=1E-9*MAX(1,ABS(Key!$C$37))),FALSE))),"✘ TRY AGAIN",IF(AND(OR(ISNUMBER(FIND({"=","(",",","+","-","*","/","&"," ","<",">",":","@","^"}&"AVERAGEIF"&"(",UPPER(_xlfn.FORMULATEXT('F3-2 Arena'!$M$7)))))),"✔ CLEAR","✘ CLOSE · right value, but use AVERAGEIF")))))} | F34: {=IF(E34="Show hint",Key!$B$37,"")} | G34: {=IF(LEFT(D34,1)="✔",IF(E34="Show hint",5,10),0)} -> 0
A35: C5 | B35: In M8 add up the Revenue of orders with 40 or more Units. | C35: ▶ ARENA C5 (cell M8) | D35: {=IF(ISBLANK('F3-2 Arena'!$M$8),"",IF(NOT(_xlfn.ISFORMULA('F3-2 Arena'!$M$8)),"✘ That's a typed value · enter a formula",IF(ISERROR('F3-2 Arena'!$M$8),"✘ Your formula returns "&IFERROR(CHOOSE(ERROR.TYPE('F3-2 Arena'!$M$8),"#NULL!","#DIV/0!","#VALUE!","#REF!","#NAME?","#NUM!","#N/A","#GETTING_DATA","#SPILL!","#CONNECT!","#BLOCKED!","#UNKNOWN!","#FIELD!","#CALC!"),"an error"),IF(NOT(AND(IFERROR(AND(ISNUMBER('F3-2 Arena'!$M$8),ABS('F3-2 Arena'!$M$8-Key!$C$38)<=1E-9*MAX(1,ABS(Key!$C$38))),FALSE))),"✘ TRY AGAIN",IF(AND(OR(ISNUMBER(FIND({"=","(",",","+","-","*","/","&"," ","<",">",":","@","^"}&"SUMIF"&"(",UPPER(_xlfn.FORMULATEXT('F3-2 Arena'!$M$8)))))),"✔ CLEAR","✘ CLOSE · right value, but use SUMIF")))))} | F35: {=IF(E35="Show hint",Key!$B$38,"")} | G35: {=IF(LEFT(D35,1)="✔",IF(E35="Show hint",5,10),0)} -> 0

Sheet F3-2 Arena
A1: ARENA ▸ F3-2 MONEY BAGS
A2: Practice area · everything here is editable. Missions and their checks are on the stage sheet.
A3: PASS CODE | B3: MONEYBAG | D3: ◀ Back to F3-2 Money Bags
B5: Order | C5: Date | D5: Region | E5: Rep | F5: Product | G5: Units | H5: Revenue | K5: Min units
B6: O-101 | C6: 46027 | D6: East | E6: Kim | F6: Widget | G6: 40 | H6: 1200 | K6: 40 | L6: West revenue
B7: O-102 | C7: 46031 | D7: West | E7: Lee | F7: Gadget | G7: 15 | H7: 900 | L7: Kim's average units
B8: O-103 | C8: 46036 | D8: North | E8: Ava | F8: Widget | G8: 55 | H8: 1650 | K8: Start | L8: Revenue of orders with 40+ units
B9: O-104 | C9: 46042 | D9: East | E9: Kim | F9: Gizmo | G9: 20 | H9: 1000 | K9: 46054
B10: O-105 | C10: 46055 | D10: South | E10: Raj | F10: Gadget | G10: 60 | H10: 3600 | K10: End
B11: O-106 | C11: 46060 | D11: West | E11: Lee | F11: Widget | G11: 35 | H11: 1050 | K11: 46112
B12: O-107 | C12: 46064 | D12: East | E12: Ava | F12: Gadget | G12: 25 | H12: 1500
B13: O-108 | C13: 46072 | D13: North | E13: Raj | F13: Gizmo | G13: 45 | H13: 2250
B14: O-109 | C14: 46084 | D14: West | E14: Kim | F14: Gizmo | G14: 10 | H14: 500
B15: O-110 | C15: 46089 | D15: East | E15: Lee | F15: Widget | G15: 70 | H15: 2100
B16: O-111 | C16: 46096 | D16: South | E16: Ava | F16: Widget | G16: 30 | H16: 900
B17: O-112 | C17: 46103 | D17: North | E17: Kim | F17: Gadget | G17: 50 | H17: 3000
B18: O-113 | C18: 46113 | D18: East | E18: Raj | F18: Gizmo | G18: 65 | H18: 3250
B19: O-114 | C19: 46118 | D19: West | E19: Ava | F19: Gadget | G19: 20 | H19: 1200
B20: O-115 | C20: 46125 | D20: South | E20: Lee | F20: Gizmo | G20: 15 | H20: 750
B21: O-116 | C21: 46133 | D21: East | E21: Kim | F21: Widget | G21: 50 | H21: 1500
B22: O-117 | C22: 46146 | D22: North | E22: Lee | F22: Widget | G22: 25 | H22: 750
B23: O-118 | C23: 46154 | D23: West | E23: Raj | F23: Gadget | G23: 40 | H23: 2400
... B25: O-120 | C25: 46169 | D25: East | E25: Ava | F25: Gadget | G25: 55 | H25: 3300

Sheet F3-3 Multi-Filter
A1: STAGE F3-3 ▸ MULTI-FILTER
A2: Goal: stack several conditions
A3: {="SCORE "&TEXT(SUM($G$13:$G$38),"0000")&" / 0190"} -> SCORE 0000 / 0190 | C3: {=IF(SUM($G$13:$G$38)>=190,"★★★",IF(SUM($G$13:$G$38)>=190*0.8,"★★☆",IF(SUM($G$13:$G$38)>=190*0.5,"★☆☆","☆☆☆")))} -> ☆☆☆ | D3: {=REPT("█",ROUND(10*SUM($G$13:$G$38)/190,0))&REPT("░",10-ROUND(10*SUM($G$13:$G$38)/190,0))&" "&TEXT(SUM($G$13:$G$38)/190,"0%")} -> ░░░░░░░░░░ 0% | F3: {=IF(SUM($G$13:$G$38)>=190*0.5,"STAGE CLEAR! ▶ Next: F3-4 Extremes","")}
A5: BRIEFING · new moves in this stage
A6: # | B6: What it does · Pro tip | C6: Keys / Syntax
A7: 1 | B7: Count rows that meet several conditions at once. Tip: Pairs of range + criteria; every pair must match. | C7: COUNTIFS
A8: 2 | B8: Add values whose rows meet several conditions. Tip: The sum range comes FIRST in SUMIFS (last in SUMIF). | C8: SUMIFS
A9: 3 | B9: Average values whose rows meet several conditions. Tip: Average range first, then range/criteria pairs. | C9: AVERAGEIFS
A11: WARM-UP · flashback to earlier stages
A12: # | B12: Mission | C12: Your answer | D12: Result | E12: Hint? | F12: Hint | G12: XP
A13: W1 | B13: Which function adds values that meet one condition? (from F3-2 Money Bags) | D13: {=IFERROR(_xlfn.LET(_xlpm.a,'F3-3 Multi-Filter'!$C$13,IF(TRIM(_xlpm.a&"")="","",IF(OR(SUBSTITUTE(SUBSTITUTE(SUBSTITUTE(SUBSTITUTE(SUBSTITUTE(SUBSTITUTE(SUBSTITUTE(SUBSTITUTE(SUBSTITUTE(SUBSTITUTE(SUBSTITUTE(SUBSTITUTE(SUBSTITUTE(SUBSTITUTE(SUBSTITUTE(SUBSTITUTE(SUBSTITUTE(SUBSTITUTE(SUBSTITUTE(SUBSTITUTE(SUBSTITUTE(SUBSTITUTE(SUBSTITUTE(SUBSTITUTE(SUBSTITUTE(SUBSTITUTE(SUBSTITUTE(UPPER(_xlpm.a)," ",""),"CONTROL","CTRL"),"CTL","CTRL"),"ESCAPE","ESC"),"RETURN","ENTER"),"PAGEDOWN","PGDN"),"PGDOWN","PGDN"),"PAGEUP","PGUP"),"ARROWKEYS","ARROW"),"ARROWKEY","ARROW"),"ARROWS","ARROW"),"DOWNARROW","DOWN"),"UPARROW","UP"),"LEFTARROW","LEFT"),"RIGHTARROW","RIGHT"),"ARROWDOWN","DOWN"),"ARROWUP","UP"),"ARROWLEFT","LEFT"),"ARROWRIGHT","RIGHT"),"↓","DOWN"),"↑","UP"),"←","LEFT"),"→","RIGHT"),"SPACEBAR","SPACE"),"−","-"),"MINUS","-"),"PLUS","+")=Key!$E$39:$J$39),"✔ CLEAR","✘ TRY AGAIN"))),"✘ TRY AGAIN")} | F13: {=IF(E13="Show hint",Key!$B$39,"")} | G13: {=IF(LEFT(D13,1)="✔",IF(E13="Show hint",5,10),0)} -> 0
A14: W2 | B14: Which function averages values that meet one condition? (from F3-2 Money Bags) | D14: {=IFERROR(_xlfn.LET(_xlpm.a,'F3-3 Multi-Filter'!$C$14,IF(TRIM(_xlpm.a&"")="","",IF(OR(SUBSTITUTE(SUBSTITUTE(SUBSTITUTE(SUBSTITUTE(SUBSTITUTE(SUBSTITUTE(SUBSTITUTE(SUBSTITUTE(SUBSTITUTE(SUBSTITUTE(SUBSTITUTE(SUBSTITUTE(SUBSTITUTE(SUBSTITUTE(SUBSTITUTE(SUBSTITUTE(SUBSTITUTE(SUBSTITUTE(SUBSTITUTE(SUBSTITUTE(SUBSTITUTE(SUBSTITUTE(SUBSTITUTE(SUBSTITUTE(SUBSTITUTE(SUBSTITUTE(SUBSTITUTE(UPPER(_xlpm.a)," ",""),"CONTROL","CTRL"),"CTL","CTRL"),"ESCAPE","ESC"),"RETURN","ENTER"),"PAGEDOWN","PGDN"),"PGDOWN","PGDN"),"PAGEUP","PGUP"),"ARROWKEYS","ARROW"),"ARROWKEY","ARROW"),"ARROWS","ARROW"),"DOWNARROW","DOWN"),"UPARROW","UP"),"LEFTARROW","LEFT"),"RIGHTARROW","RIGHT"),"ARROWDOWN","DOWN"),"ARROWUP","UP"),"ARROWLEFT","LEFT"),"ARROWRIGHT","RIGHT"),"↓","DOWN"),"↑","UP"),"←","LEFT"),"→","RIGHT"),"SPACEBAR","SPACE"),"−","-"),"MINUS","-"),"PLUS","+")=Key!$E$40:$J$40),"✔ CLEAR","✘ TRY AGAIN"))),"✘ TRY AGAIN")} | F14: {=IF(E14="Show hint",Key!$B$40,"")} | G14: {=IF(LEFT(D14,1)="✔",IF(E14="Show hint",5,10),0)} -> 0
A15: W3 | B15: Which keys open the Format Cells dialog? (from S3-3 Format Power) | D15: {=IFERROR(_xlfn.LET(_xlpm.a,'F3-3 Multi-Filter'!$C$15,IF(TRIM(_xlpm.a&"")="","",IF(OR(SUBSTITUTE(SUBSTITUTE(SUBSTITUTE(SUBSTITUTE(SUBSTITUTE(SUBSTITUTE(SUBSTITUTE(SUBSTITUTE(SUBSTITUTE(SUBSTITUTE(SUBSTITUTE(SUBSTITUTE(SUBSTITUTE(SUBSTITUTE(SUBSTITUTE(SUBSTITUTE(SUBSTITUTE(SUBSTITUTE(SUBSTITUTE(SUBSTITUTE(SUBSTITUTE(SUBSTITUTE(SUBSTITUTE(SUBSTITUTE(SUBSTITUTE(SUBSTITUTE(SUBSTITUTE(UPPER(_xlpm.a)," ",""),"CONTROL","CTRL"),"CTL","CTRL"),"ESCAPE","ESC"),"RETURN","ENTER"),"PAGEDOWN","PGDN"),"PGDOWN","PGDN"),"PAGEUP","PGUP"),"ARROWKEYS","ARROW"),"ARROWKEY","ARROW"),"ARROWS","ARROW"),"DOWNARROW","DOWN"),"UPARROW","UP"),"LEFTARROW","LEFT"),"RIGHTARROW","RIGHT"),"ARROWDOWN","DOWN"),"ARROWUP","UP"),"ARROWLEFT","LEFT"),"ARROWRIGHT","RIGHT"),"↓","DOWN"),"↑","UP"),"←","LEFT"),"→","RIGHT"),"SPACEBAR","SPACE"),"−","-"),"MINUS","-"),"PLUS","+")=Key!$E$41:$E$41),"✔ CLEAR","✘ TRY AGAIN"))),"✘ TRY AGAIN")} | F15: {=IF(E15="Show hint",Key!$B$41,"")} | G15: {=IF(LEFT(D15,1)="✔",IF(E15="Show hint",5,10),0)} -> 0
A16: W4 | B16: Which keys add an outline border? (from S3-3 Format Power) | D16: {=IFERROR(_xlfn.LET(_xlpm.a,'F3-3 Multi-Filter'!$C$16,IF(TRIM(_xlpm.a&"")="","",IF(OR(SUBSTITUTE(SUBSTITUTE(SUBSTITUTE(SUBSTITUTE(SUBSTITUTE(SUBSTITUTE(SUBSTITUTE(SUBSTITUTE(SUBSTITUTE(SUBSTITUTE(SUBSTITUTE(SUBSTITUTE(SUBSTITUTE(SUBSTITUTE(SUBSTITUTE(SUBSTITUTE(SUBSTITUTE(SUBSTITUTE(SUBSTITUTE(SUBSTITUTE(SUBSTITUTE(SUBSTITUTE(SUBSTITUTE(SUBSTITUTE(SUBSTITUTE(SUBSTITUTE(SUBSTITUTE(UPPER(_xlpm.a)," ",""),"CONTROL","CTRL"),"CTL","CTRL"),"ESCAPE","ESC"),"RETURN","ENTER"),"PAGEDOWN","PGDN"),"PGDOWN","PGDN"),"PAGEUP","PGUP"),"ARROWKEYS","ARROW"),"ARROWKEY","ARROW"),"ARROWS","ARROW"),"DOWNARROW","DOWN"),"UPARROW","UP"),"LEFTARROW","LEFT"),"RIGHTARROW","RIGHT"),"ARROWDOWN","DOWN"),"ARROWUP","UP"),"ARROWLEFT","LEFT"),"ARROWRIGHT","RIGHT"),"↓","DOWN"),"↑","UP"),"←","LEFT"),"→","RIGHT"),"SPACEBAR","SPACE"),"−","-"),"MINUS","-"),"PLUS","+")=Key!$E$42:$H$42),"✔ CLEAR","✘ TRY AGAIN"))),"✘ TRY AGAIN")} | F16: {=IF(E16="Show hint",Key!$B$42,"")} | G16: {=IF(LEFT(D16,1)="✔",IF(E16="Show hint",5,10),0)} -> 0
A17: W5 | B17: Which keys remove the outline border? (from S3-3 Format Power) | D17: {=IFERROR(_xlfn.LET(_xlpm.a,'F3-3 Multi-Filter'!$C$17,IF(TRIM(_xlpm.a&"")="","",IF(OR(SUBSTITUTE(SUBSTITUTE(SUBSTITUTE(SUBSTITUTE(SUBSTITUTE(SUBSTITUTE(SUBSTITUTE(SUBSTITUTE(SUBSTITUTE(SUBSTITUTE(SUBSTITUTE(SUBSTITUTE(SUBSTITUTE(SUBSTITUTE(SUBSTITUTE(SUBSTITUTE(SUBSTITUTE(SUBSTITUTE(SUBSTITUTE(SUBSTITUTE(SUBSTITUTE(SUBSTITUTE(SUBSTITUTE(SUBSTITUTE(SUBSTITUTE(SUBSTITUTE(SUBSTITUTE(UPPER(_xlpm.a)," ",""),"CONTROL","CTRL"),"CTL","CTRL"),"ESCAPE","ESC"),"RETURN","ENTER"),"PAGEDOWN","PGDN"),"PGDOWN","PGDN"),"PAGEUP","PGUP"),"ARROWKEYS","ARROW"),"ARROWKEY","ARROW"),"ARROWS","ARROW"),"DOWNARROW","DOWN"),"UPARROW","UP"),"LEFTARROW","LEFT"),"RIGHTARROW","RIGHT"),"ARROWDOWN","DOWN"),"ARROWUP","UP"),"ARROWLEFT","LEFT"),"ARROWRIGHT","RIGHT"),"↓","DOWN"),"↑","UP"),"←","LEFT"),"→","RIGHT"),"SPACEBAR","SPACE"),"−","-"),"MINUS","-"),"PLUS","+")=Key!$E$43:$H$43),"✔ CLEAR","✘ TRY AGAIN"))),"✘ TRY AGAIN")} | F17: {=IF(E17="Show hint",Key!$B$43,"")} | G17: {=IF(LEFT(D17,1)="✔",IF(E17="Show hint",5,10),0)} -> 0
A18: W6 | B18: Which key shows the ribbon KeyTips? (from S3-3 Format Power) | D18: {=IFERROR(_xlfn.LET(_xlpm.a,'F3-3 Multi-Filter'!$C$18,IF(TRIM(_xlpm.a&"")="","",IF(OR(SUBSTITUTE(SUBSTITUTE(SUBSTITUTE(SUBSTITUTE(SUBSTITUTE(SUBSTITUTE(SUBSTITUTE(SUBSTITUTE(SUBSTITUTE(SUBSTITUTE(SUBSTITUTE(SUBSTITUTE(SUBSTITUTE(SUBSTITUTE(SUBSTITUTE(SUBSTITUTE(SUBSTITUTE(SUBSTITUTE(SUBSTITUTE(SUBSTITUTE(SUBSTITUTE(SUBSTITUTE(SUBSTITUTE(SUBSTITUTE(SUBSTITUTE(SUBSTITUTE(SUBSTITUTE(UPPER(_xlpm.a)," ",""),"CONTROL","CTRL"),"CTL","CTRL"),"ESCAPE","ESC"),"RETURN","ENTER"),"PAGEDOWN","PGDN"),"PGDOWN","PGDN"),"PAGEUP","PGUP"),"ARROWKEYS","ARROW"),"ARROWKEY","ARROW"),"ARROWS","ARROW"),"DOWNARROW","DOWN"),"UPARROW","UP"),"LEFTARROW","LEFT"),"RIGHTARROW","RIGHT"),"ARROWDOWN","DOWN"),"ARROWUP","UP"),"ARROWLEFT","LEFT"),"ARROWRIGHT","RIGHT"),"↓","DOWN"),"↑","UP"),"←","LEFT"),"→","RIGHT"),"SPACEBAR","SPACE"),"−","-"),"MINUS","-"),"PLUS","+")=Key!$E$44:$F$44),"✔ CLEAR","✘ TRY AGAIN"))),"✘ TRY AGAIN")} | F18: {=IF(E18="Show hint",Key!$B$44,"")} | G18: {=IF(LEFT(D18,1)="✔",IF(E18="Show hint",5,10),0)} -> 0
A19: W7 | B19: Which KeyTips center the selected cells? (from S3-3 Format Power) | D19: {=IFERROR(_xlfn.LET(_xlpm.a,'F3-3 Multi-Filter'!$C$19,IF(TRIM(_xlpm.a&"")="","",IF(OR(SUBSTITUTE(SUBSTITUTE(SUBSTITUTE(SUBSTITUTE(SUBSTITUTE(SUBSTITUTE(SUBSTITUTE(SUBSTITUTE(SUBSTITUTE(SUBSTITUTE(SUBSTITUTE(SUBSTITUTE(SUBSTITUTE(SUBSTITUTE(SUBSTITUTE(SUBSTITUTE(SUBSTITUTE(SUBSTITUTE(SUBSTITUTE(SUBSTITUTE(SUBSTITUTE(SUBSTITUTE(SUBSTITUTE(SUBSTITUTE(SUBSTITUTE(SUBSTITUTE(SUBSTITUTE(UPPER(_xlpm.a)," ",""),"CONTROL","CTRL"),"CTL","CTRL"),"ESCAPE","ESC"),"RETURN","ENTER"),"PAGEDOWN","PGDN"),"PGDOWN","PGDN"),"PAGEUP","PGUP"),"ARROWKEYS","ARROW"),"ARROWKEY","ARROW"),"ARROWS","ARROW"),"DOWNARROW","DOWN"),"UPARROW","UP"),"LEFTARROW","LEFT"),"RIGHTARROW","RIGHT"),"ARROWDOWN","DOWN"),"ARROWUP","UP"),"ARROWLEFT","LEFT"),"ARROWRIGHT","RIGHT"),"↓","DOWN"),"↑","UP"),"←","LEFT"),"→","RIGHT"),"SPACEBAR","SPACE"),"−","-"),"MINUS","-"),"PLUS","+")=Key!$E$45:$T$45),"✔ CLEAR","✘ TRY AGAIN"))),"✘ TRY AGAIN")} | F19: {=IF(E19="Show hint",Key!$B$45,"")} | G19: {=IF(LEFT(D19,1)="✔",IF(E19="Show hint",5,10),0)} -> 0
A20: W8 | B20: Which KeyTips open the Fill Color menu? (from S3-3 Format Power) | D20: {=IFERROR(_xlfn.LET(_xlpm.a,'F3-3 Multi-Filter'!$C$20,IF(TRIM(_xlpm.a&"")="","",IF(OR(SUBSTITUTE(SUBSTITUTE(SUBSTITUTE(SUBSTITUTE(SUBSTITUTE(SUBSTITUTE(SUBSTITUTE(SUBSTITUTE(SUBSTITUTE(SUBSTITUTE(SUBSTITUTE(SUBSTITUTE(SUBSTITUTE(SUBSTITUTE(SUBSTITUTE(SUBSTITUTE(SUBSTITUTE(SUBSTITUTE(SUBSTITUTE(SUBSTITUTE(SUBSTITUTE(SUBSTITUTE(SUBSTITUTE(SUBSTITUTE(SUBSTITUTE(SUBSTITUTE(SUBSTITUTE(UPPER(_xlpm.a)," ",""),"CONTROL","CTRL"),"CTL","CTRL"),"ESCAPE","ESC"),"RETURN","ENTER"),"PAGEDOWN","PGDN"),"PGDOWN","PGDN"),"PAGEUP","PGUP"),"ARROWKEYS","ARROW"),"ARROWKEY","ARROW"),"ARROWS","ARROW"),"DOWNARROW","DOWN"),"UPARROW","UP"),"LEFTARROW","LEFT"),"RIGHTARROW","RIGHT"),"ARROWDOWN","DOWN"),"ARROWUP","UP"),"ARROWLEFT","LEFT"),"ARROWRIGHT","RIGHT"),"↓","DOWN"),"↑","UP"),"←","LEFT"),"→","RIGHT"),"SPACEBAR","SPACE"),"−","-"),"MINUS","-"),"PLUS","+")=Key!$E$46:$T$46),"✔ CLEAR","✘ TRY AGAIN"))),"✘ TRY AGAIN")} | F20: {=IF(E20="Show hint",Key!$B$46,"")} | G20: {=IF(LEFT(D20,1)="✔",IF(E20="Show hint",5,10),0)} -> 0
A21: W9 | B21: Which key repeats your last action? (from S3-3 Format Power) | D21: {=IFERROR(_xlfn.LET(_xlpm.a,'F3-3 Multi-Filter'!$C$21,IF(TRIM(_xlpm.a&"")="","",IF(OR(SUBSTITUTE(SUBSTITUTE(SUBSTITUTE(SUBSTITUTE(SUBSTITUTE(SUBSTITUTE(SUBSTITUTE(SUBSTITUTE(SUBSTITUTE(SUBSTITUTE(SUBSTITUTE(SUBSTITUTE(SUBSTITUTE(SUBSTITUTE(SUBSTITUTE(SUBSTITUTE(SUBSTITUTE(SUBSTITUTE(SUBSTITUTE(SUBSTITUTE(SUBSTITUTE(SUBSTITUTE(SUBSTITUTE(SUBSTITUTE(SUBSTITUTE(SUBSTITUTE(SUBSTITUTE(UPPER(_xlpm.a)," ",""),"CONTROL","CTRL"),"CTL","CTRL"),"ESCAPE","ESC"),"RETURN","ENTER"),"PAGEDOWN","PGDN"),"PGDOWN","PGDN"),"PAGEUP","PGUP"),"ARROWKEYS","ARROW"),"ARROWKEY","ARROW"),"ARROWS","ARROW"),"DOWNARROW","DOWN"),"UPARROW","UP"),"LEFTARROW","LEFT"),"RIGHTARROW","RIGHT"),"ARROWDOWN","DOWN"),"ARROWUP","UP"),"ARROWLEFT","LEFT"),"ARROWRIGHT","RIGHT"),"↓","DOWN"),"↑","UP"),"←","LEFT"),"→","RIGHT"),"SPACEBAR","SPACE"),"−","-"),"MINUS","-"),"PLUS","+")=Key!$E$47:$F$47),"✔ CLEAR","✘ TRY AGAIN"))),"✘ TRY AGAIN")} | F21: {=IF(E21="Show hint",Key!$B$47,"")} | G21: {=IF(LEFT(D21,1)="✔",IF(E21="Show hint",5,10),0)} -> 0
A22: W10 | B22: Which keys copy the selection? (from S2-2 Clone Machine) | D22: {=IFERROR(_xlfn.LET(_xlpm.a,'F3-3 Multi-Filter'!$C$22,IF(TRIM(_xlpm.a&"")="","",IF(OR(SUBSTITUTE(SUBSTITUTE(SUBSTITUTE(SUBSTITUTE(SUBSTITUTE(SUBSTITUTE(SUBSTITUTE(SUBSTITUTE(SUBSTITUTE(SUBSTITUTE(SUBSTITUTE(SUBSTITUTE(SUBSTITUTE(SUBSTITUTE(SUBSTITUTE(SUBSTITUTE(SUBSTITUTE(SUBSTITUTE(SUBSTITUTE(SUBSTITUTE(SUBSTITUTE(SUBSTITUTE(SUBSTITUTE(SUBSTITUTE(SUBSTITUTE(SUBSTITUTE(SUBSTITUTE(UPPER(_xlpm.a)," ",""),"CONTROL","CTRL"),"CTL","CTRL"),"ESCAPE","ESC"),"RETURN","ENTER"),"PAGEDOWN","PGDN"),"PGDOWN","PGDN"),"PAGEUP","PGUP"),"ARROWKEYS","ARROW"),"ARROWKEY","ARROW"),"ARROWS","ARROW"),"DOWNARROW","DOWN"),"UPARROW","UP"),"LEFTARROW","LEFT"),"RIGHTARROW","RIGHT"),"ARROWDOWN","DOWN"),"ARROWUP","UP"),"ARROWLEFT","LEFT"),"ARROWRIGHT","RIGHT"),"↓","DOWN"),"↑","UP"),"←","LEFT"),"→","RIGHT"),"SPACEBAR","SPACE"),"−","-"),"MINUS","-"),"PLUS","+")=Key!$E$48:$E$48),"✔ CLEAR","✘ TRY AGAIN"))),"✘ TRY AGAIN")} | F22: {=IF(E22="Show hint",Key!$B$48,"")} | G22: {=IF(LEFT(D22,1)="✔",IF(E22="Show hint",5,10),0)} -> 0
A24: TRAINING · recognize the move (pick from the list)
A25: # | B25: Mission | C25: Your answer | D25: Result | E25: Hint? | F25: Hint | G25: XP
A26: T1 | B26: Which function counts rows that meet several conditions? | D26: {=IFERROR(IF('F3-3 Multi-Filter'!$C$26&""="","",IF('F3-3 Multi-Filter'!$C$26&""=Key!$C$49&"","✔ CLEAR","✘ TRY AGAIN")),"✘ TRY AGAIN")} | F26: {=IF(E26="Show hint",Key!$B$49,"")} | G26: {=IF(LEFT(D26,1)="✔",IF(E26="Show hint",5,10),0)} -> 0
A27: T2 | B27: Which function adds values that meet several conditions? | D27: {=IFERROR(IF('F3-3 Multi-Filter'!$C$27&""="","",IF('F3-3 Multi-Filter'!$C$27&""=Key!$C$50&"","✔ CLEAR","✘ TRY AGAIN")),"✘ TRY AGAIN")} | F27: {=IF(E27="Show hint",Key!$B$50,"")} | G27: {=IF(LEFT(D27,1)="✔",IF(E27="Show hint",5,10),0)} -> 0
A28: T3 | B28: Which function averages values that meet several conditions? | D28: {=IFERROR(IF('F3-3 Multi-Filter'!$C$28&""="","",IF('F3-3 Multi-Filter'!$C$28&""=Key!$C$51&"","✔ CLEAR","✘ TRY AGAIN")),"✘ TRY AGAIN")} | F28: {=IF(E28="Show hint",Key!$B$51,"")} | G28: {=IF(LEFT(D28,1)="✔",IF(E28="Show hint",5,10),0)} -> 0
A30: CHALLENGES · recall it, then do it
B31: ▶ Open F3-3 Arena (or press Ctrl+PgDn)
A32: # | B32: Mission | C32: Your answer | D32: Result | E32: Hint? | F32: Hint | G32: XP
