Workbook

Sheet Start
A1: SHORTCUTS 4 ▸ ORGANIZE & ANALYZE
A2: Reshape sheets, find anything, filter and sort from the keyboard.
A4: HOW TO PLAY
A5: 1 · Each stage: read the BRIEFING, then answer WARM-UP, TRAINING and CHALLENGES.
A6: 2 · Yellow cells are yours: type, pick from a list (Alt+↓), or follow a ▶ ARENA link and do the move there.
A7: 3 · ✔ CLEAR = right · ✘ = try again · · not yet = drill not done. Stuck? Pick 'Show hint' (5 XP instead of 10).
A8: 4 · Formatting or hiding drills: press F9 to refresh the check. Tab jumps between yellow cells.
A9: Needs Windows with Microsoft Excel 365 or 2021+ (English). In Protected View, click Enable Editing.
A11: STAGE SELECT
A12: Stage | B12: Name | C12: Score | D12: Stars | E12: Status | F12: Go
A13: S4-1 | B13: Construction Crew | C13: {=SUM('S4-1 Construction Crew'!$G$14:$G$42)&" / 220"} -> 0 / 220 | D13: {=IF(SUM('S4-1 Construction Crew'!$G$14:$G$42)>=220,"★★★",IF(SUM('S4-1 Construction Crew'!$G$14:$G$42)>=220*0.8,"★★☆",IF(SUM('S4-1 Construction Crew'!$G$14:$G$42)>=220*0.5,"★☆☆","☆☆☆")))} -> ☆☆☆ | E13: {=IF(SUM('S4-1 Construction Crew'!$G$14:$G$42)>=220,"PERFECT",IF(SUM('S4-1 Construction Crew'!$G$14:$G$42)>=220*0.5,"CLEARED",IF(SUM('S4-1 Construction Crew'!$G$14:$G$42)>0,"IN PROGRESS","NEW")))} -> NEW | F13: Go to S4-1 Construction Crew
A14: S4-2 | B14: Sheet Master | C14: {=SUM('S4-2 Sheet Master'!$G$18:$G$53)&" / 290"} -> 0 / 290 | D14: {=IF(SUM('S4-2 Sheet Master'!$G$18:$G$53)>=290,"★★★",IF(SUM('S4-2 Sheet Master'!$G$18:$G$53)>=290*0.8,"★★☆",IF(SUM('S4-2 Sheet Master'!$G$18:$G$53)>=290*0.5,"★☆☆","☆☆☆")))} -> ☆☆☆ | E14: {=IF(SUM('S4-2 Sheet Master'!$G$18:$G$53)>=290,"PERFECT",IF(SUM('S4-2 Sheet Master'!$G$18:$G$53)>=290*0.5,"CLEARED",IF(SUM('S4-2 Sheet Master'!$G$18:$G$53)>0,"IN PROGRESS","NEW")))} -> NEW | F14: Go to S4-2 Sheet Master
A15: S4-3 | B15: Detective | C15: {=SUM('S4-3 Detective'!$G$12:$G$35)&" / 170"} -> 0 / 170 | D15: {=IF(SUM('S4-3 Detective'!$G$12:$G$35)>=170,"★★★",IF(SUM('S4-3 Detective'!$G$12:$G$35)>=170*0.8,"★★☆",IF(SUM('S4-3 Detective'!$G$12:$G$35)>=170*0.5,"★☆☆","☆☆☆")))} -> ☆☆☆ | E15: {=IF(SUM('S4-3 Detective'!$G$12:$G$35)>=170,"PERFECT",IF(SUM('S4-3 Detective'!$G$12:$G$35)>=170*0.5,"CLEARED",IF(SUM('S4-3 Detective'!$G$12:$G$35)>0,"IN PROGRESS","NEW")))} -> NEW | F15: Go to S4-3 Detective
A16: S4-4 | B16: Data Wrangler | C16: {=SUM('S4-4 Data Wrangler'!$G$16:$G$47)&" / 250"} -> 0 / 250 | D16: {=IF(SUM('S4-4 Data Wrangler'!$G$16:$G$47)>=250,"★★★",IF(SUM('S4-4 Data Wrangler'!$G$16:$G$47)>=250*0.8,"★★☆",IF(SUM('S4-4 Data Wrangler'!$G$16:$G$47)>=250*0.5,"★☆☆","☆☆☆")))} -> ☆☆☆ | E16: {=IF(SUM('S4-4 Data Wrangler'!$G$16:$G$47)>=250,"PERFECT",IF(SUM('S4-4 Data Wrangler'!$G$16:$G$47)>=250*0.5,"CLEARED",IF(SUM('S4-4 Data Wrangler'!$G$16:$G$47)>0,"IN PROGRESS","NEW")))} -> NEW | F16: Go to S4-4 Data Wrangler
A17: BOSS | B17: Boss | C17: {=SUM(Boss!$G$14:$G$33)&" / 160"} -> 0 / 160 | D17: {=IF(SUM(Boss!$G$14:$G$33)>=160,"★★★",IF(SUM(Boss!$G$14:$G$33)>=160*0.8,"★★☆",IF(SUM(Boss!$G$14:$G$33)>=160*0.5,"★☆☆","☆☆☆")))} -> ☆☆☆ | E17: {=IF(Boss!$C$10="OPEN",IF(SUM(Boss!$G$14:$G$33)>=160*0.5,"DEFEATED","OPEN"),"LOCKED")} -> LOCKED | F17: Go to the Boss
A19: TOTAL SCORE | B19: {=(SUM('S4-1 Construction Crew'!$G$14:$G$42)+SUM('S4-2 Sheet Master'!$G$18:$G$53)+SUM('S4-3 Detective'!$G$12:$G$35)+SUM('S4-4 Data Wrangler'!$G$16:$G$47)+SUM(Boss!$G$14:$G$33))&" / 1090"} -> 0 / 1090
A20: RANK | B20: {=_xlfn.LET(_xlpm.p,(SUM('S4-1 Construction Crew'!$G$14:$G$42)+SUM('S4-2 Sheet Master'!$G$18:$G$53)+SUM('S4-3 Detective'!$G$12:$G$35)+SUM('S4-4 Data Wrangler'!$G$16:$G$47)+SUM(Boss!$G$14:$G$33))/1090,IF(AND(_xlpm.p>=1,ISNUMBER(Boss!$C$8),Boss!$C$8<=12),"S",IF(_xlpm.p>=0.9,"A",IF(_xlpm.p>=0.75,"B",IF(_xlpm.p>=0.5,"C","D")))))} -> D | C20: S = 100% and under par · A ≥ 90% · B ≥ 75% · C ≥ 50%
A21: BEST TIME | B21: {=IF(ISNUMBER(Boss!$C$8),Boss!$C$8&" min (par 12)","—")} -> —
A22: NEXT UP | B22: {=IFERROR(INDEX($A$13:$A$16,MATCH("☆☆☆",$D$13:$D$16,0))&" "&INDEX($B$13:$B$16,MATCH("☆☆☆",$D$13:$D$16,0)),IF(Boss!$C$10="OPEN","the Boss","All clear! Aim for rank S"))} -> S4-1 Construction Crew
A24: Replay a stage: select its yellow answer cells and press Delete. Undo an arena drill with Ctrl+Z.

Sheet S4-1 Construction Crew
A1: STAGE S4-1 ▸ CONSTRUCTION CREW
A2: Goal: insert, delete and hide rows and columns
A3: {="SCORE "&TEXT(SUM($G$14:$G$42),"0000")&" / 0220"} -> SCORE 0000 / 0220 | C3: {=IF(SUM($G$14:$G$42)>=220,"★★★",IF(SUM($G$14:$G$42)>=220*0.8,"★★☆",IF(SUM($G$14:$G$42)>=220*0.5,"★☆☆","☆☆☆")))} -> ☆☆☆ | D3: {=REPT("█",ROUND(10*SUM($G$14:$G$42)/220,0))&REPT("░",10-ROUND(10*SUM($G$14:$G$42)/220,0))&" "&TEXT(SUM($G$14:$G$42)/220,"0%")} -> ░░░░░░░░░░ 0% | F3: {=IF(SUM($G$14:$G$42)>=220*0.5,"STAGE CLEAR! ▶ Next: S4-2 Sheet Master","")}
A5: BRIEFING · new moves in this stage
A6: # | B6: What it does · Pro tip | C6: Keys / Syntax
A7: 1 | B7: Insert cells; with whole rows selected, insert whole rows. Tip: Select rows with Shift+Space first, then Ctrl+Shift++. | C7: Ctrl+Shift++
A8: 2 | B8: Delete the selected cells; with whole rows selected, delete the rows. Tip: Shift+Space first, then Ctrl+-. | C8: Ctrl+-
A9: 3 | B9: Hide the selected rows. Tip: Hidden rows keep their data. | C9: Ctrl+9
A10: 4 | B10: Hide the selected columns. Tip: Pair with Ctrl+Space to grab the column. | C10: Ctrl+0
A12: WARM-UP · flashback to earlier stages
A13: # | B13: Mission | C13: Your answer | D13: Result | E13: Hint? | F13: Hint | G13: XP
A14: W1 | B14: Which function adds values that meet one condition? (from F3-2 Money Bags) | D14: {=IFERROR(_xlfn.LET(_xlpm.a,'S4-1 Construction Crew'!$C$14,IF(TRIM(_xlpm.a&"")="","",IF(OR(SUBSTITUTE(SUBSTITUTE(SUBSTITUTE(SUBSTITUTE(SUBSTITUTE(SUBSTITUTE(SUBSTITUTE(SUBSTITUTE(SUBSTITUTE(SUBSTITUTE(SUBSTITUTE(SUBSTITUTE(SUBSTITUTE(SUBSTITUTE(SUBSTITUTE(SUBSTITUTE(SUBSTITUTE(SUBSTITUTE(SUBSTITUTE(SUBSTITUTE(SUBSTITUTE(SUBSTITUTE(SUBSTITUTE(SUBSTITUTE(SUBSTITUTE(SUBSTITUTE(SUBSTITUTE(UPPER(_xlpm.a)," ",""),"CONTROL","CTRL"),"CTL","CTRL"),"ESCAPE","ESC"),"RETURN","ENTER"),"PAGEDOWN","PGDN"),"PGDOWN","PGDN"),"PAGEUP","PGUP"),"ARROWKEYS","ARROW"),"ARROWKEY","ARROW"),"ARROWS","ARROW"),"DOWNARROW","DOWN"),"UPARROW","UP"),"LEFTARROW","LEFT"),"RIGHTARROW","RIGHT"),"ARROWDOWN","DOWN"),"ARROWUP","UP"),"ARROWLEFT","LEFT"),"ARROWRIGHT","RIGHT"),"↓","DOWN"),"↑","UP"),"←","LEFT"),"→","RIGHT"),"SPACEBAR","SPACE"),"−","-"),"MINUS","-"),"PLUS","+")=Key!$E$2:$J$2),"✔ CLEAR","✘ TRY AGAIN"))),"✘ TRY AGAIN")} | F14: {=IF(E14="Show hint",Key!$B$2,"")} | G14: {=IF(LEFT(D14,1)="✔",IF(E14="Show hint",5,10),0)} -> 0
A15: W2 | B15: Which function averages values that meet one condition? (from F3-2 Money Bags) | D15: {=IFERROR(_xlfn.LET(_xlpm.a,'S4-1 Construction Crew'!$C$15,IF(TRIM(_xlpm.a&"")="","",IF(OR(SUBSTITUTE(SUBSTITUTE(SUBSTITUTE(SUBSTITUTE(SUBSTITUTE(SUBSTITUTE(SUBSTITUTE(SUBSTITUTE(SUBSTITUTE(SUBSTITUTE(SUBSTITUTE(SUBSTITUTE(SUBSTITUTE(SUBSTITUTE(SUBSTITUTE(SUBSTITUTE(SUBSTITUTE(SUBSTITUTE(SUBSTITUTE(SUBSTITUTE(SUBSTITUTE(SUBSTITUTE(SUBSTITUTE(SUBSTITUTE(SUBSTITUTE(SUBSTITUTE(SUBSTITUTE(UPPER(_xlpm.a)," ",""),"CONTROL","CTRL"),"CTL","CTRL"),"ESCAPE","ESC"),"RETURN","ENTER"),"PAGEDOWN","PGDN"),"PGDOWN","PGDN"),"PAGEUP","PGUP"),"ARROWKEYS","ARROW"),"ARROWKEY","ARROW"),"ARROWS","ARROW"),"DOWNARROW","DOWN"),"UPARROW","UP"),"LEFTARROW","LEFT"),"RIGHTARROW","RIGHT"),"ARROWDOWN","DOWN"),"ARROWUP","UP"),"ARROWLEFT","LEFT"),"ARROWRIGHT","RIGHT"),"↓","DOWN"),"↑","UP"),"←","LEFT"),"→","RIGHT"),"SPACEBAR","SPACE"),"−","-"),"MINUS","-"),"PLUS","+")=Key!$E$3:$J$3),"✔ CLEAR","✘ TRY AGAIN"))),"✘ TRY AGAIN")} | F15: {=IF(E15="Show hint",Key!$B$3,"")} | G15: {=IF(LEFT(D15,1)="✔",IF(E15="Show hint",5,10),0)} -> 0
A16: W3 | B16: Which keys run Flash Fill? (from S2-3 Stamps & Smart Fill) | D16: {=IFERROR(_xlfn.LET(_xlpm.a,'S4-1 Construction Crew'!$C$16,IF(TRIM(_xlpm.a&"")="","",IF(OR(SUBSTITUTE(SUBSTITUTE(SUBSTITUTE(SUBSTITUTE(SUBSTITUTE(SUBSTITUTE(SUBSTITUTE(SUBSTITUTE(SUBSTITUTE(SUBSTITUTE(SUBSTITUTE(SUBSTITUTE(SUBSTITUTE(SUBSTITUTE(SUBSTITUTE(SUBSTITUTE(SUBSTITUTE(SUBSTITUTE(SUBSTITUTE(SUBSTITUTE(SUBSTITUTE(SUBSTITUTE(SUBSTITUTE(SUBSTITUTE(SUBSTITUTE(SUBSTITUTE(SUBSTITUTE(UPPER(_xlpm.a)," ",""),"CONTROL","CTRL"),"CTL","CTRL"),"ESCAPE","ESC"),"RETURN","ENTER"),"PAGEDOWN","PGDN"),"PGDOWN","PGDN"),"PAGEUP","PGUP"),"ARROWKEYS","ARROW"),"ARROWKEY","ARROW"),"ARROWS","ARROW"),"DOWNARROW","DOWN"),"UPARROW","UP"),"LEFTARROW","LEFT"),"RIGHTARROW","RIGHT"),"ARROWDOWN","DOWN"),"ARROWUP","UP"),"ARROWLEFT","LEFT"),"ARROWRIGHT","RIGHT"),"↓","DOWN"),"↑","UP"),"←","LEFT"),"→","RIGHT"),"SPACEBAR","SPACE"),"−","-"),"MINUS","-"),"PLUS","+")=Key!$E$4:$E$4),"✔ CLEAR","✘ TRY AGAIN"))),"✘ TRY AGAIN")} | F16: {=IF(E16="Show hint",Key!$B$4,"")} | G16: {=IF(LEFT(D16,1)="✔",IF(E16="Show hint",5,10),0)} -> 0
A17: W4 | B17: Which keys open the dropdown list of a cell? (from S2-3 Stamps & Smart Fill) | D17: {=IFERROR(_xlfn.LET(_xlpm.a,'S4-1 Construction Crew'!$C$17,IF(TRIM(_xlpm.a&"")="","",IF(OR(SUBSTITUTE(SUBSTITUTE(SUBSTITUTE(SUBSTITUTE(SUBSTITUTE(SUBSTITUTE(SUBSTITUTE(SUBSTITUTE(SUBSTITUTE(SUBSTITUTE(SUBSTITUTE(SUBSTITUTE(SUBSTITUTE(SUBSTITUTE(SUBSTITUTE(SUBSTITUTE(SUBSTITUTE(SUBSTITUTE(SUBSTITUTE(SUBSTITUTE(SUBSTITUTE(SUBSTITUTE(SUBSTITUTE(SUBSTITUTE(SUBSTITUTE(SUBSTITUTE(SUBSTITUTE(UPPER(_xlpm.a)," ",""),"CONTROL","CTRL"),"CTL","CTRL"),"ESCAPE","ESC"),"RETURN","ENTER"),"PAGEDOWN","PGDN"),"PGDOWN","PGDN"),"PAGEUP","PGUP"),"ARROWKEYS","ARROW"),"ARROWKEY","ARROW"),"ARROWS","ARROW"),"DOWNARROW","DOWN"),"UPARROW","UP"),"LEFTARROW","LEFT"),"RIGHTARROW","RIGHT"),"ARROWDOWN","DOWN"),"ARROWUP","UP"),"ARROWLEFT","LEFT"),"ARROWRIGHT","RIGHT"),"↓","DOWN"),"↑","UP"),"←","LEFT"),"→","RIGHT"),"SPACEBAR","SPACE"),"−","-"),"MINUS","-"),"PLUS","+")=Key!$E$5:$E$5),"✔ CLEAR","✘ TRY AGAIN"))),"✘ TRY AGAIN")} | F17: {=IF(E17="Show hint",Key!$B$5,"")} | G17: {=IF(LEFT(D17,1)="✔",IF(E17="Show hint",5,10),0)} -> 0
A18: W5 | B18: Which operator means 'greater than or equal to'? (from F2-1 True or False) | D18: {=IFERROR(_xlfn.LET(_xlpm.a,'S4-1 Construction Crew'!$C$18,IF(TRIM(_xlpm.a&"")="","",IF(OR(SUBSTITUTE(SUBSTITUTE(SUBSTITUTE(SUBSTITUTE(SUBSTITUTE(SUBSTITUTE(SUBSTITUTE(SUBSTITUTE(SUBSTITUTE(SUBSTITUTE(SUBSTITUTE(SUBSTITUTE(SUBSTITUTE(SUBSTITUTE(SUBSTITUTE(SUBSTITUTE(SUBSTITUTE(SUBSTITUTE(SUBSTITUTE(SUBSTITUTE(SUBSTITUTE(SUBSTITUTE(SUBSTITUTE(SUBSTITUTE(SUBSTITUTE(SUBSTITUTE(SUBSTITUTE(UPPER(_xlpm.a)," ",""),"CONTROL","CTRL"),"CTL","CTRL"),"ESCAPE","ESC"),"RETURN","ENTER"),"PAGEDOWN","PGDN"),"PGDOWN","PGDN"),"PAGEUP","PGUP"),"ARROWKEYS","ARROW"),"ARROWKEY","ARROW"),"ARROWS","ARROW"),"DOWNARROW","DOWN"),"UPARROW","UP"),"LEFTARROW","LEFT"),"RIGHTARROW","RIGHT"),"ARROWDOWN","DOWN"),"ARROWUP","UP"),"ARROWLEFT","LEFT"),"ARROWRIGHT","RIGHT"),"↓","DOWN"),"↑","UP"),"←","LEFT"),"→","RIGHT"),"SPACEBAR","SPACE"),"−","-"),"MINUS","-"),"PLUS","+")=Key!$E$6:$E$6),"✔ CLEAR","✘ TRY AGAIN"))),"✘ TRY AGAIN")} | F18: {=IF(E18="Show hint",Key!$B$6,"")} | G18: {=IF(LEFT(D18,1)="✔",IF(E18="Show hint",5,10),0)} -> 0
A19: W6 | B19: Which operator means 'not equal to'? (from F2-1 True or False) | D19: {=IFERROR(_xlfn.LET(_xlpm.a,'S4-1 Construction Crew'!$C$19,IF(TRIM(_xlpm.a&"")="","",IF(OR(SUBSTITUTE(SUBSTITUTE(SUBSTITUTE(SUBSTITUTE(SUBSTITUTE(SUBSTITUTE(SUBSTITUTE(SUBSTITUTE(SUBSTITUTE(SUBSTITUTE(SUBSTITUTE(SUBSTITUTE(SUBSTITUTE(SUBSTITUTE(SUBSTITUTE(SUBSTITUTE(SUBSTITUTE(SUBSTITUTE(SUBSTITUTE(SUBSTITUTE(SUBSTITUTE(SUBSTITUTE(SUBSTITUTE(SUBSTITUTE(SUBSTITUTE(SUBSTITUTE(SUBSTITUTE(UPPER(_xlpm.a)," ",""),"CONTROL","CTRL"),"CTL","CTRL"),"ESCAPE","ESC"),"RETURN","ENTER"),"PAGEDOWN","PGDN"),"PGDOWN","PGDN"),"PAGEUP","PGUP"),"ARROWKEYS","ARROW"),"ARROWKEY","ARROW"),"ARROWS","ARROW"),"DOWNARROW","DOWN"),"UPARROW","UP"),"LEFTARROW","LEFT"),"RIGHTARROW","RIGHT"),"ARROWDOWN","DOWN"),"ARROWUP","UP"),"ARROWLEFT","LEFT"),"ARROWRIGHT","RIGHT"),"↓","DOWN"),"↑","UP"),"←","LEFT"),"→","RIGHT"),"SPACEBAR","SPACE"),"−","-"),"MINUS","-"),"PLUS","+")=Key!$E$7:$E$7),"✔ CLEAR","✘ TRY AGAIN"))),"✘ TRY AGAIN")} | F19: {=IF(E19="Show hint",Key!$B$7,"")} | G19: {=IF(LEFT(D19,1)="✔",IF(E19="Show hint",5,10),0)} -> 0
A20: W7 | B20: What must surround text inside a formula? (from F2-1 True or False) | D20: {=IFERROR(_xlfn.LET(_xlpm.a,'S4-1 Construction Crew'!$C$20,IF(TRIM(_xlpm.a&"")="","",IF(OR(SUBSTITUTE(SUBSTITUTE(SUBSTITUTE(SUBSTITUTE(SUBSTITUTE(SUBSTITUTE(SUBSTITUTE(SUBSTITUTE(SUBSTITUTE(SUBSTITUTE(SUBSTITUTE(SUBSTITUTE(SUBSTITUTE(SUBSTITUTE(SUBSTITUTE(SUBSTITUTE(SUBSTITUTE(SUBSTITUTE(SUBSTITUTE(SUBSTITUTE(SUBSTITUTE(SUBSTITUTE(SUBSTITUTE(SUBSTITUTE(SUBSTITUTE(SUBSTITUTE(SUBSTITUTE(UPPER(_xlpm.a)," ",""),"CONTROL","CTRL"),"CTL","CTRL"),"ESCAPE","ESC"),"RETURN","ENTER"),"PAGEDOWN","PGDN"),"PGDOWN","PGDN"),"PAGEUP","PGUP"),"ARROWKEYS","ARROW"),"ARROWKEY","ARROW"),"ARROWS","ARROW"),"DOWNARROW","DOWN"),"UPARROW","UP"),"LEFTARROW","LEFT"),"RIGHTARROW","RIGHT"),"ARROWDOWN","DOWN"),"ARROWUP","UP"),"ARROWLEFT","LEFT"),"ARROWRIGHT","RIGHT"),"↓","DOWN"),"↑","UP"),"←","LEFT"),"→","RIGHT"),"SPACEBAR","SPACE"),"−","-"),"MINUS","-"),"PLUS","+")=Key!$E$8:$H$8),"✔ CLEAR","✘ TRY AGAIN"))),"✘ TRY AGAIN")} | F20: {=IF(E20="Show hint",Key!$B$8,"")} | G20: {=IF(LEFT(D20,1)="✔",IF(E20="Show hint",5,10),0)} -> 0
A21: W8 | B21: Which function returns one value when a test is TRUE and another when FALSE? (from F2-2 Fork in the Road) | D21: {=IFERROR(_xlfn.LET(_xlpm.a,'S4-1 Construction Crew'!$C$21,IF(TRIM(_xlpm.a&"")="","",IF(OR(SUBSTITUTE(SUBSTITUTE(SUBSTITUTE(SUBSTITUTE(SUBSTITUTE(SUBSTITUTE(SUBSTITUTE(SUBSTITUTE(SUBSTITUTE(SUBSTITUTE(SUBSTITUTE(SUBSTITUTE(SUBSTITUTE(SUBSTITUTE(SUBSTITUTE(SUBSTITUTE(SUBSTITUTE(SUBSTITUTE(SUBSTITUTE(SUBSTITUTE(SUBSTITUTE(SUBSTITUTE(SUBSTITUTE(SUBSTITUTE(SUBSTITUTE(SUBSTITUTE(SUBSTITUTE(UPPER(_xlpm.a)," ",""),"CONTROL","CTRL"),"CTL","CTRL"),"ESCAPE","ESC"),"RETURN","ENTER"),"PAGEDOWN","PGDN"),"PGDOWN","PGDN"),"PAGEUP","PGUP"),"ARROWKEYS","ARROW"),"ARROWKEY","ARROW"),"ARROWS","ARROW"),"DOWNARROW","DOWN"),"UPARROW","UP"),"LEFTARROW","LEFT"),"RIGHTARROW","RIGHT"),"ARROWDOWN","DOWN"),"ARROWUP","UP"),"ARROWLEFT","LEFT"),"ARROWRIGHT","RIGHT"),"↓","DOWN"),"↑","UP"),"←","LEFT"),"→","RIGHT"),"SPACEBAR","SPACE"),"−","-"),"MINUS","-"),"PLUS","+")=Key!$E$9:$J$9),"✔ CLEAR","✘ TRY AGAIN"))),"✘ TRY AGAIN")} | F21: {=IF(E21="Show hint",Key!$B$9,"")} | G21: {=IF(LEFT(D21,1)="✔",IF(E21="Show hint",5,10),0)} -> 0
A22: W9 | B22: In =IF(B2>100,B2*0.9,B2), what is returned when B2 is 50? (from F2-2 Fork in the Road) | D22: {=IFERROR(_xlfn.LET(_xlpm.a,'S4-1 Construction Crew'!$C$22,IF(TRIM(_xlpm.a&"")="","",IF(OR(SUBSTITUTE(SUBSTITUTE(SUBSTITUTE(SUBSTITUTE(SUBSTITUTE(SUBSTITUTE(SUBSTITUTE(SUBSTITUTE(SUBSTITUTE(SUBSTITUTE(SUBSTITUTE(SUBSTITUTE(SUBSTITUTE(SUBSTITUTE(SUBSTITUTE(SUBSTITUTE(SUBSTITUTE(SUBSTITUTE(SUBSTITUTE(SUBSTITUTE(SUBSTITUTE(SUBSTITUTE(SUBSTITUTE(SUBSTITUTE(SUBSTITUTE(SUBSTITUTE(SUBSTITUTE(UPPER(_xlpm.a)," ",""),"CONTROL","CTRL"),"CTL","CTRL"),"ESCAPE","ESC"),"RETURN","ENTER"),"PAGEDOWN","PGDN"),"PGDOWN","PGDN"),"PAGEUP","PGUP"),"ARROWKEYS","ARROW"),"ARROWKEY","ARROW"),"ARROWS","ARROW"),"DOWNARROW","DOWN"),"UPARROW","UP"),"LEFTARROW","LEFT"),"RIGHTARROW","RIGHT"),"ARROWDOWN","DOWN"),"ARROWUP","UP"),"ARROWLEFT","LEFT"),"ARROWRIGHT","RIGHT"),"↓","DOWN"),"↑","UP"),"←","LEFT"),"→","RIGHT"),"SPACEBAR","SPACE"),"−","-"),"MINUS","-"),"PLUS","+")=Key!$E$10:$E$10),"✔ CLEAR","✘ TRY AGAIN"))),"✘ TRY AGAIN")} | F22: {=IF(E22="Show hint",Key!$B$10,"")} | G22: {=IF(LEFT(D22,1)="✔",IF(E22="Show hint",5,10),0)} -> 0
A23: W10 | B23: What do you type in a formula for an empty, blank-looking result? (from F2-2 Fork in the Road) | D23: {=IFERROR(_xlfn.LET(_xlpm.a,'S4-1 Construction Crew'!$C$23,IF(TRIM(_xlpm.a&"")="","",IF(OR(SUBSTITUTE(SUBSTITUTE(SUBSTITUTE(SUBSTITUTE(SUBSTITUTE(SUBSTITUTE(SUBSTITUTE(SUBSTITUTE(SUBSTITUTE(SUBSTITUTE(SUBSTITUTE(SUBSTITUTE(SUBSTITUTE(SUBSTITUTE(SUBSTITUTE(SUBSTITUTE(SUBSTITUTE(SUBSTITUTE(SUBSTITUTE(SUBSTITUTE(SUBSTITUTE(SUBSTITUTE(SUBSTITUTE(SUBSTITUTE(SUBSTITUTE(SUBSTITUTE(SUBSTITUTE(UPPER(_xlpm.a)," ",""),"CONTROL","CTRL"),"CTL","CTRL"),"ESCAPE","ESC"),"RETURN","ENTER"),"PAGEDOWN","PGDN"),"PGDOWN","PGDN"),"PAGEUP","PGUP"),"ARROWKEYS","ARROW"),"ARROWKEY","ARROW"),"ARROWS","ARROW"),"DOWNARROW","DOWN"),"UPARROW","UP"),"LEFTARROW","LEFT"),"RIGHTARROW","RIGHT"),"ARROWDOWN","DOWN"),"ARROWUP","UP"),"ARROWLEFT","LEFT"),"ARROWRIGHT","RIGHT"),"↓","DOWN"),"↑","UP"),"←","LEFT"),"→","RIGHT"),"SPACEBAR","SPACE"),"−","-"),"MINUS","-"),"PLUS","+")=Key!$E$11:$E$11),"✔ CLEAR","✘ TRY AGAIN"))),"✘ TRY AGAIN")} | F23: {=IF(E23="Show hint",Key!$B$11,"")} | G23: {=IF(LEFT(D23,1)="✔",IF(E23="Show hint",5,10),0)} -> 0
A25: TRAINING · recognize the move (pick from the list)
A26: # | B26: Mission | C26: Your answer | D26: Result | E26: Hint? | F26: Hint | G26: XP
A27: T1 | B27: Which keys insert cells or rows? | D27: {=IFERROR(IF('S4-1 Construction Crew'!$C$27&""="","",IF('S4-1 Construction Crew'!$C$27&""=Key!$C$12&"","✔ CLEAR","✘ TRY AGAIN")),"✘ TRY AGAIN")} | F27: {=IF(E27="Show hint",Key!$B$12,"")} | G27: {=IF(LEFT(D27,1)="✔",IF(E27="Show hint",5,10),0)} -> 0
A28: T2 | B28: Which keys delete the selected cells or rows? | D28: {=IFERROR(IF('S4-1 Construction Crew'!$C$28&""="","",IF('S4-1 Construction Crew'!$C$28&""=Key!$C$13&"","✔ CLEAR","✘ TRY AGAIN")),"✘ TRY AGAIN")} | F28: {=IF(E28="Show hint",Key!$B$13,"")} | G28: {=IF(LEFT(D28,1)="✔",IF(E28="Show hint",5,10),0)} -> 0
A29: T3 | B29: Which keys hide the selected rows? | D29: {=IFERROR(IF('S4-1 Construction Crew'!$C$29&""="","",IF('S4-1 Construction Crew'!$C$29&""=Key!$C$14&"","✔ CLEAR","✘ TRY AGAIN")),"✘ TRY AGAIN")} | F29: {=IF(E29="Show hint",Key!$B$14,"")} | G29: {=IF(LEFT(D29,1)="✔",IF(E29="Show hint",5,10),0)} -> 0
A30: T4 | B30: Which keys hide the selected columns? | D30: {=IFERROR(IF('S4-1 Construction Crew'!$C$30&""="","",IF('S4-1 Construction Crew'!$C$30&""=Key!$C$15&"","✔ CLEAR","✘ TRY AGAIN")),"✘ TRY AGAIN")} | F30: {=IF(E30="Show hint",Key!$B$15,"")} | G30: {=IF(LEFT(D30,1)="✔",IF(E30="Show hint",5,10),0)} -> 0
A32: CHALLENGES · recall it, then do it
B33: ▶ Open S4-1 Arena (or press Ctrl+PgDn)
A34: # | B34: Mission | C34: Your answer | D34: Result | E34: Hint? | F34: Hint | G34: XP
A35: C1 | B35: Which keys insert cells or rows? | D35: {=IFERROR(_xlfn.LET(_xlpm.a,'S4-1 Construction Crew'!$C$35,IF(TRIM(_xlpm.a&"")="","",IF(OR(SUBSTITUTE(SUBSTITUTE(SUBSTITUTE(SUBSTITUTE(SUBSTITUTE(SUBSTITUTE(SUBSTITUTE(SUBSTITUTE(SUBSTITUTE(SUBSTITUTE(SUBSTITUTE(SUBSTITUTE(SUBSTITUTE(SUBSTITUTE(SUBSTITUTE(SUBSTITUTE(SUBSTITUTE(SUBSTITUTE(SUBSTITUTE(SUBSTITUTE(SUBSTITUTE(SUBSTITUTE(SUBSTITUTE(SUBSTITUTE(SUBSTITUTE(SUBSTITUTE(SUBSTITUTE(UPPER(_xlpm.a)," ",""),"CONTROL","CTRL"),"CTL","CTRL"),"ESCAPE","ESC"),"RETURN","ENTER"),"PAGEDOWN","PGDN"),"PGDOWN","PGDN"),"PAGEUP","PGUP"),"ARROWKEYS","ARROW"),"ARROWKEY","ARROW"),"ARROWS","ARROW"),"DOWNARROW","DOWN"),"UPARROW","UP"),"LEFTARROW","LEFT"),"RIGHTARROW","RIGHT"),"ARROWDOWN","DOWN"),"ARROWUP","UP"),"ARROWLEFT","LEFT"),"ARROWRIGHT","RIGHT"),"↓","DOWN"),"↑","UP"),"←","LEFT"),"→","RIGHT"),"SPACEBAR","SPACE"),"−","-"),"MINUS","-"),"PLUS","+")=Key!$E$16:$I$16),"✔ CLEAR","✘ TRY AGAIN"))),"✘ TRY AGAIN")} | F35: {=IF(E35="Show hint",Key!$B$16,"")} | G35: {=IF(LEFT(D35,1)="✔",IF(E35="Show hint",5,10),0)} -> 0
A36: C2 | B36: Which keys delete the selected cells or rows? | D36: {=IFERROR(_xlfn.LET(_xlpm.a,'S4-1 Construction Crew'!$C$36,IF(TRIM(_xlpm.a&"")="","",IF(OR(SUBSTITUTE(SUBSTITUTE(SUBSTITUTE(SUBSTITUTE(SUBSTITUTE(SUBSTITUTE(SUBSTITUTE(SUBSTITUTE(SUBSTITUTE(SUBSTITUTE(SUBSTITUTE(SUBSTITUTE(SUBSTITUTE(SUBSTITUTE(SUBSTITUTE(SUBSTITUTE(SUBSTITUTE(SUBSTITUTE(SUBSTITUTE(SUBSTITUTE(SUBSTITUTE(SUBSTITUTE(SUBSTITUTE(SUBSTITUTE(SUBSTITUTE(SUBSTITUTE(SUBSTITUTE(UPPER(_xlpm.a)," ",""),"CONTROL","CTRL"),"CTL","CTRL"),"ESCAPE","ESC"),"RETURN","ENTER"),"PAGEDOWN","PGDN"),"PGDOWN","PGDN"),"PAGEUP","PGUP"),"ARROWKEYS","ARROW"),"ARROWKEY","ARROW"),"ARROWS","ARROW"),"DOWNARROW","DOWN"),"UPARROW","UP"),"LEFTARROW","LEFT"),"RIGHTARROW","RIGHT"),"ARROWDOWN","DOWN"),"ARROWUP","UP"),"ARROWLEFT","LEFT"),"ARROWRIGHT","RIGHT"),"↓","DOWN"),"↑","UP"),"←","LEFT"),"→","RIGHT"),"SPACEBAR","SPACE"),"−","-"),"MINUS","-"),"PLUS","+")=Key!$E$17:$E$17),"✔ CLEAR","✘ TRY AGAIN"))),"✘ TRY AGAIN")} | F36: {=IF(E36="Show hint",Key!$B$17,"")} | G36: {=IF(LEFT(D36,1)="✔",IF(E36="Show hint",5,10),0)} -> 0
A37: C3 | B37: Which keys hide the selected rows? | D37: {=IFERROR(_xlfn.LET(_xlpm.a,'S4-1 Construction Crew'!$C$37,IF(TRIM(_xlpm.a&"")="","",IF(OR(SUBSTITUTE(SUBSTITUTE(SUBSTITUTE(SUBSTITUTE(SUBSTITUTE(SUBSTITUTE(SUBSTITUTE(SUBSTITUTE(SUBSTITUTE(SUBSTITUTE(SUBSTITUTE(SUBSTITUTE(SUBSTITUTE(SUBSTITUTE(SUBSTITUTE(SUBSTITUTE(SUBSTITUTE(SUBSTITUTE(SUBSTITUTE(SUBSTITUTE(SUBSTITUTE(SUBSTITUTE(SUBSTITUTE(SUBSTITUTE(SUBSTITUTE(SUBSTITUTE(SUBSTITUTE(UPPER(_xlpm.a)," ",""),"CONTROL","CTRL"),"CTL","CTRL"),"ESCAPE","ESC"),"RETURN","ENTER"),"PAGEDOWN","PGDN"),"PGDOWN","PGDN"),"PAGEUP","PGUP"),"ARROWKEYS","ARROW"),"ARROWKEY","ARROW"),"ARROWS","ARROW"),"DOWNARROW","DOWN"),"UPARROW","UP"),"LEFTARROW","LEFT"),"RIGHTARROW","RIGHT"),"ARROWDOWN","DOWN"),"ARROWUP","UP"),"ARROWLEFT","LEFT"),"ARROWRIGHT","RIGHT"),"↓","DOWN"),"↑","UP"),"←","LEFT"),"→","RIGHT"),"SPACEBAR","SPACE"),"−","-"),"MINUS","-"),"PLUS","+")=Key!$E$18:$E$18),"✔ CLEAR","✘ TRY AGAIN"))),"✘ TRY AGAIN")} | F37: {=IF(E37="Show hint",Key!$B$18,"")} | G37: {=IF(LEFT(D37,1)="✔",IF(E37="Show hint",5,10),0)} -> 0
A38: C4 | B38: Which keys hide the selected columns? | D38: {=IFERROR(_xlfn.LET(_xlpm.a,'S4-1 Construction Crew'!$C$38,IF(TRIM(_xlpm.a&"")="","",IF(OR(SUBSTITUTE(SUBSTITUTE(SUBSTITUTE(SUBSTITUTE(SUBSTITUTE(SUBSTITUTE(SUBSTITUTE(SUBSTITUTE(SUBSTITUTE(SUBSTITUTE(SUBSTITUTE(SUBSTITUTE(SUBSTITUTE(SUBSTITUTE(SUBSTITUTE(SUBSTITUTE(SUBSTITUTE(SUBSTITUTE(SUBSTITUTE(SUBSTITUTE(SUBSTITUTE(SUBSTITUTE(SUBSTITUTE(SUBSTITUTE(SUBSTITUTE(SUBSTITUTE(SUBSTITUTE(UPPER(_xlpm.a)," ",""),"CONTROL","CTRL"),"CTL","CTRL"),"ESCAPE","ESC"),"RETURN","ENTER"),"PAGEDOWN","PGDN"),"PGDOWN","PGDN"),"PAGEUP","PGUP"),"ARROWKEYS","ARROW"),"ARROWKEY","ARROW"),"ARROWS","ARROW"),"DOWNARROW","DOWN"),"UPARROW","UP"),"LEFTARROW","LEFT"),"RIGHTARROW","RIGHT"),"ARROWDOWN","DOWN"),"ARROWUP","UP"),"ARROWLEFT","LEFT"),"ARROWRIGHT","RIGHT"),"↓","DOWN"),"↑","UP"),"←","LEFT"),"→","RIGHT"),"SPACEBAR","SPACE"),"−","-"),"MINUS","-"),"PLUS","+")=Key!$E$19:$E$19),"✔ CLEAR","✘ TRY AGAIN"))),"✘ TRY AGAIN")} | F38: {=IF(E38="Show hint",Key!$B$19,"")} | G38: {=IF(LEFT(D38,1)="✔",IF(E38="Show hint",5,10),0)} -> 0
A39: C5 | B39: In the LIST block, rows with DELETE ME must go. Click the first DELETE ME cell, press Shift+Space, then Shift+↓ twice to select all three rows, and press Ctrl+-. | C39: ▶ ARENA C5 (cell B32) | D39: {=IF(IFERROR(AND(COUNTIF('S4-1 Arena'!$B:$B,"DELETE ME")=0,COUNTIF('S4-1 Arena'!$B:$B,"KEEP")=7),FALSE),"✔ CLEAR","· not yet")} -> · not yet | F39: {=IF(E39="Show hint",Key!$B$20,"")} | G39: {=IF(LEFT(D39,1)="✔",IF(E39="Show hint",5,10),0)} -> 0
A40: C6 | B40: Click INSERT ABOVE (B25), press Shift+Space, then Shift+↓ once to select two rows, and press Ctrl+Shift++ to insert two blank rows above it. | C40: ▶ ARENA C6 (cell B25) | D40: {=IF(IFERROR(MATCH("INSERT ABOVE",'S4-1 Arena'!$B:$B,0)-MATCH("ROW ABOVE",'S4-1 Arena'!$B:$B,0)=3,FALSE),"✔ CLEAR","· not yet")} -> · not yet | F40: {=IF(E40="Show hint",Key!$B$21,"")} | G40: {=IF(LEFT(D40,1)="✔",IF(E40="Show hint",5,10),0)} -> 0
A41: C7 | B41: Hide both SECRET rows: click a SECRET cell, press Shift+Space, then Ctrl+9. Repeat for the other one, then press F9. | C41: ▶ ARENA C7 (cell B14) | D41: {=IF(IFERROR(AND(SUMPRODUCT(SUBTOTAL(103,OFFSET('S4-1 Arena'!$B$13,ROW('S4-1 Arena'!$B$13:$B$20)-ROW('S4-1 Arena'!$B$13),0))*('S4-1 Arena'!$B$13:$B$20="SECRET"))=0,SUBTOTAL(103,'S4-1 Arena'!$B$13:$B$20)=6),FALSE),"✔ CLEAR","· not yet · press F9")} -> · not yet · press F9 | F41: {=IF(E41="Show hint",Key!$B$22,"")} | G41: {=IF(LEFT(D41,1)="✔",IF(E41="Show hint",5,10),0)} -> 0
A42: C8 | B42: Click H5 (HIDE ME), press Ctrl+Space to select column H, then Ctrl+0 to hide it. Press F9. | C42: ▶ ARENA C8 (cell H5) | D42: {=IF(IFERROR(INDEX(CELL("width",'S4-1 Arena'!$H$5),1)=0,FALSE),"✔ CLEAR","· not yet · press F9")} -> · not yet · press F9 | F42: {=IF(E42="Show hint",Key!$B$23,"")} | G42: {=IF(LEFT(D42,1)="✔",IF(E42="Show hint",5,10),0)} -> 0

Sheet S4-1 Arena
A1: ARENA ▸ S4-1 CONSTRUCTION CREW
A2: Practice area · everything here is editable. Missions and their checks are on the stage sheet.
A3: PASS CODE | B3: BUILDER | D3: ◀ Back to S4-1 Construction Crew
H5: HIDE ME
H6: 1
H7: 2
H8: 3
H9: 4
H10: 5
B12: SECRET LIST
B13: open | C13: 1
B14: SECRET | C14: 2
B15: open | C15: 3
B16: open | C16: 4
B17: SECRET | C17: 5
B18: open | C18: 6
B19: open | C19: 7
B20: open | C20: 8
B24: ROW ABOVE
B25: INSERT ABOVE
B29: LIST
B30: KEEP | C30: 1
B31: KEEP | C31: 2
B32: DELETE ME | C32: 3
B33: DELETE ME | C33: 4
B34: DELETE ME | C34: 5
B35: KEEP | C35: 6
B36: KEEP | C36: 7
B37: KEEP | C37: 8
B38: KEEP | C38: 9
B39: KEEP | C39: 10

Sheet S4-2 Sheet Master
A1: STAGE S4-2 ▸ SHEET MASTER
A2: Goal: manage sheets and files from the keyboard
A3: {="SCORE "&TEXT(SUM($G$18:$G$53),"0000")&" / 0290"} -> SCORE 0000 / 0290 | C3: {=IF(SUM($G$18:$G$53)>=290,"★★★",IF(SUM($G$18:$G$53)>=290*0.8,"★★☆",IF(SUM($G$18:$G$53)>=290*0.5,"★☆☆","☆☆☆")))} -> ☆☆☆ | D3: {=REPT("█",ROUND(10*SUM($G$18:$G$53)/290,0))&REPT("░",10-ROUND(10*SUM($G$18:$G$53)/290,0))&" "&TEXT(SUM($G$18:$G$53)/290,"0%")} -> ░░░░░░░░░░ 0% | F3: {=IF(SUM($G$18:$G$53)>=290*0.5,"STAGE CLEAR! ▶ Next: S4-3 Detective","")}
A5: BRIEFING · new moves in this stage
A6: # | B6: What it does · Pro tip | C6: Keys / Syntax
A7: 1 | B7: Insert a new worksheet. Tip: Alt+Shift+F1 does the same. | C7: Shift+F11
A8: 2 | B8: Rename the current sheet (KeyTips: Home, Format, Rename). Tip: Type the new name, then Enter. | C8: Alt+H, O, R
A9: 3 | B9: Save the workbook. Tip: Save early, save often. | C9: Ctrl+S
A10: 4 | B10: Open Save As to save a copy or change the name. Tip: Keep the original and practice on a copy. | C10: F12
A11: 5 | B11: Create a new blank workbook. Tip: Starts fresh in a new window. | C11: Ctrl+N
A12: 6 | B12: Open a workbook (and see your recent files). Tip: Recent files are listed first. | C12: Ctrl+O
A13: 7 | B13: Close the current workbook window. Tip: Excel asks before losing changes. | C13: Ctrl+W
A14: 8 | B14: Open Print (with a preview). Tip: Check the preview before paper. | C14: Ctrl+P
A16: WARM-UP · flashback to earlier stages
A17: # | B17: Mission | C17: Your answer | D17: Result | E17: Hint? | F17: Hint | G17: XP
A18: W1 | B18: Which keys insert cells or rows? (from S4-1 Construction Crew) | D18: {=IFERROR(_xlfn.LET(_xlpm.a,'S4-2 Sheet Master'!$C$18,IF(TRIM(_xlpm.a&"")="","",IF(OR(SUBSTITUTE(SUBSTITUTE(SUBSTITUTE(SUBSTITUTE(SUBSTITUTE(SUBSTITUTE(SUBSTITUTE(SUBSTITUTE(SUBSTITUTE(SUBSTITUTE(SUBSTITUTE(SUBSTITUTE(SUBSTITUTE(SUBSTITUTE(SUBSTITUTE(SUBSTITUTE(SUBSTITUTE(SUBSTITUTE(SUBSTITUTE(SUBSTITUTE(SUBSTITUTE(SUBSTITUTE(SUBSTITUTE(SUBSTITUTE(SUBSTITUTE(SUBSTITUTE(SUBSTITUTE(UPPER(_xlpm.a)," ",""),"CONTROL","CTRL"),"CTL","CTRL"),"ESCAPE","ESC"),"RETURN","ENTER"),"PAGEDOWN","PGDN"),"PGDOWN","PGDN"),"PAGEUP","PGUP"),"ARROWKEYS","ARROW"),"ARROWKEY","ARROW"),"ARROWS","ARROW"),"DOWNARROW","DOWN"),"UPARROW","UP"),"LEFTARROW","LEFT"),"RIGHTARROW","RIGHT"),"ARROWDOWN","DOWN"),"ARROWUP","UP"),"ARROWLEFT","LEFT"),"ARROWRIGHT","RIGHT"),"↓","DOWN"),"↑","UP"),"←","LEFT"),"→","RIGHT"),"SPACEBAR","SPACE"),"−","-"),"MINUS","-"),"PLUS","+")=Key!$E$24:$I$24),"✔ CLEAR","✘ TRY AGAIN"))),"✘ TRY AGAIN")} | F18: {=IF(E18="Show hint",Key!$B$24,"")} | G18: {=IF(LEFT(D18,1)="✔",IF(E18="Show hint",5,10),0)} -> 0
A19: W2 | B19: Which keys delete the selected cells or rows? (from S4-1 Construction Crew) | D19: {=IFERROR(_xlfn.LET(_xlpm.a,'S4-2 Sheet Master'!$C$19,IF(TRIM(_xlpm.a&"")="","",IF(OR(SUBSTITUTE(SUBSTITUTE(SUBSTITUTE(SUBSTITUTE(SUBSTITUTE(SUBSTITUTE(SUBSTITUTE(SUBSTITUTE(SUBSTITUTE(SUBSTITUTE(SUBSTITUTE(SUBSTITUTE(SUBSTITUTE(SUBSTITUTE(SUBSTITUTE(SUBSTITUTE(SUBSTITUTE(SUBSTITUTE(SUBSTITUTE(SUBSTITUTE(SUBSTITUTE(SUBSTITUTE(SUBSTITUTE(SUBSTITUTE(SUBSTITUTE(SUBSTITUTE(SUBSTITUTE(UPPER(_xlpm.a)," ",""),"CONTROL","CTRL"),"CTL","CTRL"),"ESCAPE","ESC"),"RETURN","ENTER"),"PAGEDOWN","PGDN"),"PGDOWN","PGDN"),"PAGEUP","PGUP"),"ARROWKEYS","ARROW"),"ARROWKEY","ARROW"),"ARROWS","ARROW"),"DOWNARROW","DOWN"),"UPARROW","UP"),"LEFTARROW","LEFT"),"RIGHTARROW","RIGHT"),"ARROWDOWN","DOWN"),"ARROWUP","UP"),"ARROWLEFT","LEFT"),"ARROWRIGHT","RIGHT"),"↓","DOWN"),"↑","UP"),"←","LEFT"),"→","RIGHT"),"SPACEBAR","SPACE"),"−","-"),"MINUS","-"),"PLUS","+")=Key!$E$25:$E$25),"✔ CLEAR","✘ TRY AGAIN"))),"✘ TRY AGAIN")} | F19: {=IF(E19="Show hint",Key!$B$25,"")} | G19: {=IF(LEFT(D19,1)="✔",IF(E19="Show hint",5,10),0)} -> 0
A20: W3 | B20: Which keys hide the selected rows? (from S4-1 Construction Crew) | D20: {=IFERROR(_xlfn.LET(_xlpm.a,'S4-2 Sheet Master'!$C$20,IF(TRIM(_xlpm.a&"")="","",IF(OR(SUBSTITUTE(SUBSTITUTE(SUBSTITUTE(SUBSTITUTE(SUBSTITUTE(SUBSTITUTE(SUBSTITUTE(SUBSTITUTE(SUBSTITUTE(SUBSTITUTE(SUBSTITUTE(SUBSTITUTE(SUBSTITUTE(SUBSTITUTE(SUBSTITUTE(SUBSTITUTE(SUBSTITUTE(SUBSTITUTE(SUBSTITUTE(SUBSTITUTE(SUBSTITUTE(SUBSTITUTE(SUBSTITUTE(SUBSTITUTE(SUBSTITUTE(SUBSTITUTE(SUBSTITUTE(UPPER(_xlpm.a)," ",""),"CONTROL","CTRL"),"CTL","CTRL"),"ESCAPE","ESC"),"RETURN","ENTER"),"PAGEDOWN","PGDN"),"PGDOWN","PGDN"),"PAGEUP","PGUP"),"ARROWKEYS","ARROW"),"ARROWKEY","ARROW"),"ARROWS","ARROW"),"DOWNARROW","DOWN"),"UPARROW","UP"),"LEFTARROW","LEFT"),"RIGHTARROW","RIGHT"),"ARROWDOWN","DOWN"),"ARROWUP","UP"),"ARROWLEFT","LEFT"),"ARROWRIGHT","RIGHT"),"↓","DOWN"),"↑","UP"),"←","LEFT"),"→","RIGHT"),"SPACEBAR","SPACE"),"−","-"),"MINUS","-"),"PLUS","+")=Key!$E$26:$E$26),"✔ CLEAR","✘ TRY AGAIN"))),"✘ TRY AGAIN")} | F20: {=IF(E20="Show hint",Key!$B$26,"")} | G20: {=IF(LEFT(D20,1)="✔",IF(E20="Show hint",5,10),0)} -> 0
A21: W4 | B21: Which keys hide the selected columns? (from S4-1 Construction Crew) | D21: {=IFERROR(_xlfn.LET(_xlpm.a,'S4-2 Sheet Master'!$C$21,IF(TRIM(_xlpm.a&"")="","",IF(OR(SUBSTITUTE(SUBSTITUTE(SUBSTITUTE(SUBSTITUTE(SUBSTITUTE(SUBSTITUTE(SUBSTITUTE(SUBSTITUTE(SUBSTITUTE(SUBSTITUTE(SUBSTITUTE(SUBSTITUTE(SUBSTITUTE(SUBSTITUTE(SUBSTITUTE(SUBSTITUTE(SUBSTITUTE(SUBSTITUTE(SUBSTITUTE(SUBSTITUTE(SUBSTITUTE(SUBSTITUTE(SUBSTITUTE(SUBSTITUTE(SUBSTITUTE(SUBSTITUTE(SUBSTITUTE(UPPER(_xlpm.a)," ",""),"CONTROL","CTRL"),"CTL","CTRL"),"ESCAPE","ESC"),"RETURN","ENTER"),"PAGEDOWN","PGDN"),"PGDOWN","PGDN"),"PAGEUP","PGUP"),"ARROWKEYS","ARROW"),"ARROWKEY","ARROW"),"ARROWS","ARROW"),"DOWNARROW","DOWN"),"UPARROW","UP"),"LEFTARROW","LEFT"),"RIGHTARROW","RIGHT"),"ARROWDOWN","DOWN"),"ARROWUP","UP"),"ARROWLEFT","LEFT"),"ARROWRIGHT","RIGHT"),"↓","DOWN"),"↑","UP"),"←","LEFT"),"→","RIGHT"),"SPACEBAR","SPACE"),"−","-"),"MINUS","-"),"PLUS","+")=Key!$E$27:$E$27),"✔ CLEAR","✘ TRY AGAIN"))),"✘ TRY AGAIN")} | F21: {=IF(E21="Show hint",Key!$B$27,"")} | G21: {=IF(LEFT(D21,1)="✔",IF(E21="Show hint",5,10),0)} -> 0
A22: W5 | B22: Which function counts rows that meet several conditions? (from F3-3 Multi-Filter) | D22: {=IFERROR(_xlfn.LET(_xlpm.a,'S4-2 Sheet Master'!$C$22,IF(TRIM(_xlpm.a&"")="","",IF(OR(SUBSTITUTE(SUBSTITUTE(SUBSTITUTE(SUBSTITUTE(SUBSTITUTE(SUBSTITUTE(SUBSTITUTE(SUBSTITUTE(SUBSTITUTE(SUBSTITUTE(SUBSTITUTE(SUBSTITUTE(SUBSTITUTE(SUBSTITUTE(SUBSTITUTE(SUBSTITUTE(SUBSTITUTE(SUBSTITUTE(SUBSTITUTE(SUBSTITUTE(SUBSTITUTE(SUBSTITUTE(SUBSTITUTE(SUBSTITUTE(SUBSTITUTE(SUBSTITUTE(SUBSTITUTE(UPPER(_xlpm.a)," ",""),"CONTROL","CTRL"),"CTL","CTRL"),"ESCAPE","ESC"),"RETURN","ENTER"),"PAGEDOWN","PGDN"),"PGDOWN","PGDN"),"PAGEUP","PGUP"),"ARROWKEYS","ARROW"),"ARROWKEY","ARROW"),"ARROWS","ARROW"),"DOWNARROW","DOWN"),"UPARROW","UP"),"LEFTARROW","LEFT"),"RIGHTARROW","RIGHT"),"ARROWDOWN","DOWN"),"ARROWUP","UP"),"ARROWLEFT","LEFT"),"ARROWRIGHT","RIGHT"),"↓","DOWN"),"↑","UP"),"←","LEFT"),"→","RIGHT"),"SPACEBAR","SPACE"),"−","-"),"MINUS","-"),"PLUS","+")=Key!$E$28:$J$28),"✔ CLEAR","✘ TRY AGAIN"))),"✘ TRY AGAIN")} | F22: {=IF(E22="Show hint",Key!$B$28,"")} | G22: {=IF(LEFT(D22,1)="✔",IF(E22="Show hint",5,10),0)} -> 0
A23: W6 | B23: Which function adds values that meet several conditions? (from F3-3 Multi-Filter) | D23: {=IFERROR(_xlfn.LET(_xlpm.a,'S4-2 Sheet Master'!$C$23,IF(TRIM(_xlpm.a&"")="","",IF(OR(SUBSTITUTE(SUBSTITUTE(SUBSTITUTE(SUBSTITUTE(SUBSTITUTE(SUBSTITUTE(SUBSTITUTE(SUBSTITUTE(SUBSTITUTE(SUBSTITUTE(SUBSTITUTE(SUBSTITUTE(SUBSTITUTE(SUBSTITUTE(SUBSTITUTE(SUBSTITUTE(SUBSTITUTE(SUBSTITUTE(SUBSTITUTE(SUBSTITUTE(SUBSTITUTE(SUBSTITUTE(SUBSTITUTE(SUBSTITUTE(SUBSTITUTE(SUBSTITUTE(SUBSTITUTE(UPPER(_xlpm.a)," ",""),"CONTROL","CTRL"),"CTL","CTRL"),"ESCAPE","ESC"),"RETURN","ENTER"),"PAGEDOWN","PGDN"),"PGDOWN","PGDN"),"PAGEUP","PGUP"),"ARROWKEYS","ARROW"),"ARROWKEY","ARROW"),"ARROWS","ARROW"),"DOWNARROW","DOWN"),"UPARROW","UP"),"LEFTARROW","LEFT"),"RIGHTARROW","RIGHT"),"ARROWDOWN","DOWN"),"ARROWUP","UP"),"ARROWLEFT","LEFT"),"ARROWRIGHT","RIGHT"),"↓","DOWN"),"↑","UP"),"←","LEFT"),"→","RIGHT"),"SPACEBAR","SPACE"),"−","-"),"MINUS","-"),"PLUS","+")=Key!$E$29:$J$29),"✔ CLEAR","✘ TRY AGAIN"))),"✘ TRY AGAIN")} | F23: {=IF(E23="Show hint",Key!$B$29,"")} | G23: {=IF(LEFT(D23,1)="✔",IF(E23="Show hint",5,10),0)} -> 0
A24: W7 | B24: Which function averages values that meet several conditions? (from F3-3 Multi-Filter) | D24: {=IFERROR(_xlfn.LET(_xlpm.a,'S4-2 Sheet Master'!$C$24,IF(TRIM(_xlpm.a&"")="","",IF(OR(SUBSTITUTE(SUBSTITUTE(SUBSTITUTE(SUBSTITUTE(SUBSTITUTE(SUBSTITUTE(SUBSTITUTE(SUBSTITUTE(SUBSTITUTE(SUBSTITUTE(SUBSTITUTE(SUBSTITUTE(SUBSTITUTE(SUBSTITUTE(SUBSTITUTE(SUBSTITUTE(SUBSTITUTE(SUBSTITUTE(SUBSTITUTE(SUBSTITUTE(SUBSTITUTE(SUBSTITUTE(SUBSTITUTE(SUBSTITUTE(SUBSTITUTE(SUBSTITUTE(SUBSTITUTE(UPPER(_xlpm.a)," ",""),"CONTROL","CTRL"),"CTL","CTRL"),"ESCAPE","ESC"),"RETURN","ENTER"),"PAGEDOWN","PGDN"),"PGDOWN","PGDN"),"PAGEUP","PGUP"),"ARROWKEYS","ARROW"),"ARROWKEY","ARROW"),"ARROWS","ARROW"),"DOWNARROW","DOWN"),"UPARROW","UP"),"LEFTARROW","LEFT"),"RIGHTARROW","RIGHT"),"ARROWDOWN","DOWN"),"ARROWUP","UP"),"ARROWLEFT","LEFT"),"ARROWRIGHT","RIGHT"),"↓","DOWN"),"↑","UP"),"←","LEFT"),"→","RIGHT"),"SPACEBAR","SPACE"),"−","-"),"MINUS","-"),"PLUS","+")=Key!$E$30:$J$30),"✔ CLEAR","✘ TRY AGAIN"))),"✘ TRY AGAIN")} | F24: {=IF(E24="Show hint",Key!$B$30,"")} | G24: {=IF(LEFT(D24,1)="✔",IF(E24="Show hint",5,10),0)} -> 0
A25: W8 | B25: Which function is TRUE only when all its conditions are TRUE? (from F2-3 Combo Moves) | D25: {=IFERROR(_xlfn.LET(_xlpm.a,'S4-2 Sheet Master'!$C$25,IF(TRIM(_xlpm.a&"")="","",IF(OR(SUBSTITUTE(SUBSTITUTE(SUBSTITUTE(SUBSTITUTE(SUBSTITUTE(SUBSTITUTE(SUBSTITUTE(SUBSTITUTE(SUBSTITUTE(SUBSTITUTE(SUBSTITUTE(SUBSTITUTE(SUBSTITUTE(SUBSTITUTE(SUBSTITUTE(SUBSTITUTE(SUBSTITUTE(SUBSTITUTE(SUBSTITUTE(SUBSTITUTE(SUBSTITUTE(SUBSTITUTE(SUBSTITUTE(SUBSTITUTE(SUBSTITUTE(SUBSTITUTE(SUBSTITUTE(UPPER(_xlpm.a)," ",""),"CONTROL","CTRL"),"CTL","CTRL"),"ESCAPE","ESC"),"RETURN","ENTER"),"PAGEDOWN","PGDN"),"PGDOWN","PGDN"),"PAGEUP","PGUP"),"ARROWKEYS","ARROW"),"ARROWKEY","ARROW"),"ARROWS","ARROW"),"DOWNARROW","DOWN"),"UPARROW","UP"),"LEFTARROW","LEFT"),"RIGHTARROW","RIGHT"),"ARROWDOWN","DOWN"),"ARROWUP","UP"),"ARROWLEFT","LEFT"),"ARROWRIGHT","RIGHT"),"↓","DOWN"),"↑","UP"),"←","LEFT"),"→","RIGHT"),"SPACEBAR","SPACE"),"−","-"),"MINUS","-"),"PLUS","+")=Key!$E$31:$J$31),"✔ CLEAR","✘ TRY AGAIN"))),"✘ TRY AGAIN")} | F25: {=IF(E25="Show hint",Key!$B$31,"")} | G25: {=IF(LEFT(D25,1)="✔",IF(E25="Show hint",5,10),0)} -> 0
A26: W9 | B26: Which function is TRUE when at least one condition is TRUE? (from F2-3 Combo Moves) | D26: {=IFERROR(_xlfn.LET(_xlpm.a,'S4-2 Sheet Master'!$C$26,IF(TRIM(_xlpm.a&"")="","",IF(OR(SUBSTITUTE(SUBSTITUTE(SUBSTITUTE(SUBSTITUTE(SUBSTITUTE(SUBSTITUTE(SUBSTITUTE(SUBSTITUTE(SUBSTITUTE(SUBSTITUTE(SUBSTITUTE(SUBSTITUTE(SUBSTITUTE(SUBSTITUTE(SUBSTITUTE(SUBSTITUTE(SUBSTITUTE(SUBSTITUTE(SUBSTITUTE(SUBSTITUTE(SUBSTITUTE(SUBSTITUTE(SUBSTITUTE(SUBSTITUTE(SUBSTITUTE(SUBSTITUTE(SUBSTITUTE(UPPER(_xlpm.a)," ",""),"CONTROL","CTRL"),"CTL","CTRL"),"ESCAPE","ESC"),"RETURN","ENTER"),"PAGEDOWN","PGDN"),"PGDOWN","PGDN"),"PAGEUP","PGUP"),"ARROWKEYS","ARROW"),"ARROWKEY","ARROW"),"ARROWS","ARROW"),"DOWNARROW","DOWN"),"UPARROW","UP"),"LEFTARROW","LEFT"),"RIGHTARROW","RIGHT"),"ARROWDOWN","DOWN"),"ARROWUP","UP"),"ARROWLEFT","LEFT"),"ARROWRIGHT","RIGHT"),"↓","DOWN"),"↑","UP"),"←","LEFT"),"→","RIGHT"),"SPACEBAR","SPACE"),"−","-"),"MINUS","-"),"PLUS","+")=Key!$E$32:$J$32),"✔ CLEAR","✘ TRY AGAIN"))),"✘ TRY AGAIN")} | F26: {=IF(E26="Show hint",Key!$B$32,"")} | G26: {=IF(LEFT(D26,1)="✔",IF(E26="Show hint",5,10),0)} -> 0
A27: W10 | B27: Which function flips TRUE and FALSE? (from F2-3 Combo Moves) | D27: {=IFERROR(_xlfn.LET(_xlpm.a,'S4-2 Sheet Master'!$C$27,IF(TRIM(_xlpm.a&"")="","",IF(OR(SUBSTITUTE(SUBSTITUTE(SUBSTITUTE(SUBSTITUTE(SUBSTITUTE(SUBSTITUTE(SUBSTITUTE(SUBSTITUTE(SUBSTITUTE(SUBSTITUTE(SUBSTITUTE(SUBSTITUTE(SUBSTITUTE(SUBSTITUTE(SUBSTITUTE(SUBSTITUTE(SUBSTITUTE(SUBSTITUTE(SUBSTITUTE(SUBSTITUTE(SUBSTITUTE(SUBSTITUTE(SUBSTITUTE(SUBSTITUTE(SUBSTITUTE(SUBSTITUTE(SUBSTITUTE(UPPER(_xlpm.a)," ",""),"CONTROL","CTRL"),"CTL","CTRL"),"ESCAPE","ESC"),"RETURN","ENTER"),"PAGEDOWN","PGDN"),"PGDOWN","PGDN"),"PAGEUP","PGUP"),"ARROWKEYS","ARROW"),"ARROWKEY","ARROW"),"ARROWS","ARROW"),"DOWNARROW","DOWN"),"UPARROW","UP"),"LEFTARROW","LEFT"),"RIGHTARROW","RIGHT"),"ARROWDOWN","DOWN"),"ARROWUP","UP"),"ARROWLEFT","LEFT"),"ARROWRIGHT","RIGHT"),"↓","DOWN"),"↑","UP"),"←","LEFT"),"→","RIGHT"),"SPACEBAR","SPACE"),"−","-"),"MINUS","-"),"PLUS","+")=Key!$E$33:$J$33),"✔ CLEAR","✘ TRY AGAIN"))),"✘ TRY AGAIN")} | F27: {=IF(E27="Show hint",Key!$B$33,"")} | G27: {=IF(LEFT(D27,1)="✔",IF(E27="Show hint",5,10),0)} -> 0
A29: TRAINING · recognize the move (pick from the list)
A30: # | B30: Mission | C30: Your answer | D30: Result | E30: Hint? | F30: Hint | G30: XP
A31: T1 | B31: Which keys insert a new worksheet? | D31: {=IFERROR(IF('S4-2 Sheet Master'!$C$31&""="","",IF('S4-2 Sheet Master'!$C$31&""=Key!$C$34&"","✔ CLEAR","✘ TRY AGAIN")),"✘ TRY AGAIN")} | F31: {=IF(E31="Show hint",Key!$B$34,"")} | G31: {=IF(LEFT(D31,1)="✔",IF(E31="Show hint",5,10),0)} -> 0
A32: T2 | B32: Which KeyTips rename the current sheet? | D32: {=IFERROR(IF('S4-2 Sheet Master'!$C$32&""="","",IF('S4-2 Sheet Master'!$C$32&""=Key!$C$35&"","✔ CLEAR","✘ TRY AGAIN")),"✘ TRY AGAIN")} | F32: {=IF(E32="Show hint",Key!$B$35,"")} | G32: {=IF(LEFT(D32,1)="✔",IF(E32="Show hint",5,10),0)} -> 0
A33: T3 | B33: Which keys save the workbook? | D33: {=IFERROR(IF('S4-2 Sheet Master'!$C$33&""="","",IF('S4-2 Sheet Master'!$C$33&""=Key!$C$36&"","✔ CLEAR","✘ TRY AGAIN")),"✘ TRY AGAIN")} | F33: {=IF(E33="Show hint",Key!$B$36,"")} | G33: {=IF(LEFT(D33,1)="✔",IF(E33="Show hint",5,10),0)} -> 0
A34: T4 | B34: Which key opens Save As? | D34: {=IFERROR(IF('S4-2 Sheet Master'!$C$34&""="","",IF('S4-2 Sheet Master'!$C$34&""=Key!$C$37&"","✔ CLEAR","✘ TRY AGAIN")),"✘ TRY AGAIN")} | F34: {=IF(E34="Show hint",Key!$B$37,"")} | G34: {=IF(LEFT(D34,1)="✔",IF(E34="Show hint",5,10),0)} -> 0
A35: T5 | B35: Which keys create a new blank workbook? | D35: {=IFERROR(IF('S4-2 Sheet Master'!$C$35&""="","",IF('S4-2 Sheet Master'!$C$35&""=Key!$C$38&"","✔ CLEAR","✘ TRY AGAIN")),"✘ TRY AGAIN")} | F35: {=IF(E35="Show hint",Key!$B$38,"")} | G35: {=IF(LEFT(D35,1)="✔",IF(E35="Show hint",5,10),0)} -> 0
A36: T6 | B36: Which keys open a workbook? | D36: {=IFERROR(IF('S4-2 Sheet Master'!$C$36&""="","",IF('S4-2 Sheet Master'!$C$36&""=Key!$C$39&"","✔ CLEAR","✘ TRY AGAIN")),"✘ TRY AGAIN")} | F36: {=IF(E36="Show hint",Key!$B$39,"")} | G36: {=IF(LEFT(D36,1)="✔",IF(E36="Show hint",5,10),0)} -> 0
A37: T7 | B37: Which keys close the current workbook? | D37: {=IFERROR(IF('S4-2 Sheet Master'!$C$37&""="","",IF('S4-2 Sheet Master'!$C$37&""=Key!$C$40&"","✔ CLEAR","✘ TRY AGAIN")),"✘ TRY AGAIN")} | F37: {=IF(E37="Show hint",Key!$B$40,"")} | G37: {=IF(LEFT(D37,1)="✔",IF(E37="Show hint",5,10),0)} -> 0
A38: T8 | B38: Which keys open Print? | D38: {=IFERROR(IF('S4-2 Sheet Master'!$C$38&""="","",IF('S4-2 Sheet Master'!$C$38&""=Key!$C$41&"","✔ CLEAR","✘ TRY AGAIN")),"✘ TRY AGAIN")} | F38: {=IF(E38="Show hint",Key!$B$41,"")} | G38: {=IF(LEFT(D38,1)="✔",IF(E38="Show hint",5,10),0)} -> 0
A40: CHALLENGES · recall it, then do it
B41: ▶ Open S4-2 Arena (or press Ctrl+PgDn)
A42: # | B42: Mission | C42: Your answer | D42: Result | E42: Hint? | F42: Hint | G42: XP
A43: C1 | B43: Which keys insert a new worksheet? | D43: {=IFERROR(_xlfn.LET(_xlpm.a,'S4-2 Sheet Master'!$C$43,IF(TRIM(_xlpm.a&"")="","",IF(OR(SUBSTITUTE(SUBSTITUTE(SUBSTITUTE(SUBSTITUTE(SUBSTITUTE(SUBSTITUTE(SUBSTITUTE(SUBSTITUTE(SUBSTITUTE(SUBSTITUTE(SUBSTITUTE(SUBSTITUTE(SUBSTITUTE(SUBSTITUTE(SUBSTITUTE(SUBSTITUTE(SUBSTITUTE(SUBSTITUTE(SUBSTITUTE(SUBSTITUTE(SUBSTITUTE(SUBSTITUTE(SUBSTITUTE(SUBSTITUTE(SUBSTITUTE(SUBSTITUTE(SUBSTITUTE(UPPER(_xlpm.a)," ",""),"CONTROL","CTRL"),"CTL","CTRL"),"ESCAPE","ESC"),"RETURN","ENTER"),"PAGEDOWN","PGDN"),"PGDOWN","PGDN"),"PAGEUP","PGUP"),"ARROWKEYS","ARROW"),"ARROWKEY","ARROW"),"ARROWS","ARROW"),"DOWNARROW","DOWN"),"UPARROW","UP"),"LEFTARROW","LEFT"),"RIGHTARROW","RIGHT"),"ARROWDOWN","DOWN"),"ARROWUP","UP"),"ARROWLEFT","LEFT"),"ARROWRIGHT","RIGHT"),"↓","DOWN"),"↑","UP"),"←","LEFT"),"→","RIGHT"),"SPACEBAR","SPACE"),"−","-"),"MINUS","-"),"PLUS","+")=Key!$E$42:$G$42),"✔ CLEAR","✘ TRY AGAIN"))),"✘ TRY AGAIN")} | F43: {=IF(E43="Show hint",Key!$B$42,"")} | G43: {=IF(LEFT(D43,1)="✔",IF(E43="Show hint",5,10),0)} -> 0
A44: C2 | B44: Which KeyTips rename the current sheet? | D44: {=IFERROR(_xlfn.LET(_xlpm.a,'S4-2 Sheet Master'!$C$44,IF(TRIM(_xlpm.a&"")="","",IF(OR(SUBSTITUTE(SUBSTITUTE(SUBSTITUTE(SUBSTITUTE(SUBSTITUTE(SUBSTITUTE(SUBSTITUTE(SUBSTITUTE(SUBSTITUTE(SUBSTITUTE(SUBSTITUTE(SUBSTITUTE(SUBSTITUTE(SUBSTITUTE(SUBSTITUTE(SUBSTITUTE(SUBSTITUTE(SUBSTITUTE(SUBSTITUTE(SUBSTITUTE(SUBSTITUTE(SUBSTITUTE(SUBSTITUTE(SUBSTITUTE(SUBSTITUTE(SUBSTITUTE(SUBSTITUTE(UPPER(_xlpm.a)," ",""),"CONTROL","CTRL"),"CTL","CTRL"),"ESCAPE","ESC"),"RETURN","ENTER"),"PAGEDOWN","PGDN"),"PGDOWN","PGDN"),"PAGEUP","PGUP"),"ARROWKEYS","ARROW"),"ARROWKEY","ARROW"),"ARROWS","ARROW"),"DOWNARROW","DOWN"),"UPARROW","UP"),"LEFTARROW","LEFT"),"RIGHTARROW","RIGHT"),"ARROWDOWN","DOWN"),"ARROWUP","UP"),"ARROWLEFT","LEFT"),"ARROWRIGHT","RIGHT"),"↓","DOWN"),"↑","UP"),"←","LEFT"),"→","RIGHT"),"SPACEBAR","SPACE"),"−","-"),"MINUS","-"),"PLUS","+")=Key!$E$43:$T$43),"✔ CLEAR","✘ TRY AGAIN"))),"✘ TRY AGAIN")} | F44: {=IF(E44="Show hint",Key!$B$43,"")} | G44: {=IF(LEFT(D44,1)="✔",IF(E44="Show hint",5,10),0)} -> 0
...

Sheet S4-2 Arena
A1: ARENA ▸ S4-2 SHEET MASTER
A2: Practice area · everything here is editable. Missions and their checks are on the stage sheet.
A3: PASS CODE | B3: TABS | D3: ◀ Back to S4-2 Sheet Master
B5: Sheet tricks happen on the sheet tabs. The missions are on the stage sheet.

Sheet Rename Me
A1: RENAME ME
A2: Rename this sheet to Vault with Alt, H, O, R (mission on stage S4-2).

Sheet S4-3 Detective
A1: STAGE S4-3 ▸ DETECTIVE
A2: Goal: find and fix anything in seconds
A3: {="SCORE "&TEXT(SUM($G$12:$G$35),"0000")&" / 0170"} -> SCORE 0000 / 0170 | C3: {=IF(SUM($G$12:$G$35)>=170,"★★★",IF(SUM($G$12:$G$35)>=170*0.8,"★★☆",IF(SUM($G$12:$G$35)>=170*0.5,"★☆☆","☆☆☆")))} -> ☆☆☆ | D3: {=REPT("█",ROUND(10*SUM($G$12:$G$35)/170,0))&REPT("░",10-ROUND(10*SUM($G$12:$G$35)/170,0))&" "&TEXT(SUM($G$12:$G$35)/170,"0%")} -> ░░░░░░░░░░ 0% | F3: {=IF(SUM($G$12:$G$35)>=170*0.5,"STAGE CLEAR! ▶ Next: S4-4 Data Wrangler","")}
A5: BRIEFING · new moves in this stage
A6: # | B6: What it does · Pro tip | C6: Keys / Syntax
A7: 1 | B7: Find text or numbers anywhere on the sheet. Tip: Find All lists every match and counts them. | C7: Ctrl+F
A8: 2 | B8: Find and replace text or numbers. Tip: Replace All fixes every match at once. | C8: Ctrl+H
A10: WARM-UP · flashback to earlier stages
A11: # | B11: Mission | C11: Your answer | D11: Result | E11: Hint? | F11: Hint | G11: XP
A12: W1 | B12: Which keys insert a new worksheet? (from S4-2 Sheet Master) | D12: {=IFERROR(_xlfn.LET(_xlpm.a,'S4-3 Detective'!$C$12,IF(TRIM(_xlpm.a&"")="","",IF(OR(SUBSTITUTE(SUBSTITUTE(SUBSTITUTE(SUBSTITUTE(SUBSTITUTE(SUBSTITUTE(SUBSTITUTE(SUBSTITUTE(SUBSTITUTE(SUBSTITUTE(SUBSTITUTE(SUBSTITUTE(SUBSTITUTE(SUBSTITUTE(SUBSTITUTE(SUBSTITUTE(SUBSTITUTE(SUBSTITUTE(SUBSTITUTE(SUBSTITUTE(SUBSTITUTE(SUBSTITUTE(SUBSTITUTE(SUBSTITUTE(SUBSTITUTE(SUBSTITUTE(SUBSTITUTE(UPPER(_xlpm.a)," ",""),"CONTROL","CTRL"),"CTL","CTRL"),"ESCAPE","ESC"),"RETURN","ENTER"),"PAGEDOWN","PGDN"),"PGDOWN","PGDN"),"PAGEUP","PGUP"),"ARROWKEYS","ARROW"),"ARROWKEY","ARROW"),"ARROWS","ARROW"),"DOWNARROW","DOWN"),"UPARROW","UP"),"LEFTARROW","LEFT"),"RIGHTARROW","RIGHT"),"ARROWDOWN","DOWN"),"ARROWUP","UP"),"ARROWLEFT","LEFT"),"ARROWRIGHT","RIGHT"),"↓","DOWN"),"↑","UP"),"←","LEFT"),"→","RIGHT"),"SPACEBAR","SPACE"),"−","-"),"MINUS","-"),"PLUS","+")=Key!$E$53:$G$53),"✔ CLEAR","✘ TRY AGAIN"))),"✘ TRY AGAIN")} | F12: {=IF(E12="Show hint",Key!$B$53,"")} | G12: {=IF(LEFT(D12,1)="✔",IF(E12="Show hint",5,10),0)} -> 0
A13: W2 | B13: Which KeyTips rename the current sheet? (from S4-2 Sheet Master) | D13: {=IFERROR(_xlfn.LET(_xlpm.a,'S4-3 Detective'!$C$13,IF(TRIM(_xlpm.a&"")="","",IF(OR(SUBSTITUTE(SUBSTITUTE(SUBSTITUTE(SUBSTITUTE(SUBSTITUTE(SUBSTITUTE(SUBSTITUTE(SUBSTITUTE(SUBSTITUTE(SUBSTITUTE(SUBSTITUTE(SUBSTITUTE(SUBSTITUTE(SUBSTITUTE(SUBSTITUTE(SUBSTITUTE(SUBSTITUTE(SUBSTITUTE(SUBSTITUTE(SUBSTITUTE(SUBSTITUTE(SUBSTITUTE(SUBSTITUTE(SUBSTITUTE(SUBSTITUTE(SUBSTITUTE(SUBSTITUTE(UPPER(_xlpm.a)," ",""),"CONTROL","CTRL"),"CTL","CTRL"),"ESCAPE","ESC"),"RETURN","ENTER"),"PAGEDOWN","PGDN"),"PGDOWN","PGDN"),"PAGEUP","PGUP"),"ARROWKEYS","ARROW"),"ARROWKEY","ARROW"),"ARROWS","ARROW"),"DOWNARROW","DOWN"),"UPARROW","UP"),"LEFTARROW","LEFT"),"RIGHTARROW","RIGHT"),"ARROWDOWN","DOWN"),"ARROWUP","UP"),"ARROWLEFT","LEFT"),"ARROWRIGHT","RIGHT"),"↓","DOWN"),"↑","UP"),"←","LEFT"),"→","RIGHT"),"SPACEBAR","SPACE"),"−","-"),"MINUS","-"),"PLUS","+")=Key!$E$54:$T$54),"✔ CLEAR","✘ TRY AGAIN"))),"✘ TRY AGAIN")} | F13: {=IF(E13="Show hint",Key!$B$54,"")} | G13: {=IF(LEFT(D13,1)="✔",IF(E13="Show hint",5,10),0)} -> 0
A14: W3 | B14: Which keys save the workbook? (from S4-2 Sheet Master) | D14: {=IFERROR(_xlfn.LET(_xlpm.a,'S4-3 Detective'!$C$14,IF(TRIM(_xlpm.a&"")="","",IF(OR(SUBSTITUTE(SUBSTITUTE(SUBSTITUTE(SUBSTITUTE(SUBSTITUTE(SUBSTITUTE(SUBSTITUTE(SUBSTITUTE(SUBSTITUTE(SUBSTITUTE(SUBSTITUTE(SUBSTITUTE(SUBSTITUTE(SUBSTITUTE(SUBSTITUTE(SUBSTITUTE(SUBSTITUTE(SUBSTITUTE(SUBSTITUTE(SUBSTITUTE(SUBSTITUTE(SUBSTITUTE(SUBSTITUTE(SUBSTITUTE(SUBSTITUTE(SUBSTITUTE(SUBSTITUTE(UPPER(_xlpm.a)," ",""),"CONTROL","CTRL"),"CTL","CTRL"),"ESCAPE","ESC"),"RETURN","ENTER"),"PAGEDOWN","PGDN"),"PGDOWN","PGDN"),"PAGEUP","PGUP"),"ARROWKEYS","ARROW"),"ARROWKEY","ARROW"),"ARROWS","ARROW"),"DOWNARROW","DOWN"),"UPARROW","UP"),"LEFTARROW","LEFT"),"RIGHTARROW","RIGHT"),"ARROWDOWN","DOWN"),"ARROWUP","UP"),"ARROWLEFT","LEFT"),"ARROWRIGHT","RIGHT"),"↓","DOWN"),"↑","UP"),"←","LEFT"),"→","RIGHT"),"SPACEBAR","SPACE"),"−","-"),"MINUS","-"),"PLUS","+")=Key!$E$55:$E$55),"✔ CLEAR","✘ TRY AGAIN"))),"✘ TRY AGAIN")} | F14: {=IF(E14="Show hint",Key!$B$55,"")} | G14: {=IF(LEFT(D14,1)="✔",IF(E14="Show hint",5,10),0)} -> 0
A15: W4 | B15: Which key opens Save As? (from S4-2 Sheet Master) | D15: {=IFERROR(_xlfn.LET(_xlpm.a,'S4-3 Detective'!$C$15,IF(TRIM(_xlpm.a&"")="","",IF(OR(SUBSTITUTE(SUBSTITUTE(SUBSTITUTE(SUBSTITUTE(SUBSTITUTE(SUBSTITUTE(SUBSTITUTE(SUBSTITUTE(SUBSTITUTE(SUBSTITUTE(SUBSTITUTE(SUBSTITUTE(SUBSTITUTE(SUBSTITUTE(SUBSTITUTE(SUBSTITUTE(SUBSTITUTE(SUBSTITUTE(SUBSTITUTE(SUBSTITUTE(SUBSTITUTE(SUBSTITUTE(SUBSTITUTE(SUBSTITUTE(SUBSTITUTE(SUBSTITUTE(SUBSTITUTE(UPPER(_xlpm.a)," ",""),"CONTROL","CTRL"),"CTL","CTRL"),"ESCAPE","ESC"),"RETURN","ENTER"),"PAGEDOWN","PGDN"),"PGDOWN","PGDN"),"PAGEUP","PGUP"),"ARROWKEYS","ARROW"),"ARROWKEY","ARROW"),"ARROWS","ARROW"),"DOWNARROW","DOWN"),"UPARROW","UP"),"LEFTARROW","LEFT"),"RIGHTARROW","RIGHT"),"ARROWDOWN","DOWN"),"ARROWUP","UP"),"ARROWLEFT","LEFT"),"ARROWRIGHT","RIGHT"),"↓","DOWN"),"↑","UP"),"←","LEFT"),"→","RIGHT"),"SPACEBAR","SPACE"),"−","-"),"MINUS","-"),"PLUS","+")=Key!$E$56:$E$56),"✔ CLEAR","✘ TRY AGAIN"))),"✘ TRY AGAIN")} | F15: {=IF(E15="Show hint",Key!$B$56,"")} | G15: {=IF(LEFT(D15,1)="✔",IF(E15="Show hint",5,10),0)} -> 0
A16: W5 | B16: Which keys create a new blank workbook? (from S4-2 Sheet Master) | D16: {=IFERROR(_xlfn.LET(_xlpm.a,'S4-3 Detective'!$C$16,IF(TRIM(_xlpm.a&"")="","",IF(OR(SUBSTITUTE(SUBSTITUTE(SUBSTITUTE(SUBSTITUTE(SUBSTITUTE(SUBSTITUTE(SUBSTITUTE(SUBSTITUTE(SUBSTITUTE(SUBSTITUTE(SUBSTITUTE(SUBSTITUTE(SUBSTITUTE(SUBSTITUTE(SUBSTITUTE(SUBSTITUTE(SUBSTITUTE(SUBSTITUTE(SUBSTITUTE(SUBSTITUTE(SUBSTITUTE(SUBSTITUTE(SUBSTITUTE(SUBSTITUTE(SUBSTITUTE(SUBSTITUTE(SUBSTITUTE(UPPER(_xlpm.a)," ",""),"CONTROL","CTRL"),"CTL","CTRL"),"ESCAPE","ESC"),"RETURN","ENTER"),"PAGEDOWN","PGDN"),"PGDOWN","PGDN"),"PAGEUP","PGUP"),"ARROWKEYS","ARROW"),"ARROWKEY","ARROW"),"ARROWS","ARROW"),"DOWNARROW","DOWN"),"UPARROW","UP"),"LEFTARROW","LEFT"),"RIGHTARROW","RIGHT"),"ARROWDOWN","DOWN"),"ARROWUP","UP"),"ARROWLEFT","LEFT"),"ARROWRIGHT","RIGHT"),"↓","DOWN"),"↑","UP"),"←","LEFT"),"→","RIGHT"),"SPACEBAR","SPACE"),"−","-"),"MINUS","-"),"PLUS","+")=Key!$E$57:$E$57),"✔ CLEAR","✘ TRY AGAIN"))),"✘ TRY AGAIN")} | F16: {=IF(E16="Show hint",Key!$B$57,"")} | G16: {=IF(LEFT(D16,1)="✔",IF(E16="Show hint",5,10),0)} -> 0
A17: W6 | B17: Which keys open a workbook? (from S4-2 Sheet Master) | D17: {=IFERROR(_xlfn.LET(_xlpm.a,'S4-3 Detective'!$C$17,IF(TRIM(_xlpm.a&"")="","",IF(OR(SUBSTITUTE(SUBSTITUTE(SUBSTITUTE(SUBSTITUTE(SUBSTITUTE(SUBSTITUTE(SUBSTITUTE(SUBSTITUTE(SUBSTITUTE(SUBSTITUTE(SUBSTITUTE(SUBSTITUTE(SUBSTITUTE(SUBSTITUTE(SUBSTITUTE(SUBSTITUTE(SUBSTITUTE(SUBSTITUTE(SUBSTITUTE(SUBSTITUTE(SUBSTITUTE(SUBSTITUTE(SUBSTITUTE(SUBSTITUTE(SUBSTITUTE(SUBSTITUTE(SUBSTITUTE(UPPER(_xlpm.a)," ",""),"CONTROL","CTRL"),"CTL","CTRL"),"ESCAPE","ESC"),"RETURN","ENTER"),"PAGEDOWN","PGDN"),"PGDOWN","PGDN"),"PAGEUP","PGUP"),"ARROWKEYS","ARROW"),"ARROWKEY","ARROW"),"ARROWS","ARROW"),"DOWNARROW","DOWN"),"UPARROW","UP"),"LEFTARROW","LEFT"),"RIGHTARROW","RIGHT"),"ARROWDOWN","DOWN"),"ARROWUP","UP"),"ARROWLEFT","LEFT"),"ARROWRIGHT","RIGHT"),"↓","DOWN"),"↑","UP"),"←","LEFT"),"→","RIGHT"),"SPACEBAR","SPACE"),"−","-"),"MINUS","-"),"PLUS","+")=Key!$E$58:$E$58),"✔ CLEAR","✘ TRY AGAIN"))),"✘ TRY AGAIN")} | F17: {=IF(E17="Show hint",Key!$B$58,"")} | G17: {=IF(LEFT(D17,1)="✔",IF(E17="Show hint",5,10),0)} -> 0
A18: W7 | B18: Which keys close the current workbook? (from S4-2 Sheet Master) | D18: {=IFERROR(_xlfn.LET(_xlpm.a,'S4-3 Detective'!$C$18,IF(TRIM(_xlpm.a&"")="","",IF(OR(SUBSTITUTE(SUBSTITUTE(SUBSTITUTE(SUBSTITUTE(SUBSTITUTE(SUBSTITUTE(SUBSTITUTE(SUBSTITUTE(SUBSTITUTE(SUBSTITUTE(SUBSTITUTE(SUBSTITUTE(SUBSTITUTE(SUBSTITUTE(SUBSTITUTE(SUBSTITUTE(SUBSTITUTE(SUBSTITUTE(SUBSTITUTE(SUBSTITUTE(SUBSTITUTE(SUBSTITUTE(SUBSTITUTE(SUBSTITUTE(SUBSTITUTE(SUBSTITUTE(SUBSTITUTE(UPPER(_xlpm.a)," ",""),"CONTROL","CTRL"),"CTL","CTRL"),"ESCAPE","ESC"),"RETURN","ENTER"),"PAGEDOWN","PGDN"),"PGDOWN","PGDN"),"PAGEUP","PGUP"),"ARROWKEYS","ARROW"),"ARROWKEY","ARROW"),"ARROWS","ARROW"),"DOWNARROW","DOWN"),"UPARROW","UP"),"LEFTARROW","LEFT"),"RIGHTARROW","RIGHT"),"ARROWDOWN","DOWN"),"ARROWUP","UP"),"ARROWLEFT","LEFT"),"ARROWRIGHT","RIGHT"),"↓","DOWN"),"↑","UP"),"←","LEFT"),"→","RIGHT"),"SPACEBAR","SPACE"),"−","-"),"MINUS","-"),"PLUS","+")=Key!$E$59:$E$59),"✔ CLEAR","✘ TRY AGAIN"))),"✘ TRY AGAIN")} | F18: {=IF(E18="Show hint",Key!$B$59,"")} | G18: {=IF(LEFT(D18,1)="✔",IF(E18="Show hint",5,10),0)} -> 0
A19: W8 | B19: Which keys open Print? (from S4-2 Sheet Master) | D19: {=IFERROR(_xlfn.LET(_xlpm.a,'S4-3 Detective'!$C$19,IF(TRIM(_xlpm.a&"")="","",IF(OR(SUBSTITUTE(SUBSTITUTE(SUBSTITUTE(SUBSTITUTE(SUBSTITUTE(SUBSTITUTE(SUBSTITUTE(SUBSTITUTE(SUBSTITUTE(SUBSTITUTE(SUBSTITUTE(SUBSTITUTE(SUBSTITUTE(SUBSTITUTE(SUBSTITUTE(SUBSTITUTE(SUBSTITUTE(SUBSTITUTE(SUBSTITUTE(SUBSTITUTE(SUBSTITUTE(SUBSTITUTE(SUBSTITUTE(SUBSTITUTE(SUBSTITUTE(SUBSTITUTE(SUBSTITUTE(UPPER(_xlpm.a)," ",""),"CONTROL","CTRL"),"CTL","CTRL"),"ESCAPE","ESC"),"RETURN","ENTER"),"PAGEDOWN","PGDN"),"PGDOWN","PGDN"),"PAGEUP","PGUP"),"ARROWKEYS","ARROW"),"ARROWKEY","ARROW"),"ARROWS","ARROW"),"DOWNARROW","DOWN"),"UPARROW","UP"),"LEFTARROW","LEFT"),"RIGHTARROW","RIGHT"),"ARROWDOWN","DOWN"),"ARROWUP","UP"),"ARROWLEFT","LEFT"),"ARROWRIGHT","RIGHT"),"↓","DOWN"),"↑","UP"),"←","LEFT"),"→","RIGHT"),"SPACEBAR","SPACE"),"−","-"),"MINUS","-"),"PLUS","+")=Key!$E$60:$E$60),"✔ CLEAR","✘ TRY AGAIN"))),"✘ TRY AGAIN")} | F19: {=IF(E19="Show hint",Key!$B$60,"")} | G19: {=IF(LEFT(D19,1)="✔",IF(E19="Show hint",5,10),0)} -> 0
A20: W9 | B20: Which function returns the largest value that meets conditions? (from F3-4 Extremes) | D20: {=IFERROR(_xlfn.LET(_xlpm.a,'S4-3 Detective'!$C$20,IF(TRIM(_xlpm.a&"")="","",IF(OR(SUBSTITUTE(SUBSTITUTE(SUBSTITUTE(SUBSTITUTE(SUBSTITUTE(SUBSTITUTE(SUBSTITUTE(SUBSTITUTE(SUBSTITUTE(SUBSTITUTE(SUBSTITUTE(SUBSTITUTE(SUBSTITUTE(SUBSTITUTE(SUBSTITUTE(SUBSTITUTE(SUBSTITUTE(SUBSTITUTE(SUBSTITUTE(SUBSTITUTE(SUBSTITUTE(SUBSTITUTE(SUBSTITUTE(SUBSTITUTE(SUBSTITUTE(SUBSTITUTE(SUBSTITUTE(UPPER(_xlpm.a)," ",""),"CONTROL","CTRL"),"CTL","CTRL"),"ESCAPE","ESC"),"RETURN","ENTER"),"PAGEDOWN","PGDN"),"PGDOWN","PGDN"),"PAGEUP","PGUP"),"ARROWKEYS","ARROW"),"ARROWKEY","ARROW"),"ARROWS","ARROW"),"DOWNARROW","DOWN"),"UPARROW","UP"),"LEFTARROW","LEFT"),"RIGHTARROW","RIGHT"),"ARROWDOWN","DOWN"),"ARROWUP","UP"),"ARROWLEFT","LEFT"),"ARROWRIGHT","RIGHT"),"↓","DOWN"),"↑","UP"),"←","LEFT"),"→","RIGHT"),"SPACEBAR","SPACE"),"−","-"),"MINUS","-"),"PLUS","+")=Key!$E$61:$J$61),"✔ CLEAR","✘ TRY AGAIN"))),"✘ TRY AGAIN")} | F20: {=IF(E20="Show hint",Key!$B$61,"")} | G20: {=IF(LEFT(D20,1)="✔",IF(E20="Show hint",5,10),0)} -> 0
A21: W10 | B21: Which function returns the smallest value that meets conditions? (from F3-4 Extremes) | D21: {=IFERROR(_xlfn.LET(_xlpm.a,'S4-3 Detective'!$C$21,IF(TRIM(_xlpm.a&"")="","",IF(OR(SUBSTITUTE(SUBSTITUTE(SUBSTITUTE(SUBSTITUTE(SUBSTITUTE(SUBSTITUTE(SUBSTITUTE(SUBSTITUTE(SUBSTITUTE(SUBSTITUTE(SUBSTITUTE(SUBSTITUTE(SUBSTITUTE(SUBSTITUTE(SUBSTITUTE(SUBSTITUTE(SUBSTITUTE(SUBSTITUTE(SUBSTITUTE(SUBSTITUTE(SUBSTITUTE(SUBSTITUTE(SUBSTITUTE(SUBSTITUTE(SUBSTITUTE(SUBSTITUTE(SUBSTITUTE(UPPER(_xlpm.a)," ",""),"CONTROL","CTRL"),"CTL","CTRL"),"ESCAPE","ESC"),"RETURN","ENTER"),"PAGEDOWN","PGDN"),"PGDOWN","PGDN"),"PAGEUP","PGUP"),"ARROWKEYS","ARROW"),"ARROWKEY","ARROW"),"ARROWS","ARROW"),"DOWNARROW","DOWN"),"UPARROW","UP"),"LEFTARROW","LEFT"),"RIGHTARROW","RIGHT"),"ARROWDOWN","DOWN"),"ARROWUP","UP"),"ARROWLEFT","LEFT"),"ARROWRIGHT","RIGHT"),"↓","DOWN"),"↑","UP"),"←","LEFT"),"→","RIGHT"),"SPACEBAR","SPACE"),"−","-"),"MINUS","-"),"PLUS","+")=Key!$E$62:$J$62),"✔ CLEAR","✘ TRY AGAIN"))),"✘ TRY AGAIN")} | F21: {=IF(E21="Show hint",Key!$B$62,"")} | G21: {=IF(LEFT(D21,1)="✔",IF(E21="Show hint",5,10),0)} -> 0
A23: TRAINING · recognize the move (pick from the list)
A24: # | B24: Mission | C24: Your answer | D24: Result | E24: Hint? | F24: Hint | G24: XP
A25: T1 | B25: Which keys open Find? | D25: {=IFERROR(IF('S4-3 Detective'!$C$25&""="","",IF('S4-3 Detective'!$C$25&""=Key!$C$63&"","✔ CLEAR","✘ TRY AGAIN")),"✘ TRY AGAIN")} | F25: {=IF(E25="Show hint",Key!$B$63,"")} | G25: {=IF(LEFT(D25,1)="✔",IF(E25="Show hint",5,10),0)} -> 0
A26: T2 | B26: Which keys open Find and Replace on the Replace tab? | D26: {=IFERROR(IF('S4-3 Detective'!$C$26&""="","",IF('S4-3 Detective'!$C$26&""=Key!$C$64&"","✔ CLEAR","✘ TRY AGAIN")),"✘ TRY AGAIN")} | F26: {=IF(E26="Show hint",Key!$B$64,"")} | G26: {=IF(LEFT(D26,1)="✔",IF(E26="Show hint",5,10),0)} -> 0
A28: CHALLENGES · recall it, then do it
B29: ▶ Open S4-3 Arena (or press Ctrl+PgDn)
A30: # | B30: Mission | C30: Your answer | D30: Result | E30: Hint? | F30: Hint | G30: XP
A31: C1 | B31: Which keys open Find? | D31: {=IFERROR(_xlfn.LET(_xlpm.a,'S4-3 Detective'!$C$31,IF(TRIM(_xlpm.a&"")="","",IF(OR(SUBSTITUTE(SUBSTITUTE(SUBSTITUTE(SUBSTITUTE(SUBSTITUTE(SUBSTITUTE(SUBSTITUTE(SUBSTITUTE(SUBSTITUTE(SUBSTITUTE(SUBSTITUTE(SUBSTITUTE(SUBSTITUTE(SUBSTITUTE(SUBSTITUTE(SUBSTITUTE(SUBSTITUTE(SUBSTITUTE(SUBSTITUTE(SUBSTITUTE(SUBSTITUTE(SUBSTITUTE(SUBSTITUTE(SUBSTITUTE(SUBSTITUTE(SUBSTITUTE(SUBSTITUTE(UPPER(_xlpm.a)," ",""),"CONTROL","CTRL"),"CTL","CTRL"),"ESCAPE","ESC"),"RETURN","ENTER"),"PAGEDOWN","PGDN"),"PGDOWN","PGDN"),"PAGEUP","PGUP"),"ARROWKEYS","ARROW"),"ARROWKEY","ARROW"),"ARROWS","ARROW"),"DOWNARROW","DOWN"),"UPARROW","UP"),"LEFTARROW","LEFT"),"RIGHTARROW","RIGHT"),"ARROWDOWN","DOWN"),"ARROWUP","UP"),"ARROWLEFT","LEFT"),"ARROWRIGHT","RIGHT"),"↓","DOWN"),"↑","UP"),"←","LEFT"),"→","RIGHT"),"SPACEBAR","SPACE"),"−","-"),"MINUS","-"),"PLUS","+")=Key!$E$65:$E$65),"✔ CLEAR","✘ TRY AGAIN"))),"✘ TRY AGAIN")} | F31: {=IF(E31="Show hint",Key!$B$65,"")} | G31: {=IF(LEFT(D31,1)="✔",IF(E31="Show hint",5,10),0)} -> 0
A32: C2 | B32: Which keys open Find and Replace on the Replace tab? | D32: {=IFERROR(_xlfn.LET(_xlpm.a,'S4-3 Detective'!$C$32,IF(TRIM(_xlpm.a&"")="","",IF(OR(SUBSTITUTE(SUBSTITUTE(SUBSTITUTE(SUBSTITUTE(SUBSTITUTE(SUBSTITUTE(SUBSTITUTE(SUBSTITUTE(SUBSTITUTE(SUBSTITUTE(SUBSTITUTE(SUBSTITUTE(SUBSTITUTE(SUBSTITUTE(SUBSTITUTE(SUBSTITUTE(SUBSTITUTE(SUBSTITUTE(SUBSTITUTE(SUBSTITUTE(SUBSTITUTE(SUBSTITUTE(SUBSTITUTE(SUBSTITUTE(SUBSTITUTE(SUBSTITUTE(SUBSTITUTE(UPPER(_xlpm.a)," ",""),"CONTROL","CTRL"),"CTL","CTRL"),"ESCAPE","ESC"),"RETURN","ENTER"),"PAGEDOWN","PGDN"),"PGDOWN","PGDN"),"PAGEUP","PGUP"),"ARROWKEYS","ARROW"),"ARROWKEY","ARROW"),"ARROWS","ARROW"),"DOWNARROW","DOWN"),"UPARROW","UP"),"LEFTARROW","LEFT"),"RIGHTARROW","RIGHT"),"ARROWDOWN","DOWN"),"ARROWUP","UP"),"ARROWLEFT","LEFT"),"ARROWRIGHT","RIGHT"),"↓","DOWN"),"↑","UP"),"←","LEFT"),"→","RIGHT"),"SPACEBAR","SPACE"),"−","-"),"MINUS","-"),"PLUS","+")=Key!$E$66:$E$66),"✔ CLEAR","✘ TRY AGAIN"))),"✘ TRY AGAIN")} | F32: {=IF(E32="Show hint",Key!$B$66,"")} | G32: {=IF(LEFT(D32,1)="✔",IF(E32="Show hint",5,10),0)} -> 0
A33: C3 | B33: In the arena press Ctrl+F, search for Dragonfruit and press Enter. Type the Stock number in its row. | D33: {=IFERROR(_xlfn.LET(_xlpm.a,'S4-3 Detective'!$C$33,IF(TRIM(_xlpm.a&"")="","",IF(ABS(IF(ISNUMBER(_xlpm.a),_xlpm.a,VALUE(_xlpm.a&""))-Key!$C$67)<=1E-9*MAX(1,ABS(Key!$C$67)),"✔ CLEAR","✘ TRY AGAIN"))),"✘ TRY AGAIN")} | F33: {=IF(E33="Show hint",Key!$B$67,"")} | G33: {=IF(LEFT(D33,1)="✔",IF(E33="Show hint",5,10),0)} -> 0
A34: C4 | B34: Press Ctrl+H. Replace every N/A in the Note column with 0: Find what N/A, Replace with 0, then Replace All. | C34: ▶ ARENA C4 (cell F6) | D34: {=IF(IFERROR(AND(COUNTIF('S4-3 Arena'!$F$6:$F$305,"N/A")=0,COUNTIF('S4-3 Arena'!$F$6:$F$305,0)=33),FALSE),"✔ CLEAR","· not yet")} -> · not yet | F34: {=IF(E34="Show hint",Key!$B$68,"")} | G34: {=IF(LEFT(D34,1)="✔",IF(E34="Show hint",5,10),0)} -> 0
A35: C5 | B35: Press Ctrl+F, type Gadget and click Find All. The dialog reports how many cells were found. Type that number. | D35: {=IFERROR(_xlfn.LET(_xlpm.a,'S4-3 Detective'!$C$35,IF(TRIM(_xlpm.a&"")="","",IF(ABS(IF(ISNUMBER(_xlpm.a),_xlpm.a,VALUE(_xlpm.a&""))-Key!$C$69)<=1E-9*MAX(1,ABS(Key!$C$69)),"✔ CLEAR","✘ TRY AGAIN"))),"✘ TRY AGAIN")} | F35: {=IF(E35="Show hint",Key!$B$69,"")} | G35: {=IF(LEFT(D35,1)="✔",IF(E35="Show hint",5,10),0)} -> 0

Sheet S4-3 Arena
A1: ARENA ▸ S4-3 DETECTIVE
A2: Practice area · everything here is editable. Missions and their checks are on the stage sheet.
A3: PASS CODE | B3: SLEUTH | D3: ◀ Back to S4-3 Detective
B5: SKU | C5: Product | D5: Category | E5: Stock | F5: Note
B6: SKU-1000 | C6: Apple | D6: Food | E6: 5 | F6: Check
B7: SKU-1001 | C7: Kiwi | D7: Food | E7: 18 | F7: OK
B8: SKU-1002 | C8: Quince | D8: Food | E8: 31 | F8: Check
B9: SKU-1003 | C9: Gizmo | D9: Tech | E9: 44 | F9: OK
B10: SKU-1004 | C10: Pear | D10: Food | E10: 57 | F10: N/A
B11: SKU-1005 | C11: Widget | D11: Tech | E11: 70 | F11: OK
B12: SKU-1006 | C12: Olive | D12: Food | E12: 83 | F12: Check
B13: SKU-1007 | C13: Mini Gadget | D13: Tech | E13: 6 | F13: OK
B14: SKU-1008 | C14: Nut Mix | D14: Food | E14: 19 | F14: Check
B15: SKU-1009 | C15: Gadget Pro | D15: Tech | E15: 32 | F15: OK
B16: SKU-1010 | C16: Gadget Max | D16: Tech | E16: 45 | F16: Check
B17: SKU-1011 | C17: Cherry | D17: Food | E17: 58 | F17: OK
... B305: SKU-1299 | C305: Lemon | D305: Food | E305: 22 | F305: OK

Sheet S4-4 Data Wrangler
A1: STAGE S4-4 ▸ DATA WRANGLER
