Workbook

Sheet Start
A1: FORMULAS 4 ▸ LOOKUPS
A2: Find a value in one column and bring back its partner from another.
A4: HOW TO PLAY
A5: 1 · Each stage: read the BRIEFING, then answer WARM-UP, TRAINING and CHALLENGES.
A6: 2 · Yellow cells are yours: type, pick from a list (Alt+↓), or follow a ▶ ARENA link and do the move there.
A7: 3 · ✔ CLEAR = right · ✘ = try again · · not yet = drill not done. Stuck? Pick 'Show hint' (5 XP instead of 10).
A8: 4 · Formatting or hiding drills: press F9 to refresh the check. Tab jumps between yellow cells.
A9: Needs Windows with Microsoft Excel 365 or 2021+ (English). In Protected View, click Enable Editing.
A11: STAGE SELECT
A12: Stage | B12: Name | C12: Score | D12: Stars | E12: Status | F12: Go
A13: F4-1 | B13: Seeker | C13: {=SUM('F4-1 Seeker'!$G$12:$G$34)&" / 160"} -> 0 / 160 | D13: {=IF(SUM('F4-1 Seeker'!$G$12:$G$34)>=160,"★★★",IF(SUM('F4-1 Seeker'!$G$12:$G$34)>=160*0.8,"★★☆",IF(SUM('F4-1 Seeker'!$G$12:$G$34)>=160*0.5,"★☆☆","☆☆☆")))} -> ☆☆☆ | E13: {=IF(SUM('F4-1 Seeker'!$G$12:$G$34)>=160,"PERFECT",IF(SUM('F4-1 Seeker'!$G$12:$G$34)>=160*0.5,"CLEARED",IF(SUM('F4-1 Seeker'!$G$12:$G$34)>0,"IN PROGRESS","NEW")))} -> NEW | F13: Go to F4-1 Seeker
A14: F4-2 | B14: Safety Net | C14: {=SUM('F4-2 Safety Net'!$G$12:$G$34)&" / 160"} -> 0 / 160 | D14: {=IF(SUM('F4-2 Safety Net'!$G$12:$G$34)>=160,"★★★",IF(SUM('F4-2 Safety Net'!$G$12:$G$34)>=160*0.8,"★★☆",IF(SUM('F4-2 Safety Net'!$G$12:$G$34)>=160*0.5,"★☆☆","☆☆☆")))} -> ☆☆☆ | E14: {=IF(SUM('F4-2 Safety Net'!$G$12:$G$34)>=160,"PERFECT",IF(SUM('F4-2 Safety Net'!$G$12:$G$34)>=160*0.5,"CLEARED",IF(SUM('F4-2 Safety Net'!$G$12:$G$34)>0,"IN PROGRESS","NEW")))} -> NEW | F14: Go to F4-2 Safety Net
A15: F4-3 | B15: Old School | C15: {=SUM('F4-3 Old School'!$G$12:$G$34)&" / 160"} -> 0 / 160 | D15: {=IF(SUM('F4-3 Old School'!$G$12:$G$34)>=160,"★★★",IF(SUM('F4-3 Old School'!$G$12:$G$34)>=160*0.8,"★★☆",IF(SUM('F4-3 Old School'!$G$12:$G$34)>=160*0.5,"★☆☆","☆☆☆")))} -> ☆☆☆ | E15: {=IF(SUM('F4-3 Old School'!$G$12:$G$34)>=160,"PERFECT",IF(SUM('F4-3 Old School'!$G$12:$G$34)>=160*0.5,"CLEARED",IF(SUM('F4-3 Old School'!$G$12:$G$34)>0,"IN PROGRESS","NEW")))} -> NEW | F15: Go to F4-3 Old School
A16: F4-4 | B16: Power Couple | C16: {=SUM('F4-4 Power Couple'!$G$14:$G$42)&" / 220"} -> 0 / 220 | D16: {=IF(SUM('F4-4 Power Couple'!$G$14:$G$42)>=220,"★★★",IF(SUM('F4-4 Power Couple'!$G$14:$G$42)>=220*0.8,"★★☆",IF(SUM('F4-4 Power Couple'!$G$14:$G$42)>=220*0.5,"★☆☆","☆☆☆")))} -> ☆☆☆ | E16: {=IF(SUM('F4-4 Power Couple'!$G$14:$G$42)>=220,"PERFECT",IF(SUM('F4-4 Power Couple'!$G$14:$G$42)>=220*0.5,"CLEARED",IF(SUM('F4-4 Power Couple'!$G$14:$G$42)>0,"IN PROGRESS","NEW")))} -> NEW | F16: Go to F4-4 Power Couple
A17: F4-5 | B17: Tiers | C17: {=SUM('F4-5 Tiers'!$G$12:$G$34)&" / 160"} -> 0 / 160 | D17: {=IF(SUM('F4-5 Tiers'!$G$12:$G$34)>=160,"★★★",IF(SUM('F4-5 Tiers'!$G$12:$G$34)>=160*0.8,"★★☆",IF(SUM('F4-5 Tiers'!$G$12:$G$34)>=160*0.5,"★☆☆","☆☆☆")))} -> ☆☆☆ | E17: {=IF(SUM('F4-5 Tiers'!$G$12:$G$34)>=160,"PERFECT",IF(SUM('F4-5 Tiers'!$G$12:$G$34)>=160*0.5,"CLEARED",IF(SUM('F4-5 Tiers'!$G$12:$G$34)>0,"IN PROGRESS","NEW")))} -> NEW | F17: Go to F4-5 Tiers
A18: BOSS | B18: Boss | C18: {=SUM(Boss!$G$14:$G$33)&" / 160"} -> 0 / 160 | D18: {=IF(SUM(Boss!$G$14:$G$33)>=160,"★★★",IF(SUM(Boss!$G$14:$G$33)>=160*0.8,"★★☆",IF(SUM(Boss!$G$14:$G$33)>=160*0.5,"★☆☆","☆☆☆")))} -> ☆☆☆ | E18: {=IF(Boss!$C$10="OPEN",IF(SUM(Boss!$G$14:$G$33)>=160*0.5,"DEFEATED","OPEN"),"LOCKED")} -> LOCKED | F18: Go to the Boss
A20: TOTAL SCORE | B20: {=(SUM('F4-1 Seeker'!$G$12:$G$34)+SUM('F4-2 Safety Net'!$G$12:$G$34)+SUM('F4-3 Old School'!$G$12:$G$34)+SUM('F4-4 Power Couple'!$G$14:$G$42)+SUM('F4-5 Tiers'!$G$12:$G$34)+SUM(Boss!$G$14:$G$33))&" / 1020"} -> 0 / 1020
A21: RANK | B21: {=_xlfn.LET(_xlpm.p,(SUM('F4-1 Seeker'!$G$12:$G$34)+SUM('F4-2 Safety Net'!$G$12:$G$34)+SUM('F4-3 Old School'!$G$12:$G$34)+SUM('F4-4 Power Couple'!$G$14:$G$42)+SUM('F4-5 Tiers'!$G$12:$G$34)+SUM(Boss!$G$14:$G$33))/1020,IF(AND(_xlpm.p>=1,ISNUMBER(Boss!$C$8),Boss!$C$8<=15),"S",IF(_xlpm.p>=0.9,"A",IF(_xlpm.p>=0.75,"B",IF(_xlpm.p>=0.5,"C","D")))))} -> D | C21: S = 100% and under par · A ≥ 90% · B ≥ 75% · C ≥ 50%
A22: BEST TIME | B22: {=IF(ISNUMBER(Boss!$C$8),Boss!$C$8&" min (par 15)","—")} -> —
A23: NEXT UP | B23: {=IFERROR(INDEX($A$13:$A$17,MATCH("☆☆☆",$D$13:$D$17,0))&" "&INDEX($B$13:$B$17,MATCH("☆☆☆",$D$13:$D$17,0)),IF(Boss!$C$10="OPEN","the Boss","All clear! Aim for rank S"))} -> F4-1 Seeker
A25: Replay a stage: select its yellow answer cells and press Delete. Undo an arena drill with Ctrl+Z.

Sheet F4-1 Seeker
A1: STAGE F4-1 ▸ SEEKER
A2: Goal: look up a value and bring back its partner
A3: {="SCORE "&TEXT(SUM($G$12:$G$34),"0000")&" / 0160"} -> SCORE 0000 / 0160 | C3: {=IF(SUM($G$12:$G$34)>=160,"★★★",IF(SUM($G$12:$G$34)>=160*0.8,"★★☆",IF(SUM($G$12:$G$34)>=160*0.5,"★☆☆","☆☆☆")))} -> ☆☆☆ | D3: {=REPT("█",ROUND(10*SUM($G$12:$G$34)/160,0))&REPT("░",10-ROUND(10*SUM($G$12:$G$34)/160,0))&" "&TEXT(SUM($G$12:$G$34)/160,"0%")} -> ░░░░░░░░░░ 0% | F3: {=IF(SUM($G$12:$G$34)>=160*0.5,"STAGE CLEAR! ▶ Next: F4-2 Safety Net","")}
A5: BRIEFING · new moves in this stage
A6: # | B6: What it does · Pro tip | C6: Keys / Syntax
A7: 1 | B7: XLOOKUP(lookup_value, lookup_array, return_array) finds a match and returns its partner. Tip: Works left or right, exact match by default. | C7: XLOOKUP
A8: 2 | B8: Lock lookup ranges with $ before you fill the formula down. Tip: Otherwise the ranges slide down and miss rows. | C8: $B$6:$B$20
A10: WARM-UP · flashback to earlier stages
A11: # | B11: Mission | C11: Your answer | D11: Result | E11: Hint? | F11: Hint | G11: XP
A12: W1 | B12: Which keys hide the selected rows? (from S4-1 Construction Crew) | D12: {=IFERROR(_xlfn.LET(_xlpm.a,'F4-1 Seeker'!$C$12,IF(TRIM(_xlpm.a&"")="","",IF(OR(SUBSTITUTE(SUBSTITUTE(SUBSTITUTE(SUBSTITUTE(SUBSTITUTE(SUBSTITUTE(SUBSTITUTE(SUBSTITUTE(SUBSTITUTE(SUBSTITUTE(SUBSTITUTE(SUBSTITUTE(SUBSTITUTE(SUBSTITUTE(SUBSTITUTE(SUBSTITUTE(SUBSTITUTE(SUBSTITUTE(SUBSTITUTE(SUBSTITUTE(SUBSTITUTE(SUBSTITUTE(SUBSTITUTE(SUBSTITUTE(SUBSTITUTE(SUBSTITUTE(SUBSTITUTE(UPPER(_xlpm.a)," ",""),"CONTROL","CTRL"),"CTL","CTRL"),"ESCAPE","ESC"),"RETURN","ENTER"),"PAGEDOWN","PGDN"),"PGDOWN","PGDN"),"PAGEUP","PGUP"),"ARROWKEYS","ARROW"),"ARROWKEY","ARROW"),"ARROWS","ARROW"),"DOWNARROW","DOWN"),"UPARROW","UP"),"LEFTARROW","LEFT"),"RIGHTARROW","RIGHT"),"ARROWDOWN","DOWN"),"ARROWUP","UP"),"ARROWLEFT","LEFT"),"ARROWRIGHT","RIGHT"),"↓","DOWN"),"↑","UP"),"←","LEFT"),"→","RIGHT"),"SPACEBAR","SPACE"),"−","-"),"MINUS","-"),"PLUS","+")=Key!$E$2:$E$2),"✔ CLEAR","✘ TRY AGAIN"))),"✘ TRY AGAIN")} | F12: {=IF(E12="Show hint",Key!$B$2,"")} | G12: {=IF(LEFT(D12,1)="✔",IF(E12="Show hint",5,10),0)} -> 0
A13: W2 | B13: Which keys hide the selected columns? (from S4-1 Construction Crew) | D13: {=IFERROR(_xlfn.LET(_xlpm.a,'F4-1 Seeker'!$C$13,IF(TRIM(_xlpm.a&"")="","",IF(OR(SUBSTITUTE(SUBSTITUTE(SUBSTITUTE(SUBSTITUTE(SUBSTITUTE(SUBSTITUTE(SUBSTITUTE(SUBSTITUTE(SUBSTITUTE(SUBSTITUTE(SUBSTITUTE(SUBSTITUTE(SUBSTITUTE(SUBSTITUTE(SUBSTITUTE(SUBSTITUTE(SUBSTITUTE(SUBSTITUTE(SUBSTITUTE(SUBSTITUTE(SUBSTITUTE(SUBSTITUTE(SUBSTITUTE(SUBSTITUTE(SUBSTITUTE(SUBSTITUTE(SUBSTITUTE(UPPER(_xlpm.a)," ",""),"CONTROL","CTRL"),"CTL","CTRL"),"ESCAPE","ESC"),"RETURN","ENTER"),"PAGEDOWN","PGDN"),"PGDOWN","PGDN"),"PAGEUP","PGUP"),"ARROWKEYS","ARROW"),"ARROWKEY","ARROW"),"ARROWS","ARROW"),"DOWNARROW","DOWN"),"UPARROW","UP"),"LEFTARROW","LEFT"),"RIGHTARROW","RIGHT"),"ARROWDOWN","DOWN"),"ARROWUP","UP"),"ARROWLEFT","LEFT"),"ARROWRIGHT","RIGHT"),"↓","DOWN"),"↑","UP"),"←","LEFT"),"→","RIGHT"),"SPACEBAR","SPACE"),"−","-"),"MINUS","-"),"PLUS","+")=Key!$E$3:$E$3),"✔ CLEAR","✘ TRY AGAIN"))),"✘ TRY AGAIN")} | F13: {=IF(E13="Show hint",Key!$B$3,"")} | G13: {=IF(LEFT(D13,1)="✔",IF(E13="Show hint",5,10),0)} -> 0
A14: W3 | B14: Which keys insert a new worksheet? (from S4-2 Sheet Master) | D14: {=IFERROR(_xlfn.LET(_xlpm.a,'F4-1 Seeker'!$C$14,IF(TRIM(_xlpm.a&"")="","",IF(OR(SUBSTITUTE(SUBSTITUTE(SUBSTITUTE(SUBSTITUTE(SUBSTITUTE(SUBSTITUTE(SUBSTITUTE(SUBSTITUTE(SUBSTITUTE(SUBSTITUTE(SUBSTITUTE(SUBSTITUTE(SUBSTITUTE(SUBSTITUTE(SUBSTITUTE(SUBSTITUTE(SUBSTITUTE(SUBSTITUTE(SUBSTITUTE(SUBSTITUTE(SUBSTITUTE(SUBSTITUTE(SUBSTITUTE(SUBSTITUTE(SUBSTITUTE(SUBSTITUTE(SUBSTITUTE(UPPER(_xlpm.a)," ",""),"CONTROL","CTRL"),"CTL","CTRL"),"ESCAPE","ESC"),"RETURN","ENTER"),"PAGEDOWN","PGDN"),"PGDOWN","PGDN"),"PAGEUP","PGUP"),"ARROWKEYS","ARROW"),"ARROWKEY","ARROW"),"ARROWS","ARROW"),"DOWNARROW","DOWN"),"UPARROW","UP"),"LEFTARROW","LEFT"),"RIGHTARROW","RIGHT"),"ARROWDOWN","DOWN"),"ARROWUP","UP"),"ARROWLEFT","LEFT"),"ARROWRIGHT","RIGHT"),"↓","DOWN"),"↑","UP"),"←","LEFT"),"→","RIGHT"),"SPACEBAR","SPACE"),"−","-"),"MINUS","-"),"PLUS","+")=Key!$E$4:$G$4),"✔ CLEAR","✘ TRY AGAIN"))),"✘ TRY AGAIN")} | F14: {=IF(E14="Show hint",Key!$B$4,"")} | G14: {=IF(LEFT(D14,1)="✔",IF(E14="Show hint",5,10),0)} -> 0
A15: W4 | B15: Which KeyTips rename the current sheet? (from S4-2 Sheet Master) | D15: {=IFERROR(_xlfn.LET(_xlpm.a,'F4-1 Seeker'!$C$15,IF(TRIM(_xlpm.a&"")="","",IF(OR(SUBSTITUTE(SUBSTITUTE(SUBSTITUTE(SUBSTITUTE(SUBSTITUTE(SUBSTITUTE(SUBSTITUTE(SUBSTITUTE(SUBSTITUTE(SUBSTITUTE(SUBSTITUTE(SUBSTITUTE(SUBSTITUTE(SUBSTITUTE(SUBSTITUTE(SUBSTITUTE(SUBSTITUTE(SUBSTITUTE(SUBSTITUTE(SUBSTITUTE(SUBSTITUTE(SUBSTITUTE(SUBSTITUTE(SUBSTITUTE(SUBSTITUTE(SUBSTITUTE(SUBSTITUTE(UPPER(_xlpm.a)," ",""),"CONTROL","CTRL"),"CTL","CTRL"),"ESCAPE","ESC"),"RETURN","ENTER"),"PAGEDOWN","PGDN"),"PGDOWN","PGDN"),"PAGEUP","PGUP"),"ARROWKEYS","ARROW"),"ARROWKEY","ARROW"),"ARROWS","ARROW"),"DOWNARROW","DOWN"),"UPARROW","UP"),"LEFTARROW","LEFT"),"RIGHTARROW","RIGHT"),"ARROWDOWN","DOWN"),"ARROWUP","UP"),"ARROWLEFT","LEFT"),"ARROWRIGHT","RIGHT"),"↓","DOWN"),"↑","UP"),"←","LEFT"),"→","RIGHT"),"SPACEBAR","SPACE"),"−","-"),"MINUS","-"),"PLUS","+")=Key!$E$5:$T$5),"✔ CLEAR","✘ TRY AGAIN"))),"✘ TRY AGAIN")} | F15: {=IF(E15="Show hint",Key!$B$5,"")} | G15: {=IF(LEFT(D15,1)="✔",IF(E15="Show hint",5,10),0)} -> 0
A16: W5 | B16: Which keys save the workbook? (from S4-2 Sheet Master) | D16: {=IFERROR(_xlfn.LET(_xlpm.a,'F4-1 Seeker'!$C$16,IF(TRIM(_xlpm.a&"")="","",IF(OR(SUBSTITUTE(SUBSTITUTE(SUBSTITUTE(SUBSTITUTE(SUBSTITUTE(SUBSTITUTE(SUBSTITUTE(SUBSTITUTE(SUBSTITUTE(SUBSTITUTE(SUBSTITUTE(SUBSTITUTE(SUBSTITUTE(SUBSTITUTE(SUBSTITUTE(SUBSTITUTE(SUBSTITUTE(SUBSTITUTE(SUBSTITUTE(SUBSTITUTE(SUBSTITUTE(SUBSTITUTE(SUBSTITUTE(SUBSTITUTE(SUBSTITUTE(SUBSTITUTE(SUBSTITUTE(UPPER(_xlpm.a)," ",""),"CONTROL","CTRL"),"CTL","CTRL"),"ESCAPE","ESC"),"RETURN","ENTER"),"PAGEDOWN","PGDN"),"PGDOWN","PGDN"),"PAGEUP","PGUP"),"ARROWKEYS","ARROW"),"ARROWKEY","ARROW"),"ARROWS","ARROW"),"DOWNARROW","DOWN"),"UPARROW","UP"),"LEFTARROW","LEFT"),"RIGHTARROW","RIGHT"),"ARROWDOWN","DOWN"),"ARROWUP","UP"),"ARROWLEFT","LEFT"),"ARROWRIGHT","RIGHT"),"↓","DOWN"),"↑","UP"),"←","LEFT"),"→","RIGHT"),"SPACEBAR","SPACE"),"−","-"),"MINUS","-"),"PLUS","+")=Key!$E$6:$E$6),"✔ CLEAR","✘ TRY AGAIN"))),"✘ TRY AGAIN")} | F16: {=IF(E16="Show hint",Key!$B$6,"")} | G16: {=IF(LEFT(D16,1)="✔",IF(E16="Show hint",5,10),0)} -> 0
A17: W6 | B17: Which key opens Save As? (from S4-2 Sheet Master) | D17: {=IFERROR(_xlfn.LET(_xlpm.a,'F4-1 Seeker'!$C$17,IF(TRIM(_xlpm.a&"")="","",IF(OR(SUBSTITUTE(SUBSTITUTE(SUBSTITUTE(SUBSTITUTE(SUBSTITUTE(SUBSTITUTE(SUBSTITUTE(SUBSTITUTE(SUBSTITUTE(SUBSTITUTE(SUBSTITUTE(SUBSTITUTE(SUBSTITUTE(SUBSTITUTE(SUBSTITUTE(SUBSTITUTE(SUBSTITUTE(SUBSTITUTE(SUBSTITUTE(SUBSTITUTE(SUBSTITUTE(SUBSTITUTE(SUBSTITUTE(SUBSTITUTE(SUBSTITUTE(SUBSTITUTE(SUBSTITUTE(UPPER(_xlpm.a)," ",""),"CONTROL","CTRL"),"CTL","CTRL"),"ESCAPE","ESC"),"RETURN","ENTER"),"PAGEDOWN","PGDN"),"PGDOWN","PGDN"),"PAGEUP","PGUP"),"ARROWKEYS","ARROW"),"ARROWKEY","ARROW"),"ARROWS","ARROW"),"DOWNARROW","DOWN"),"UPARROW","UP"),"LEFTARROW","LEFT"),"RIGHTARROW","RIGHT"),"ARROWDOWN","DOWN"),"ARROWUP","UP"),"ARROWLEFT","LEFT"),"ARROWRIGHT","RIGHT"),"↓","DOWN"),"↑","UP"),"←","LEFT"),"→","RIGHT"),"SPACEBAR","SPACE"),"−","-"),"MINUS","-"),"PLUS","+")=Key!$E$7:$E$7),"✔ CLEAR","✘ TRY AGAIN"))),"✘ TRY AGAIN")} | F17: {=IF(E17="Show hint",Key!$B$7,"")} | G17: {=IF(LEFT(D17,1)="✔",IF(E17="Show hint",5,10),0)} -> 0
A18: W7 | B18: Which keys create a new blank workbook? (from S4-2 Sheet Master) | D18: {=IFERROR(_xlfn.LET(_xlpm.a,'F4-1 Seeker'!$C$18,IF(TRIM(_xlpm.a&"")="","",IF(OR(SUBSTITUTE(SUBSTITUTE(SUBSTITUTE(SUBSTITUTE(SUBSTITUTE(SUBSTITUTE(SUBSTITUTE(SUBSTITUTE(SUBSTITUTE(SUBSTITUTE(SUBSTITUTE(SUBSTITUTE(SUBSTITUTE(SUBSTITUTE(SUBSTITUTE(SUBSTITUTE(SUBSTITUTE(SUBSTITUTE(SUBSTITUTE(SUBSTITUTE(SUBSTITUTE(SUBSTITUTE(SUBSTITUTE(SUBSTITUTE(SUBSTITUTE(SUBSTITUTE(SUBSTITUTE(UPPER(_xlpm.a)," ",""),"CONTROL","CTRL"),"CTL","CTRL"),"ESCAPE","ESC"),"RETURN","ENTER"),"PAGEDOWN","PGDN"),"PGDOWN","PGDN"),"PAGEUP","PGUP"),"ARROWKEYS","ARROW"),"ARROWKEY","ARROW"),"ARROWS","ARROW"),"DOWNARROW","DOWN"),"UPARROW","UP"),"LEFTARROW","LEFT"),"RIGHTARROW","RIGHT"),"ARROWDOWN","DOWN"),"ARROWUP","UP"),"ARROWLEFT","LEFT"),"ARROWRIGHT","RIGHT"),"↓","DOWN"),"↑","UP"),"←","LEFT"),"→","RIGHT"),"SPACEBAR","SPACE"),"−","-"),"MINUS","-"),"PLUS","+")=Key!$E$8:$E$8),"✔ CLEAR","✘ TRY AGAIN"))),"✘ TRY AGAIN")} | F18: {=IF(E18="Show hint",Key!$B$8,"")} | G18: {=IF(LEFT(D18,1)="✔",IF(E18="Show hint",5,10),0)} -> 0
A19: W8 | B19: Which keys open a workbook? (from S4-2 Sheet Master) | D19: {=IFERROR(_xlfn.LET(_xlpm.a,'F4-1 Seeker'!$C$19,IF(TRIM(_xlpm.a&"")="","",IF(OR(SUBSTITUTE(SUBSTITUTE(SUBSTITUTE(SUBSTITUTE(SUBSTITUTE(SUBSTITUTE(SUBSTITUTE(SUBSTITUTE(SUBSTITUTE(SUBSTITUTE(SUBSTITUTE(SUBSTITUTE(SUBSTITUTE(SUBSTITUTE(SUBSTITUTE(SUBSTITUTE(SUBSTITUTE(SUBSTITUTE(SUBSTITUTE(SUBSTITUTE(SUBSTITUTE(SUBSTITUTE(SUBSTITUTE(SUBSTITUTE(SUBSTITUTE(SUBSTITUTE(SUBSTITUTE(UPPER(_xlpm.a)," ",""),"CONTROL","CTRL"),"CTL","CTRL"),"ESCAPE","ESC"),"RETURN","ENTER"),"PAGEDOWN","PGDN"),"PGDOWN","PGDN"),"PAGEUP","PGUP"),"ARROWKEYS","ARROW"),"ARROWKEY","ARROW"),"ARROWS","ARROW"),"DOWNARROW","DOWN"),"UPARROW","UP"),"LEFTARROW","LEFT"),"RIGHTARROW","RIGHT"),"ARROWDOWN","DOWN"),"ARROWUP","UP"),"ARROWLEFT","LEFT"),"ARROWRIGHT","RIGHT"),"↓","DOWN"),"↑","UP"),"←","LEFT"),"→","RIGHT"),"SPACEBAR","SPACE"),"−","-"),"MINUS","-"),"PLUS","+")=Key!$E$9:$E$9),"✔ CLEAR","✘ TRY AGAIN"))),"✘ TRY AGAIN")} | F19: {=IF(E19="Show hint",Key!$B$9,"")} | G19: {=IF(LEFT(D19,1)="✔",IF(E19="Show hint",5,10),0)} -> 0
A20: W9 | B20: Which keys close the current workbook? (from S4-2 Sheet Master) | D20: {=IFERROR(_xlfn.LET(_xlpm.a,'F4-1 Seeker'!$C$20,IF(TRIM(_xlpm.a&"")="","",IF(OR(SUBSTITUTE(SUBSTITUTE(SUBSTITUTE(SUBSTITUTE(SUBSTITUTE(SUBSTITUTE(SUBSTITUTE(SUBSTITUTE(SUBSTITUTE(SUBSTITUTE(SUBSTITUTE(SUBSTITUTE(SUBSTITUTE(SUBSTITUTE(SUBSTITUTE(SUBSTITUTE(SUBSTITUTE(SUBSTITUTE(SUBSTITUTE(SUBSTITUTE(SUBSTITUTE(SUBSTITUTE(SUBSTITUTE(SUBSTITUTE(SUBSTITUTE(SUBSTITUTE(SUBSTITUTE(UPPER(_xlpm.a)," ",""),"CONTROL","CTRL"),"CTL","CTRL"),"ESCAPE","ESC"),"RETURN","ENTER"),"PAGEDOWN","PGDN"),"PGDOWN","PGDN"),"PAGEUP","PGUP"),"ARROWKEYS","ARROW"),"ARROWKEY","ARROW"),"ARROWS","ARROW"),"DOWNARROW","DOWN"),"UPARROW","UP"),"LEFTARROW","LEFT"),"RIGHTARROW","RIGHT"),"ARROWDOWN","DOWN"),"ARROWUP","UP"),"ARROWLEFT","LEFT"),"ARROWRIGHT","RIGHT"),"↓","DOWN"),"↑","UP"),"←","LEFT"),"→","RIGHT"),"SPACEBAR","SPACE"),"−","-"),"MINUS","-"),"PLUS","+")=Key!$E$10:$E$10),"✔ CLEAR","✘ TRY AGAIN"))),"✘ TRY AGAIN")} | F20: {=IF(E20="Show hint",Key!$B$10,"")} | G20: {=IF(LEFT(D20,1)="✔",IF(E20="Show hint",5,10),0)} -> 0
A21: W10 | B21: Which keys open Print? (from S4-2 Sheet Master) | D21: {=IFERROR(_xlfn.LET(_xlpm.a,'F4-1 Seeker'!$C$21,IF(TRIM(_xlpm.a&"")="","",IF(OR(SUBSTITUTE(SUBSTITUTE(SUBSTITUTE(SUBSTITUTE(SUBSTITUTE(SUBSTITUTE(SUBSTITUTE(SUBSTITUTE(SUBSTITUTE(SUBSTITUTE(SUBSTITUTE(SUBSTITUTE(SUBSTITUTE(SUBSTITUTE(SUBSTITUTE(SUBSTITUTE(SUBSTITUTE(SUBSTITUTE(SUBSTITUTE(SUBSTITUTE(SUBSTITUTE(SUBSTITUTE(SUBSTITUTE(SUBSTITUTE(SUBSTITUTE(SUBSTITUTE(SUBSTITUTE(UPPER(_xlpm.a)," ",""),"CONTROL","CTRL"),"CTL","CTRL"),"ESCAPE","ESC"),"RETURN","ENTER"),"PAGEDOWN","PGDN"),"PGDOWN","PGDN"),"PAGEUP","PGUP"),"ARROWKEYS","ARROW"),"ARROWKEY","ARROW"),"ARROWS","ARROW"),"DOWNARROW","DOWN"),"UPARROW","UP"),"LEFTARROW","LEFT"),"RIGHTARROW","RIGHT"),"ARROWDOWN","DOWN"),"ARROWUP","UP"),"ARROWLEFT","LEFT"),"ARROWRIGHT","RIGHT"),"↓","DOWN"),"↑","UP"),"←","LEFT"),"→","RIGHT"),"SPACEBAR","SPACE"),"−","-"),"MINUS","-"),"PLUS","+")=Key!$E$11:$E$11),"✔ CLEAR","✘ TRY AGAIN"))),"✘ TRY AGAIN")} | F21: {=IF(E21="Show hint",Key!$B$11,"")} | G21: {=IF(LEFT(D21,1)="✔",IF(E21="Show hint",5,10),0)} -> 0
A23: TRAINING · recognize the move (pick from the list)
A24: # | B24: Mission | C24: Your answer | D24: Result | E24: Hint? | F24: Hint | G24: XP
A25: T1 | B25: Which modern function finds a value and returns the matching item from another column? | D25: {=IFERROR(IF('F4-1 Seeker'!$C$25&""="","",IF('F4-1 Seeker'!$C$25&""=Key!$C$12&"","✔ CLEAR","✘ TRY AGAIN")),"✘ TRY AGAIN")} | F25: {=IF(E25="Show hint",Key!$B$12,"")} | G25: {=IF(LEFT(D25,1)="✔",IF(E25="Show hint",5,10),0)} -> 0
A26: T2 | B26: Which symbol locks a range so it doesn't shift when you fill down? | D26: {=IFERROR(IF('F4-1 Seeker'!$C$26&""="","",IF('F4-1 Seeker'!$C$26&""=Key!$C$13&"","✔ CLEAR","✘ TRY AGAIN")),"✘ TRY AGAIN")} | F26: {=IF(E26="Show hint",Key!$B$13,"")} | G26: {=IF(LEFT(D26,1)="✔",IF(E26="Show hint",5,10),0)} -> 0
A28: CHALLENGES · recall it, then do it
B29: ▶ Open F4-1 Arena (or press Ctrl+PgDn)
A30: # | B30: Mission | C30: Your answer | D30: Result | E30: Hint? | F30: Hint | G30: XP
A31: C1 | B31: Which modern function finds a value and returns the matching item from another column? | D31: {=IFERROR(_xlfn.LET(_xlpm.a,'F4-1 Seeker'!$C$31,IF(TRIM(_xlpm.a&"")="","",IF(OR(SUBSTITUTE(SUBSTITUTE(SUBSTITUTE(SUBSTITUTE(SUBSTITUTE(SUBSTITUTE(SUBSTITUTE(SUBSTITUTE(SUBSTITUTE(SUBSTITUTE(SUBSTITUTE(SUBSTITUTE(SUBSTITUTE(SUBSTITUTE(SUBSTITUTE(SUBSTITUTE(SUBSTITUTE(SUBSTITUTE(SUBSTITUTE(SUBSTITUTE(SUBSTITUTE(SUBSTITUTE(SUBSTITUTE(SUBSTITUTE(SUBSTITUTE(SUBSTITUTE(SUBSTITUTE(UPPER(_xlpm.a)," ",""),"CONTROL","CTRL"),"CTL","CTRL"),"ESCAPE","ESC"),"RETURN","ENTER"),"PAGEDOWN","PGDN"),"PGDOWN","PGDN"),"PAGEUP","PGUP"),"ARROWKEYS","ARROW"),"ARROWKEY","ARROW"),"ARROWS","ARROW"),"DOWNARROW","DOWN"),"UPARROW","UP"),"LEFTARROW","LEFT"),"RIGHTARROW","RIGHT"),"ARROWDOWN","DOWN"),"ARROWUP","UP"),"ARROWLEFT","LEFT"),"ARROWRIGHT","RIGHT"),"↓","DOWN"),"↑","UP"),"←","LEFT"),"→","RIGHT"),"SPACEBAR","SPACE"),"−","-"),"MINUS","-"),"PLUS","+")=Key!$E$14:$J$14),"✔ CLEAR","✘ TRY AGAIN"))),"✘ TRY AGAIN")} | F31: {=IF(E31="Show hint",Key!$B$14,"")} | G31: {=IF(LEFT(D31,1)="✔",IF(E31="Show hint",5,10),0)} -> 0
A32: C2 | B32: Which symbol locks a range so it doesn't shift when you fill down? | D32: {=IFERROR(_xlfn.LET(_xlpm.a,'F4-1 Seeker'!$C$32,IF(TRIM(_xlpm.a&"")="","",IF(OR(SUBSTITUTE(SUBSTITUTE(SUBSTITUTE(SUBSTITUTE(SUBSTITUTE(SUBSTITUTE(SUBSTITUTE(SUBSTITUTE(SUBSTITUTE(SUBSTITUTE(SUBSTITUTE(SUBSTITUTE(SUBSTITUTE(SUBSTITUTE(SUBSTITUTE(SUBSTITUTE(SUBSTITUTE(SUBSTITUTE(SUBSTITUTE(SUBSTITUTE(SUBSTITUTE(SUBSTITUTE(SUBSTITUTE(SUBSTITUTE(SUBSTITUTE(SUBSTITUTE(SUBSTITUTE(UPPER(_xlpm.a)," ",""),"CONTROL","CTRL"),"CTL","CTRL"),"ESCAPE","ESC"),"RETURN","ENTER"),"PAGEDOWN","PGDN"),"PGDOWN","PGDN"),"PAGEUP","PGUP"),"ARROWKEYS","ARROW"),"ARROWKEY","ARROW"),"ARROWS","ARROW"),"DOWNARROW","DOWN"),"UPARROW","UP"),"LEFTARROW","LEFT"),"RIGHTARROW","RIGHT"),"ARROWDOWN","DOWN"),"ARROWUP","UP"),"ARROWLEFT","LEFT"),"ARROWRIGHT","RIGHT"),"↓","DOWN"),"↑","UP"),"←","LEFT"),"→","RIGHT"),"SPACEBAR","SPACE"),"−","-"),"MINUS","-"),"PLUS","+")=Key!$E$15:$G$15),"✔ CLEAR","✘ TRY AGAIN"))),"✘ TRY AGAIN")} | F32: {=IF(E32="Show hint",Key!$B$15,"")} | G32: {=IF(LEFT(D32,1)="✔",IF(E32="Show hint",5,10),0)} -> 0
A33: C3 | B33: In J6 find the Price of the product whose ID is in I6: =XLOOKUP(I6,B6:B20,E6:E20). | C33: ▶ ARENA C3 (cell J6) | D33: {=IF(ISBLANK('F4-1 Arena'!$J$6),"",IF(NOT(_xlfn.ISFORMULA('F4-1 Arena'!$J$6)),"✘ That's a typed value · enter a formula",IF(ISERROR('F4-1 Arena'!$J$6),"✘ Your formula returns "&IFERROR(CHOOSE(ERROR.TYPE('F4-1 Arena'!$J$6),"#NULL!","#DIV/0!","#VALUE!","#REF!","#NAME?","#NUM!","#N/A","#GETTING_DATA","#SPILL!","#CONNECT!","#BLOCKED!","#UNKNOWN!","#FIELD!","#CALC!"),"an error"),IF(NOT(AND(IFERROR(AND(ISNUMBER('F4-1 Arena'!$J$6),ABS('F4-1 Arena'!$J$6-Key!$C$16)<=1E-9*MAX(1,ABS(Key!$C$16))),FALSE))),"✘ TRY AGAIN",IF(AND(OR(ISNUMBER(FIND({"=","(",",","+","-","*","/","&"," ","<",">",":","@","^"}&"XLOOKUP"&"(",UPPER(_xlfn.FORMULATEXT('F4-1 Arena'!$J$6)))))),"✔ CLEAR","✘ CLOSE · right value, but use XLOOKUP")))))} | F33: {=IF(E33="Show hint",Key!$B$16,"")} | G33: {=IF(LEFT(D33,1)="✔",IF(E33="Show hint",5,10),0)} -> 0
A34: C4 | B34: In J10 write =XLOOKUP(I10,$B$6:$B$20,$F$6:$F$20) to get the Stock, then fill down to J13 with Ctrl+D. The $ signs keep the ranges in place. | C34: ▶ ARENA C4 (cell J10) | D34: {=IF(COUNTA('F4-1 Arena'!$J$10,'F4-1 Arena'!$J$11,'F4-1 Arena'!$J$12,'F4-1 Arena'!$J$13)=0,"",IF(OR(NOT(_xlfn.ISFORMULA('F4-1 Arena'!$J$10)),NOT(_xlfn.ISFORMULA('F4-1 Arena'!$J$11)),NOT(_xlfn.ISFORMULA('F4-1 Arena'!$J$12)),NOT(_xlfn.ISFORMULA('F4-1 Arena'!$J$13))),"✘ Some cells aren't formulas yet",IF(OR(ISERROR('F4-1 Arena'!$J$10),ISERROR('F4-1 Arena'!$J$11),ISERROR('F4-1 Arena'!$J$12),ISERROR('F4-1 Arena'!$J$13)),"✘ Some cells show an error",IF(NOT(AND(IFERROR(AND(ISNUMBER('F4-1 Arena'!$J$10),ABS('F4-1 Arena'!$J$10-Key!$E$17)<=1E-9*MAX(1,ABS(Key!$E$17))),FALSE),IFERROR(AND(ISNUMBER('F4-1 Arena'!$J$11),ABS('F4-1 Arena'!$J$11-Key!$F$17)<=1E-9*MAX(1,ABS(Key!$F$17))),FALSE),IFERROR(AND(ISNUMBER('F4-1 Arena'!$J$12),ABS('F4-1 Arena'!$J$12-Key!$G$17)<=1E-9*MAX(1,ABS(Key!$G$17))),FALSE),IFERROR(AND(ISNUMBER('F4-1 Arena'!$J$13),ABS('F4-1 Arena'!$J$13-Key!$H$17)<=1E-9*MAX(1,ABS(Key!$H$17))),FALSE))),"✘ TRY AGAIN",IF(AND(OR(ISNUMBER(FIND({"=","(",",","+","-","*","/","&"," ","<",">",":","@","^"}&"XLOOKUP"&"(",UPPER(_xlfn.FORMULATEXT('F4-1 Arena'!$J$10)))))),IF(ISNUMBER(FIND("$",_xlfn.FORMULATEXT('F4-1 Arena'!$J$10))),"✔ CLEAR","✘ CLOSE · add $ so it fills correctly (F4)"),"✘ CLOSE · right value, but use XLOOKUP")))))} | F34: {=IF(E34="Show hint",Key!$B$17,"")} | G34: {=IF(LEFT(D34,1)="✔",IF(E34="Show hint",5,10),0)} -> 0

Sheet F4-1 Arena
A1: ARENA ▸ F4-1 SEEKER
A2: Practice area · everything here is editable. Missions and their checks are on the stage sheet.
A3: PASS CODE | B3: SEEKER | D3: ◀ Back to F4-1 Seeker
B5: ID | C5: Product | D5: Category | E5: Price | F5: Stock | I5: Find ID | J5: Price
B6: P-01 | C6: Apple | D6: Fruit | E6: 0.5 | F6: 120 | I6: P-07
B7: P-02 | C7: Banana | D7: Fruit | E7: 0.25 | F7: 200
B8: P-03 | C8: Carrot | D8: Veg | E8: 0.3 | F8: 80
B9: P-04 | C9: Dragonfruit | D9: Fruit | E9: 3.5 | F9: 12 | I9: Order IDs | J9: Stock
B10: P-05 | C10: Eggplant | D10: Veg | E10: 1.2 | F10: 30 | I10: P-03
B11: P-06 | C11: Fig | D11: Fruit | E11: 2 | F11: 25 | I11: P-11
B12: P-07 | C12: Garlic | D12: Veg | E12: 0.8 | F12: 60 | I12: P-01
B13: P-08 | C13: Honeydew | D13: Fruit | E13: 4 | F13: 8 | I13: P-14
B14: P-09 | C14: Iceberg | D14: Veg | E14: 1.5 | F14: 40
B15: P-10 | C15: Jalapeno | D15: Veg | E15: 0.2 | F15: 150
B16: P-11 | C16: Kiwi | D16: Fruit | E16: 0.6 | F16: 90
B17: P-12 | C17: Leek | D17: Veg | E17: 1.1 | F17: 35
B18: P-13 | C18: Mango | D18: Fruit | E18: 1.8 | F18: 45
B19: P-14 | C19: Nectarine | D19: Fruit | E19: 0.9 | F19: 70
B20: P-15 | C20: Okra | D20: Veg | E20: 2.2 | F20: 18

Sheet F4-2 Safety Net
A1: STAGE F4-2 ▸ SAFETY NET
A2: Goal: handle missing values and return several columns
A3: {="SCORE "&TEXT(SUM($G$12:$G$34),"0000")&" / 0160"} -> SCORE 0000 / 0160 | C3: {=IF(SUM($G$12:$G$34)>=160,"★★★",IF(SUM($G$12:$G$34)>=160*0.8,"★★☆",IF(SUM($G$12:$G$34)>=160*0.5,"★☆☆","☆☆☆")))} -> ☆☆☆ | D3: {=REPT("█",ROUND(10*SUM($G$12:$G$34)/160,0))&REPT("░",10-ROUND(10*SUM($G$12:$G$34)/160,0))&" "&TEXT(SUM($G$12:$G$34)/160,"0%")} -> ░░░░░░░░░░ 0% | F3: {=IF(SUM($G$12:$G$34)>=160*0.5,"STAGE CLEAR! ▶ Next: F4-3 Old School","")}
A5: BRIEFING · new moves in this stage
A6: # | B6: What it does · Pro tip | C6: Keys / Syntax
A7: 1 | B7: XLOOKUP's 4th argument: what to show when nothing matches. Tip: =XLOOKUP(A2,B:B,C:C,"Not found") instead of #N/A. | C7: if_not_found
A8: 2 | B8: Give XLOOKUP a return range two columns wide and both values spill out. Tip: One formula, several answers side by side. | C8: return 2+ columns
A10: WARM-UP · flashback to earlier stages
A11: # | B11: Mission | C11: Your answer | D11: Result | E11: Hint? | F11: Hint | G11: XP
A12: W1 | B12: Which modern function finds a value and returns the matching item from another column? (from F4-1 Seeker) | D12: {=IFERROR(_xlfn.LET(_xlpm.a,'F4-2 Safety Net'!$C$12,IF(TRIM(_xlpm.a&"")="","",IF(OR(SUBSTITUTE(SUBSTITUTE(SUBSTITUTE(SUBSTITUTE(SUBSTITUTE(SUBSTITUTE(SUBSTITUTE(SUBSTITUTE(SUBSTITUTE(SUBSTITUTE(SUBSTITUTE(SUBSTITUTE(SUBSTITUTE(SUBSTITUTE(SUBSTITUTE(SUBSTITUTE(SUBSTITUTE(SUBSTITUTE(SUBSTITUTE(SUBSTITUTE(SUBSTITUTE(SUBSTITUTE(SUBSTITUTE(SUBSTITUTE(SUBSTITUTE(SUBSTITUTE(SUBSTITUTE(UPPER(_xlpm.a)," ",""),"CONTROL","CTRL"),"CTL","CTRL"),"ESCAPE","ESC"),"RETURN","ENTER"),"PAGEDOWN","PGDN"),"PGDOWN","PGDN"),"PAGEUP","PGUP"),"ARROWKEYS","ARROW"),"ARROWKEY","ARROW"),"ARROWS","ARROW"),"DOWNARROW","DOWN"),"UPARROW","UP"),"LEFTARROW","LEFT"),"RIGHTARROW","RIGHT"),"ARROWDOWN","DOWN"),"ARROWUP","UP"),"ARROWLEFT","LEFT"),"ARROWRIGHT","RIGHT"),"↓","DOWN"),"↑","UP"),"←","LEFT"),"→","RIGHT"),"SPACEBAR","SPACE"),"−","-"),"MINUS","-"),"PLUS","+")=Key!$E$18:$J$18),"✔ CLEAR","✘ TRY AGAIN"))),"✘ TRY AGAIN")} | F12: {=IF(E12="Show hint",Key!$B$18,"")} | G12: {=IF(LEFT(D12,1)="✔",IF(E12="Show hint",5,10),0)} -> 0
A13: W2 | B13: Which symbol locks a range so it doesn't shift when you fill down? (from F4-1 Seeker) | D13: {=IFERROR(_xlfn.LET(_xlpm.a,'F4-2 Safety Net'!$C$13,IF(TRIM(_xlpm.a&"")="","",IF(OR(SUBSTITUTE(SUBSTITUTE(SUBSTITUTE(SUBSTITUTE(SUBSTITUTE(SUBSTITUTE(SUBSTITUTE(SUBSTITUTE(SUBSTITUTE(SUBSTITUTE(SUBSTITUTE(SUBSTITUTE(SUBSTITUTE(SUBSTITUTE(SUBSTITUTE(SUBSTITUTE(SUBSTITUTE(SUBSTITUTE(SUBSTITUTE(SUBSTITUTE(SUBSTITUTE(SUBSTITUTE(SUBSTITUTE(SUBSTITUTE(SUBSTITUTE(SUBSTITUTE(SUBSTITUTE(UPPER(_xlpm.a)," ",""),"CONTROL","CTRL"),"CTL","CTRL"),"ESCAPE","ESC"),"RETURN","ENTER"),"PAGEDOWN","PGDN"),"PGDOWN","PGDN"),"PAGEUP","PGUP"),"ARROWKEYS","ARROW"),"ARROWKEY","ARROW"),"ARROWS","ARROW"),"DOWNARROW","DOWN"),"UPARROW","UP"),"LEFTARROW","LEFT"),"RIGHTARROW","RIGHT"),"ARROWDOWN","DOWN"),"ARROWUP","UP"),"ARROWLEFT","LEFT"),"ARROWRIGHT","RIGHT"),"↓","DOWN"),"↑","UP"),"←","LEFT"),"→","RIGHT"),"SPACEBAR","SPACE"),"−","-"),"MINUS","-"),"PLUS","+")=Key!$E$19:$G$19),"✔ CLEAR","✘ TRY AGAIN"))),"✘ TRY AGAIN")} | F13: {=IF(E13="Show hint",Key!$B$19,"")} | G13: {=IF(LEFT(D13,1)="✔",IF(E13="Show hint",5,10),0)} -> 0
A14: W3 | B14: Which keys open Find? (from S4-3 Detective) | D14: {=IFERROR(_xlfn.LET(_xlpm.a,'F4-2 Safety Net'!$C$14,IF(TRIM(_xlpm.a&"")="","",IF(OR(SUBSTITUTE(SUBSTITUTE(SUBSTITUTE(SUBSTITUTE(SUBSTITUTE(SUBSTITUTE(SUBSTITUTE(SUBSTITUTE(SUBSTITUTE(SUBSTITUTE(SUBSTITUTE(SUBSTITUTE(SUBSTITUTE(SUBSTITUTE(SUBSTITUTE(SUBSTITUTE(SUBSTITUTE(SUBSTITUTE(SUBSTITUTE(SUBSTITUTE(SUBSTITUTE(SUBSTITUTE(SUBSTITUTE(SUBSTITUTE(SUBSTITUTE(SUBSTITUTE(SUBSTITUTE(UPPER(_xlpm.a)," ",""),"CONTROL","CTRL"),"CTL","CTRL"),"ESCAPE","ESC"),"RETURN","ENTER"),"PAGEDOWN","PGDN"),"PGDOWN","PGDN"),"PAGEUP","PGUP"),"ARROWKEYS","ARROW"),"ARROWKEY","ARROW"),"ARROWS","ARROW"),"DOWNARROW","DOWN"),"UPARROW","UP"),"LEFTARROW","LEFT"),"RIGHTARROW","RIGHT"),"ARROWDOWN","DOWN"),"ARROWUP","UP"),"ARROWLEFT","LEFT"),"ARROWRIGHT","RIGHT"),"↓","DOWN"),"↑","UP"),"←","LEFT"),"→","RIGHT"),"SPACEBAR","SPACE"),"−","-"),"MINUS","-"),"PLUS","+")=Key!$E$20:$E$20),"✔ CLEAR","✘ TRY AGAIN"))),"✘ TRY AGAIN")} | F14: {=IF(E14="Show hint",Key!$B$20,"")} | G14: {=IF(LEFT(D14,1)="✔",IF(E14="Show hint",5,10),0)} -> 0
A15: W4 | B15: Which keys open Find and Replace on the Replace tab? (from S4-3 Detective) | D15: {=IFERROR(_xlfn.LET(_xlpm.a,'F4-2 Safety Net'!$C$15,IF(TRIM(_xlpm.a&"")="","",IF(OR(SUBSTITUTE(SUBSTITUTE(SUBSTITUTE(SUBSTITUTE(SUBSTITUTE(SUBSTITUTE(SUBSTITUTE(SUBSTITUTE(SUBSTITUTE(SUBSTITUTE(SUBSTITUTE(SUBSTITUTE(SUBSTITUTE(SUBSTITUTE(SUBSTITUTE(SUBSTITUTE(SUBSTITUTE(SUBSTITUTE(SUBSTITUTE(SUBSTITUTE(SUBSTITUTE(SUBSTITUTE(SUBSTITUTE(SUBSTITUTE(SUBSTITUTE(SUBSTITUTE(SUBSTITUTE(UPPER(_xlpm.a)," ",""),"CONTROL","CTRL"),"CTL","CTRL"),"ESCAPE","ESC"),"RETURN","ENTER"),"PAGEDOWN","PGDN"),"PGDOWN","PGDN"),"PAGEUP","PGUP"),"ARROWKEYS","ARROW"),"ARROWKEY","ARROW"),"ARROWS","ARROW"),"DOWNARROW","DOWN"),"UPARROW","UP"),"LEFTARROW","LEFT"),"RIGHTARROW","RIGHT"),"ARROWDOWN","DOWN"),"ARROWUP","UP"),"ARROWLEFT","LEFT"),"ARROWRIGHT","RIGHT"),"↓","DOWN"),"↑","UP"),"←","LEFT"),"→","RIGHT"),"SPACEBAR","SPACE"),"−","-"),"MINUS","-"),"PLUS","+")=Key!$E$21:$E$21),"✔ CLEAR","✘ TRY AGAIN"))),"✘ TRY AGAIN")} | F15: {=IF(E15="Show hint",Key!$B$21,"")} | G15: {=IF(LEFT(D15,1)="✔",IF(E15="Show hint",5,10),0)} -> 0
A16: W5 | B16: Which function is TRUE when a value is a number? (from F2-5 Error Shield) | D16: {=IFERROR(_xlfn.LET(_xlpm.a,'F4-2 Safety Net'!$C$16,IF(TRIM(_xlpm.a&"")="","",IF(OR(SUBSTITUTE(SUBSTITUTE(SUBSTITUTE(SUBSTITUTE(SUBSTITUTE(SUBSTITUTE(SUBSTITUTE(SUBSTITUTE(SUBSTITUTE(SUBSTITUTE(SUBSTITUTE(SUBSTITUTE(SUBSTITUTE(SUBSTITUTE(SUBSTITUTE(SUBSTITUTE(SUBSTITUTE(SUBSTITUTE(SUBSTITUTE(SUBSTITUTE(SUBSTITUTE(SUBSTITUTE(SUBSTITUTE(SUBSTITUTE(SUBSTITUTE(SUBSTITUTE(SUBSTITUTE(UPPER(_xlpm.a)," ",""),"CONTROL","CTRL"),"CTL","CTRL"),"ESCAPE","ESC"),"RETURN","ENTER"),"PAGEDOWN","PGDN"),"PGDOWN","PGDN"),"PAGEUP","PGUP"),"ARROWKEYS","ARROW"),"ARROWKEY","ARROW"),"ARROWS","ARROW"),"DOWNARROW","DOWN"),"UPARROW","UP"),"LEFTARROW","LEFT"),"RIGHTARROW","RIGHT"),"ARROWDOWN","DOWN"),"ARROWUP","UP"),"ARROWLEFT","LEFT"),"ARROWRIGHT","RIGHT"),"↓","DOWN"),"↑","UP"),"←","LEFT"),"→","RIGHT"),"SPACEBAR","SPACE"),"−","-"),"MINUS","-"),"PLUS","+")=Key!$E$22:$J$22),"✔ CLEAR","✘ TRY AGAIN"))),"✘ TRY AGAIN")} | F16: {=IF(E16="Show hint",Key!$B$22,"")} | G16: {=IF(LEFT(D16,1)="✔",IF(E16="Show hint",5,10),0)} -> 0
A17: W6 | B17: Which keys apply the Currency format? (from S3-1 Number Skins) | D17: {=IFERROR(_xlfn.LET(_xlpm.a,'F4-2 Safety Net'!$C$17,IF(TRIM(_xlpm.a&"")="","",IF(OR(SUBSTITUTE(SUBSTITUTE(SUBSTITUTE(SUBSTITUTE(SUBSTITUTE(SUBSTITUTE(SUBSTITUTE(SUBSTITUTE(SUBSTITUTE(SUBSTITUTE(SUBSTITUTE(SUBSTITUTE(SUBSTITUTE(SUBSTITUTE(SUBSTITUTE(SUBSTITUTE(SUBSTITUTE(SUBSTITUTE(SUBSTITUTE(SUBSTITUTE(SUBSTITUTE(SUBSTITUTE(SUBSTITUTE(SUBSTITUTE(SUBSTITUTE(SUBSTITUTE(SUBSTITUTE(UPPER(_xlpm.a)," ",""),"CONTROL","CTRL"),"CTL","CTRL"),"ESCAPE","ESC"),"RETURN","ENTER"),"PAGEDOWN","PGDN"),"PGDOWN","PGDN"),"PAGEUP","PGUP"),"ARROWKEYS","ARROW"),"ARROWKEY","ARROW"),"ARROWS","ARROW"),"DOWNARROW","DOWN"),"UPARROW","UP"),"LEFTARROW","LEFT"),"RIGHTARROW","RIGHT"),"ARROWDOWN","DOWN"),"ARROWUP","UP"),"ARROWLEFT","LEFT"),"ARROWRIGHT","RIGHT"),"↓","DOWN"),"↑","UP"),"←","LEFT"),"→","RIGHT"),"SPACEBAR","SPACE"),"−","-"),"MINUS","-"),"PLUS","+")=Key!$E$23:$H$23),"✔ CLEAR","✘ TRY AGAIN"))),"✘ TRY AGAIN")} | F17: {=IF(E17="Show hint",Key!$B$23,"")} | G17: {=IF(LEFT(D17,1)="✔",IF(E17="Show hint",5,10),0)} -> 0
A18: W7 | B18: Which keys apply the Percent format? (from S3-1 Number Skins) | D18: {=IFERROR(_xlfn.LET(_xlpm.a,'F4-2 Safety Net'!$C$18,IF(TRIM(_xlpm.a&"")="","",IF(OR(SUBSTITUTE(SUBSTITUTE(SUBSTITUTE(SUBSTITUTE(SUBSTITUTE(SUBSTITUTE(SUBSTITUTE(SUBSTITUTE(SUBSTITUTE(SUBSTITUTE(SUBSTITUTE(SUBSTITUTE(SUBSTITUTE(SUBSTITUTE(SUBSTITUTE(SUBSTITUTE(SUBSTITUTE(SUBSTITUTE(SUBSTITUTE(SUBSTITUTE(SUBSTITUTE(SUBSTITUTE(SUBSTITUTE(SUBSTITUTE(SUBSTITUTE(SUBSTITUTE(SUBSTITUTE(UPPER(_xlpm.a)," ",""),"CONTROL","CTRL"),"CTL","CTRL"),"ESCAPE","ESC"),"RETURN","ENTER"),"PAGEDOWN","PGDN"),"PGDOWN","PGDN"),"PAGEUP","PGUP"),"ARROWKEYS","ARROW"),"ARROWKEY","ARROW"),"ARROWS","ARROW"),"DOWNARROW","DOWN"),"UPARROW","UP"),"LEFTARROW","LEFT"),"RIGHTARROW","RIGHT"),"ARROWDOWN","DOWN"),"ARROWUP","UP"),"ARROWLEFT","LEFT"),"ARROWRIGHT","RIGHT"),"↓","DOWN"),"↑","UP"),"←","LEFT"),"→","RIGHT"),"SPACEBAR","SPACE"),"−","-"),"MINUS","-"),"PLUS","+")=Key!$E$24:$H$24),"✔ CLEAR","✘ TRY AGAIN"))),"✘ TRY AGAIN")} | F18: {=IF(E18="Show hint",Key!$B$24,"")} | G18: {=IF(LEFT(D18,1)="✔",IF(E18="Show hint",5,10),0)} -> 0
A19: W8 | B19: Which keys apply the Number format with a thousands separator? (from S3-1 Number Skins) | D19: {=IFERROR(_xlfn.LET(_xlpm.a,'F4-2 Safety Net'!$C$19,IF(TRIM(_xlpm.a&"")="","",IF(OR(SUBSTITUTE(SUBSTITUTE(SUBSTITUTE(SUBSTITUTE(SUBSTITUTE(SUBSTITUTE(SUBSTITUTE(SUBSTITUTE(SUBSTITUTE(SUBSTITUTE(SUBSTITUTE(SUBSTITUTE(SUBSTITUTE(SUBSTITUTE(SUBSTITUTE(SUBSTITUTE(SUBSTITUTE(SUBSTITUTE(SUBSTITUTE(SUBSTITUTE(SUBSTITUTE(SUBSTITUTE(SUBSTITUTE(SUBSTITUTE(SUBSTITUTE(SUBSTITUTE(SUBSTITUTE(UPPER(_xlpm.a)," ",""),"CONTROL","CTRL"),"CTL","CTRL"),"ESCAPE","ESC"),"RETURN","ENTER"),"PAGEDOWN","PGDN"),"PGDOWN","PGDN"),"PAGEUP","PGUP"),"ARROWKEYS","ARROW"),"ARROWKEY","ARROW"),"ARROWS","ARROW"),"DOWNARROW","DOWN"),"UPARROW","UP"),"LEFTARROW","LEFT"),"RIGHTARROW","RIGHT"),"ARROWDOWN","DOWN"),"ARROWUP","UP"),"ARROWLEFT","LEFT"),"ARROWRIGHT","RIGHT"),"↓","DOWN"),"↑","UP"),"←","LEFT"),"→","RIGHT"),"SPACEBAR","SPACE"),"−","-"),"MINUS","-"),"PLUS","+")=Key!$E$25:$H$25),"✔ CLEAR","✘ TRY AGAIN"))),"✘ TRY AGAIN")} | F19: {=IF(E19="Show hint",Key!$B$25,"")} | G19: {=IF(LEFT(D19,1)="✔",IF(E19="Show hint",5,10),0)} -> 0
A20: W9 | B20: Which keys apply the Date format? (from S3-1 Number Skins) | D20: {=IFERROR(_xlfn.LET(_xlpm.a,'F4-2 Safety Net'!$C$20,IF(TRIM(_xlpm.a&"")="","",IF(OR(SUBSTITUTE(SUBSTITUTE(SUBSTITUTE(SUBSTITUTE(SUBSTITUTE(SUBSTITUTE(SUBSTITUTE(SUBSTITUTE(SUBSTITUTE(SUBSTITUTE(SUBSTITUTE(SUBSTITUTE(SUBSTITUTE(SUBSTITUTE(SUBSTITUTE(SUBSTITUTE(SUBSTITUTE(SUBSTITUTE(SUBSTITUTE(SUBSTITUTE(SUBSTITUTE(SUBSTITUTE(SUBSTITUTE(SUBSTITUTE(SUBSTITUTE(SUBSTITUTE(SUBSTITUTE(UPPER(_xlpm.a)," ",""),"CONTROL","CTRL"),"CTL","CTRL"),"ESCAPE","ESC"),"RETURN","ENTER"),"PAGEDOWN","PGDN"),"PGDOWN","PGDN"),"PAGEUP","PGUP"),"ARROWKEYS","ARROW"),"ARROWKEY","ARROW"),"ARROWS","ARROW"),"DOWNARROW","DOWN"),"UPARROW","UP"),"LEFTARROW","LEFT"),"RIGHTARROW","RIGHT"),"ARROWDOWN","DOWN"),"ARROWUP","UP"),"ARROWLEFT","LEFT"),"ARROWRIGHT","RIGHT"),"↓","DOWN"),"↑","UP"),"←","LEFT"),"→","RIGHT"),"SPACEBAR","SPACE"),"−","-"),"MINUS","-"),"PLUS","+")=Key!$E$26:$H$26),"✔ CLEAR","✘ TRY AGAIN"))),"✘ TRY AGAIN")} | F20: {=IF(E20="Show hint",Key!$B$26,"")} | G20: {=IF(LEFT(D20,1)="✔",IF(E20="Show hint",5,10),0)} -> 0
A21: W10 | B21: Which keys apply the Time format? (from S3-1 Number Skins) | D21: {=IFERROR(_xlfn.LET(_xlpm.a,'F4-2 Safety Net'!$C$21,IF(TRIM(_xlpm.a&"")="","",IF(OR(SUBSTITUTE(SUBSTITUTE(SUBSTITUTE(SUBSTITUTE(SUBSTITUTE(SUBSTITUTE(SUBSTITUTE(SUBSTITUTE(SUBSTITUTE(SUBSTITUTE(SUBSTITUTE(SUBSTITUTE(SUBSTITUTE(SUBSTITUTE(SUBSTITUTE(SUBSTITUTE(SUBSTITUTE(SUBSTITUTE(SUBSTITUTE(SUBSTITUTE(SUBSTITUTE(SUBSTITUTE(SUBSTITUTE(SUBSTITUTE(SUBSTITUTE(SUBSTITUTE(SUBSTITUTE(UPPER(_xlpm.a)," ",""),"CONTROL","CTRL"),"CTL","CTRL"),"ESCAPE","ESC"),"RETURN","ENTER"),"PAGEDOWN","PGDN"),"PGDOWN","PGDN"),"PAGEUP","PGUP"),"ARROWKEYS","ARROW"),"ARROWKEY","ARROW"),"ARROWS","ARROW"),"DOWNARROW","DOWN"),"UPARROW","UP"),"LEFTARROW","LEFT"),"RIGHTARROW","RIGHT"),"ARROWDOWN","DOWN"),"ARROWUP","UP"),"ARROWLEFT","LEFT"),"ARROWRIGHT","RIGHT"),"↓","DOWN"),"↑","UP"),"←","LEFT"),"→","RIGHT"),"SPACEBAR","SPACE"),"−","-"),"MINUS","-"),"PLUS","+")=Key!$E$27:$H$27),"✔ CLEAR","✘ TRY AGAIN"))),"✘ TRY AGAIN")} | F21: {=IF(E21="Show hint",Key!$B$27,"")} | G21: {=IF(LEFT(D21,1)="✔",IF(E21="Show hint",5,10),0)} -> 0
A23: TRAINING · recognize the move (pick from the list)
A24: # | B24: Mission | C24: Your answer | D24: Result | E24: Hint? | F24: Hint | G24: XP
A25: T1 | B25: Which XLOOKUP argument number sets the result when no match is found? | D25: {=IFERROR(IF('F4-2 Safety Net'!$C$25&""="","",IF('F4-2 Safety Net'!$C$25&""=Key!$C$28&"","✔ CLEAR","✘ TRY AGAIN")),"✘ TRY AGAIN")} | F25: {=IF(E25="Show hint",Key!$B$28,"")} | G25: {=IF(LEFT(D25,1)="✔",IF(E25="Show hint",5,10),0)} -> 0
A26: T2 | B26: If the return array is E6:F20, how many columns does the result spill into? | D26: {=IFERROR(IF('F4-2 Safety Net'!$C$26&""="","",IF('F4-2 Safety Net'!$C$26&""=Key!$C$29&"","✔ CLEAR","✘ TRY AGAIN")),"✘ TRY AGAIN")} | F26: {=IF(E26="Show hint",Key!$B$29,"")} | G26: {=IF(LEFT(D26,1)="✔",IF(E26="Show hint",5,10),0)} -> 0
A28: CHALLENGES · recall it, then do it
B29: ▶ Open F4-2 Arena (or press Ctrl+PgDn)
A30: # | B30: Mission | C30: Your answer | D30: Result | E30: Hint? | F30: Hint | G30: XP
A31: C1 | B31: Which XLOOKUP argument number sets the result when no match is found? | D31: {=IFERROR(_xlfn.LET(_xlpm.a,'F4-2 Safety Net'!$C$31,IF(TRIM(_xlpm.a&"")="","",IF(OR(SUBSTITUTE(SUBSTITUTE(SUBSTITUTE(SUBSTITUTE(SUBSTITUTE(SUBSTITUTE(SUBSTITUTE(SUBSTITUTE(SUBSTITUTE(SUBSTITUTE(SUBSTITUTE(SUBSTITUTE(SUBSTITUTE(SUBSTITUTE(SUBSTITUTE(SUBSTITUTE(SUBSTITUTE(SUBSTITUTE(SUBSTITUTE(SUBSTITUTE(SUBSTITUTE(SUBSTITUTE(SUBSTITUTE(SUBSTITUTE(SUBSTITUTE(SUBSTITUTE(SUBSTITUTE(UPPER(_xlpm.a)," ",""),"CONTROL","CTRL"),"CTL","CTRL"),"ESCAPE","ESC"),"RETURN","ENTER"),"PAGEDOWN","PGDN"),"PGDOWN","PGDN"),"PAGEUP","PGUP"),"ARROWKEYS","ARROW"),"ARROWKEY","ARROW"),"ARROWS","ARROW"),"DOWNARROW","DOWN"),"UPARROW","UP"),"LEFTARROW","LEFT"),"RIGHTARROW","RIGHT"),"ARROWDOWN","DOWN"),"ARROWUP","UP"),"ARROWLEFT","LEFT"),"ARROWRIGHT","RIGHT"),"↓","DOWN"),"↑","UP"),"←","LEFT"),"→","RIGHT"),"SPACEBAR","SPACE"),"−","-"),"MINUS","-"),"PLUS","+")=Key!$E$30:$H$30),"✔ CLEAR","✘ TRY AGAIN"))),"✘ TRY AGAIN")} | F31: {=IF(E31="Show hint",Key!$B$30,"")} | G31: {=IF(LEFT(D31,1)="✔",IF(E31="Show hint",5,10),0)} -> 0
A32: C2 | B32: If the return array is E6:F20, how many columns does the result spill into? | D32: {=IFERROR(_xlfn.LET(_xlpm.a,'F4-2 Safety Net'!$C$32,IF(TRIM(_xlpm.a&"")="","",IF(OR(SUBSTITUTE(SUBSTITUTE(SUBSTITUTE(SUBSTITUTE(SUBSTITUTE(SUBSTITUTE(SUBSTITUTE(SUBSTITUTE(SUBSTITUTE(SUBSTITUTE(SUBSTITUTE(SUBSTITUTE(SUBSTITUTE(SUBSTITUTE(SUBSTITUTE(SUBSTITUTE(SUBSTITUTE(SUBSTITUTE(SUBSTITUTE(SUBSTITUTE(SUBSTITUTE(SUBSTITUTE(SUBSTITUTE(SUBSTITUTE(SUBSTITUTE(SUBSTITUTE(SUBSTITUTE(UPPER(_xlpm.a)," ",""),"CONTROL","CTRL"),"CTL","CTRL"),"ESCAPE","ESC"),"RETURN","ENTER"),"PAGEDOWN","PGDN"),"PGDOWN","PGDN"),"PAGEUP","PGUP"),"ARROWKEYS","ARROW"),"ARROWKEY","ARROW"),"ARROWS","ARROW"),"DOWNARROW","DOWN"),"UPARROW","UP"),"LEFTARROW","LEFT"),"RIGHTARROW","RIGHT"),"ARROWDOWN","DOWN"),"ARROWUP","UP"),"ARROWLEFT","LEFT"),"ARROWRIGHT","RIGHT"),"↓","DOWN"),"↑","UP"),"←","LEFT"),"→","RIGHT"),"SPACEBAR","SPACE"),"−","-"),"MINUS","-"),"PLUS","+")=Key!$E$31:$F$31),"✔ CLEAR","✘ TRY AGAIN"))),"✘ TRY AGAIN")} | F32: {=IF(E32="Show hint",Key!$B$31,"")} | G32: {=IF(LEFT(D32,1)="✔",IF(E32="Show hint",5,10),0)} -> 0
A33: C3 | B33: I6 holds an ID that doesn't exist. In J6 look up its Product (column C) and show "Not found" instead of an error. | C33: ▶ ARENA C3 (cell J6) | D33: {=IF(ISBLANK('F4-2 Arena'!$J$6),"",IF(NOT(_xlfn.ISFORMULA('F4-2 Arena'!$J$6)),"✘ That's a typed value · enter a formula",IF(ISERROR('F4-2 Arena'!$J$6),"✘ Your formula returns "&IFERROR(CHOOSE(ERROR.TYPE('F4-2 Arena'!$J$6),"#NULL!","#DIV/0!","#VALUE!","#REF!","#NAME?","#NUM!","#N/A","#GETTING_DATA","#SPILL!","#CONNECT!","#BLOCKED!","#UNKNOWN!","#FIELD!","#CALC!"),"an error"),IF(NOT(AND(IFERROR(AND(ISTEXT('F4-2 Arena'!$J$6),'F4-2 Arena'!$J$6=Key!$C$32),FALSE))),"✘ TRY AGAIN",IF(AND(OR(ISNUMBER(FIND({"=","(",",","+","-","*","/","&"," ","<",">",":","@","^"}&"XLOOKUP"&"(",UPPER(_xlfn.FORMULATEXT('F4-2 Arena'!$J$6)))))),"✔ CLEAR","✘ CLOSE · right value, but use XLOOKUP")))))} | F33: {=IF(E33="Show hint",Key!$B$32,"")} | G33: {=IF(LEFT(D33,1)="✔",IF(E33="Show hint",5,10),0)} -> 0
A34: C4 | B34: In J9 return BOTH the Price and the Stock of the ID in I9 with one XLOOKUP: make the return array E6:F20. | C34: ▶ ARENA C4 (cell J9) | D34: {=IF(ISBLANK('F4-2 Arena'!$J$9),"",IF(NOT(_xlfn.ISFORMULA('F4-2 Arena'!$J$9)),"✘ That's a typed value · enter a formula",IF(ISERROR('F4-2 Arena'!$J$9),"✘ Your formula returns "&IFERROR(CHOOSE(ERROR.TYPE('F4-2 Arena'!$J$9),"#NULL!","#DIV/0!","#VALUE!","#REF!","#NAME?","#NUM!","#N/A","#GETTING_DATA","#SPILL!","#CONNECT!","#BLOCKED!","#UNKNOWN!","#FIELD!","#CALC!"),"an error"),IF(IFERROR(AND(ROWS(_xlfn.ANCHORARRAY('F4-2 Arena'!$J$9))=ROWS(_xlfn.ANCHORARRAY(Key!$E$2001)),COLUMNS(_xlfn.ANCHORARRAY('F4-2 Arena'!$J$9))=COLUMNS(_xlfn.ANCHORARRAY(Key!$E$2001)),SUM(--(_xlfn.ANCHORARRAY('F4-2 Arena'!$J$9)=_xlfn.ANCHORARRAY(Key!$E$2001)))=ROWS(_xlfn.ANCHORARRAY(Key!$E$2001))*COLUMNS(_xlfn.ANCHORARRAY(Key!$E$2001))),FALSE),IF(AND(OR(ISNUMBER(FIND({"=","(",",","+","-","*","/","&"," ","<",">",":","@","^"}&"XLOOKUP"&"(",UPPER(_xlfn.FORMULATEXT('F4-2 Arena'!$J$9)))))),"✔ CLEAR","✘ CLOSE · right result, but use XLOOKUP"),"✘ TRY AGAIN"))))} | F34: {=IF(E34="Show hint",Key!$B$33,"")} | G34: {=IF(LEFT(D34,1)="✔",IF(E34="Show hint",5,10),0)} -> 0

Sheet F4-2 Arena
A1: ARENA ▸ F4-2 SAFETY NET
A2: Practice area · everything here is editable. Missions and their checks are on the stage sheet.
A3: PASS CODE | B3: SAFETYNET | D3: ◀ Back to F4-2 Safety Net
B5: ID | C5: Product | D5: Category | E5: Price | F5: Stock | I5: Find ID | J5: Product
B6: P-01 | C6: Apple | D6: Fruit | E6: 0.5 | F6: 120 | I6: P-99
B7: P-02 | C7: Banana | D7: Fruit | E7: 0.25 | F7: 200
B8: P-03 | C8: Carrot | D8: Veg | E8: 0.3 | F8: 80 | I8: Find ID | J8: Price | K8: Stock
B9: P-04 | C9: Dragonfruit | D9: Fruit | E9: 3.5 | F9: 12 | I9: P-05
B10: P-05 | C10: Eggplant | D10: Veg | E10: 1.2 | F10: 30
B11: P-06 | C11: Fig | D11: Fruit | E11: 2 | F11: 25
B12: P-07 | C12: Garlic | D12: Veg | E12: 0.8 | F12: 60
B13: P-08 | C13: Honeydew | D13: Fruit | E13: 4 | F13: 8
B14: P-09 | C14: Iceberg | D14: Veg | E14: 1.5 | F14: 40
B15: P-10 | C15: Jalapeno | D15: Veg | E15: 0.2 | F15: 150
B16: P-11 | C16: Kiwi | D16: Fruit | E16: 0.6 | F16: 90
B17: P-12 | C17: Leek | D17: Veg | E17: 1.1 | F17: 35
B18: P-13 | C18: Mango | D18: Fruit | E18: 1.8 | F18: 45
B19: P-14 | C19: Nectarine | D19: Fruit | E19: 0.9 | F19: 70
B20: P-15 | C20: Okra | D20: Veg | E20: 2.2 | F20: 18

Sheet F4-3 Old School
A1: STAGE F4-3 ▸ OLD SCHOOL
A2: Goal: read and write classic VLOOKUP
A3: {="SCORE "&TEXT(SUM($G$12:$G$34),"0000")&" / 0160"} -> SCORE 0000 / 0160 | C3: {=IF(SUM($G$12:$G$34)>=160,"★★★",IF(SUM($G$12:$G$34)>=160*0.8,"★★☆",IF(SUM($G$12:$G$34)>=160*0.5,"★☆☆","☆☆☆")))} -> ☆☆☆ | D3: {=REPT("█",ROUND(10*SUM($G$12:$G$34)/160,0))&REPT("░",10-ROUND(10*SUM($G$12:$G$34)/160,0))&" "&TEXT(SUM($G$12:$G$34)/160,"0%")} -> ░░░░░░░░░░ 0% | F3: {=IF(SUM($G$12:$G$34)>=160*0.5,"STAGE CLEAR! ▶ Next: F4-4 Power Couple","")}
A5: BRIEFING · new moves in this stage
A6: # | B6: What it does · Pro tip | C6: Keys / Syntax
A7: 1 | B7: VLOOKUP(value, table, column_number, FALSE) searches the FIRST column of a table. Tip: Still everywhere in older files. | C7: VLOOKUP
A8: 2 | B8: End VLOOKUP with FALSE for an exact match. Tip: Forget it and VLOOKUP may return a wrong neighbor. | C8: FALSE = exact
A10: WARM-UP · flashback to earlier stages
A11: # | B11: Mission | C11: Your answer | D11: Result | E11: Hint? | F11: Hint | G11: XP
A12: W1 | B12: Which XLOOKUP argument number sets the result when no match is found? (from F4-2 Safety Net) | D12: {=IFERROR(_xlfn.LET(_xlpm.a,'F4-3 Old School'!$C$12,IF(TRIM(_xlpm.a&"")="","",IF(OR(SUBSTITUTE(SUBSTITUTE(SUBSTITUTE(SUBSTITUTE(SUBSTITUTE(SUBSTITUTE(SUBSTITUTE(SUBSTITUTE(SUBSTITUTE(SUBSTITUTE(SUBSTITUTE(SUBSTITUTE(SUBSTITUTE(SUBSTITUTE(SUBSTITUTE(SUBSTITUTE(SUBSTITUTE(SUBSTITUTE(SUBSTITUTE(SUBSTITUTE(SUBSTITUTE(SUBSTITUTE(SUBSTITUTE(SUBSTITUTE(SUBSTITUTE(SUBSTITUTE(SUBSTITUTE(UPPER(_xlpm.a)," ",""),"CONTROL","CTRL"),"CTL","CTRL"),"ESCAPE","ESC"),"RETURN","ENTER"),"PAGEDOWN","PGDN"),"PGDOWN","PGDN"),"PAGEUP","PGUP"),"ARROWKEYS","ARROW"),"ARROWKEY","ARROW"),"ARROWS","ARROW"),"DOWNARROW","DOWN"),"UPARROW","UP"),"LEFTARROW","LEFT"),"RIGHTARROW","RIGHT"),"ARROWDOWN","DOWN"),"ARROWUP","UP"),"ARROWLEFT","LEFT"),"ARROWRIGHT","RIGHT"),"↓","DOWN"),"↑","UP"),"←","LEFT"),"→","RIGHT"),"SPACEBAR","SPACE"),"−","-"),"MINUS","-"),"PLUS","+")=Key!$E$34:$H$34),"✔ CLEAR","✘ TRY AGAIN"))),"✘ TRY AGAIN")} | F12: {=IF(E12="Show hint",Key!$B$34,"")} | G12: {=IF(LEFT(D12,1)="✔",IF(E12="Show hint",5,10),0)} -> 0
A13: W2 | B13: If the return array is E6:F20, how many columns does the result spill into? (from F4-2 Safety Net) | D13: {=IFERROR(_xlfn.LET(_xlpm.a,'F4-3 Old School'!$C$13,IF(TRIM(_xlpm.a&"")="","",IF(OR(SUBSTITUTE(SUBSTITUTE(SUBSTITUTE(SUBSTITUTE(SUBSTITUTE(SUBSTITUTE(SUBSTITUTE(SUBSTITUTE(SUBSTITUTE(SUBSTITUTE(SUBSTITUTE(SUBSTITUTE(SUBSTITUTE(SUBSTITUTE(SUBSTITUTE(SUBSTITUTE(SUBSTITUTE(SUBSTITUTE(SUBSTITUTE(SUBSTITUTE(SUBSTITUTE(SUBSTITUTE(SUBSTITUTE(SUBSTITUTE(SUBSTITUTE(SUBSTITUTE(SUBSTITUTE(UPPER(_xlpm.a)," ",""),"CONTROL","CTRL"),"CTL","CTRL"),"ESCAPE","ESC"),"RETURN","ENTER"),"PAGEDOWN","PGDN"),"PGDOWN","PGDN"),"PAGEUP","PGUP"),"ARROWKEYS","ARROW"),"ARROWKEY","ARROW"),"ARROWS","ARROW"),"DOWNARROW","DOWN"),"UPARROW","UP"),"LEFTARROW","LEFT"),"RIGHTARROW","RIGHT"),"ARROWDOWN","DOWN"),"ARROWUP","UP"),"ARROWLEFT","LEFT"),"ARROWRIGHT","RIGHT"),"↓","DOWN"),"↑","UP"),"←","LEFT"),"→","RIGHT"),"SPACEBAR","SPACE"),"−","-"),"MINUS","-"),"PLUS","+")=Key!$E$35:$F$35),"✔ CLEAR","✘ TRY AGAIN"))),"✘ TRY AGAIN")} | F13: {=IF(E13="Show hint",Key!$B$35,"")} | G13: {=IF(LEFT(D13,1)="✔",IF(E13="Show hint",5,10),0)} -> 0
A14: W3 | B14: Which keys turn filter buttons on and off? (from S4-4 Data Wrangler) | D14: {=IFERROR(_xlfn.LET(_xlpm.a,'F4-3 Old School'!$C$14,IF(TRIM(_xlpm.a&"")="","",IF(OR(SUBSTITUTE(SUBSTITUTE(SUBSTITUTE(SUBSTITUTE(SUBSTITUTE(SUBSTITUTE(SUBSTITUTE(SUBSTITUTE(SUBSTITUTE(SUBSTITUTE(SUBSTITUTE(SUBSTITUTE(SUBSTITUTE(SUBSTITUTE(SUBSTITUTE(SUBSTITUTE(SUBSTITUTE(SUBSTITUTE(SUBSTITUTE(SUBSTITUTE(SUBSTITUTE(SUBSTITUTE(SUBSTITUTE(SUBSTITUTE(SUBSTITUTE(SUBSTITUTE(SUBSTITUTE(UPPER(_xlpm.a)," ",""),"CONTROL","CTRL"),"CTL","CTRL"),"ESCAPE","ESC"),"RETURN","ENTER"),"PAGEDOWN","PGDN"),"PGDOWN","PGDN"),"PAGEUP","PGUP"),"ARROWKEYS","ARROW"),"ARROWKEY","ARROW"),"ARROWS","ARROW"),"DOWNARROW","DOWN"),"UPARROW","UP"),"LEFTARROW","LEFT"),"RIGHTARROW","RIGHT"),"ARROWDOWN","DOWN"),"ARROWUP","UP"),"ARROWLEFT","LEFT"),"ARROWRIGHT","RIGHT"),"↓","DOWN"),"↑","UP"),"←","LEFT"),"→","RIGHT"),"SPACEBAR","SPACE"),"−","-"),"MINUS","-"),"PLUS","+")=Key!$E$36:$F$36),"✔ CLEAR","✘ TRY AGAIN"))),"✘ TRY AGAIN")} | F14: {=IF(E14="Show hint",Key!$B$36,"")} | G14: {=IF(LEFT(D14,1)="✔",IF(E14="Show hint",5,10),0)} -> 0
A15: W4 | B15: Which keys open the filter menu of a header cell? (from S4-4 Data Wrangler) | D15: {=IFERROR(_xlfn.LET(_xlpm.a,'F4-3 Old School'!$C$15,IF(TRIM(_xlpm.a&"")="","",IF(OR(SUBSTITUTE(SUBSTITUTE(SUBSTITUTE(SUBSTITUTE(SUBSTITUTE(SUBSTITUTE(SUBSTITUTE(SUBSTITUTE(SUBSTITUTE(SUBSTITUTE(SUBSTITUTE(SUBSTITUTE(SUBSTITUTE(SUBSTITUTE(SUBSTITUTE(SUBSTITUTE(SUBSTITUTE(SUBSTITUTE(SUBSTITUTE(SUBSTITUTE(SUBSTITUTE(SUBSTITUTE(SUBSTITUTE(SUBSTITUTE(SUBSTITUTE(SUBSTITUTE(SUBSTITUTE(UPPER(_xlpm.a)," ",""),"CONTROL","CTRL"),"CTL","CTRL"),"ESCAPE","ESC"),"RETURN","ENTER"),"PAGEDOWN","PGDN"),"PGDOWN","PGDN"),"PAGEUP","PGUP"),"ARROWKEYS","ARROW"),"ARROWKEY","ARROW"),"ARROWS","ARROW"),"DOWNARROW","DOWN"),"UPARROW","UP"),"LEFTARROW","LEFT"),"RIGHTARROW","RIGHT"),"ARROWDOWN","DOWN"),"ARROWUP","UP"),"ARROWLEFT","LEFT"),"ARROWRIGHT","RIGHT"),"↓","DOWN"),"↑","UP"),"←","LEFT"),"→","RIGHT"),"SPACEBAR","SPACE"),"−","-"),"MINUS","-"),"PLUS","+")=Key!$E$37:$E$37),"✔ CLEAR","✘ TRY AGAIN"))),"✘ TRY AGAIN")} | F15: {=IF(E15="Show hint",Key!$B$37,"")} | G15: {=IF(LEFT(D15,1)="✔",IF(E15="Show hint",5,10),0)} -> 0
A16: W5 | B16: Which keys turn a range into a Table? (from S4-4 Data Wrangler) | D16: {=IFERROR(_xlfn.LET(_xlpm.a,'F4-3 Old School'!$C$16,IF(TRIM(_xlpm.a&"")="","",IF(OR(SUBSTITUTE(SUBSTITUTE(SUBSTITUTE(SUBSTITUTE(SUBSTITUTE(SUBSTITUTE(SUBSTITUTE(SUBSTITUTE(SUBSTITUTE(SUBSTITUTE(SUBSTITUTE(SUBSTITUTE(SUBSTITUTE(SUBSTITUTE(SUBSTITUTE(SUBSTITUTE(SUBSTITUTE(SUBSTITUTE(SUBSTITUTE(SUBSTITUTE(SUBSTITUTE(SUBSTITUTE(SUBSTITUTE(SUBSTITUTE(SUBSTITUTE(SUBSTITUTE(SUBSTITUTE(UPPER(_xlpm.a)," ",""),"CONTROL","CTRL"),"CTL","CTRL"),"ESCAPE","ESC"),"RETURN","ENTER"),"PAGEDOWN","PGDN"),"PGDOWN","PGDN"),"PAGEUP","PGUP"),"ARROWKEYS","ARROW"),"ARROWKEY","ARROW"),"ARROWS","ARROW"),"DOWNARROW","DOWN"),"UPARROW","UP"),"LEFTARROW","LEFT"),"RIGHTARROW","RIGHT"),"ARROWDOWN","DOWN"),"ARROWUP","UP"),"ARROWLEFT","LEFT"),"ARROWRIGHT","RIGHT"),"↓","DOWN"),"↑","UP"),"←","LEFT"),"→","RIGHT"),"SPACEBAR","SPACE"),"−","-"),"MINUS","-"),"PLUS","+")=Key!$E$38:$F$38),"✔ CLEAR","✘ TRY AGAIN"))),"✘ TRY AGAIN")} | F16: {=IF(E16="Show hint",Key!$B$38,"")} | G16: {=IF(LEFT(D16,1)="✔",IF(E16="Show hint",5,10),0)} -> 0
A17: W6 | B17: Which KeyTips sort A to Z? (from S4-4 Data Wrangler) | D17: {=IFERROR(_xlfn.LET(_xlpm.a,'F4-3 Old School'!$C$17,IF(TRIM(_xlpm.a&"")="","",IF(OR(SUBSTITUTE(SUBSTITUTE(SUBSTITUTE(SUBSTITUTE(SUBSTITUTE(SUBSTITUTE(SUBSTITUTE(SUBSTITUTE(SUBSTITUTE(SUBSTITUTE(SUBSTITUTE(SUBSTITUTE(SUBSTITUTE(SUBSTITUTE(SUBSTITUTE(SUBSTITUTE(SUBSTITUTE(SUBSTITUTE(SUBSTITUTE(SUBSTITUTE(SUBSTITUTE(SUBSTITUTE(SUBSTITUTE(SUBSTITUTE(SUBSTITUTE(SUBSTITUTE(SUBSTITUTE(UPPER(_xlpm.a)," ",""),"CONTROL","CTRL"),"CTL","CTRL"),"ESCAPE","ESC"),"RETURN","ENTER"),"PAGEDOWN","PGDN"),"PGDOWN","PGDN"),"PAGEUP","PGUP"),"ARROWKEYS","ARROW"),"ARROWKEY","ARROW"),"ARROWS","ARROW"),"DOWNARROW","DOWN"),"UPARROW","UP"),"LEFTARROW","LEFT"),"RIGHTARROW","RIGHT"),"ARROWDOWN","DOWN"),"ARROWUP","UP"),"ARROWLEFT","LEFT"),"ARROWRIGHT","RIGHT"),"↓","DOWN"),"↑","UP"),"←","LEFT"),"→","RIGHT"),"SPACEBAR","SPACE"),"−","-"),"MINUS","-"),"PLUS","+")=Key!$E$39:$T$39),"✔ CLEAR","✘ TRY AGAIN"))),"✘ TRY AGAIN")} | F17: {=IF(E17="Show hint",Key!$B$39,"")} | G17: {=IF(LEFT(D17,1)="✔",IF(E17="Show hint",5,10),0)} -> 0
A18: W7 | B18: Which KeyTips sort Z to A? (from S4-4 Data Wrangler) | D18: {=IFERROR(_xlfn.LET(_xlpm.a,'F4-3 Old School'!$C$18,IF(TRIM(_xlpm.a&"")="","",IF(OR(SUBSTITUTE(SUBSTITUTE(SUBSTITUTE(SUBSTITUTE(SUBSTITUTE(SUBSTITUTE(SUBSTITUTE(SUBSTITUTE(SUBSTITUTE(SUBSTITUTE(SUBSTITUTE(SUBSTITUTE(SUBSTITUTE(SUBSTITUTE(SUBSTITUTE(SUBSTITUTE(SUBSTITUTE(SUBSTITUTE(SUBSTITUTE(SUBSTITUTE(SUBSTITUTE(SUBSTITUTE(SUBSTITUTE(SUBSTITUTE(SUBSTITUTE(SUBSTITUTE(SUBSTITUTE(UPPER(_xlpm.a)," ",""),"CONTROL","CTRL"),"CTL","CTRL"),"ESCAPE","ESC"),"RETURN","ENTER"),"PAGEDOWN","PGDN"),"PGDOWN","PGDN"),"PAGEUP","PGUP"),"ARROWKEYS","ARROW"),"ARROWKEY","ARROW"),"ARROWS","ARROW"),"DOWNARROW","DOWN"),"UPARROW","UP"),"LEFTARROW","LEFT"),"RIGHTARROW","RIGHT"),"ARROWDOWN","DOWN"),"ARROWUP","UP"),"ARROWLEFT","LEFT"),"ARROWRIGHT","RIGHT"),"↓","DOWN"),"↑","UP"),"←","LEFT"),"→","RIGHT"),"SPACEBAR","SPACE"),"−","-"),"MINUS","-"),"PLUS","+")=Key!$E$40:$T$40),"✔ CLEAR","✘ TRY AGAIN"))),"✘ TRY AGAIN")} | F18: {=IF(E18="Show hint",Key!$B$40,"")} | G18: {=IF(LEFT(D18,1)="✔",IF(E18="Show hint",5,10),0)} -> 0
A19: W8 | B19: Which keys insert an instant chart on the sheet? (from S4-4 Data Wrangler) | D19: {=IFERROR(_xlfn.LET(_xlpm.a,'F4-3 Old School'!$C$19,IF(TRIM(_xlpm.a&"")="","",IF(OR(SUBSTITUTE(SUBSTITUTE(SUBSTITUTE(SUBSTITUTE(SUBSTITUTE(SUBSTITUTE(SUBSTITUTE(SUBSTITUTE(SUBSTITUTE(SUBSTITUTE(SUBSTITUTE(SUBSTITUTE(SUBSTITUTE(SUBSTITUTE(SUBSTITUTE(SUBSTITUTE(SUBSTITUTE(SUBSTITUTE(SUBSTITUTE(SUBSTITUTE(SUBSTITUTE(SUBSTITUTE(SUBSTITUTE(SUBSTITUTE(SUBSTITUTE(SUBSTITUTE(SUBSTITUTE(UPPER(_xlpm.a)," ",""),"CONTROL","CTRL"),"CTL","CTRL"),"ESCAPE","ESC"),"RETURN","ENTER"),"PAGEDOWN","PGDN"),"PGDOWN","PGDN"),"PAGEUP","PGUP"),"ARROWKEYS","ARROW"),"ARROWKEY","ARROW"),"ARROWS","ARROW"),"DOWNARROW","DOWN"),"UPARROW","UP"),"LEFTARROW","LEFT"),"RIGHTARROW","RIGHT"),"ARROWDOWN","DOWN"),"ARROWUP","UP"),"ARROWLEFT","LEFT"),"ARROWRIGHT","RIGHT"),"↓","DOWN"),"↑","UP"),"←","LEFT"),"→","RIGHT"),"SPACEBAR","SPACE"),"−","-"),"MINUS","-"),"PLUS","+")=Key!$E$41:$E$41),"✔ CLEAR","✘ TRY AGAIN"))),"✘ TRY AGAIN")} | F19: {=IF(E19="Show hint",Key!$B$41,"")} | G19: {=IF(LEFT(D19,1)="✔",IF(E19="Show hint",5,10),0)} -> 0
A20: W9 | B20: Which keys reset a cell to the General format? (from S3-1 Number Skins) | D20: {=IFERROR(_xlfn.LET(_xlpm.a,'F4-3 Old School'!$C$20,IF(TRIM(_xlpm.a&"")="","",IF(OR(SUBSTITUTE(SUBSTITUTE(SUBSTITUTE(SUBSTITUTE(SUBSTITUTE(SUBSTITUTE(SUBSTITUTE(SUBSTITUTE(SUBSTITUTE(SUBSTITUTE(SUBSTITUTE(SUBSTITUTE(SUBSTITUTE(SUBSTITUTE(SUBSTITUTE(SUBSTITUTE(SUBSTITUTE(SUBSTITUTE(SUBSTITUTE(SUBSTITUTE(SUBSTITUTE(SUBSTITUTE(SUBSTITUTE(SUBSTITUTE(SUBSTITUTE(SUBSTITUTE(SUBSTITUTE(UPPER(_xlpm.a)," ",""),"CONTROL","CTRL"),"CTL","CTRL"),"ESCAPE","ESC"),"RETURN","ENTER"),"PAGEDOWN","PGDN"),"PGDOWN","PGDN"),"PAGEUP","PGUP"),"ARROWKEYS","ARROW"),"ARROWKEY","ARROW"),"ARROWS","ARROW"),"DOWNARROW","DOWN"),"UPARROW","UP"),"LEFTARROW","LEFT"),"RIGHTARROW","RIGHT"),"ARROWDOWN","DOWN"),"ARROWUP","UP"),"ARROWLEFT","LEFT"),"ARROWRIGHT","RIGHT"),"↓","DOWN"),"↑","UP"),"←","LEFT"),"→","RIGHT"),"SPACEBAR","SPACE"),"−","-"),"MINUS","-"),"PLUS","+")=Key!$E$42:$H$42),"✔ CLEAR","✘ TRY AGAIN"))),"✘ TRY AGAIN")} | F20: {=IF(E20="Show hint",Key!$B$42,"")} | G20: {=IF(LEFT(D20,1)="✔",IF(E20="Show hint",5,10),0)} -> 0
A21: W10 | B21: Which keys toggle bold? (from S3-2 Text Style) | D21: {=IFERROR(_xlfn.LET(_xlpm.a,'F4-3 Old School'!$C$21,IF(TRIM(_xlpm.a&"")="","",IF(OR(SUBSTITUTE(SUBSTITUTE(SUBSTITUTE(SUBSTITUTE(SUBSTITUTE(SUBSTITUTE(SUBSTITUTE(SUBSTITUTE(SUBSTITUTE(SUBSTITUTE(SUBSTITUTE(SUBSTITUTE(SUBSTITUTE(SUBSTITUTE(SUBSTITUTE(SUBSTITUTE(SUBSTITUTE(SUBSTITUTE(SUBSTITUTE(SUBSTITUTE(SUBSTITUTE(SUBSTITUTE(SUBSTITUTE(SUBSTITUTE(SUBSTITUTE(SUBSTITUTE(SUBSTITUTE(UPPER(_xlpm.a)," ",""),"CONTROL","CTRL"),"CTL","CTRL"),"ESCAPE","ESC"),"RETURN","ENTER"),"PAGEDOWN","PGDN"),"PGDOWN","PGDN"),"PAGEUP","PGUP"),"ARROWKEYS","ARROW"),"ARROWKEY","ARROW"),"ARROWS","ARROW"),"DOWNARROW","DOWN"),"UPARROW","UP"),"LEFTARROW","LEFT"),"RIGHTARROW","RIGHT"),"ARROWDOWN","DOWN"),"ARROWUP","UP"),"ARROWLEFT","LEFT"),"ARROWRIGHT","RIGHT"),"↓","DOWN"),"↑","UP"),"←","LEFT"),"→","RIGHT"),"SPACEBAR","SPACE"),"−","-"),"MINUS","-"),"PLUS","+")=Key!$E$43:$F$43),"✔ CLEAR","✘ TRY AGAIN"))),"✘ TRY AGAIN")} | F21: {=IF(E21="Show hint",Key!$B$43,"")} | G21: {=IF(LEFT(D21,1)="✔",IF(E21="Show hint",5,10),0)} -> 0
A23: TRAINING · recognize the move (pick from the list)
A24: # | B24: Mission | C24: Your answer | D24: Result | E24: Hint? | F24: Hint | G24: XP
A25: T1 | B25: Which classic function searches the first column of a table and returns a column by number? | D25: {=IFERROR(IF('F4-3 Old School'!$C$25&""="","",IF('F4-3 Old School'!$C$25&""=Key!$C$44&"","✔ CLEAR","✘ TRY AGAIN")),"✘ TRY AGAIN")} | F25: {=IF(E25="Show hint",Key!$B$44,"")} | G25: {=IF(LEFT(D25,1)="✔",IF(E25="Show hint",5,10),0)} -> 0
A26: T2 | B26: Which 4th argument makes VLOOKUP find an exact match? | D26: {=IFERROR(IF('F4-3 Old School'!$C$26&""="","",IF('F4-3 Old School'!$C$26&""=Key!$C$45&"","✔ CLEAR","✘ TRY AGAIN")),"✘ TRY AGAIN")} | F26: {=IF(E26="Show hint",Key!$B$45,"")} | G26: {=IF(LEFT(D26,1)="✔",IF(E26="Show hint",5,10),0)} -> 0
A28: CHALLENGES · recall it, then do it
B29: ▶ Open F4-3 Arena (or press Ctrl+PgDn)
A30: # | B30: Mission | C30: Your answer | D30: Result | E30: Hint? | F30: Hint | G30: XP
A31: C1 | B31: Which classic function searches the first column of a table and returns a column by number? | D31: {=IFERROR(_xlfn.LET(_xlpm.a,'F4-3 Old School'!$C$31,IF(TRIM(_xlpm.a&"")="","",IF(OR(SUBSTITUTE(SUBSTITUTE(SUBSTITUTE(SUBSTITUTE(SUBSTITUTE(SUBSTITUTE(SUBSTITUTE(SUBSTITUTE(SUBSTITUTE(SUBSTITUTE(SUBSTITUTE(SUBSTITUTE(SUBSTITUTE(SUBSTITUTE(SUBSTITUTE(SUBSTITUTE(SUBSTITUTE(SUBSTITUTE(SUBSTITUTE(SUBSTITUTE(SUBSTITUTE(SUBSTITUTE(SUBSTITUTE(SUBSTITUTE(SUBSTITUTE(SUBSTITUTE(SUBSTITUTE(UPPER(_xlpm.a)," ",""),"CONTROL","CTRL"),"CTL","CTRL"),"ESCAPE","ESC"),"RETURN","ENTER"),"PAGEDOWN","PGDN"),"PGDOWN","PGDN"),"PAGEUP","PGUP"),"ARROWKEYS","ARROW"),"ARROWKEY","ARROW"),"ARROWS","ARROW"),"DOWNARROW","DOWN"),"UPARROW","UP"),"LEFTARROW","LEFT"),"RIGHTARROW","RIGHT"),"ARROWDOWN","DOWN"),"ARROWUP","UP"),"ARROWLEFT","LEFT"),"ARROWRIGHT","RIGHT"),"↓","DOWN"),"↑","UP"),"←","LEFT"),"→","RIGHT"),"SPACEBAR","SPACE"),"−","-"),"MINUS","-"),"PLUS","+")=Key!$E$46:$J$46),"✔ CLEAR","✘ TRY AGAIN"))),"✘ TRY AGAIN")} | F31: {=IF(E31="Show hint",Key!$B$46,"")} | G31: {=IF(LEFT(D31,1)="✔",IF(E31="Show hint",5,10),0)} -> 0
A32: C2 | B32: Which 4th argument makes VLOOKUP find an exact match? | D32: {=IFERROR(_xlfn.LET(_xlpm.a,'F4-3 Old School'!$C$32,IF(TRIM(_xlpm.a&"")="","",IF(OR(SUBSTITUTE(SUBSTITUTE(SUBSTITUTE(SUBSTITUTE(SUBSTITUTE(SUBSTITUTE(SUBSTITUTE(SUBSTITUTE(SUBSTITUTE(SUBSTITUTE(SUBSTITUTE(SUBSTITUTE(SUBSTITUTE(SUBSTITUTE(SUBSTITUTE(SUBSTITUTE(SUBSTITUTE(SUBSTITUTE(SUBSTITUTE(SUBSTITUTE(SUBSTITUTE(SUBSTITUTE(SUBSTITUTE(SUBSTITUTE(SUBSTITUTE(SUBSTITUTE(SUBSTITUTE(UPPER(_xlpm.a)," ",""),"CONTROL","CTRL"),"CTL","CTRL"),"ESCAPE","ESC"),"RETURN","ENTER"),"PAGEDOWN","PGDN"),"PGDOWN","PGDN"),"PAGEUP","PGUP"),"ARROWKEYS","ARROW"),"ARROWKEY","ARROW"),"ARROWS","ARROW"),"DOWNARROW","DOWN"),"UPARROW","UP"),"LEFTARROW","LEFT"),"RIGHTARROW","RIGHT"),"ARROWDOWN","DOWN"),"ARROWUP","UP"),"ARROWLEFT","LEFT"),"ARROWRIGHT","RIGHT"),"↓","DOWN"),"↑","UP"),"←","LEFT"),"→","RIGHT"),"SPACEBAR","SPACE"),"−","-"),"MINUS","-"),"PLUS","+")=Key!$E$47:$F$47),"✔ CLEAR","✘ TRY AGAIN"))),"✘ TRY AGAIN")} | F32: {=IF(E32="Show hint",Key!$B$47,"")} | G32: {=IF(LEFT(D32,1)="✔",IF(E32="Show hint",5,10),0)} -> 0
A33: C3 | B33: In J6 return the Category of the ID in I6 with =VLOOKUP(I6,B6:F20,3,FALSE). Category is the 3rd column of B:F. | C33: ▶ ARENA C3 (cell J6) | D33: {=IF(ISBLANK('F4-3 Arena'!$J$6),"",IF(NOT(_xlfn.ISFORMULA('F4-3 Arena'!$J$6)),"✘ That's a typed value · enter a formula",IF(ISERROR('F4-3 Arena'!$J$6),"✘ Your formula returns "&IFERROR(CHOOSE(ERROR.TYPE('F4-3 Arena'!$J$6),"#NULL!","#DIV/0!","#VALUE!","#REF!","#NAME?","#NUM!","#N/A","#GETTING_DATA","#SPILL!","#CONNECT!","#BLOCKED!","#UNKNOWN!","#FIELD!","#CALC!"),"an error"),IF(NOT(AND(IFERROR(AND(ISTEXT('F4-3 Arena'!$J$6),'F4-3 Arena'!$J$6=Key!$C$48),FALSE))),"✘ TRY AGAIN",IF(AND(OR(ISNUMBER(FIND({"=","(",",","+","-","*","/","&"," ","<",">",":","@","^"}&"VLOOKUP"&"(",UPPER(_xlfn.FORMULATEXT('F4-3 Arena'!$J$6)))))),"✔ CLEAR","✘ CLOSE · right value, but use VLOOKUP")))))} | F33: {=IF(E33="Show hint",Key!$B$48,"")} | G33: {=IF(LEFT(D33,1)="✔",IF(E33="Show hint",5,10),0)} -> 0
A34: C4 | B34: In J9 return the Stock of the ID in I9 with VLOOKUP. Stock is column 5 of B:F. | C34: ▶ ARENA C4 (cell J9) | D34: {=IF(ISBLANK('F4-3 Arena'!$J$9),"",IF(NOT(_xlfn.ISFORMULA('F4-3 Arena'!$J$9)),"✘ That's a typed value · enter a formula",IF(ISERROR('F4-3 Arena'!$J$9),"✘ Your formula returns "&IFERROR(CHOOSE(ERROR.TYPE('F4-3 Arena'!$J$9),"#NULL!","#DIV/0!","#VALUE!","#REF!","#NAME?","#NUM!","#N/A","#GETTING_DATA","#SPILL!","#CONNECT!","#BLOCKED!","#UNKNOWN!","#FIELD!","#CALC!"),"an error"),IF(NOT(AND(IFERROR(AND(ISNUMBER('F4-3 Arena'!$J$9),ABS('F4-3 Arena'!$J$9-Key!$C$49)<=1E-9*MAX(1,ABS(Key!$C$49))),FALSE))),"✘ TRY AGAIN",IF(AND(OR(ISNUMBER(FIND({"=","(",",","+","-","*","/","&"," ","<",">",":","@","^"}&"VLOOKUP"&"(",UPPER(_xlfn.FORMULATEXT('F4-3 Arena'!$J$9)))))),"✔ CLEAR","✘ CLOSE · right value, but use VLOOKUP")))))} | F34: {=IF(E34="Show hint",Key!$B$49,"")} | G34: {=IF(LEFT(D34,1)="✔",IF(E34="Show hint",5,10),0)} -> 0

Sheet F4-3 Arena
A1: ARENA ▸ F4-3 OLD SCHOOL
A2: Practice area · everything here is editable. Missions and their checks are on the stage sheet.
A3: PASS CODE | B3: CLASSIC | D3: ◀ Back to F4-3 Old School
B5: ID | C5: Product | D5: Category | E5: Price | F5: Stock | I5: Find ID | J5: Category
B6: P-01 | C6: Apple | D6: Fruit | E6: 0.5 | F6: 120 | I6: P-12
B7: P-02 | C7: Banana | D7: Fruit | E7: 0.25 | F7: 200
B8: P-03 | C8: Carrot | D8: Veg | E8: 0.3 | F8: 80 | I8: Find ID | J8: Stock
B9: P-04 | C9: Dragonfruit | D9: Fruit | E9: 3.5 | F9: 12 | I9: P-04
B10: P-05 | C10: Eggplant | D10: Veg | E10: 1.2 | F10: 30
B11: P-06 | C11: Fig | D11: Fruit | E11: 2 | F11: 25
B12: P-07 | C12: Garlic | D12: Veg | E12: 0.8 | F12: 60
B13: P-08 | C13: Honeydew | D13: Fruit | E13: 4 | F13: 8
B14: P-09 | C14: Iceberg | D14: Veg | E14: 1.5 | F14: 40
B15: P-10 | C15: Jalapeno | D15: Veg | E15: 0.2 | F15: 150
B16: P-11 | C16: Kiwi | D16: Fruit | E16: 0.6 | F16: 90
B17: P-12 | C17: Leek | D17: Veg | E17: 1.1 | F17: 35
B18: P-13 | C18: Mango | D18: Fruit | E18: 1.8 | F18: 45
