Workbook

Sheet Start
A1: FORMULAS 6 ▸ DATES
A2: Build, split and shift dates; count days and workdays.
A4: HOW TO PLAY
A5: 1 · Each stage: read the BRIEFING, then answer WARM-UP, TRAINING and CHALLENGES.
A6: 2 · Yellow cells are yours: type, pick from a list (Alt+↓), or follow a ▶ ARENA link and do the move there.
A7: 3 · ✔ CLEAR = right · ✘ = try again · · not yet = drill not done. Stuck? Pick 'Show hint' (5 XP instead of 10).
A8: 4 · Formatting or hiding drills: press F9 to refresh the check. Tab jumps between yellow cells.
A9: Needs Windows with Microsoft Excel 365 or 2021+ (English). In Protected View, click Enable Editing.
A11: STAGE SELECT
A12: Stage | B12: Name | C12: Score | D12: Stars | E12: Status | F12: Go
A13: F6-1 | B13: Calendar | C13: {=SUM('F6-1 Calendar'!$G$17:$G$53)&" / 300"} -> 0 / 300 | D13: {=IF(SUM('F6-1 Calendar'!$G$17:$G$53)>=300,"★★★",IF(SUM('F6-1 Calendar'!$G$17:$G$53)>=300*0.8,"★★☆",IF(SUM('F6-1 Calendar'!$G$17:$G$53)>=300*0.5,"★☆☆","☆☆☆")))} -> ☆☆☆ | E13: {=IF(SUM('F6-1 Calendar'!$G$17:$G$53)>=300,"PERFECT",IF(SUM('F6-1 Calendar'!$G$17:$G$53)>=300*0.5,"CLEARED",IF(SUM('F6-1 Calendar'!$G$17:$G$53)>0,"IN PROGRESS","NEW")))} -> NEW | F13: Go to F6-1 Calendar
A14: F6-2 | B14: Date Math | C14: {=SUM('F6-2 Date Math'!$G$13:$G$39)&" / 200"} -> 0 / 200 | D14: {=IF(SUM('F6-2 Date Math'!$G$13:$G$39)>=200,"★★★",IF(SUM('F6-2 Date Math'!$G$13:$G$39)>=200*0.8,"★★☆",IF(SUM('F6-2 Date Math'!$G$13:$G$39)>=200*0.5,"★☆☆","☆☆☆")))} -> ☆☆☆ | E14: {=IF(SUM('F6-2 Date Math'!$G$13:$G$39)>=200,"PERFECT",IF(SUM('F6-2 Date Math'!$G$13:$G$39)>=200*0.5,"CLEARED",IF(SUM('F6-2 Date Math'!$G$13:$G$39)>0,"IN PROGRESS","NEW")))} -> NEW | F14: Go to F6-2 Date Math
A15: F6-3 | B15: Deadlines | C15: {=SUM('F6-3 Deadlines'!$G$14:$G$42)&" / 220"} -> 0 / 220 | D15: {=IF(SUM('F6-3 Deadlines'!$G$14:$G$42)>=220,"★★★",IF(SUM('F6-3 Deadlines'!$G$14:$G$42)>=220*0.8,"★★☆",IF(SUM('F6-3 Deadlines'!$G$14:$G$42)>=220*0.5,"★☆☆","☆☆☆")))} -> ☆☆☆ | E15: {=IF(SUM('F6-3 Deadlines'!$G$14:$G$42)>=220,"PERFECT",IF(SUM('F6-3 Deadlines'!$G$14:$G$42)>=220*0.5,"CLEARED",IF(SUM('F6-3 Deadlines'!$G$14:$G$42)>0,"IN PROGRESS","NEW")))} -> NEW | F15: Go to F6-3 Deadlines
A16: BOSS | B16: Boss | C16: {=SUM(Boss!$G$14:$G$33)&" / 160"} -> 0 / 160 | D16: {=IF(SUM(Boss!$G$14:$G$33)>=160,"★★★",IF(SUM(Boss!$G$14:$G$33)>=160*0.8,"★★☆",IF(SUM(Boss!$G$14:$G$33)>=160*0.5,"★☆☆","☆☆☆")))} -> ☆☆☆ | E16: {=IF(Boss!$C$10="OPEN",IF(SUM(Boss!$G$14:$G$33)>=160*0.5,"DEFEATED","OPEN"),"LOCKED")} -> LOCKED | F16: Go to the Boss
A18: TOTAL SCORE | B18: {=(SUM('F6-1 Calendar'!$G$17:$G$53)+SUM('F6-2 Date Math'!$G$13:$G$39)+SUM('F6-3 Deadlines'!$G$14:$G$42)+SUM(Boss!$G$14:$G$33))&" / 880"} -> 0 / 880
A19: RANK | B19: {=_xlfn.LET(_xlpm.p,(SUM('F6-1 Calendar'!$G$17:$G$53)+SUM('F6-2 Date Math'!$G$13:$G$39)+SUM('F6-3 Deadlines'!$G$14:$G$42)+SUM(Boss!$G$14:$G$33))/880,IF(AND(_xlpm.p>=1,ISNUMBER(Boss!$C$8),Boss!$C$8<=12),"S",IF(_xlpm.p>=0.9,"A",IF(_xlpm.p>=0.75,"B",IF(_xlpm.p>=0.5,"C","D")))))} -> D | C19: S = 100% and under par · A ≥ 90% · B ≥ 75% · C ≥ 50%
A20: BEST TIME | B20: {=IF(ISNUMBER(Boss!$C$8),Boss!$C$8&" min (par 12)","—")} -> —
A21: NEXT UP | B21: {=IFERROR(INDEX($A$13:$A$15,MATCH("☆☆☆",$D$13:$D$15,0))&" "&INDEX($B$13:$B$15,MATCH("☆☆☆",$D$13:$D$15,0)),IF(Boss!$C$10="OPEN","the Boss","All clear! Aim for rank S"))} -> F6-1 Calendar
A23: Replay a stage: select its yellow answer cells and press Delete. Undo an arena drill with Ctrl+Z.

Sheet F6-1 Calendar
A1: STAGE F6-1 ▸ CALENDAR
A2: Goal: build dates and take them apart
A3: {="SCORE "&TEXT(SUM($G$17:$G$53),"0000")&" / 0300"} -> SCORE 0000 / 0300 | C3: {=IF(SUM($G$17:$G$53)>=300,"★★★",IF(SUM($G$17:$G$53)>=300*0.8,"★★☆",IF(SUM($G$17:$G$53)>=300*0.5,"★☆☆","☆☆☆")))} -> ☆☆☆ | D3: {=REPT("█",ROUND(10*SUM($G$17:$G$53)/300,0))&REPT("░",10-ROUND(10*SUM($G$17:$G$53)/300,0))&" "&TEXT(SUM($G$17:$G$53)/300,"0%")} -> ░░░░░░░░░░ 0% | F3: {=IF(SUM($G$17:$G$53)>=300*0.5,"STAGE CLEAR! ▶ Next: F6-2 Date Math","")}
A5: BRIEFING · new moves in this stage
A6: # | B6: What it does · Pro tip | C6: Keys / Syntax
A7: 1 | B7: =TODAY() is today's date; it updates every day. Tip: Use Ctrl+; instead when the date must never change. | C7: TODAY
A8: 2 | B8: =NOW() is today's date AND the current time. Tip: It updates on every recalc. | C8: NOW
A9: 3 | B9: DATE(year, month, day) builds a real date. Tip: =DATE(2026,7,4) is 4 July 2026. | C9: DATE
A10: 4 | B10: YEAR(date) returns the year number. Tip: =YEAR(B6) gives 2026. | C10: YEAR
A11: 5 | B11: MONTH(date) returns 1 to 12. Tip: =MONTH(B6) gives 3 for March. | C11: MONTH
A12: 6 | B12: DAY(date) returns the day of the month, 1 to 31. Tip: =DAY(B6) gives 15. | C12: DAY
A13: 7 | B13: WEEKDAY(date) returns 1 (Sunday) to 7 (Saturday). Tip: WEEKDAY(date,2) counts Monday as 1 instead. | C13: WEEKDAY
A15: WARM-UP · flashback to earlier stages
A16: # | B16: Mission | C16: Your answer | D16: Result | E16: Hint? | F16: Hint | G16: XP
A17: W1 | B17: Which function removes extra spaces from text? (from F5-2 Clean Up) | D17: {=IFERROR(_xlfn.LET(_xlpm.a,'F6-1 Calendar'!$C$17,IF(TRIM(_xlpm.a&"")="","",IF(OR(SUBSTITUTE(SUBSTITUTE(SUBSTITUTE(SUBSTITUTE(SUBSTITUTE(SUBSTITUTE(SUBSTITUTE(SUBSTITUTE(SUBSTITUTE(SUBSTITUTE(SUBSTITUTE(SUBSTITUTE(SUBSTITUTE(SUBSTITUTE(SUBSTITUTE(SUBSTITUTE(SUBSTITUTE(SUBSTITUTE(SUBSTITUTE(SUBSTITUTE(SUBSTITUTE(SUBSTITUTE(SUBSTITUTE(SUBSTITUTE(SUBSTITUTE(SUBSTITUTE(SUBSTITUTE(UPPER(_xlpm.a)," ",""),"CONTROL","CTRL"),"CTL","CTRL"),"ESCAPE","ESC"),"RETURN","ENTER"),"PAGEDOWN","PGDN"),"PGDOWN","PGDN"),"PAGEUP","PGUP"),"ARROWKEYS","ARROW"),"ARROWKEY","ARROW"),"ARROWS","ARROW"),"DOWNARROW","DOWN"),"UPARROW","UP"),"LEFTARROW","LEFT"),"RIGHTARROW","RIGHT"),"ARROWDOWN","DOWN"),"ARROWUP","UP"),"ARROWLEFT","LEFT"),"ARROWRIGHT","RIGHT"),"↓","DOWN"),"↑","UP"),"←","LEFT"),"→","RIGHT"),"SPACEBAR","SPACE"),"−","-"),"MINUS","-"),"PLUS","+")=Key!$E$2:$J$2),"✔ CLEAR","✘ TRY AGAIN"))),"✘ TRY AGAIN")} | F17: {=IF(E17="Show hint",Key!$B$2,"")} | G17: {=IF(LEFT(D17,1)="✔",IF(E17="Show hint",5,10),0)} -> 0
A18: W2 | B18: Which function converts text to all capitals? (from F5-2 Clean Up) | D18: {=IFERROR(_xlfn.LET(_xlpm.a,'F6-1 Calendar'!$C$18,IF(TRIM(_xlpm.a&"")="","",IF(OR(SUBSTITUTE(SUBSTITUTE(SUBSTITUTE(SUBSTITUTE(SUBSTITUTE(SUBSTITUTE(SUBSTITUTE(SUBSTITUTE(SUBSTITUTE(SUBSTITUTE(SUBSTITUTE(SUBSTITUTE(SUBSTITUTE(SUBSTITUTE(SUBSTITUTE(SUBSTITUTE(SUBSTITUTE(SUBSTITUTE(SUBSTITUTE(SUBSTITUTE(SUBSTITUTE(SUBSTITUTE(SUBSTITUTE(SUBSTITUTE(SUBSTITUTE(SUBSTITUTE(SUBSTITUTE(UPPER(_xlpm.a)," ",""),"CONTROL","CTRL"),"CTL","CTRL"),"ESCAPE","ESC"),"RETURN","ENTER"),"PAGEDOWN","PGDN"),"PGDOWN","PGDN"),"PAGEUP","PGUP"),"ARROWKEYS","ARROW"),"ARROWKEY","ARROW"),"ARROWS","ARROW"),"DOWNARROW","DOWN"),"UPARROW","UP"),"LEFTARROW","LEFT"),"RIGHTARROW","RIGHT"),"ARROWDOWN","DOWN"),"ARROWUP","UP"),"ARROWLEFT","LEFT"),"ARROWRIGHT","RIGHT"),"↓","DOWN"),"↑","UP"),"←","LEFT"),"→","RIGHT"),"SPACEBAR","SPACE"),"−","-"),"MINUS","-"),"PLUS","+")=Key!$E$3:$J$3),"✔ CLEAR","✘ TRY AGAIN"))),"✘ TRY AGAIN")} | F18: {=IF(E18="Show hint",Key!$B$3,"")} | G18: {=IF(LEFT(D18,1)="✔",IF(E18="Show hint",5,10),0)} -> 0
A19: W3 | B19: Which function converts text to all lowercase? (from F5-2 Clean Up) | D19: {=IFERROR(_xlfn.LET(_xlpm.a,'F6-1 Calendar'!$C$19,IF(TRIM(_xlpm.a&"")="","",IF(OR(SUBSTITUTE(SUBSTITUTE(SUBSTITUTE(SUBSTITUTE(SUBSTITUTE(SUBSTITUTE(SUBSTITUTE(SUBSTITUTE(SUBSTITUTE(SUBSTITUTE(SUBSTITUTE(SUBSTITUTE(SUBSTITUTE(SUBSTITUTE(SUBSTITUTE(SUBSTITUTE(SUBSTITUTE(SUBSTITUTE(SUBSTITUTE(SUBSTITUTE(SUBSTITUTE(SUBSTITUTE(SUBSTITUTE(SUBSTITUTE(SUBSTITUTE(SUBSTITUTE(SUBSTITUTE(UPPER(_xlpm.a)," ",""),"CONTROL","CTRL"),"CTL","CTRL"),"ESCAPE","ESC"),"RETURN","ENTER"),"PAGEDOWN","PGDN"),"PGDOWN","PGDN"),"PAGEUP","PGUP"),"ARROWKEYS","ARROW"),"ARROWKEY","ARROW"),"ARROWS","ARROW"),"DOWNARROW","DOWN"),"UPARROW","UP"),"LEFTARROW","LEFT"),"RIGHTARROW","RIGHT"),"ARROWDOWN","DOWN"),"ARROWUP","UP"),"ARROWLEFT","LEFT"),"ARROWRIGHT","RIGHT"),"↓","DOWN"),"↑","UP"),"←","LEFT"),"→","RIGHT"),"SPACEBAR","SPACE"),"−","-"),"MINUS","-"),"PLUS","+")=Key!$E$4:$J$4),"✔ CLEAR","✘ TRY AGAIN"))),"✘ TRY AGAIN")} | F19: {=IF(E19="Show hint",Key!$B$4,"")} | G19: {=IF(LEFT(D19,1)="✔",IF(E19="Show hint",5,10),0)} -> 0
A20: W4 | B20: Which function capitalizes the first letter of each word? (from F5-2 Clean Up) | D20: {=IFERROR(_xlfn.LET(_xlpm.a,'F6-1 Calendar'!$C$20,IF(TRIM(_xlpm.a&"")="","",IF(OR(SUBSTITUTE(SUBSTITUTE(SUBSTITUTE(SUBSTITUTE(SUBSTITUTE(SUBSTITUTE(SUBSTITUTE(SUBSTITUTE(SUBSTITUTE(SUBSTITUTE(SUBSTITUTE(SUBSTITUTE(SUBSTITUTE(SUBSTITUTE(SUBSTITUTE(SUBSTITUTE(SUBSTITUTE(SUBSTITUTE(SUBSTITUTE(SUBSTITUTE(SUBSTITUTE(SUBSTITUTE(SUBSTITUTE(SUBSTITUTE(SUBSTITUTE(SUBSTITUTE(SUBSTITUTE(UPPER(_xlpm.a)," ",""),"CONTROL","CTRL"),"CTL","CTRL"),"ESCAPE","ESC"),"RETURN","ENTER"),"PAGEDOWN","PGDN"),"PGDOWN","PGDN"),"PAGEUP","PGUP"),"ARROWKEYS","ARROW"),"ARROWKEY","ARROW"),"ARROWS","ARROW"),"DOWNARROW","DOWN"),"UPARROW","UP"),"LEFTARROW","LEFT"),"RIGHTARROW","RIGHT"),"ARROWDOWN","DOWN"),"ARROWUP","UP"),"ARROWLEFT","LEFT"),"ARROWRIGHT","RIGHT"),"↓","DOWN"),"↑","UP"),"←","LEFT"),"→","RIGHT"),"SPACEBAR","SPACE"),"−","-"),"MINUS","-"),"PLUS","+")=Key!$E$5:$J$5),"✔ CLEAR","✘ TRY AGAIN"))),"✘ TRY AGAIN")} | F20: {=IF(E20="Show hint",Key!$B$5,"")} | G20: {=IF(LEFT(D20,1)="✔",IF(E20="Show hint",5,10),0)} -> 0
A21: W5 | B21: Which function replaces every occurrence of some text with other text? (from F5-2 Clean Up) | D21: {=IFERROR(_xlfn.LET(_xlpm.a,'F6-1 Calendar'!$C$21,IF(TRIM(_xlpm.a&"")="","",IF(OR(SUBSTITUTE(SUBSTITUTE(SUBSTITUTE(SUBSTITUTE(SUBSTITUTE(SUBSTITUTE(SUBSTITUTE(SUBSTITUTE(SUBSTITUTE(SUBSTITUTE(SUBSTITUTE(SUBSTITUTE(SUBSTITUTE(SUBSTITUTE(SUBSTITUTE(SUBSTITUTE(SUBSTITUTE(SUBSTITUTE(SUBSTITUTE(SUBSTITUTE(SUBSTITUTE(SUBSTITUTE(SUBSTITUTE(SUBSTITUTE(SUBSTITUTE(SUBSTITUTE(SUBSTITUTE(UPPER(_xlpm.a)," ",""),"CONTROL","CTRL"),"CTL","CTRL"),"ESCAPE","ESC"),"RETURN","ENTER"),"PAGEDOWN","PGDN"),"PGDOWN","PGDN"),"PAGEUP","PGUP"),"ARROWKEYS","ARROW"),"ARROWKEY","ARROW"),"ARROWS","ARROW"),"DOWNARROW","DOWN"),"UPARROW","UP"),"LEFTARROW","LEFT"),"RIGHTARROW","RIGHT"),"ARROWDOWN","DOWN"),"ARROWUP","UP"),"ARROWLEFT","LEFT"),"ARROWRIGHT","RIGHT"),"↓","DOWN"),"↑","UP"),"←","LEFT"),"→","RIGHT"),"SPACEBAR","SPACE"),"−","-"),"MINUS","-"),"PLUS","+")=Key!$E$6:$J$6),"✔ CLEAR","✘ TRY AGAIN"))),"✘ TRY AGAIN")} | F21: {=IF(E21="Show hint",Key!$B$6,"")} | G21: {=IF(LEFT(D21,1)="✔",IF(E21="Show hint",5,10),0)} -> 0
A22: W6 | B22: Which keys open Find and Replace on the Replace tab? (from S4-3 Detective) | D22: {=IFERROR(_xlfn.LET(_xlpm.a,'F6-1 Calendar'!$C$22,IF(TRIM(_xlpm.a&"")="","",IF(OR(SUBSTITUTE(SUBSTITUTE(SUBSTITUTE(SUBSTITUTE(SUBSTITUTE(SUBSTITUTE(SUBSTITUTE(SUBSTITUTE(SUBSTITUTE(SUBSTITUTE(SUBSTITUTE(SUBSTITUTE(SUBSTITUTE(SUBSTITUTE(SUBSTITUTE(SUBSTITUTE(SUBSTITUTE(SUBSTITUTE(SUBSTITUTE(SUBSTITUTE(SUBSTITUTE(SUBSTITUTE(SUBSTITUTE(SUBSTITUTE(SUBSTITUTE(SUBSTITUTE(SUBSTITUTE(UPPER(_xlpm.a)," ",""),"CONTROL","CTRL"),"CTL","CTRL"),"ESCAPE","ESC"),"RETURN","ENTER"),"PAGEDOWN","PGDN"),"PGDOWN","PGDN"),"PAGEUP","PGUP"),"ARROWKEYS","ARROW"),"ARROWKEY","ARROW"),"ARROWS","ARROW"),"DOWNARROW","DOWN"),"UPARROW","UP"),"LEFTARROW","LEFT"),"RIGHTARROW","RIGHT"),"ARROWDOWN","DOWN"),"ARROWUP","UP"),"ARROWLEFT","LEFT"),"ARROWRIGHT","RIGHT"),"↓","DOWN"),"↑","UP"),"←","LEFT"),"→","RIGHT"),"SPACEBAR","SPACE"),"−","-"),"MINUS","-"),"PLUS","+")=Key!$E$7:$E$7),"✔ CLEAR","✘ TRY AGAIN"))),"✘ TRY AGAIN")} | F22: {=IF(E22="Show hint",Key!$B$7,"")} | G22: {=IF(LEFT(D22,1)="✔",IF(E22="Show hint",5,10),0)} -> 0
A23: W7 | B23: Which keys turn filter buttons on and off? (from S4-4 Data Wrangler) | D23: {=IFERROR(_xlfn.LET(_xlpm.a,'F6-1 Calendar'!$C$23,IF(TRIM(_xlpm.a&"")="","",IF(OR(SUBSTITUTE(SUBSTITUTE(SUBSTITUTE(SUBSTITUTE(SUBSTITUTE(SUBSTITUTE(SUBSTITUTE(SUBSTITUTE(SUBSTITUTE(SUBSTITUTE(SUBSTITUTE(SUBSTITUTE(SUBSTITUTE(SUBSTITUTE(SUBSTITUTE(SUBSTITUTE(SUBSTITUTE(SUBSTITUTE(SUBSTITUTE(SUBSTITUTE(SUBSTITUTE(SUBSTITUTE(SUBSTITUTE(SUBSTITUTE(SUBSTITUTE(SUBSTITUTE(SUBSTITUTE(UPPER(_xlpm.a)," ",""),"CONTROL","CTRL"),"CTL","CTRL"),"ESCAPE","ESC"),"RETURN","ENTER"),"PAGEDOWN","PGDN"),"PGDOWN","PGDN"),"PAGEUP","PGUP"),"ARROWKEYS","ARROW"),"ARROWKEY","ARROW"),"ARROWS","ARROW"),"DOWNARROW","DOWN"),"UPARROW","UP"),"LEFTARROW","LEFT"),"RIGHTARROW","RIGHT"),"ARROWDOWN","DOWN"),"ARROWUP","UP"),"ARROWLEFT","LEFT"),"ARROWRIGHT","RIGHT"),"↓","DOWN"),"↑","UP"),"←","LEFT"),"→","RIGHT"),"SPACEBAR","SPACE"),"−","-"),"MINUS","-"),"PLUS","+")=Key!$E$8:$F$8),"✔ CLEAR","✘ TRY AGAIN"))),"✘ TRY AGAIN")} | F23: {=IF(E23="Show hint",Key!$B$8,"")} | G23: {=IF(LEFT(D23,1)="✔",IF(E23="Show hint",5,10),0)} -> 0
A24: W8 | B24: Which keys open the filter menu of a header cell? (from S4-4 Data Wrangler) | D24: {=IFERROR(_xlfn.LET(_xlpm.a,'F6-1 Calendar'!$C$24,IF(TRIM(_xlpm.a&"")="","",IF(OR(SUBSTITUTE(SUBSTITUTE(SUBSTITUTE(SUBSTITUTE(SUBSTITUTE(SUBSTITUTE(SUBSTITUTE(SUBSTITUTE(SUBSTITUTE(SUBSTITUTE(SUBSTITUTE(SUBSTITUTE(SUBSTITUTE(SUBSTITUTE(SUBSTITUTE(SUBSTITUTE(SUBSTITUTE(SUBSTITUTE(SUBSTITUTE(SUBSTITUTE(SUBSTITUTE(SUBSTITUTE(SUBSTITUTE(SUBSTITUTE(SUBSTITUTE(SUBSTITUTE(SUBSTITUTE(UPPER(_xlpm.a)," ",""),"CONTROL","CTRL"),"CTL","CTRL"),"ESCAPE","ESC"),"RETURN","ENTER"),"PAGEDOWN","PGDN"),"PGDOWN","PGDN"),"PAGEUP","PGUP"),"ARROWKEYS","ARROW"),"ARROWKEY","ARROW"),"ARROWS","ARROW"),"DOWNARROW","DOWN"),"UPARROW","UP"),"LEFTARROW","LEFT"),"RIGHTARROW","RIGHT"),"ARROWDOWN","DOWN"),"ARROWUP","UP"),"ARROWLEFT","LEFT"),"ARROWRIGHT","RIGHT"),"↓","DOWN"),"↑","UP"),"←","LEFT"),"→","RIGHT"),"SPACEBAR","SPACE"),"−","-"),"MINUS","-"),"PLUS","+")=Key!$E$9:$E$9),"✔ CLEAR","✘ TRY AGAIN"))),"✘ TRY AGAIN")} | F24: {=IF(E24="Show hint",Key!$B$9,"")} | G24: {=IF(LEFT(D24,1)="✔",IF(E24="Show hint",5,10),0)} -> 0
A25: W9 | B25: Which keys turn a range into a Table? (from S4-4 Data Wrangler) | D25: {=IFERROR(_xlfn.LET(_xlpm.a,'F6-1 Calendar'!$C$25,IF(TRIM(_xlpm.a&"")="","",IF(OR(SUBSTITUTE(SUBSTITUTE(SUBSTITUTE(SUBSTITUTE(SUBSTITUTE(SUBSTITUTE(SUBSTITUTE(SUBSTITUTE(SUBSTITUTE(SUBSTITUTE(SUBSTITUTE(SUBSTITUTE(SUBSTITUTE(SUBSTITUTE(SUBSTITUTE(SUBSTITUTE(SUBSTITUTE(SUBSTITUTE(SUBSTITUTE(SUBSTITUTE(SUBSTITUTE(SUBSTITUTE(SUBSTITUTE(SUBSTITUTE(SUBSTITUTE(SUBSTITUTE(SUBSTITUTE(UPPER(_xlpm.a)," ",""),"CONTROL","CTRL"),"CTL","CTRL"),"ESCAPE","ESC"),"RETURN","ENTER"),"PAGEDOWN","PGDN"),"PGDOWN","PGDN"),"PAGEUP","PGUP"),"ARROWKEYS","ARROW"),"ARROWKEY","ARROW"),"ARROWS","ARROW"),"DOWNARROW","DOWN"),"UPARROW","UP"),"LEFTARROW","LEFT"),"RIGHTARROW","RIGHT"),"ARROWDOWN","DOWN"),"ARROWUP","UP"),"ARROWLEFT","LEFT"),"ARROWRIGHT","RIGHT"),"↓","DOWN"),"↑","UP"),"←","LEFT"),"→","RIGHT"),"SPACEBAR","SPACE"),"−","-"),"MINUS","-"),"PLUS","+")=Key!$E$10:$F$10),"✔ CLEAR","✘ TRY AGAIN"))),"✘ TRY AGAIN")} | F25: {=IF(E25="Show hint",Key!$B$10,"")} | G25: {=IF(LEFT(D25,1)="✔",IF(E25="Show hint",5,10),0)} -> 0
A26: W10 | B26: Which KeyTips sort A to Z? (from S4-4 Data Wrangler) | D26: {=IFERROR(_xlfn.LET(_xlpm.a,'F6-1 Calendar'!$C$26,IF(TRIM(_xlpm.a&"")="","",IF(OR(SUBSTITUTE(SUBSTITUTE(SUBSTITUTE(SUBSTITUTE(SUBSTITUTE(SUBSTITUTE(SUBSTITUTE(SUBSTITUTE(SUBSTITUTE(SUBSTITUTE(SUBSTITUTE(SUBSTITUTE(SUBSTITUTE(SUBSTITUTE(SUBSTITUTE(SUBSTITUTE(SUBSTITUTE(SUBSTITUTE(SUBSTITUTE(SUBSTITUTE(SUBSTITUTE(SUBSTITUTE(SUBSTITUTE(SUBSTITUTE(SUBSTITUTE(SUBSTITUTE(SUBSTITUTE(UPPER(_xlpm.a)," ",""),"CONTROL","CTRL"),"CTL","CTRL"),"ESCAPE","ESC"),"RETURN","ENTER"),"PAGEDOWN","PGDN"),"PGDOWN","PGDN"),"PAGEUP","PGUP"),"ARROWKEYS","ARROW"),"ARROWKEY","ARROW"),"ARROWS","ARROW"),"DOWNARROW","DOWN"),"UPARROW","UP"),"LEFTARROW","LEFT"),"RIGHTARROW","RIGHT"),"ARROWDOWN","DOWN"),"ARROWUP","UP"),"ARROWLEFT","LEFT"),"ARROWRIGHT","RIGHT"),"↓","DOWN"),"↑","UP"),"←","LEFT"),"→","RIGHT"),"SPACEBAR","SPACE"),"−","-"),"MINUS","-"),"PLUS","+")=Key!$E$11:$T$11),"✔ CLEAR","✘ TRY AGAIN"))),"✘ TRY AGAIN")} | F26: {=IF(E26="Show hint",Key!$B$11,"")} | G26: {=IF(LEFT(D26,1)="✔",IF(E26="Show hint",5,10),0)} -> 0
A28: TRAINING · recognize the move (pick from the list)
A29: # | B29: Mission | C29: Your answer | D29: Result | E29: Hint? | F29: Hint | G29: XP
A30: T1 | B30: Which function returns today's date? | D30: {=IFERROR(IF('F6-1 Calendar'!$C$30&""="","",IF('F6-1 Calendar'!$C$30&""=Key!$C$12&"","✔ CLEAR","✘ TRY AGAIN")),"✘ TRY AGAIN")} | F30: {=IF(E30="Show hint",Key!$B$12,"")} | G30: {=IF(LEFT(D30,1)="✔",IF(E30="Show hint",5,10),0)} -> 0
A31: T2 | B31: Which function returns the current date and time? | D31: {=IFERROR(IF('F6-1 Calendar'!$C$31&""="","",IF('F6-1 Calendar'!$C$31&""=Key!$C$13&"","✔ CLEAR","✘ TRY AGAIN")),"✘ TRY AGAIN")} | F31: {=IF(E31="Show hint",Key!$B$13,"")} | G31: {=IF(LEFT(D31,1)="✔",IF(E31="Show hint",5,10),0)} -> 0
A32: T3 | B32: Which function builds a date from a year, month and day? | D32: {=IFERROR(IF('F6-1 Calendar'!$C$32&""="","",IF('F6-1 Calendar'!$C$32&""=Key!$C$14&"","✔ CLEAR","✘ TRY AGAIN")),"✘ TRY AGAIN")} | F32: {=IF(E32="Show hint",Key!$B$14,"")} | G32: {=IF(LEFT(D32,1)="✔",IF(E32="Show hint",5,10),0)} -> 0
A33: T4 | B33: Which function returns the year of a date? | D33: {=IFERROR(IF('F6-1 Calendar'!$C$33&""="","",IF('F6-1 Calendar'!$C$33&""=Key!$C$15&"","✔ CLEAR","✘ TRY AGAIN")),"✘ TRY AGAIN")} | F33: {=IF(E33="Show hint",Key!$B$15,"")} | G33: {=IF(LEFT(D33,1)="✔",IF(E33="Show hint",5,10),0)} -> 0
A34: T5 | B34: Which function returns the month number of a date? | D34: {=IFERROR(IF('F6-1 Calendar'!$C$34&""="","",IF('F6-1 Calendar'!$C$34&""=Key!$C$16&"","✔ CLEAR","✘ TRY AGAIN")),"✘ TRY AGAIN")} | F34: {=IF(E34="Show hint",Key!$B$16,"")} | G34: {=IF(LEFT(D34,1)="✔",IF(E34="Show hint",5,10),0)} -> 0
A35: T6 | B35: Which function returns the day of the month? | D35: {=IFERROR(IF('F6-1 Calendar'!$C$35&""="","",IF('F6-1 Calendar'!$C$35&""=Key!$C$17&"","✔ CLEAR","✘ TRY AGAIN")),"✘ TRY AGAIN")} | F35: {=IF(E35="Show hint",Key!$B$17,"")} | G35: {=IF(LEFT(D35,1)="✔",IF(E35="Show hint",5,10),0)} -> 0
A36: T7 | B36: Which function returns the day of the week as a number? | D36: {=IFERROR(IF('F6-1 Calendar'!$C$36&""="","",IF('F6-1 Calendar'!$C$36&""=Key!$C$18&"","✔ CLEAR","✘ TRY AGAIN")),"✘ TRY AGAIN")} | F36: {=IF(E36="Show hint",Key!$B$18,"")} | G36: {=IF(LEFT(D36,1)="✔",IF(E36="Show hint",5,10),0)} -> 0
A38: CHALLENGES · recall it, then do it
B39: ▶ Open F6-1 Arena (or press Ctrl+PgDn)
A40: # | B40: Mission | C40: Your answer | D40: Result | E40: Hint? | F40: Hint | G40: XP
A41: C1 | B41: Which function returns today's date? | D41: {=IFERROR(_xlfn.LET(_xlpm.a,'F6-1 Calendar'!$C$41,IF(TRIM(_xlpm.a&"")="","",IF(OR(SUBSTITUTE(SUBSTITUTE(SUBSTITUTE(SUBSTITUTE(SUBSTITUTE(SUBSTITUTE(SUBSTITUTE(SUBSTITUTE(SUBSTITUTE(SUBSTITUTE(SUBSTITUTE(SUBSTITUTE(SUBSTITUTE(SUBSTITUTE(SUBSTITUTE(SUBSTITUTE(SUBSTITUTE(SUBSTITUTE(SUBSTITUTE(SUBSTITUTE(SUBSTITUTE(SUBSTITUTE(SUBSTITUTE(SUBSTITUTE(SUBSTITUTE(SUBSTITUTE(SUBSTITUTE(UPPER(_xlpm.a)," ",""),"CONTROL","CTRL"),"CTL","CTRL"),"ESCAPE","ESC"),"RETURN","ENTER"),"PAGEDOWN","PGDN"),"PGDOWN","PGDN"),"PAGEUP","PGUP"),"ARROWKEYS","ARROW"),"ARROWKEY","ARROW"),"ARROWS","ARROW"),"DOWNARROW","DOWN"),"UPARROW","UP"),"LEFTARROW","LEFT"),"RIGHTARROW","RIGHT"),"ARROWDOWN","DOWN"),"ARROWUP","UP"),"ARROWLEFT","LEFT"),"ARROWRIGHT","RIGHT"),"↓","DOWN"),"↑","UP"),"←","LEFT"),"→","RIGHT"),"SPACEBAR","SPACE"),"−","-"),"MINUS","-"),"PLUS","+")=Key!$E$19:$J$19),"✔ CLEAR","✘ TRY AGAIN"))),"✘ TRY AGAIN")} | F41: {=IF(E41="Show hint",Key!$B$19,"")} | G41: {=IF(LEFT(D41,1)="✔",IF(E41="Show hint",5,10),0)} -> 0
A42: C2 | B42: Which function returns the current date and time? | D42: {=IFERROR(_xlfn.LET(_xlpm.a,'F6-1 Calendar'!$C$42,IF(TRIM(_xlpm.a&"")="","",IF(OR(SUBSTITUTE(SUBSTITUTE(SUBSTITUTE(SUBSTITUTE(SUBSTITUTE(SUBSTITUTE(SUBSTITUTE(SUBSTITUTE(SUBSTITUTE(SUBSTITUTE(SUBSTITUTE(SUBSTITUTE(SUBSTITUTE(SUBSTITUTE(SUBSTITUTE(SUBSTITUTE(SUBSTITUTE(SUBSTITUTE(SUBSTITUTE(SUBSTITUTE(SUBSTITUTE(SUBSTITUTE(SUBSTITUTE(SUBSTITUTE(SUBSTITUTE(SUBSTITUTE(SUBSTITUTE(UPPER(_xlpm.a)," ",""),"CONTROL","CTRL"),"CTL","CTRL"),"ESCAPE","ESC"),"RETURN","ENTER"),"PAGEDOWN","PGDN"),"PGDOWN","PGDN"),"PAGEUP","PGUP"),"ARROWKEYS","ARROW"),"ARROWKEY","ARROW"),"ARROWS","ARROW"),"DOWNARROW","DOWN"),"UPARROW","UP"),"LEFTARROW","LEFT"),"RIGHTARROW","RIGHT"),"ARROWDOWN","DOWN"),"ARROWUP","UP"),"ARROWLEFT","LEFT"),"ARROWRIGHT","RIGHT"),"↓","DOWN"),"↑","UP"),"←","LEFT"),"→","RIGHT"),"SPACEBAR","SPACE"),"−","-"),"MINUS","-"),"PLUS","+")=Key!$E$20:$J$20),"✔ CLEAR","✘ TRY AGAIN"))),"✘ TRY AGAIN")} | F42: {=IF(E42="Show hint",Key!$B$20,"")} | G42: {=IF(LEFT(D42,1)="✔",IF(E42="Show hint",5,10),0)} -> 0
A43: C3 | B43: Which function builds a date from a year, month and day? | D43: {=IFERROR(_xlfn.LET(_xlpm.a,'F6-1 Calendar'!$C$43,IF(TRIM(_xlpm.a&"")="","",IF(OR(SUBSTITUTE(SUBSTITUTE(SUBSTITUTE(SUBSTITUTE(SUBSTITUTE(SUBSTITUTE(SUBSTITUTE(SUBSTITUTE(SUBSTITUTE(SUBSTITUTE(SUBSTITUTE(SUBSTITUTE(SUBSTITUTE(SUBSTITUTE(SUBSTITUTE(SUBSTITUTE(SUBSTITUTE(SUBSTITUTE(SUBSTITUTE(SUBSTITUTE(SUBSTITUTE(SUBSTITUTE(SUBSTITUTE(SUBSTITUTE(SUBSTITUTE(SUBSTITUTE(SUBSTITUTE(UPPER(_xlpm.a)," ",""),"CONTROL","CTRL"),"CTL","CTRL"),"ESCAPE","ESC"),"RETURN","ENTER"),"PAGEDOWN","PGDN"),"PGDOWN","PGDN"),"PAGEUP","PGUP"),"ARROWKEYS","ARROW"),"ARROWKEY","ARROW"),"ARROWS","ARROW"),"DOWNARROW","DOWN"),"UPARROW","UP"),"LEFTARROW","LEFT"),"RIGHTARROW","RIGHT"),"ARROWDOWN","DOWN"),"ARROWUP","UP"),"ARROWLEFT","LEFT"),"ARROWRIGHT","RIGHT"),"↓","DOWN"),"↑","UP"),"←","LEFT"),"→","RIGHT"),"SPACEBAR","SPACE"),"−","-"),"MINUS","-"),"PLUS","+")=Key!$E$21:$J$21),"✔ CLEAR","✘ TRY AGAIN"))),"✘ TRY AGAIN")} | F43: {=IF(E43="Show hint",Key!$B$21,"")} | G43: {=IF(LEFT(D43,1)="✔",IF(E43="Show hint",5,10),0)} -> 0
A44: C4 | B44: Which function returns the year of a date? | D44: {=IFERROR(_xlfn.LET(_xlpm.a,'F6-1 Calendar'!$C$44,IF(TRIM(_xlpm.a&"")="","",IF(OR(SUBSTITUTE(SUBSTITUTE(SUBSTITUTE(SUBSTITUTE(SUBSTITUTE(SUBSTITUTE(SUBSTITUTE(SUBSTITUTE(SUBSTITUTE(SUBSTITUTE(SUBSTITUTE(SUBSTITUTE(SUBSTITUTE(SUBSTITUTE(SUBSTITUTE(SUBSTITUTE(SUBSTITUTE(SUBSTITUTE(SUBSTITUTE(SUBSTITUTE(SUBSTITUTE(SUBSTITUTE(SUBSTITUTE(SUBSTITUTE(SUBSTITUTE(SUBSTITUTE(SUBSTITUTE(UPPER(_xlpm.a)," ",""),"CONTROL","CTRL"),"CTL","CTRL"),"ESCAPE","ESC"),"RETURN","ENTER"),"PAGEDOWN","PGDN"),"PGDOWN","PGDN"),"PAGEUP","PGUP"),"ARROWKEYS","ARROW"),"ARROWKEY","ARROW"),"ARROWS","ARROW"),"DOWNARROW","DOWN"),"UPARROW","UP"),"LEFTARROW","LEFT"),"RIGHTARROW","RIGHT"),"ARROWDOWN","DOWN"),"ARROWUP","UP"),"ARROWLEFT","LEFT"),"ARROWRIGHT","RIGHT"),"↓","DOWN"),"↑","UP"),"←","LEFT"),"→","RIGHT"),"SPACEBAR","SPACE"),"−","-"),"MINUS","-"),"PLUS","+")=Key!$E$22:$J$22),"✔ CLEAR","✘ TRY AGAIN"))),"✘ TRY AGAIN")} | F44: {=IF(E44="Show hint",Key!$B$22,"")} | G44: {=IF(LEFT(D44,1)="✔",IF(E44="Show hint",5,10),0)} -> 0
...

Sheet F6-1 Arena
A1: ARENA ▸ F6-1 CALENDAR
A2: Practice area · everything here is editable. Missions and their checks are on the stage sheet.
A3: PASS CODE | B3: CALENDAR | D3: ◀ Back to F6-1 Calendar
B5: Date | C5: Task
B6: 46096 | C6: Today
C7: Build 4 July 2026
C8: Year of B6
C9: Month of B6
C10: Day of B6
C11: Weekday of B6

Sheet F6-2 Date Math
A1: STAGE F6-2 ▸ DATE MATH
A2: Goal: add, subtract and measure dates
A3: {="SCORE "&TEXT(SUM($G$13:$G$39),"0000")&" / 0200"} -> SCORE 0000 / 0200 | C3: {=IF(SUM($G$13:$G$39)>=200,"★★★",IF(SUM($G$13:$G$39)>=200*0.8,"★★☆",IF(SUM($G$13:$G$39)>=200*0.5,"★☆☆","☆☆☆")))} -> ☆☆☆ | D3: {=REPT("█",ROUND(10*SUM($G$13:$G$39)/200,0))&REPT("░",10-ROUND(10*SUM($G$13:$G$39)/200,0))&" "&TEXT(SUM($G$13:$G$39)/200,"0%")} -> ░░░░░░░░░░ 0% | F3: {=IF(SUM($G$13:$G$39)>=200*0.5,"STAGE CLEAR! ▶ Next: F6-3 Deadlines","")}
A5: BRIEFING · new moves in this stage
A6: # | B6: What it does · Pro tip | C6: Keys / Syntax
A7: 1 | B7: Subtract two dates to get the days between them. Tip: Dates are numbers underneath, so plain minus works. | C7: =end-start
A8: 2 | B8: Add a number to a date to move forward that many days. Tip: =B6+30 is 30 days after B6. | C8: =date+30
A9: 3 | B9: DATEDIF(start, end, "Y"/"M"/"D") counts full years, months or days. Tip: Perfect for ages: =DATEDIF(birthday,TODAY(),"Y"). | C9: DATEDIF
A11: WARM-UP · flashback to earlier stages
A12: # | B12: Mission | C12: Your answer | D12: Result | E12: Hint? | F12: Hint | G12: XP
A13: W1 | B13: Which function returns today's date? (from F6-1 Calendar) | D13: {=IFERROR(_xlfn.LET(_xlpm.a,'F6-2 Date Math'!$C$13,IF(TRIM(_xlpm.a&"")="","",IF(OR(SUBSTITUTE(SUBSTITUTE(SUBSTITUTE(SUBSTITUTE(SUBSTITUTE(SUBSTITUTE(SUBSTITUTE(SUBSTITUTE(SUBSTITUTE(SUBSTITUTE(SUBSTITUTE(SUBSTITUTE(SUBSTITUTE(SUBSTITUTE(SUBSTITUTE(SUBSTITUTE(SUBSTITUTE(SUBSTITUTE(SUBSTITUTE(SUBSTITUTE(SUBSTITUTE(SUBSTITUTE(SUBSTITUTE(SUBSTITUTE(SUBSTITUTE(SUBSTITUTE(SUBSTITUTE(UPPER(_xlpm.a)," ",""),"CONTROL","CTRL"),"CTL","CTRL"),"ESCAPE","ESC"),"RETURN","ENTER"),"PAGEDOWN","PGDN"),"PGDOWN","PGDN"),"PAGEUP","PGUP"),"ARROWKEYS","ARROW"),"ARROWKEY","ARROW"),"ARROWS","ARROW"),"DOWNARROW","DOWN"),"UPARROW","UP"),"LEFTARROW","LEFT"),"RIGHTARROW","RIGHT"),"ARROWDOWN","DOWN"),"ARROWUP","UP"),"ARROWLEFT","LEFT"),"ARROWRIGHT","RIGHT"),"↓","DOWN"),"↑","UP"),"←","LEFT"),"→","RIGHT"),"SPACEBAR","SPACE"),"−","-"),"MINUS","-"),"PLUS","+")=Key!$E$32:$J$32),"✔ CLEAR","✘ TRY AGAIN"))),"✘ TRY AGAIN")} | F13: {=IF(E13="Show hint",Key!$B$32,"")} | G13: {=IF(LEFT(D13,1)="✔",IF(E13="Show hint",5,10),0)} -> 0
A14: W2 | B14: Which function returns the current date and time? (from F6-1 Calendar) | D14: {=IFERROR(_xlfn.LET(_xlpm.a,'F6-2 Date Math'!$C$14,IF(TRIM(_xlpm.a&"")="","",IF(OR(SUBSTITUTE(SUBSTITUTE(SUBSTITUTE(SUBSTITUTE(SUBSTITUTE(SUBSTITUTE(SUBSTITUTE(SUBSTITUTE(SUBSTITUTE(SUBSTITUTE(SUBSTITUTE(SUBSTITUTE(SUBSTITUTE(SUBSTITUTE(SUBSTITUTE(SUBSTITUTE(SUBSTITUTE(SUBSTITUTE(SUBSTITUTE(SUBSTITUTE(SUBSTITUTE(SUBSTITUTE(SUBSTITUTE(SUBSTITUTE(SUBSTITUTE(SUBSTITUTE(SUBSTITUTE(UPPER(_xlpm.a)," ",""),"CONTROL","CTRL"),"CTL","CTRL"),"ESCAPE","ESC"),"RETURN","ENTER"),"PAGEDOWN","PGDN"),"PGDOWN","PGDN"),"PAGEUP","PGUP"),"ARROWKEYS","ARROW"),"ARROWKEY","ARROW"),"ARROWS","ARROW"),"DOWNARROW","DOWN"),"UPARROW","UP"),"LEFTARROW","LEFT"),"RIGHTARROW","RIGHT"),"ARROWDOWN","DOWN"),"ARROWUP","UP"),"ARROWLEFT","LEFT"),"ARROWRIGHT","RIGHT"),"↓","DOWN"),"↑","UP"),"←","LEFT"),"→","RIGHT"),"SPACEBAR","SPACE"),"−","-"),"MINUS","-"),"PLUS","+")=Key!$E$33:$J$33),"✔ CLEAR","✘ TRY AGAIN"))),"✘ TRY AGAIN")} | F14: {=IF(E14="Show hint",Key!$B$33,"")} | G14: {=IF(LEFT(D14,1)="✔",IF(E14="Show hint",5,10),0)} -> 0
A15: W3 | B15: Which function builds a date from a year, month and day? (from F6-1 Calendar) | D15: {=IFERROR(_xlfn.LET(_xlpm.a,'F6-2 Date Math'!$C$15,IF(TRIM(_xlpm.a&"")="","",IF(OR(SUBSTITUTE(SUBSTITUTE(SUBSTITUTE(SUBSTITUTE(SUBSTITUTE(SUBSTITUTE(SUBSTITUTE(SUBSTITUTE(SUBSTITUTE(SUBSTITUTE(SUBSTITUTE(SUBSTITUTE(SUBSTITUTE(SUBSTITUTE(SUBSTITUTE(SUBSTITUTE(SUBSTITUTE(SUBSTITUTE(SUBSTITUTE(SUBSTITUTE(SUBSTITUTE(SUBSTITUTE(SUBSTITUTE(SUBSTITUTE(SUBSTITUTE(SUBSTITUTE(SUBSTITUTE(UPPER(_xlpm.a)," ",""),"CONTROL","CTRL"),"CTL","CTRL"),"ESCAPE","ESC"),"RETURN","ENTER"),"PAGEDOWN","PGDN"),"PGDOWN","PGDN"),"PAGEUP","PGUP"),"ARROWKEYS","ARROW"),"ARROWKEY","ARROW"),"ARROWS","ARROW"),"DOWNARROW","DOWN"),"UPARROW","UP"),"LEFTARROW","LEFT"),"RIGHTARROW","RIGHT"),"ARROWDOWN","DOWN"),"ARROWUP","UP"),"ARROWLEFT","LEFT"),"ARROWRIGHT","RIGHT"),"↓","DOWN"),"↑","UP"),"←","LEFT"),"→","RIGHT"),"SPACEBAR","SPACE"),"−","-"),"MINUS","-"),"PLUS","+")=Key!$E$34:$J$34),"✔ CLEAR","✘ TRY AGAIN"))),"✘ TRY AGAIN")} | F15: {=IF(E15="Show hint",Key!$B$34,"")} | G15: {=IF(LEFT(D15,1)="✔",IF(E15="Show hint",5,10),0)} -> 0
A16: W4 | B16: Which function returns the year of a date? (from F6-1 Calendar) | D16: {=IFERROR(_xlfn.LET(_xlpm.a,'F6-2 Date Math'!$C$16,IF(TRIM(_xlpm.a&"")="","",IF(OR(SUBSTITUTE(SUBSTITUTE(SUBSTITUTE(SUBSTITUTE(SUBSTITUTE(SUBSTITUTE(SUBSTITUTE(SUBSTITUTE(SUBSTITUTE(SUBSTITUTE(SUBSTITUTE(SUBSTITUTE(SUBSTITUTE(SUBSTITUTE(SUBSTITUTE(SUBSTITUTE(SUBSTITUTE(SUBSTITUTE(SUBSTITUTE(SUBSTITUTE(SUBSTITUTE(SUBSTITUTE(SUBSTITUTE(SUBSTITUTE(SUBSTITUTE(SUBSTITUTE(SUBSTITUTE(UPPER(_xlpm.a)," ",""),"CONTROL","CTRL"),"CTL","CTRL"),"ESCAPE","ESC"),"RETURN","ENTER"),"PAGEDOWN","PGDN"),"PGDOWN","PGDN"),"PAGEUP","PGUP"),"ARROWKEYS","ARROW"),"ARROWKEY","ARROW"),"ARROWS","ARROW"),"DOWNARROW","DOWN"),"UPARROW","UP"),"LEFTARROW","LEFT"),"RIGHTARROW","RIGHT"),"ARROWDOWN","DOWN"),"ARROWUP","UP"),"ARROWLEFT","LEFT"),"ARROWRIGHT","RIGHT"),"↓","DOWN"),"↑","UP"),"←","LEFT"),"→","RIGHT"),"SPACEBAR","SPACE"),"−","-"),"MINUS","-"),"PLUS","+")=Key!$E$35:$J$35),"✔ CLEAR","✘ TRY AGAIN"))),"✘ TRY AGAIN")} | F16: {=IF(E16="Show hint",Key!$B$35,"")} | G16: {=IF(LEFT(D16,1)="✔",IF(E16="Show hint",5,10),0)} -> 0
A17: W5 | B17: Which function returns the month number of a date? (from F6-1 Calendar) | D17: {=IFERROR(_xlfn.LET(_xlpm.a,'F6-2 Date Math'!$C$17,IF(TRIM(_xlpm.a&"")="","",IF(OR(SUBSTITUTE(SUBSTITUTE(SUBSTITUTE(SUBSTITUTE(SUBSTITUTE(SUBSTITUTE(SUBSTITUTE(SUBSTITUTE(SUBSTITUTE(SUBSTITUTE(SUBSTITUTE(SUBSTITUTE(SUBSTITUTE(SUBSTITUTE(SUBSTITUTE(SUBSTITUTE(SUBSTITUTE(SUBSTITUTE(SUBSTITUTE(SUBSTITUTE(SUBSTITUTE(SUBSTITUTE(SUBSTITUTE(SUBSTITUTE(SUBSTITUTE(SUBSTITUTE(SUBSTITUTE(UPPER(_xlpm.a)," ",""),"CONTROL","CTRL"),"CTL","CTRL"),"ESCAPE","ESC"),"RETURN","ENTER"),"PAGEDOWN","PGDN"),"PGDOWN","PGDN"),"PAGEUP","PGUP"),"ARROWKEYS","ARROW"),"ARROWKEY","ARROW"),"ARROWS","ARROW"),"DOWNARROW","DOWN"),"UPARROW","UP"),"LEFTARROW","LEFT"),"RIGHTARROW","RIGHT"),"ARROWDOWN","DOWN"),"ARROWUP","UP"),"ARROWLEFT","LEFT"),"ARROWRIGHT","RIGHT"),"↓","DOWN"),"↑","UP"),"←","LEFT"),"→","RIGHT"),"SPACEBAR","SPACE"),"−","-"),"MINUS","-"),"PLUS","+")=Key!$E$36:$J$36),"✔ CLEAR","✘ TRY AGAIN"))),"✘ TRY AGAIN")} | F17: {=IF(E17="Show hint",Key!$B$36,"")} | G17: {=IF(LEFT(D17,1)="✔",IF(E17="Show hint",5,10),0)} -> 0
A18: W6 | B18: Which function returns the day of the month? (from F6-1 Calendar) | D18: {=IFERROR(_xlfn.LET(_xlpm.a,'F6-2 Date Math'!$C$18,IF(TRIM(_xlpm.a&"")="","",IF(OR(SUBSTITUTE(SUBSTITUTE(SUBSTITUTE(SUBSTITUTE(SUBSTITUTE(SUBSTITUTE(SUBSTITUTE(SUBSTITUTE(SUBSTITUTE(SUBSTITUTE(SUBSTITUTE(SUBSTITUTE(SUBSTITUTE(SUBSTITUTE(SUBSTITUTE(SUBSTITUTE(SUBSTITUTE(SUBSTITUTE(SUBSTITUTE(SUBSTITUTE(SUBSTITUTE(SUBSTITUTE(SUBSTITUTE(SUBSTITUTE(SUBSTITUTE(SUBSTITUTE(SUBSTITUTE(UPPER(_xlpm.a)," ",""),"CONTROL","CTRL"),"CTL","CTRL"),"ESCAPE","ESC"),"RETURN","ENTER"),"PAGEDOWN","PGDN"),"PGDOWN","PGDN"),"PAGEUP","PGUP"),"ARROWKEYS","ARROW"),"ARROWKEY","ARROW"),"ARROWS","ARROW"),"DOWNARROW","DOWN"),"UPARROW","UP"),"LEFTARROW","LEFT"),"RIGHTARROW","RIGHT"),"ARROWDOWN","DOWN"),"ARROWUP","UP"),"ARROWLEFT","LEFT"),"ARROWRIGHT","RIGHT"),"↓","DOWN"),"↑","UP"),"←","LEFT"),"→","RIGHT"),"SPACEBAR","SPACE"),"−","-"),"MINUS","-"),"PLUS","+")=Key!$E$37:$J$37),"✔ CLEAR","✘ TRY AGAIN"))),"✘ TRY AGAIN")} | F18: {=IF(E18="Show hint",Key!$B$37,"")} | G18: {=IF(LEFT(D18,1)="✔",IF(E18="Show hint",5,10),0)} -> 0
A19: W7 | B19: Which function returns the day of the week as a number? (from F6-1 Calendar) | D19: {=IFERROR(_xlfn.LET(_xlpm.a,'F6-2 Date Math'!$C$19,IF(TRIM(_xlpm.a&"")="","",IF(OR(SUBSTITUTE(SUBSTITUTE(SUBSTITUTE(SUBSTITUTE(SUBSTITUTE(SUBSTITUTE(SUBSTITUTE(SUBSTITUTE(SUBSTITUTE(SUBSTITUTE(SUBSTITUTE(SUBSTITUTE(SUBSTITUTE(SUBSTITUTE(SUBSTITUTE(SUBSTITUTE(SUBSTITUTE(SUBSTITUTE(SUBSTITUTE(SUBSTITUTE(SUBSTITUTE(SUBSTITUTE(SUBSTITUTE(SUBSTITUTE(SUBSTITUTE(SUBSTITUTE(SUBSTITUTE(UPPER(_xlpm.a)," ",""),"CONTROL","CTRL"),"CTL","CTRL"),"ESCAPE","ESC"),"RETURN","ENTER"),"PAGEDOWN","PGDN"),"PGDOWN","PGDN"),"PAGEUP","PGUP"),"ARROWKEYS","ARROW"),"ARROWKEY","ARROW"),"ARROWS","ARROW"),"DOWNARROW","DOWN"),"UPARROW","UP"),"LEFTARROW","LEFT"),"RIGHTARROW","RIGHT"),"ARROWDOWN","DOWN"),"ARROWUP","UP"),"ARROWLEFT","LEFT"),"ARROWRIGHT","RIGHT"),"↓","DOWN"),"↑","UP"),"←","LEFT"),"→","RIGHT"),"SPACEBAR","SPACE"),"−","-"),"MINUS","-"),"PLUS","+")=Key!$E$38:$J$38),"✔ CLEAR","✘ TRY AGAIN"))),"✘ TRY AGAIN")} | F19: {=IF(E19="Show hint",Key!$B$38,"")} | G19: {=IF(LEFT(D19,1)="✔",IF(E19="Show hint",5,10),0)} -> 0
A20: W8 | B20: Which function returns the position of text, matching case? (from F5-3 Find the Gem) | D20: {=IFERROR(_xlfn.LET(_xlpm.a,'F6-2 Date Math'!$C$20,IF(TRIM(_xlpm.a&"")="","",IF(OR(SUBSTITUTE(SUBSTITUTE(SUBSTITUTE(SUBSTITUTE(SUBSTITUTE(SUBSTITUTE(SUBSTITUTE(SUBSTITUTE(SUBSTITUTE(SUBSTITUTE(SUBSTITUTE(SUBSTITUTE(SUBSTITUTE(SUBSTITUTE(SUBSTITUTE(SUBSTITUTE(SUBSTITUTE(SUBSTITUTE(SUBSTITUTE(SUBSTITUTE(SUBSTITUTE(SUBSTITUTE(SUBSTITUTE(SUBSTITUTE(SUBSTITUTE(SUBSTITUTE(SUBSTITUTE(UPPER(_xlpm.a)," ",""),"CONTROL","CTRL"),"CTL","CTRL"),"ESCAPE","ESC"),"RETURN","ENTER"),"PAGEDOWN","PGDN"),"PGDOWN","PGDN"),"PAGEUP","PGUP"),"ARROWKEYS","ARROW"),"ARROWKEY","ARROW"),"ARROWS","ARROW"),"DOWNARROW","DOWN"),"UPARROW","UP"),"LEFTARROW","LEFT"),"RIGHTARROW","RIGHT"),"ARROWDOWN","DOWN"),"ARROWUP","UP"),"ARROWLEFT","LEFT"),"ARROWRIGHT","RIGHT"),"↓","DOWN"),"↑","UP"),"←","LEFT"),"→","RIGHT"),"SPACEBAR","SPACE"),"−","-"),"MINUS","-"),"PLUS","+")=Key!$E$39:$J$39),"✔ CLEAR","✘ TRY AGAIN"))),"✘ TRY AGAIN")} | F20: {=IF(E20="Show hint",Key!$B$39,"")} | G20: {=IF(LEFT(D20,1)="✔",IF(E20="Show hint",5,10),0)} -> 0
A21: W9 | B21: Which function returns a position while ignoring case? (from F5-3 Find the Gem) | D21: {=IFERROR(_xlfn.LET(_xlpm.a,'F6-2 Date Math'!$C$21,IF(TRIM(_xlpm.a&"")="","",IF(OR(SUBSTITUTE(SUBSTITUTE(SUBSTITUTE(SUBSTITUTE(SUBSTITUTE(SUBSTITUTE(SUBSTITUTE(SUBSTITUTE(SUBSTITUTE(SUBSTITUTE(SUBSTITUTE(SUBSTITUTE(SUBSTITUTE(SUBSTITUTE(SUBSTITUTE(SUBSTITUTE(SUBSTITUTE(SUBSTITUTE(SUBSTITUTE(SUBSTITUTE(SUBSTITUTE(SUBSTITUTE(SUBSTITUTE(SUBSTITUTE(SUBSTITUTE(SUBSTITUTE(SUBSTITUTE(UPPER(_xlpm.a)," ",""),"CONTROL","CTRL"),"CTL","CTRL"),"ESCAPE","ESC"),"RETURN","ENTER"),"PAGEDOWN","PGDN"),"PGDOWN","PGDN"),"PAGEUP","PGUP"),"ARROWKEYS","ARROW"),"ARROWKEY","ARROW"),"ARROWS","ARROW"),"DOWNARROW","DOWN"),"UPARROW","UP"),"LEFTARROW","LEFT"),"RIGHTARROW","RIGHT"),"ARROWDOWN","DOWN"),"ARROWUP","UP"),"ARROWLEFT","LEFT"),"ARROWRIGHT","RIGHT"),"↓","DOWN"),"↑","UP"),"←","LEFT"),"→","RIGHT"),"SPACEBAR","SPACE"),"−","-"),"MINUS","-"),"PLUS","+")=Key!$E$40:$J$40),"✔ CLEAR","✘ TRY AGAIN"))),"✘ TRY AGAIN")} | F21: {=IF(E21="Show hint",Key!$B$40,"")} | G21: {=IF(LEFT(D21,1)="✔",IF(E21="Show hint",5,10),0)} -> 0
A22: W10 | B22: Which function supplies the cut position inside =LEFT(A2, ____("@",A2)-1)? (from F5-3 Find the Gem) | D22: {=IFERROR(_xlfn.LET(_xlpm.a,'F6-2 Date Math'!$C$22,IF(TRIM(_xlpm.a&"")="","",IF(OR(SUBSTITUTE(SUBSTITUTE(SUBSTITUTE(SUBSTITUTE(SUBSTITUTE(SUBSTITUTE(SUBSTITUTE(SUBSTITUTE(SUBSTITUTE(SUBSTITUTE(SUBSTITUTE(SUBSTITUTE(SUBSTITUTE(SUBSTITUTE(SUBSTITUTE(SUBSTITUTE(SUBSTITUTE(SUBSTITUTE(SUBSTITUTE(SUBSTITUTE(SUBSTITUTE(SUBSTITUTE(SUBSTITUTE(SUBSTITUTE(SUBSTITUTE(SUBSTITUTE(SUBSTITUTE(UPPER(_xlpm.a)," ",""),"CONTROL","CTRL"),"CTL","CTRL"),"ESCAPE","ESC"),"RETURN","ENTER"),"PAGEDOWN","PGDN"),"PGDOWN","PGDN"),"PAGEUP","PGUP"),"ARROWKEYS","ARROW"),"ARROWKEY","ARROW"),"ARROWS","ARROW"),"DOWNARROW","DOWN"),"UPARROW","UP"),"LEFTARROW","LEFT"),"RIGHTARROW","RIGHT"),"ARROWDOWN","DOWN"),"ARROWUP","UP"),"ARROWLEFT","LEFT"),"ARROWRIGHT","RIGHT"),"↓","DOWN"),"↑","UP"),"←","LEFT"),"→","RIGHT"),"SPACEBAR","SPACE"),"−","-"),"MINUS","-"),"PLUS","+")=Key!$E$41:$E$41),"✔ CLEAR","✘ TRY AGAIN"))),"✘ TRY AGAIN")} | F22: {=IF(E22="Show hint",Key!$B$41,"")} | G22: {=IF(LEFT(D22,1)="✔",IF(E22="Show hint",5,10),0)} -> 0
A24: TRAINING · recognize the move (pick from the list)
A25: # | B25: Mission | C25: Your answer | D25: Result | E25: Hint? | F25: Hint | G25: XP
A26: T1 | B26: What do you get when you subtract an earlier date from a later one (one word)? | D26: {=IFERROR(IF('F6-2 Date Math'!$C$26&""="","",IF('F6-2 Date Math'!$C$26&""=Key!$C$42&"","✔ CLEAR","✘ TRY AGAIN")),"✘ TRY AGAIN")} | F26: {=IF(E26="Show hint",Key!$B$42,"")} | G26: {=IF(LEFT(D26,1)="✔",IF(E26="Show hint",5,10),0)} -> 0
A27: T2 | B27: Type the formula for the date 30 days after the date in B6. | D27: {=IFERROR(IF('F6-2 Date Math'!$C$27&""="","",IF('F6-2 Date Math'!$C$27&""=Key!$C$43&"","✔ CLEAR","✘ TRY AGAIN")),"✘ TRY AGAIN")} | F27: {=IF(E27="Show hint",Key!$B$43,"")} | G27: {=IF(LEFT(D27,1)="✔",IF(E27="Show hint",5,10),0)} -> 0
A28: T3 | B28: Which function counts full years or months between two dates? | D28: {=IFERROR(IF('F6-2 Date Math'!$C$28&""="","",IF('F6-2 Date Math'!$C$28&""=Key!$C$44&"","✔ CLEAR","✘ TRY AGAIN")),"✘ TRY AGAIN")} | F28: {=IF(E28="Show hint",Key!$B$44,"")} | G28: {=IF(LEFT(D28,1)="✔",IF(E28="Show hint",5,10),0)} -> 0
A30: CHALLENGES · recall it, then do it
B31: ▶ Open F6-2 Arena (or press Ctrl+PgDn)
A32: # | B32: Mission | C32: Your answer | D32: Result | E32: Hint? | F32: Hint | G32: XP
A33: C1 | B33: What do you get when you subtract an earlier date from a later one (one word)? | D33: {=IFERROR(_xlfn.LET(_xlpm.a,'F6-2 Date Math'!$C$33,IF(TRIM(_xlpm.a&"")="","",IF(OR(SUBSTITUTE(SUBSTITUTE(SUBSTITUTE(SUBSTITUTE(SUBSTITUTE(SUBSTITUTE(SUBSTITUTE(SUBSTITUTE(SUBSTITUTE(SUBSTITUTE(SUBSTITUTE(SUBSTITUTE(SUBSTITUTE(SUBSTITUTE(SUBSTITUTE(SUBSTITUTE(SUBSTITUTE(SUBSTITUTE(SUBSTITUTE(SUBSTITUTE(SUBSTITUTE(SUBSTITUTE(SUBSTITUTE(SUBSTITUTE(SUBSTITUTE(SUBSTITUTE(SUBSTITUTE(UPPER(_xlpm.a)," ",""),"CONTROL","CTRL"),"CTL","CTRL"),"ESCAPE","ESC"),"RETURN","ENTER"),"PAGEDOWN","PGDN"),"PGDOWN","PGDN"),"PAGEUP","PGUP"),"ARROWKEYS","ARROW"),"ARROWKEY","ARROW"),"ARROWS","ARROW"),"DOWNARROW","DOWN"),"UPARROW","UP"),"LEFTARROW","LEFT"),"RIGHTARROW","RIGHT"),"ARROWDOWN","DOWN"),"ARROWUP","UP"),"ARROWLEFT","LEFT"),"ARROWRIGHT","RIGHT"),"↓","DOWN"),"↑","UP"),"←","LEFT"),"→","RIGHT"),"SPACEBAR","SPACE"),"−","-"),"MINUS","-"),"PLUS","+")=Key!$E$45:$F$45),"✔ CLEAR","✘ TRY AGAIN"))),"✘ TRY AGAIN")} | F33: {=IF(E33="Show hint",Key!$B$45,"")} | G33: {=IF(LEFT(D33,1)="✔",IF(E33="Show hint",5,10),0)} -> 0
A34: C2 | B34: Type the formula for the date 30 days after the date in B6. | D34: {=IFERROR(_xlfn.LET(_xlpm.a,'F6-2 Date Math'!$C$34,IF(TRIM(_xlpm.a&"")="","",IF(OR(SUBSTITUTE(SUBSTITUTE(SUBSTITUTE(SUBSTITUTE(SUBSTITUTE(SUBSTITUTE(SUBSTITUTE(SUBSTITUTE(SUBSTITUTE(SUBSTITUTE(SUBSTITUTE(SUBSTITUTE(SUBSTITUTE(SUBSTITUTE(SUBSTITUTE(SUBSTITUTE(SUBSTITUTE(SUBSTITUTE(SUBSTITUTE(SUBSTITUTE(SUBSTITUTE(SUBSTITUTE(SUBSTITUTE(SUBSTITUTE(SUBSTITUTE(SUBSTITUTE(SUBSTITUTE(UPPER(_xlpm.a)," ",""),"CONTROL","CTRL"),"CTL","CTRL"),"ESCAPE","ESC"),"RETURN","ENTER"),"PAGEDOWN","PGDN"),"PGDOWN","PGDN"),"PAGEUP","PGUP"),"ARROWKEYS","ARROW"),"ARROWKEY","ARROW"),"ARROWS","ARROW"),"DOWNARROW","DOWN"),"UPARROW","UP"),"LEFTARROW","LEFT"),"RIGHTARROW","RIGHT"),"ARROWDOWN","DOWN"),"ARROWUP","UP"),"ARROWLEFT","LEFT"),"ARROWRIGHT","RIGHT"),"↓","DOWN"),"↑","UP"),"←","LEFT"),"→","RIGHT"),"SPACEBAR","SPACE"),"−","-"),"MINUS","-"),"PLUS","+")=Key!$E$46:$H$46),"✔ CLEAR","✘ TRY AGAIN"))),"✘ TRY AGAIN")} | F34: {=IF(E34="Show hint",Key!$B$46,"")} | G34: {=IF(LEFT(D34,1)="✔",IF(E34="Show hint",5,10),0)} -> 0
A35: C3 | B35: Which function counts full years or months between two dates? | D35: {=IFERROR(_xlfn.LET(_xlpm.a,'F6-2 Date Math'!$C$35,IF(TRIM(_xlpm.a&"")="","",IF(OR(SUBSTITUTE(SUBSTITUTE(SUBSTITUTE(SUBSTITUTE(SUBSTITUTE(SUBSTITUTE(SUBSTITUTE(SUBSTITUTE(SUBSTITUTE(SUBSTITUTE(SUBSTITUTE(SUBSTITUTE(SUBSTITUTE(SUBSTITUTE(SUBSTITUTE(SUBSTITUTE(SUBSTITUTE(SUBSTITUTE(SUBSTITUTE(SUBSTITUTE(SUBSTITUTE(SUBSTITUTE(SUBSTITUTE(SUBSTITUTE(SUBSTITUTE(SUBSTITUTE(SUBSTITUTE(UPPER(_xlpm.a)," ",""),"CONTROL","CTRL"),"CTL","CTRL"),"ESCAPE","ESC"),"RETURN","ENTER"),"PAGEDOWN","PGDN"),"PGDOWN","PGDN"),"PAGEUP","PGUP"),"ARROWKEYS","ARROW"),"ARROWKEY","ARROW"),"ARROWS","ARROW"),"DOWNARROW","DOWN"),"UPARROW","UP"),"LEFTARROW","LEFT"),"RIGHTARROW","RIGHT"),"ARROWDOWN","DOWN"),"ARROWUP","UP"),"ARROWLEFT","LEFT"),"ARROWRIGHT","RIGHT"),"↓","DOWN"),"↑","UP"),"←","LEFT"),"→","RIGHT"),"SPACEBAR","SPACE"),"−","-"),"MINUS","-"),"PLUS","+")=Key!$E$47:$J$47),"✔ CLEAR","✘ TRY AGAIN"))),"✘ TRY AGAIN")} | F35: {=IF(E35="Show hint",Key!$B$47,"")} | G35: {=IF(LEFT(D35,1)="✔",IF(E35="Show hint",5,10),0)} -> 0
A36: C4 | B36: In D6 count the days from B6 to B7 by subtracting the dates. | C36: ▶ ARENA C4 (cell D6) | D36: {=IF(ISBLANK('F6-2 Arena'!$D$6),"",IF(NOT(_xlfn.ISFORMULA('F6-2 Arena'!$D$6)),"✘ That's a typed value · enter a formula",IF(ISERROR('F6-2 Arena'!$D$6),"✘ Your formula returns "&IFERROR(CHOOSE(ERROR.TYPE('F6-2 Arena'!$D$6),"#NULL!","#DIV/0!","#VALUE!","#REF!","#NAME?","#NUM!","#N/A","#GETTING_DATA","#SPILL!","#CONNECT!","#BLOCKED!","#UNKNOWN!","#FIELD!","#CALC!"),"an error"),IF(NOT(AND(IFERROR(AND(ISNUMBER('F6-2 Arena'!$D$6),ABS('F6-2 Arena'!$D$6-Key!$C$48)<=1E-9*MAX(1,ABS(Key!$C$48))),FALSE))),"✘ TRY AGAIN","✔ CLEAR"))))} | F36: {=IF(E36="Show hint",Key!$B$48,"")} | G36: {=IF(LEFT(D36,1)="✔",IF(E36="Show hint",5,10),0)} -> 0
A37: C5 | B37: In D7 return the date 30 days after B6. | C37: ▶ ARENA C5 (cell D7) | D37: {=IF(ISBLANK('F6-2 Arena'!$D$7),"",IF(NOT(_xlfn.ISFORMULA('F6-2 Arena'!$D$7)),"✘ That's a typed value · enter a formula",IF(ISERROR('F6-2 Arena'!$D$7),"✘ Your formula returns "&IFERROR(CHOOSE(ERROR.TYPE('F6-2 Arena'!$D$7),"#NULL!","#DIV/0!","#VALUE!","#REF!","#NAME?","#NUM!","#N/A","#GETTING_DATA","#SPILL!","#CONNECT!","#BLOCKED!","#UNKNOWN!","#FIELD!","#CALC!"),"an error"),IF(NOT(AND(IFERROR(AND(ISNUMBER('F6-2 Arena'!$D$7),ABS('F6-2 Arena'!$D$7-Key!$C$49)<=1E-9*MAX(1,ABS(Key!$C$49))),FALSE))),"✘ TRY AGAIN","✔ CLEAR"))))} | F37: {=IF(E37="Show hint",Key!$B$49,"")} | G37: {=IF(LEFT(D37,1)="✔",IF(E37="Show hint",5,10),0)} -> 0
A38: C6 | B38: In D8 return the age in full years from the birthday in B9 to the date in B10: =DATEDIF(B9,B10,"Y"). | C38: ▶ ARENA C6 (cell D8) | D38: {=IF(ISBLANK('F6-2 Arena'!$D$8),"",IF(NOT(_xlfn.ISFORMULA('F6-2 Arena'!$D$8)),"✘ That's a typed value · enter a formula",IF(ISERROR('F6-2 Arena'!$D$8),"✘ Your formula returns "&IFERROR(CHOOSE(ERROR.TYPE('F6-2 Arena'!$D$8),"#NULL!","#DIV/0!","#VALUE!","#REF!","#NAME?","#NUM!","#N/A","#GETTING_DATA","#SPILL!","#CONNECT!","#BLOCKED!","#UNKNOWN!","#FIELD!","#CALC!"),"an error"),IF(NOT(AND(IFERROR(AND(ISNUMBER('F6-2 Arena'!$D$8),ABS('F6-2 Arena'!$D$8-Key!$C$50)<=1E-9*MAX(1,ABS(Key!$C$50))),FALSE))),"✘ TRY AGAIN",IF(AND(OR(ISNUMBER(FIND({"=","(",",","+","-","*","/","&"," ","<",">",":","@","^"}&"DATEDIF"&"(",UPPER(_xlfn.FORMULATEXT('F6-2 Arena'!$D$8)))))),"✔ CLEAR","✘ CLOSE · right value, but use DATEDIF")))))} | F38: {=IF(E38="Show hint",Key!$B$50,"")} | G38: {=IF(LEFT(D38,1)="✔",IF(E38="Show hint",5,10),0)} -> 0
A39: C7 | B39: In D9 count the full months from B6 to B7 with DATEDIF and "M". | C39: ▶ ARENA C7 (cell D9) | D39: {=IF(ISBLANK('F6-2 Arena'!$D$9),"",IF(NOT(_xlfn.ISFORMULA('F6-2 Arena'!$D$9)),"✘ That's a typed value · enter a formula",IF(ISERROR('F6-2 Arena'!$D$9),"✘ Your formula returns "&IFERROR(CHOOSE(ERROR.TYPE('F6-2 Arena'!$D$9),"#NULL!","#DIV/0!","#VALUE!","#REF!","#NAME?","#NUM!","#N/A","#GETTING_DATA","#SPILL!","#CONNECT!","#BLOCKED!","#UNKNOWN!","#FIELD!","#CALC!"),"an error"),IF(NOT(AND(IFERROR(AND(ISNUMBER('F6-2 Arena'!$D$9),ABS('F6-2 Arena'!$D$9-Key!$C$51)<=1E-9*MAX(1,ABS(Key!$C$51))),FALSE))),"✘ TRY AGAIN",IF(AND(OR(ISNUMBER(FIND({"=","(",",","+","-","*","/","&"," ","<",">",":","@","^"}&"DATEDIF"&"(",UPPER(_xlfn.FORMULATEXT('F6-2 Arena'!$D$9)))))),"✔ CLEAR","✘ CLOSE · right value, but use DATEDIF")))))} | F39: {=IF(E39="Show hint",Key!$B$51,"")} | G39: {=IF(LEFT(D39,1)="✔",IF(E39="Show hint",5,10),0)} -> 0

Sheet F6-2 Arena
A1: ARENA ▸ F6-2 DATE MATH
A2: Practice area · everything here is editable. Missions and their checks are on the stage sheet.
A3: PASS CODE | B3: DATEMATH | D3: ◀ Back to F6-2 Date Math
B5: Dates | C5: Task
A6: Start | B6: 46096 | C6: Days from B6 to B7
A7: End | B7: 46143 | C7: 30 days after B6
C8: Age in full years (B9 → B10)
A9: Birthday | B9: 33105 | C9: Full months B6 → B7
A10: On | B10: 46096

Sheet F6-3 Deadlines
A1: STAGE F6-3 ▸ DEADLINES
A2: Goal: plan with months, month-ends and workdays
A3: {="SCORE "&TEXT(SUM($G$14:$G$42),"0000")&" / 0220"} -> SCORE 0000 / 0220 | C3: {=IF(SUM($G$14:$G$42)>=220,"★★★",IF(SUM($G$14:$G$42)>=220*0.8,"★★☆",IF(SUM($G$14:$G$42)>=220*0.5,"★☆☆","☆☆☆")))} -> ☆☆☆ | D3: {=REPT("█",ROUND(10*SUM($G$14:$G$42)/220,0))&REPT("░",10-ROUND(10*SUM($G$14:$G$42)/220,0))&" "&TEXT(SUM($G$14:$G$42)/220,"0%")} -> ░░░░░░░░░░ 0% | F3: {=IF(SUM($G$14:$G$42)>=220*0.5,"STAGE CLEAR! ▶ Next: Boss","")}
A5: BRIEFING · new moves in this stage
A6: # | B6: What it does · Pro tip | C6: Keys / Syntax
A7: 1 | B7: EDATE(date, months) moves by whole months. Tip: =EDATE(B6,3) is 3 months on. | C7: EDATE
A8: 2 | B8: EOMONTH(date, months) returns a month's last day. Tip: =EOMONTH(B6,0) is the end of B6's month. | C8: EOMONTH
A9: 3 | B9: Count the Monday–Friday days between two dates (both included). Tip: Add a holiday list as a third argument. | C9: NETWORKDAYS
A10: 4 | B10: WORKDAY(start, n): the date n working days later. Tip: Skips weekends automatically. | C10: WORKDAY
A12: WARM-UP · flashback to earlier stages
A13: # | B13: Mission | C13: Your answer | D13: Result | E13: Hint? | F13: Hint | G13: XP
A14: W1 | B14: What do you get when you subtract an earlier date from a later one (one word)? (from F6-2 Date Math) | D14: {=IFERROR(_xlfn.LET(_xlpm.a,'F6-3 Deadlines'!$C$14,IF(TRIM(_xlpm.a&"")="","",IF(OR(SUBSTITUTE(SUBSTITUTE(SUBSTITUTE(SUBSTITUTE(SUBSTITUTE(SUBSTITUTE(SUBSTITUTE(SUBSTITUTE(SUBSTITUTE(SUBSTITUTE(SUBSTITUTE(SUBSTITUTE(SUBSTITUTE(SUBSTITUTE(SUBSTITUTE(SUBSTITUTE(SUBSTITUTE(SUBSTITUTE(SUBSTITUTE(SUBSTITUTE(SUBSTITUTE(SUBSTITUTE(SUBSTITUTE(SUBSTITUTE(SUBSTITUTE(SUBSTITUTE(SUBSTITUTE(UPPER(_xlpm.a)," ",""),"CONTROL","CTRL"),"CTL","CTRL"),"ESCAPE","ESC"),"RETURN","ENTER"),"PAGEDOWN","PGDN"),"PGDOWN","PGDN"),"PAGEUP","PGUP"),"ARROWKEYS","ARROW"),"ARROWKEY","ARROW"),"ARROWS","ARROW"),"DOWNARROW","DOWN"),"UPARROW","UP"),"LEFTARROW","LEFT"),"RIGHTARROW","RIGHT"),"ARROWDOWN","DOWN"),"ARROWUP","UP"),"ARROWLEFT","LEFT"),"ARROWRIGHT","RIGHT"),"↓","DOWN"),"↑","UP"),"←","LEFT"),"→","RIGHT"),"SPACEBAR","SPACE"),"−","-"),"MINUS","-"),"PLUS","+")=Key!$E$52:$F$52),"✔ CLEAR","✘ TRY AGAIN"))),"✘ TRY AGAIN")} | F14: {=IF(E14="Show hint",Key!$B$52,"")} | G14: {=IF(LEFT(D14,1)="✔",IF(E14="Show hint",5,10),0)} -> 0
A15: W2 | B15: Type the formula for the date 30 days after the date in B6. (from F6-2 Date Math) | D15: {=IFERROR(_xlfn.LET(_xlpm.a,'F6-3 Deadlines'!$C$15,IF(TRIM(_xlpm.a&"")="","",IF(OR(SUBSTITUTE(SUBSTITUTE(SUBSTITUTE(SUBSTITUTE(SUBSTITUTE(SUBSTITUTE(SUBSTITUTE(SUBSTITUTE(SUBSTITUTE(SUBSTITUTE(SUBSTITUTE(SUBSTITUTE(SUBSTITUTE(SUBSTITUTE(SUBSTITUTE(SUBSTITUTE(SUBSTITUTE(SUBSTITUTE(SUBSTITUTE(SUBSTITUTE(SUBSTITUTE(SUBSTITUTE(SUBSTITUTE(SUBSTITUTE(SUBSTITUTE(SUBSTITUTE(SUBSTITUTE(UPPER(_xlpm.a)," ",""),"CONTROL","CTRL"),"CTL","CTRL"),"ESCAPE","ESC"),"RETURN","ENTER"),"PAGEDOWN","PGDN"),"PGDOWN","PGDN"),"PAGEUP","PGUP"),"ARROWKEYS","ARROW"),"ARROWKEY","ARROW"),"ARROWS","ARROW"),"DOWNARROW","DOWN"),"UPARROW","UP"),"LEFTARROW","LEFT"),"RIGHTARROW","RIGHT"),"ARROWDOWN","DOWN"),"ARROWUP","UP"),"ARROWLEFT","LEFT"),"ARROWRIGHT","RIGHT"),"↓","DOWN"),"↑","UP"),"←","LEFT"),"→","RIGHT"),"SPACEBAR","SPACE"),"−","-"),"MINUS","-"),"PLUS","+")=Key!$E$53:$H$53),"✔ CLEAR","✘ TRY AGAIN"))),"✘ TRY AGAIN")} | F15: {=IF(E15="Show hint",Key!$B$53,"")} | G15: {=IF(LEFT(D15,1)="✔",IF(E15="Show hint",5,10),0)} -> 0
A16: W3 | B16: Which function counts full years or months between two dates? (from F6-2 Date Math) | D16: {=IFERROR(_xlfn.LET(_xlpm.a,'F6-3 Deadlines'!$C$16,IF(TRIM(_xlpm.a&"")="","",IF(OR(SUBSTITUTE(SUBSTITUTE(SUBSTITUTE(SUBSTITUTE(SUBSTITUTE(SUBSTITUTE(SUBSTITUTE(SUBSTITUTE(SUBSTITUTE(SUBSTITUTE(SUBSTITUTE(SUBSTITUTE(SUBSTITUTE(SUBSTITUTE(SUBSTITUTE(SUBSTITUTE(SUBSTITUTE(SUBSTITUTE(SUBSTITUTE(SUBSTITUTE(SUBSTITUTE(SUBSTITUTE(SUBSTITUTE(SUBSTITUTE(SUBSTITUTE(SUBSTITUTE(SUBSTITUTE(UPPER(_xlpm.a)," ",""),"CONTROL","CTRL"),"CTL","CTRL"),"ESCAPE","ESC"),"RETURN","ENTER"),"PAGEDOWN","PGDN"),"PGDOWN","PGDN"),"PAGEUP","PGUP"),"ARROWKEYS","ARROW"),"ARROWKEY","ARROW"),"ARROWS","ARROW"),"DOWNARROW","DOWN"),"UPARROW","UP"),"LEFTARROW","LEFT"),"RIGHTARROW","RIGHT"),"ARROWDOWN","DOWN"),"ARROWUP","UP"),"ARROWLEFT","LEFT"),"ARROWRIGHT","RIGHT"),"↓","DOWN"),"↑","UP"),"←","LEFT"),"→","RIGHT"),"SPACEBAR","SPACE"),"−","-"),"MINUS","-"),"PLUS","+")=Key!$E$54:$J$54),"✔ CLEAR","✘ TRY AGAIN"))),"✘ TRY AGAIN")} | F16: {=IF(E16="Show hint",Key!$B$54,"")} | G16: {=IF(LEFT(D16,1)="✔",IF(E16="Show hint",5,10),0)} -> 0
A17: W4 | B17: Which function joins a range of text with a delimiter? (from F5-4 Assemble) | D17: {=IFERROR(_xlfn.LET(_xlpm.a,'F6-3 Deadlines'!$C$17,IF(TRIM(_xlpm.a&"")="","",IF(OR(SUBSTITUTE(SUBSTITUTE(SUBSTITUTE(SUBSTITUTE(SUBSTITUTE(SUBSTITUTE(SUBSTITUTE(SUBSTITUTE(SUBSTITUTE(SUBSTITUTE(SUBSTITUTE(SUBSTITUTE(SUBSTITUTE(SUBSTITUTE(SUBSTITUTE(SUBSTITUTE(SUBSTITUTE(SUBSTITUTE(SUBSTITUTE(SUBSTITUTE(SUBSTITUTE(SUBSTITUTE(SUBSTITUTE(SUBSTITUTE(SUBSTITUTE(SUBSTITUTE(SUBSTITUTE(UPPER(_xlpm.a)," ",""),"CONTROL","CTRL"),"CTL","CTRL"),"ESCAPE","ESC"),"RETURN","ENTER"),"PAGEDOWN","PGDN"),"PGDOWN","PGDN"),"PAGEUP","PGUP"),"ARROWKEYS","ARROW"),"ARROWKEY","ARROW"),"ARROWS","ARROW"),"DOWNARROW","DOWN"),"UPARROW","UP"),"LEFTARROW","LEFT"),"RIGHTARROW","RIGHT"),"ARROWDOWN","DOWN"),"ARROWUP","UP"),"ARROWLEFT","LEFT"),"ARROWRIGHT","RIGHT"),"↓","DOWN"),"↑","UP"),"←","LEFT"),"→","RIGHT"),"SPACEBAR","SPACE"),"−","-"),"MINUS","-"),"PLUS","+")=Key!$E$55:$J$55),"✔ CLEAR","✘ TRY AGAIN"))),"✘ TRY AGAIN")} | F17: {=IF(E17="Show hint",Key!$B$55,"")} | G17: {=IF(LEFT(D17,1)="✔",IF(E17="Show hint",5,10),0)} -> 0
A18: W5 | B18: Which function turns a number or date into formatted text? (from F5-4 Assemble) | D18: {=IFERROR(_xlfn.LET(_xlpm.a,'F6-3 Deadlines'!$C$18,IF(TRIM(_xlpm.a&"")="","",IF(OR(SUBSTITUTE(SUBSTITUTE(SUBSTITUTE(SUBSTITUTE(SUBSTITUTE(SUBSTITUTE(SUBSTITUTE(SUBSTITUTE(SUBSTITUTE(SUBSTITUTE(SUBSTITUTE(SUBSTITUTE(SUBSTITUTE(SUBSTITUTE(SUBSTITUTE(SUBSTITUTE(SUBSTITUTE(SUBSTITUTE(SUBSTITUTE(SUBSTITUTE(SUBSTITUTE(SUBSTITUTE(SUBSTITUTE(SUBSTITUTE(SUBSTITUTE(SUBSTITUTE(SUBSTITUTE(UPPER(_xlpm.a)," ",""),"CONTROL","CTRL"),"CTL","CTRL"),"ESCAPE","ESC"),"RETURN","ENTER"),"PAGEDOWN","PGDN"),"PGDOWN","PGDN"),"PAGEUP","PGUP"),"ARROWKEYS","ARROW"),"ARROWKEY","ARROW"),"ARROWS","ARROW"),"DOWNARROW","DOWN"),"UPARROW","UP"),"LEFTARROW","LEFT"),"RIGHTARROW","RIGHT"),"ARROWDOWN","DOWN"),"ARROWUP","UP"),"ARROWLEFT","LEFT"),"ARROWRIGHT","RIGHT"),"↓","DOWN"),"↑","UP"),"←","LEFT"),"→","RIGHT"),"SPACEBAR","SPACE"),"−","-"),"MINUS","-"),"PLUS","+")=Key!$E$56:$J$56),"✔ CLEAR","✘ TRY AGAIN"))),"✘ TRY AGAIN")} | F18: {=IF(E18="Show hint",Key!$B$56,"")} | G18: {=IF(LEFT(D18,1)="✔",IF(E18="Show hint",5,10),0)} -> 0
A19: W6 | B19: Which function turns text that looks like a number into a number? (from F5-4 Assemble) | D19: {=IFERROR(_xlfn.LET(_xlpm.a,'F6-3 Deadlines'!$C$19,IF(TRIM(_xlpm.a&"")="","",IF(OR(SUBSTITUTE(SUBSTITUTE(SUBSTITUTE(SUBSTITUTE(SUBSTITUTE(SUBSTITUTE(SUBSTITUTE(SUBSTITUTE(SUBSTITUTE(SUBSTITUTE(SUBSTITUTE(SUBSTITUTE(SUBSTITUTE(SUBSTITUTE(SUBSTITUTE(SUBSTITUTE(SUBSTITUTE(SUBSTITUTE(SUBSTITUTE(SUBSTITUTE(SUBSTITUTE(SUBSTITUTE(SUBSTITUTE(SUBSTITUTE(SUBSTITUTE(SUBSTITUTE(SUBSTITUTE(UPPER(_xlpm.a)," ",""),"CONTROL","CTRL"),"CTL","CTRL"),"ESCAPE","ESC"),"RETURN","ENTER"),"PAGEDOWN","PGDN"),"PGDOWN","PGDN"),"PAGEUP","PGUP"),"ARROWKEYS","ARROW"),"ARROWKEY","ARROW"),"ARROWS","ARROW"),"DOWNARROW","DOWN"),"UPARROW","UP"),"LEFTARROW","LEFT"),"RIGHTARROW","RIGHT"),"ARROWDOWN","DOWN"),"ARROWUP","UP"),"ARROWLEFT","LEFT"),"ARROWRIGHT","RIGHT"),"↓","DOWN"),"↑","UP"),"←","LEFT"),"→","RIGHT"),"SPACEBAR","SPACE"),"−","-"),"MINUS","-"),"PLUS","+")=Key!$E$57:$J$57),"✔ CLEAR","✘ TRY AGAIN"))),"✘ TRY AGAIN")} | F19: {=IF(E19="Show hint",Key!$B$57,"")} | G19: {=IF(LEFT(D19,1)="✔",IF(E19="Show hint",5,10),0)} -> 0
A20: W7 | B20: Which KeyTips sort Z to A? (from S4-4 Data Wrangler) | D20: {=IFERROR(_xlfn.LET(_xlpm.a,'F6-3 Deadlines'!$C$20,IF(TRIM(_xlpm.a&"")="","",IF(OR(SUBSTITUTE(SUBSTITUTE(SUBSTITUTE(SUBSTITUTE(SUBSTITUTE(SUBSTITUTE(SUBSTITUTE(SUBSTITUTE(SUBSTITUTE(SUBSTITUTE(SUBSTITUTE(SUBSTITUTE(SUBSTITUTE(SUBSTITUTE(SUBSTITUTE(SUBSTITUTE(SUBSTITUTE(SUBSTITUTE(SUBSTITUTE(SUBSTITUTE(SUBSTITUTE(SUBSTITUTE(SUBSTITUTE(SUBSTITUTE(SUBSTITUTE(SUBSTITUTE(SUBSTITUTE(UPPER(_xlpm.a)," ",""),"CONTROL","CTRL"),"CTL","CTRL"),"ESCAPE","ESC"),"RETURN","ENTER"),"PAGEDOWN","PGDN"),"PGDOWN","PGDN"),"PAGEUP","PGUP"),"ARROWKEYS","ARROW"),"ARROWKEY","ARROW"),"ARROWS","ARROW"),"DOWNARROW","DOWN"),"UPARROW","UP"),"LEFTARROW","LEFT"),"RIGHTARROW","RIGHT"),"ARROWDOWN","DOWN"),"ARROWUP","UP"),"ARROWLEFT","LEFT"),"ARROWRIGHT","RIGHT"),"↓","DOWN"),"↑","UP"),"←","LEFT"),"→","RIGHT"),"SPACEBAR","SPACE"),"−","-"),"MINUS","-"),"PLUS","+")=Key!$E$58:$T$58),"✔ CLEAR","✘ TRY AGAIN"))),"✘ TRY AGAIN")} | F20: {=IF(E20="Show hint",Key!$B$58,"")} | G20: {=IF(LEFT(D20,1)="✔",IF(E20="Show hint",5,10),0)} -> 0
A21: W8 | B21: Which keys insert an instant chart on the sheet? (from S4-4 Data Wrangler) | D21: {=IFERROR(_xlfn.LET(_xlpm.a,'F6-3 Deadlines'!$C$21,IF(TRIM(_xlpm.a&"")="","",IF(OR(SUBSTITUTE(SUBSTITUTE(SUBSTITUTE(SUBSTITUTE(SUBSTITUTE(SUBSTITUTE(SUBSTITUTE(SUBSTITUTE(SUBSTITUTE(SUBSTITUTE(SUBSTITUTE(SUBSTITUTE(SUBSTITUTE(SUBSTITUTE(SUBSTITUTE(SUBSTITUTE(SUBSTITUTE(SUBSTITUTE(SUBSTITUTE(SUBSTITUTE(SUBSTITUTE(SUBSTITUTE(SUBSTITUTE(SUBSTITUTE(SUBSTITUTE(SUBSTITUTE(SUBSTITUTE(UPPER(_xlpm.a)," ",""),"CONTROL","CTRL"),"CTL","CTRL"),"ESCAPE","ESC"),"RETURN","ENTER"),"PAGEDOWN","PGDN"),"PGDOWN","PGDN"),"PAGEUP","PGUP"),"ARROWKEYS","ARROW"),"ARROWKEY","ARROW"),"ARROWS","ARROW"),"DOWNARROW","DOWN"),"UPARROW","UP"),"LEFTARROW","LEFT"),"RIGHTARROW","RIGHT"),"ARROWDOWN","DOWN"),"ARROWUP","UP"),"ARROWLEFT","LEFT"),"ARROWRIGHT","RIGHT"),"↓","DOWN"),"↑","UP"),"←","LEFT"),"→","RIGHT"),"SPACEBAR","SPACE"),"−","-"),"MINUS","-"),"PLUS","+")=Key!$E$59:$E$59),"✔ CLEAR","✘ TRY AGAIN"))),"✘ TRY AGAIN")} | F21: {=IF(E21="Show hint",Key!$B$59,"")} | G21: {=IF(LEFT(D21,1)="✔",IF(E21="Show hint",5,10),0)} -> 0
A22: W9 | B22: Which modern function finds a value and returns the matching item from another column? (from F4-1 Seeker) | D22: {=IFERROR(_xlfn.LET(_xlpm.a,'F6-3 Deadlines'!$C$22,IF(TRIM(_xlpm.a&"")="","",IF(OR(SUBSTITUTE(SUBSTITUTE(SUBSTITUTE(SUBSTITUTE(SUBSTITUTE(SUBSTITUTE(SUBSTITUTE(SUBSTITUTE(SUBSTITUTE(SUBSTITUTE(SUBSTITUTE(SUBSTITUTE(SUBSTITUTE(SUBSTITUTE(SUBSTITUTE(SUBSTITUTE(SUBSTITUTE(SUBSTITUTE(SUBSTITUTE(SUBSTITUTE(SUBSTITUTE(SUBSTITUTE(SUBSTITUTE(SUBSTITUTE(SUBSTITUTE(SUBSTITUTE(SUBSTITUTE(UPPER(_xlpm.a)," ",""),"CONTROL","CTRL"),"CTL","CTRL"),"ESCAPE","ESC"),"RETURN","ENTER"),"PAGEDOWN","PGDN"),"PGDOWN","PGDN"),"PAGEUP","PGUP"),"ARROWKEYS","ARROW"),"ARROWKEY","ARROW"),"ARROWS","ARROW"),"DOWNARROW","DOWN"),"UPARROW","UP"),"LEFTARROW","LEFT"),"RIGHTARROW","RIGHT"),"ARROWDOWN","DOWN"),"ARROWUP","UP"),"ARROWLEFT","LEFT"),"ARROWRIGHT","RIGHT"),"↓","DOWN"),"↑","UP"),"←","LEFT"),"→","RIGHT"),"SPACEBAR","SPACE"),"−","-"),"MINUS","-"),"PLUS","+")=Key!$E$60:$J$60),"✔ CLEAR","✘ TRY AGAIN"))),"✘ TRY AGAIN")} | F22: {=IF(E22="Show hint",Key!$B$60,"")} | G22: {=IF(LEFT(D22,1)="✔",IF(E22="Show hint",5,10),0)} -> 0
A23: W10 | B23: Which symbol locks a range so it doesn't shift when you fill down? (from F4-1 Seeker) | D23: {=IFERROR(_xlfn.LET(_xlpm.a,'F6-3 Deadlines'!$C$23,IF(TRIM(_xlpm.a&"")="","",IF(OR(SUBSTITUTE(SUBSTITUTE(SUBSTITUTE(SUBSTITUTE(SUBSTITUTE(SUBSTITUTE(SUBSTITUTE(SUBSTITUTE(SUBSTITUTE(SUBSTITUTE(SUBSTITUTE(SUBSTITUTE(SUBSTITUTE(SUBSTITUTE(SUBSTITUTE(SUBSTITUTE(SUBSTITUTE(SUBSTITUTE(SUBSTITUTE(SUBSTITUTE(SUBSTITUTE(SUBSTITUTE(SUBSTITUTE(SUBSTITUTE(SUBSTITUTE(SUBSTITUTE(SUBSTITUTE(UPPER(_xlpm.a)," ",""),"CONTROL","CTRL"),"CTL","CTRL"),"ESCAPE","ESC"),"RETURN","ENTER"),"PAGEDOWN","PGDN"),"PGDOWN","PGDN"),"PAGEUP","PGUP"),"ARROWKEYS","ARROW"),"ARROWKEY","ARROW"),"ARROWS","ARROW"),"DOWNARROW","DOWN"),"UPARROW","UP"),"LEFTARROW","LEFT"),"RIGHTARROW","RIGHT"),"ARROWDOWN","DOWN"),"ARROWUP","UP"),"ARROWLEFT","LEFT"),"ARROWRIGHT","RIGHT"),"↓","DOWN"),"↑","UP"),"←","LEFT"),"→","RIGHT"),"SPACEBAR","SPACE"),"−","-"),"MINUS","-"),"PLUS","+")=Key!$E$61:$G$61),"✔ CLEAR","✘ TRY AGAIN"))),"✘ TRY AGAIN")} | F23: {=IF(E23="Show hint",Key!$B$61,"")} | G23: {=IF(LEFT(D23,1)="✔",IF(E23="Show hint",5,10),0)} -> 0
A25: TRAINING · recognize the move (pick from the list)
A26: # | B26: Mission | C26: Your answer | D26: Result | E26: Hint? | F26: Hint | G26: XP
A27: T1 | B27: Which function moves a date forward or back by whole months? | D27: {=IFERROR(IF('F6-3 Deadlines'!$C$27&""="","",IF('F6-3 Deadlines'!$C$27&""=Key!$C$62&"","✔ CLEAR","✘ TRY AGAIN")),"✘ TRY AGAIN")} | F27: {=IF(E27="Show hint",Key!$B$62,"")} | G27: {=IF(LEFT(D27,1)="✔",IF(E27="Show hint",5,10),0)} -> 0
A28: T2 | B28: Which function returns the last day of a month? | D28: {=IFERROR(IF('F6-3 Deadlines'!$C$28&""="","",IF('F6-3 Deadlines'!$C$28&""=Key!$C$63&"","✔ CLEAR","✘ TRY AGAIN")),"✘ TRY AGAIN")} | F28: {=IF(E28="Show hint",Key!$B$63,"")} | G28: {=IF(LEFT(D28,1)="✔",IF(E28="Show hint",5,10),0)} -> 0
A29: T3 | B29: Which function counts the working days between two dates? | D29: {=IFERROR(IF('F6-3 Deadlines'!$C$29&""="","",IF('F6-3 Deadlines'!$C$29&""=Key!$C$64&"","✔ CLEAR","✘ TRY AGAIN")),"✘ TRY AGAIN")} | F29: {=IF(E29="Show hint",Key!$B$64,"")} | G29: {=IF(LEFT(D29,1)="✔",IF(E29="Show hint",5,10),0)} -> 0
A30: T4 | B30: Which function returns the date a number of working days later? | D30: {=IFERROR(IF('F6-3 Deadlines'!$C$30&""="","",IF('F6-3 Deadlines'!$C$30&""=Key!$C$65&"","✔ CLEAR","✘ TRY AGAIN")),"✘ TRY AGAIN")} | F30: {=IF(E30="Show hint",Key!$B$65,"")} | G30: {=IF(LEFT(D30,1)="✔",IF(E30="Show hint",5,10),0)} -> 0
A32: CHALLENGES · recall it, then do it
B33: ▶ Open F6-3 Arena (or press Ctrl+PgDn)
A34: # | B34: Mission | C34: Your answer | D34: Result | E34: Hint? | F34: Hint | G34: XP
A35: C1 | B35: Which function moves a date forward or back by whole months? | D35: {=IFERROR(_xlfn.LET(_xlpm.a,'F6-3 Deadlines'!$C$35,IF(TRIM(_xlpm.a&"")="","",IF(OR(SUBSTITUTE(SUBSTITUTE(SUBSTITUTE(SUBSTITUTE(SUBSTITUTE(SUBSTITUTE(SUBSTITUTE(SUBSTITUTE(SUBSTITUTE(SUBSTITUTE(SUBSTITUTE(SUBSTITUTE(SUBSTITUTE(SUBSTITUTE(SUBSTITUTE(SUBSTITUTE(SUBSTITUTE(SUBSTITUTE(SUBSTITUTE(SUBSTITUTE(SUBSTITUTE(SUBSTITUTE(SUBSTITUTE(SUBSTITUTE(SUBSTITUTE(SUBSTITUTE(SUBSTITUTE(UPPER(_xlpm.a)," ",""),"CONTROL","CTRL"),"CTL","CTRL"),"ESCAPE","ESC"),"RETURN","ENTER"),"PAGEDOWN","PGDN"),"PGDOWN","PGDN"),"PAGEUP","PGUP"),"ARROWKEYS","ARROW"),"ARROWKEY","ARROW"),"ARROWS","ARROW"),"DOWNARROW","DOWN"),"UPARROW","UP"),"LEFTARROW","LEFT"),"RIGHTARROW","RIGHT"),"ARROWDOWN","DOWN"),"ARROWUP","UP"),"ARROWLEFT","LEFT"),"ARROWRIGHT","RIGHT"),"↓","DOWN"),"↑","UP"),"←","LEFT"),"→","RIGHT"),"SPACEBAR","SPACE"),"−","-"),"MINUS","-"),"PLUS","+")=Key!$E$66:$J$66),"✔ CLEAR","✘ TRY AGAIN"))),"✘ TRY AGAIN")} | F35: {=IF(E35="Show hint",Key!$B$66,"")} | G35: {=IF(LEFT(D35,1)="✔",IF(E35="Show hint",5,10),0)} -> 0
A36: C2 | B36: Which function returns the last day of a month? | D36: {=IFERROR(_xlfn.LET(_xlpm.a,'F6-3 Deadlines'!$C$36,IF(TRIM(_xlpm.a&"")="","",IF(OR(SUBSTITUTE(SUBSTITUTE(SUBSTITUTE(SUBSTITUTE(SUBSTITUTE(SUBSTITUTE(SUBSTITUTE(SUBSTITUTE(SUBSTITUTE(SUBSTITUTE(SUBSTITUTE(SUBSTITUTE(SUBSTITUTE(SUBSTITUTE(SUBSTITUTE(SUBSTITUTE(SUBSTITUTE(SUBSTITUTE(SUBSTITUTE(SUBSTITUTE(SUBSTITUTE(SUBSTITUTE(SUBSTITUTE(SUBSTITUTE(SUBSTITUTE(SUBSTITUTE(SUBSTITUTE(UPPER(_xlpm.a)," ",""),"CONTROL","CTRL"),"CTL","CTRL"),"ESCAPE","ESC"),"RETURN","ENTER"),"PAGEDOWN","PGDN"),"PGDOWN","PGDN"),"PAGEUP","PGUP"),"ARROWKEYS","ARROW"),"ARROWKEY","ARROW"),"ARROWS","ARROW"),"DOWNARROW","DOWN"),"UPARROW","UP"),"LEFTARROW","LEFT"),"RIGHTARROW","RIGHT"),"ARROWDOWN","DOWN"),"ARROWUP","UP"),"ARROWLEFT","LEFT"),"ARROWRIGHT","RIGHT"),"↓","DOWN"),"↑","UP"),"←","LEFT"),"→","RIGHT"),"SPACEBAR","SPACE"),"−","-"),"MINUS","-"),"PLUS","+")=Key!$E$67:$J$67),"✔ CLEAR","✘ TRY AGAIN"))),"✘ TRY AGAIN")} | F36: {=IF(E36="Show hint",Key!$B$67,"")} | G36: {=IF(LEFT(D36,1)="✔",IF(E36="Show hint",5,10),0)} -> 0
