Workbook

Sheet Start
A1: FORMULAS 7 ▸ DYNAMIC ARRAYS
A2: One formula, many results: SEQUENCE, FILTER, SORT, UNIQUE and LET.
A4: HOW TO PLAY
A5: 1 · Each stage: read the BRIEFING, then answer WARM-UP, TRAINING and CHALLENGES.
A6: 2 · Yellow cells are yours: type, pick from a list (Alt+↓), or follow a ▶ ARENA link and do the move there.
A7: 3 · ✔ CLEAR = right · ✘ = try again · · not yet = drill not done. Stuck? Pick 'Show hint' (5 XP instead of 10).
A8: 4 · Formatting or hiding drills: press F9 to refresh the check. Tab jumps between yellow cells.
A9: Needs Windows with Microsoft Excel 365 or 2021+ (English). In Protected View, click Enable Editing.
A11: STAGE SELECT
A12: Stage | B12: Name | C12: Score | D12: Stars | E12: Status | F12: Go
A13: F7-1 | B13: Spill Zone | C13: {=SUM('F7-1 Spill Zone'!$G$14:$G$41)&" / 210"} -> 0 / 210 | D13: {=IF(SUM('F7-1 Spill Zone'!$G$14:$G$41)>=210,"★★★",IF(SUM('F7-1 Spill Zone'!$G$14:$G$41)>=210*0.8,"★★☆",IF(SUM('F7-1 Spill Zone'!$G$14:$G$41)>=210*0.5,"★☆☆","☆☆☆")))} -> ☆☆☆ | E13: {=IF(SUM('F7-1 Spill Zone'!$G$14:$G$41)>=210,"PERFECT",IF(SUM('F7-1 Spill Zone'!$G$14:$G$41)>=210*0.5,"CLEARED",IF(SUM('F7-1 Spill Zone'!$G$14:$G$41)>0,"IN PROGRESS","NEW")))} -> NEW | F13: Go to F7-1 Spill Zone
A14: F7-2 | B14: Sifter | C14: {=SUM('F7-2 Sifter'!$G$13:$G$38)&" / 190"} -> 0 / 190 | D14: {=IF(SUM('F7-2 Sifter'!$G$13:$G$38)>=190,"★★★",IF(SUM('F7-2 Sifter'!$G$13:$G$38)>=190*0.8,"★★☆",IF(SUM('F7-2 Sifter'!$G$13:$G$38)>=190*0.5,"★☆☆","☆☆☆")))} -> ☆☆☆ | E14: {=IF(SUM('F7-2 Sifter'!$G$13:$G$38)>=190,"PERFECT",IF(SUM('F7-2 Sifter'!$G$13:$G$38)>=190*0.5,"CLEARED",IF(SUM('F7-2 Sifter'!$G$13:$G$38)>0,"IN PROGRESS","NEW")))} -> NEW | F14: Go to F7-2 Sifter
A15: F7-3 | B15: Sorter | C15: {=SUM('F7-3 Sorter'!$G$13:$G$39)&" / 200"} -> 0 / 200 | D15: {=IF(SUM('F7-3 Sorter'!$G$13:$G$39)>=200,"★★★",IF(SUM('F7-3 Sorter'!$G$13:$G$39)>=200*0.8,"★★☆",IF(SUM('F7-3 Sorter'!$G$13:$G$39)>=200*0.5,"★☆☆","☆☆☆")))} -> ☆☆☆ | E15: {=IF(SUM('F7-3 Sorter'!$G$13:$G$39)>=200,"PERFECT",IF(SUM('F7-3 Sorter'!$G$13:$G$39)>=200*0.5,"CLEARED",IF(SUM('F7-3 Sorter'!$G$13:$G$39)>0,"IN PROGRESS","NEW")))} -> NEW | F15: Go to F7-3 Sorter
A16: F7-4 | B16: Combo | C16: {=SUM('F7-4 Combo'!$G$12:$G$36)&" / 180"} -> 0 / 180 | D16: {=IF(SUM('F7-4 Combo'!$G$12:$G$36)>=180,"★★★",IF(SUM('F7-4 Combo'!$G$12:$G$36)>=180*0.8,"★★☆",IF(SUM('F7-4 Combo'!$G$12:$G$36)>=180*0.5,"★☆☆","☆☆☆")))} -> ☆☆☆ | E16: {=IF(SUM('F7-4 Combo'!$G$12:$G$36)>=180,"PERFECT",IF(SUM('F7-4 Combo'!$G$12:$G$36)>=180*0.5,"CLEARED",IF(SUM('F7-4 Combo'!$G$12:$G$36)>0,"IN PROGRESS","NEW")))} -> NEW | F16: Go to F7-4 Combo
A17: BOSS | B17: Boss | C17: {=SUM(Boss!$G$14:$G$35)&" / 180"} -> 0 / 180 | D17: {=IF(SUM(Boss!$G$14:$G$35)>=180,"★★★",IF(SUM(Boss!$G$14:$G$35)>=180*0.8,"★★☆",IF(SUM(Boss!$G$14:$G$35)>=180*0.5,"★☆☆","☆☆☆")))} -> ☆☆☆ | E17: {=IF(Boss!$C$10="OPEN",IF(SUM(Boss!$G$14:$G$35)>=180*0.5,"DEFEATED","OPEN"),"LOCKED")} -> LOCKED | F17: Go to the Boss
A19: TOTAL SCORE | B19: {=(SUM('F7-1 Spill Zone'!$G$14:$G$41)+SUM('F7-2 Sifter'!$G$13:$G$38)+SUM('F7-3 Sorter'!$G$13:$G$39)+SUM('F7-4 Combo'!$G$12:$G$36)+SUM(Boss!$G$14:$G$35))&" / 960"} -> 0 / 960
A20: RANK | B20: {=_xlfn.LET(_xlpm.p,(SUM('F7-1 Spill Zone'!$G$14:$G$41)+SUM('F7-2 Sifter'!$G$13:$G$38)+SUM('F7-3 Sorter'!$G$13:$G$39)+SUM('F7-4 Combo'!$G$12:$G$36)+SUM(Boss!$G$14:$G$35))/960,IF(AND(_xlpm.p>=1,ISNUMBER(Boss!$C$8),Boss!$C$8<=15),"S",IF(_xlpm.p>=0.9,"A",IF(_xlpm.p>=0.75,"B",IF(_xlpm.p>=0.5,"C","D")))))} -> D | C20: S = 100% and under par · A ≥ 90% · B ≥ 75% · C ≥ 50%
A21: BEST TIME | B21: {=IF(ISNUMBER(Boss!$C$8),Boss!$C$8&" min (par 15)","—")} -> —
A22: NEXT UP | B22: {=IFERROR(INDEX($A$13:$A$16,MATCH("☆☆☆",$D$13:$D$16,0))&" "&INDEX($B$13:$B$16,MATCH("☆☆☆",$D$13:$D$16,0)),IF(Start!$E$17="DEFEATED","All clear! Aim for rank S","the Boss"))} -> F7-1 Spill Zone
A24: Replay a stage: select a run of its yellow cells (Ctrl+click to add more), then press Delete. Undo an arena drill with Ctrl+Z.

Sheet F7-1 Spill Zone
A1: STAGE F7-1 ▸ SPILL ZONE
A2: Goal: let one formula fill many cells
A3: {="SCORE "&TEXT(SUM($G$14:$G$41),"0000")&" / 0210"} -> SCORE 0000 / 0210 | C3: {=IF(SUM($G$14:$G$41)>=210,"★★★",IF(SUM($G$14:$G$41)>=210*0.8,"★★☆",IF(SUM($G$14:$G$41)>=210*0.5,"★☆☆","☆☆☆")))} -> ☆☆☆ | D3: {=REPT("█",ROUND(10*SUM($G$14:$G$41)/210,0))&REPT("░",10-ROUND(10*SUM($G$14:$G$41)/210,0))&" "&TEXT(SUM($G$14:$G$41)/210,"0%")} -> ░░░░░░░░░░ 0% | F3: {=IF(SUM($G$14:$G$41)>=210*0.5,"STAGE CLEAR! ▶ Next: F7-2 Sifter","")}
A5: BRIEFING · new moves in this stage
A6: # | B6: What it does · Pro tip | C6: Keys / Syntax
A7: 1 | B7: One formula can return many values; they spill into the cells around it. Tip: Edit only the top-left cell; the rest follow. | C7: spill
A8: 2 | B8: #SPILL! means something is in the way of the results. Tip: Clear the blocking cells and the results appear. | C8: #SPILL!
A9: 3 | B9: Add # after the top-left cell to refer to the whole spill. Tip: =SUM(H5#) grows and shrinks with the spill. | C9: H5#
A10: 4 | B10: SEQUENCE(rows) spills the numbers 1, 2, 3 … Tip: =SEQUENCE(4,1,10,10) spills 10, 20, 30, 40. | C10: SEQUENCE
A12: WARM-UP · flashback to earlier stages
A13: # | B13: Mission | C13: Your answer | D13: Result | E13: Hint? | F13: Hint | G13: XP
A14: W1 | B14: Which function returns today's date? (from F6-1 Calendar) | D14: {=IFERROR(_xlfn.LET(_xlpm.a,'F7-1 Spill Zone'!$C$14,IF(TRIM(_xlpm.a&"")="","",IF(OR(SUBSTITUTE(SUBSTITUTE(SUBSTITUTE(SUBSTITUTE(SUBSTITUTE(SUBSTITUTE(SUBSTITUTE(SUBSTITUTE(SUBSTITUTE(SUBSTITUTE(SUBSTITUTE(SUBSTITUTE(SUBSTITUTE(SUBSTITUTE(SUBSTITUTE(SUBSTITUTE(SUBSTITUTE(SUBSTITUTE(SUBSTITUTE(SUBSTITUTE(SUBSTITUTE(SUBSTITUTE(SUBSTITUTE(SUBSTITUTE(SUBSTITUTE(SUBSTITUTE(SUBSTITUTE(UPPER(_xlpm.a)," ",""),"CONTROL","CTRL"),"CTL","CTRL"),"ESCAPE","ESC"),"RETURN","ENTER"),"PAGEDOWN","PGDN"),"PGDOWN","PGDN"),"PAGEUP","PGUP"),"ARROWKEYS","ARROW"),"ARROWKEY","ARROW"),"ARROWS","ARROW"),"DOWNARROW","DOWN"),"UPARROW","UP"),"LEFTARROW","LEFT"),"RIGHTARROW","RIGHT"),"ARROWDOWN","DOWN"),"ARROWUP","UP"),"ARROWLEFT","LEFT"),"ARROWRIGHT","RIGHT"),"↓","DOWN"),"↑","UP"),"←","LEFT"),"→","RIGHT"),"SPACEBAR","SPACE"),"−","-"),"MINUS","-"),"PLUS","+")=Key!$E$2:$J$2),"✔ CLEAR","✘ TRY AGAIN"))),"✘ TRY AGAIN")} | F14: {=IF(E14="Show hint",Key!$B$2,"")} | G14: {=IF(LEFT(D14,1)="✔",IF(E14="Show hint",5,10),0)} -> 0
A15: W2 | B15: Which function returns the current date and time? (from F6-1 Calendar) | D15: {=IFERROR(_xlfn.LET(_xlpm.a,'F7-1 Spill Zone'!$C$15,IF(TRIM(_xlpm.a&"")="","",IF(OR(SUBSTITUTE(SUBSTITUTE(SUBSTITUTE(SUBSTITUTE(SUBSTITUTE(SUBSTITUTE(SUBSTITUTE(SUBSTITUTE(SUBSTITUTE(SUBSTITUTE(SUBSTITUTE(SUBSTITUTE(SUBSTITUTE(SUBSTITUTE(SUBSTITUTE(SUBSTITUTE(SUBSTITUTE(SUBSTITUTE(SUBSTITUTE(SUBSTITUTE(SUBSTITUTE(SUBSTITUTE(SUBSTITUTE(SUBSTITUTE(SUBSTITUTE(SUBSTITUTE(SUBSTITUTE(UPPER(_xlpm.a)," ",""),"CONTROL","CTRL"),"CTL","CTRL"),"ESCAPE","ESC"),"RETURN","ENTER"),"PAGEDOWN","PGDN"),"PGDOWN","PGDN"),"PAGEUP","PGUP"),"ARROWKEYS","ARROW"),"ARROWKEY","ARROW"),"ARROWS","ARROW"),"DOWNARROW","DOWN"),"UPARROW","UP"),"LEFTARROW","LEFT"),"RIGHTARROW","RIGHT"),"ARROWDOWN","DOWN"),"ARROWUP","UP"),"ARROWLEFT","LEFT"),"ARROWRIGHT","RIGHT"),"↓","DOWN"),"↑","UP"),"←","LEFT"),"→","RIGHT"),"SPACEBAR","SPACE"),"−","-"),"MINUS","-"),"PLUS","+")=Key!$E$3:$J$3),"✔ CLEAR","✘ TRY AGAIN"))),"✘ TRY AGAIN")} | F15: {=IF(E15="Show hint",Key!$B$3,"")} | G15: {=IF(LEFT(D15,1)="✔",IF(E15="Show hint",5,10),0)} -> 0
A16: W3 | B16: Which function builds a date from a year, month and day? (from F6-1 Calendar) | D16: {=IFERROR(_xlfn.LET(_xlpm.a,'F7-1 Spill Zone'!$C$16,IF(TRIM(_xlpm.a&"")="","",IF(OR(SUBSTITUTE(SUBSTITUTE(SUBSTITUTE(SUBSTITUTE(SUBSTITUTE(SUBSTITUTE(SUBSTITUTE(SUBSTITUTE(SUBSTITUTE(SUBSTITUTE(SUBSTITUTE(SUBSTITUTE(SUBSTITUTE(SUBSTITUTE(SUBSTITUTE(SUBSTITUTE(SUBSTITUTE(SUBSTITUTE(SUBSTITUTE(SUBSTITUTE(SUBSTITUTE(SUBSTITUTE(SUBSTITUTE(SUBSTITUTE(SUBSTITUTE(SUBSTITUTE(SUBSTITUTE(UPPER(_xlpm.a)," ",""),"CONTROL","CTRL"),"CTL","CTRL"),"ESCAPE","ESC"),"RETURN","ENTER"),"PAGEDOWN","PGDN"),"PGDOWN","PGDN"),"PAGEUP","PGUP"),"ARROWKEYS","ARROW"),"ARROWKEY","ARROW"),"ARROWS","ARROW"),"DOWNARROW","DOWN"),"UPARROW","UP"),"LEFTARROW","LEFT"),"RIGHTARROW","RIGHT"),"ARROWDOWN","DOWN"),"ARROWUP","UP"),"ARROWLEFT","LEFT"),"ARROWRIGHT","RIGHT"),"↓","DOWN"),"↑","UP"),"←","LEFT"),"→","RIGHT"),"SPACEBAR","SPACE"),"−","-"),"MINUS","-"),"PLUS","+")=Key!$E$4:$J$4),"✔ CLEAR","✘ TRY AGAIN"))),"✘ TRY AGAIN")} | F16: {=IF(E16="Show hint",Key!$B$4,"")} | G16: {=IF(LEFT(D16,1)="✔",IF(E16="Show hint",5,10),0)} -> 0
A17: W4 | B17: Which function returns the year of a date? (from F6-1 Calendar) | D17: {=IFERROR(_xlfn.LET(_xlpm.a,'F7-1 Spill Zone'!$C$17,IF(TRIM(_xlpm.a&"")="","",IF(OR(SUBSTITUTE(SUBSTITUTE(SUBSTITUTE(SUBSTITUTE(SUBSTITUTE(SUBSTITUTE(SUBSTITUTE(SUBSTITUTE(SUBSTITUTE(SUBSTITUTE(SUBSTITUTE(SUBSTITUTE(SUBSTITUTE(SUBSTITUTE(SUBSTITUTE(SUBSTITUTE(SUBSTITUTE(SUBSTITUTE(SUBSTITUTE(SUBSTITUTE(SUBSTITUTE(SUBSTITUTE(SUBSTITUTE(SUBSTITUTE(SUBSTITUTE(SUBSTITUTE(SUBSTITUTE(UPPER(_xlpm.a)," ",""),"CONTROL","CTRL"),"CTL","CTRL"),"ESCAPE","ESC"),"RETURN","ENTER"),"PAGEDOWN","PGDN"),"PGDOWN","PGDN"),"PAGEUP","PGUP"),"ARROWKEYS","ARROW"),"ARROWKEY","ARROW"),"ARROWS","ARROW"),"DOWNARROW","DOWN"),"UPARROW","UP"),"LEFTARROW","LEFT"),"RIGHTARROW","RIGHT"),"ARROWDOWN","DOWN"),"ARROWUP","UP"),"ARROWLEFT","LEFT"),"ARROWRIGHT","RIGHT"),"↓","DOWN"),"↑","UP"),"←","LEFT"),"→","RIGHT"),"SPACEBAR","SPACE"),"−","-"),"MINUS","-"),"PLUS","+")=Key!$E$5:$J$5),"✔ CLEAR","✘ TRY AGAIN"))),"✘ TRY AGAIN")} | F17: {=IF(E17="Show hint",Key!$B$5,"")} | G17: {=IF(LEFT(D17,1)="✔",IF(E17="Show hint",5,10),0)} -> 0
A18: W5 | B18: Which function returns the month number of a date? (from F6-1 Calendar) | D18: {=IFERROR(_xlfn.LET(_xlpm.a,'F7-1 Spill Zone'!$C$18,IF(TRIM(_xlpm.a&"")="","",IF(OR(SUBSTITUTE(SUBSTITUTE(SUBSTITUTE(SUBSTITUTE(SUBSTITUTE(SUBSTITUTE(SUBSTITUTE(SUBSTITUTE(SUBSTITUTE(SUBSTITUTE(SUBSTITUTE(SUBSTITUTE(SUBSTITUTE(SUBSTITUTE(SUBSTITUTE(SUBSTITUTE(SUBSTITUTE(SUBSTITUTE(SUBSTITUTE(SUBSTITUTE(SUBSTITUTE(SUBSTITUTE(SUBSTITUTE(SUBSTITUTE(SUBSTITUTE(SUBSTITUTE(SUBSTITUTE(UPPER(_xlpm.a)," ",""),"CONTROL","CTRL"),"CTL","CTRL"),"ESCAPE","ESC"),"RETURN","ENTER"),"PAGEDOWN","PGDN"),"PGDOWN","PGDN"),"PAGEUP","PGUP"),"ARROWKEYS","ARROW"),"ARROWKEY","ARROW"),"ARROWS","ARROW"),"DOWNARROW","DOWN"),"UPARROW","UP"),"LEFTARROW","LEFT"),"RIGHTARROW","RIGHT"),"ARROWDOWN","DOWN"),"ARROWUP","UP"),"ARROWLEFT","LEFT"),"ARROWRIGHT","RIGHT"),"↓","DOWN"),"↑","UP"),"←","LEFT"),"→","RIGHT"),"SPACEBAR","SPACE"),"−","-"),"MINUS","-"),"PLUS","+")=Key!$E$6:$J$6),"✔ CLEAR","✘ TRY AGAIN"))),"✘ TRY AGAIN")} | F18: {=IF(E18="Show hint",Key!$B$6,"")} | G18: {=IF(LEFT(D18,1)="✔",IF(E18="Show hint",5,10),0)} -> 0
A19: W6 | B19: Which function returns the day of the month? (from F6-1 Calendar) | D19: {=IFERROR(_xlfn.LET(_xlpm.a,'F7-1 Spill Zone'!$C$19,IF(TRIM(_xlpm.a&"")="","",IF(OR(SUBSTITUTE(SUBSTITUTE(SUBSTITUTE(SUBSTITUTE(SUBSTITUTE(SUBSTITUTE(SUBSTITUTE(SUBSTITUTE(SUBSTITUTE(SUBSTITUTE(SUBSTITUTE(SUBSTITUTE(SUBSTITUTE(SUBSTITUTE(SUBSTITUTE(SUBSTITUTE(SUBSTITUTE(SUBSTITUTE(SUBSTITUTE(SUBSTITUTE(SUBSTITUTE(SUBSTITUTE(SUBSTITUTE(SUBSTITUTE(SUBSTITUTE(SUBSTITUTE(SUBSTITUTE(UPPER(_xlpm.a)," ",""),"CONTROL","CTRL"),"CTL","CTRL"),"ESCAPE","ESC"),"RETURN","ENTER"),"PAGEDOWN","PGDN"),"PGDOWN","PGDN"),"PAGEUP","PGUP"),"ARROWKEYS","ARROW"),"ARROWKEY","ARROW"),"ARROWS","ARROW"),"DOWNARROW","DOWN"),"UPARROW","UP"),"LEFTARROW","LEFT"),"RIGHTARROW","RIGHT"),"ARROWDOWN","DOWN"),"ARROWUP","UP"),"ARROWLEFT","LEFT"),"ARROWRIGHT","RIGHT"),"↓","DOWN"),"↑","UP"),"←","LEFT"),"→","RIGHT"),"SPACEBAR","SPACE"),"−","-"),"MINUS","-"),"PLUS","+")=Key!$E$7:$J$7),"✔ CLEAR","✘ TRY AGAIN"))),"✘ TRY AGAIN")} | F19: {=IF(E19="Show hint",Key!$B$7,"")} | G19: {=IF(LEFT(D19,1)="✔",IF(E19="Show hint",5,10),0)} -> 0
A20: W7 | B20: Which function returns the day of the week as a number? (from F6-1 Calendar) | D20: {=IFERROR(_xlfn.LET(_xlpm.a,'F7-1 Spill Zone'!$C$20,IF(TRIM(_xlpm.a&"")="","",IF(OR(SUBSTITUTE(SUBSTITUTE(SUBSTITUTE(SUBSTITUTE(SUBSTITUTE(SUBSTITUTE(SUBSTITUTE(SUBSTITUTE(SUBSTITUTE(SUBSTITUTE(SUBSTITUTE(SUBSTITUTE(SUBSTITUTE(SUBSTITUTE(SUBSTITUTE(SUBSTITUTE(SUBSTITUTE(SUBSTITUTE(SUBSTITUTE(SUBSTITUTE(SUBSTITUTE(SUBSTITUTE(SUBSTITUTE(SUBSTITUTE(SUBSTITUTE(SUBSTITUTE(SUBSTITUTE(UPPER(_xlpm.a)," ",""),"CONTROL","CTRL"),"CTL","CTRL"),"ESCAPE","ESC"),"RETURN","ENTER"),"PAGEDOWN","PGDN"),"PGDOWN","PGDN"),"PAGEUP","PGUP"),"ARROWKEYS","ARROW"),"ARROWKEY","ARROW"),"ARROWS","ARROW"),"DOWNARROW","DOWN"),"UPARROW","UP"),"LEFTARROW","LEFT"),"RIGHTARROW","RIGHT"),"ARROWDOWN","DOWN"),"ARROWUP","UP"),"ARROWLEFT","LEFT"),"ARROWRIGHT","RIGHT"),"↓","DOWN"),"↑","UP"),"←","LEFT"),"→","RIGHT"),"SPACEBAR","SPACE"),"−","-"),"MINUS","-"),"PLUS","+")=Key!$E$8:$J$8),"✔ CLEAR","✘ TRY AGAIN"))),"✘ TRY AGAIN")} | F20: {=IF(E20="Show hint",Key!$B$8,"")} | G20: {=IF(LEFT(D20,1)="✔",IF(E20="Show hint",5,10),0)} -> 0
A21: W8 | B21: Which function returns the item at a given position in a range? (from F4-4 Power Couple) | D21: {=IFERROR(_xlfn.LET(_xlpm.a,'F7-1 Spill Zone'!$C$21,IF(TRIM(_xlpm.a&"")="","",IF(OR(SUBSTITUTE(SUBSTITUTE(SUBSTITUTE(SUBSTITUTE(SUBSTITUTE(SUBSTITUTE(SUBSTITUTE(SUBSTITUTE(SUBSTITUTE(SUBSTITUTE(SUBSTITUTE(SUBSTITUTE(SUBSTITUTE(SUBSTITUTE(SUBSTITUTE(SUBSTITUTE(SUBSTITUTE(SUBSTITUTE(SUBSTITUTE(SUBSTITUTE(SUBSTITUTE(SUBSTITUTE(SUBSTITUTE(SUBSTITUTE(SUBSTITUTE(SUBSTITUTE(SUBSTITUTE(UPPER(_xlpm.a)," ",""),"CONTROL","CTRL"),"CTL","CTRL"),"ESCAPE","ESC"),"RETURN","ENTER"),"PAGEDOWN","PGDN"),"PGDOWN","PGDN"),"PAGEUP","PGUP"),"ARROWKEYS","ARROW"),"ARROWKEY","ARROW"),"ARROWS","ARROW"),"DOWNARROW","DOWN"),"UPARROW","UP"),"LEFTARROW","LEFT"),"RIGHTARROW","RIGHT"),"ARROWDOWN","DOWN"),"ARROWUP","UP"),"ARROWLEFT","LEFT"),"ARROWRIGHT","RIGHT"),"↓","DOWN"),"↑","UP"),"←","LEFT"),"→","RIGHT"),"SPACEBAR","SPACE"),"−","-"),"MINUS","-"),"PLUS","+")=Key!$E$9:$J$9),"✔ CLEAR","✘ TRY AGAIN"))),"✘ TRY AGAIN")} | F21: {=IF(E21="Show hint",Key!$B$9,"")} | G21: {=IF(LEFT(D21,1)="✔",IF(E21="Show hint",5,10),0)} -> 0
A22: W9 | B22: Which function returns the position of a value in a range? (from F4-4 Power Couple) | D22: {=IFERROR(_xlfn.LET(_xlpm.a,'F7-1 Spill Zone'!$C$22,IF(TRIM(_xlpm.a&"")="","",IF(OR(SUBSTITUTE(SUBSTITUTE(SUBSTITUTE(SUBSTITUTE(SUBSTITUTE(SUBSTITUTE(SUBSTITUTE(SUBSTITUTE(SUBSTITUTE(SUBSTITUTE(SUBSTITUTE(SUBSTITUTE(SUBSTITUTE(SUBSTITUTE(SUBSTITUTE(SUBSTITUTE(SUBSTITUTE(SUBSTITUTE(SUBSTITUTE(SUBSTITUTE(SUBSTITUTE(SUBSTITUTE(SUBSTITUTE(SUBSTITUTE(SUBSTITUTE(SUBSTITUTE(SUBSTITUTE(UPPER(_xlpm.a)," ",""),"CONTROL","CTRL"),"CTL","CTRL"),"ESCAPE","ESC"),"RETURN","ENTER"),"PAGEDOWN","PGDN"),"PGDOWN","PGDN"),"PAGEUP","PGUP"),"ARROWKEYS","ARROW"),"ARROWKEY","ARROW"),"ARROWS","ARROW"),"DOWNARROW","DOWN"),"UPARROW","UP"),"LEFTARROW","LEFT"),"RIGHTARROW","RIGHT"),"ARROWDOWN","DOWN"),"ARROWUP","UP"),"ARROWLEFT","LEFT"),"ARROWRIGHT","RIGHT"),"↓","DOWN"),"↑","UP"),"←","LEFT"),"→","RIGHT"),"SPACEBAR","SPACE"),"−","-"),"MINUS","-"),"PLUS","+")=Key!$E$10:$J$10),"✔ CLEAR","✘ TRY AGAIN"))),"✘ TRY AGAIN")} | F22: {=IF(E22="Show hint",Key!$B$10,"")} | G22: {=IF(LEFT(D22,1)="✔",IF(E22="Show hint",5,10),0)} -> 0
A23: W10 | B23: Which function goes inside INDEX to find the row position? (from F4-4 Power Couple) | D23: {=IFERROR(_xlfn.LET(_xlpm.a,'F7-1 Spill Zone'!$C$23,IF(TRIM(_xlpm.a&"")="","",IF(OR(SUBSTITUTE(SUBSTITUTE(SUBSTITUTE(SUBSTITUTE(SUBSTITUTE(SUBSTITUTE(SUBSTITUTE(SUBSTITUTE(SUBSTITUTE(SUBSTITUTE(SUBSTITUTE(SUBSTITUTE(SUBSTITUTE(SUBSTITUTE(SUBSTITUTE(SUBSTITUTE(SUBSTITUTE(SUBSTITUTE(SUBSTITUTE(SUBSTITUTE(SUBSTITUTE(SUBSTITUTE(SUBSTITUTE(SUBSTITUTE(SUBSTITUTE(SUBSTITUTE(SUBSTITUTE(UPPER(_xlpm.a)," ",""),"CONTROL","CTRL"),"CTL","CTRL"),"ESCAPE","ESC"),"RETURN","ENTER"),"PAGEDOWN","PGDN"),"PGDOWN","PGDN"),"PAGEUP","PGUP"),"ARROWKEYS","ARROW"),"ARROWKEY","ARROW"),"ARROWS","ARROW"),"DOWNARROW","DOWN"),"UPARROW","UP"),"LEFTARROW","LEFT"),"RIGHTARROW","RIGHT"),"ARROWDOWN","DOWN"),"ARROWUP","UP"),"ARROWLEFT","LEFT"),"ARROWRIGHT","RIGHT"),"↓","DOWN"),"↑","UP"),"←","LEFT"),"→","RIGHT"),"SPACEBAR","SPACE"),"−","-"),"MINUS","-"),"PLUS","+")=Key!$E$11:$P$11),"✔ CLEAR","✘ TRY AGAIN"))),"✘ TRY AGAIN")} | F23: {=IF(E23="Show hint",Key!$B$11,"")} | G23: {=IF(LEFT(D23,1)="✔",IF(E23="Show hint",5,10),0)} -> 0
A25: TRAINING · recognize the move (pick from the list)
A26: # | B26: Mission | C26: Your answer | D26: Result | E26: Hint? | F26: Hint | G26: XP
A27: T1 | B27: What is it called when one formula's results flow into neighboring cells? | D27: {=IFERROR(IF('F7-1 Spill Zone'!$C$27&""="","",IF('F7-1 Spill Zone'!$C$27&""=Key!$C$12&"","✔ CLEAR","✘ TRY AGAIN")),"✘ TRY AGAIN")} | F27: {=IF(E27="Show hint",Key!$B$12,"")} | G27: {=IF(LEFT(D27,1)="✔",IF(E27="Show hint",5,10),0)} -> 0
A28: T2 | B28: Which error appears when a spill range is blocked? | D28: {=IFERROR(IF('F7-1 Spill Zone'!$C$28&""="","",IF('F7-1 Spill Zone'!$C$28&""=Key!$C$13&"","✔ CLEAR","✘ TRY AGAIN")),"✘ TRY AGAIN")} | F28: {=IF(E28="Show hint",Key!$B$13,"")} | G28: {=IF(LEFT(D28,1)="✔",IF(E28="Show hint",5,10),0)} -> 0
A29: T3 | B29: How do you refer to the whole spill that starts in H5? | D29: {=IFERROR(IF('F7-1 Spill Zone'!$C$29&""="","",IF('F7-1 Spill Zone'!$C$29&""=Key!$C$14&"","✔ CLEAR","✘ TRY AGAIN")),"✘ TRY AGAIN")} | F29: {=IF(E29="Show hint",Key!$B$14,"")} | G29: {=IF(LEFT(D29,1)="✔",IF(E29="Show hint",5,10),0)} -> 0
A30: T4 | B30: Which function spills a list of sequential numbers? | D30: {=IFERROR(IF('F7-1 Spill Zone'!$C$30&""="","",IF('F7-1 Spill Zone'!$C$30&""=Key!$C$15&"","✔ CLEAR","✘ TRY AGAIN")),"✘ TRY AGAIN")} | F30: {=IF(E30="Show hint",Key!$B$15,"")} | G30: {=IF(LEFT(D30,1)="✔",IF(E30="Show hint",5,10),0)} -> 0
A32: CHALLENGES · recall it, then do it
B33: ▶ Open F7-1 Arena (or press Ctrl+PgDn)
A34: # | B34: Mission | C34: Your answer | D34: Result | E34: Hint? | F34: Hint | G34: XP
A35: C1 | B35: What is it called when one formula's results flow into neighboring cells? | D35: {=IFERROR(_xlfn.LET(_xlpm.a,'F7-1 Spill Zone'!$C$35,IF(TRIM(_xlpm.a&"")="","",IF(OR(SUBSTITUTE(SUBSTITUTE(SUBSTITUTE(SUBSTITUTE(SUBSTITUTE(SUBSTITUTE(SUBSTITUTE(SUBSTITUTE(SUBSTITUTE(SUBSTITUTE(SUBSTITUTE(SUBSTITUTE(SUBSTITUTE(SUBSTITUTE(SUBSTITUTE(SUBSTITUTE(SUBSTITUTE(SUBSTITUTE(SUBSTITUTE(SUBSTITUTE(SUBSTITUTE(SUBSTITUTE(SUBSTITUTE(SUBSTITUTE(SUBSTITUTE(SUBSTITUTE(SUBSTITUTE(UPPER(_xlpm.a)," ",""),"CONTROL","CTRL"),"CTL","CTRL"),"ESCAPE","ESC"),"RETURN","ENTER"),"PAGEDOWN","PGDN"),"PGDOWN","PGDN"),"PAGEUP","PGUP"),"ARROWKEYS","ARROW"),"ARROWKEY","ARROW"),"ARROWS","ARROW"),"DOWNARROW","DOWN"),"UPARROW","UP"),"LEFTARROW","LEFT"),"RIGHTARROW","RIGHT"),"ARROWDOWN","DOWN"),"ARROWUP","UP"),"ARROWLEFT","LEFT"),"ARROWRIGHT","RIGHT"),"↓","DOWN"),"↑","UP"),"←","LEFT"),"→","RIGHT"),"SPACEBAR","SPACE"),"−","-"),"MINUS","-"),"PLUS","+")=Key!$E$16:$G$16),"✔ CLEAR","✘ TRY AGAIN"))),"✘ TRY AGAIN")} | F35: {=IF(E35="Show hint",Key!$B$16,"")} | G35: {=IF(LEFT(D35,1)="✔",IF(E35="Show hint",5,10),0)} -> 0
A36: C2 | B36: Which error appears when a spill range is blocked? | D36: {=IFERROR(_xlfn.LET(_xlpm.a,'F7-1 Spill Zone'!$C$36,IF(TRIM(_xlpm.a&"")="","",IF(OR(SUBSTITUTE(SUBSTITUTE(SUBSTITUTE(SUBSTITUTE(SUBSTITUTE(SUBSTITUTE(SUBSTITUTE(SUBSTITUTE(SUBSTITUTE(SUBSTITUTE(SUBSTITUTE(SUBSTITUTE(SUBSTITUTE(SUBSTITUTE(SUBSTITUTE(SUBSTITUTE(SUBSTITUTE(SUBSTITUTE(SUBSTITUTE(SUBSTITUTE(SUBSTITUTE(SUBSTITUTE(SUBSTITUTE(SUBSTITUTE(SUBSTITUTE(SUBSTITUTE(SUBSTITUTE(UPPER(_xlpm.a)," ",""),"CONTROL","CTRL"),"CTL","CTRL"),"ESCAPE","ESC"),"RETURN","ENTER"),"PAGEDOWN","PGDN"),"PGDOWN","PGDN"),"PAGEUP","PGUP"),"ARROWKEYS","ARROW"),"ARROWKEY","ARROW"),"ARROWS","ARROW"),"DOWNARROW","DOWN"),"UPARROW","UP"),"LEFTARROW","LEFT"),"RIGHTARROW","RIGHT"),"ARROWDOWN","DOWN"),"ARROWUP","UP"),"ARROWLEFT","LEFT"),"ARROWRIGHT","RIGHT"),"↓","DOWN"),"↑","UP"),"←","LEFT"),"→","RIGHT"),"SPACEBAR","SPACE"),"−","-"),"MINUS","-"),"PLUS","+")=Key!$E$17:$L$17),"✔ CLEAR","✘ TRY AGAIN"))),"✘ TRY AGAIN")} | F36: {=IF(E36="Show hint",Key!$B$17,"")} | G36: {=IF(LEFT(D36,1)="✔",IF(E36="Show hint",5,10),0)} -> 0
A37: C3 | B37: How do you refer to the whole spill that starts in H5? | D37: {=IFERROR(_xlfn.LET(_xlpm.a,'F7-1 Spill Zone'!$C$37,IF(TRIM(_xlpm.a&"")="","",IF(OR(SUBSTITUTE(SUBSTITUTE(SUBSTITUTE(SUBSTITUTE(SUBSTITUTE(SUBSTITUTE(SUBSTITUTE(SUBSTITUTE(SUBSTITUTE(SUBSTITUTE(SUBSTITUTE(SUBSTITUTE(SUBSTITUTE(SUBSTITUTE(SUBSTITUTE(SUBSTITUTE(SUBSTITUTE(SUBSTITUTE(SUBSTITUTE(SUBSTITUTE(SUBSTITUTE(SUBSTITUTE(SUBSTITUTE(SUBSTITUTE(SUBSTITUTE(SUBSTITUTE(SUBSTITUTE(UPPER(_xlpm.a)," ",""),"CONTROL","CTRL"),"CTL","CTRL"),"ESCAPE","ESC"),"RETURN","ENTER"),"PAGEDOWN","PGDN"),"PGDOWN","PGDN"),"PAGEUP","PGUP"),"ARROWKEYS","ARROW"),"ARROWKEY","ARROW"),"ARROWS","ARROW"),"DOWNARROW","DOWN"),"UPARROW","UP"),"LEFTARROW","LEFT"),"RIGHTARROW","RIGHT"),"ARROWDOWN","DOWN"),"ARROWUP","UP"),"ARROWLEFT","LEFT"),"ARROWRIGHT","RIGHT"),"↓","DOWN"),"↑","UP"),"←","LEFT"),"→","RIGHT"),"SPACEBAR","SPACE"),"−","-"),"MINUS","-"),"PLUS","+")=Key!$E$18:$E$18),"✔ CLEAR","✘ TRY AGAIN"))),"✘ TRY AGAIN")} | F37: {=IF(E37="Show hint",Key!$B$18,"")} | G37: {=IF(LEFT(D37,1)="✔",IF(E37="Show hint",5,10),0)} -> 0
A38: C4 | B38: Which function spills a list of sequential numbers? | D38: {=IFERROR(_xlfn.LET(_xlpm.a,'F7-1 Spill Zone'!$C$38,IF(TRIM(_xlpm.a&"")="","",IF(OR(SUBSTITUTE(SUBSTITUTE(SUBSTITUTE(SUBSTITUTE(SUBSTITUTE(SUBSTITUTE(SUBSTITUTE(SUBSTITUTE(SUBSTITUTE(SUBSTITUTE(SUBSTITUTE(SUBSTITUTE(SUBSTITUTE(SUBSTITUTE(SUBSTITUTE(SUBSTITUTE(SUBSTITUTE(SUBSTITUTE(SUBSTITUTE(SUBSTITUTE(SUBSTITUTE(SUBSTITUTE(SUBSTITUTE(SUBSTITUTE(SUBSTITUTE(SUBSTITUTE(SUBSTITUTE(UPPER(_xlpm.a)," ",""),"CONTROL","CTRL"),"CTL","CTRL"),"ESCAPE","ESC"),"RETURN","ENTER"),"PAGEDOWN","PGDN"),"PGDOWN","PGDN"),"PAGEUP","PGUP"),"ARROWKEYS","ARROW"),"ARROWKEY","ARROW"),"ARROWS","ARROW"),"DOWNARROW","DOWN"),"UPARROW","UP"),"LEFTARROW","LEFT"),"RIGHTARROW","RIGHT"),"ARROWDOWN","DOWN"),"ARROWUP","UP"),"ARROWLEFT","LEFT"),"ARROWRIGHT","RIGHT"),"↓","DOWN"),"↑","UP"),"←","LEFT"),"→","RIGHT"),"SPACEBAR","SPACE"),"−","-"),"MINUS","-"),"PLUS","+")=Key!$E$19:$J$19),"✔ CLEAR","✘ TRY AGAIN"))),"✘ TRY AGAIN")} | F38: {=IF(E38="Show hint",Key!$B$19,"")} | G38: {=IF(LEFT(D38,1)="✔",IF(E38="Show hint",5,10),0)} -> 0
A39: C5 | B39: In K6 type =SEQUENCE(10) and press Enter. One formula fills K6:K15. | C39: ▶ ARENA C5 (cell K6) | D39: {=IF(ISBLANK('F7-1 Arena'!$K$6),"",IF(NOT(_xlfn.ISFORMULA('F7-1 Arena'!$K$6)),"✘ That's a typed value · enter a formula",IF(ISERROR('F7-1 Arena'!$K$6),"✘ Your formula returns "&IFERROR(CHOOSE(ERROR.TYPE('F7-1 Arena'!$K$6),"#NULL!","#DIV/0!","#VALUE!","#REF!","#NAME?","#NUM!","#N/A","#GETTING_DATA","#SPILL!","#CONNECT!","#BLOCKED!","#UNKNOWN!","#FIELD!","#CALC!"),"an error"),IF(IFERROR(AND(ROWS(_xlfn.ANCHORARRAY('F7-1 Arena'!$K$6))=ROWS(_xlfn.ANCHORARRAY(Key!$E$2001)),COLUMNS(_xlfn.ANCHORARRAY('F7-1 Arena'!$K$6))=COLUMNS(_xlfn.ANCHORARRAY(Key!$E$2001)),SUM(--(_xlfn.ANCHORARRAY('F7-1 Arena'!$K$6)=_xlfn.ANCHORARRAY(Key!$E$2001)))=ROWS(_xlfn.ANCHORARRAY(Key!$E$2001))*COLUMNS(_xlfn.ANCHORARRAY(Key!$E$2001))),FALSE),IF(AND(OR(ISNUMBER(FIND({"=","(",",","+","-","*","/","&"," ","<",">",":","@","^"}&"SEQUENCE"&"(",UPPER(_xlfn.FORMULATEXT('F7-1 Arena'!$K$6)))))),"✔ CLEAR","✘ CLOSE · right result, but use SEQUENCE"),"✘ TRY AGAIN"))))} | F39: {=IF(E39="Show hint",Key!$B$20,"")} | G39: {=IF(LEFT(D39,1)="✔",IF(E39="Show hint",5,10),0)} -> 0
A40: C6 | B40: M6 shows #SPILL! because M8 is in its way. Click M8 and press Delete: five numbers spill into place. | C40: ▶ ARENA C6 (cell M8) | D40: {=IF(IFERROR(AND(_xlfn.ISFORMULA('F7-1 Arena'!$M$6),ROWS(_xlfn.ANCHORARRAY('F7-1 Arena'!$M$6))=5),FALSE),"✔ CLEAR","· not yet")} -> · not yet | F40: {=IF(E40="Show hint",Key!$B$21,"")} | G40: {=IF(LEFT(D40,1)="✔",IF(E40="Show hint",5,10),0)} -> 0
A41: C7 | B41: O6 spills four numbers. In K20 add up the whole spill with =SUM(O6#). | C41: ▶ ARENA C7 (cell K20) | D41: {=IF(ISBLANK('F7-1 Arena'!$K$20),"",IF(NOT(_xlfn.ISFORMULA('F7-1 Arena'!$K$20)),"✘ That's a typed value · enter a formula",IF(ISERROR('F7-1 Arena'!$K$20),"✘ Your formula returns "&IFERROR(CHOOSE(ERROR.TYPE('F7-1 Arena'!$K$20),"#NULL!","#DIV/0!","#VALUE!","#REF!","#NAME?","#NUM!","#N/A","#GETTING_DATA","#SPILL!","#CONNECT!","#BLOCKED!","#UNKNOWN!","#FIELD!","#CALC!"),"an error"),IF(NOT(AND(IFERROR(AND(ISNUMBER('F7-1 Arena'!$K$20),ABS('F7-1 Arena'!$K$20-Key!$C$22)<=1E-9*MAX(1,ABS(Key!$C$22))),FALSE))),"✘ TRY AGAIN",IF(ISNUMBER(FIND("#",_xlfn.FORMULATEXT('F7-1 Arena'!$K$20))),"✔ CLEAR","✘ CLOSE · your formula needs #")))))} | F41: {=IF(E41="Show hint",Key!$B$22,"")} | G41: {=IF(LEFT(D41,1)="✔",IF(E41="Show hint",5,10),0)} -> 0

Sheet F7-1 Arena
A1: ARENA ▸ F7-1 SPILL ZONE
A2: Practice area · everything here is editable. Missions and their checks are on the stage sheet.
A3: PASS CODE | B3: SPILLWAY | D3: ◀ Back to F7-1 Spill Zone
B5: Order | C5: Date | D5: Region | E5: Rep | F5: Product | G5: Units | H5: Revenue | K5: SEQUENCE ▼ | M5: Blocked spill | O5: Ready-made spill
B6: O-101 | C6: 46027 | D6: East | E6: Kim | F6: Widget | G6: 40 | H6: 1200 | M6: {=_xlfn.SEQUENCE(5)} -> #SPILL! | O6: {=_xlfn.SEQUENCE(4,1,10,10)} -> 10
B7: O-102 | C7: 46031 | D7: West | E7: Lee | F7: Gadget | G7: 15 | H7: 900
B8: O-103 | C8: 46036 | D8: North | E8: Ava | F8: Widget | G8: 55 | H8: 1650 | M8: BLOCK
B9: O-104 | C9: 46042 | D9: East | E9: Kim | F9: Gizmo | G9: 20 | H9: 1000
B10: O-105 | C10: 46055 | D10: South | E10: Raj | F10: Gadget | G10: 60 | H10: 3600
B11: O-106 | C11: 46060 | D11: West | E11: Lee | F11: Widget | G11: 35 | H11: 1050
B12: O-107 | C12: 46064 | D12: East | E12: Ava | F12: Gadget | G12: 25 | H12: 1500
B13: O-108 | C13: 46072 | D13: North | E13: Raj | F13: Gizmo | G13: 45 | H13: 2250
B14: O-109 | C14: 46084 | D14: West | E14: Kim | F14: Gizmo | G14: 10 | H14: 500
B15: O-110 | C15: 46089 | D15: East | E15: Lee | F15: Widget | G15: 70 | H15: 2100
B16: O-111 | C16: 46096 | D16: South | E16: Ava | F16: Widget | G16: 30 | H16: 900
B17: O-112 | C17: 46103 | D17: North | E17: Kim | F17: Gadget | G17: 50 | H17: 3000
B18: O-113 | C18: 46113 | D18: East | E18: Raj | F18: Gizmo | G18: 65 | H18: 3250
B19: O-114 | C19: 46118 | D19: West | E19: Ava | F19: Gadget | G19: 20 | H19: 1200 | K19: Sum of O6#
B20: O-115 | C20: 46125 | D20: South | E20: Lee | F20: Gizmo | G20: 15 | H20: 750
B21: O-116 | C21: 46133 | D21: East | E21: Kim | F21: Widget | G21: 50 | H21: 1500
B22: O-117 | C22: 46146 | D22: North | E22: Lee | F22: Widget | G22: 25 | H22: 750
B23: O-118 | C23: 46154 | D23: West | E23: Raj | F23: Gadget | G23: 40 | H23: 2400
B24: O-119 | C24: 46161 | D24: South | E24: Kim | F24: Gizmo | G24: 35 | H24: 1750
B25: O-120 | C25: 46169 | D25: East | E25: Ava | F25: Gadget | G25: 55 | H25: 3300

Sheet F7-2 Sifter
A1: STAGE F7-2 ▸ SIFTER
A2: Goal: pull out exactly the rows you need
A3: {="SCORE "&TEXT(SUM($G$13:$G$38),"0000")&" / 0190"} -> SCORE 0000 / 0190 | C3: {=IF(SUM($G$13:$G$38)>=190,"★★★",IF(SUM($G$13:$G$38)>=190*0.8,"★★☆",IF(SUM($G$13:$G$38)>=190*0.5,"★☆☆","☆☆☆")))} -> ☆☆☆ | D3: {=REPT("█",ROUND(10*SUM($G$13:$G$38)/190,0))&REPT("░",10-ROUND(10*SUM($G$13:$G$38)/190,0))&" "&TEXT(SUM($G$13:$G$38)/190,"0%")} -> ░░░░░░░░░░ 0% | F3: {=IF(SUM($G$13:$G$38)>=190*0.5,"STAGE CLEAR! ▶ Next: F7-3 Sorter","")}
A5: BRIEFING · new moves in this stage
A6: # | B6: What it does · Pro tip | C6: Keys / Syntax
A7: 1 | B7: FILTER(range, condition) spills only the matching rows. Tip: =FILTER(B6:H25,D6:D25="East") | C7: FILTER
A8: 2 | B8: Multiply conditions for AND; add them for OR. Tip: (D6:D25="East")*(G6:G25>40) keeps rows that pass both. | C8: (…)*(…)
A9: 3 | B9: FILTER's 3rd argument: what to show when nothing matches. Tip: Without it, an empty result is #CALC!. | C9: if_empty
A11: WARM-UP · flashback to earlier stages
A12: # | B12: Mission | C12: Your answer | D12: Result | E12: Hint? | F12: Hint | G12: XP
A13: W1 | B13: What is it called when one formula's results flow into neighboring cells? (from F7-1 Spill Zone) | D13: {=IFERROR(_xlfn.LET(_xlpm.a,'F7-2 Sifter'!$C$13,IF(TRIM(_xlpm.a&"")="","",IF(OR(SUBSTITUTE(SUBSTITUTE(SUBSTITUTE(SUBSTITUTE(SUBSTITUTE(SUBSTITUTE(SUBSTITUTE(SUBSTITUTE(SUBSTITUTE(SUBSTITUTE(SUBSTITUTE(SUBSTITUTE(SUBSTITUTE(SUBSTITUTE(SUBSTITUTE(SUBSTITUTE(SUBSTITUTE(SUBSTITUTE(SUBSTITUTE(SUBSTITUTE(SUBSTITUTE(SUBSTITUTE(SUBSTITUTE(SUBSTITUTE(SUBSTITUTE(SUBSTITUTE(SUBSTITUTE(UPPER(_xlpm.a)," ",""),"CONTROL","CTRL"),"CTL","CTRL"),"ESCAPE","ESC"),"RETURN","ENTER"),"PAGEDOWN","PGDN"),"PGDOWN","PGDN"),"PAGEUP","PGUP"),"ARROWKEYS","ARROW"),"ARROWKEY","ARROW"),"ARROWS","ARROW"),"DOWNARROW","DOWN"),"UPARROW","UP"),"LEFTARROW","LEFT"),"RIGHTARROW","RIGHT"),"ARROWDOWN","DOWN"),"ARROWUP","UP"),"ARROWLEFT","LEFT"),"ARROWRIGHT","RIGHT"),"↓","DOWN"),"↑","UP"),"←","LEFT"),"→","RIGHT"),"SPACEBAR","SPACE"),"−","-"),"MINUS","-"),"PLUS","+")=Key!$E$23:$G$23),"✔ CLEAR","✘ TRY AGAIN"))),"✘ TRY AGAIN")} | F13: {=IF(E13="Show hint",Key!$B$23,"")} | G13: {=IF(LEFT(D13,1)="✔",IF(E13="Show hint",5,10),0)} -> 0
A14: W2 | B14: Which error appears when a spill range is blocked? (from F7-1 Spill Zone) | D14: {=IFERROR(_xlfn.LET(_xlpm.a,'F7-2 Sifter'!$C$14,IF(TRIM(_xlpm.a&"")="","",IF(OR(SUBSTITUTE(SUBSTITUTE(SUBSTITUTE(SUBSTITUTE(SUBSTITUTE(SUBSTITUTE(SUBSTITUTE(SUBSTITUTE(SUBSTITUTE(SUBSTITUTE(SUBSTITUTE(SUBSTITUTE(SUBSTITUTE(SUBSTITUTE(SUBSTITUTE(SUBSTITUTE(SUBSTITUTE(SUBSTITUTE(SUBSTITUTE(SUBSTITUTE(SUBSTITUTE(SUBSTITUTE(SUBSTITUTE(SUBSTITUTE(SUBSTITUTE(SUBSTITUTE(SUBSTITUTE(UPPER(_xlpm.a)," ",""),"CONTROL","CTRL"),"CTL","CTRL"),"ESCAPE","ESC"),"RETURN","ENTER"),"PAGEDOWN","PGDN"),"PGDOWN","PGDN"),"PAGEUP","PGUP"),"ARROWKEYS","ARROW"),"ARROWKEY","ARROW"),"ARROWS","ARROW"),"DOWNARROW","DOWN"),"UPARROW","UP"),"LEFTARROW","LEFT"),"RIGHTARROW","RIGHT"),"ARROWDOWN","DOWN"),"ARROWUP","UP"),"ARROWLEFT","LEFT"),"ARROWRIGHT","RIGHT"),"↓","DOWN"),"↑","UP"),"←","LEFT"),"→","RIGHT"),"SPACEBAR","SPACE"),"−","-"),"MINUS","-"),"PLUS","+")=Key!$E$24:$L$24),"✔ CLEAR","✘ TRY AGAIN"))),"✘ TRY AGAIN")} | F14: {=IF(E14="Show hint",Key!$B$24,"")} | G14: {=IF(LEFT(D14,1)="✔",IF(E14="Show hint",5,10),0)} -> 0
A15: W3 | B15: How do you refer to the whole spill that starts in H5? (from F7-1 Spill Zone) | D15: {=IFERROR(_xlfn.LET(_xlpm.a,'F7-2 Sifter'!$C$15,IF(TRIM(_xlpm.a&"")="","",IF(OR(SUBSTITUTE(SUBSTITUTE(SUBSTITUTE(SUBSTITUTE(SUBSTITUTE(SUBSTITUTE(SUBSTITUTE(SUBSTITUTE(SUBSTITUTE(SUBSTITUTE(SUBSTITUTE(SUBSTITUTE(SUBSTITUTE(SUBSTITUTE(SUBSTITUTE(SUBSTITUTE(SUBSTITUTE(SUBSTITUTE(SUBSTITUTE(SUBSTITUTE(SUBSTITUTE(SUBSTITUTE(SUBSTITUTE(SUBSTITUTE(SUBSTITUTE(SUBSTITUTE(SUBSTITUTE(UPPER(_xlpm.a)," ",""),"CONTROL","CTRL"),"CTL","CTRL"),"ESCAPE","ESC"),"RETURN","ENTER"),"PAGEDOWN","PGDN"),"PGDOWN","PGDN"),"PAGEUP","PGUP"),"ARROWKEYS","ARROW"),"ARROWKEY","ARROW"),"ARROWS","ARROW"),"DOWNARROW","DOWN"),"UPARROW","UP"),"LEFTARROW","LEFT"),"RIGHTARROW","RIGHT"),"ARROWDOWN","DOWN"),"ARROWUP","UP"),"ARROWLEFT","LEFT"),"ARROWRIGHT","RIGHT"),"↓","DOWN"),"↑","UP"),"←","LEFT"),"→","RIGHT"),"SPACEBAR","SPACE"),"−","-"),"MINUS","-"),"PLUS","+")=Key!$E$25:$E$25),"✔ CLEAR","✘ TRY AGAIN"))),"✘ TRY AGAIN")} | F15: {=IF(E15="Show hint",Key!$B$25,"")} | G15: {=IF(LEFT(D15,1)="✔",IF(E15="Show hint",5,10),0)} -> 0
A16: W4 | B16: Which function spills a list of sequential numbers? (from F7-1 Spill Zone) | D16: {=IFERROR(_xlfn.LET(_xlpm.a,'F7-2 Sifter'!$C$16,IF(TRIM(_xlpm.a&"")="","",IF(OR(SUBSTITUTE(SUBSTITUTE(SUBSTITUTE(SUBSTITUTE(SUBSTITUTE(SUBSTITUTE(SUBSTITUTE(SUBSTITUTE(SUBSTITUTE(SUBSTITUTE(SUBSTITUTE(SUBSTITUTE(SUBSTITUTE(SUBSTITUTE(SUBSTITUTE(SUBSTITUTE(SUBSTITUTE(SUBSTITUTE(SUBSTITUTE(SUBSTITUTE(SUBSTITUTE(SUBSTITUTE(SUBSTITUTE(SUBSTITUTE(SUBSTITUTE(SUBSTITUTE(SUBSTITUTE(UPPER(_xlpm.a)," ",""),"CONTROL","CTRL"),"CTL","CTRL"),"ESCAPE","ESC"),"RETURN","ENTER"),"PAGEDOWN","PGDN"),"PGDOWN","PGDN"),"PAGEUP","PGUP"),"ARROWKEYS","ARROW"),"ARROWKEY","ARROW"),"ARROWS","ARROW"),"DOWNARROW","DOWN"),"UPARROW","UP"),"LEFTARROW","LEFT"),"RIGHTARROW","RIGHT"),"ARROWDOWN","DOWN"),"ARROWUP","UP"),"ARROWLEFT","LEFT"),"ARROWRIGHT","RIGHT"),"↓","DOWN"),"↑","UP"),"←","LEFT"),"→","RIGHT"),"SPACEBAR","SPACE"),"−","-"),"MINUS","-"),"PLUS","+")=Key!$E$26:$J$26),"✔ CLEAR","✘ TRY AGAIN"))),"✘ TRY AGAIN")} | F16: {=IF(E16="Show hint",Key!$B$26,"")} | G16: {=IF(LEFT(D16,1)="✔",IF(E16="Show hint",5,10),0)} -> 0
A17: W5 | B17: What do you get when you subtract an earlier date from a later one (one word)? (from F6-2 Date Math) | D17: {=IFERROR(_xlfn.LET(_xlpm.a,'F7-2 Sifter'!$C$17,IF(TRIM(_xlpm.a&"")="","",IF(OR(SUBSTITUTE(SUBSTITUTE(SUBSTITUTE(SUBSTITUTE(SUBSTITUTE(SUBSTITUTE(SUBSTITUTE(SUBSTITUTE(SUBSTITUTE(SUBSTITUTE(SUBSTITUTE(SUBSTITUTE(SUBSTITUTE(SUBSTITUTE(SUBSTITUTE(SUBSTITUTE(SUBSTITUTE(SUBSTITUTE(SUBSTITUTE(SUBSTITUTE(SUBSTITUTE(SUBSTITUTE(SUBSTITUTE(SUBSTITUTE(SUBSTITUTE(SUBSTITUTE(SUBSTITUTE(UPPER(_xlpm.a)," ",""),"CONTROL","CTRL"),"CTL","CTRL"),"ESCAPE","ESC"),"RETURN","ENTER"),"PAGEDOWN","PGDN"),"PGDOWN","PGDN"),"PAGEUP","PGUP"),"ARROWKEYS","ARROW"),"ARROWKEY","ARROW"),"ARROWS","ARROW"),"DOWNARROW","DOWN"),"UPARROW","UP"),"LEFTARROW","LEFT"),"RIGHTARROW","RIGHT"),"ARROWDOWN","DOWN"),"ARROWUP","UP"),"ARROWLEFT","LEFT"),"ARROWRIGHT","RIGHT"),"↓","DOWN"),"↑","UP"),"←","LEFT"),"→","RIGHT"),"SPACEBAR","SPACE"),"−","-"),"MINUS","-"),"PLUS","+")=Key!$E$27:$F$27),"✔ CLEAR","✘ TRY AGAIN"))),"✘ TRY AGAIN")} | F17: {=IF(E17="Show hint",Key!$B$27,"")} | G17: {=IF(LEFT(D17,1)="✔",IF(E17="Show hint",5,10),0)} -> 0
A18: W6 | B18: Type the formula for the date 30 days after the date in B6. (from F6-2 Date Math) | D18: {=IFERROR(_xlfn.LET(_xlpm.a,'F7-2 Sifter'!$C$18,IF(TRIM(_xlpm.a&"")="","",IF(OR(SUBSTITUTE(SUBSTITUTE(SUBSTITUTE(SUBSTITUTE(SUBSTITUTE(SUBSTITUTE(SUBSTITUTE(SUBSTITUTE(SUBSTITUTE(SUBSTITUTE(SUBSTITUTE(SUBSTITUTE(SUBSTITUTE(SUBSTITUTE(SUBSTITUTE(SUBSTITUTE(SUBSTITUTE(SUBSTITUTE(SUBSTITUTE(SUBSTITUTE(SUBSTITUTE(SUBSTITUTE(SUBSTITUTE(SUBSTITUTE(SUBSTITUTE(SUBSTITUTE(SUBSTITUTE(UPPER(_xlpm.a)," ",""),"CONTROL","CTRL"),"CTL","CTRL"),"ESCAPE","ESC"),"RETURN","ENTER"),"PAGEDOWN","PGDN"),"PGDOWN","PGDN"),"PAGEUP","PGUP"),"ARROWKEYS","ARROW"),"ARROWKEY","ARROW"),"ARROWS","ARROW"),"DOWNARROW","DOWN"),"UPARROW","UP"),"LEFTARROW","LEFT"),"RIGHTARROW","RIGHT"),"ARROWDOWN","DOWN"),"ARROWUP","UP"),"ARROWLEFT","LEFT"),"ARROWRIGHT","RIGHT"),"↓","DOWN"),"↑","UP"),"←","LEFT"),"→","RIGHT"),"SPACEBAR","SPACE"),"−","-"),"MINUS","-"),"PLUS","+")=Key!$E$28:$H$28),"✔ CLEAR","✘ TRY AGAIN"))),"✘ TRY AGAIN")} | F18: {=IF(E18="Show hint",Key!$B$28,"")} | G18: {=IF(LEFT(D18,1)="✔",IF(E18="Show hint",5,10),0)} -> 0
A19: W7 | B19: Which function counts full years or months between two dates? (from F6-2 Date Math) | D19: {=IFERROR(_xlfn.LET(_xlpm.a,'F7-2 Sifter'!$C$19,IF(TRIM(_xlpm.a&"")="","",IF(OR(SUBSTITUTE(SUBSTITUTE(SUBSTITUTE(SUBSTITUTE(SUBSTITUTE(SUBSTITUTE(SUBSTITUTE(SUBSTITUTE(SUBSTITUTE(SUBSTITUTE(SUBSTITUTE(SUBSTITUTE(SUBSTITUTE(SUBSTITUTE(SUBSTITUTE(SUBSTITUTE(SUBSTITUTE(SUBSTITUTE(SUBSTITUTE(SUBSTITUTE(SUBSTITUTE(SUBSTITUTE(SUBSTITUTE(SUBSTITUTE(SUBSTITUTE(SUBSTITUTE(SUBSTITUTE(UPPER(_xlpm.a)," ",""),"CONTROL","CTRL"),"CTL","CTRL"),"ESCAPE","ESC"),"RETURN","ENTER"),"PAGEDOWN","PGDN"),"PGDOWN","PGDN"),"PAGEUP","PGUP"),"ARROWKEYS","ARROW"),"ARROWKEY","ARROW"),"ARROWS","ARROW"),"DOWNARROW","DOWN"),"UPARROW","UP"),"LEFTARROW","LEFT"),"RIGHTARROW","RIGHT"),"ARROWDOWN","DOWN"),"ARROWUP","UP"),"ARROWLEFT","LEFT"),"ARROWRIGHT","RIGHT"),"↓","DOWN"),"↑","UP"),"←","LEFT"),"→","RIGHT"),"SPACEBAR","SPACE"),"−","-"),"MINUS","-"),"PLUS","+")=Key!$E$29:$J$29),"✔ CLEAR","✘ TRY AGAIN"))),"✘ TRY AGAIN")} | F19: {=IF(E19="Show hint",Key!$B$29,"")} | G19: {=IF(LEFT(D19,1)="✔",IF(E19="Show hint",5,10),0)} -> 0
A20: W8 | B20: Which modern function returns a position with an exact match by default? (from F4-4 Power Couple) | D20: {=IFERROR(_xlfn.LET(_xlpm.a,'F7-2 Sifter'!$C$20,IF(TRIM(_xlpm.a&"")="","",IF(OR(SUBSTITUTE(SUBSTITUTE(SUBSTITUTE(SUBSTITUTE(SUBSTITUTE(SUBSTITUTE(SUBSTITUTE(SUBSTITUTE(SUBSTITUTE(SUBSTITUTE(SUBSTITUTE(SUBSTITUTE(SUBSTITUTE(SUBSTITUTE(SUBSTITUTE(SUBSTITUTE(SUBSTITUTE(SUBSTITUTE(SUBSTITUTE(SUBSTITUTE(SUBSTITUTE(SUBSTITUTE(SUBSTITUTE(SUBSTITUTE(SUBSTITUTE(SUBSTITUTE(SUBSTITUTE(UPPER(_xlpm.a)," ",""),"CONTROL","CTRL"),"CTL","CTRL"),"ESCAPE","ESC"),"RETURN","ENTER"),"PAGEDOWN","PGDN"),"PGDOWN","PGDN"),"PAGEUP","PGUP"),"ARROWKEYS","ARROW"),"ARROWKEY","ARROW"),"ARROWS","ARROW"),"DOWNARROW","DOWN"),"UPARROW","UP"),"LEFTARROW","LEFT"),"RIGHTARROW","RIGHT"),"ARROWDOWN","DOWN"),"ARROWUP","UP"),"ARROWLEFT","LEFT"),"ARROWRIGHT","RIGHT"),"↓","DOWN"),"↑","UP"),"←","LEFT"),"→","RIGHT"),"SPACEBAR","SPACE"),"−","-"),"MINUS","-"),"PLUS","+")=Key!$E$30:$J$30),"✔ CLEAR","✘ TRY AGAIN"))),"✘ TRY AGAIN")} | F20: {=IF(E20="Show hint",Key!$B$30,"")} | G20: {=IF(LEFT(D20,1)="✔",IF(E20="Show hint",5,10),0)} -> 0
A21: W9 | B21: Which XLOOKUP match_mode returns an exact match or the next smaller item? (from F4-5 Tiers) | D21: {=IFERROR(_xlfn.LET(_xlpm.a,'F7-2 Sifter'!$C$21,IF(TRIM(_xlpm.a&"")="","",IF(OR(SUBSTITUTE(SUBSTITUTE(SUBSTITUTE(SUBSTITUTE(SUBSTITUTE(SUBSTITUTE(SUBSTITUTE(SUBSTITUTE(SUBSTITUTE(SUBSTITUTE(SUBSTITUTE(SUBSTITUTE(SUBSTITUTE(SUBSTITUTE(SUBSTITUTE(SUBSTITUTE(SUBSTITUTE(SUBSTITUTE(SUBSTITUTE(SUBSTITUTE(SUBSTITUTE(SUBSTITUTE(SUBSTITUTE(SUBSTITUTE(SUBSTITUTE(SUBSTITUTE(SUBSTITUTE(UPPER(_xlpm.a)," ",""),"CONTROL","CTRL"),"CTL","CTRL"),"ESCAPE","ESC"),"RETURN","ENTER"),"PAGEDOWN","PGDN"),"PGDOWN","PGDN"),"PAGEUP","PGUP"),"ARROWKEYS","ARROW"),"ARROWKEY","ARROW"),"ARROWS","ARROW"),"DOWNARROW","DOWN"),"UPARROW","UP"),"LEFTARROW","LEFT"),"RIGHTARROW","RIGHT"),"ARROWDOWN","DOWN"),"ARROWUP","UP"),"ARROWLEFT","LEFT"),"ARROWRIGHT","RIGHT"),"↓","DOWN"),"↑","UP"),"←","LEFT"),"→","RIGHT"),"SPACEBAR","SPACE"),"−","-"),"MINUS","-"),"PLUS","+")=Key!$E$31:$E$31),"✔ CLEAR","✘ TRY AGAIN"))),"✘ TRY AGAIN")} | F21: {=IF(E21="Show hint",Key!$B$31,"")} | G21: {=IF(LEFT(D21,1)="✔",IF(E21="Show hint",5,10),0)} -> 0
A22: W10 | B22: For an approximate VLOOKUP, how must the first column be sorted? (from F4-5 Tiers) | D22: {=IFERROR(_xlfn.LET(_xlpm.a,'F7-2 Sifter'!$C$22,IF(TRIM(_xlpm.a&"")="","",IF(OR(SUBSTITUTE(SUBSTITUTE(SUBSTITUTE(SUBSTITUTE(SUBSTITUTE(SUBSTITUTE(SUBSTITUTE(SUBSTITUTE(SUBSTITUTE(SUBSTITUTE(SUBSTITUTE(SUBSTITUTE(SUBSTITUTE(SUBSTITUTE(SUBSTITUTE(SUBSTITUTE(SUBSTITUTE(SUBSTITUTE(SUBSTITUTE(SUBSTITUTE(SUBSTITUTE(SUBSTITUTE(SUBSTITUTE(SUBSTITUTE(SUBSTITUTE(SUBSTITUTE(SUBSTITUTE(UPPER(_xlpm.a)," ",""),"CONTROL","CTRL"),"CTL","CTRL"),"ESCAPE","ESC"),"RETURN","ENTER"),"PAGEDOWN","PGDN"),"PGDOWN","PGDN"),"PAGEUP","PGUP"),"ARROWKEYS","ARROW"),"ARROWKEY","ARROW"),"ARROWS","ARROW"),"DOWNARROW","DOWN"),"UPARROW","UP"),"LEFTARROW","LEFT"),"RIGHTARROW","RIGHT"),"ARROWDOWN","DOWN"),"ARROWUP","UP"),"ARROWLEFT","LEFT"),"ARROWRIGHT","RIGHT"),"↓","DOWN"),"↑","UP"),"←","LEFT"),"→","RIGHT"),"SPACEBAR","SPACE"),"−","-"),"MINUS","-"),"PLUS","+")=Key!$E$32:$H$32),"✔ CLEAR","✘ TRY AGAIN"))),"✘ TRY AGAIN")} | F22: {=IF(E22="Show hint",Key!$B$32,"")} | G22: {=IF(LEFT(D22,1)="✔",IF(E22="Show hint",5,10),0)} -> 0
A24: TRAINING · recognize the move (pick from the list)
A25: # | B25: Mission | C25: Your answer | D25: Result | E25: Hint? | F25: Hint | G25: XP
A26: T1 | B26: Which function returns only the rows that meet a condition? | D26: {=IFERROR(IF('F7-2 Sifter'!$C$26&""="","",IF('F7-2 Sifter'!$C$26&""=Key!$C$33&"","✔ CLEAR","✘ TRY AGAIN")),"✘ TRY AGAIN")} | F26: {=IF(E26="Show hint",Key!$B$33,"")} | G26: {=IF(LEFT(D26,1)="✔",IF(E26="Show hint",5,10),0)} -> 0
A27: T2 | B27: Which move is this? Multiply conditions for AND; add them for OR. | D27: {=IFERROR(IF('F7-2 Sifter'!$C$27&""="","",IF('F7-2 Sifter'!$C$27&""=Key!$C$34&"","✔ CLEAR","✘ TRY AGAIN")),"✘ TRY AGAIN")} | F27: {=IF(E27="Show hint",Key!$B$34,"")} | G27: {=IF(LEFT(D27,1)="✔",IF(E27="Show hint",5,10),0)} -> 0
A28: T3 | B28: Which FILTER argument number sets what to show when nothing matches? | D28: {=IFERROR(IF('F7-2 Sifter'!$C$28&""="","",IF('F7-2 Sifter'!$C$28&""=Key!$C$35&"","✔ CLEAR","✘ TRY AGAIN")),"✘ TRY AGAIN")} | F28: {=IF(E28="Show hint",Key!$B$35,"")} | G28: {=IF(LEFT(D28,1)="✔",IF(E28="Show hint",5,10),0)} -> 0
A30: CHALLENGES · recall it, then do it
B31: ▶ Open F7-2 Arena (or press Ctrl+PgDn)
A32: # | B32: Mission | C32: Your answer | D32: Result | E32: Hint? | F32: Hint | G32: XP
A33: C1 | B33: Which function returns only the rows that meet a condition? | D33: {=IFERROR(_xlfn.LET(_xlpm.a,'F7-2 Sifter'!$C$33,IF(TRIM(_xlpm.a&"")="","",IF(OR(SUBSTITUTE(SUBSTITUTE(SUBSTITUTE(SUBSTITUTE(SUBSTITUTE(SUBSTITUTE(SUBSTITUTE(SUBSTITUTE(SUBSTITUTE(SUBSTITUTE(SUBSTITUTE(SUBSTITUTE(SUBSTITUTE(SUBSTITUTE(SUBSTITUTE(SUBSTITUTE(SUBSTITUTE(SUBSTITUTE(SUBSTITUTE(SUBSTITUTE(SUBSTITUTE(SUBSTITUTE(SUBSTITUTE(SUBSTITUTE(SUBSTITUTE(SUBSTITUTE(SUBSTITUTE(UPPER(_xlpm.a)," ",""),"CONTROL","CTRL"),"CTL","CTRL"),"ESCAPE","ESC"),"RETURN","ENTER"),"PAGEDOWN","PGDN"),"PGDOWN","PGDN"),"PAGEUP","PGUP"),"ARROWKEYS","ARROW"),"ARROWKEY","ARROW"),"ARROWS","ARROW"),"DOWNARROW","DOWN"),"UPARROW","UP"),"LEFTARROW","LEFT"),"RIGHTARROW","RIGHT"),"ARROWDOWN","DOWN"),"ARROWUP","UP"),"ARROWLEFT","LEFT"),"ARROWRIGHT","RIGHT"),"↓","DOWN"),"↑","UP"),"←","LEFT"),"→","RIGHT"),"SPACEBAR","SPACE"),"−","-"),"MINUS","-"),"PLUS","+")=Key!$E$36:$J$36),"✔ CLEAR","✘ TRY AGAIN"))),"✘ TRY AGAIN")} | F33: {=IF(E33="Show hint",Key!$B$36,"")} | G33: {=IF(LEFT(D33,1)="✔",IF(E33="Show hint",5,10),0)} -> 0
A34: C2 | B34: In FILTER, which operator joins two conditions so BOTH must be true? | D34: {=IFERROR(_xlfn.LET(_xlpm.a,'F7-2 Sifter'!$C$34,IF(TRIM(_xlpm.a&"")="","",IF(OR(SUBSTITUTE(SUBSTITUTE(SUBSTITUTE(SUBSTITUTE(SUBSTITUTE(SUBSTITUTE(SUBSTITUTE(SUBSTITUTE(SUBSTITUTE(SUBSTITUTE(SUBSTITUTE(SUBSTITUTE(SUBSTITUTE(SUBSTITUTE(SUBSTITUTE(SUBSTITUTE(SUBSTITUTE(SUBSTITUTE(SUBSTITUTE(SUBSTITUTE(SUBSTITUTE(SUBSTITUTE(SUBSTITUTE(SUBSTITUTE(SUBSTITUTE(SUBSTITUTE(SUBSTITUTE(UPPER(_xlpm.a)," ",""),"CONTROL","CTRL"),"CTL","CTRL"),"ESCAPE","ESC"),"RETURN","ENTER"),"PAGEDOWN","PGDN"),"PGDOWN","PGDN"),"PAGEUP","PGUP"),"ARROWKEYS","ARROW"),"ARROWKEY","ARROW"),"ARROWS","ARROW"),"DOWNARROW","DOWN"),"UPARROW","UP"),"LEFTARROW","LEFT"),"RIGHTARROW","RIGHT"),"ARROWDOWN","DOWN"),"ARROWUP","UP"),"ARROWLEFT","LEFT"),"ARROWRIGHT","RIGHT"),"↓","DOWN"),"↑","UP"),"←","LEFT"),"→","RIGHT"),"SPACEBAR","SPACE"),"−","-"),"MINUS","-"),"PLUS","+")=Key!$E$37:$F$37),"✔ CLEAR","✘ TRY AGAIN"))),"✘ TRY AGAIN")} | F34: {=IF(E34="Show hint",Key!$B$37,"")} | G34: {=IF(LEFT(D34,1)="✔",IF(E34="Show hint",5,10),0)} -> 0
A35: C3 | B35: Which FILTER argument number sets what to show when nothing matches? | D35: {=IFERROR(_xlfn.LET(_xlpm.a,'F7-2 Sifter'!$C$35,IF(TRIM(_xlpm.a&"")="","",IF(OR(SUBSTITUTE(SUBSTITUTE(SUBSTITUTE(SUBSTITUTE(SUBSTITUTE(SUBSTITUTE(SUBSTITUTE(SUBSTITUTE(SUBSTITUTE(SUBSTITUTE(SUBSTITUTE(SUBSTITUTE(SUBSTITUTE(SUBSTITUTE(SUBSTITUTE(SUBSTITUTE(SUBSTITUTE(SUBSTITUTE(SUBSTITUTE(SUBSTITUTE(SUBSTITUTE(SUBSTITUTE(SUBSTITUTE(SUBSTITUTE(SUBSTITUTE(SUBSTITUTE(SUBSTITUTE(UPPER(_xlpm.a)," ",""),"CONTROL","CTRL"),"CTL","CTRL"),"ESCAPE","ESC"),"RETURN","ENTER"),"PAGEDOWN","PGDN"),"PGDOWN","PGDN"),"PAGEUP","PGUP"),"ARROWKEYS","ARROW"),"ARROWKEY","ARROW"),"ARROWS","ARROW"),"DOWNARROW","DOWN"),"UPARROW","UP"),"LEFTARROW","LEFT"),"RIGHTARROW","RIGHT"),"ARROWDOWN","DOWN"),"ARROWUP","UP"),"ARROWLEFT","LEFT"),"ARROWRIGHT","RIGHT"),"↓","DOWN"),"↑","UP"),"←","LEFT"),"→","RIGHT"),"SPACEBAR","SPACE"),"−","-"),"MINUS","-"),"PLUS","+")=Key!$E$38:$H$38),"✔ CLEAR","✘ TRY AGAIN"))),"✘ TRY AGAIN")} | F35: {=IF(E35="Show hint",Key!$B$38,"")} | G35: {=IF(LEFT(D35,1)="✔",IF(E35="Show hint",5,10),0)} -> 0
A36: C4 | B36: In K6 spill every East order (all columns): =FILTER(B6:H25,D6:D25="East"). | C36: ▶ ARENA C4 (cell K6) | D36: {=IF(ISBLANK('F7-2 Arena'!$K$6),"",IF(NOT(_xlfn.ISFORMULA('F7-2 Arena'!$K$6)),"✘ That's a typed value · enter a formula",IF(ISERROR('F7-2 Arena'!$K$6),"✘ Your formula returns "&IFERROR(CHOOSE(ERROR.TYPE('F7-2 Arena'!$K$6),"#NULL!","#DIV/0!","#VALUE!","#REF!","#NAME?","#NUM!","#N/A","#GETTING_DATA","#SPILL!","#CONNECT!","#BLOCKED!","#UNKNOWN!","#FIELD!","#CALC!"),"an error"),IF(IFERROR(AND(ROWS(_xlfn.ANCHORARRAY('F7-2 Arena'!$K$6))=ROWS(_xlfn.ANCHORARRAY(Key!$E$2101)),COLUMNS(_xlfn.ANCHORARRAY('F7-2 Arena'!$K$6))=COLUMNS(_xlfn.ANCHORARRAY(Key!$E$2101)),SUM(--(_xlfn.ANCHORARRAY('F7-2 Arena'!$K$6)=_xlfn.ANCHORARRAY(Key!$E$2101)))=ROWS(_xlfn.ANCHORARRAY(Key!$E$2101))*COLUMNS(_xlfn.ANCHORARRAY(Key!$E$2101))),FALSE),IF(AND(OR(ISNUMBER(FIND({"=","(",",","+","-","*","/","&"," ","<",">",":","@","^"}&"FILTER"&"(",UPPER(_xlfn.FORMULATEXT('F7-2 Arena'!$K$6)))))),"✔ CLEAR","✘ CLOSE · right result, but use FILTER"),"✘ TRY AGAIN"))))} | F36: {=IF(E36="Show hint",Key!$B$39,"")} | G36: {=IF(LEFT(D36,1)="✔",IF(E36="Show hint",5,10),0)} -> 0
A37: C5 | B37: In K20 spill the Order IDs of East orders with more than 40 units. Join the two conditions with *. | C37: ▶ ARENA C5 (cell K20) | D37: {=IF(ISBLANK('F7-2 Arena'!$K$20),"",IF(NOT(_xlfn.ISFORMULA('F7-2 Arena'!$K$20)),"✘ That's a typed value · enter a formula",IF(ISERROR('F7-2 Arena'!$K$20),"✘ Your formula returns "&IFERROR(CHOOSE(ERROR.TYPE('F7-2 Arena'!$K$20),"#NULL!","#DIV/0!","#VALUE!","#REF!","#NAME?","#NUM!","#N/A","#GETTING_DATA","#SPILL!","#CONNECT!","#BLOCKED!","#UNKNOWN!","#FIELD!","#CALC!"),"an error"),IF(IFERROR(AND(ROWS(_xlfn.ANCHORARRAY('F7-2 Arena'!$K$20))=ROWS(_xlfn.ANCHORARRAY(Key!$E$2201)),COLUMNS(_xlfn.ANCHORARRAY('F7-2 Arena'!$K$20))=COLUMNS(_xlfn.ANCHORARRAY(Key!$E$2201)),SUM(--(_xlfn.ANCHORARRAY('F7-2 Arena'!$K$20)=_xlfn.ANCHORARRAY(Key!$E$2201)))=ROWS(_xlfn.ANCHORARRAY(Key!$E$2201))*COLUMNS(_xlfn.ANCHORARRAY(Key!$E$2201))),FALSE),IF(AND(OR(ISNUMBER(FIND({"=","(",",","+","-","*","/","&"," ","<",">",":","@","^"}&"FILTER"&"(",UPPER(_xlfn.FORMULATEXT('F7-2 Arena'!$K$20)))))),"✔ CLEAR","✘ CLOSE · right result, but use FILTER"),"✘ TRY AGAIN"))))} | F37: {=IF(E37="Show hint",Key!$B$40,"")} | G37: {=IF(LEFT(D37,1)="✔",IF(E37="Show hint",5,10),0)} -> 0
A38: C6 | B38: There is no Central region. In K30 filter the Order IDs for "Central" and show None when nothing matches. | C38: ▶ ARENA C6 (cell K30) | D38: {=IF(ISBLANK('F7-2 Arena'!$K$30),"",IF(NOT(_xlfn.ISFORMULA('F7-2 Arena'!$K$30)),"✘ That's a typed value · enter a formula",IF(ISERROR('F7-2 Arena'!$K$30),"✘ Your formula returns "&IFERROR(CHOOSE(ERROR.TYPE('F7-2 Arena'!$K$30),"#NULL!","#DIV/0!","#VALUE!","#REF!","#NAME?","#NUM!","#N/A","#GETTING_DATA","#SPILL!","#CONNECT!","#BLOCKED!","#UNKNOWN!","#FIELD!","#CALC!"),"an error"),IF(NOT(AND(IFERROR(AND(ISTEXT('F7-2 Arena'!$K$30),'F7-2 Arena'!$K$30=Key!$C$41),FALSE))),"✘ TRY AGAIN",IF(AND(OR(ISNUMBER(FIND({"=","(",",","+","-","*","/","&"," ","<",">",":","@","^"}&"FILTER"&"(",UPPER(_xlfn.FORMULATEXT('F7-2 Arena'!$K$30)))))),"✔ CLEAR","✘ CLOSE · right value, but use FILTER")))))} | F38: {=IF(E38="Show hint",Key!$B$41,"")} | G38: {=IF(LEFT(D38,1)="✔",IF(E38="Show hint",5,10),0)} -> 0

Sheet F7-2 Arena
A1: ARENA ▸ F7-2 SIFTER
A2: Practice area · everything here is editable. Missions and their checks are on the stage sheet.
A3: PASS CODE | B3: SIFTER | D3: ◀ Back to F7-2 Sifter
B5: Order | C5: Date | D5: Region | E5: Rep | F5: Product | G5: Units | H5: Revenue | K5: East orders ▼
B6: O-101 | C6: 46027 | D6: East | E6: Kim | F6: Widget | G6: 40 | H6: 1200
B7: O-102 | C7: 46031 | D7: West | E7: Lee | F7: Gadget | G7: 15 | H7: 900
B8: O-103 | C8: 46036 | D8: North | E8: Ava | F8: Widget | G8: 55 | H8: 1650
B9: O-104 | C9: 46042 | D9: East | E9: Kim | F9: Gizmo | G9: 20 | H9: 1000
B10: O-105 | C10: 46055 | D10: South | E10: Raj | F10: Gadget | G10: 60 | H10: 3600
B11: O-106 | C11: 46060 | D11: West | E11: Lee | F11: Widget | G11: 35 | H11: 1050
B12: O-107 | C12: 46064 | D12: East | E12: Ava | F12: Gadget | G12: 25 | H12: 1500
B13: O-108 | C13: 46072 | D13: North | E13: Raj | F13: Gizmo | G13: 45 | H13: 2250
B14: O-109 | C14: 46084 | D14: West | E14: Kim | F14: Gizmo | G14: 10 | H14: 500
B15: O-110 | C15: 46089 | D15: East | E15: Lee | F15: Widget | G15: 70 | H15: 2100
B16: O-111 | C16: 46096 | D16: South | E16: Ava | F16: Widget | G16: 30 | H16: 900
B17: O-112 | C17: 46103 | D17: North | E17: Kim | F17: Gadget | G17: 50 | H17: 3000
B18: O-113 | C18: 46113 | D18: East | E18: Raj | F18: Gizmo | G18: 65 | H18: 3250
B19: O-114 | C19: 46118 | D19: West | E19: Ava | F19: Gadget | G19: 20 | H19: 1200 | K19: Big East orders ▼
B20: O-115 | C20: 46125 | D20: South | E20: Lee | F20: Gizmo | G20: 15 | H20: 750
B21: O-116 | C21: 46133 | D21: East | E21: Kim | F21: Widget | G21: 50 | H21: 1500
B22: O-117 | C22: 46146 | D22: North | E22: Lee | F22: Widget | G22: 25 | H22: 750
B23: O-118 | C23: 46154 | D23: West | E23: Raj | F23: Gadget | G23: 40 | H23: 2400
B24: O-119 | C24: 46161 | D24: South | E24: Kim | F24: Gizmo | G24: 35 | H24: 1750
B25: O-120 | C25: 46169 | D25: East | E25: Ava | F25: Gadget | G25: 55 | H25: 3300
K29: Central orders ▼

Sheet F7-3 Sorter
A1: STAGE F7-3 ▸ SORTER
A2: Goal: sort and de-duplicate with one formula
A3: {="SCORE "&TEXT(SUM($G$13:$G$39),"0000")&" / 0200"} -> SCORE 0000 / 0200 | C3: {=IF(SUM($G$13:$G$39)>=200,"★★★",IF(SUM($G$13:$G$39)>=200*0.8,"★★☆",IF(SUM($G$13:$G$39)>=200*0.5,"★☆☆","☆☆☆")))} -> ☆☆☆ | D3: {=REPT("█",ROUND(10*SUM($G$13:$G$39)/200,0))&REPT("░",10-ROUND(10*SUM($G$13:$G$39)/200,0))&" "&TEXT(SUM($G$13:$G$39)/200,"0%")} -> ░░░░░░░░░░ 0% | F3: {=IF(SUM($G$13:$G$39)>=200*0.5,"STAGE CLEAR! ▶ Next: F7-4 Combo","")}
A5: BRIEFING · new moves in this stage
A6: # | B6: What it does · Pro tip | C6: Keys / Syntax
A7: 1 | B7: SORT(range, column, order) spills a sorted copy; -1 = largest first. Tip: The original data never moves. | C7: SORT
A8: 2 | B8: SORTBY(range, by_range, order) sorts by a column you don't show. Tip: =SORTBY(B6:B25,C6:C25,-1) lists IDs newest first. | C8: SORTBY
A9: 3 | B9: UNIQUE(range) spills each different value once. Tip: Wrap in COUNTA to count the distinct values. | C9: UNIQUE
A11: WARM-UP · flashback to earlier stages
A12: # | B12: Mission | C12: Your answer | D12: Result | E12: Hint? | F12: Hint | G12: XP
A13: W1 | B13: Which function returns only the rows that meet a condition? (from F7-2 Sifter) | D13: {=IFERROR(_xlfn.LET(_xlpm.a,'F7-3 Sorter'!$C$13,IF(TRIM(_xlpm.a&"")="","",IF(OR(SUBSTITUTE(SUBSTITUTE(SUBSTITUTE(SUBSTITUTE(SUBSTITUTE(SUBSTITUTE(SUBSTITUTE(SUBSTITUTE(SUBSTITUTE(SUBSTITUTE(SUBSTITUTE(SUBSTITUTE(SUBSTITUTE(SUBSTITUTE(SUBSTITUTE(SUBSTITUTE(SUBSTITUTE(SUBSTITUTE(SUBSTITUTE(SUBSTITUTE(SUBSTITUTE(SUBSTITUTE(SUBSTITUTE(SUBSTITUTE(SUBSTITUTE(SUBSTITUTE(SUBSTITUTE(UPPER(_xlpm.a)," ",""),"CONTROL","CTRL"),"CTL","CTRL"),"ESCAPE","ESC"),"RETURN","ENTER"),"PAGEDOWN","PGDN"),"PGDOWN","PGDN"),"PAGEUP","PGUP"),"ARROWKEYS","ARROW"),"ARROWKEY","ARROW"),"ARROWS","ARROW"),"DOWNARROW","DOWN"),"UPARROW","UP"),"LEFTARROW","LEFT"),"RIGHTARROW","RIGHT"),"ARROWDOWN","DOWN"),"ARROWUP","UP"),"ARROWLEFT","LEFT"),"ARROWRIGHT","RIGHT"),"↓","DOWN"),"↑","UP"),"←","LEFT"),"→","RIGHT"),"SPACEBAR","SPACE"),"−","-"),"MINUS","-"),"PLUS","+")=Key!$E$42:$J$42),"✔ CLEAR","✘ TRY AGAIN"))),"✘ TRY AGAIN")} | F13: {=IF(E13="Show hint",Key!$B$42,"")} | G13: {=IF(LEFT(D13,1)="✔",IF(E13="Show hint",5,10),0)} -> 0
A14: W2 | B14: In FILTER, which operator joins two conditions so BOTH must be true? (from F7-2 Sifter) | D14: {=IFERROR(_xlfn.LET(_xlpm.a,'F7-3 Sorter'!$C$14,IF(TRIM(_xlpm.a&"")="","",IF(OR(SUBSTITUTE(SUBSTITUTE(SUBSTITUTE(SUBSTITUTE(SUBSTITUTE(SUBSTITUTE(SUBSTITUTE(SUBSTITUTE(SUBSTITUTE(SUBSTITUTE(SUBSTITUTE(SUBSTITUTE(SUBSTITUTE(SUBSTITUTE(SUBSTITUTE(SUBSTITUTE(SUBSTITUTE(SUBSTITUTE(SUBSTITUTE(SUBSTITUTE(SUBSTITUTE(SUBSTITUTE(SUBSTITUTE(SUBSTITUTE(SUBSTITUTE(SUBSTITUTE(SUBSTITUTE(UPPER(_xlpm.a)," ",""),"CONTROL","CTRL"),"CTL","CTRL"),"ESCAPE","ESC"),"RETURN","ENTER"),"PAGEDOWN","PGDN"),"PGDOWN","PGDN"),"PAGEUP","PGUP"),"ARROWKEYS","ARROW"),"ARROWKEY","ARROW"),"ARROWS","ARROW"),"DOWNARROW","DOWN"),"UPARROW","UP"),"LEFTARROW","LEFT"),"RIGHTARROW","RIGHT"),"ARROWDOWN","DOWN"),"ARROWUP","UP"),"ARROWLEFT","LEFT"),"ARROWRIGHT","RIGHT"),"↓","DOWN"),"↑","UP"),"←","LEFT"),"→","RIGHT"),"SPACEBAR","SPACE"),"−","-"),"MINUS","-"),"PLUS","+")=Key!$E$43:$F$43),"✔ CLEAR","✘ TRY AGAIN"))),"✘ TRY AGAIN")} | F14: {=IF(E14="Show hint",Key!$B$43,"")} | G14: {=IF(LEFT(D14,1)="✔",IF(E14="Show hint",5,10),0)} -> 0
A15: W3 | B15: Which FILTER argument number sets what to show when nothing matches? (from F7-2 Sifter) | D15: {=IFERROR(_xlfn.LET(_xlpm.a,'F7-3 Sorter'!$C$15,IF(TRIM(_xlpm.a&"")="","",IF(OR(SUBSTITUTE(SUBSTITUTE(SUBSTITUTE(SUBSTITUTE(SUBSTITUTE(SUBSTITUTE(SUBSTITUTE(SUBSTITUTE(SUBSTITUTE(SUBSTITUTE(SUBSTITUTE(SUBSTITUTE(SUBSTITUTE(SUBSTITUTE(SUBSTITUTE(SUBSTITUTE(SUBSTITUTE(SUBSTITUTE(SUBSTITUTE(SUBSTITUTE(SUBSTITUTE(SUBSTITUTE(SUBSTITUTE(SUBSTITUTE(SUBSTITUTE(SUBSTITUTE(SUBSTITUTE(UPPER(_xlpm.a)," ",""),"CONTROL","CTRL"),"CTL","CTRL"),"ESCAPE","ESC"),"RETURN","ENTER"),"PAGEDOWN","PGDN"),"PGDOWN","PGDN"),"PAGEUP","PGUP"),"ARROWKEYS","ARROW"),"ARROWKEY","ARROW"),"ARROWS","ARROW"),"DOWNARROW","DOWN"),"UPARROW","UP"),"LEFTARROW","LEFT"),"RIGHTARROW","RIGHT"),"ARROWDOWN","DOWN"),"ARROWUP","UP"),"ARROWLEFT","LEFT"),"ARROWRIGHT","RIGHT"),"↓","DOWN"),"↑","UP"),"←","LEFT"),"→","RIGHT"),"SPACEBAR","SPACE"),"−","-"),"MINUS","-"),"PLUS","+")=Key!$E$44:$H$44),"✔ CLEAR","✘ TRY AGAIN"))),"✘ TRY AGAIN")} | F15: {=IF(E15="Show hint",Key!$B$44,"")} | G15: {=IF(LEFT(D15,1)="✔",IF(E15="Show hint",5,10),0)} -> 0
A16: W4 | B16: Which function moves a date forward or back by whole months? (from F6-3 Deadlines) | D16: {=IFERROR(_xlfn.LET(_xlpm.a,'F7-3 Sorter'!$C$16,IF(TRIM(_xlpm.a&"")="","",IF(OR(SUBSTITUTE(SUBSTITUTE(SUBSTITUTE(SUBSTITUTE(SUBSTITUTE(SUBSTITUTE(SUBSTITUTE(SUBSTITUTE(SUBSTITUTE(SUBSTITUTE(SUBSTITUTE(SUBSTITUTE(SUBSTITUTE(SUBSTITUTE(SUBSTITUTE(SUBSTITUTE(SUBSTITUTE(SUBSTITUTE(SUBSTITUTE(SUBSTITUTE(SUBSTITUTE(SUBSTITUTE(SUBSTITUTE(SUBSTITUTE(SUBSTITUTE(SUBSTITUTE(SUBSTITUTE(UPPER(_xlpm.a)," ",""),"CONTROL","CTRL"),"CTL","CTRL"),"ESCAPE","ESC"),"RETURN","ENTER"),"PAGEDOWN","PGDN"),"PGDOWN","PGDN"),"PAGEUP","PGUP"),"ARROWKEYS","ARROW"),"ARROWKEY","ARROW"),"ARROWS","ARROW"),"DOWNARROW","DOWN"),"UPARROW","UP"),"LEFTARROW","LEFT"),"RIGHTARROW","RIGHT"),"ARROWDOWN","DOWN"),"ARROWUP","UP"),"ARROWLEFT","LEFT"),"ARROWRIGHT","RIGHT"),"↓","DOWN"),"↑","UP"),"←","LEFT"),"→","RIGHT"),"SPACEBAR","SPACE"),"−","-"),"MINUS","-"),"PLUS","+")=Key!$E$45:$J$45),"✔ CLEAR","✘ TRY AGAIN"))),"✘ TRY AGAIN")} | F16: {=IF(E16="Show hint",Key!$B$45,"")} | G16: {=IF(LEFT(D16,1)="✔",IF(E16="Show hint",5,10),0)} -> 0
A17: W5 | B17: Which function returns the last day of a month? (from F6-3 Deadlines) | D17: {=IFERROR(_xlfn.LET(_xlpm.a,'F7-3 Sorter'!$C$17,IF(TRIM(_xlpm.a&"")="","",IF(OR(SUBSTITUTE(SUBSTITUTE(SUBSTITUTE(SUBSTITUTE(SUBSTITUTE(SUBSTITUTE(SUBSTITUTE(SUBSTITUTE(SUBSTITUTE(SUBSTITUTE(SUBSTITUTE(SUBSTITUTE(SUBSTITUTE(SUBSTITUTE(SUBSTITUTE(SUBSTITUTE(SUBSTITUTE(SUBSTITUTE(SUBSTITUTE(SUBSTITUTE(SUBSTITUTE(SUBSTITUTE(SUBSTITUTE(SUBSTITUTE(SUBSTITUTE(SUBSTITUTE(SUBSTITUTE(UPPER(_xlpm.a)," ",""),"CONTROL","CTRL"),"CTL","CTRL"),"ESCAPE","ESC"),"RETURN","ENTER"),"PAGEDOWN","PGDN"),"PGDOWN","PGDN"),"PAGEUP","PGUP"),"ARROWKEYS","ARROW"),"ARROWKEY","ARROW"),"ARROWS","ARROW"),"DOWNARROW","DOWN"),"UPARROW","UP"),"LEFTARROW","LEFT"),"RIGHTARROW","RIGHT"),"ARROWDOWN","DOWN"),"ARROWUP","UP"),"ARROWLEFT","LEFT"),"ARROWRIGHT","RIGHT"),"↓","DOWN"),"↑","UP"),"←","LEFT"),"→","RIGHT"),"SPACEBAR","SPACE"),"−","-"),"MINUS","-"),"PLUS","+")=Key!$E$46:$J$46),"✔ CLEAR","✘ TRY AGAIN"))),"✘ TRY AGAIN")} | F17: {=IF(E17="Show hint",Key!$B$46,"")} | G17: {=IF(LEFT(D17,1)="✔",IF(E17="Show hint",5,10),0)} -> 0
A18: W6 | B18: Which function counts the working days between two dates? (from F6-3 Deadlines) | D18: {=IFERROR(_xlfn.LET(_xlpm.a,'F7-3 Sorter'!$C$18,IF(TRIM(_xlpm.a&"")="","",IF(OR(SUBSTITUTE(SUBSTITUTE(SUBSTITUTE(SUBSTITUTE(SUBSTITUTE(SUBSTITUTE(SUBSTITUTE(SUBSTITUTE(SUBSTITUTE(SUBSTITUTE(SUBSTITUTE(SUBSTITUTE(SUBSTITUTE(SUBSTITUTE(SUBSTITUTE(SUBSTITUTE(SUBSTITUTE(SUBSTITUTE(SUBSTITUTE(SUBSTITUTE(SUBSTITUTE(SUBSTITUTE(SUBSTITUTE(SUBSTITUTE(SUBSTITUTE(SUBSTITUTE(SUBSTITUTE(UPPER(_xlpm.a)," ",""),"CONTROL","CTRL"),"CTL","CTRL"),"ESCAPE","ESC"),"RETURN","ENTER"),"PAGEDOWN","PGDN"),"PGDOWN","PGDN"),"PAGEUP","PGUP"),"ARROWKEYS","ARROW"),"ARROWKEY","ARROW"),"ARROWS","ARROW"),"DOWNARROW","DOWN"),"UPARROW","UP"),"LEFTARROW","LEFT"),"RIGHTARROW","RIGHT"),"ARROWDOWN","DOWN"),"ARROWUP","UP"),"ARROWLEFT","LEFT"),"ARROWRIGHT","RIGHT"),"↓","DOWN"),"↑","UP"),"←","LEFT"),"→","RIGHT"),"SPACEBAR","SPACE"),"−","-"),"MINUS","-"),"PLUS","+")=Key!$E$47:$J$47),"✔ CLEAR","✘ TRY AGAIN"))),"✘ TRY AGAIN")} | F18: {=IF(E18="Show hint",Key!$B$47,"")} | G18: {=IF(LEFT(D18,1)="✔",IF(E18="Show hint",5,10),0)} -> 0
A19: W7 | B19: Which function returns the date a number of working days later? (from F6-3 Deadlines) | D19: {=IFERROR(_xlfn.LET(_xlpm.a,'F7-3 Sorter'!$C$19,IF(TRIM(_xlpm.a&"")="","",IF(OR(SUBSTITUTE(SUBSTITUTE(SUBSTITUTE(SUBSTITUTE(SUBSTITUTE(SUBSTITUTE(SUBSTITUTE(SUBSTITUTE(SUBSTITUTE(SUBSTITUTE(SUBSTITUTE(SUBSTITUTE(SUBSTITUTE(SUBSTITUTE(SUBSTITUTE(SUBSTITUTE(SUBSTITUTE(SUBSTITUTE(SUBSTITUTE(SUBSTITUTE(SUBSTITUTE(SUBSTITUTE(SUBSTITUTE(SUBSTITUTE(SUBSTITUTE(SUBSTITUTE(SUBSTITUTE(UPPER(_xlpm.a)," ",""),"CONTROL","CTRL"),"CTL","CTRL"),"ESCAPE","ESC"),"RETURN","ENTER"),"PAGEDOWN","PGDN"),"PGDOWN","PGDN"),"PAGEUP","PGUP"),"ARROWKEYS","ARROW"),"ARROWKEY","ARROW"),"ARROWS","ARROW"),"DOWNARROW","DOWN"),"UPARROW","UP"),"LEFTARROW","LEFT"),"RIGHTARROW","RIGHT"),"ARROWDOWN","DOWN"),"ARROWUP","UP"),"ARROWLEFT","LEFT"),"ARROWRIGHT","RIGHT"),"↓","DOWN"),"↑","UP"),"←","LEFT"),"→","RIGHT"),"SPACEBAR","SPACE"),"−","-"),"MINUS","-"),"PLUS","+")=Key!$E$48:$J$48),"✔ CLEAR","✘ TRY AGAIN"))),"✘ TRY AGAIN")} | F19: {=IF(E19="Show hint",Key!$B$48,"")} | G19: {=IF(LEFT(D19,1)="✔",IF(E19="Show hint",5,10),0)} -> 0
A20: W8 | B20: Which function returns characters from the start of a text? (from F5-1 Cut & Splice) | D20: {=IFERROR(_xlfn.LET(_xlpm.a,'F7-3 Sorter'!$C$20,IF(TRIM(_xlpm.a&"")="","",IF(OR(SUBSTITUTE(SUBSTITUTE(SUBSTITUTE(SUBSTITUTE(SUBSTITUTE(SUBSTITUTE(SUBSTITUTE(SUBSTITUTE(SUBSTITUTE(SUBSTITUTE(SUBSTITUTE(SUBSTITUTE(SUBSTITUTE(SUBSTITUTE(SUBSTITUTE(SUBSTITUTE(SUBSTITUTE(SUBSTITUTE(SUBSTITUTE(SUBSTITUTE(SUBSTITUTE(SUBSTITUTE(SUBSTITUTE(SUBSTITUTE(SUBSTITUTE(SUBSTITUTE(SUBSTITUTE(UPPER(_xlpm.a)," ",""),"CONTROL","CTRL"),"CTL","CTRL"),"ESCAPE","ESC"),"RETURN","ENTER"),"PAGEDOWN","PGDN"),"PGDOWN","PGDN"),"PAGEUP","PGUP"),"ARROWKEYS","ARROW"),"ARROWKEY","ARROW"),"ARROWS","ARROW"),"DOWNARROW","DOWN"),"UPARROW","UP"),"LEFTARROW","LEFT"),"RIGHTARROW","RIGHT"),"ARROWDOWN","DOWN"),"ARROWUP","UP"),"ARROWLEFT","LEFT"),"ARROWRIGHT","RIGHT"),"↓","DOWN"),"↑","UP"),"←","LEFT"),"→","RIGHT"),"SPACEBAR","SPACE"),"−","-"),"MINUS","-"),"PLUS","+")=Key!$E$49:$J$49),"✔ CLEAR","✘ TRY AGAIN"))),"✘ TRY AGAIN")} | F20: {=IF(E20="Show hint",Key!$B$49,"")} | G20: {=IF(LEFT(D20,1)="✔",IF(E20="Show hint",5,10),0)} -> 0
A21: W9 | B21: Which function returns characters from the end of a text? (from F5-1 Cut & Splice) | D21: {=IFERROR(_xlfn.LET(_xlpm.a,'F7-3 Sorter'!$C$21,IF(TRIM(_xlpm.a&"")="","",IF(OR(SUBSTITUTE(SUBSTITUTE(SUBSTITUTE(SUBSTITUTE(SUBSTITUTE(SUBSTITUTE(SUBSTITUTE(SUBSTITUTE(SUBSTITUTE(SUBSTITUTE(SUBSTITUTE(SUBSTITUTE(SUBSTITUTE(SUBSTITUTE(SUBSTITUTE(SUBSTITUTE(SUBSTITUTE(SUBSTITUTE(SUBSTITUTE(SUBSTITUTE(SUBSTITUTE(SUBSTITUTE(SUBSTITUTE(SUBSTITUTE(SUBSTITUTE(SUBSTITUTE(SUBSTITUTE(UPPER(_xlpm.a)," ",""),"CONTROL","CTRL"),"CTL","CTRL"),"ESCAPE","ESC"),"RETURN","ENTER"),"PAGEDOWN","PGDN"),"PGDOWN","PGDN"),"PAGEUP","PGUP"),"ARROWKEYS","ARROW"),"ARROWKEY","ARROW"),"ARROWS","ARROW"),"DOWNARROW","DOWN"),"UPARROW","UP"),"LEFTARROW","LEFT"),"RIGHTARROW","RIGHT"),"ARROWDOWN","DOWN"),"ARROWUP","UP"),"ARROWLEFT","LEFT"),"ARROWRIGHT","RIGHT"),"↓","DOWN"),"↑","UP"),"←","LEFT"),"→","RIGHT"),"SPACEBAR","SPACE"),"−","-"),"MINUS","-"),"PLUS","+")=Key!$E$50:$J$50),"✔ CLEAR","✘ TRY AGAIN"))),"✘ TRY AGAIN")} | F21: {=IF(E21="Show hint",Key!$B$50,"")} | G21: {=IF(LEFT(D21,1)="✔",IF(E21="Show hint",5,10),0)} -> 0
