Workbook

Sheet Start
A1: FINAL BOSS ▸ THE CHAMPIONSHIP
A2: Every shortcut and formula from the course in one championship. Beat par for rank S.
A4: HOW TO PLAY
A5: 1 · Each stage: read the BRIEFING, then answer WARM-UP, TRAINING and CHALLENGES.
A6: 2 · Yellow cells are yours: type, pick from a list (Alt+↓), or follow a ▶ ARENA link and do the move there.
A7: 3 · ✔ CLEAR = right · ✘ = try again · · not yet = drill not done. Stuck? Pick 'Show hint' (5 XP instead of 10).
A8: 4 · Formatting or hiding drills: press F9 to refresh the check. Tab jumps between yellow cells.
A9: Needs Windows with Microsoft Excel 365 or 2021+ (English). In Protected View, click Enable Editing.
A11: STAGE SELECT
A12: Stage | B12: Name | C12: Score | D12: Stars | E12: Status | F12: Go
A13: R1 | B13: Shortcut Gauntlet | C13: {=SUM('R1 Shortcut Gauntlet'!$G$8:$G$16)&" / 90"} -> 0 / 90 | D13: {=IF(SUM('R1 Shortcut Gauntlet'!$G$8:$G$16)>=90,"★★★",IF(SUM('R1 Shortcut Gauntlet'!$G$8:$G$16)>=90*0.8,"★★☆",IF(SUM('R1 Shortcut Gauntlet'!$G$8:$G$16)>=90*0.5,"★☆☆","☆☆☆")))} -> ☆☆☆ | E13: {=IF(SUM('R1 Shortcut Gauntlet'!$G$8:$G$16)>=90,"PERFECT",IF(SUM('R1 Shortcut Gauntlet'!$G$8:$G$16)>=90*0.5,"CLEARED",IF(SUM('R1 Shortcut Gauntlet'!$G$8:$G$16)>0,"IN PROGRESS","NEW")))} -> NEW | F13: Go to R1 Shortcut Gauntlet
A14: R2 | B14: Formula Gauntlet | C14: {=SUM('R2 Formula Gauntlet'!$G$7:$G$50)&" / 400"} -> 0 / 400 | D14: {=IF(SUM('R2 Formula Gauntlet'!$G$7:$G$50)>=400,"★★★",IF(SUM('R2 Formula Gauntlet'!$G$7:$G$50)>=400*0.8,"★★☆",IF(SUM('R2 Formula Gauntlet'!$G$7:$G$50)>=400*0.5,"★☆☆","☆☆☆")))} -> ☆☆☆ | E14: {=IF(SUM('R2 Formula Gauntlet'!$G$7:$G$50)>=400,"PERFECT",IF(SUM('R2 Formula Gauntlet'!$G$7:$G$50)>=400*0.5,"CLEARED",IF(SUM('R2 Formula Gauntlet'!$G$7:$G$50)>0,"IN PROGRESS","NEW")))} -> NEW | F14: Go to R2 Formula Gauntlet
A15: R3 | B15: Real-World Mission | C15: {=SUM('R3 Real-World Mission'!$G$8:$G$15)&" / 80"} -> 0 / 80 | D15: {=IF(SUM('R3 Real-World Mission'!$G$8:$G$15)>=80,"★★★",IF(SUM('R3 Real-World Mission'!$G$8:$G$15)>=80*0.8,"★★☆",IF(SUM('R3 Real-World Mission'!$G$8:$G$15)>=80*0.5,"★☆☆","☆☆☆")))} -> ☆☆☆ | E15: {=IF(SUM('R3 Real-World Mission'!$G$8:$G$15)>=80,"PERFECT",IF(SUM('R3 Real-World Mission'!$G$8:$G$15)>=80*0.5,"CLEARED",IF(SUM('R3 Real-World Mission'!$G$8:$G$15)>0,"IN PROGRESS","NEW")))} -> NEW | F15: Go to R3 Real-World Mission
A17: TOTAL SCORE | B17: {=(SUM('R1 Shortcut Gauntlet'!$G$8:$G$16)+SUM('R2 Formula Gauntlet'!$G$7:$G$50)+SUM('R3 Real-World Mission'!$G$8:$G$15))&" / 570"} -> 0 / 570
A18: RANK | B18: {=_xlfn.LET(_xlpm.p,(SUM('R1 Shortcut Gauntlet'!$G$8:$G$16)+SUM('R2 Formula Gauntlet'!$G$7:$G$50)+SUM('R3 Real-World Mission'!$G$8:$G$15))/570,IF(AND(_xlpm.p>=1,ISNUMBER(Start!$C$42),Start!$C$42<=45),"S",IF(_xlpm.p>=0.9,"A",IF(_xlpm.p>=0.75,"B",IF(_xlpm.p>=0.5,"C","D")))))} -> D | C18: S = 100% and under par · A ≥ 90% · B ≥ 75% · C ≥ 50%
A19: BEST TIME | B19: {=IF(ISNUMBER(Start!$C$42),Start!$C$42&" min (par 45)","—")} -> —
A20: NEXT UP | B20: {=IFERROR(INDEX($A$13:$A$15,MATCH("☆☆☆",$D$13:$D$15,0))&" "&INDEX($B$13:$B$15,MATCH("☆☆☆",$D$13:$D$15,0)),"All clear! Aim for rank S")} -> R1 Shortcut Gauntlet
A22: Replay a stage: select its yellow answer cells and press Delete. Undo an arena drill with Ctrl+Z.
A39: SPEEDRUN · stamp START before Round 1 and FINISH after Round 3
B40: START (Ctrl+Shift+:)
B41: FINISH (Ctrl+Shift+:)
B42: TIME | C42: {=IF(OR(C40="",C41=""),"",ROUND(MOD(C41-C40,1)*1440,0))}
B43: PAR | C43: 45

Sheet R1 Shortcut Gauntlet
A1: R1 ▸ SHORTCUT GAUNTLET
A2: Goal: prove every shortcut is in your fingers
A3: {="SCORE "&TEXT(SUM($G$8:$G$16),"0000")&" / 0090"} -> SCORE 0000 / 0090 | C3: {=IF(SUM($G$8:$G$16)>=90,"★★★",IF(SUM($G$8:$G$16)>=90*0.8,"★★☆",IF(SUM($G$8:$G$16)>=90*0.5,"★☆☆","☆☆☆")))} -> ☆☆☆ | D3: {=REPT("█",ROUND(10*SUM($G$8:$G$16)/90,0))&REPT("░",10-ROUND(10*SUM($G$8:$G$16)/90,0))&" "&TEXT(SUM($G$8:$G$16)/90,"0%")} -> ░░░░░░░░░░ 0% | F3: {=IF(SUM($G$8:$G$16)>=90*0.5,"STAGE CLEAR! ▶ Next: R2 Formula Gauntlet","")}
A5: MISSIONS
B6: ▶ Open R1 Arena (or press Ctrl+PgDn)
A7: # | B7: Mission | C7: Your answer | D7: Result | E7: Hint? | F7: Hint | G7: XP
A8: M1 | B8: In the R1 Arena click B6 and press Ctrl+↓. Type the word at the end of the trail. | D8: {=IFERROR(_xlfn.LET(_xlpm.a,'R1 Shortcut Gauntlet'!$C$8,IF(TRIM(_xlpm.a&"")="","",IF(SUBSTITUTE(SUBSTITUTE(UPPER(_xlpm.a&"")," ",""),"$","")=Key!$C$2,"✔ CLEAR","✘ TRY AGAIN"))),"✘ TRY AGAIN")} | F8: {=IF(E8="Show hint",Key!$B$2,"")} | G8: {=IF(LEFT(D8,1)="✔",IF(E8="Show hint",5,10),0)} -> 0
A9: M2 | B9: Click D6 and keep pressing Ctrl+↓ until you reach a word. Type it. | D9: {=IFERROR(_xlfn.LET(_xlpm.a,'R1 Shortcut Gauntlet'!$C$9,IF(TRIM(_xlpm.a&"")="","",IF(SUBSTITUTE(SUBSTITUTE(UPPER(_xlpm.a&"")," ",""),"$","")=Key!$C$3,"✔ CLEAR","✘ TRY AGAIN"))),"✘ TRY AGAIN")} | F9: {=IF(E9="Show hint",Key!$B$3,"")} | G9: {=IF(LEFT(D9,1)="✔",IF(E9="Show hint",5,10),0)} -> 0
A10: M3 | B10: Press F5 (or Ctrl+G) and go to H500. Type the word there. | D10: {=IFERROR(_xlfn.LET(_xlpm.a,'R1 Shortcut Gauntlet'!$C$10,IF(TRIM(_xlpm.a&"")="","",IF(SUBSTITUTE(SUBSTITUTE(UPPER(_xlpm.a&"")," ",""),"$","")=Key!$C$4,"✔ CLEAR","✘ TRY AGAIN"))),"✘ TRY AGAIN")} | F10: {=IF(E10="Show hint",Key!$B$4,"")} | G10: {=IF(LEFT(D10,1)="✔",IF(E10="Show hint",5,10),0)} -> 0
A11: M4 | B11: Press Ctrl+End. Type the word in the last used cell. | D11: {=IFERROR(_xlfn.LET(_xlpm.a,'R1 Shortcut Gauntlet'!$C$11,IF(TRIM(_xlpm.a&"")="","",IF(SUBSTITUTE(SUBSTITUTE(UPPER(_xlpm.a&"")," ",""),"$","")=Key!$C$5,"✔ CLEAR","✘ TRY AGAIN"))),"✘ TRY AGAIN")} | F11: {=IF(E11="Show hint",Key!$B$5,"")} | G11: {=IF(LEFT(D11,1)="✔",IF(E11="Show hint",5,10),0)} -> 0
A12: M5 | B12: Select F6:F12, type GO and press Ctrl+Enter. | C12: ▶ ARENA M5 (cell F6) | D12: {=IF(IFERROR(AND('R1 Arena'!$F$6="GO",'R1 Arena'!$F$7="GO",'R1 Arena'!$F$8="GO",'R1 Arena'!$F$9="GO",'R1 Arena'!$F$10="GO",'R1 Arena'!$F$11="GO",'R1 Arena'!$F$12="GO"),FALSE),"✔ CLEAR","· not yet")} -> · not yet | F12: {=IF(E12="Show hint",Key!$B$6,"")} | G12: {=IF(LEFT(D12,1)="✔",IF(E12="Show hint",5,10),0)} -> 0
A13: M6 | B13: In F15 type Excel, press Alt+Enter, type Arcade, then press Enter. | C13: ▶ ARENA M6 (cell F15) | D13: {=IF(IFERROR(EXACT('R1 Arena'!$F$15,"Excel"&CHAR(10)&"Arcade"),FALSE),"✔ CLEAR","· not yet")} -> · not yet | F13: {=IF(E13="Show hint",Key!$B$7,"")} | G13: {=IF(LEFT(D13,1)="✔",IF(E13="Show hint",5,10),0)} -> 0
A14: M7 | B14: Stamp today's date in F17 with Ctrl+;, then Enter. | C14: ▶ ARENA M7 (cell F17) | D14: {=IF(IFERROR(AND(ISNUMBER('R1 Arena'!$F$17),NOT(_xlfn.ISFORMULA('R1 Arena'!$F$17)),'R1 Arena'!$F$17=INT('R1 Arena'!$F$17),'R1 Arena'!$F$17>=DATE(2026,10,12),'R1 Arena'!$F$17<=TODAY()),FALSE),"✔ CLEAR","· not yet")} -> · not yet | F14: {=IF(E14="Show hint",Key!$B$8,"")} | G14: {=IF(LEFT(D14,1)="✔",IF(E14="Show hint",5,10),0)} -> 0
A15: M8 | B15: Make H6:H10 percentages with Ctrl+Shift+%. Press F9. | C15: ▶ ARENA M8 (cell H6) | D15: {=IF(IFERROR(AND(OR(CELL("format",'R1 Arena'!$H$6)="P0"),OR(CELL("format",'R1 Arena'!$H$7)="P0"),OR(CELL("format",'R1 Arena'!$H$8)="P0"),OR(CELL("format",'R1 Arena'!$H$9)="P0"),OR(CELL("format",'R1 Arena'!$H$10)="P0")),FALSE),"✔ CLEAR","· not yet · press F9")} -> · not yet · press F9 | F15: {=IF(E15="Show hint",Key!$B$9,"")} | G15: {=IF(LEFT(D15,1)="✔",IF(E15="Show hint",5,10),0)} -> 0
A16: M9 | B16: Filter the table at B810 to show only North: Ctrl+Shift+L, then Alt+↓ on the Region header. | C16: ▶ ARENA M9 (cell C810) | D16: {=IF(IFERROR(AND(SUBTOTAL(103,'R1 Arena'!$C$811:$C$830)=4,SUMPRODUCT(SUBTOTAL(103,OFFSET('R1 Arena'!$C$811,ROW('R1 Arena'!$C$811:$C$830)-ROW('R1 Arena'!$C$811),0))*('R1 Arena'!$C$811:$C$830<>"North"))=0),FALSE),"✔ CLEAR","· not yet")} -> · not yet | F16: {=IF(E16="Show hint",Key!$B$10,"")} | G16: {=IF(LEFT(D16,1)="✔",IF(E16="Show hint",5,10),0)} -> 0

Sheet R1 Arena
A1: ARENA ▸ R1 SHORTCUT GAUNTLET
A2: Practice area · everything here is editable. Missions and their checks are on the stage sheet.
A3: PASS CODE | B3: GAUNTLET | D3: ◀ Back to R1 Shortcut Gauntlet
B5: TRAIL ▼ | D5: SCATTER ▼ | F5: GO ▼ | H5: SHARES ▼
B6: 1 | D6: 1 | H6: 0.1
B7: 2 | D7: 2 | H7: 0.25
B8: 3 | D8: 3 | H8: 0.5
B9: 4 | D9: 4 | H9: 0.75
B10: 5 | D10: 5 | H10: 0.9
B11: 6 | D11: 6
B12: 7 | D12: 7
B13: 8 | D13: 8
B14: 9 | D14: 9 | F14: TWO LINES ▼
B15: 10 | D15: 10
B16: 11 | D16: 11 | F16: DATE ▼
B17: 12 | D17: 12
B18: 13 | D18: 13
B19: 14 | D19: 14
B20: 15 | D20: 15
B21: 16 | D21: 16
B22: 17 | D22: 17
B23: 18 | D23: 18
B24: 19 | D24: 19
B25: 20 | D25: 20
B26: 21 | D26: 21
B27: 22 | D27: 22
B28: 23 | D28: 23
... B30: 25 | D30: 25
B31: 26
B32: 27
B33: 28
B34: 29
B35: 30
B36: 31
B37: 32
B38: 33
B39: 34
B40: 35
B41: 36
B42: 37
...

Sheet R2 Formula Gauntlet
A1: R2 ▸ FORMULA GAUNTLET
A2: Goal: answer real questions with the right formula
A3: {="SCORE "&TEXT(SUM($G$7:$G$50),"0000")&" / 0400"} -> SCORE 0000 / 0400 | C3: {=IF(SUM($G$7:$G$50)>=400,"★★★",IF(SUM($G$7:$G$50)>=400*0.8,"★★☆",IF(SUM($G$7:$G$50)>=400*0.5,"★☆☆","☆☆☆")))} -> ☆☆☆ | D3: {=REPT("█",ROUND(10*SUM($G$7:$G$50)/400,0))&REPT("░",10-ROUND(10*SUM($G$7:$G$50)/400,0))&" "&TEXT(SUM($G$7:$G$50)/400,"0%")} -> ░░░░░░░░░░ 0% | F3: {=IF(SUM($G$7:$G$50)>=400*0.5,"STAGE CLEAR! ▶ Next: R3 Real-World Mission","")}
A5: GAUNTLET · rapid recall from the whole course
A6: # | B6: Mission | C6: Your answer | D6: Result | E6: Hint? | F6: Hint | G6: XP
A7: G1 | B7: Which FILTER argument number sets what to show when nothing matches? (from F7-2 Sifter) | D7: {=IFERROR(_xlfn.LET(_xlpm.a,'R2 Formula Gauntlet'!$C$7,IF(TRIM(_xlpm.a&"")="","",IF(OR(SUBSTITUTE(SUBSTITUTE(SUBSTITUTE(SUBSTITUTE(SUBSTITUTE(SUBSTITUTE(SUBSTITUTE(SUBSTITUTE(SUBSTITUTE(SUBSTITUTE(SUBSTITUTE(SUBSTITUTE(SUBSTITUTE(SUBSTITUTE(SUBSTITUTE(SUBSTITUTE(SUBSTITUTE(SUBSTITUTE(SUBSTITUTE(SUBSTITUTE(SUBSTITUTE(SUBSTITUTE(SUBSTITUTE(SUBSTITUTE(SUBSTITUTE(SUBSTITUTE(SUBSTITUTE(UPPER(_xlpm.a)," ",""),"CONTROL","CTRL"),"CTL","CTRL"),"ESCAPE","ESC"),"RETURN","ENTER"),"PAGEDOWN","PGDN"),"PGDOWN","PGDN"),"PAGEUP","PGUP"),"ARROWKEYS","ARROW"),"ARROWKEY","ARROW"),"ARROWS","ARROW"),"DOWNARROW","DOWN"),"UPARROW","UP"),"LEFTARROW","LEFT"),"RIGHTARROW","RIGHT"),"ARROWDOWN","DOWN"),"ARROWUP","UP"),"ARROWLEFT","LEFT"),"ARROWRIGHT","RIGHT"),"↓","DOWN"),"↑","UP"),"←","LEFT"),"→","RIGHT"),"SPACEBAR","SPACE"),"−","-"),"MINUS","-"),"PLUS","+")=Key!$E$11:$H$11),"✔ CLEAR","✘ TRY AGAIN"))),"✘ TRY AGAIN")} | F7: {=IF(E7="Show hint",Key!$B$11,"")} | G7: {=IF(LEFT(D7,1)="✔",IF(E7="Show hint",5,10),0)} -> 0
A8: G2 | B8: Which function spills a sorted copy of a range? (from F7-3 Sorter) | D8: {=IFERROR(_xlfn.LET(_xlpm.a,'R2 Formula Gauntlet'!$C$8,IF(TRIM(_xlpm.a&"")="","",IF(OR(SUBSTITUTE(SUBSTITUTE(SUBSTITUTE(SUBSTITUTE(SUBSTITUTE(SUBSTITUTE(SUBSTITUTE(SUBSTITUTE(SUBSTITUTE(SUBSTITUTE(SUBSTITUTE(SUBSTITUTE(SUBSTITUTE(SUBSTITUTE(SUBSTITUTE(SUBSTITUTE(SUBSTITUTE(SUBSTITUTE(SUBSTITUTE(SUBSTITUTE(SUBSTITUTE(SUBSTITUTE(SUBSTITUTE(SUBSTITUTE(SUBSTITUTE(SUBSTITUTE(SUBSTITUTE(UPPER(_xlpm.a)," ",""),"CONTROL","CTRL"),"CTL","CTRL"),"ESCAPE","ESC"),"RETURN","ENTER"),"PAGEDOWN","PGDN"),"PGDOWN","PGDN"),"PAGEUP","PGUP"),"ARROWKEYS","ARROW"),"ARROWKEY","ARROW"),"ARROWS","ARROW"),"DOWNARROW","DOWN"),"UPARROW","UP"),"LEFTARROW","LEFT"),"RIGHTARROW","RIGHT"),"ARROWDOWN","DOWN"),"ARROWUP","UP"),"ARROWLEFT","LEFT"),"ARROWRIGHT","RIGHT"),"↓","DOWN"),"↑","UP"),"←","LEFT"),"→","RIGHT"),"SPACEBAR","SPACE"),"−","-"),"MINUS","-"),"PLUS","+")=Key!$E$12:$J$12),"✔ CLEAR","✘ TRY AGAIN"))),"✘ TRY AGAIN")} | F8: {=IF(E8="Show hint",Key!$B$12,"")} | G8: {=IF(LEFT(D8,1)="✔",IF(E8="Show hint",5,10),0)} -> 0
A9: G3 | B9: Which function sorts a range by another range? (from F7-3 Sorter) | D9: {=IFERROR(_xlfn.LET(_xlpm.a,'R2 Formula Gauntlet'!$C$9,IF(TRIM(_xlpm.a&"")="","",IF(OR(SUBSTITUTE(SUBSTITUTE(SUBSTITUTE(SUBSTITUTE(SUBSTITUTE(SUBSTITUTE(SUBSTITUTE(SUBSTITUTE(SUBSTITUTE(SUBSTITUTE(SUBSTITUTE(SUBSTITUTE(SUBSTITUTE(SUBSTITUTE(SUBSTITUTE(SUBSTITUTE(SUBSTITUTE(SUBSTITUTE(SUBSTITUTE(SUBSTITUTE(SUBSTITUTE(SUBSTITUTE(SUBSTITUTE(SUBSTITUTE(SUBSTITUTE(SUBSTITUTE(SUBSTITUTE(UPPER(_xlpm.a)," ",""),"CONTROL","CTRL"),"CTL","CTRL"),"ESCAPE","ESC"),"RETURN","ENTER"),"PAGEDOWN","PGDN"),"PGDOWN","PGDN"),"PAGEUP","PGUP"),"ARROWKEYS","ARROW"),"ARROWKEY","ARROW"),"ARROWS","ARROW"),"DOWNARROW","DOWN"),"UPARROW","UP"),"LEFTARROW","LEFT"),"RIGHTARROW","RIGHT"),"ARROWDOWN","DOWN"),"ARROWUP","UP"),"ARROWLEFT","LEFT"),"ARROWRIGHT","RIGHT"),"↓","DOWN"),"↑","UP"),"←","LEFT"),"→","RIGHT"),"SPACEBAR","SPACE"),"−","-"),"MINUS","-"),"PLUS","+")=Key!$E$13:$J$13),"✔ CLEAR","✘ TRY AGAIN"))),"✘ TRY AGAIN")} | F9: {=IF(E9="Show hint",Key!$B$13,"")} | G9: {=IF(LEFT(D9,1)="✔",IF(E9="Show hint",5,10),0)} -> 0
A10: G4 | B10: Which function returns each distinct value once? (from F7-3 Sorter) | D10: {=IFERROR(_xlfn.LET(_xlpm.a,'R2 Formula Gauntlet'!$C$10,IF(TRIM(_xlpm.a&"")="","",IF(OR(SUBSTITUTE(SUBSTITUTE(SUBSTITUTE(SUBSTITUTE(SUBSTITUTE(SUBSTITUTE(SUBSTITUTE(SUBSTITUTE(SUBSTITUTE(SUBSTITUTE(SUBSTITUTE(SUBSTITUTE(SUBSTITUTE(SUBSTITUTE(SUBSTITUTE(SUBSTITUTE(SUBSTITUTE(SUBSTITUTE(SUBSTITUTE(SUBSTITUTE(SUBSTITUTE(SUBSTITUTE(SUBSTITUTE(SUBSTITUTE(SUBSTITUTE(SUBSTITUTE(SUBSTITUTE(UPPER(_xlpm.a)," ",""),"CONTROL","CTRL"),"CTL","CTRL"),"ESCAPE","ESC"),"RETURN","ENTER"),"PAGEDOWN","PGDN"),"PGDOWN","PGDN"),"PAGEUP","PGUP"),"ARROWKEYS","ARROW"),"ARROWKEY","ARROW"),"ARROWS","ARROW"),"DOWNARROW","DOWN"),"UPARROW","UP"),"LEFTARROW","LEFT"),"RIGHTARROW","RIGHT"),"ARROWDOWN","DOWN"),"ARROWUP","UP"),"ARROWLEFT","LEFT"),"ARROWRIGHT","RIGHT"),"↓","DOWN"),"↑","UP"),"←","LEFT"),"→","RIGHT"),"SPACEBAR","SPACE"),"−","-"),"MINUS","-"),"PLUS","+")=Key!$E$14:$J$14),"✔ CLEAR","✘ TRY AGAIN"))),"✘ TRY AGAIN")} | F10: {=IF(E10="Show hint",Key!$B$14,"")} | G10: {=IF(LEFT(D10,1)="✔",IF(E10="Show hint",5,10),0)} -> 0
A11: G5 | B11: Which function lets you name a value inside a formula? (from F7-4 Combo) | D11: {=IFERROR(_xlfn.LET(_xlpm.a,'R2 Formula Gauntlet'!$C$11,IF(TRIM(_xlpm.a&"")="","",IF(OR(SUBSTITUTE(SUBSTITUTE(SUBSTITUTE(SUBSTITUTE(SUBSTITUTE(SUBSTITUTE(SUBSTITUTE(SUBSTITUTE(SUBSTITUTE(SUBSTITUTE(SUBSTITUTE(SUBSTITUTE(SUBSTITUTE(SUBSTITUTE(SUBSTITUTE(SUBSTITUTE(SUBSTITUTE(SUBSTITUTE(SUBSTITUTE(SUBSTITUTE(SUBSTITUTE(SUBSTITUTE(SUBSTITUTE(SUBSTITUTE(SUBSTITUTE(SUBSTITUTE(SUBSTITUTE(UPPER(_xlpm.a)," ",""),"CONTROL","CTRL"),"CTL","CTRL"),"ESCAPE","ESC"),"RETURN","ENTER"),"PAGEDOWN","PGDN"),"PGDOWN","PGDN"),"PAGEUP","PGUP"),"ARROWKEYS","ARROW"),"ARROWKEY","ARROW"),"ARROWS","ARROW"),"DOWNARROW","DOWN"),"UPARROW","UP"),"LEFTARROW","LEFT"),"RIGHTARROW","RIGHT"),"ARROWDOWN","DOWN"),"ARROWUP","UP"),"ARROWLEFT","LEFT"),"ARROWRIGHT","RIGHT"),"↓","DOWN"),"↑","UP"),"←","LEFT"),"→","RIGHT"),"SPACEBAR","SPACE"),"−","-"),"MINUS","-"),"PLUS","+")=Key!$E$15:$J$15),"✔ CLEAR","✘ TRY AGAIN"))),"✘ TRY AGAIN")} | F11: {=IF(E11="Show hint",Key!$B$15,"")} | G11: {=IF(LEFT(D11,1)="✔",IF(E11="Show hint",5,10),0)} -> 0
A12: G6 | B12: In =SORT(UNIQUE(E6:E25)), which function removes the duplicates? (from F7-4 Combo) | D12: {=IFERROR(_xlfn.LET(_xlpm.a,'R2 Formula Gauntlet'!$C$12,IF(TRIM(_xlpm.a&"")="","",IF(OR(SUBSTITUTE(SUBSTITUTE(SUBSTITUTE(SUBSTITUTE(SUBSTITUTE(SUBSTITUTE(SUBSTITUTE(SUBSTITUTE(SUBSTITUTE(SUBSTITUTE(SUBSTITUTE(SUBSTITUTE(SUBSTITUTE(SUBSTITUTE(SUBSTITUTE(SUBSTITUTE(SUBSTITUTE(SUBSTITUTE(SUBSTITUTE(SUBSTITUTE(SUBSTITUTE(SUBSTITUTE(SUBSTITUTE(SUBSTITUTE(SUBSTITUTE(SUBSTITUTE(SUBSTITUTE(UPPER(_xlpm.a)," ",""),"CONTROL","CTRL"),"CTL","CTRL"),"ESCAPE","ESC"),"RETURN","ENTER"),"PAGEDOWN","PGDN"),"PGDOWN","PGDN"),"PAGEUP","PGUP"),"ARROWKEYS","ARROW"),"ARROWKEY","ARROW"),"ARROWS","ARROW"),"DOWNARROW","DOWN"),"UPARROW","UP"),"LEFTARROW","LEFT"),"RIGHTARROW","RIGHT"),"ARROWDOWN","DOWN"),"ARROWUP","UP"),"ARROWLEFT","LEFT"),"ARROWRIGHT","RIGHT"),"↓","DOWN"),"↑","UP"),"←","LEFT"),"→","RIGHT"),"SPACEBAR","SPACE"),"−","-"),"MINUS","-"),"PLUS","+")=Key!$E$16:$E$16),"✔ CLEAR","✘ TRY AGAIN"))),"✘ TRY AGAIN")} | F12: {=IF(E12="Show hint",Key!$B$16,"")} | G12: {=IF(LEFT(D12,1)="✔",IF(E12="Show hint",5,10),0)} -> 0
A13: G7 | B13: Which function returns the position of text, matching case? (from F5-3 Find the Gem) | D13: {=IFERROR(_xlfn.LET(_xlpm.a,'R2 Formula Gauntlet'!$C$13,IF(TRIM(_xlpm.a&"")="","",IF(OR(SUBSTITUTE(SUBSTITUTE(SUBSTITUTE(SUBSTITUTE(SUBSTITUTE(SUBSTITUTE(SUBSTITUTE(SUBSTITUTE(SUBSTITUTE(SUBSTITUTE(SUBSTITUTE(SUBSTITUTE(SUBSTITUTE(SUBSTITUTE(SUBSTITUTE(SUBSTITUTE(SUBSTITUTE(SUBSTITUTE(SUBSTITUTE(SUBSTITUTE(SUBSTITUTE(SUBSTITUTE(SUBSTITUTE(SUBSTITUTE(SUBSTITUTE(SUBSTITUTE(SUBSTITUTE(UPPER(_xlpm.a)," ",""),"CONTROL","CTRL"),"CTL","CTRL"),"ESCAPE","ESC"),"RETURN","ENTER"),"PAGEDOWN","PGDN"),"PGDOWN","PGDN"),"PAGEUP","PGUP"),"ARROWKEYS","ARROW"),"ARROWKEY","ARROW"),"ARROWS","ARROW"),"DOWNARROW","DOWN"),"UPARROW","UP"),"LEFTARROW","LEFT"),"RIGHTARROW","RIGHT"),"ARROWDOWN","DOWN"),"ARROWUP","UP"),"ARROWLEFT","LEFT"),"ARROWRIGHT","RIGHT"),"↓","DOWN"),"↑","UP"),"←","LEFT"),"→","RIGHT"),"SPACEBAR","SPACE"),"−","-"),"MINUS","-"),"PLUS","+")=Key!$E$17:$J$17),"✔ CLEAR","✘ TRY AGAIN"))),"✘ TRY AGAIN")} | F13: {=IF(E13="Show hint",Key!$B$17,"")} | G13: {=IF(LEFT(D13,1)="✔",IF(E13="Show hint",5,10),0)} -> 0
A14: G8 | B14: Which function returns a position while ignoring case? (from F5-3 Find the Gem) | D14: {=IFERROR(_xlfn.LET(_xlpm.a,'R2 Formula Gauntlet'!$C$14,IF(TRIM(_xlpm.a&"")="","",IF(OR(SUBSTITUTE(SUBSTITUTE(SUBSTITUTE(SUBSTITUTE(SUBSTITUTE(SUBSTITUTE(SUBSTITUTE(SUBSTITUTE(SUBSTITUTE(SUBSTITUTE(SUBSTITUTE(SUBSTITUTE(SUBSTITUTE(SUBSTITUTE(SUBSTITUTE(SUBSTITUTE(SUBSTITUTE(SUBSTITUTE(SUBSTITUTE(SUBSTITUTE(SUBSTITUTE(SUBSTITUTE(SUBSTITUTE(SUBSTITUTE(SUBSTITUTE(SUBSTITUTE(SUBSTITUTE(UPPER(_xlpm.a)," ",""),"CONTROL","CTRL"),"CTL","CTRL"),"ESCAPE","ESC"),"RETURN","ENTER"),"PAGEDOWN","PGDN"),"PGDOWN","PGDN"),"PAGEUP","PGUP"),"ARROWKEYS","ARROW"),"ARROWKEY","ARROW"),"ARROWS","ARROW"),"DOWNARROW","DOWN"),"UPARROW","UP"),"LEFTARROW","LEFT"),"RIGHTARROW","RIGHT"),"ARROWDOWN","DOWN"),"ARROWUP","UP"),"ARROWLEFT","LEFT"),"ARROWRIGHT","RIGHT"),"↓","DOWN"),"↑","UP"),"←","LEFT"),"→","RIGHT"),"SPACEBAR","SPACE"),"−","-"),"MINUS","-"),"PLUS","+")=Key!$E$18:$J$18),"✔ CLEAR","✘ TRY AGAIN"))),"✘ TRY AGAIN")} | F14: {=IF(E14="Show hint",Key!$B$18,"")} | G14: {=IF(LEFT(D14,1)="✔",IF(E14="Show hint",5,10),0)} -> 0
A15: G9 | B15: Which function supplies the cut position inside =LEFT(A2, ____("@",A2)-1)? (from F5-3 Find the Gem) | D15: {=IFERROR(_xlfn.LET(_xlpm.a,'R2 Formula Gauntlet'!$C$15,IF(TRIM(_xlpm.a&"")="","",IF(OR(SUBSTITUTE(SUBSTITUTE(SUBSTITUTE(SUBSTITUTE(SUBSTITUTE(SUBSTITUTE(SUBSTITUTE(SUBSTITUTE(SUBSTITUTE(SUBSTITUTE(SUBSTITUTE(SUBSTITUTE(SUBSTITUTE(SUBSTITUTE(SUBSTITUTE(SUBSTITUTE(SUBSTITUTE(SUBSTITUTE(SUBSTITUTE(SUBSTITUTE(SUBSTITUTE(SUBSTITUTE(SUBSTITUTE(SUBSTITUTE(SUBSTITUTE(SUBSTITUTE(SUBSTITUTE(UPPER(_xlpm.a)," ",""),"CONTROL","CTRL"),"CTL","CTRL"),"ESCAPE","ESC"),"RETURN","ENTER"),"PAGEDOWN","PGDN"),"PGDOWN","PGDN"),"PAGEUP","PGUP"),"ARROWKEYS","ARROW"),"ARROWKEY","ARROW"),"ARROWS","ARROW"),"DOWNARROW","DOWN"),"UPARROW","UP"),"LEFTARROW","LEFT"),"RIGHTARROW","RIGHT"),"ARROWDOWN","DOWN"),"ARROWUP","UP"),"ARROWLEFT","LEFT"),"ARROWRIGHT","RIGHT"),"↓","DOWN"),"↑","UP"),"←","LEFT"),"→","RIGHT"),"SPACEBAR","SPACE"),"−","-"),"MINUS","-"),"PLUS","+")=Key!$E$19:$E$19),"✔ CLEAR","✘ TRY AGAIN"))),"✘ TRY AGAIN")} | F15: {=IF(E15="Show hint",Key!$B$19,"")} | G15: {=IF(LEFT(D15,1)="✔",IF(E15="Show hint",5,10),0)} -> 0
A16: G10 | B16: Which function joins a range of text with a delimiter? (from F5-4 Assemble) | D16: {=IFERROR(_xlfn.LET(_xlpm.a,'R2 Formula Gauntlet'!$C$16,IF(TRIM(_xlpm.a&"")="","",IF(OR(SUBSTITUTE(SUBSTITUTE(SUBSTITUTE(SUBSTITUTE(SUBSTITUTE(SUBSTITUTE(SUBSTITUTE(SUBSTITUTE(SUBSTITUTE(SUBSTITUTE(SUBSTITUTE(SUBSTITUTE(SUBSTITUTE(SUBSTITUTE(SUBSTITUTE(SUBSTITUTE(SUBSTITUTE(SUBSTITUTE(SUBSTITUTE(SUBSTITUTE(SUBSTITUTE(SUBSTITUTE(SUBSTITUTE(SUBSTITUTE(SUBSTITUTE(SUBSTITUTE(SUBSTITUTE(UPPER(_xlpm.a)," ",""),"CONTROL","CTRL"),"CTL","CTRL"),"ESCAPE","ESC"),"RETURN","ENTER"),"PAGEDOWN","PGDN"),"PGDOWN","PGDN"),"PAGEUP","PGUP"),"ARROWKEYS","ARROW"),"ARROWKEY","ARROW"),"ARROWS","ARROW"),"DOWNARROW","DOWN"),"UPARROW","UP"),"LEFTARROW","LEFT"),"RIGHTARROW","RIGHT"),"ARROWDOWN","DOWN"),"ARROWUP","UP"),"ARROWLEFT","LEFT"),"ARROWRIGHT","RIGHT"),"↓","DOWN"),"↑","UP"),"←","LEFT"),"→","RIGHT"),"SPACEBAR","SPACE"),"−","-"),"MINUS","-"),"PLUS","+")=Key!$E$20:$J$20),"✔ CLEAR","✘ TRY AGAIN"))),"✘ TRY AGAIN")} | F16: {=IF(E16="Show hint",Key!$B$20,"")} | G16: {=IF(LEFT(D16,1)="✔",IF(E16="Show hint",5,10),0)} -> 0
A17: G11 | B17: Which function turns a number or date into formatted text? (from F5-4 Assemble) | D17: {=IFERROR(_xlfn.LET(_xlpm.a,'R2 Formula Gauntlet'!$C$17,IF(TRIM(_xlpm.a&"")="","",IF(OR(SUBSTITUTE(SUBSTITUTE(SUBSTITUTE(SUBSTITUTE(SUBSTITUTE(SUBSTITUTE(SUBSTITUTE(SUBSTITUTE(SUBSTITUTE(SUBSTITUTE(SUBSTITUTE(SUBSTITUTE(SUBSTITUTE(SUBSTITUTE(SUBSTITUTE(SUBSTITUTE(SUBSTITUTE(SUBSTITUTE(SUBSTITUTE(SUBSTITUTE(SUBSTITUTE(SUBSTITUTE(SUBSTITUTE(SUBSTITUTE(SUBSTITUTE(SUBSTITUTE(SUBSTITUTE(UPPER(_xlpm.a)," ",""),"CONTROL","CTRL"),"CTL","CTRL"),"ESCAPE","ESC"),"RETURN","ENTER"),"PAGEDOWN","PGDN"),"PGDOWN","PGDN"),"PAGEUP","PGUP"),"ARROWKEYS","ARROW"),"ARROWKEY","ARROW"),"ARROWS","ARROW"),"DOWNARROW","DOWN"),"UPARROW","UP"),"LEFTARROW","LEFT"),"RIGHTARROW","RIGHT"),"ARROWDOWN","DOWN"),"ARROWUP","UP"),"ARROWLEFT","LEFT"),"ARROWRIGHT","RIGHT"),"↓","DOWN"),"↑","UP"),"←","LEFT"),"→","RIGHT"),"SPACEBAR","SPACE"),"−","-"),"MINUS","-"),"PLUS","+")=Key!$E$21:$J$21),"✔ CLEAR","✘ TRY AGAIN"))),"✘ TRY AGAIN")} | F17: {=IF(E17="Show hint",Key!$B$21,"")} | G17: {=IF(LEFT(D17,1)="✔",IF(E17="Show hint",5,10),0)} -> 0
A18: G12 | B18: Which function turns text that looks like a number into a number? (from F5-4 Assemble) | D18: {=IFERROR(_xlfn.LET(_xlpm.a,'R2 Formula Gauntlet'!$C$18,IF(TRIM(_xlpm.a&"")="","",IF(OR(SUBSTITUTE(SUBSTITUTE(SUBSTITUTE(SUBSTITUTE(SUBSTITUTE(SUBSTITUTE(SUBSTITUTE(SUBSTITUTE(SUBSTITUTE(SUBSTITUTE(SUBSTITUTE(SUBSTITUTE(SUBSTITUTE(SUBSTITUTE(SUBSTITUTE(SUBSTITUTE(SUBSTITUTE(SUBSTITUTE(SUBSTITUTE(SUBSTITUTE(SUBSTITUTE(SUBSTITUTE(SUBSTITUTE(SUBSTITUTE(SUBSTITUTE(SUBSTITUTE(SUBSTITUTE(UPPER(_xlpm.a)," ",""),"CONTROL","CTRL"),"CTL","CTRL"),"ESCAPE","ESC"),"RETURN","ENTER"),"PAGEDOWN","PGDN"),"PGDOWN","PGDN"),"PAGEUP","PGUP"),"ARROWKEYS","ARROW"),"ARROWKEY","ARROW"),"ARROWS","ARROW"),"DOWNARROW","DOWN"),"UPARROW","UP"),"LEFTARROW","LEFT"),"RIGHTARROW","RIGHT"),"ARROWDOWN","DOWN"),"ARROWUP","UP"),"ARROWLEFT","LEFT"),"ARROWRIGHT","RIGHT"),"↓","DOWN"),"↑","UP"),"←","LEFT"),"→","RIGHT"),"SPACEBAR","SPACE"),"−","-"),"MINUS","-"),"PLUS","+")=Key!$E$22:$J$22),"✔ CLEAR","✘ TRY AGAIN"))),"✘ TRY AGAIN")} | F18: {=IF(E18="Show hint",Key!$B$22,"")} | G18: {=IF(LEFT(D18,1)="✔",IF(E18="Show hint",5,10),0)} -> 0
A19: G13 | B19: Which function returns today's date? (from F6-1 Calendar) | D19: {=IFERROR(_xlfn.LET(_xlpm.a,'R2 Formula Gauntlet'!$C$19,IF(TRIM(_xlpm.a&"")="","",IF(OR(SUBSTITUTE(SUBSTITUTE(SUBSTITUTE(SUBSTITUTE(SUBSTITUTE(SUBSTITUTE(SUBSTITUTE(SUBSTITUTE(SUBSTITUTE(SUBSTITUTE(SUBSTITUTE(SUBSTITUTE(SUBSTITUTE(SUBSTITUTE(SUBSTITUTE(SUBSTITUTE(SUBSTITUTE(SUBSTITUTE(SUBSTITUTE(SUBSTITUTE(SUBSTITUTE(SUBSTITUTE(SUBSTITUTE(SUBSTITUTE(SUBSTITUTE(SUBSTITUTE(SUBSTITUTE(UPPER(_xlpm.a)," ",""),"CONTROL","CTRL"),"CTL","CTRL"),"ESCAPE","ESC"),"RETURN","ENTER"),"PAGEDOWN","PGDN"),"PGDOWN","PGDN"),"PAGEUP","PGUP"),"ARROWKEYS","ARROW"),"ARROWKEY","ARROW"),"ARROWS","ARROW"),"DOWNARROW","DOWN"),"UPARROW","UP"),"LEFTARROW","LEFT"),"RIGHTARROW","RIGHT"),"ARROWDOWN","DOWN"),"ARROWUP","UP"),"ARROWLEFT","LEFT"),"ARROWRIGHT","RIGHT"),"↓","DOWN"),"↑","UP"),"←","LEFT"),"→","RIGHT"),"SPACEBAR","SPACE"),"−","-"),"MINUS","-"),"PLUS","+")=Key!$E$23:$J$23),"✔ CLEAR","✘ TRY AGAIN"))),"✘ TRY AGAIN")} | F19: {=IF(E19="Show hint",Key!$B$23,"")} | G19: {=IF(LEFT(D19,1)="✔",IF(E19="Show hint",5,10),0)} -> 0
A20: G14 | B20: Which function returns the current date and time? (from F6-1 Calendar) | D20: {=IFERROR(_xlfn.LET(_xlpm.a,'R2 Formula Gauntlet'!$C$20,IF(TRIM(_xlpm.a&"")="","",IF(OR(SUBSTITUTE(SUBSTITUTE(SUBSTITUTE(SUBSTITUTE(SUBSTITUTE(SUBSTITUTE(SUBSTITUTE(SUBSTITUTE(SUBSTITUTE(SUBSTITUTE(SUBSTITUTE(SUBSTITUTE(SUBSTITUTE(SUBSTITUTE(SUBSTITUTE(SUBSTITUTE(SUBSTITUTE(SUBSTITUTE(SUBSTITUTE(SUBSTITUTE(SUBSTITUTE(SUBSTITUTE(SUBSTITUTE(SUBSTITUTE(SUBSTITUTE(SUBSTITUTE(SUBSTITUTE(UPPER(_xlpm.a)," ",""),"CONTROL","CTRL"),"CTL","CTRL"),"ESCAPE","ESC"),"RETURN","ENTER"),"PAGEDOWN","PGDN"),"PGDOWN","PGDN"),"PAGEUP","PGUP"),"ARROWKEYS","ARROW"),"ARROWKEY","ARROW"),"ARROWS","ARROW"),"DOWNARROW","DOWN"),"UPARROW","UP"),"LEFTARROW","LEFT"),"RIGHTARROW","RIGHT"),"ARROWDOWN","DOWN"),"ARROWUP","UP"),"ARROWLEFT","LEFT"),"ARROWRIGHT","RIGHT"),"↓","DOWN"),"↑","UP"),"←","LEFT"),"→","RIGHT"),"SPACEBAR","SPACE"),"−","-"),"MINUS","-"),"PLUS","+")=Key!$E$24:$J$24),"✔ CLEAR","✘ TRY AGAIN"))),"✘ TRY AGAIN")} | F20: {=IF(E20="Show hint",Key!$B$24,"")} | G20: {=IF(LEFT(D20,1)="✔",IF(E20="Show hint",5,10),0)} -> 0
A21: G15 | B21: Which function builds a date from a year, month and day? (from F6-1 Calendar) | D21: {=IFERROR(_xlfn.LET(_xlpm.a,'R2 Formula Gauntlet'!$C$21,IF(TRIM(_xlpm.a&"")="","",IF(OR(SUBSTITUTE(SUBSTITUTE(SUBSTITUTE(SUBSTITUTE(SUBSTITUTE(SUBSTITUTE(SUBSTITUTE(SUBSTITUTE(SUBSTITUTE(SUBSTITUTE(SUBSTITUTE(SUBSTITUTE(SUBSTITUTE(SUBSTITUTE(SUBSTITUTE(SUBSTITUTE(SUBSTITUTE(SUBSTITUTE(SUBSTITUTE(SUBSTITUTE(SUBSTITUTE(SUBSTITUTE(SUBSTITUTE(SUBSTITUTE(SUBSTITUTE(SUBSTITUTE(SUBSTITUTE(UPPER(_xlpm.a)," ",""),"CONTROL","CTRL"),"CTL","CTRL"),"ESCAPE","ESC"),"RETURN","ENTER"),"PAGEDOWN","PGDN"),"PGDOWN","PGDN"),"PAGEUP","PGUP"),"ARROWKEYS","ARROW"),"ARROWKEY","ARROW"),"ARROWS","ARROW"),"DOWNARROW","DOWN"),"UPARROW","UP"),"LEFTARROW","LEFT"),"RIGHTARROW","RIGHT"),"ARROWDOWN","DOWN"),"ARROWUP","UP"),"ARROWLEFT","LEFT"),"ARROWRIGHT","RIGHT"),"↓","DOWN"),"↑","UP"),"←","LEFT"),"→","RIGHT"),"SPACEBAR","SPACE"),"−","-"),"MINUS","-"),"PLUS","+")=Key!$E$25:$J$25),"✔ CLEAR","✘ TRY AGAIN"))),"✘ TRY AGAIN")} | F21: {=IF(E21="Show hint",Key!$B$25,"")} | G21: {=IF(LEFT(D21,1)="✔",IF(E21="Show hint",5,10),0)} -> 0
A22: G16 | B22: Which function returns the year of a date? (from F6-1 Calendar) | D22: {=IFERROR(_xlfn.LET(_xlpm.a,'R2 Formula Gauntlet'!$C$22,IF(TRIM(_xlpm.a&"")="","",IF(OR(SUBSTITUTE(SUBSTITUTE(SUBSTITUTE(SUBSTITUTE(SUBSTITUTE(SUBSTITUTE(SUBSTITUTE(SUBSTITUTE(SUBSTITUTE(SUBSTITUTE(SUBSTITUTE(SUBSTITUTE(SUBSTITUTE(SUBSTITUTE(SUBSTITUTE(SUBSTITUTE(SUBSTITUTE(SUBSTITUTE(SUBSTITUTE(SUBSTITUTE(SUBSTITUTE(SUBSTITUTE(SUBSTITUTE(SUBSTITUTE(SUBSTITUTE(SUBSTITUTE(SUBSTITUTE(UPPER(_xlpm.a)," ",""),"CONTROL","CTRL"),"CTL","CTRL"),"ESCAPE","ESC"),"RETURN","ENTER"),"PAGEDOWN","PGDN"),"PGDOWN","PGDN"),"PAGEUP","PGUP"),"ARROWKEYS","ARROW"),"ARROWKEY","ARROW"),"ARROWS","ARROW"),"DOWNARROW","DOWN"),"UPARROW","UP"),"LEFTARROW","LEFT"),"RIGHTARROW","RIGHT"),"ARROWDOWN","DOWN"),"ARROWUP","UP"),"ARROWLEFT","LEFT"),"ARROWRIGHT","RIGHT"),"↓","DOWN"),"↑","UP"),"←","LEFT"),"→","RIGHT"),"SPACEBAR","SPACE"),"−","-"),"MINUS","-"),"PLUS","+")=Key!$E$26:$J$26),"✔ CLEAR","✘ TRY AGAIN"))),"✘ TRY AGAIN")} | F22: {=IF(E22="Show hint",Key!$B$26,"")} | G22: {=IF(LEFT(D22,1)="✔",IF(E22="Show hint",5,10),0)} -> 0
A23: G17 | B23: Which function returns the month number of a date? (from F6-1 Calendar) | D23: {=IFERROR(_xlfn.LET(_xlpm.a,'R2 Formula Gauntlet'!$C$23,IF(TRIM(_xlpm.a&"")="","",IF(OR(SUBSTITUTE(SUBSTITUTE(SUBSTITUTE(SUBSTITUTE(SUBSTITUTE(SUBSTITUTE(SUBSTITUTE(SUBSTITUTE(SUBSTITUTE(SUBSTITUTE(SUBSTITUTE(SUBSTITUTE(SUBSTITUTE(SUBSTITUTE(SUBSTITUTE(SUBSTITUTE(SUBSTITUTE(SUBSTITUTE(SUBSTITUTE(SUBSTITUTE(SUBSTITUTE(SUBSTITUTE(SUBSTITUTE(SUBSTITUTE(SUBSTITUTE(SUBSTITUTE(SUBSTITUTE(UPPER(_xlpm.a)," ",""),"CONTROL","CTRL"),"CTL","CTRL"),"ESCAPE","ESC"),"RETURN","ENTER"),"PAGEDOWN","PGDN"),"PGDOWN","PGDN"),"PAGEUP","PGUP"),"ARROWKEYS","ARROW"),"ARROWKEY","ARROW"),"ARROWS","ARROW"),"DOWNARROW","DOWN"),"UPARROW","UP"),"LEFTARROW","LEFT"),"RIGHTARROW","RIGHT"),"ARROWDOWN","DOWN"),"ARROWUP","UP"),"ARROWLEFT","LEFT"),"ARROWRIGHT","RIGHT"),"↓","DOWN"),"↑","UP"),"←","LEFT"),"→","RIGHT"),"SPACEBAR","SPACE"),"−","-"),"MINUS","-"),"PLUS","+")=Key!$E$27:$J$27),"✔ CLEAR","✘ TRY AGAIN"))),"✘ TRY AGAIN")} | F23: {=IF(E23="Show hint",Key!$B$27,"")} | G23: {=IF(LEFT(D23,1)="✔",IF(E23="Show hint",5,10),0)} -> 0
A24: G18 | B24: Which function returns the day of the month? (from F6-1 Calendar) | D24: {=IFERROR(_xlfn.LET(_xlpm.a,'R2 Formula Gauntlet'!$C$24,IF(TRIM(_xlpm.a&"")="","",IF(OR(SUBSTITUTE(SUBSTITUTE(SUBSTITUTE(SUBSTITUTE(SUBSTITUTE(SUBSTITUTE(SUBSTITUTE(SUBSTITUTE(SUBSTITUTE(SUBSTITUTE(SUBSTITUTE(SUBSTITUTE(SUBSTITUTE(SUBSTITUTE(SUBSTITUTE(SUBSTITUTE(SUBSTITUTE(SUBSTITUTE(SUBSTITUTE(SUBSTITUTE(SUBSTITUTE(SUBSTITUTE(SUBSTITUTE(SUBSTITUTE(SUBSTITUTE(SUBSTITUTE(SUBSTITUTE(UPPER(_xlpm.a)," ",""),"CONTROL","CTRL"),"CTL","CTRL"),"ESCAPE","ESC"),"RETURN","ENTER"),"PAGEDOWN","PGDN"),"PGDOWN","PGDN"),"PAGEUP","PGUP"),"ARROWKEYS","ARROW"),"ARROWKEY","ARROW"),"ARROWS","ARROW"),"DOWNARROW","DOWN"),"UPARROW","UP"),"LEFTARROW","LEFT"),"RIGHTARROW","RIGHT"),"ARROWDOWN","DOWN"),"ARROWUP","UP"),"ARROWLEFT","LEFT"),"ARROWRIGHT","RIGHT"),"↓","DOWN"),"↑","UP"),"←","LEFT"),"→","RIGHT"),"SPACEBAR","SPACE"),"−","-"),"MINUS","-"),"PLUS","+")=Key!$E$28:$J$28),"✔ CLEAR","✘ TRY AGAIN"))),"✘ TRY AGAIN")} | F24: {=IF(E24="Show hint",Key!$B$28,"")} | G24: {=IF(LEFT(D24,1)="✔",IF(E24="Show hint",5,10),0)} -> 0
A25: G19 | B25: Which function returns the day of the week as a number? (from F6-1 Calendar) | D25: {=IFERROR(_xlfn.LET(_xlpm.a,'R2 Formula Gauntlet'!$C$25,IF(TRIM(_xlpm.a&"")="","",IF(OR(SUBSTITUTE(SUBSTITUTE(SUBSTITUTE(SUBSTITUTE(SUBSTITUTE(SUBSTITUTE(SUBSTITUTE(SUBSTITUTE(SUBSTITUTE(SUBSTITUTE(SUBSTITUTE(SUBSTITUTE(SUBSTITUTE(SUBSTITUTE(SUBSTITUTE(SUBSTITUTE(SUBSTITUTE(SUBSTITUTE(SUBSTITUTE(SUBSTITUTE(SUBSTITUTE(SUBSTITUTE(SUBSTITUTE(SUBSTITUTE(SUBSTITUTE(SUBSTITUTE(SUBSTITUTE(UPPER(_xlpm.a)," ",""),"CONTROL","CTRL"),"CTL","CTRL"),"ESCAPE","ESC"),"RETURN","ENTER"),"PAGEDOWN","PGDN"),"PGDOWN","PGDN"),"PAGEUP","PGUP"),"ARROWKEYS","ARROW"),"ARROWKEY","ARROW"),"ARROWS","ARROW"),"DOWNARROW","DOWN"),"UPARROW","UP"),"LEFTARROW","LEFT"),"RIGHTARROW","RIGHT"),"ARROWDOWN","DOWN"),"ARROWUP","UP"),"ARROWLEFT","LEFT"),"ARROWRIGHT","RIGHT"),"↓","DOWN"),"↑","UP"),"←","LEFT"),"→","RIGHT"),"SPACEBAR","SPACE"),"−","-"),"MINUS","-"),"PLUS","+")=Key!$E$29:$J$29),"✔ CLEAR","✘ TRY AGAIN"))),"✘ TRY AGAIN")} | F25: {=IF(E25="Show hint",Key!$B$29,"")} | G25: {=IF(LEFT(D25,1)="✔",IF(E25="Show hint",5,10),0)} -> 0
A26: G20 | B26: What do you get when you subtract an earlier date from a later one (one word)? (from F6-2 Date Math) | D26: {=IFERROR(_xlfn.LET(_xlpm.a,'R2 Formula Gauntlet'!$C$26,IF(TRIM(_xlpm.a&"")="","",IF(OR(SUBSTITUTE(SUBSTITUTE(SUBSTITUTE(SUBSTITUTE(SUBSTITUTE(SUBSTITUTE(SUBSTITUTE(SUBSTITUTE(SUBSTITUTE(SUBSTITUTE(SUBSTITUTE(SUBSTITUTE(SUBSTITUTE(SUBSTITUTE(SUBSTITUTE(SUBSTITUTE(SUBSTITUTE(SUBSTITUTE(SUBSTITUTE(SUBSTITUTE(SUBSTITUTE(SUBSTITUTE(SUBSTITUTE(SUBSTITUTE(SUBSTITUTE(SUBSTITUTE(SUBSTITUTE(UPPER(_xlpm.a)," ",""),"CONTROL","CTRL"),"CTL","CTRL"),"ESCAPE","ESC"),"RETURN","ENTER"),"PAGEDOWN","PGDN"),"PGDOWN","PGDN"),"PAGEUP","PGUP"),"ARROWKEYS","ARROW"),"ARROWKEY","ARROW"),"ARROWS","ARROW"),"DOWNARROW","DOWN"),"UPARROW","UP"),"LEFTARROW","LEFT"),"RIGHTARROW","RIGHT"),"ARROWDOWN","DOWN"),"ARROWUP","UP"),"ARROWLEFT","LEFT"),"ARROWRIGHT","RIGHT"),"↓","DOWN"),"↑","UP"),"←","LEFT"),"→","RIGHT"),"SPACEBAR","SPACE"),"−","-"),"MINUS","-"),"PLUS","+")=Key!$E$30:$F$30),"✔ CLEAR","✘ TRY AGAIN"))),"✘ TRY AGAIN")} | F26: {=IF(E26="Show hint",Key!$B$30,"")} | G26: {=IF(LEFT(D26,1)="✔",IF(E26="Show hint",5,10),0)} -> 0
A27: G21 | B27: Type the formula for the date 30 days after the date in B6. (from F6-2 Date Math) | D27: {=IFERROR(_xlfn.LET(_xlpm.a,'R2 Formula Gauntlet'!$C$27,IF(TRIM(_xlpm.a&"")="","",IF(OR(SUBSTITUTE(SUBSTITUTE(SUBSTITUTE(SUBSTITUTE(SUBSTITUTE(SUBSTITUTE(SUBSTITUTE(SUBSTITUTE(SUBSTITUTE(SUBSTITUTE(SUBSTITUTE(SUBSTITUTE(SUBSTITUTE(SUBSTITUTE(SUBSTITUTE(SUBSTITUTE(SUBSTITUTE(SUBSTITUTE(SUBSTITUTE(SUBSTITUTE(SUBSTITUTE(SUBSTITUTE(SUBSTITUTE(SUBSTITUTE(SUBSTITUTE(SUBSTITUTE(SUBSTITUTE(UPPER(_xlpm.a)," ",""),"CONTROL","CTRL"),"CTL","CTRL"),"ESCAPE","ESC"),"RETURN","ENTER"),"PAGEDOWN","PGDN"),"PGDOWN","PGDN"),"PAGEUP","PGUP"),"ARROWKEYS","ARROW"),"ARROWKEY","ARROW"),"ARROWS","ARROW"),"DOWNARROW","DOWN"),"UPARROW","UP"),"LEFTARROW","LEFT"),"RIGHTARROW","RIGHT"),"ARROWDOWN","DOWN"),"ARROWUP","UP"),"ARROWLEFT","LEFT"),"ARROWRIGHT","RIGHT"),"↓","DOWN"),"↑","UP"),"←","LEFT"),"→","RIGHT"),"SPACEBAR","SPACE"),"−","-"),"MINUS","-"),"PLUS","+")=Key!$E$31:$H$31),"✔ CLEAR","✘ TRY AGAIN"))),"✘ TRY AGAIN")} | F27: {=IF(E27="Show hint",Key!$B$31,"")} | G27: {=IF(LEFT(D27,1)="✔",IF(E27="Show hint",5,10),0)} -> 0
A28: G22 | B28: Which function counts full years or months between two dates? (from F6-2 Date Math) | D28: {=IFERROR(_xlfn.LET(_xlpm.a,'R2 Formula Gauntlet'!$C$28,IF(TRIM(_xlpm.a&"")="","",IF(OR(SUBSTITUTE(SUBSTITUTE(SUBSTITUTE(SUBSTITUTE(SUBSTITUTE(SUBSTITUTE(SUBSTITUTE(SUBSTITUTE(SUBSTITUTE(SUBSTITUTE(SUBSTITUTE(SUBSTITUTE(SUBSTITUTE(SUBSTITUTE(SUBSTITUTE(SUBSTITUTE(SUBSTITUTE(SUBSTITUTE(SUBSTITUTE(SUBSTITUTE(SUBSTITUTE(SUBSTITUTE(SUBSTITUTE(SUBSTITUTE(SUBSTITUTE(SUBSTITUTE(SUBSTITUTE(UPPER(_xlpm.a)," ",""),"CONTROL","CTRL"),"CTL","CTRL"),"ESCAPE","ESC"),"RETURN","ENTER"),"PAGEDOWN","PGDN"),"PGDOWN","PGDN"),"PAGEUP","PGUP"),"ARROWKEYS","ARROW"),"ARROWKEY","ARROW"),"ARROWS","ARROW"),"DOWNARROW","DOWN"),"UPARROW","UP"),"LEFTARROW","LEFT"),"RIGHTARROW","RIGHT"),"ARROWDOWN","DOWN"),"ARROWUP","UP"),"ARROWLEFT","LEFT"),"ARROWRIGHT","RIGHT"),"↓","DOWN"),"↑","UP"),"←","LEFT"),"→","RIGHT"),"SPACEBAR","SPACE"),"−","-"),"MINUS","-"),"PLUS","+")=Key!$E$32:$J$32),"✔ CLEAR","✘ TRY AGAIN"))),"✘ TRY AGAIN")} | F28: {=IF(E28="Show hint",Key!$B$32,"")} | G28: {=IF(LEFT(D28,1)="✔",IF(E28="Show hint",5,10),0)} -> 0
A29: G23 | B29: Which function moves a date forward or back by whole months? (from F6-3 Deadlines) | D29: {=IFERROR(_xlfn.LET(_xlpm.a,'R2 Formula Gauntlet'!$C$29,IF(TRIM(_xlpm.a&"")="","",IF(OR(SUBSTITUTE(SUBSTITUTE(SUBSTITUTE(SUBSTITUTE(SUBSTITUTE(SUBSTITUTE(SUBSTITUTE(SUBSTITUTE(SUBSTITUTE(SUBSTITUTE(SUBSTITUTE(SUBSTITUTE(SUBSTITUTE(SUBSTITUTE(SUBSTITUTE(SUBSTITUTE(SUBSTITUTE(SUBSTITUTE(SUBSTITUTE(SUBSTITUTE(SUBSTITUTE(SUBSTITUTE(SUBSTITUTE(SUBSTITUTE(SUBSTITUTE(SUBSTITUTE(SUBSTITUTE(UPPER(_xlpm.a)," ",""),"CONTROL","CTRL"),"CTL","CTRL"),"ESCAPE","ESC"),"RETURN","ENTER"),"PAGEDOWN","PGDN"),"PGDOWN","PGDN"),"PAGEUP","PGUP"),"ARROWKEYS","ARROW"),"ARROWKEY","ARROW"),"ARROWS","ARROW"),"DOWNARROW","DOWN"),"UPARROW","UP"),"LEFTARROW","LEFT"),"RIGHTARROW","RIGHT"),"ARROWDOWN","DOWN"),"ARROWUP","UP"),"ARROWLEFT","LEFT"),"ARROWRIGHT","RIGHT"),"↓","DOWN"),"↑","UP"),"←","LEFT"),"→","RIGHT"),"SPACEBAR","SPACE"),"−","-"),"MINUS","-"),"PLUS","+")=Key!$E$33:$J$33),"✔ CLEAR","✘ TRY AGAIN"))),"✘ TRY AGAIN")} | F29: {=IF(E29="Show hint",Key!$B$33,"")} | G29: {=IF(LEFT(D29,1)="✔",IF(E29="Show hint",5,10),0)} -> 0
A30: G24 | B30: Which function returns the last day of a month? (from F6-3 Deadlines) | D30: {=IFERROR(_xlfn.LET(_xlpm.a,'R2 Formula Gauntlet'!$C$30,IF(TRIM(_xlpm.a&"")="","",IF(OR(SUBSTITUTE(SUBSTITUTE(SUBSTITUTE(SUBSTITUTE(SUBSTITUTE(SUBSTITUTE(SUBSTITUTE(SUBSTITUTE(SUBSTITUTE(SUBSTITUTE(SUBSTITUTE(SUBSTITUTE(SUBSTITUTE(SUBSTITUTE(SUBSTITUTE(SUBSTITUTE(SUBSTITUTE(SUBSTITUTE(SUBSTITUTE(SUBSTITUTE(SUBSTITUTE(SUBSTITUTE(SUBSTITUTE(SUBSTITUTE(SUBSTITUTE(SUBSTITUTE(SUBSTITUTE(UPPER(_xlpm.a)," ",""),"CONTROL","CTRL"),"CTL","CTRL"),"ESCAPE","ESC"),"RETURN","ENTER"),"PAGEDOWN","PGDN"),"PGDOWN","PGDN"),"PAGEUP","PGUP"),"ARROWKEYS","ARROW"),"ARROWKEY","ARROW"),"ARROWS","ARROW"),"DOWNARROW","DOWN"),"UPARROW","UP"),"LEFTARROW","LEFT"),"RIGHTARROW","RIGHT"),"ARROWDOWN","DOWN"),"ARROWUP","UP"),"ARROWLEFT","LEFT"),"ARROWRIGHT","RIGHT"),"↓","DOWN"),"↑","UP"),"←","LEFT"),"→","RIGHT"),"SPACEBAR","SPACE"),"−","-"),"MINUS","-"),"PLUS","+")=Key!$E$34:$J$34),"✔ CLEAR","✘ TRY AGAIN"))),"✘ TRY AGAIN")} | F30: {=IF(E30="Show hint",Key!$B$34,"")} | G30: {=IF(LEFT(D30,1)="✔",IF(E30="Show hint",5,10),0)} -> 0
A31: G25 | B31: Which function counts the working days between two dates? (from F6-3 Deadlines) | D31: {=IFERROR(_xlfn.LET(_xlpm.a,'R2 Formula Gauntlet'!$C$31,IF(TRIM(_xlpm.a&"")="","",IF(OR(SUBSTITUTE(SUBSTITUTE(SUBSTITUTE(SUBSTITUTE(SUBSTITUTE(SUBSTITUTE(SUBSTITUTE(SUBSTITUTE(SUBSTITUTE(SUBSTITUTE(SUBSTITUTE(SUBSTITUTE(SUBSTITUTE(SUBSTITUTE(SUBSTITUTE(SUBSTITUTE(SUBSTITUTE(SUBSTITUTE(SUBSTITUTE(SUBSTITUTE(SUBSTITUTE(SUBSTITUTE(SUBSTITUTE(SUBSTITUTE(SUBSTITUTE(SUBSTITUTE(SUBSTITUTE(UPPER(_xlpm.a)," ",""),"CONTROL","CTRL"),"CTL","CTRL"),"ESCAPE","ESC"),"RETURN","ENTER"),"PAGEDOWN","PGDN"),"PGDOWN","PGDN"),"PAGEUP","PGUP"),"ARROWKEYS","ARROW"),"ARROWKEY","ARROW"),"ARROWS","ARROW"),"DOWNARROW","DOWN"),"UPARROW","UP"),"LEFTARROW","LEFT"),"RIGHTARROW","RIGHT"),"ARROWDOWN","DOWN"),"ARROWUP","UP"),"ARROWLEFT","LEFT"),"ARROWRIGHT","RIGHT"),"↓","DOWN"),"↑","UP"),"←","LEFT"),"→","RIGHT"),"SPACEBAR","SPACE"),"−","-"),"MINUS","-"),"PLUS","+")=Key!$E$35:$J$35),"✔ CLEAR","✘ TRY AGAIN"))),"✘ TRY AGAIN")} | F31: {=IF(E31="Show hint",Key!$B$35,"")} | G31: {=IF(LEFT(D31,1)="✔",IF(E31="Show hint",5,10),0)} -> 0
A32: G26 | B32: Which function returns the date a number of working days later? (from F6-3 Deadlines) | D32: {=IFERROR(_xlfn.LET(_xlpm.a,'R2 Formula Gauntlet'!$C$32,IF(TRIM(_xlpm.a&"")="","",IF(OR(SUBSTITUTE(SUBSTITUTE(SUBSTITUTE(SUBSTITUTE(SUBSTITUTE(SUBSTITUTE(SUBSTITUTE(SUBSTITUTE(SUBSTITUTE(SUBSTITUTE(SUBSTITUTE(SUBSTITUTE(SUBSTITUTE(SUBSTITUTE(SUBSTITUTE(SUBSTITUTE(SUBSTITUTE(SUBSTITUTE(SUBSTITUTE(SUBSTITUTE(SUBSTITUTE(SUBSTITUTE(SUBSTITUTE(SUBSTITUTE(SUBSTITUTE(SUBSTITUTE(SUBSTITUTE(UPPER(_xlpm.a)," ",""),"CONTROL","CTRL"),"CTL","CTRL"),"ESCAPE","ESC"),"RETURN","ENTER"),"PAGEDOWN","PGDN"),"PGDOWN","PGDN"),"PAGEUP","PGUP"),"ARROWKEYS","ARROW"),"ARROWKEY","ARROW"),"ARROWS","ARROW"),"DOWNARROW","DOWN"),"UPARROW","UP"),"LEFTARROW","LEFT"),"RIGHTARROW","RIGHT"),"ARROWDOWN","DOWN"),"ARROWUP","UP"),"ARROWLEFT","LEFT"),"ARROWRIGHT","RIGHT"),"↓","DOWN"),"↑","UP"),"←","LEFT"),"→","RIGHT"),"SPACEBAR","SPACE"),"−","-"),"MINUS","-"),"PLUS","+")=Key!$E$36:$J$36),"✔ CLEAR","✘ TRY AGAIN"))),"✘ TRY AGAIN")} | F32: {=IF(E32="Show hint",Key!$B$36,"")} | G32: {=IF(LEFT(D32,1)="✔",IF(E32="Show hint",5,10),0)} -> 0
A33: G27 | B33: What is it called when one formula's results flow into neighboring cells? (from F7-1 Spill Zone) | D33: {=IFERROR(_xlfn.LET(_xlpm.a,'R2 Formula Gauntlet'!$C$33,IF(TRIM(_xlpm.a&"")="","",IF(OR(SUBSTITUTE(SUBSTITUTE(SUBSTITUTE(SUBSTITUTE(SUBSTITUTE(SUBSTITUTE(SUBSTITUTE(SUBSTITUTE(SUBSTITUTE(SUBSTITUTE(SUBSTITUTE(SUBSTITUTE(SUBSTITUTE(SUBSTITUTE(SUBSTITUTE(SUBSTITUTE(SUBSTITUTE(SUBSTITUTE(SUBSTITUTE(SUBSTITUTE(SUBSTITUTE(SUBSTITUTE(SUBSTITUTE(SUBSTITUTE(SUBSTITUTE(SUBSTITUTE(SUBSTITUTE(UPPER(_xlpm.a)," ",""),"CONTROL","CTRL"),"CTL","CTRL"),"ESCAPE","ESC"),"RETURN","ENTER"),"PAGEDOWN","PGDN"),"PGDOWN","PGDN"),"PAGEUP","PGUP"),"ARROWKEYS","ARROW"),"ARROWKEY","ARROW"),"ARROWS","ARROW"),"DOWNARROW","DOWN"),"UPARROW","UP"),"LEFTARROW","LEFT"),"RIGHTARROW","RIGHT"),"ARROWDOWN","DOWN"),"ARROWUP","UP"),"ARROWLEFT","LEFT"),"ARROWRIGHT","RIGHT"),"↓","DOWN"),"↑","UP"),"←","LEFT"),"→","RIGHT"),"SPACEBAR","SPACE"),"−","-"),"MINUS","-"),"PLUS","+")=Key!$E$37:$G$37),"✔ CLEAR","✘ TRY AGAIN"))),"✘ TRY AGAIN")} | F33: {=IF(E33="Show hint",Key!$B$37,"")} | G33: {=IF(LEFT(D33,1)="✔",IF(E33="Show hint",5,10),0)} -> 0
A34: G28 | B34: Which error appears when a spill range is blocked? (from F7-1 Spill Zone) | D34: {=IFERROR(_xlfn.LET(_xlpm.a,'R2 Formula Gauntlet'!$C$34,IF(TRIM(_xlpm.a&"")="","",IF(OR(SUBSTITUTE(SUBSTITUTE(SUBSTITUTE(SUBSTITUTE(SUBSTITUTE(SUBSTITUTE(SUBSTITUTE(SUBSTITUTE(SUBSTITUTE(SUBSTITUTE(SUBSTITUTE(SUBSTITUTE(SUBSTITUTE(SUBSTITUTE(SUBSTITUTE(SUBSTITUTE(SUBSTITUTE(SUBSTITUTE(SUBSTITUTE(SUBSTITUTE(SUBSTITUTE(SUBSTITUTE(SUBSTITUTE(SUBSTITUTE(SUBSTITUTE(SUBSTITUTE(SUBSTITUTE(UPPER(_xlpm.a)," ",""),"CONTROL","CTRL"),"CTL","CTRL"),"ESCAPE","ESC"),"RETURN","ENTER"),"PAGEDOWN","PGDN"),"PGDOWN","PGDN"),"PAGEUP","PGUP"),"ARROWKEYS","ARROW"),"ARROWKEY","ARROW"),"ARROWS","ARROW"),"DOWNARROW","DOWN"),"UPARROW","UP"),"LEFTARROW","LEFT"),"RIGHTARROW","RIGHT"),"ARROWDOWN","DOWN"),"ARROWUP","UP"),"ARROWLEFT","LEFT"),"ARROWRIGHT","RIGHT"),"↓","DOWN"),"↑","UP"),"←","LEFT"),"→","RIGHT"),"SPACEBAR","SPACE"),"−","-"),"MINUS","-"),"PLUS","+")=Key!$E$38:$G$38),"✔ CLEAR","✘ TRY AGAIN"))),"✘ TRY AGAIN")} | F34: {=IF(E34="Show hint",Key!$B$38,"")} | G34: {=IF(LEFT(D34,1)="✔",IF(E34="Show hint",5,10),0)} -> 0
A35: G29 | B35: How do you refer to the whole spill that starts in H5? (from F7-1 Spill Zone) | D35: {=IFERROR(_xlfn.LET(_xlpm.a,'R2 Formula Gauntlet'!$C$35,IF(TRIM(_xlpm.a&"")="","",IF(OR(SUBSTITUTE(SUBSTITUTE(SUBSTITUTE(SUBSTITUTE(SUBSTITUTE(SUBSTITUTE(SUBSTITUTE(SUBSTITUTE(SUBSTITUTE(SUBSTITUTE(SUBSTITUTE(SUBSTITUTE(SUBSTITUTE(SUBSTITUTE(SUBSTITUTE(SUBSTITUTE(SUBSTITUTE(SUBSTITUTE(SUBSTITUTE(SUBSTITUTE(SUBSTITUTE(SUBSTITUTE(SUBSTITUTE(SUBSTITUTE(SUBSTITUTE(SUBSTITUTE(SUBSTITUTE(UPPER(_xlpm.a)," ",""),"CONTROL","CTRL"),"CTL","CTRL"),"ESCAPE","ESC"),"RETURN","ENTER"),"PAGEDOWN","PGDN"),"PGDOWN","PGDN"),"PAGEUP","PGUP"),"ARROWKEYS","ARROW"),"ARROWKEY","ARROW"),"ARROWS","ARROW"),"DOWNARROW","DOWN"),"UPARROW","UP"),"LEFTARROW","LEFT"),"RIGHTARROW","RIGHT"),"ARROWDOWN","DOWN"),"ARROWUP","UP"),"ARROWLEFT","LEFT"),"ARROWRIGHT","RIGHT"),"↓","DOWN"),"↑","UP"),"←","LEFT"),"→","RIGHT"),"SPACEBAR","SPACE"),"−","-"),"MINUS","-"),"PLUS","+")=Key!$E$39:$E$39),"✔ CLEAR","✘ TRY AGAIN"))),"✘ TRY AGAIN")} | F35: {=IF(E35="Show hint",Key!$B$39,"")} | G35: {=IF(LEFT(D35,1)="✔",IF(E35="Show hint",5,10),0)} -> 0
A36: G30 | B36: Which function spills a list of sequential numbers? (from F7-1 Spill Zone) | D36: {=IFERROR(_xlfn.LET(_xlpm.a,'R2 Formula Gauntlet'!$C$36,IF(TRIM(_xlpm.a&"")="","",IF(OR(SUBSTITUTE(SUBSTITUTE(SUBSTITUTE(SUBSTITUTE(SUBSTITUTE(SUBSTITUTE(SUBSTITUTE(SUBSTITUTE(SUBSTITUTE(SUBSTITUTE(SUBSTITUTE(SUBSTITUTE(SUBSTITUTE(SUBSTITUTE(SUBSTITUTE(SUBSTITUTE(SUBSTITUTE(SUBSTITUTE(SUBSTITUTE(SUBSTITUTE(SUBSTITUTE(SUBSTITUTE(SUBSTITUTE(SUBSTITUTE(SUBSTITUTE(SUBSTITUTE(SUBSTITUTE(UPPER(_xlpm.a)," ",""),"CONTROL","CTRL"),"CTL","CTRL"),"ESCAPE","ESC"),"RETURN","ENTER"),"PAGEDOWN","PGDN"),"PGDOWN","PGDN"),"PAGEUP","PGUP"),"ARROWKEYS","ARROW"),"ARROWKEY","ARROW"),"ARROWS","ARROW"),"DOWNARROW","DOWN"),"UPARROW","UP"),"LEFTARROW","LEFT"),"RIGHTARROW","RIGHT"),"ARROWDOWN","DOWN"),"ARROWUP","UP"),"ARROWLEFT","LEFT"),"ARROWRIGHT","RIGHT"),"↓","DOWN"),"↑","UP"),"←","LEFT"),"→","RIGHT"),"SPACEBAR","SPACE"),"−","-"),"MINUS","-"),"PLUS","+")=Key!$E$40:$J$40),"✔ CLEAR","✘ TRY AGAIN"))),"✘ TRY AGAIN")} | F36: {=IF(E36="Show hint",Key!$B$40,"")} | G36: {=IF(LEFT(D36,1)="✔",IF(E36="Show hint",5,10),0)} -> 0
A37: G31 | B37: Which function returns only the rows that meet a condition? (from F7-2 Sifter) | D37: {=IFERROR(_xlfn.LET(_xlpm.a,'R2 Formula Gauntlet'!$C$37,IF(TRIM(_xlpm.a&"")="","",IF(OR(SUBSTITUTE(SUBSTITUTE(SUBSTITUTE(SUBSTITUTE(SUBSTITUTE(SUBSTITUTE(SUBSTITUTE(SUBSTITUTE(SUBSTITUTE(SUBSTITUTE(SUBSTITUTE(SUBSTITUTE(SUBSTITUTE(SUBSTITUTE(SUBSTITUTE(SUBSTITUTE(SUBSTITUTE(SUBSTITUTE(SUBSTITUTE(SUBSTITUTE(SUBSTITUTE(SUBSTITUTE(SUBSTITUTE(SUBSTITUTE(SUBSTITUTE(SUBSTITUTE(SUBSTITUTE(UPPER(_xlpm.a)," ",""),"CONTROL","CTRL"),"CTL","CTRL"),"ESCAPE","ESC"),"RETURN","ENTER"),"PAGEDOWN","PGDN"),"PGDOWN","PGDN"),"PAGEUP","PGUP"),"ARROWKEYS","ARROW"),"ARROWKEY","ARROW"),"ARROWS","ARROW"),"DOWNARROW","DOWN"),"UPARROW","UP"),"LEFTARROW","LEFT"),"RIGHTARROW","RIGHT"),"ARROWDOWN","DOWN"),"ARROWUP","UP"),"ARROWLEFT","LEFT"),"ARROWRIGHT","RIGHT"),"↓","DOWN"),"↑","UP"),"←","LEFT"),"→","RIGHT"),"SPACEBAR","SPACE"),"−","-"),"MINUS","-"),"PLUS","+")=Key!$E$41:$J$41),"✔ CLEAR","✘ TRY AGAIN"))),"✘ TRY AGAIN")} | F37: {=IF(E37="Show hint",Key!$B$41,"")} | G37: {=IF(LEFT(D37,1)="✔",IF(E37="Show hint",5,10),0)} -> 0
A38: G32 | B38: In FILTER, which operator joins two conditions so BOTH must be true? (from F7-2 Sifter) | D38: {=IFERROR(_xlfn.LET(_xlpm.a,'R2 Formula Gauntlet'!$C$38,IF(TRIM(_xlpm.a&"")="","",IF(OR(SUBSTITUTE(SUBSTITUTE(SUBSTITUTE(SUBSTITUTE(SUBSTITUTE(SUBSTITUTE(SUBSTITUTE(SUBSTITUTE(SUBSTITUTE(SUBSTITUTE(SUBSTITUTE(SUBSTITUTE(SUBSTITUTE(SUBSTITUTE(SUBSTITUTE(SUBSTITUTE(SUBSTITUTE(SUBSTITUTE(SUBSTITUTE(SUBSTITUTE(SUBSTITUTE(SUBSTITUTE(SUBSTITUTE(SUBSTITUTE(SUBSTITUTE(SUBSTITUTE(SUBSTITUTE(UPPER(_xlpm.a)," ",""),"CONTROL","CTRL"),"CTL","CTRL"),"ESCAPE","ESC"),"RETURN","ENTER"),"PAGEDOWN","PGDN"),"PGDOWN","PGDN"),"PAGEUP","PGUP"),"ARROWKEYS","ARROW"),"ARROWKEY","ARROW"),"ARROWS","ARROW"),"DOWNARROW","DOWN"),"UPARROW","UP"),"LEFTARROW","LEFT"),"RIGHTARROW","RIGHT"),"ARROWDOWN","DOWN"),"ARROWUP","UP"),"ARROWLEFT","LEFT"),"ARROWRIGHT","RIGHT"),"↓","DOWN"),"↑","UP"),"←","LEFT"),"→","RIGHT"),"SPACEBAR","SPACE"),"−","-"),"MINUS","-"),"PLUS","+")=Key!$E$42:$F$42),"✔ CLEAR","✘ TRY AGAIN"))),"✘ TRY AGAIN")} | F38: {=IF(E38="Show hint",Key!$B$42,"")} | G38: {=IF(LEFT(D38,1)="✔",IF(E38="Show hint",5,10),0)} -> 0
A40: MISSIONS
B41: ▶ Open R2 Arena (or press Ctrl+PgDn)
A42: # | B42: Mission | C42: Your answer | D42: Result | E42: Hint? | F42: Hint | G42: XP
...

Sheet R2 Arena
A1: ARENA ▸ R2 FORMULA GAUNTLET
A2: Practice area · everything here is editable. Missions and their checks are on the stage sheet.
A3: PASS CODE | B3: FORMULAS | D3: ◀ Back to R2 Formula Gauntlet
B5: Order | C5: Date | D5: Region | E5: Rep | F5: Product | G5: Units | H5: Revenue | I5: Flag | K5: Region | L5: Manager | Q5: Raj's orders ▼
B6: O-101 | C6: 46027 | D6: East | E6: Kim | F6: Widget | G6: 40 | H6: 1200 | K6: East | L6: Mia | N6: West Gadget revenue
B7: O-102 | C7: 46031 | D7: West | E7: Lee | F7: Gadget | G7: 15 | H7: 900 | K7: West | L7: Noah | N7: North orders with 50+ units
B8: O-103 | C8: 46036 | D8: North | E8: Ava | F8: Widget | G8: 55 | H8: 1650 | K8: North | L8: Zoe | N8: Manager of South
B9: O-104 | C9: 46042 | D9: East | E9: Kim | F9: Gizmo | G9: 20 | H9: 1000 | K9: South | L9: Liam | N9: East average revenue (rounded)
B10: O-105 | C10: 46055 | D10: South | E10: Raj | F10: Gadget | G10: 60 | H10: 3600 | N10: Different products
B11: O-106 | C11: 46060 | D11: West | E11: Lee | F11: Widget | G11: 35 | H11: 1050 | N11: Month-end of the latest order
B12: O-107 | C12: 46064 | D12: East | E12: Ava | F12: Gadget | G12: 25 | H12: 1500
B13: O-108 | C13: 46072 | D13: North | E13: Raj | F13: Gizmo | G13: 45 | H13: 2250
B14: O-109 | C14: 46084 | D14: West | E14: Kim | F14: Gizmo | G14: 10 | H14: 500
B15: O-110 | C15: 46089 | D15: East | E15: Lee | F15: Widget | G15: 70 | H15: 2100
B16: O-111 | C16: 46096 | D16: South | E16: Ava | F16: Widget | G16: 30 | H16: 900
B17: O-112 | C17: 46103 | D17: North | E17: Kim | F17: Gadget | G17: 50 | H17: 3000
B18: O-113 | C18: 46113 | D18: East | E18: Raj | F18: Gizmo | G18: 65 | H18: 3250
B19: O-114 | C19: 46118 | D19: West | E19: Ava | F19: Gadget | G19: 20 | H19: 1200
B20: O-115 | C20: 46125 | D20: South | E20: Lee | F20: Gizmo | G20: 15 | H20: 750
B21: O-116 | C21: 46133 | D21: East | E21: Kim | F21: Widget | G21: 50 | H21: 1500
B22: O-117 | C22: 46146 | D22: North | E22: Lee | F22: Widget | G22: 25 | H22: 750
B23: O-118 | C23: 46154 | D23: West | E23: Raj | F23: Gadget | G23: 40 | H23: 2400
... B25: O-120 | C25: 46169 | D25: East | E25: Ava | F25: Gadget | G25: 55 | H25: 3300

Sheet R3 Real-World Mission
A1: R3 ▸ REAL-WORLD MISSION
A2: Goal: clean a messy export and report on it
A3: {="SCORE "&TEXT(SUM($G$8:$G$15),"0000")&" / 0080"} -> SCORE 0000 / 0080 | C3: {=IF(SUM($G$8:$G$15)>=80,"★★★",IF(SUM($G$8:$G$15)>=80*0.8,"★★☆",IF(SUM($G$8:$G$15)>=80*0.5,"★☆☆","☆☆☆")))} -> ☆☆☆ | D3: {=REPT("█",ROUND(10*SUM($G$8:$G$15)/80,0))&REPT("░",10-ROUND(10*SUM($G$8:$G$15)/80,0))&" "&TEXT(SUM($G$8:$G$15)/80,"0%")} -> ░░░░░░░░░░ 0% | F3: {=IF(SUM($G$8:$G$15)>=80*0.5,"STAGE CLEAR! ▶ Next: Certificate","")}
A5: MISSIONS
B6: ▶ Open R3 Arena (or press Ctrl+PgDn)
A7: # | B7: Mission | C7: Your answer | D7: Result | E7: Hint? | F7: Hint | G7: XP
A8: M1 | B8: Clean the names: in E6 write =PROPER(TRIM(B6)) and fill down to E17. | C8: ▶ ARENA M1 (cell E6) | D8: {=IF(COUNTA('R3 Arena'!$E$6,'R3 Arena'!$E$7,'R3 Arena'!$E$8,'R3 Arena'!$E$9,'R3 Arena'!$E$10,'R3 Arena'!$E$11,'R3 Arena'!$E$12,'R3 Arena'!$E$13,'R3 Arena'!$E$14,'R3 Arena'!$E$15,'R3 Arena'!$E$16,'R3 Arena'!$E$17)=0,"",IF(OR(NOT(_xlfn.ISFORMULA('R3 Arena'!$E$6)),NOT(_xlfn.ISFORMULA('R3 Arena'!$E$7)),NOT(_xlfn.ISFORMULA('R3 Arena'!$E$8)),NOT(_xlfn.ISFORMULA('R3 Arena'!$E$9)),NOT(_xlfn.ISFORMULA('R3 Arena'!$E$10)),NOT(_xlfn.ISFORMULA('R3 Arena'!$E$11)),NOT(_xlfn.ISFORMULA('R3 Arena'!$E$12)),NOT(_xlfn.ISFORMULA('R3 Arena'!$E$13)),NOT(_xlfn.ISFORMULA('R3 Arena'!$E$14)),NOT(_xlfn.ISFORMULA('R3 Arena'!$E$15)),NOT(_xlfn.ISFORMULA('R3 Arena'!$E$16)),NOT(_xlfn.ISFORMULA('R3 Arena'!$E$17))),"✘ Some cells aren't formulas yet",IF(OR(ISERROR('R3 Arena'!$E$6),ISERROR('R3 Arena'!$E$7),ISERROR('R3 Arena'!$E$8),ISERROR('R3 Arena'!$E$9),ISERROR('R3 Arena'!$E$10),ISERROR('R3 Arena'!$E$11),ISERROR('R3 Arena'!$E$12),ISERROR('R3 Arena'!$E$13),ISERROR('R3 Arena'!$E$14),ISERROR('R3 Arena'!$E$15),ISERROR('R3 Arena'!$E$16),ISERROR('R3 Arena'!$E$17)),"✘ Some cells show an error",IF(NOT(AND(IFERROR(AND(ISTEXT('R3 Arena'!$E$6),EXACT('R3 Arena'!$E$6,Key!$E$51)),FALSE),IFERROR(AND(ISTEXT('R3 Arena'!$E$7),EXACT('R3 Arena'!$E$7,Key!$F$51)),FALSE),IFERROR(AND(ISTEXT('R3 Arena'!$E$8),EXACT('R3 Arena'!$E$8,Key!$G$51)),FALSE),IFERROR(AND(ISTEXT('R3 Arena'!$E$9),EXACT('R3 Arena'!$E$9,Key!$H$51)),FALSE),IFERROR(AND(ISTEXT('R3 Arena'!$E$10),EXACT('R3 Arena'!$E$10,Key!$I$51)),FALSE),IFERROR(AND(ISTEXT('R3 Arena'!$E$11),EXACT('R3 Arena'!$E$11,Key!$J$51)),FALSE),IFERROR(AND(ISTEXT('R3 Arena'!$E$12),EXACT('R3 Arena'!$E$12,Key!$K$51)),FALSE),IFERROR(AND(ISTEXT('R3 Arena'!$E$13),EXACT('R3 Arena'!$E$13,Key!$L$51)),FALSE),IFERROR(AND(ISTEXT('R3 Arena'!$E$14),EXACT('R3 Arena'!$E$14,Key!$M$51)),FALSE),IFERROR(AND(ISTEXT('R3 Arena'!$E$15),EXACT('R3 Arena'!$E$15,Key!$N$51)),FALSE),IFERROR(AND(ISTEXT('R3 Arena'!$E$16),EXACT('R3 Arena'!$E$16,Key!$O$51)),FALSE),IFERROR(AND(ISTEXT('R3 Arena'!$E$17),EXACT('R3 Arena'!$E$17,Key!$P$51)),FALSE))),"✘ TRY AGAIN",IF(AND(OR(ISNUMBER(FIND({"=","(",",","+","-","*","/","&"," ","<",">",":","@","^"}&"PROPER"&"(",UPPER(_xlfn.FORMULATEXT('R3 Arena'!$E$6))))),OR(ISNUMBER(FIND({"=","(",",","+","-","*","/","&"," ","<",">",":","@","^"}&"TRIM"&"(",UPPER(_xlfn.FORMULATEXT('R3 Arena'!$E$6)))))),"✔ CLEAR","✘ CLOSE · right value, but use PROPER and TRIM")))))} | F8: {=IF(E8="Show hint",Key!$B$51,"")} | G8: {=IF(LEFT(D8,1)="✔",IF(E8="Show hint",5,10),0)} -> 0
A9: M2 | B9: Turn the text amounts into numbers: in F6 write =VALUE(D6) and fill down to F17. | C9: ▶ ARENA M2 (cell F6) | D9: {=IF(COUNTA('R3 Arena'!$F$6,'R3 Arena'!$F$7,'R3 Arena'!$F$8,'R3 Arena'!$F$9,'R3 Arena'!$F$10,'R3 Arena'!$F$11,'R3 Arena'!$F$12,'R3 Arena'!$F$13,'R3 Arena'!$F$14,'R3 Arena'!$F$15,'R3 Arena'!$F$16,'R3 Arena'!$F$17)=0,"",IF(OR(NOT(_xlfn.ISFORMULA('R3 Arena'!$F$6)),NOT(_xlfn.ISFORMULA('R3 Arena'!$F$7)),NOT(_xlfn.ISFORMULA('R3 Arena'!$F$8)),NOT(_xlfn.ISFORMULA('R3 Arena'!$F$9)),NOT(_xlfn.ISFORMULA('R3 Arena'!$F$10)),NOT(_xlfn.ISFORMULA('R3 Arena'!$F$11)),NOT(_xlfn.ISFORMULA('R3 Arena'!$F$12)),NOT(_xlfn.ISFORMULA('R3 Arena'!$F$13)),NOT(_xlfn.ISFORMULA('R3 Arena'!$F$14)),NOT(_xlfn.ISFORMULA('R3 Arena'!$F$15)),NOT(_xlfn.ISFORMULA('R3 Arena'!$F$16)),NOT(_xlfn.ISFORMULA('R3 Arena'!$F$17))),"✘ Some cells aren't formulas yet",IF(OR(ISERROR('R3 Arena'!$F$6),ISERROR('R3 Arena'!$F$7),ISERROR('R3 Arena'!$F$8),ISERROR('R3 Arena'!$F$9),ISERROR('R3 Arena'!$F$10),ISERROR('R3 Arena'!$F$11),ISERROR('R3 Arena'!$F$12),ISERROR('R3 Arena'!$F$13),ISERROR('R3 Arena'!$F$14),ISERROR('R3 Arena'!$F$15),ISERROR('R3 Arena'!$F$16),ISERROR('R3 Arena'!$F$17)),"✘ Some cells show an error",IF(NOT(AND(IFERROR(AND(ISNUMBER('R3 Arena'!$F$6),ABS('R3 Arena'!$F$6-Key!$E$52)<=1E-9*MAX(1,ABS(Key!$E$52))),FALSE),IFERROR(AND(ISNUMBER('R3 Arena'!$F$7),ABS('R3 Arena'!$F$7-Key!$F$52)<=1E-9*MAX(1,ABS(Key!$F$52))),FALSE),IFERROR(AND(ISNUMBER('R3 Arena'!$F$8),ABS('R3 Arena'!$F$8-Key!$G$52)<=1E-9*MAX(1,ABS(Key!$G$52))),FALSE),IFERROR(AND(ISNUMBER('R3 Arena'!$F$9),ABS('R3 Arena'!$F$9-Key!$H$52)<=1E-9*MAX(1,ABS(Key!$H$52))),FALSE),IFERROR(AND(ISNUMBER('R3 Arena'!$F$10),ABS('R3 Arena'!$F$10-Key!$I$52)<=1E-9*MAX(1,ABS(Key!$I$52))),FALSE),IFERROR(AND(ISNUMBER('R3 Arena'!$F$11),ABS('R3 Arena'!$F$11-Key!$J$52)<=1E-9*MAX(1,ABS(Key!$J$52))),FALSE),IFERROR(AND(ISNUMBER('R3 Arena'!$F$12),ABS('R3 Arena'!$F$12-Key!$K$52)<=1E-9*MAX(1,ABS(Key!$K$52))),FALSE),IFERROR(AND(ISNUMBER('R3 Arena'!$F$13),ABS('R3 Arena'!$F$13-Key!$L$52)<=1E-9*MAX(1,ABS(Key!$L$52))),FALSE),IFERROR(AND(ISNUMBER('R3 Arena'!$F$14),ABS('R3 Arena'!$F$14-Key!$M$52)<=1E-9*MAX(1,ABS(Key!$M$52))),FALSE),IFERROR(AND(ISNUMBER('R3 Arena'!$F$15),ABS('R3 Arena'!$F$15-Key!$N$52)<=1E-9*MAX(1,ABS(Key!$N$52))),FALSE),IFERROR(AND(ISNUMBER('R3 Arena'!$F$16),ABS('R3 Arena'!$F$16-Key!$O$52)<=1E-9*MAX(1,ABS(Key!$O$52))),FALSE),IFERROR(AND(ISNUMBER('R3 Arena'!$F$17),ABS('R3 Arena'!$F$17-Key!$P$52)<=1E-9*MAX(1,ABS(Key!$P$52))),FALSE))),"✘ TRY AGAIN",IF(AND(OR(ISNUMBER(FIND({"=","(",",","+","-","*","/","&"," ","<",">",":","@","^"}&"VALUE"&"(",UPPER(_xlfn.FORMULATEXT('R3 Arena'!$F$6)))))),"✔ CLEAR","✘ CLOSE · right value, but use VALUE")))))} | F9: {=IF(E9="Show hint",Key!$B$52,"")} | G9: {=IF(LEFT(D9,1)="✔",IF(E9="Show hint",5,10),0)} -> 0
A10: M3 | B10: Look up each Region name: in G6 write =XLOOKUP(C6,$K$6:$K$9,$L$6:$L$9) and fill down to G17. | C10: ▶ ARENA M3 (cell G6) | D10: {=IF(COUNTA('R3 Arena'!$G$6,'R3 Arena'!$G$7,'R3 Arena'!$G$8,'R3 Arena'!$G$9,'R3 Arena'!$G$10,'R3 Arena'!$G$11,'R3 Arena'!$G$12,'R3 Arena'!$G$13,'R3 Arena'!$G$14,'R3 Arena'!$G$15,'R3 Arena'!$G$16,'R3 Arena'!$G$17)=0,"",IF(OR(NOT(_xlfn.ISFORMULA('R3 Arena'!$G$6)),NOT(_xlfn.ISFORMULA('R3 Arena'!$G$7)),NOT(_xlfn.ISFORMULA('R3 Arena'!$G$8)),NOT(_xlfn.ISFORMULA('R3 Arena'!$G$9)),NOT(_xlfn.ISFORMULA('R3 Arena'!$G$10)),NOT(_xlfn.ISFORMULA('R3 Arena'!$G$11)),NOT(_xlfn.ISFORMULA('R3 Arena'!$G$12)),NOT(_xlfn.ISFORMULA('R3 Arena'!$G$13)),NOT(_xlfn.ISFORMULA('R3 Arena'!$G$14)),NOT(_xlfn.ISFORMULA('R3 Arena'!$G$15)),NOT(_xlfn.ISFORMULA('R3 Arena'!$G$16)),NOT(_xlfn.ISFORMULA('R3 Arena'!$G$17))),"✘ Some cells aren't formulas yet",IF(OR(ISERROR('R3 Arena'!$G$6),ISERROR('R3 Arena'!$G$7),ISERROR('R3 Arena'!$G$8),ISERROR('R3 Arena'!$G$9),ISERROR('R3 Arena'!$G$10),ISERROR('R3 Arena'!$G$11),ISERROR('R3 Arena'!$G$12),ISERROR('R3 Arena'!$G$13),ISERROR('R3 Arena'!$G$14),ISERROR('R3 Arena'!$G$15),ISERROR('R3 Arena'!$G$16),ISERROR('R3 Arena'!$G$17)),"✘ Some cells show an error",IF(NOT(AND(IFERROR(AND(ISTEXT('R3 Arena'!$G$6),'R3 Arena'!$G$6=Key!$E$53),FALSE),IFERROR(AND(ISTEXT('R3 Arena'!$G$7),'R3 Arena'!$G$7=Key!$F$53),FALSE),IFERROR(AND(ISTEXT('R3 Arena'!$G$8),'R3 Arena'!$G$8=Key!$G$53),FALSE),IFERROR(AND(ISTEXT('R3 Arena'!$G$9),'R3 Arena'!$G$9=Key!$H$53),FALSE),IFERROR(AND(ISTEXT('R3 Arena'!$G$10),'R3 Arena'!$G$10=Key!$I$53),FALSE),IFERROR(AND(ISTEXT('R3 Arena'!$G$11),'R3 Arena'!$G$11=Key!$J$53),FALSE),IFERROR(AND(ISTEXT('R3 Arena'!$G$12),'R3 Arena'!$G$12=Key!$K$53),FALSE),IFERROR(AND(ISTEXT('R3 Arena'!$G$13),'R3 Arena'!$G$13=Key!$L$53),FALSE),IFERROR(AND(ISTEXT('R3 Arena'!$G$14),'R3 Arena'!$G$14=Key!$M$53),FALSE),IFERROR(AND(ISTEXT('R3 Arena'!$G$15),'R3 Arena'!$G$15=Key!$N$53),FALSE),IFERROR(AND(ISTEXT('R3 Arena'!$G$16),'R3 Arena'!$G$16=Key!$O$53),FALSE),IFERROR(AND(ISTEXT('R3 Arena'!$G$17),'R3 Arena'!$G$17=Key!$P$53),FALSE))),"✘ TRY AGAIN",IF(AND(OR(ISNUMBER(FIND({"=","(",",","+","-","*","/","&"," ","<",">",":","@","^"}&"XLOOKUP"&"(",UPPER(_xlfn.FORMULATEXT('R3 Arena'!$G$6)))))),IF(ISNUMBER(FIND("$",_xlfn.FORMULATEXT('R3 Arena'!$G$6))),"✔ CLEAR","✘ CLOSE · add $ so it fills correctly (F4)"),"✘ CLOSE · right value, but use XLOOKUP")))))} | F10: {=IF(E10="Show hint",Key!$B$53,"")} | G10: {=IF(LEFT(D10,1)="✔",IF(E10="Show hint",5,10),0)} -> 0
A11: M4 | B11: In O6 total the East amounts from your new columns: =SUMIFS(F6:F17,G6:G17,"East"). | C11: ▶ ARENA M4 (cell O6) | D11: {=IF(ISBLANK('R3 Arena'!$O$6),"",IF(NOT(_xlfn.ISFORMULA('R3 Arena'!$O$6)),"✘ That's a typed value · enter a formula",IF(ISERROR('R3 Arena'!$O$6),"✘ Your formula returns "&IFERROR(CHOOSE(ERROR.TYPE('R3 Arena'!$O$6),"#NULL!","#DIV/0!","#VALUE!","#REF!","#NAME?","#NUM!","#N/A","#GETTING_DATA","#SPILL!","#CONNECT!","#BLOCKED!","#UNKNOWN!","#FIELD!","#CALC!"),"an error"),IF(NOT(AND(IFERROR(AND(ISNUMBER('R3 Arena'!$O$6),ABS('R3 Arena'!$O$6-Key!$C$54)<=1E-9*MAX(1,ABS(Key!$C$54))),FALSE))),"✘ TRY AGAIN",IF(AND(OR(ISNUMBER(FIND({"=","(",",","+","-","*","/","&"," ","<",">",":","@","^"}&"SUMIFS"&"(",UPPER(_xlfn.FORMULATEXT('R3 Arena'!$O$6)))))),"✔ CLEAR","✘ CLOSE · right value, but use SUMIFS")))))} | F11: {=IF(E11="Show hint",Key!$B$54,"")} | G11: {=IF(LEFT(D11,1)="✔",IF(E11="Show hint",5,10),0)} -> 0
A12: M5 | B12: In H6 flag big orders: "Big" when the Amount (F6) is at least 1000, otherwise empty text. Fill down to H17. | C12: ▶ ARENA M5 (cell H6) | D12: {=IF(COUNTA('R3 Arena'!$H$6,'R3 Arena'!$H$7,'R3 Arena'!$H$8,'R3 Arena'!$H$9,'R3 Arena'!$H$10,'R3 Arena'!$H$11,'R3 Arena'!$H$12,'R3 Arena'!$H$13,'R3 Arena'!$H$14,'R3 Arena'!$H$15,'R3 Arena'!$H$16,'R3 Arena'!$H$17)=0,"",IF(OR(NOT(_xlfn.ISFORMULA('R3 Arena'!$H$6)),NOT(_xlfn.ISFORMULA('R3 Arena'!$H$7)),NOT(_xlfn.ISFORMULA('R3 Arena'!$H$8)),NOT(_xlfn.ISFORMULA('R3 Arena'!$H$9)),NOT(_xlfn.ISFORMULA('R3 Arena'!$H$10)),NOT(_xlfn.ISFORMULA('R3 Arena'!$H$11)),NOT(_xlfn.ISFORMULA('R3 Arena'!$H$12)),NOT(_xlfn.ISFORMULA('R3 Arena'!$H$13)),NOT(_xlfn.ISFORMULA('R3 Arena'!$H$14)),NOT(_xlfn.ISFORMULA('R3 Arena'!$H$15)),NOT(_xlfn.ISFORMULA('R3 Arena'!$H$16)),NOT(_xlfn.ISFORMULA('R3 Arena'!$H$17))),"✘ Some cells aren't formulas yet",IF(OR(ISERROR('R3 Arena'!$H$6),ISERROR('R3 Arena'!$H$7),ISERROR('R3 Arena'!$H$8),ISERROR('R3 Arena'!$H$9),ISERROR('R3 Arena'!$H$10),ISERROR('R3 Arena'!$H$11),ISERROR('R3 Arena'!$H$12),ISERROR('R3 Arena'!$H$13),ISERROR('R3 Arena'!$H$14),ISERROR('R3 Arena'!$H$15),ISERROR('R3 Arena'!$H$16),ISERROR('R3 Arena'!$H$17)),"✘ Some cells show an error",IF(NOT(AND(IFERROR(AND(ISTEXT('R3 Arena'!$H$6),'R3 Arena'!$H$6=Key!$E$55),FALSE),IFERROR(AND(ISTEXT('R3 Arena'!$H$7),'R3 Arena'!$H$7=Key!$F$55),FALSE),IFERROR(AND(ISTEXT('R3 Arena'!$H$8),'R3 Arena'!$H$8=Key!$G$55),FALSE),IFERROR(AND(ISTEXT('R3 Arena'!$H$9),'R3 Arena'!$H$9=Key!$H$55),FALSE),IFERROR(AND(ISTEXT('R3 Arena'!$H$10),'R3 Arena'!$H$10=Key!$I$55),FALSE),IFERROR(AND(ISTEXT('R3 Arena'!$H$11),'R3 Arena'!$H$11=Key!$J$55),FALSE),IFERROR(AND(ISTEXT('R3 Arena'!$H$12),'R3 Arena'!$H$12=Key!$K$55),FALSE),IFERROR(AND(ISTEXT('R3 Arena'!$H$13),'R3 Arena'!$H$13=Key!$L$55),FALSE),IFERROR(AND(ISTEXT('R3 Arena'!$H$14),'R3 Arena'!$H$14=Key!$M$55),FALSE),IFERROR(AND(ISTEXT('R3 Arena'!$H$15),'R3 Arena'!$H$15=Key!$N$55),FALSE),IFERROR(AND(ISTEXT('R3 Arena'!$H$16),'R3 Arena'!$H$16=Key!$O$55),FALSE),IFERROR(AND(ISTEXT('R3 Arena'!$H$17),'R3 Arena'!$H$17=Key!$P$55),FALSE))),"✘ TRY AGAIN",IF(AND(OR(ISNUMBER(FIND({"=","(",",","+","-","*","/","&"," ","<",">",":","@","^"}&"IF"&"(",UPPER(_xlfn.FORMULATEXT('R3 Arena'!$H$6)))))),"✔ CLEAR","✘ CLOSE · right value, but use IF")))))} | F12: {=IF(E12="Show hint",Key!$B$55,"")} | G12: {=IF(LEFT(D12,1)="✔",IF(E12="Show hint",5,10),0)} -> 0
